Workbook

Sheet Сводная
A1: Период | D1: Итого к перечислению на счет, руб | E1: шт. | H1: Выручка | K1: Себестоимость продаж | L1: Логистика | M1: Комиссия | N1: Хранение | O1: Платная приемка | P1: Штрафы | Q1: Реклама Ozon | R1: Прочее | S1: Доп. услуги | T1: Услуги FBO | U1: Компенсировано | V1: Пополнение рекламного кабинета | W1: ЕАЭС | X1: Налог | Y1: Итого | Z1: Итог месяц | AA1: % Cебестоимости | AB1: Маржинальность, % | AC1: Рентабельность, % | AD1: Доля рекламы, %
A2: Месяц | B2: Даты | C2: Нед | E2: Заказы | F2: Продажи | G2: Возвраты | H2: Продажи | I2: Возвраты | J2: Общая
A3: Январь | B3: 01-04.01 | D3: =J3-SUM(L3:T3)+U3+V3 -> 1074.71 | E3: ='Юнит 01-04.01'!K$24 -> 122 | F3: ='Юнит 01-04.01'!P$24 -> 51 | G3: ='Юнит 01-04.01'!Q$24 -> 1 | H3: ='Юнит 01-04.01'!S$24 -> 85937 | I3: ='Юнит 01-04.01'!T$24 -> -1600 | J3: =H3+I3 -> 84337 | K3: ='Юнит 01-04.01'!W$24 -> 6252.96 | L3: ='Юнит 01-04.01'!Z$24 -> 8548.62 | M3: ='Юнит 01-04.01'!X$24 -> 36264.91 | Q3: ='Юнит 01-04.01'!AA$24 -> 36772.95 | R3: 1675.81 | S3: 0 | T3: 0 | W3: 5252 | X3: =(J3)*0.01 -> 843.37 | Y3: =J3-SUM(L3:T3)-K3-X3+U3-V3+W3 -> -769.62 | Z3: =SUM(Y3:Y7) -> 43931.01 | AA3: =K3/J3 -> 0.074142547 | AB3: =Y3/K3 -> -0.12308091 | AC3: =Y3/J3 -> -0.0091255321 | AD3: =Q3/J3 -> 0.43602393
B4: 05-11.01 | D4: =J4-SUM(L4:T4)+U4+V4 -> 57707.57 | E4: ='Юнит 05-11.01'!K$24 -> 183 | F4: ='Юнит 05-11.01'!P$24 -> 168 | G4: ='Юнит 05-11.01'!Q$24 -> 8 | H4: ='Юнит 05-11.01'!S$24 -> 277715 | I4: ='Юнит 05-11.01'!T$24 -> -13822 | J4: =H4+I4 -> 263893 | K4: ='Юнит 05-11.01'!W$24 -> 20205.96 | L4: ='Юнит 05-11.01'!Z$24 -> 28076.33 | M4: ='Юнит 05-11.01'!X$24 -> 113473.99 | Q4: ='Юнит 05-11.01'!AA$24 -> 56365.38 | R4: 4144.33 | S4: 75 | T4: 4050.4 | X4: =(J4)*0.01 -> 2638.93 | Y4: =J4-SUM(L4:T4)-K4-X4+U4-V4+W4 -> 34862.68 | AA4: =K4/J4 -> 0.076568761 | AB4: =Y4/K4 -> 1.7253662 | AC4: =Y4/J4 -> 0.13210915 | AD4: =Q4/J4 -> 0.2135918
B5: 12-18.01 | D5: =J5-SUM(L5:T5)+U5+V5 -> 36064.15 | E5: ='Юнит 12-18.01'!K$24 -> 144 | F5: ='Юнит 12-18.01'!P$24 -> 122 | G5: ='Юнит 12-18.01'!Q$24 -> 2 | H5: ='Юнит 12-18.01'!S$24 -> 211029 | I5: ='Юнит 12-18.01'!T$24 -> -3221 | J5: =H5+I5 -> 207808 | K5: ='Юнит 12-18.01'!W$24 -> 15093.09 | L5: ='Юнит 12-18.01'!Z$24 -> 24172.28 | M5: ='Юнит 12-18.01'!X$24 -> 89357.44 | Q5: ='Юнит 12-18.01'!AA$24 -> 53249.12 | R5: 4025.01 | S5: 0 | T5: 940 | W5: 5135 | X5: =(J5)*0.01 -> 2078.08 | Y5: =J5-SUM(L5:T5)-K5-X5+U5-V5+W5 -> 24027.98 | AA5: =K5/J5 -> 0.072629976 | AB5: =Y5/K5 -> 1.5919855 | AC5: =Y5/J5 -> 0.11562587 | AD5: =Q5/J5 -> 0.25624192
B6: 19-25.01 | D6: =J6-SUM(L6:T6)+U6+V6 -> 34413.47 | E6: ='Юнит 19-25.01'!K$24 -> 154 | F6: ='Юнит 19-25.01'!P$24 -> 91 | G6: ='Юнит 19-25.01'!Q$24 -> 2 | H6: ='Юнит 19-25.01'!S$24 -> 161208 | I6: ='Юнит 19-25.01'!T$24 -> -3229 | J6: =H6+I6 -> 157979 | K6: ='Юнит 19-25.01'!W$24 -> 11132.49 | L6: ='Юнит 19-25.01'!Z$24 -> 16989.46 | M6: ='Юнит 19-25.01'!X$24 -> 67930.97 | Q6: ='Юнит 19-25.01'!AA$24 -> 42151.21 | R6: 3468.89 | S6: 25 | T6: 0 | V6: 7000 | X6: =(J6)*0.01 -> 1579.79 | Y6: =J6-SUM(L6:T6)-K6-X6+U6-V6+W6 -> 7701.19 | AA6: =K6/J6 -> 0.070468163 | AB6: =Y6/K6 -> 0.69177605 | AC6: =Y6/J6 -> 0.048748188 | AD6: =Q6/J6 -> 0.26681527
B7: 26-31.01 | D7: =J7-SUM(L7:T7)+U7+V7 -> -6035.1 | E7: ='Юнит 26-31.01'!K$24 -> 200 | F7: ='Юнит 26-31.01'!P$24 -> 112 | G7: ='Юнит 26-31.01'!Q$24 -> 2 | H7: ='Юнит 26-31.01'!S$24 -> 200558 | I7: ='Юнит 26-31.01'!T$24 -> -3595 | J7: =H7+I7 -> 196963 | K7: ='Юнит 26-31.01'!W$24 -> 13886.49 | L7: ='Юнит 26-31.01'!Z$24 -> 20843.55 | M7: ='Юнит 26-31.01'!X$24 -> 84694.09 | Q7: ='Юнит 26-31.01'!AA$24 -> 50770.67 | R7: 3661.19 | S7: 150 | T7: 43993.6 | U7: 1115 | X7: =(J7)*0.01 -> 1969.63 | Y7: =J7-SUM(L7:T7)-K7-X7+U7-V7+W7 -> -21891.22 | AA7: =(K7+K8)/(J7+J8) -> 0.070282074 | AB7: =(Y7+Y8)/(K7+K8) -> -0.76300764 | AC7: =(Y7+Y8)/(J7+J8) -> -0.05362576 | AD7: =(Q7+Q8)/(J7+J8) -> 0.25406002
B8: 01.02-01.02 | D8: =J8-SUM(L8:T8)+U8+V8 -> 7323.99 | E8: ='Юнит 01.02'!K$24 -> 36 | F8: ='Юнит 01.02'!P$24 -> 19 | G8: ='Юнит 01.02'!Q$24 -> 1 | H8: ='Юнит 01.02'!S$24 -> 34372 | I8: ='Юнит 01.02'!T$24 -> -1750 | J8: =H8+I8 -> 32622 | K8: ='Юнит 01.02'!W$24 -> 2249.22 | L8: ='Юнит 01.02'!Z$24 -> 3179.52 | M8: ='Юнит 01.02'!X$24 -> 14027.46 | Q8: ='Юнит 01.02'!AA$24 -> 7557.7 | R8: 533.33 | W8: 4831 | X8: =(J8)*0.01 -> 326.22 | Y8: =J8-SUM(L8:T8)-K8-X8+U8-V8+W8 -> 9579.55 | Z8: =SUM(Y8:Y12) -> 9579.55
B9: 02.02-08.02 | AA9: =K9/J9 -> #DIV/0! | AB9: =Y9/K9 -> #DIV/0! | AC9: =Y9/J9 -> #DIV/0! | AD9: =Q9/J9 -> #DIV/0!
B10: 09-15.02 | AA10: =K10/J10 -> #DIV/0! | AB10: =Y10/K10 -> #DIV/0! | AC10: =Y10/J10 -> #DIV/0! | AD10: =Q10/J10 -> #DIV/0!
B11: 16-22.02 | AA11: =K11/J11 -> #DIV/0! | AB11: =Y11/K11 -> #DIV/0! | AC11: =Y11/J11 -> #DIV/0! | AD11: =Q11/J11 -> #DIV/0!
B12: 23-28.02 | AA12: =K12/J12 -> #DIV/0! | AB12: =Y12/K12 -> #DIV/0! | AC12: =Y12/J12 -> #DIV/0! | AD12: =Q12/J12 -> #DIV/0!
A13: Итого | D13: =SUM(D3:D12) -> 130548.79 | E13: =SUM(E3:E12) -> 839 | F13: =SUM(F3:F12) -> 563 | G13: =SUM(G3:G12) -> 16 | H13: =SUM(H3:H12) -> 970819 | I13: =SUM(I3:I12) -> -27217 | J13: =SUM(J3:J12) -> 943602 | K13: =SUM(K3:K12) -> 68820.21 | ... Z13: =SUM(Z3:Z12) -> 53510.56 | AA13: =K13/J13 -> 0.072933514 | AB13: =Y13/K13 -> 0.77754136 | AC13: =Y13/J13 -> 0.056708824 | AD13: =Q13/J13 -> 0.26162199
H14: % от выручки за весь период
I15: =-I13/H13 -> 0.028035092 | J15: 0 | K15: =K13/$J$13 -> 0.072933514 | L15: =L13/$J$13 -> 0.10789481 | M15: =M13/$J$13 -> 0.43 | Q15: =Q13/$J$13 -> 0.26162199 | R15: =R13/$J$13 -> 0.018555026 | S15: =S13/$J$13 -> 0.00026494221 | T15: =T13/$J$13 -> 0.051911717 | U15: =U13/$J$13 -> 0.0011816423 | V15: =V13/$J$13 -> 0.0074183819 | X15: =X13/$J$13 -> 0.01 | Y15: =Y13/K13 -> 0.77754136 | Z15: Маржинальность, % | AA15: =Y13/J13 -> 0.056708824
A17: январь | D17: =SUM(D3:D7) -> 123224.8 | E17: =SUM(E3:E7) -> 803 | F17: =SUM(F3:F7) -> 544 | G17: =SUM(G3:G7) -> 15 | H17: =SUM(H3:H7) -> 936447 | I17: =SUM(I3:I7) -> -25467 | J17: =SUM(J3:J7) -> 910980 | K17: =SUM(K3:K7) -> 66570.99 | ... Z17: =SUM(Z3:Z7) -> 43931.01

Sheet АВС 02-08.02
B2: ОЧКИ
C3: Прибыль | D3: % прибыль | E3: Доля | F3: ABC прибыль | G3: ABC кол-во | J3: Кол-во | K3: % кол-во | L3: Доля | M3: ABC кол-во
B4: черные с железкой классика | D4: =C4/C$18 -> #DIV/0! | E4: =D4 -> #DIV/0! | F4: =IF(AND(E4<=0),"C",IF(E4<=0.8,"A",IF(E4<=0.95,"B","C"))) -> #DIV/0! | G4: =VLOOKUP(B$4:B$17,I$4:M$17,5,0) -> #DIV/0! | I4: черные с железкой классика | K4: =J4/J$18 -> #DIV/0! | L4: =K4 -> #DIV/0! | M4: =_xlfn.IFS(L4<80%,"A",L4<=95%,"B",L4>95%,"C") -> #DIV/0!
B5: qs черные | D5: =C5/C$18 -> #DIV/0! | E5: =D5+E4 -> #DIV/0! | F5: =IF(AND(E5<=0),"C",IF(E5<=0.8,"A",IF(E5<=0.95,"B","C"))) -> #DIV/0! | G5: =VLOOKUP(B$4:B$17,I$4:M$17,5,0) -> #DIV/0! | I5: qs черные | K5: =J5/J$18 -> #DIV/0! | L5: =K5+L4 -> #DIV/0! | M5: =_xlfn.IFS(L5<80%,"A",L5<=95%,"B",L5>95%,"C") -> #DIV/0!
B6: qs синие | D6: =C6/C$18 -> #DIV/0! | E6: =D6+E5 -> #DIV/0! | F6: =IF(AND(E6<=0),"C",IF(E6<=0.8,"A",IF(E6<=0.95,"B","C"))) -> #DIV/0! | G6: =VLOOKUP(B$4:B$17,I$4:M$17,5,0) -> #DIV/0! | I6: qs синие | K6: =J6/J$18 -> #DIV/0! | L6: =K6+L5 -> #DIV/0! | M6: =_xlfn.IFS(L6<80%,"A",L6<=95%,"B",L6>95%,"C") -> #DIV/0!
B7: qs желтые | D7: =C7/C$18 -> #DIV/0! | E7: =D7+E6 -> #DIV/0! | F7: =IF(AND(E7<=0),"C",IF(E7<=0.8,"A",IF(E7<=0.95,"B","C"))) -> #DIV/0! | G7: =VLOOKUP(B$4:B$17,I$4:M$17,5,0) -> #DIV/0! | I7: qs желтые | K7: =J7/J$18 -> #DIV/0! | L7: =K7+L6 -> #DIV/0! | M7: =_xlfn.IFS(L7<80%,"A",L7<=95%,"B",L7>95%,"C") -> #DIV/0!
B8: qs коричневые | D8: =C8/C$18 -> #DIV/0! | E8: =D8+E7 -> #DIV/0! | F8: =IF(AND(E8<=0),"C",IF(E8<=0.8,"A",IF(E8<=0.95,"B","C"))) -> #DIV/0! | G8: =VLOOKUP(B$4:B$17,I$4:M$17,5,0) -> #DIV/0! | I8: qs коричневые | K8: =J8/J$18 -> #DIV/0! | L8: =K8+L7 -> #DIV/0! | M8: =_xlfn.IFS(L8<80%,"A",L8<=95%,"B",L8>95%,"C") -> #DIV/0!
B9: MR8854 C2 | D9: =C9/C$18 -> #DIV/0! | E9: =D9+E8 -> #DIV/0! | F9: =IF(AND(E9<=0),"C",IF(E9<=0.8,"A",IF(E9<=0.95,"B","C"))) -> #DIV/0! | G9: =VLOOKUP(B$4:B$17,I$4:M$17,5,0) -> #DIV/0! | I9: MR8854 C2 | K9: =J9/J$18 -> #DIV/0! | L9: =K9+L8 -> #DIV/0! | M9: =_xlfn.IFS(L9<80%,"A",L9<=95%,"B",L9>95%,"C") -> #DIV/0!
B10: th черн | D10: =C10/C$18 -> #DIV/0! | E10: =D10+E9 -> #DIV/0! | F10: =IF(AND(E10<=0),"C",IF(E10<=0.8,"A",IF(E10<=0.95,"B","C"))) -> #DIV/0! | G10: =VLOOKUP(B$4:B$17,I$4:M$17,5,0) -> #DIV/0! | I10: th черн | K10: =J10/J$18 -> #DIV/0! | L10: =K10+L9 -> #DIV/0! | M10: =_xlfn.IFS(L10<80%,"A",L10<=95%,"B",L10>95%,"C") -> #DIV/0!
B11: th син | D11: =C11/C$18 -> #DIV/0! | E11: =D11+E10 -> #DIV/0! | F11: =IF(AND(E11<=0),"C",IF(E11<=0.8,"A",IF(E11<=0.95,"B","C"))) -> #DIV/0! | G11: =VLOOKUP(B$4:B$17,I$4:M$17,5,0) -> #DIV/0! | I11: th син | K11: =J11/J$18 -> #DIV/0! | L11: =K11+L10 -> #DIV/0! | M11: =_xlfn.IFS(L11<80%,"A",L11<=95%,"B",L11>95%,"C") -> #DIV/0!
B12: th желт | D12: =C12/C$18 -> #DIV/0! | E12: =D12+E5 -> #DIV/0! | F12: =IF(AND(E12<=0),"C",IF(E12<=0.8,"A",IF(E12<=0.95,"B","C"))) -> #DIV/0! | G12: =VLOOKUP(B$4:B$17,I$4:M$17,5,0) -> #DIV/0! | I12: th желт | K12: =J12/J$18 -> #DIV/0! | L12: =K12+L5 -> #DIV/0! | M12: =_xlfn.IFS(L12<80%,"A",L12<=95%,"B",L12>95%,"C") -> #DIV/0!
B13: th коричн | D13: =C13/C$18 -> #DIV/0! | E13: =D13+E12 -> #DIV/0! | F13: =IF(AND(E13<=0),"C",IF(E13<=0.8,"A",IF(E13<=0.95,"B","C"))) -> #DIV/0! | G13: =VLOOKUP(B$4:B$17,I$4:M$17,5,0) -> #DIV/0! | I13: th коричн | K13: =J13/J$18 -> #DIV/0! | L13: =K13+L12 -> #DIV/0! | M13: =_xlfn.IFS(L13<80%,"A",L13<=95%,"B",L13>95%,"C") -> #DIV/0!
B14: flip черный | D14: =C14/C$18 -> #DIV/0! | E14: =D14+E13 -> #DIV/0! | F14: =IF(AND(E14<=0),"C",IF(E14<=0.8,"A",IF(E14<=0.95,"B","C"))) -> #DIV/0! | G14: =VLOOKUP(B$4:B$17,I$4:M$17,5,0) -> #DIV/0! | I14: flip черный | K14: =J14/J$18 -> #DIV/0! | L14: =K14+L13 -> #DIV/0! | M14: =_xlfn.IFS(L14<80%,"A",L14<=95%,"B",L14>95%,"C") -> #DIV/0!
B15: flip синий | D15: =C15/C$18 -> #DIV/0! | E15: =D15+E14 -> #DIV/0! | F15: =IF(AND(E15<=0),"C",IF(E15<=0.8,"A",IF(E15<=0.95,"B","C"))) -> #DIV/0! | G15: =VLOOKUP(B$4:B$17,I$4:M$17,5,0) -> #DIV/0! | I15: flip синий | K15: =J15/J$18 -> #DIV/0! | L15: =K15+L14 -> #DIV/0! | M15: =_xlfn.IFS(L15<80%,"A",L15<=95%,"B",L15>95%,"C") -> #DIV/0!
B16: flip жел | D16: =C16/C$18 -> #DIV/0! | E16: =D16+E15 -> #DIV/0! | F16: =IF(AND(E16<=0),"C",IF(E16<=0.8,"A",IF(E16<=0.95,"B","C"))) -> #DIV/0! | G16: =VLOOKUP(B$4:B$17,I$4:M$17,5,0) -> #DIV/0! | I16: flip жел | K16: =J16/J$18 -> #DIV/0! | L16: =K16+L15 -> #DIV/0! | M16: =_xlfn.IFS(L16<80%,"A",L16<=95%,"B",L16>95%,"C") -> #DIV/0!
B17: flip коричневый | D17: =C17/C$18 -> #DIV/0! | E17: =D17+E14 -> #DIV/0! | F17: =IF(AND(E17<=0),"C",IF(E17<=0.8,"A",IF(E17<=0.95,"B","C"))) -> #DIV/0! | G17: =VLOOKUP(B$4:B$17,I$4:M$17,5,0) -> #DIV/0! | I17: flip коричневый | K17: =J17/J$18 -> #DIV/0! | L17: =K17+L14 -> #DIV/0! | M17: =_xlfn.IFS(L17<80%,"A",L17<=95%,"B",L17>95%,"C") -> #DIV/0!
C18: =SUM(C4:C17) -> 0 | D18: =SUM(D4:D17) -> #DIV/0! | J18: =SUM(J4:J17) -> 0 | K18: =SUM(K4:K17) -> #DIV/0!
C21: Прибыль | D21: % прибыль | E21: Доля | F21: ABC прибыль | G21: ABC кол-во | J21: Кол-во | K21: % кол-во | L21: Доля | M21: ABC кол-во
D22: =C22/C$42 -> #DIV/0! | E22: =D22 -> #DIV/0! | F22: =IF(AND(E22<=0),"C",IF(E22<=0.8,"A",IF(E22<=0.95,"B","C"))) -> #DIV/0! | G22: =VLOOKUP(B$22:B$42,I$22:M$42,5,0) -> #N/A | K22: =J22/J$42 -> #DIV/0! | L22: =K22 -> #DIV/0! | M22: =_xlfn.IFS(L22<80%,"A",L22<=95%,"B",L22>95%,"C") -> #DIV/0!
D23: =C23/C$42 -> #DIV/0! | E23: =D23+E22 -> #DIV/0! | F23: =IF(AND(E23<=0),"C",IF(E23<=0.8,"A",IF(E23<=0.95,"B","C"))) -> #DIV/0! | G23: =VLOOKUP(B$22:B$42,I$22:M$42,5,0) -> #N/A | K23: =J23/J$42 -> #DIV/0! | L23: =K23+L22 -> #DIV/0! | M23: =_xlfn.IFS(L23<80%,"A",L23<=95%,"B",L23>95%,"C") -> #DIV/0!
D24: =C24/C$42 -> #DIV/0! | E24: =D24+E23 -> #DIV/0! | F24: =IF(AND(E24<=0),"C",IF(E24<=0.8,"A",IF(E24<=0.95,"B","C"))) -> #DIV/0! | G24: =VLOOKUP(B$22:B$42,I$22:M$42,5,0) -> #N/A | K24: =J24/J$42 -> #DIV/0! | L24: =K24+L23 -> #DIV/0! | M24: =_xlfn.IFS(L24<80%,"A",L24<=95%,"B",L24>95%,"C") -> #DIV/0!
D25: =C25/C$42 -> #DIV/0! | E25: =D25+E24 -> #DIV/0! | F25: =IF(AND(E25<=0),"C",IF(E25<=0.8,"A",IF(E25<=0.95,"B","C"))) -> #DIV/0! | G25: =VLOOKUP(B$22:B$42,I$22:M$42,5,0) -> #N/A | K25: =J25/J$42 -> #DIV/0! | L25: =K25+L24 -> #DIV/0! | M25: =_xlfn.IFS(L25<80%,"A",L25<=95%,"B",L25>95%,"C") -> #DIV/0!
D26: =C26/C$42 -> #DIV/0! | E26: =D26+E25 -> #DIV/0! | F26: =IF(AND(E26<=0),"C",IF(E26<=0.8,"A",IF(E26<=0.95,"B","C"))) -> #DIV/0! | G26: =VLOOKUP(B$22:B$42,I$22:M$42,5,0) -> #N/A | K26: =J26/J$42 -> #DIV/0! | L26: =K26+L25 -> #DIV/0! | M26: =_xlfn.IFS(L26<80%,"A",L26<=95%,"B",L26>95%,"C") -> #DIV/0!
D27: =C27/C$42 -> #DIV/0! | E27: =D27+E26 -> #DIV/0! | F27: =IF(AND(E27<=0),"C",IF(E27<=0.8,"A",IF(E27<=0.95,"B","C"))) -> #DIV/0! | G27: =VLOOKUP(B$22:B$42,I$22:M$42,5,0) -> #N/A | K27: =J27/J$42 -> #DIV/0! | L27: =K27+L26 -> #DIV/0! | M27: =_xlfn.IFS(L27<80%,"A",L27<=95%,"B",L27>95%,"C") -> #DIV/0!
D28: =C28/C$42 -> #DIV/0! | E28: =D28+E27 -> #DIV/0! | F28: =IF(AND(E28<=0),"C",IF(E28<=0.8,"A",IF(E28<=0.95,"B","C"))) -> #DIV/0! | G28: =VLOOKUP(B$22:B$42,I$22:M$42,5,0) -> #N/A | K28: =J28/J$42 -> #DIV/0! | L28: =K28+L27 -> #DIV/0! | M28: =_xlfn.IFS(L28<80%,"A",L28<=95%,"B",L28>95%,"C") -> #DIV/0!
D29: =C29/C$42 -> #DIV/0! | E29: =D29+E28 -> #DIV/0! | F29: =IF(AND(E29<=0),"C",IF(E29<=0.8,"A",IF(E29<=0.95,"B","C"))) -> #DIV/0! | G29: =VLOOKUP(B$22:B$42,I$22:M$42,5,0) -> #N/A | K29: =J29/J$42 -> #DIV/0! | L29: =K29+L28 -> #DIV/0! | M29: =_xlfn.IFS(L29<80%,"A",L29<=95%,"B",L29>95%,"C") -> #DIV/0!
D30: =C30/C$42 -> #DIV/0! | E30: =D30+E29 -> #DIV/0! | F30: =IF(AND(E30<=0),"C",IF(E30<=0.8,"A",IF(E30<=0.95,"B","C"))) -> #DIV/0! | G30: =VLOOKUP(B$22:B$42,I$22:M$42,5,0) -> #N/A | K30: =J30/J$42 -> #DIV/0! | L30: =K30+L29 -> #DIV/0! | M30: =_xlfn.IFS(L30<80%,"A",L30<=95%,"B",L30>95%,"C") -> #DIV/0!
D31: =C31/C$42 -> #DIV/0! | E31: =D31+E30 -> #DIV/0! | F31: =IF(AND(E31<=0),"C",IF(E31<=0.8,"A",IF(E31<=0.95,"B","C"))) -> #DIV/0! | G31: =VLOOKUP(B$22:B$42,I$22:M$42,5,0) -> #N/A | K31: =J31/J$42 -> #DIV/0! | L31: =K31+L30 -> #DIV/0! | M31: =_xlfn.IFS(L31<80%,"A",L31<=95%,"B",L31>95%,"C") -> #DIV/0!
D32: =C32/C$42 -> #DIV/0! | E32: =D32+E31 -> #DIV/0! | F32: =IF(AND(E32<=0),"C",IF(E32<=0.8,"A",IF(E32<=0.95,"B","C"))) -> #DIV/0! | G32: =VLOOKUP(B$22:B$42,I$22:M$42,5,0) -> #N/A | K32: =J32/J$42 -> #DIV/0! | L32: =K32+L31 -> #DIV/0! | M32: =_xlfn.IFS(L32<80%,"A",L32<=95%,"B",L32>95%,"C") -> #DIV/0!
D33: =C33/C$42 -> #DIV/0! | E33: =D33+E32 -> #DIV/0! | F33: =IF(AND(E33<=0),"C",IF(E33<=0.8,"A",IF(E33<=0.95,"B","C"))) -> #DIV/0! | G33: =VLOOKUP(B$22:B$42,I$22:M$42,5,0) -> #N/A | K33: =J33/J$42 -> #DIV/0! | L33: =K33+L32 -> #DIV/0! | M33: =_xlfn.IFS(L33<80%,"A",L33<=95%,"B",L33>95%,"C") -> #DIV/0!
D34: =C34/C$42 -> #DIV/0! | E34: =D34+E33 -> #DIV/0! | F34: =IF(AND(E34<=0),"C",IF(E34<=0.8,"A",IF(E34<=0.95,"B","C"))) -> #DIV/0! | G34: =VLOOKUP(B$22:B$42,I$22:M$42,5,0) -> #N/A | K34: =J34/J$42 -> #DIV/0! | L34: =K34+L33 -> #DIV/0! | M34: =_xlfn.IFS(L34<80%,"A",L34<=95%,"B",L34>95%,"C") -> #DIV/0!
... D41: =C41/C$42 -> #DIV/0! | E41: =D41+E40 -> #DIV/0! | F41: =IF(AND(E41<=0),"C",IF(E41<=0.8,"A",IF(E41<=0.95,"B","C"))) -> #DIV/0! | G41: =VLOOKUP(B$22:B$42,I$22:M$42,5,0) -> #N/A | K41: =J41/J$42 -> #DIV/0! | L41: =K41+L40 -> #DIV/0! | M41: =_xlfn.IFS(L41<80%,"A",L41<=95%,"B",L41>95%,"C") -> #DIV/0!
C42: =SUM(C22:C41) -> 0 | D42: =SUM(D22:D41) -> #DIV/0! | J42: =SUM(J22:J41) -> 0 | K42: =SUM(K22:K41) -> #DIV/0!

Sheet АВС ЯНВАРЬ
B2: ОЧКИ
C3: Прибыль | D3: % прибыль | E3: Доля | F3: ABC прибыль | G3: ABC кол-во | J3: Кол-во | K3: % кол-во | L3: Доля | M3: ABC кол-во
B4: flip жел | C4: =ЯНВАРЬ!AE15 -> 30164.137 | D4: =C4/C$18 -> 0.27352858 | E4: =D4 -> 0.27352858 | F4: =IF(AND(E4<=0),"C",IF(E4<=0.8,"A",IF(E4<=0.95,"B","C"))) -> A | G4: =VLOOKUP(B$4:B$17,I$4:M$17,5,0) -> A | I4: th желт | J4: =ЯНВАРЬ!R11 -> 165 | K4: =J4/J$18 -> 0.31190926 | L4: =K4 -> 0.31190926 | M4: =_xlfn.IFS(L4<80%,"A",L4<=95%,"B",L4>95%,"C") -> A
B5: th желт | C5: =ЯНВАРЬ!AE11 -> 27810.244 | D5: =C5/C$18 -> 0.25218347 | E5: =D5+E4 -> 0.52571205 | F5: =IF(AND(E5<=0),"C",IF(E5<=0.8,"A",IF(E5<=0.95,"B","C"))) -> A | G5: =VLOOKUP(B$4:B$17,I$4:M$17,5,0) -> A | I5: flip жел | J5: =ЯНВАРЬ!R15 -> 161 | K5: =J5/J$18 -> 0.30434783 | L5: =K5+L4 -> 0.61625709 | M5: =_xlfn.IFS(L5<80%,"A",L5<=95%,"B",L5>95%,"C") -> A
B6: qs желтые | C6: =ЯНВАРЬ!AE6 -> 20914.501 | D6: =C6/C$18 -> 0.18965283 | E6: =D6+E5 -> 0.71536488 | F6: =IF(AND(E6<=0),"C",IF(E6<=0.8,"A",IF(E6<=0.95,"B","C"))) -> A | G6: =VLOOKUP(B$4:B$17,I$4:M$17,5,0) -> A | I6: qs желтые | J6: =ЯНВАРЬ!R6 -> 82 | K6: =J6/J$18 -> 0.15500945 | L6: =K6+L5 -> 0.77126654 | M6: =_xlfn.IFS(L6<80%,"A",L6<=95%,"B",L6>95%,"C") -> A
B7: qs черные | C7: =ЯНВАРЬ!AE4 -> 10414.952 | D7: =C7/C$18 -> 0.094442848 | E7: =D7+E6 -> 0.80980772 | F7: =IF(AND(E7<=0),"C",IF(E7<=0.8,"A",IF(E7<=0.95,"B","C"))) -> B | G7: =VLOOKUP(B$4:B$17,I$4:M$17,5,0) -> C | I7: qs коричневые | J7: =ЯНВАРЬ!R7 -> 45 | K7: =J7/J$18 -> 0.085066163 | L7: =K7+L6 -> 0.8563327 | M7: =_xlfn.IFS(L7<80%,"A",L7<=95%,"B",L7>95%,"C") -> B
B8: qs коричневые | C8: =ЯНВАРЬ!AE7 -> 9317.0299 | D8: =C8/C$18 -> 0.084486886 | E8: =D8+E7 -> 0.89429461 | F8: =IF(AND(E8<=0),"C",IF(E8<=0.8,"A",IF(E8<=0.95,"B","C"))) -> B | G8: =VLOOKUP(B$4:B$17,I$4:M$17,5,0) -> B | I8: MR8854 C2 | J8: =ЯНВАРЬ!R8 -> 31 | K8: =J8/J$18 -> 0.058601134 | L8: =K8+L7 -> 0.91493384 | M8: =_xlfn.IFS(L8<80%,"A",L8<=95%,"B",L8>95%,"C") -> B
B9: черные с железкой классика | C9: =ЯНВАРЬ!AE3 -> 6488.9299 | D9: =C9/C$18 -> 0.058841658 | E9: =D9+E8 -> 0.95313627 | F9: =IF(AND(E9<=0),"C",IF(E9<=0.8,"A",IF(E9<=0.95,"B","C"))) -> C | G9: =VLOOKUP(B$4:B$17,I$4:M$17,5,0) -> C | I9: qs черные | J9: =ЯНВАРЬ!R4 -> 19 | K9: =J9/J$18 -> 0.035916824 | L9: =K9+L8 -> 0.95085066 | M9: =_xlfn.IFS(L9<80%,"A",L9<=95%,"B",L9>95%,"C") -> C
B10: qs синие | C10: =ЯНВАРЬ!AE5 -> 4628.4433 | D10: =C10/C$18 -> 0.041970753 | E10: =D10+E9 -> 0.99510702 | F10: =IF(AND(E10<=0),"C",IF(E10<=0.8,"A",IF(E10<=0.95,"B","C"))) -> C | G10: =VLOOKUP(B$4:B$17,I$4:M$17,5,0) -> C | I10: черные с железкой классика | J10: =ЯНВАРЬ!R3 -> 15 | K10: =J10/J$18 -> 0.028355388 | L10: =K10+L9 -> 0.97920605 | M10: =_xlfn.IFS(L10<80%,"A",L10<=95%,"B",L10>95%,"C") -> C
B11: MR8854 C2 | C11: =ЯНВАРЬ!AE8 -> 4052.5984 | D11: =C11/C$18 -> 0.036748988 | E11: =D11+E10 -> 1.031856 | F11: =IF(AND(E11<=0),"C",IF(E11<=0.8,"A",IF(E11<=0.95,"B","C"))) -> C | G11: =VLOOKUP(B$4:B$17,I$4:M$17,5,0) -> B | I11: qs синие | J11: =ЯНВАРЬ!R5 -> 9 | K11: =J11/J$18 -> 0.017013233 | L11: =K11+L10 -> 0.99621928 | M11: =_xlfn.IFS(L11<80%,"A",L11<=95%,"B",L11>95%,"C") -> C
B12: th черн | C12: =ЯНВАРЬ!AE9 -> 284.37054 | D12: =C12/C$18 -> 0.0025786739 | E12: =D12+E5 -> 0.52829072 | F12: =IF(AND(E12<=0),"C",IF(E12<=0.8,"A",IF(E12<=0.95,"B","C"))) -> A | G12: =VLOOKUP(B$4:B$17,I$4:M$17,5,0) -> A | I12: th черн | J12: =ЯНВАРЬ!R9 -> 1 | K12: =J12/J$18 -> 0.0018903592 | L12: =K12+L5 -> 0.61814745 | M12: =_xlfn.IFS(L12<80%,"A",L12<=95%,"B",L12>95%,"C") -> A
B13: flip черный | C13: =ЯНВАРЬ!AE13 -> 207.80595 | D13: =C13/C$18 -> 0.0018843857 | E13: =D13+E12 -> 0.53017511 | F13: =IF(AND(E13<=0),"C",IF(E13<=0.8,"A",IF(E13<=0.95,"B","C"))) -> A | G13: =VLOOKUP(B$4:B$17,I$4:M$17,5,0) -> A | I13: flip черный | J13: =ЯНВАРЬ!R13 -> 1 | K13: =J13/J$18 -> 0.0018903592 | L13: =K13+L12 -> 0.62003781 | M13: =_xlfn.IFS(L13<80%,"A",L13<=95%,"B",L13>95%,"C") -> A
B14: th коричн | C14: =ЯНВАРЬ!AE12 -> -555.84386 | D14: =C14/C$18 -> -0.0050403956 | E14: =D14+E13 -> 0.52513471 | F14: =IF(AND(E14<=0),"C",IF(E14<=0.8,"A",IF(E14<=0.95,"B","C"))) -> A | G14: =VLOOKUP(B$4:B$17,I$4:M$17,5,0) -> A | I14: th син | J14: =ЯНВАРЬ!R10 -> 0 | K14: =J14/J$18 -> 0 | L14: =K14+L13 -> 0.62003781 | M14: =_xlfn.IFS(L14<80%,"A",L14<=95%,"B",L14>95%,"C") -> A
B15: flip синий | C15: =ЯНВАРЬ!AE14 -> -607.06546 | D15: =C15/C$18 -> -0.0055048734 | E15: =D15+E14 -> 0.51962984 | F15: =IF(AND(E15<=0),"C",IF(E15<=0.8,"A",IF(E15<=0.95,"B","C"))) -> A | G15: =VLOOKUP(B$4:B$17,I$4:M$17,5,0) -> A | I15: th коричн | J15: =ЯНВАРЬ!R12 -> 0 | K15: =J15/J$18 -> 0 | L15: =K15+L14 -> 0.62003781 | M15: =_xlfn.IFS(L15<80%,"A",L15<=95%,"B",L15>95%,"C") -> A
B16: flip коричневый | C16: =ЯНВАРЬ!AE16 -> -1324.8447 | D16: =C16/C$18 -> -0.0120137 | E16: =D16+E15 -> 0.50761614 | F16: =IF(AND(E16<=0),"C",IF(E16<=0.8,"A",IF(E16<=0.95,"B","C"))) -> A | G16: =VLOOKUP(B$4:B$17,I$4:M$17,5,0) -> A | I16: flip синий | J16: =ЯНВАРЬ!R14 -> 0 | K16: =J16/J$18 -> 0 | L16: =K16+L15 -> 0.62003781 | M16: =_xlfn.IFS(L16<80%,"A",L16<=95%,"B",L16>95%,"C") -> A
B17: th син | C17: =ЯНВАРЬ!AE10 -> -1517.4339 | D17: =C17/C$18 -> -0.0137601 | E17: =D17+E14 -> 0.51137461 | F17: =IF(AND(E17<=0),"C",IF(E17<=0.8,"A",IF(E17<=0.95,"B","C"))) -> A | G17: =VLOOKUP(B$4:B$17,I$4:M$17,5,0) -> A | I17: flip коричневый | J17: =ЯНВАРЬ!R16 -> 0 | K17: =J17/J$18 -> 0 | L17: =K17+L14 -> 0.62003781 | M17: =_xlfn.IFS(L17<80%,"A",L17<=95%,"B",L17>95%,"C") -> A
C18: =SUM(C4:C17) -> 110277.82 | D18: =SUM(D4:D17) -> 1 | J18: =SUM(J4:J17) -> 529 | K18: =SUM(K4:K17) -> 1
C21: Прибыль | D21: % прибыль | E21: Доля | F21: ABC прибыль | G21: ABC кол-во | J21: Кол-во | K21: % кол-во | L21: Доля | M21: ABC кол-во
D22: =C22/C$42 -> #DIV/0! | E22: =D22 -> #DIV/0! | F22: =IF(AND(E22<=0),"C",IF(E22<=0.8,"A",IF(E22<=0.95,"B","C"))) -> #DIV/0! | G22: =VLOOKUP(B$22:B$42,I$22:M$42,5,0) -> #N/A | K22: =J22/J$42 -> #DIV/0! | L22: =K22 -> #DIV/0! | M22: =_xlfn.IFS(L22<80%,"A",L22<=95%,"B",L22>95%,"C") -> #DIV/0!
D23: =C23/C$42 -> #DIV/0! | E23: =D23+E22 -> #DIV/0! | F23: =IF(AND(E23<=0),"C",IF(E23<=0.8,"A",IF(E23<=0.95,"B","C"))) -> #DIV/0! | G23: =VLOOKUP(B$22:B$42,I$22:M$42,5,0) -> #N/A | K23: =J23/J$42 -> #DIV/0! | L23: =K23+L22 -> #DIV/0! | M23: =_xlfn.IFS(L23<80%,"A",L23<=95%,"B",L23>95%,"C") -> #DIV/0!
D24: =C24/C$42 -> #DIV/0! | E24: =D24+E23 -> #DIV/0! | F24: =IF(AND(E24<=0),"C",IF(E24<=0.8,"A",IF(E24<=0.95,"B","C"))) -> #DIV/0! | G24: =VLOOKUP(B$22:B$42,I$22:M$42,5,0) -> #N/A | K24: =J24/J$42 -> #DIV/0! | L24: =K24+L23 -> #DIV/0! | M24: =_xlfn.IFS(L24<80%,"A",L24<=95%,"B",L24>95%,"C") -> #DIV/0!
D25: =C25/C$42 -> #DIV/0! | E25: =D25+E24 -> #DIV/0! | F25: =IF(AND(E25<=0),"C",IF(E25<=0.8,"A",IF(E25<=0.95,"B","C"))) -> #DIV/0! | G25: =VLOOKUP(B$22:B$42,I$22:M$42,5,0) -> #N/A | K25: =J25/J$42 -> #DIV/0! | L25: =K25+L24 -> #DIV/0! | M25: =_xlfn.IFS(L25<80%,"A",L25<=95%,"B",L25>95%,"C") -> #DIV/0!
D26: =C26/C$42 -> #DIV/0! | E26: =D26+E25 -> #DIV/0! | F26: =IF(AND(E26<=0),"C",IF(E26<=0.8,"A",IF(E26<=0.95,"B","C"))) -> #DIV/0! | G26: =VLOOKUP(B$22:B$42,I$22:M$42,5,0) -> #N/A | K26: =J26/J$42 -> #DIV/0! | L26: =K26+L25 -> #DIV/0! | M26: =_xlfn.IFS(L26<80%,"A",L26<=95%,"B",L26>95%,"C") -> #DIV/0!
D27: =C27/C$42 -> #DIV/0! | E27: =D27+E26 -> #DIV/0! | F27: =IF(AND(E27<=0),"C",IF(E27<=0.8,"A",IF(E27<=0.95,"B","C"))) -> #DIV/0! | G27: =VLOOKUP(B$22:B$42,I$22:M$42,5,0) -> #N/A | K27: =J27/J$42 -> #DIV/0! | L27: =K27+L26 -> #DIV/0! | M27: =_xlfn.IFS(L27<80%,"A",L27<=95%,"B",L27>95%,"C") -> #DIV/0!
D28: =C28/C$42 -> #DIV/0! | E28: =D28+E27 -> #DIV/0! | F28: =IF(AND(E28<=0),"C",IF(E28<=0.8,"A",IF(E28<=0.95,"B","C"))) -> #DIV/0! | G28: =VLOOKUP(B$22:B$42,I$22:M$42,5,0) -> #N/A | K28: =J28/J$42 -> #DIV/0! | L28: =K28+L27 -> #DIV/0! | M28: =_xlfn.IFS(L28<80%,"A",L28<=95%,"B",L28>95%,"C") -> #DIV/0!
D29: =C29/C$42 -> #DIV/0! | E29: =D29+E28 -> #DIV/0! | F29: =IF(AND(E29<=0),"C",IF(E29<=0.8,"A",IF(E29<=0.95,"B","C"))) -> #DIV/0! | G29: =VLOOKUP(B$22:B$42,I$22:M$42,5,0) -> #N/A | K29: =J29/J$42 -> #DIV/0! | L29: =K29+L28 -> #DIV/0! | M29: =_xlfn.IFS(L29<80%,"A",L29<=95%,"B",L29>95%,"C") -> #DIV/0!
D30: =C30/C$42 -> #DIV/0! | E30: =D30+E29 -> #DIV/0! | F30: =IF(AND(E30<=0),"C",IF(E30<=0.8,"A",IF(E30<=0.95,"B","C"))) -> #DIV/0! | G30: =VLOOKUP(B$22:B$42,I$22:M$42,5,0) -> #N/A | K30: =J30/J$42 -> #DIV/0! | L30: =K30+L29 -> #DIV/0! | M30: =_xlfn.IFS(L30<80%,"A",L30<=95%,"B",L30>95%,"C") -> #DIV/0!
D31: =C31/C$42 -> #DIV/0! | E31: =D31+E30 -> #DIV/0! | F31: =IF(AND(E31<=0),"C",IF(E31<=0.8,"A",IF(E31<=0.95,"B","C"))) -> #DIV/0! | G31: =VLOOKUP(B$22:B$42,I$22:M$42,5,0) -> #N/A | K31: =J31/J$42 -> #DIV/0! | L31: =K31+L30 -> #DIV/0! | M31: =_xlfn.IFS(L31<80%,"A",L31<=95%,"B",L31>95%,"C") -> #DIV/0!
D32: =C32/C$42 -> #DIV/0! | E32: =D32+E31 -> #DIV/0! | F32: =IF(AND(E32<=0),"C",IF(E32<=0.8,"A",IF(E32<=0.95,"B","C"))) -> #DIV/0! | G32: =VLOOKUP(B$22:B$42,I$22:M$42,5,0) -> #N/A | K32: =J32/J$42 -> #DIV/0! | L32: =K32+L31 -> #DIV/0! | M32: =_xlfn.IFS(L32<80%,"A",L32<=95%,"B",L32>95%,"C") -> #DIV/0!
D33: =C33/C$42 -> #DIV/0! | E33: =D33+E32 -> #DIV/0! | F33: =IF(AND(E33<=0),"C",IF(E33<=0.8,"A",IF(E33<=0.95,"B","C"))) -> #DIV/0! | G33: =VLOOKUP(B$22:B$42,I$22:M$42,5,0) -> #N/A | K33: =J33/J$42 -> #DIV/0! | L33: =K33+L32 -> #DIV/0! | M33: =_xlfn.IFS(L33<80%,"A",L33<=95%,"B",L33>95%,"C") -> #DIV/0!
D34: =C34/C$42 -> #DIV/0! | E34: =D34+E33 -> #DIV/0! | F34: =IF(AND(E34<=0),"C",IF(E34<=0.8,"A",IF(E34<=0.95,"B","C"))) -> #DIV/0! | G34: =VLOOKUP(B$22:B$42,I$22:M$42,5,0) -> #N/A | K34: =J34/J$42 -> #DIV/0! | L34: =K34+L33 -> #DIV/0! | M34: =_xlfn.IFS(L34<80%,"A",L34<=95%,"B",L34>95%,"C") -> #DIV/0!
... D41: =C41/C$42 -> #DIV/0! | E41: =D41+E40 -> #DIV/0! | F41: =IF(AND(E41<=0),"C",IF(E41<=0.8,"A",IF(E41<=0.95,"B","C"))) -> #DIV/0! | G41: =VLOOKUP(B$22:B$42,I$22:M$42,5,0) -> #N/A | K41: =J41/J$42 -> #DIV/0! | L41: =K41+L40 -> #DIV/0! | M41: =_xlfn.IFS(L41<80%,"A",L41<=95%,"B",L41>95%,"C") -> #DIV/0!
C42: =SUM(C22:C41) -> 0 | D42: =SUM(D22:D41) -> #DIV/0! | J42: =SUM(J22:J41) -> 0 | K42: =SUM(K22:K41) -> #DIV/0!

Sheet АВС 26.01-01.02
B2: ОЧКИ
C3: Прибыль | D3: % прибыль | E3: Доля | F3: ABC прибыль | G3: ABC кол-во | J3: Кол-во | K3: % кол-во | L3: Доля | M3: ABC кол-во
B4: th желт | C4: ='Юнит 26.01-01.02'!AE11 -> 16111.061 | D4: =C4/C$18 -> 0.51770375 | E4: =D4 -> 0.51770375 | F4: =IF(AND(E4<=0),"C",IF(E4<=0.8,"A",IF(E4<=0.95,"B","C"))) -> A | G4: =VLOOKUP(B$4:B$17,I$4:M$17,5,0) -> A | I4: th желт | J4: ='Юнит 26.01-01.02'!R11 -> 48 | K4: =J4/J$18 -> 0.375 | L4: =K4 -> 0.375 | M4: =_xlfn.IFS(L4<80%,"A",L4<=95%,"B",L4>95%,"C") -> A
B5: flip жел | C5: ='Юнит 26.01-01.02'!AE15 -> 11558.881 | D5: =C5/C$18 -> 0.37142657 | E5: =D5+E4 -> 0.88913032 | F5: =IF(AND(E5<=0),"C",IF(E5<=0.8,"A",IF(E5<=0.95,"B","C"))) -> B | G5: =VLOOKUP(B$4:B$17,I$4:M$17,5,0) -> A | I5: flip жел | J5: ='Юнит 26.01-01.02'!R15 -> 38 | K5: =J5/J$18 -> 0.296875 | L5: =K5+L4 -> 0.671875 | M5: =_xlfn.IFS(L5<80%,"A",L5<=95%,"B",L5>95%,"C") -> A
B6: qs черные | C6: ='Юнит 26.01-01.02'!AE4 -> 3322.05 | D6: =C6/C$18 -> 0.10674888 | E6: =D6+E5 -> 0.9958792 | F6: =IF(AND(E6<=0),"C",IF(E6<=0.8,"A",IF(E6<=0.95,"B","C"))) -> C | G6: =VLOOKUP(B$4:B$17,I$4:M$17,5,0) -> C | I6: qs коричневые | J6: ='Юнит 26.01-01.02'!R7 -> 16 | K6: =J6/J$18 -> 0.125 | L6: =K6+L5 -> 0.796875 | M6: =_xlfn.IFS(L6<80%,"A",L6<=95%,"B",L6>95%,"C") -> A
B7: MR8854 C2 | C7: ='Юнит 26.01-01.02'!AE8 -> 1849.5272 | D7: =C7/C$18 -> 0.059431665 | E7: =D7+E6 -> 1.0553109 | F7: =IF(AND(E7<=0),"C",IF(E7<=0.8,"A",IF(E7<=0.95,"B","C"))) -> C | G7: =VLOOKUP(B$4:B$17,I$4:M$17,5,0) -> B | I7: MR8854 C2 | J7: ='Юнит 26.01-01.02'!R8 -> 10 | K7: =J7/J$18 -> 0.078125 | L7: =K7+L6 -> 0.875 | M7: =_xlfn.IFS(L7<80%,"A",L7<=95%,"B",L7>95%,"C") -> B
B8: qs желтые | C8: ='Юнит 26.01-01.02'!AE6 -> 1191.36 | D8: =C8/C$18 -> 0.038282491 | E8: =D8+E7 -> 1.0935934 | F8: =IF(AND(E8<=0),"C",IF(E8<=0.8,"A",IF(E8<=0.95,"B","C"))) -> C | G8: =VLOOKUP(B$4:B$17,I$4:M$17,5,0) -> B | I8: qs желтые | J8: ='Юнит 26.01-01.02'!R6 -> 6 | K8: =J8/J$18 -> 0.046875 | L8: =K8+L7 -> 0.921875 | M8: =_xlfn.IFS(L8<80%,"A",L8<=95%,"B",L8>95%,"C") -> B
B9: th коричн | C9: ='Юнит 26.01-01.02'!AE12 -> 291.34614 | D9: =C9/C$18 -> 0.0093619527 | E9: =D9+E8 -> 1.1029553 | F9: =IF(AND(E9<=0),"C",IF(E9<=0.8,"A",IF(E9<=0.95,"B","C"))) -> C | G9: =VLOOKUP(B$4:B$17,I$4:M$17,5,0) -> A | I9: qs черные | J9: ='Юнит 26.01-01.02'!R4 -> 5 | K9: =J9/J$18 -> 0.0390625 | L9: =K9+L8 -> 0.9609375 | M9: =_xlfn.IFS(L9<80%,"A",L9<=95%,"B",L9>95%,"C") -> C
B10: th черн | C10: ='Юнит 26.01-01.02'!AE9 -> 284.37054 | D10: =C10/C$18 -> 0.0091378028 | E10: =D10+E9 -> 1.1120931 | F10: =IF(AND(E10<=0),"C",IF(E10<=0.8,"A",IF(E10<=0.95,"B","C"))) -> C | G10: =VLOOKUP(B$4:B$17,I$4:M$17,5,0) -> C | I10: черные с железкой классика | J10: ='Юнит 26.01-01.02'!R3 -> 1 | K10: =J10/J$18 -> 0.0078125 | L10: =K10+L9 -> 0.96875 | M10: =_xlfn.IFS(L10<80%,"A",L10<=95%,"B",L10>95%,"C") -> C
B11: flip черный | C11: ='Юнит 26.01-01.02'!AE13 -> 207.80595 | D11: =C11/C$18 -> 0.0066775192 | E11: =D11+E10 -> 1.1187706 | F11: =IF(AND(E11<=0),"C",IF(E11<=0.8,"A",IF(E11<=0.95,"B","C"))) -> C | G11: =VLOOKUP(B$4:B$17,I$4:M$17,5,0) -> A | I11: th черн | J11: ='Юнит 26.01-01.02'!R9 -> 1 | K11: =J11/J$18 -> 0.0078125 | L11: =K11+L10 -> 0.9765625 | M11: =_xlfn.IFS(L11<80%,"A",L11<=95%,"B",L11>95%,"C") -> C
B12: черные с железкой классика | C12: ='Юнит 26.01-01.02'!AE3 -> 152.11 | D12: =C12/C$18 -> 0.004887817 | E12: =D12+E5 -> 0.89401814 | F12: =IF(AND(E12<=0),"C",IF(E12<=0.8,"A",IF(E12<=0.95,"B","C"))) -> B | G12: =VLOOKUP(B$4:B$17,I$4:M$17,5,0) -> C | I12: th син | J12: ='Юнит 26.01-01.02'!R10 -> 1 | K12: =J12/J$18 -> 0.0078125 | L12: =K12+L5 -> 0.6796875 | M12: =_xlfn.IFS(L12<80%,"A",L12<=95%,"B",L12>95%,"C") -> A
B13: qs синие | C13: ='Юнит 26.01-01.02'!AE5 -> 0 | D13: =C13/C$18 -> 0 | E13: =D13+E12 -> 0.89401814 | F13: =IF(AND(E13<=0),"C",IF(E13<=0.8,"A",IF(E13<=0.95,"B","C"))) -> B | G13: =VLOOKUP(B$4:B$17,I$4:M$17,5,0) -> A | I13: th коричн | J13: ='Юнит 26.01-01.02'!R12 -> 1 | K13: =J13/J$18 -> 0.0078125 | L13: =K13+L12 -> 0.6875 | M13: =_xlfn.IFS(L13<80%,"A",L13<=95%,"B",L13>95%,"C") -> A
B14: qs коричневые | C14: ='Юнит 26.01-01.02'!AE7 -> -472.79957 | D14: =C14/C$18 -> -0.015192675 | E14: =D14+E13 -> 0.87882546 | F14: =IF(AND(E14<=0),"C",IF(E14<=0.8,"A",IF(E14<=0.95,"B","C"))) -> B | G14: =VLOOKUP(B$4:B$17,I$4:M$17,5,0) -> A | I14: flip черный | J14: ='Юнит 26.01-01.02'!R13 -> 1 | K14: =J14/J$18 -> 0.0078125 | L14: =K14+L13 -> 0.6953125 | M14: =_xlfn.IFS(L14<80%,"A",L14<=95%,"B",L14>95%,"C") -> A
B15: flip синий | C15: ='Юнит 26.01-01.02'!AE14 -> -807.06546 | D15: =C15/C$18 -> -0.025933786 | E15: =D15+E14 -> 0.85289167 | F15: =IF(AND(E15<=0),"C",IF(E15<=0.8,"A",IF(E15<=0.95,"B","C"))) -> B | G15: =VLOOKUP(B$4:B$17,I$4:M$17,5,0) -> A | I15: qs синие | J15: ='Юнит 26.01-01.02'!R5 -> 0 | K15: =J15/J$18 -> 0 | L15: =K15+L14 -> 0.6953125 | M15: =_xlfn.IFS(L15<80%,"A",L15<=95%,"B",L15>95%,"C") -> A
B16: th син | C16: ='Юнит 26.01-01.02'!AE10 -> -963.6769 | D16: =C16/C$18 -> -0.03096625 | E16: =D16+E15 -> 0.82192542 | F16: =IF(AND(E16<=0),"C",IF(E16<=0.8,"A",IF(E16<=0.95,"B","C"))) -> B | G16: =VLOOKUP(B$4:B$17,I$4:M$17,5,0) -> A | I16: flip синий | J16: ='Юнит 26.01-01.02'!R14 -> 0 | K16: =J16/J$18 -> 0 | L16: =K16+L15 -> 0.6953125 | M16: =_xlfn.IFS(L16<80%,"A",L16<=95%,"B",L16>95%,"C") -> A
B17: flip коричневый | C17: ='Юнит 26.01-01.02'!AE16 -> -1604.7377 | D17: =C17/C$18 -> -0.051565737 | E17: =D17+E14 -> 0.82725972 | F17: =IF(AND(E17<=0),"C",IF(E17<=0.8,"A",IF(E17<=0.95,"B","C"))) -> B | G17: =VLOOKUP(B$4:B$17,I$4:M$17,5,0) -> A | I17: flip коричневый | J17: ='Юнит 26.01-01.02'!R16 -> 0 | K17: =J17/J$18 -> 0 | L17: =K17+L14 -> 0.6953125 | M17: =_xlfn.IFS(L17<80%,"A",L17<=95%,"B",L17>95%,"C") -> A
C18: =SUM(C4:C17) -> 31120.232 | D18: =SUM(D4:D17) -> 1 | J18: =SUM(J4:J17) -> 128 | K18: =SUM(K4:K17) -> 1
C21: Прибыль | D21: % прибыль | E21: Доля | F21: ABC прибыль | G21: ABC кол-во | J21: Кол-во | K21: % кол-во | L21: Доля | M21: ABC кол-во
D22: =C22/C$42 -> #DIV/0! | E22: =D22 -> #DIV/0! | F22: =IF(AND(E22<=0),"C",IF(E22<=0.8,"A",IF(E22<=0.95,"B","C"))) -> #DIV/0! | G22: =VLOOKUP(B$22:B$42,I$22:M$42,5,0) -> #N/A | K22: =J22/J$42 -> #DIV/0! | L22: =K22 -> #DIV/0! | M22: =_xlfn.IFS(L22<80%,"A",L22<=95%,"B",L22>95%,"C") -> #DIV/0!
D23: =C23/C$42 -> #DIV/0! | E23: =D23+E22 -> #DIV/0! | F23: =IF(AND(E23<=0),"C",IF(E23<=0.8,"A",IF(E23<=0.95,"B","C"))) -> #DIV/0! | G23: =VLOOKUP(B$22:B$42,I$22:M$42,5,0) -> #N/A | K23: =J23/J$42 -> #DIV/0! | L23: =K23+L22 -> #DIV/0! | M23: =_xlfn.IFS(L23<80%,"A",L23<=95%,"B",L23>95%,"C") -> #DIV/0!
D24: =C24/C$42 -> #DIV/0! | E24: =D24+E23 -> #DIV/0! | F24: =IF(AND(E24<=0),"C",IF(E24<=0.8,"A",IF(E24<=0.95,"B","C"))) -> #DIV/0! | G24: =VLOOKUP(B$22:B$42,I$22:M$42,5,0) -> #N/A | K24: =J24/J$42 -> #DIV/0! | L24: =K24+L23 -> #DIV/0! | M24: =_xlfn.IFS(L24<80%,"A",L24<=95%,"B",L24>95%,"C") -> #DIV/0!
D25: =C25/C$42 -> #DIV/0! | E25: =D25+E24 -> #DIV/0! | F25: =IF(AND(E25<=0),"C",IF(E25<=0.8,"A",IF(E25<=0.95,"B","C"))) -> #DIV/0! | G25: =VLOOKUP(B$22:B$42,I$22:M$42,5,0) -> #N/A | K25: =J25/J$42 -> #DIV/0! | L25: =K25+L24 -> #DIV/0! | M25: =_xlfn.IFS(L25<80%,"A",L25<=95%,"B",L25>95%,"C") -> #DIV/0!
D26: =C26/C$42 -> #DIV/0! | E26: =D26+E25 -> #DIV/0! | F26: =IF(AND(E26<=0),"C",IF(E26<=0.8,"A",IF(E26<=0.95,"B","C"))) -> #DIV/0! | G26: =VLOOKUP(B$22:B$42,I$22:M$42,5,0) -> #N/A | K26: =J26/J$42 -> #DIV/0! | L26: =K26+L25 -> #DIV/0! | M26: =_xlfn.IFS(L26<80%,"A",L26<=95%,"B",L26>95%,"C") -> #DIV/0!
D27: =C27/C$42 -> #DIV/0! | E27: =D27+E26 -> #DIV/0! | F27: =IF(AND(E27<=0),"C",IF(E27<=0.8,"A",IF(E27<=0.95,"B","C"))) -> #DIV/0! | G27: =VLOOKUP(B$22:B$42,I$22:M$42,5,0) -> #N/A | K27: =J27/J$42 -> #DIV/0! | L27: =K27+L26 -> #DIV/0! | M27: =_xlfn.IFS(L27<80%,"A",L27<=95%,"B",L27>95%,"C") -> #DIV/0!
D28: =C28/C$42 -> #DIV/0! | E28: =D28+E27 -> #DIV/0! | F28: =IF(AND(E28<=0),"C",IF(E28<=0.8,"A",IF(E28<=0.95,"B","C"))) -> #DIV/0! | G28: =VLOOKUP(B$22:B$42,I$22:M$42,5,0) -> #N/A | K28: =J28/J$42 -> #DIV/0! | L28: =K28+L27 -> #DIV/0! | M28: =_xlfn.IFS(L28<80%,"A",L28<=95%,"B",L28>95%,"C") -> #DIV/0!
D29: =C29/C$42 -> #DIV/0! | E29: =D29+E28 -> #DIV/0! | F29: =IF(AND(E29<=0),"C",IF(E29<=0.8,"A",IF(E29<=0.95,"B","C"))) -> #DIV/0! | G29: =VLOOKUP(B$22:B$42,I$22:M$42,5,0) -> #N/A | K29: =J29/J$42 -> #DIV/0! | L29: =K29+L28 -> #DIV/0! | M29: =_xlfn.IFS(L29<80%,"A",L29<=95%,"B",L29>95%,"C") -> #DIV/0!
D30: =C30/C$42 -> #DIV/0! | E30: =D30+E29 -> #DIV/0! | F30: =IF(AND(E30<=0),"C",IF(E30<=0.8,"A",IF(E30<=0.95,"B","C"))) -> #DIV/0! | G30: =VLOOKUP(B$22:B$42,I$22:M$42,5,0) -> #N/A | K30: =J30/J$42 -> #DIV/0! | L30: =K30+L29 -> #DIV/0! | M30: =_xlfn.IFS(L30<80%,"A",L30<=95%,"B",L30>95%,"C") -> #DIV/0!
D31: =C31/C$42 -> #DIV/0! | E31: =D31+E30 -> #DIV/0! | F31: =IF(AND(E31<=0),"C",IF(E31<=0.8,"A",IF(E31<=0.95,"B","C"))) -> #DIV/0! | G31: =VLOOKUP(B$22:B$42,I$22:M$42,5,0) -> #N/A | K31: =J31/J$42 -> #DIV/0! | L31: =K31+L30 -> #DIV/0! | M31: =_xlfn.IFS(L31<80%,"A",L31<=95%,"B",L31>95%,"C") -> #DIV/0!
D32: =C32/C$42 -> #DIV/0! | E32: =D32+E31 -> #DIV/0! | F32: =IF(AND(E32<=0),"C",IF(E32<=0.8,"A",IF(E32<=0.95,"B","C"))) -> #DIV/0! | G32: =VLOOKUP(B$22:B$42,I$22:M$42,5,0) -> #N/A | K32: =J32/J$42 -> #DIV/0! | L32: =K32+L31 -> #DIV/0! | M32: =_xlfn.IFS(L32<80%,"A",L32<=95%,"B",L32>95%,"C") -> #DIV/0!
D33: =C33/C$42 -> #DIV/0! | E33: =D33+E32 -> #DIV/0! | F33: =IF(AND(E33<=0),"C",IF(E33<=0.8,"A",IF(E33<=0.95,"B","C"))) -> #DIV/0! | G33: =VLOOKUP(B$22:B$42,I$22:M$42,5,0) -> #N/A | K33: =J33/J$42 -> #DIV/0! | L33: =K33+L32 -> #DIV/0! | M33: =_xlfn.IFS(L33<80%,"A",L33<=95%,"B",L33>95%,"C") -> #DIV/0!
D34: =C34/C$42 -> #DIV/0! | E34: =D34+E33 -> #DIV/0! | F34: =IF(AND(E34<=0),"C",IF(E34<=0.8,"A",IF(E34<=0.95,"B","C"))) -> #DIV/0! | G34: =VLOOKUP(B$22:B$42,I$22:M$42,5,0) -> #N/A | K34: =J34/J$42 -> #DIV/0! | L34: =K34+L33 -> #DIV/0! | M34: =_xlfn.IFS(L34<80%,"A",L34<=95%,"B",L34>95%,"C") -> #DIV/0!
... D41: =C41/C$42 -> #DIV/0! | E41: =D41+E40 -> #DIV/0! | F41: =IF(AND(E41<=0),"C",IF(E41<=0.8,"A",IF(E41<=0.95,"B","C"))) -> #DIV/0! | G41: =VLOOKUP(B$22:B$42,I$22:M$42,5,0) -> #N/A | K41: =J41/J$42 -> #DIV/0! | L41: =K41+L40 -> #DIV/0! | M41: =_xlfn.IFS(L41<80%,"A",L41<=95%,"B",L41>95%,"C") -> #DIV/0!
C42: =SUM(C22:C41) -> 0 | D42: =SUM(D22:D41) -> #DIV/0! | J42: =SUM(J22:J41) -> 0 | K42: =SUM(K22:K41) -> #DIV/0!

Sheet АВС 19-25.01
B2: ОЧКИ
C3: Прибыль | D3: % прибыль | E3: Доля | F3: ABC прибыль | G3: ABC кол-во | J3: Кол-во | K3: % кол-во | L3: Доля | M3: ABC кол-во
B4: qs желтые | C4: ='Юнит 19-25.01'!AE6 -> 10158.92 | D4: =C4/C$18 -> 0.52787056 | E4: =D4 -> 0.52787056 | F4: =IF(AND(E4<=0),"C",IF(E4<=0.8,"A",IF(E4<=0.95,"B","C"))) -> A | G4: =VLOOKUP(B$4:B$17,I$4:M$17,5,0) -> A | I4: th желт | J4: ='Юнит 19-25.01'!R11 -> 26 | K4: =J4/J$18 -> 0.29213483 | L4: =K4 -> 0.29213483 | M4: =_xlfn.IFS(L4<80%,"A",L4<=95%,"B",L4>95%,"C") -> A
B5: qs черные | C5: ='Юнит 19-25.01'!AE4 -> 4879.4517 | D5: =C5/C$18 -> 0.25354259 | E5: =D5+E4 -> 0.78141315 | F5: =IF(AND(E5<=0),"C",IF(E5<=0.8,"A",IF(E5<=0.95,"B","C"))) -> A | G5: =VLOOKUP(B$4:B$17,I$4:M$17,5,0) -> B | I5: qs желтые | J5: ='Юнит 19-25.01'!R6 -> 18 | K5: =J5/J$18 -> 0.20224719 | L5: =K5+L4 -> 0.49438202 | M5: =_xlfn.IFS(L5<80%,"A",L5<=95%,"B",L5>95%,"C") -> A
B6: черные с железкой классика | C6: ='Юнит 19-25.01'!AE3 -> 3054.91 | D6: =C6/C$18 -> 0.15873706 | E6: =D6+E5 -> 0.94015021 | F6: =IF(AND(E6<=0),"C",IF(E6<=0.8,"A",IF(E6<=0.95,"B","C"))) -> B | G6: =VLOOKUP(B$4:B$17,I$4:M$17,5,0) -> B | I6: flip жел | J6: ='Юнит 19-25.01'!R15 -> 17 | K6: =J6/J$18 -> 0.19101124 | L6: =K6+L5 -> 0.68539326 | M6: =_xlfn.IFS(L6<80%,"A",L6<=95%,"B",L6>95%,"C") -> A
B7: qs синие | C7: ='Юнит 19-25.01'!AE5 -> 2087.12 | D7: =C7/C$18 -> 0.10844944 | E7: =D7+E6 -> 1.0485997 | F7: =IF(AND(E7<=0),"C",IF(E7<=0.8,"A",IF(E7<=0.95,"B","C"))) -> C | G7: =VLOOKUP(B$4:B$17,I$4:M$17,5,0) -> C | I7: qs коричневые | J7: ='Юнит 19-25.01'!R7 -> 10 | K7: =J7/J$18 -> 0.11235955 | L7: =K7+L6 -> 0.79775281 | M7: =_xlfn.IFS(L7<80%,"A",L7<=95%,"B",L7>95%,"C") -> A
B8: qs коричневые | C8: ='Юнит 19-25.01'!AE7 -> 1636.0082 | D8: =C8/C$18 -> 0.085009092 | E8: =D8+E7 -> 1.1336087 | F8: =IF(AND(E8<=0),"C",IF(E8<=0.8,"A",IF(E8<=0.95,"B","C"))) -> C | G8: =VLOOKUP(B$4:B$17,I$4:M$17,5,0) -> A | I8: qs черные | J8: ='Юнит 19-25.01'!R4 -> 7 | K8: =J8/J$18 -> 0.078651685 | L8: =K8+L7 -> 0.87640449 | M8: =_xlfn.IFS(L8<80%,"A",L8<=95%,"B",L8>95%,"C") -> B
B9: th желт | C9: ='Юнит 19-25.01'!AE11 -> 2661.2441 | D9: =C9/C$18 -> 0.13828167 | E9: =D9+E8 -> 1.2718904 | F9: =IF(AND(E9<=0),"C",IF(E9<=0.8,"A",IF(E9<=0.95,"B","C"))) -> C | G9: =VLOOKUP(B$4:B$17,I$4:M$17,5,0) -> A | I9: черные с железкой классика | J9: ='Юнит 19-25.01'!R3 -> 5 | K9: =J9/J$18 -> 0.056179775 | L9: =K9+L8 -> 0.93258427 | M9: =_xlfn.IFS(L9<80%,"A",L9<=95%,"B",L9>95%,"C") -> B
B10: th черн | C10: ='Юнит 19-25.01'!AE9 -> 0 | D10: =C10/C$18 -> 0 | E10: =D10+E9 -> 1.2718904 | F10: =IF(AND(E10<=0),"C",IF(E10<=0.8,"A",IF(E10<=0.95,"B","C"))) -> C | G10: =VLOOKUP(B$4:B$17,I$4:M$17,5,0) -> A | I10: qs синие | J10: ='Юнит 19-25.01'!R5 -> 3 | K10: =J10/J$18 -> 0.033707865 | L10: =K10+L9 -> 0.96629213 | M10: =_xlfn.IFS(L10<80%,"A",L10<=95%,"B",L10>95%,"C") -> C
B11: th син | C11: ='Юнит 19-25.01'!AE10 -> 0 | D11: =C11/C$18 -> 0 | E11: =D11+E10 -> 1.2718904 | F11: =IF(AND(E11<=0),"C",IF(E11<=0.8,"A",IF(E11<=0.95,"B","C"))) -> C | G11: =VLOOKUP(B$4:B$17,I$4:M$17,5,0) -> A | I11: MR8854 C2 | J11: ='Юнит 19-25.01'!R8 -> 3 | K11: =J11/J$18 -> 0.033707865 | L11: =K11+L10 -> 1 | M11: =_xlfn.IFS(L11<80%,"A",L11<=95%,"B",L11>95%,"C") -> C
B12: th коричн | C12: ='Юнит 19-25.01'!AE12 -> 0 | D12: =C12/C$18 -> 0 | E12: =D12+E5 -> 0.78141315 | F12: =IF(AND(E12<=0),"C",IF(E12<=0.8,"A",IF(E12<=0.95,"B","C"))) -> A | G12: =VLOOKUP(B$4:B$17,I$4:M$17,5,0) -> A | I12: th черн | J12: ='Юнит 19-25.01'!R9 -> 0 | K12: =J12/J$18 -> 0 | L12: =K12+L5 -> 0.49438202 | M12: =_xlfn.IFS(L12<80%,"A",L12<=95%,"B",L12>95%,"C") -> A
B13: flip черный | C13: ='Юнит 19-25.01'!AE13 -> 0 | D13: =C13/C$18 -> 0 | E13: =D13+E12 -> 0.78141315 | F13: =IF(AND(E13<=0),"C",IF(E13<=0.8,"A",IF(E13<=0.95,"B","C"))) -> A | G13: =VLOOKUP(B$4:B$17,I$4:M$17,5,0) -> A | I13: th син | J13: ='Юнит 19-25.01'!R10 -> 0 | K13: =J13/J$18 -> 0 | L13: =K13+L12 -> 0.49438202 | M13: =_xlfn.IFS(L13<80%,"A",L13<=95%,"B",L13>95%,"C") -> A
B14: flip синий | C14: ='Юнит 19-25.01'!AE14 -> 0 | D14: =C14/C$18 -> 0 | E14: =D14+E13 -> 0.78141315 | F14: =IF(AND(E14<=0),"C",IF(E14<=0.8,"A",IF(E14<=0.95,"B","C"))) -> A | G14: =VLOOKUP(B$4:B$17,I$4:M$17,5,0) -> A | I14: th коричн | J14: ='Юнит 19-25.01'!R12 -> 0 | K14: =J14/J$18 -> 0 | L14: =K14+L13 -> 0.49438202 | M14: =_xlfn.IFS(L14<80%,"A",L14<=95%,"B",L14>95%,"C") -> A
B15: flip коричневый | C15: ='Юнит 19-25.01'!AE16 -> 0 | D15: =C15/C$18 -> 0 | E15: =D15+E14 -> 0.78141315 | F15: =IF(AND(E15<=0),"C",IF(E15<=0.8,"A",IF(E15<=0.95,"B","C"))) -> A | G15: =VLOOKUP(B$4:B$17,I$4:M$17,5,0) -> A | I15: flip черный | J15: ='Юнит 19-25.01'!R13 -> 0 | K15: =J15/J$18 -> 0 | L15: =K15+L14 -> 0.49438202 | M15: =_xlfn.IFS(L15<80%,"A",L15<=95%,"B",L15>95%,"C") -> A
B16: MR8854 C2 | C16: ='Юнит 19-25.01'!AE8 -> -789.58498 | D16: =C16/C$18 -> -0.041027852 | E16: =D16+E15 -> 0.7403853 | F16: =IF(AND(E16<=0),"C",IF(E16<=0.8,"A",IF(E16<=0.95,"B","C"))) -> A | G16: =VLOOKUP(B$4:B$17,I$4:M$17,5,0) -> C | I16: flip синий | J16: ='Юнит 19-25.01'!R14 -> 0 | K16: =J16/J$18 -> 0 | L16: =K16+L15 -> 0.49438202 | M16: =_xlfn.IFS(L16<80%,"A",L16<=95%,"B",L16>95%,"C") -> A
B17: flip жел | C17: ='Юнит 19-25.01'!AE15 -> -4442.9723 | D17: =C17/C$18 -> -0.23086256 | E17: =D17+E14 -> 0.55055059 | F17: =IF(AND(E17<=0),"C",IF(E17<=0.8,"A",IF(E17<=0.95,"B","C"))) -> A | G17: =VLOOKUP(B$4:B$17,I$4:M$17,5,0) -> A | I17: flip коричневый | J17: ='Юнит 19-25.01'!R16 -> 0 | K17: =J17/J$18 -> 0 | L17: =K17+L14 -> 0.49438202 | M17: =_xlfn.IFS(L17<80%,"A",L17<=95%,"B",L17>95%,"C") -> A
C18: =SUM(C4:C17) -> 19245.097 | D18: =SUM(D4:D17) -> 1 | J18: =SUM(J4:J17) -> 89 | K18: =SUM(K4:K17) -> 1
C21: Прибыль | D21: % прибыль | E21: Доля | F21: ABC прибыль | G21: ABC кол-во | J21: Кол-во | K21: % кол-во | L21: Доля | M21: ABC кол-во
D22: =C22/C$42 -> #DIV/0! | E22: =D22 -> #DIV/0! | F22: =IF(AND(E22<=0),"C",IF(E22<=0.8,"A",IF(E22<=0.95,"B","C"))) -> #DIV/0! | G22: =VLOOKUP(B$22:B$42,I$22:M$42,5,0) -> #N/A | K22: =J22/J$42 -> #DIV/0! | L22: =K22 -> #DIV/0! | M22: =_xlfn.IFS(L22<80%,"A",L22<=95%,"B",L22>95%,"C") -> #DIV/0!
D23: =C23/C$42 -> #DIV/0! | E23: =D23+E22 -> #DIV/0! | F23: =IF(AND(E23<=0),"C",IF(E23<=0.8,"A",IF(E23<=0.95,"B","C"))) -> #DIV/0! | G23: =VLOOKUP(B$22:B$42,I$22:M$42,5,0) -> #N/A | K23: =J23/J$42 -> #DIV/0! | L23: =K23+L22 -> #DIV/0! | M23: =_xlfn.IFS(L23<80%,"A",L23<=95%,"B",L23>95%,"C") -> #DIV/0!
D24: =C24/C$42 -> #DIV/0! | E24: =D24+E23 -> #DIV/0! | F24: =IF(AND(E24<=0),"C",IF(E24<=0.8,"A",IF(E24<=0.95,"B","C"))) -> #DIV/0! | G24: =VLOOKUP(B$22:B$42,I$22:M$42,5,0) -> #N/A | K24: =J24/J$42 -> #DIV/0! | L24: =K24+L23 -> #DIV/0! | M24: =_xlfn.IFS(L24<80%,"A",L24<=95%,"B",L24>95%,"C") -> #DIV/0!
D25: =C25/C$42 -> #DIV/0! | E25: =D25+E24 -> #DIV/0! | F25: =IF(AND(E25<=0),"C",IF(E25<=0.8,"A",IF(E25<=0.95,"B","C"))) -> #DIV/0! | G25: =VLOOKUP(B$22:B$42,I$22:M$42,5,0) -> #N/A | K25: =J25/J$42 -> #DIV/0! | L25: =K25+L24 -> #DIV/0! | M25: =_xlfn.IFS(L25<80%,"A",L25<=95%,"B",L25>95%,"C") -> #DIV/0!
D26: =C26/C$42 -> #DIV/0! | E26: =D26+E25 -> #DIV/0! | F26: =IF(AND(E26<=0),"C",IF(E26<=0.8,"A",IF(E26<=0.95,"B","C"))) -> #DIV/0! | G26: =VLOOKUP(B$22:B$42,I$22:M$42,5,0) -> #N/A | K26: =J26/J$42 -> #DIV/0! | L26: =K26+L25 -> #DIV/0! | M26: =_xlfn.IFS(L26<80%,"A",L26<=95%,"B",L26>95%,"C") -> #DIV/0!
D27: =C27/C$42 -> #DIV/0! | E27: =D27+E26 -> #DIV/0! | F27: =IF(AND(E27<=0),"C",IF(E27<=0.8,"A",IF(E27<=0.95,"B","C"))) -> #DIV/0! | G27: =VLOOKUP(B$22:B$42,I$22:M$42,5,0) -> #N/A | K27: =J27/J$42 -> #DIV/0! | L27: =K27+L26 -> #DIV/0! | M27: =_xlfn.IFS(L27<80%,"A",L27<=95%,"B",L27>95%,"C") -> #DIV/0!
D28: =C28/C$42 -> #DIV/0! | E28: =D28+E27 -> #DIV/0! | F28: =IF(AND(E28<=0),"C",IF(E28<=0.8,"A",IF(E28<=0.95,"B","C"))) -> #DIV/0! | G28: =VLOOKUP(B$22:B$42,I$22:M$42,5,0) -> #N/A | K28: =J28/J$42 -> #DIV/0! | L28: =K28+L27 -> #DIV/0! | M28: =_xlfn.IFS(L28<80%,"A",L28<=95%,"B",L28>95%,"C") -> #DIV/0!
D29: =C29/C$42 -> #DIV/0! | E29: =D29+E28 -> #DIV/0! | F29: =IF(AND(E29<=0),"C",IF(E29<=0.8,"A",IF(E29<=0.95,"B","C"))) -> #DIV/0! | G29: =VLOOKUP(B$22:B$42,I$22:M$42,5,0) -> #N/A | K29: =J29/J$42 -> #DIV/0! | L29: =K29+L28 -> #DIV/0! | M29: =_xlfn.IFS(L29<80%,"A",L29<=95%,"B",L29>95%,"C") -> #DIV/0!
D30: =C30/C$42 -> #DIV/0! | E30: =D30+E29 -> #DIV/0! | F30: =IF(AND(E30<=0),"C",IF(E30<=0.8,"A",IF(E30<=0.95,"B","C"))) -> #DIV/0! | G30: =VLOOKUP(B$22:B$42,I$22:M$42,5,0) -> #N/A | K30: =J30/J$42 -> #DIV/0! | L30: =K30+L29 -> #DIV/0! | M30: =_xlfn.IFS(L30<80%,"A",L30<=95%,"B",L30>95%,"C") -> #DIV/0!
D31: =C31/C$42 -> #DIV/0! | E31: =D31+E30 -> #DIV/0! | F31: =IF(AND(E31<=0),"C",IF(E31<=0.8,"A",IF(E31<=0.95,"B","C"))) -> #DIV/0! | G31: =VLOOKUP(B$22:B$42,I$22:M$42,5,0) -> #N/A | K31: =J31/J$42 -> #DIV/0! | L31: =K31+L30 -> #DIV/0! | M31: =_xlfn.IFS(L31<80%,"A",L31<=95%,"B",L31>95%,"C") -> #DIV/0!
D32: =C32/C$42 -> #DIV/0! | E32: =D32+E31 -> #DIV/0! | F32: =IF(AND(E32<=0),"C",IF(E32<=0.8,"A",IF(E32<=0.95,"B","C"))) -> #DIV/0! | G32: =VLOOKUP(B$22:B$42,I$22:M$42,5,0) -> #N/A | K32: =J32/J$42 -> #DIV/0! | L32: =K32+L31 -> #DIV/0! | M32: =_xlfn.IFS(L32<80%,"A",L32<=95%,"B",L32>95%,"C") -> #DIV/0!
D33: =C33/C$42 -> #DIV/0! | E33: =D33+E32 -> #DIV/0! | F33: =IF(AND(E33<=0),"C",IF(E33<=0.8,"A",IF(E33<=0.95,"B","C"))) -> #DIV/0! | G33: =VLOOKUP(B$22:B$42,I$22:M$42,5,0) -> #N/A | K33: =J33/J$42 -> #DIV/0! | L33: =K33+L32 -> #DIV/0! | M33: =_xlfn.IFS(L33<80%,"A",L33<=95%,"B",L33>95%,"C") -> #DIV/0!
D34: =C34/C$42 -> #DIV/0! | E34: =D34+E33 -> #DIV/0! | F34: =IF(AND(E34<=0),"C",IF(E34<=0.8,"A",IF(E34<=0.95,"B","C"))) -> #DIV/0! | G34: =VLOOKUP(B$22:B$42,I$22:M$42,5,0) -> #N/A | K34: =J34/J$42 -> #DIV/0! | L34: =K34+L33 -> #DIV/0! | M34: =_xlfn.IFS(L34<80%,"A",L34<=95%,"B",L34>95%,"C") -> #DIV/0!
... D41: =C41/C$42 -> #DIV/0! | E41: =D41+E40 -> #DIV/0! | F41: =IF(AND(E41<=0),"C",IF(E41<=0.8,"A",IF(E41<=0.95,"B","C"))) -> #DIV/0! | G41: =VLOOKUP(B$22:B$42,I$22:M$42,5,0) -> #N/A | K41: =J41/J$42 -> #DIV/0! | L41: =K41+L40 -> #DIV/0! | M41: =_xlfn.IFS(L41<80%,"A",L41<=95%,"B",L41>95%,"C") -> #DIV/0!
C42: =SUM(C22:C41) -> 0 | D42: =SUM(D22:D41) -> #DIV/0! | J42: =SUM(J22:J41) -> 0 | K42: =SUM(K22:K41) -> #DIV/0!

Sheet АВС 12-18.01
B2: ОЧКИ
C3: Прибыль | D3: % прибыль | E3: Доля | F3: ABC прибыль | G3: ABC кол-во | J3: Кол-во | K3: % кол-во | L3: Доля | M3: ABC кол-во
B4: flip жел | C4: ='Юнит 12-18.01'!AE15 -> 7845.5265 | D4: =C4/C$18 -> 0.31497995 | E4: =D4 -> 0.31497995 | F4: =IF(AND(E4<=0),"C",IF(E4<=0.8,"A",IF(E4<=0.95,"B","C"))) -> A | G4: =VLOOKUP(B$4:B$17,I$4:M$17,5,0) -> A | I4: flip жел | J4: ='Юнит 12-18.01'!R15 -> 37 | K4: =J4/J$18 -> 0.30833333 | L4: =K4 -> 0.30833333 | M4: =_xlfn.IFS(L4<80%,"A",L4<=95%,"B",L4>95%,"C") -> A
B5: qs желтые | C5: ='Юнит 12-18.01'!AE6 -> 4986.2704 | D5: =C5/C$18 -> 0.20018736 | E5: =D5+E4 -> 0.51516731 | F5: =IF(AND(E5<=0),"C",IF(E5<=0.8,"A",IF(E5<=0.95,"B","C"))) -> A | G5: =VLOOKUP(B$4:B$17,I$4:M$17,5,0) -> A | I5: th желт | J5: ='Юнит 12-18.01'!R11 -> 35 | K5: =J5/J$18 -> 0.29166667 | L5: =K5+L4 -> 0.6 | M5: =_xlfn.IFS(L5<80%,"A",L5<=95%,"B",L5>95%,"C") -> A
B6: qs коричневые | C6: ='Юнит 12-18.01'!AE7 -> 3808.3998 | D6: =C6/C$18 -> 0.15289854 | E6: =D6+E5 -> 0.66806585 | F6: =IF(AND(E6<=0),"C",IF(E6<=0.8,"A",IF(E6<=0.95,"B","C"))) -> A | G6: =VLOOKUP(B$4:B$17,I$4:M$17,5,0) -> B | I6: qs желтые | J6: ='Юнит 12-18.01'!R6 -> 20 | K6: =J6/J$18 -> 0.16666667 | L6: =K6+L5 -> 0.76666667 | M6: =_xlfn.IFS(L6<80%,"A",L6<=95%,"B",L6>95%,"C") -> A
B7: qs синие | C7: ='Юнит 12-18.01'!AE5 -> 2085.4874 | D7: =C7/C$18 -> 0.083727551 | E7: =D7+E6 -> 0.7517934 | F7: =IF(AND(E7<=0),"C",IF(E7<=0.8,"A",IF(E7<=0.95,"B","C"))) -> A | G7: =VLOOKUP(B$4:B$17,I$4:M$17,5,0) -> C | I7: qs коричневые | J7: ='Юнит 12-18.01'!R7 -> 10 | K7: =J7/J$18 -> 0.083333333 | L7: =K7+L6 -> 0.85 | M7: =_xlfn.IFS(L7<80%,"A",L7<=95%,"B",L7>95%,"C") -> B
B8: черные с железкой классика | C8: ='Юнит 12-18.01'!AE3 -> 1162.1223 | D8: =C8/C$18 -> 0.046656555 | E8: =D8+E7 -> 0.79844996 | F8: =IF(AND(E8<=0),"C",IF(E8<=0.8,"A",IF(E8<=0.95,"B","C"))) -> A | G8: =VLOOKUP(B$4:B$17,I$4:M$17,5,0) -> C | I8: MR8854 C2 | J8: ='Юнит 12-18.01'!R8 -> 7 | K8: =J8/J$18 -> 0.058333333 | L8: =K8+L7 -> 0.90833333 | M8: =_xlfn.IFS(L8<80%,"A",L8<=95%,"B",L8>95%,"C") -> B
B9: th желт | C9: ='Юнит 12-18.01'!AE11 -> 3663.4074 | D9: =C9/C$18 -> 0.14707743 | E9: =D9+E8 -> 0.94552739 | F9: =IF(AND(E9<=0),"C",IF(E9<=0.8,"A",IF(E9<=0.95,"B","C"))) -> B | G9: =VLOOKUP(B$4:B$17,I$4:M$17,5,0) -> A | I9: qs черные | J9: ='Юнит 12-18.01'!R4 -> 4 | K9: =J9/J$18 -> 0.033333333 | L9: =K9+L8 -> 0.94166667 | M9: =_xlfn.IFS(L9<80%,"A",L9<=95%,"B",L9>95%,"C") -> B
B10: qs черные | C10: ='Юнит 12-18.01'!AE4 -> 745.60927 | D10: =C10/C$18 -> 0.029934507 | E10: =D10+E9 -> 0.9754619 | F10: =IF(AND(E10<=0),"C",IF(E10<=0.8,"A",IF(E10<=0.95,"B","C"))) -> C | G10: =VLOOKUP(B$4:B$17,I$4:M$17,5,0) -> B | I10: qs синие | J10: ='Юнит 12-18.01'!R5 -> 4 | K10: =J10/J$18 -> 0.033333333 | L10: =K10+L9 -> 0.975 | M10: =_xlfn.IFS(L10<80%,"A",L10<=95%,"B",L10>95%,"C") -> C
B11: MR8854 C2 | C11: ='Юнит 12-18.01'!AE8 -> 611.19557 | D11: =C11/C$18 -> 0.024538105 | E11: =D11+E10 -> 1 | F11: =IF(AND(E11<=0),"C",IF(E11<=0.8,"A",IF(E11<=0.95,"B","C"))) -> C | G11: =VLOOKUP(B$4:B$17,I$4:M$17,5,0) -> B | I11: черные с железкой классика | J11: ='Юнит 12-18.01'!R3 -> 3 | K11: =J11/J$18 -> 0.025 | L11: =K11+L10 -> 1 | M11: =_xlfn.IFS(L11<80%,"A",L11<=95%,"B",L11>95%,"C") -> C
B12: th черн | C12: ='Юнит 12-18.01'!AE9 -> 0 | D12: =C12/C$18 -> 0 | E12: =D12+E5 -> 0.51516731 | F12: =IF(AND(E12<=0),"C",IF(E12<=0.8,"A",IF(E12<=0.95,"B","C"))) -> A | G12: =VLOOKUP(B$4:B$17,I$4:M$17,5,0) -> A | I12: th черн | J12: ='Юнит 12-18.01'!R9 -> 0 | K12: =J12/J$18 -> 0 | L12: =K12+L5 -> 0.6 | M12: =_xlfn.IFS(L12<80%,"A",L12<=95%,"B",L12>95%,"C") -> A
B13: th син | C13: ='Юнит 12-18.01'!AE10 -> 0 | D13: =C13/C$18 -> 0 | E13: =D13+E12 -> 0.51516731 | F13: =IF(AND(E13<=0),"C",IF(E13<=0.8,"A",IF(E13<=0.95,"B","C"))) -> A | G13: =VLOOKUP(B$4:B$17,I$4:M$17,5,0) -> A | I13: th син | J13: ='Юнит 12-18.01'!R10 -> 0 | K13: =J13/J$18 -> 0 | L13: =K13+L12 -> 0.6 | M13: =_xlfn.IFS(L13<80%,"A",L13<=95%,"B",L13>95%,"C") -> A
B14: th коричн | C14: ='Юнит 12-18.01'!AE12 -> 0 | D14: =C14/C$18 -> 0 | E14: =D14+E13 -> 0.51516731 | F14: =IF(AND(E14<=0),"C",IF(E14<=0.8,"A",IF(E14<=0.95,"B","C"))) -> A | G14: =VLOOKUP(B$4:B$17,I$4:M$17,5,0) -> A | I14: th коричн | J14: ='Юнит 12-18.01'!R12 -> 0 | K14: =J14/J$18 -> 0 | L14: =K14+L13 -> 0.6 | M14: =_xlfn.IFS(L14<80%,"A",L14<=95%,"B",L14>95%,"C") -> A
B15: flip черный | C15: ='Юнит 12-18.01'!AE13 -> 0 | D15: =C15/C$18 -> 0 | E15: =D15+E14 -> 0.51516731 | F15: =IF(AND(E15<=0),"C",IF(E15<=0.8,"A",IF(E15<=0.95,"B","C"))) -> A | G15: =VLOOKUP(B$4:B$17,I$4:M$17,5,0) -> A | I15: flip черный | J15: ='Юнит 12-18.01'!R13 -> 0 | K15: =J15/J$18 -> 0 | L15: =K15+L14 -> 0.6 | M15: =_xlfn.IFS(L15<80%,"A",L15<=95%,"B",L15>95%,"C") -> A
B16: flip синий | C16: ='Юнит 12-18.01'!AE14 -> 0 | D16: =C16/C$18 -> 0 | E16: =D16+E15 -> 0.51516731 | F16: =IF(AND(E16<=0),"C",IF(E16<=0.8,"A",IF(E16<=0.95,"B","C"))) -> A | G16: =VLOOKUP(B$4:B$17,I$4:M$17,5,0) -> A | I16: flip синий | J16: ='Юнит 12-18.01'!R14 -> 0 | K16: =J16/J$18 -> 0 | L16: =K16+L15 -> 0.6 | M16: =_xlfn.IFS(L16<80%,"A",L16<=95%,"B",L16>95%,"C") -> A
B17: flip коричневый | C17: ='Юнит 12-18.01'!AE16 -> 0 | D17: =C17/C$18 -> 0 | E17: =D17+E14 -> 0.51516731 | F17: =IF(AND(E17<=0),"C",IF(E17<=0.8,"A",IF(E17<=0.95,"B","C"))) -> A | G17: =VLOOKUP(B$4:B$17,I$4:M$17,5,0) -> A | I17: flip коричневый | J17: ='Юнит 12-18.01'!R16 -> 0 | K17: =J17/J$18 -> 0 | L17: =K17+L14 -> 0.6 | M17: =_xlfn.IFS(L17<80%,"A",L17<=95%,"B",L17>95%,"C") -> A
C18: =SUM(C4:C17) -> 24908.019 | D18: =SUM(D4:D17) -> 1 | J18: =SUM(J4:J17) -> 120 | K18: =SUM(K4:K17) -> 1
C21: Прибыль | D21: % прибыль | E21: Доля | F21: ABC прибыль | G21: ABC кол-во | J21: Кол-во | K21: % кол-во | L21: Доля | M21: ABC кол-во
D22: =C22/C$42 -> #DIV/0! | E22: =D22 -> #DIV/0! | F22: =IF(AND(E22<=0),"C",IF(E22<=0.8,"A",IF(E22<=0.95,"B","C"))) -> #DIV/0! | G22: =VLOOKUP(B$22:B$42,I$22:M$42,5,0) -> #N/A | K22: =J22/J$42 -> #DIV/0! | L22: =K22 -> #DIV/0! | M22: =_xlfn.IFS(L22<80%,"A",L22<=95%,"B",L22>95%,"C") -> #DIV/0!
D23: =C23/C$42 -> #DIV/0! | E23: =D23+E22 -> #DIV/0! | F23: =IF(AND(E23<=0),"C",IF(E23<=0.8,"A",IF(E23<=0.95,"B","C"))) -> #DIV/0! | G23: =VLOOKUP(B$22:B$42,I$22:M$42,5,0) -> #N/A | K23: =J23/J$42 -> #DIV/0! | L23: =K23+L22 -> #DIV/0! | M23: =_xlfn.IFS(L23<80%,"A",L23<=95%,"B",L23>95%,"C") -> #DIV/0!
D24: =C24/C$42 -> #DIV/0! | E24: =D24+E23 -> #DIV/0! | F24: =IF(AND(E24<=0),"C",IF(E24<=0.8,"A",IF(E24<=0.95,"B","C"))) -> #DIV/0! | G24: =VLOOKUP(B$22:B$42,I$22:M$42,5,0) -> #N/A | K24: =J24/J$42 -> #DIV/0! | L24: =K24+L23 -> #DIV/0! | M24: =_xlfn.IFS(L24<80%,"A",L24<=95%,"B",L24>95%,"C") -> #DIV/0!
D25: =C25/C$42 -> #DIV/0! | E25: =D25+E24 -> #DIV/0! | F25: =IF(AND(E25<=0),"C",IF(E25<=0.8,"A",IF(E25<=0.95,"B","C"))) -> #DIV/0! | G25: =VLOOKUP(B$22:B$42,I$22:M$42,5,0) -> #N/A | K25: =J25/J$42 -> #DIV/0! | L25: =K25+L24 -> #DIV/0! | M25: =_xlfn.IFS(L25<80%,"A",L25<=95%,"B",L25>95%,"C") -> #DIV/0!
D26: =C26/C$42 -> #DIV/0! | E26: =D26+E25 -> #DIV/0! | F26: =IF(AND(E26<=0),"C",IF(E26<=0.8,"A",IF(E26<=0.95,"B","C"))) -> #DIV/0! | G26: =VLOOKUP(B$22:B$42,I$22:M$42,5,0) -> #N/A | K26: =J26/J$42 -> #DIV/0! | L26: =K26+L25 -> #DIV/0! | M26: =_xlfn.IFS(L26<80%,"A",L26<=95%,"B",L26>95%,"C") -> #DIV/0!
D27: =C27/C$42 -> #DIV/0! | E27: =D27+E26 -> #DIV/0! | F27: =IF(AND(E27<=0),"C",IF(E27<=0.8,"A",IF(E27<=0.95,"B","C"))) -> #DIV/0! | G27: =VLOOKUP(B$22:B$42,I$22:M$42,5,0) -> #N/A | K27: =J27/J$42 -> #DIV/0! | L27: =K27+L26 -> #DIV/0! | M27: =_xlfn.IFS(L27<80%,"A",L27<=95%,"B",L27>95%,"C") -> #DIV/0!
D28: =C28/C$42 -> #DIV/0! | E28: =D28+E27 -> #DIV/0! | F28: =IF(AND(E28<=0),"C",IF(E28<=0.8,"A",IF(E28<=0.95,"B","C"))) -> #DIV/0! | G28: =VLOOKUP(B$22:B$42,I$22:M$42,5,0) -> #N/A | K28: =J28/J$42 -> #DIV/0! | L28: =K28+L27 -> #DIV/0! | M28: =_xlfn.IFS(L28<80%,"A",L28<=95%,"B",L28>95%,"C") -> #DIV/0!
D29: =C29/C$42 -> #DIV/0! | E29: =D29+E28 -> #DIV/0! | F29: =IF(AND(E29<=0),"C",IF(E29<=0.8,"A",IF(E29<=0.95,"B","C"))) -> #DIV/0! | G29: =VLOOKUP(B$22:B$42,I$22:M$42,5,0) -> #N/A | K29: =J29/J$42 -> #DIV/0! | L29: =K29+L28 -> #DIV/0! | M29: =_xlfn.IFS(L29<80%,"A",L29<=95%,"B",L29>95%,"C") -> #DIV/0!
D30: =C30/C$42 -> #DIV/0! | E30: =D30+E29 -> #DIV/0! | F30: =IF(AND(E30<=0),"C",IF(E30<=0.8,"A",IF(E30<=0.95,"B","C"))) -> #DIV/0! | G30: =VLOOKUP(B$22:B$42,I$22:M$42,5,0) -> #N/A | K30: =J30/J$42 -> #DIV/0! | L30: =K30+L29 -> #DIV/0! | M30: =_xlfn.IFS(L30<80%,"A",L30<=95%,"B",L30>95%,"C") -> #DIV/0!
D31: =C31/C$42 -> #DIV/0! | E31: =D31+E30 -> #DIV/0! | F31: =IF(AND(E31<=0),"C",IF(E31<=0.8,"A",IF(E31<=0.95,"B","C"))) -> #DIV/0! | G31: =VLOOKUP(B$22:B$42,I$22:M$42,5,0) -> #N/A | K31: =J31/J$42 -> #DIV/0! | L31: =K31+L30 -> #DIV/0! | M31: =_xlfn.IFS(L31<80%,"A",L31<=95%,"B",L31>95%,"C") -> #DIV/0!
D32: =C32/C$42 -> #DIV/0! | E32: =D32+E31 -> #DIV/0! | F32: =IF(AND(E32<=0),"C",IF(E32<=0.8,"A",IF(E32<=0.95,"B","C"))) -> #DIV/0! | G32: =VLOOKUP(B$22:B$42,I$22:M$42,5,0) -> #N/A | K32: =J32/J$42 -> #DIV/0! | L32: =K32+L31 -> #DIV/0! | M32: =_xlfn.IFS(L32<80%,"A",L32<=95%,"B",L32>95%,"C") -> #DIV/0!
D33: =C33/C$42 -> #DIV/0! | E33: =D33+E32 -> #DIV/0! | F33: =IF(AND(E33<=0),"C",IF(E33<=0.8,"A",IF(E33<=0.95,"B","C"))) -> #DIV/0! | G33: =VLOOKUP(B$22:B$42,I$22:M$42,5,0) -> #N/A | K33: =J33/J$42 -> #DIV/0! | L33: =K33+L32 -> #DIV/0! | M33: =_xlfn.IFS(L33<80%,"A",L33<=95%,"B",L33>95%,"C") -> #DIV/0!
D34: =C34/C$42 -> #DIV/0! | E34: =D34+E33 -> #DIV/0! | F34: =IF(AND(E34<=0),"C",IF(E34<=0.8,"A",IF(E34<=0.95,"B","C"))) -> #DIV/0! | G34: =VLOOKUP(B$22:B$42,I$22:M$42,5,0) -> #N/A | K34: =J34/J$42 -> #DIV/0! | L34: =K34+L33 -> #DIV/0! | M34: =_xlfn.IFS(L34<80%,"A",L34<=95%,"B",L34>95%,"C") -> #DIV/0!
... D41: =C41/C$42 -> #DIV/0! | E41: =D41+E40 -> #DIV/0! | F41: =IF(AND(E41<=0),"C",IF(E41<=0.8,"A",IF(E41<=0.95,"B","C"))) -> #DIV/0! | G41: =VLOOKUP(B$22:B$42,I$22:M$42,5,0) -> #N/A | K41: =J41/J$42 -> #DIV/0! | L41: =K41+L40 -> #DIV/0! | M41: =_xlfn.IFS(L41<80%,"A",L41<=95%,"B",L41>95%,"C") -> #DIV/0!
C42: =SUM(C22:C41) -> 0 | D42: =SUM(D22:D41) -> #DIV/0! | J42: =SUM(J22:J41) -> 0 | K42: =SUM(K22:K41) -> #DIV/0!

Sheet АВС 05-11.01
B2: ОЧКИ
C3: Прибыль | D3: % прибыль | E3: Доля | F3: ABC прибыль | G3: ABC кол-во | J3: Кол-во | K3: % кол-во | L3: Доля | M3: ABC кол-во
B4: th желт | C4: ='Юнит 05-11.01'!AE11 -> 14577.679 | D4: =C4/C$18 -> 0.32994497 | E4: =D4 -> 0.32994497 | F4: =IF(AND(E4<=0),"C",IF(E4<=0.8,"A",IF(E4<=0.95,"B","C"))) -> A | G4: =VLOOKUP(B$4:B$17,I$4:M$17,5,0) -> A | I4: th желт | J4: ='Юнит 05-11.01'!R11 -> 52 | K4: =J4/J$18 -> 0.325 | L4: =K4 -> 0.325 | M4: =_xlfn.IFS(L4<80%,"A",L4<=95%,"B",L4>95%,"C") -> A
B5: flip жел | C5: ='Юнит 05-11.01'!AE15 -> 13681.243 | D5: =C5/C$18 -> 0.3096554 | E5: =D5+E4 -> 0.63960037 | F5: =IF(AND(E5<=0),"C",IF(E5<=0.8,"A",IF(E5<=0.95,"B","C"))) -> A | G5: =VLOOKUP(B$4:B$17,I$4:M$17,5,0) -> A | I5: flip жел | J5: ='Юнит 05-11.01'!R15 -> 49 | K5: =J5/J$18 -> 0.30625 | L5: =K5+L4 -> 0.63125 | M5: =_xlfn.IFS(L5<80%,"A",L5<=95%,"B",L5>95%,"C") -> A
B6: qs желтые | C6: ='Юнит 05-11.01'!AE6 -> 6919.0166 | D6: =C6/C$18 -> 0.15660207 | E6: =D6+E5 -> 0.79620244 | F6: =IF(AND(E6<=0),"C",IF(E6<=0.8,"A",IF(E6<=0.95,"B","C"))) -> A | G6: =VLOOKUP(B$4:B$17,I$4:M$17,5,0) -> B | I6: qs желтые | J6: ='Юнит 05-11.01'!R6 -> 31 | K6: =J6/J$18 -> 0.19375 | L6: =K6+L5 -> 0.825 | M6: =_xlfn.IFS(L6<80%,"A",L6<=95%,"B",L6>95%,"C") -> B
B7: qs коричневые | C7: ='Юнит 05-11.01'!AE7 -> 2667.2832 | D7: =C7/C$18 -> 0.060370149 | E7: =D7+E6 -> 0.85657259 | F7: =IF(AND(E7<=0),"C",IF(E7<=0.8,"A",IF(E7<=0.95,"B","C"))) -> B | G7: =VLOOKUP(B$4:B$17,I$4:M$17,5,0) -> B | I7: MR8854 C2 | J7: ='Юнит 05-11.01'!R8 -> 10 | K7: =J7/J$18 -> 0.0625 | L7: =K7+L6 -> 0.8875 | M7: =_xlfn.IFS(L7<80%,"A",L7<=95%,"B",L7>95%,"C") -> B
B8: MR8854 C2 | C8: ='Юнит 05-11.01'!AE8 -> 2517.3576 | D8: =C8/C$18 -> 0.056976798 | E8: =D8+E7 -> 0.91354939 | F8: =IF(AND(E8<=0),"C",IF(E8<=0.8,"A",IF(E8<=0.95,"B","C"))) -> B | G8: =VLOOKUP(B$4:B$17,I$4:M$17,5,0) -> B | I8: qs коричневые | J8: ='Юнит 05-11.01'!R7 -> 8 | K8: =J8/J$18 -> 0.05 | L8: =K8+L7 -> 0.9375 | M8: =_xlfn.IFS(L8<80%,"A",L8<=95%,"B",L8>95%,"C") -> B
B9: черные с железкой классика | C9: ='Юнит 05-11.01'!AE3 -> 1842.5976 | D9: =C9/C$18 -> 0.041704567 | E9: =D9+E8 -> 0.95525396 | F9: =IF(AND(E9<=0),"C",IF(E9<=0.8,"A",IF(E9<=0.95,"B","C"))) -> C | G9: =VLOOKUP(B$4:B$17,I$4:M$17,5,0) -> C | I9: черные с железкой классика | J9: ='Юнит 05-11.01'!R3 -> 5 | K9: =J9/J$18 -> 0.03125 | L9: =K9+L8 -> 0.96875 | M9: =_xlfn.IFS(L9<80%,"A",L9<=95%,"B",L9>95%,"C") -> C
B10: qs черные | C10: ='Юнит 05-11.01'!AE4 -> 1521.1407 | D10: =C10/C$18 -> 0.034428849 | E10: =D10+E9 -> 0.98968281 | F10: =IF(AND(E10<=0),"C",IF(E10<=0.8,"A",IF(E10<=0.95,"B","C"))) -> C | G10: =VLOOKUP(B$4:B$17,I$4:M$17,5,0) -> C | I10: qs черные | J10: ='Юнит 05-11.01'!R4 -> 3 | K10: =J10/J$18 -> 0.01875 | L10: =K10+L9 -> 0.9875 | M10: =_xlfn.IFS(L10<80%,"A",L10<=95%,"B",L10>95%,"C") -> C
B11: qs синие | C11: ='Юнит 05-11.01'!AE5 -> 455.83588 | D11: =C11/C$18 -> 0.010317195 | E11: =D11+E10 -> 1 | F11: =IF(AND(E11<=0),"C",IF(E11<=0.8,"A",IF(E11<=0.95,"B","C"))) -> C | G11: =VLOOKUP(B$4:B$17,I$4:M$17,5,0) -> C | I11: qs синие | J11: ='Юнит 05-11.01'!R5 -> 2 | K11: =J11/J$18 -> 0.0125 | L11: =K11+L10 -> 1 | M11: =_xlfn.IFS(L11<80%,"A",L11<=95%,"B",L11>95%,"C") -> C
B12: th черн | C12: ='Юнит 05-11.01'!AE9 -> 0 | D12: =C12/C$18 -> 0 | E12: =D12+E5 -> 0.63960037 | F12: =IF(AND(E12<=0),"C",IF(E12<=0.8,"A",IF(E12<=0.95,"B","C"))) -> A | G12: =VLOOKUP(B$4:B$17,I$4:M$17,5,0) -> A | I12: th черн | J12: ='Юнит 05-11.01'!R9 -> 0 | K12: =J12/J$18 -> 0 | L12: =K12+L5 -> 0.63125 | M12: =_xlfn.IFS(L12<80%,"A",L12<=95%,"B",L12>95%,"C") -> A
B13: th син | C13: ='Юнит 05-11.01'!AE10 -> 0 | D13: =C13/C$18 -> 0 | E13: =D13+E12 -> 0.63960037 | F13: =IF(AND(E13<=0),"C",IF(E13<=0.8,"A",IF(E13<=0.95,"B","C"))) -> A | G13: =VLOOKUP(B$4:B$17,I$4:M$17,5,0) -> A | I13: th син | J13: ='Юнит 05-11.01'!R10 -> 0 | K13: =J13/J$18 -> 0 | L13: =K13+L12 -> 0.63125 | M13: =_xlfn.IFS(L13<80%,"A",L13<=95%,"B",L13>95%,"C") -> A
