Workbook

Sheet Сводная
A1: Период | D1: Итого к перечислению на счет, руб | E1: шт. | H1: Выручка | K1: Себестоимость продаж | L1: Логистика | M1: Комиссия | N1: Хранение | O1: Платная приемка | P1: Штрафы | Q1: Реклама Ozon | R1: Услуги партнёров | S1: Другие услуги и штрафы | T1: Услуги FBO | U1: Компенсировано | V1: Пополнение рекламного кабинета | W1: ЕАЭС | X1: Налог | Y1: Прибыль до вычета налогов | Z1: Прибыль после вычета налогов | AA1: Итог месяц | AB1: % Cебестоимости | AC1: Маржинальность, % | AD1: Рентабельность, % | AE1: Доля рекламы, %
A2: Месяц | B2: Даты | C2: Нед | E2: Заказы | F2: Продажи | G2: Возвраты | H2: Продажи | I2: Возвраты | J2: Общая
A3: Декабрь | B3: 29-31.12 | C3: 1 | D3: =J3-SUM(L3:T3)+U3+V3 -> 36605.68 | E3: ='Юнит 29-31.12'!K$24 -> 53 | F3: ='Юнит 29-31.12'!P$24 -> 90 | G3: ='Юнит 29-31.12'!Q$24 -> 3 | H3: ='Юнит 29-31.12'!S$24 -> 146316 | I3: ='Юнит 29-31.12'!T$24 -> -4863 | J3: =H3+I3 -> 141453 | K3: ='Юнит 29-31.12'!W$24 -> 10769.4 | L3: ='Юнит 29-31.12'!Z$24 -> 13464.42 | M3: ='Юнит 29-31.12'!X$24 -> 60824.79 | Q3: ='Юнит 29-31.12'!AA$24 -> 26762.42 | R3: 1624.89 | T3: 2170.8 | Y3: =J3-SUM(L3:T3)-K3-V3+U3+W3 -> 25836.28 | Z3: =Y3-X3 -> 25836.28
A4: Январь | B4: 01-04.01 | C4: 1 | D4: =J4-SUM(L4:T4)+U4+V4 -> 1074.71 | E4: ='Юнит 01-04.01'!K$24 -> 122 | F4: ='Юнит 01-04.01'!P$24 -> 51 | G4: ='Юнит 01-04.01'!Q$24 -> 1 | H4: ='Юнит 01-04.01'!S$24 -> 85937 | I4: ='Юнит 01-04.01'!T$24 -> -1600 | J4: =H4+I4 -> 84337 | K4: ='Юнит 01-04.01'!W$24 -> 6252.96 | L4: ='Юнит 01-04.01'!Z$24 -> 8548.62 | M4: ='Юнит 01-04.01'!X$24 -> 36264.91 | Q4: ='Юнит 01-04.01'!AA$24 -> 36772.95 | R4: 1675.81 | W4: 5252 | X4: =3481.9416*J4/SUM($J$4:$J$8) -> 322.35231 | Y4: =J4-SUM(L4:T4)-K4-V4+U4+W4 -> 73.75 | Z4: =Y4-X4 -> -248.60231 | AA4: =SUM(Z4:Z8) -> 49559.258 | AB4: =K4/J4 -> 0.074142547 | AC4: =Z4/K4 -> -0.039757541 | AD4: =Z4/J4 -> -0.0029477253 | AE4: =Q4/J4 -> 0.43602393
B5: 05-11.01 | C5: 2 | D5: =J5-SUM(L5:T5)+U5+V5 -> 57707.57 | E5: ='Юнит 05-11.01'!K$24 -> 183 | F5: ='Юнит 05-11.01'!P$24 -> 168 | G5: ='Юнит 05-11.01'!Q$24 -> 8 | H5: ='Юнит 05-11.01'!S$24 -> 277715 | I5: ='Юнит 05-11.01'!T$24 -> -13822 | J5: =H5+I5 -> 263893 | K5: ='Юнит 05-11.01'!W$24 -> 20205.96 | L5: ='Юнит 05-11.01'!Z$24 -> 28076.33 | M5: ='Юнит 05-11.01'!X$24 -> 113473.99 | Q5: ='Юнит 05-11.01'!AA$24 -> 56365.38 | R5: 4144.33 | S5: 75 | T5: 4050.4 | X5: =3481.9416*J5/SUM($J$4:$J$8) -> 1008.65 | Y5: =J5-SUM(L5:T5)-K5-V5+U5+W5 -> 37501.61 | Z5: =Y5-X5 -> 36492.96 | AB5: =K5/J5 -> 0.076568761 | AC5: =Z5/K5 -> 1.8060493 | AD5: =Z5/J5 -> 0.13828696 | AE5: =Q5/J5 -> 0.2135918
B6: 12-18.01 | C6: 3 | D6: =J6-SUM(L6:T6)+U6+V6 -> 36064.15 | E6: ='Юнит 12-18.01'!K$24 -> 144 | F6: ='Юнит 12-18.01'!P$24 -> 122 | G6: ='Юнит 12-18.01'!Q$24 -> 2 | H6: ='Юнит 12-18.01'!S$24 -> 211029 | I6: ='Юнит 12-18.01'!T$24 -> -3221 | J6: =H6+I6 -> 207808 | K6: ='Юнит 12-18.01'!W$24 -> 15093.09 | L6: ='Юнит 12-18.01'!Z$24 -> 24172.28 | M6: ='Юнит 12-18.01'!X$24 -> 89357.44 | Q6: ='Юнит 12-18.01'!AA$24 -> 53249.12 | R6: 4025.01 | S6: 0 | T6: 940 | W6: 5135 | X6: =3481.9416*J6/SUM($J$4:$J$8) -> 794.28233 | Y6: =J6-SUM(L6:T6)-K6-V6+U6+W6 -> 26106.06 | Z6: =Y6-X6 -> 25311.778 | AB6: =K6/J6 -> 0.072629976 | AC6: =Z6/K6 -> 1.6770441 | AD6: =Z6/J6 -> 0.12180367 | AE6: =Q6/J6 -> 0.25624192
B7: 19-25.01 | C7: 4 | D7: =J7-SUM(L7:T7)+U7+V7 -> 34413.47 | E7: ='Юнит 19-25.01'!K$24 -> 154 | F7: ='Юнит 19-25.01'!P$24 -> 91 | G7: ='Юнит 19-25.01'!Q$24 -> 2 | H7: ='Юнит 19-25.01'!S$24 -> 161208 | I7: ='Юнит 19-25.01'!T$24 -> -3229 | J7: =H7+I7 -> 157979 | K7: ='Юнит 19-25.01'!W$24 -> 11132.49 | L7: ='Юнит 19-25.01'!Z$24 -> 16989.46 | M7: ='Юнит 19-25.01'!X$24 -> 67930.97 | Q7: ='Юнит 19-25.01'!AA$24 -> 42151.21 | R7: 3468.89 | S7: 25 | V7: 7000 | X7: =3481.9416*J7/SUM($J$4:$J$8) -> 603.82627 | Y7: =J7-SUM(L7:T7)-K7-V7+U7+W7 -> 9280.98 | Z7: =Y7-X7 -> 8677.1537 | AB7: =K7/J7 -> 0.070468163 | AC7: =Z7/K7 -> 0.77944411 | AD7: =Z7/J7 -> 0.054925995 | AE7: =Q7/J7 -> 0.26681527
B8: 26-31.01 | C8: 5 | D8: =J8-SUM(L8:T8)+U8+V8 -> -6034.71 | E8: ='Юнит 26-31.01'!K$24 -> 200 | F8: ='Юнит 26-31.01'!P$24 -> 112 | G8: ='Юнит 26-31.01'!Q$24 -> 2 | H8: ='Юнит 26-31.01'!S$24 -> 200558 | I8: ='Юнит 26-31.01'!T$24 -> -3595 | J8: =H8+I8 -> 196963 | K8: ='Юнит 26-31.01'!W$24 -> 13886.49 | L8: ='Юнит 26-31.01'!Z$24 -> 20843.55 | M8: ='Юнит 26-31.01'!X$24 -> 84694.09 | Q8: ='Юнит 26-31.01'!AA$24 -> 50770.67 | R8: 3661.19 | S8: 150 | T8: 43993.6 | U8: 1115.39 | X8: =3481.9416*J8/SUM($J$4:$J$8) -> 752.83065 | Y8: =J8-SUM(L8:T8)-K8-V8+U8+W8 -> -19921.2 | Z8: =Y8-X8 -> -20674.031 | AB8: =(K8+K9)/(J8+J9) -> 0.070282074 | AC8: =(Z8+Z9)/(K8+K9) -> -0.67605169 | AD8: =(Z8+Z9)/(J8+J9) -> -0.047514315 | AE8: =(Q8+Q9)/(J8+J9) -> 0.25406002
A9: Февраль | B9: 01.02-01.02 | C9: 5 | D9: =J9-SUM(L9:T9)+U9+V9 -> 7323.99 | E9: ='Юнит 01.02'!K$24 -> 36 | F9: ='Юнит 01.02'!P$24 -> 19 | G9: ='Юнит 01.02'!Q$24 -> 1 | H9: ='Юнит 01.02'!S$24 -> 34372 | I9: ='Юнит 01.02'!T$24 -> -1750 | J9: =H9+I9 -> 32622 | K9: ='Юнит 01.02'!W$24 -> 2249.22 | L9: ='Юнит 01.02'!Z$24 -> 3179.52 | M9: ='Юнит 01.02'!X$24 -> 14027.46 | Q9: ='Юнит 01.02'!AA$24 -> 7557.7 | R9: 533.33 | W9: 4831 | X9: =5201.48*J9/SUM($J$9:$J$13) -> 140.3134 | Y9: =J9-SUM(L9:T9)-K9-V9+U9+W9 -> 9905.77 | Z9: =Y9-X9 -> 9765.4566 | AA9: =SUM(Z9:Z13) -> 174317.71
B10: 02.02-08.02 | C10: 6 | D10: =J10-SUM(L10:T10)+U10+V10 -> 40049.95 | E10: ='Юнит 02-08.02'!K$24 -> 225 | F10: ='Юнит 02-08.02'!P$24 -> 167 | G10: ='Юнит 02-08.02'!Q$24 -> 11 | H10: ='Юнит 02-08.02'!S$24 -> 323134 | I10: ='Юнит 02-08.02'!T$24 -> -22524 | J10: =H10+I10 -> 300610 | K10: ='Юнит 02-08.02'!W$24 -> 19848.12 | L10: ='Юнит 02-08.02'!Z$24 -> 31123.53 | M10: ='Юнит 02-08.02'!X$24 -> 129262.3 | Q10: ='Юнит 02-08.02'!AA$24 -> 66736.42 | R10: 5825.9 | T10: 27611.9 | X10: =5201.48*J10/SUM($J$9:$J$13) -> 1292.9806 | Y10: =J10-SUM(L10:T10)-K10-V10+U10+W10 -> 20201.83 | Z10: =Y10-X10 -> 18908.849 | AB10: =K10/J10 -> 0.066026147 | AC10: =Z10/K10 -> 0.9526771 | AD10: =Z10/J10 -> 0.062901598 | AE10: =Q10/J10 -> 0.22200333
B11: 09-15.02 | C11: 7 | D11: =J11-SUM(L11:T11)+U11+V11 -> 62513.5 | E11: ='Юнит 09-15.02'!K$24 -> 240 | F11: ='Юнит 09-15.02'!P$24 -> 125 | G11: ='Юнит 09-15.02'!Q$24 -> 4 | H11: ='Юнит 09-15.02'!S$24 -> 282164 | I11: ='Юнит 09-15.02'!T$24 -> -9000 | J11: =H11+I11 -> 273164 | K11: ='Юнит 09-15.02'!W$24 -> 15306.15 | L11: ='Юнит 09-15.02'!Z$24 -> 24192.27 | M11: ='Юнит 09-15.02'!X$24 -> 117460.52 | Q11: ='Юнит 09-15.02'!AA$24 -> 61070.11 | R11: 5828.6 | S11: 175 | T11: 1924 | X11: =5201.48*J11/SUM($J$9:$J$13) -> 1174.9301 | Y11: =J11-SUM(L11:T11)-K11-V11+U11+W11 -> 47207.35 | Z11: =Y11-X11 -> 46032.42 | AB11: =K11/J11 -> 0.056032823 | AC11: =Z11/K11 -> 3.007446 | AD11: =Z11/J11 -> 0.16851569 | AE11: =Q11/J11 -> 0.22356573
B12: 16-22.02 | C12: 8 | D12: =J12-SUM(L12:T12)+U12+V12 -> 82376.34 | E12: ='Юнит 16-22.02'!K$24 -> 298 | F12: ='Юнит 16-22.02'!P$24 -> 161 | G12: ='Юнит 16-22.02'!Q$24 -> 8 | H12: ='Юнит 16-22.02'!S$24 -> 373392 | I12: ='Юнит 16-22.02'!T$24 -> -18750 | J12: =H12+I12 -> 354642 | K12: ='Юнит 16-22.02'!W$24 -> 19197.06 | L12: ='Юнит 16-22.02'!Z$24 -> 31757.74 | M12: ='Юнит 16-22.02'!X$24 -> 152496.06 | Q12: ='Юнит 16-22.02'!AA$24 -> 79962.77 | R12: 8049.09 | W12: 4347 | X12: =5201.48*J12/SUM($J$9:$J$13) -> 1525.3824 | Y12: =J12-SUM(L12:T12)-K12-V12+U12+W12 -> 67526.28 | Z12: =Y12-X12 -> 66000.898 | AB12: =K12/J12 -> 0.054130814 | AC12: =Z12/K12 -> 3.4380732 | AD12: =Z12/J12 -> 0.1861057 | AE12: =Q12/J12 -> 0.22547462
B13: 23-28.02 | C13: 9 | D13: =J13-SUM(L13:T13)+U13+V13 -> 47866.26 | E13: ='Юнит 23-28.02'!K$24 -> 159 | F13: ='Юнит 23-28.02'!P$24 -> 107 | G13: ='Юнит 23-28.02'!Q$24 -> 6 | H13: ='Юнит 23-28.02'!S$24 -> 262374 | I13: ='Юнит 23-28.02'!T$24 -> -14100 | J13: =H13+I13 -> 248274 | K13: ='Юнит 23-28.02'!W$24 -> 13188.3 | L13: ='Юнит 23-28.02'!Z$24 -> 25365.95 | M13: ='Юнит 23-28.02'!X$24 -> 106757.82 | Q13: ='Юнит 23-28.02'!AA$24 -> 64457.72 | R13: 6407.47 | U13: 2581.22 | X13: =5201.48*J13/SUM($J$9:$J$13) -> 1067.8735 | Y13: =J13-SUM(L13:T13)-K13-V13+U13+W13 -> 34677.96 | Z13: =Y13-X13 -> 33610.086 | AB13: =(K13+K14)/(J13+J14) -> 0.052676864 | AC13: =(Z13+Z14)/(K13+K14) -> 2.4578024 | AD13: =(Z13+Z14)/(J13+J14) -> 0.12946932 | AE13: =(Q13+Q14)/(J13+J14) -> 0.26870709
A14: Март | B14: 46082 | C14: 9 | D14: =J14-SUM(L14:T14)+U14+V14 -> 2695.31 | E14: ='Юнит 01.03'!K$24 -> 36 | F14: ='Юнит 01.03'!P$24 -> 13 | G14: ='Юнит 01.03'!Q$24 -> 1 | H14: ='Юнит 01.03'!S$24 -> 32560 | I14: ='Юнит 01.03'!T$24 -> -2400 | J14: =H14+I14 -> 30160 | K14: ='Юнит 01.03'!W$24 -> 1478.73 | L14: ='Юнит 01.03'!Z$24 -> 3251.78 | M14: ='Юнит 01.03'!X$24 -> 12968.8 | Q14: ='Юнит 01.03'!AA$24 -> 10359.47 | R14: 884.64 | W14: 1350 | X14: =3397.77*J14/SUM($J$14:$J$19) -> 128.00473 | Y14: =J14-SUM(L14:T14)-K14-V14+U14+W14 -> 2566.58 | Z14: =Y14-X14 -> 2438.5753 | AA14: =SUM(Z14:Z19) -> 141772.43
B15: 02.03-08.03 | C15: 10 | D15: =J15-SUM(L15:T15)+U15+V15 -> 31422.07 | E15: ='Юнит 02-08.03'!K$24 -> 179 | F15: ='Юнит 02-08.03'!P$24 -> 93 | G15: ='Юнит 02-08.03'!Q$24 -> 4 | H15: ='Юнит 02-08.03'!S$24 -> 221439 | I15: ='Юнит 02-08.03'!T$24 -> -9910 | J15: =H15+I15 -> 211529 | K15: ='Юнит 02-08.03'!W$24 -> 11497.53 | L15: ='Юнит 02-08.03'!Z$24 -> 18516.49 | M15: ='Юнит 02-08.03'!X$24 -> 90957.47 | Q15: ='Юнит 02-08.03'!AA$24 -> 65685.91 | R15: 4902.06 | S15: 45 | T15: 0 | X15: =3397.77*J15/SUM($J$14:$J$19) -> 897.76895 | Y15: =J15-SUM(L15:T15)-K15-V15+U15+W15 -> 19924.54 | Z15: =Y15-X15 -> 19026.771 | AB15: =K15/J15 -> 0.054354391 | AC15: =Z15/K15 -> 1.6548573 | AD15: =Z15/J15 -> 0.089948759 | AE15: =Q15/J15 -> 0.3105291
B16: 09-15.03 | C16: 11 | D16: =J16-SUM(L16:T16)+U16+V16 -> 61950.07 | E16: ='Юнит 09-15.03'!K$24 -> 156 | F16: ='Юнит 09-15.03'!P$24 -> 97 | G16: ='Юнит 09-15.03'!Q$24 -> 5 | H16: ='Юнит 09-15.03'!S$24 -> 240785 | I16: ='Юнит 09-15.03'!T$24 -> -11873 | J16: =H16+I16 -> 228912 | K16: ='Юнит 09-15.03'!W$24 -> 12514.02 | L16: ='Юнит 09-15.03'!Z$24 -> 20045.39 | M16: ='Юнит 09-15.03'!X$24 -> 98432.16 | Q16: ='Юнит 09-15.03'!AA$24 -> 42625.75 | R16: 5778.63 | S16: 80 | T16: 0 | X16: =3397.77*J16/SUM($J$14:$J$19) -> 971.54568 | Y16: =J16-SUM(L16:T16)-K16-V16+U16+W16 -> 49436.05 | Z16: =Y16-X16 -> 48464.504 | AB16: =K16/J16 -> 0.054667383 | AC16: =Z16/K16 -> 3.8728166 | AD16: =Z16/J16 -> 0.21171675 | AE16: =Q16/J16 -> 0.1862102
B17: 16-22.03 | C17: 12 | D17: =J17-SUM(L17:T17)+U17+V17 -> 41865.51 | E17: ='Юнит 16-22.03'!K$24 -> 109 | F17: ='Юнит 16-22.03'!P$24 -> 61 | G17: ='Юнит 16-22.03'!Q$24 -> 2 | H17: ='Юнит 16-22.03'!S$24 -> 148955 | I17: ='Юнит 16-22.03'!T$24 -> -4939 | J17: =H17+I17 -> 144016 | K17: ='Юнит 16-22.03'!W$24 -> 8173.8 | L17: ='Юнит 16-22.03'!Z$24 -> 13537.32 | M17: ='Юнит 16-22.03'!X$24 -> 61926.88 | Q17: ='Юнит 16-22.03'!AA$24 -> 22870.89 | R17: 3785.4 | S17: 30 | T17: 0 | W17: 1404 | X17: =3397.77*J17/SUM($J$14:$J$19) -> 611.23105 | Y17: =J17-SUM(L17:T17)-K17-V17+U17+W17 -> 35095.71 | Z17: =Y17-X17 -> 34484.479 | AB17: =K17/J17 -> 0.056756194 | AC17: =Z17/K17 -> 4.2189042 | AD17: =Z17/J17 -> 0.23944894 | AE17: =Q17/J17 -> 0.15880798
B18: 23-29.03 | C18: 13 | D18: =J18-SUM(L18:T18)+U18+V18 -> 31815.03 | E18: ='Юнит 23-29.03'!K$24 -> 136 | F18: ='Юнит 23-29.03'!P$24 -> 59 | G18: ='Юнит 23-29.03'!Q$24 -> 5 | H18: ='Юнит 23-29.03'!S$24 -> 135999 | I18: ='Юнит 23-29.03'!T$24 -> -10689 | J18: =H18+I18 -> 125310 | K18: ='Юнит 23-29.03'!W$24 -> 7248.21 | L18: ='Юнит 23-29.03'!Z$24 -> 10759.15 | M18: ='Юнит 23-29.03'!X$24 -> 53883.3 | Q18: ='Юнит 23-29.03'!AA$24 -> 26466.97 | R18: 2330.55 | S18: 55 | T18: 0 | X18: =3397.77*J18/SUM($J$14:$J$19) -> 531.83926 | Y18: =J18-SUM(L18:T18)-K18-V18+U18+W18 -> 24566.82 | Z18: =Y18-X18 -> 24034.981 | AB18: =K18/J18 -> 0.057842231 | AC18: =Z18/K18 -> 3.3159885 | AD18: =Z18/J18 -> 0.19180417 | AE18: =Q18/J18 -> 0.21121195
B19: 30-31.03 | C19: 14 | D19: =J19-SUM(L19:T19)+U19+V19 -> 17004.19 | E19: ='Юнит 30-31.03'!K$24 -> 52 | F19: ='Юнит 30-31.03'!P$24 -> 26 | G19: ='Юнит 30-31.03'!Q$24 -> 0 | H19: ='Юнит 30-31.03'!S$24 -> 60643 | I19: ='Юнит 30-31.03'!T$24 -> 0 | J19: =H19+I19 -> 60643 | K19: ='Юнит 30-31.03'!W$24 -> 3423.69 | L19: ='Юнит 30-31.03'!Z$24 -> 4441.24 | M19: ='Юнит 30-31.03'!X$24 -> 26076.49 | Q19: ='Юнит 30-31.03'!AA$24 -> 11946.08 | R19: 1130.4 | S19: 15 | T19: 29.6 | X19: =3397.77*J19/SUM($J$14:$J$19) -> 257.38032 | Y19: =J19-SUM(L19:T19)-K19-V19+U19+W19 -> 13580.5 | Z19: =Y19-X19 -> 13323.12 | AB19: =(K19+K20)/(J19+J20) -> 0.052990653 | AC19: =(Z19+Z20)/(K19+K20) -> 4.2901781 | AD19: =(Z19+Z20)/(J19+J20) -> 0.22733934 | AE19: =(Q19+Q20)/(J19+J20) -> 0.21127753
A20: Апрель | B20: 01.04-05.04 | C20: 14 | D20: =J20-SUM(L20:T20)+U20+V20 -> 34556.54 | E20: ='Юнит 01-05.04'!K$24 -> 93 | F20: ='Юнит 01-05.04'!P$24 -> 52 | G20: ='Юнит 01-05.04'!Q$24 -> 1 | H20: ='Юнит 01-05.04'!S$24 -> 131890 | I20: ='Юнит 01-05.04'!T$24 -> -2103 | J20: =H20+I20 -> 129787 | K20: ='Юнит 01-05.04'!W$24 -> 6667.32 | L20: ='Юнит 01-05.04'!Z$24 -> 8857.02 | M20: ='Юнит 01-05.04'!X$24 -> 55808.41 | Q20: ='Юнит 01-05.04'!AA$24 -> 28287.5 | R20: 2257.53 | S20: 20 | T20: 0 | W20: 2599 | X20: ='Юнит 01-05.04'!$AD$24 -> 519.11 | Y20: =J20-SUM(L20:T20)-K20-V20+U20+W20 -> 30488.22 | Z20: =Y20-X20 -> 29969.11 | AA20: =SUM(Z20:Z31) -> 86718.86
B21: 06.04-12.04 | C21: 15 | D21: =J21-SUM(L21:T21)+U21+V21 -> 36662.16 | E21: ='Юнит 06-12.04'!K$24 -> 161 | F21: ='Юнит 06-12.04'!P$24 -> 84 | G21: ='Юнит 06-12.04'!Q$24 -> 2 | H21: ='Юнит 06-12.04'!S$24 -> 222368 | I21: ='Юнит 06-12.04'!T$24 -> -4950 | J21: =H21+I21 -> 217418 | K21: ='Юнит 06-12.04'!W$24 -> 10463.43 | L21: ='Юнит 06-12.04'!Z$24 -> 16068.74 | M21: ='Юнит 06-12.04'!X$24 -> 100034.39 | Q21: ='Юнит 06-12.04'!AA$24 -> 61249.88 | R21: 3342.83 | S21: 60 | T21: 0 | X21: ='Юнит 06-12.04'!$AD$24 -> 841.64 | Y21: =J21-SUM(L21:T21)-K21-V21+U21+W21 -> 26198.73 | Z21: =Y21-X21 -> 25357.09 | AB21: =K21/J21 -> 0.048125868 | AC21: =Z21/K21 -> 2.4234013 | AD21: =Z21/J21 -> 0.11662829 | AE21: =Q21/J21 -> 0.28171485
B22: 13-19.04 | C22: 16 | D22: =J22-SUM(L22:T22)+U22+V22 -> 25005.01 | E22: ='Юнит 13-19.04'!K$24 -> 107 | F22: ='Юнит 13-19.04'!P$24 -> 60 | G22: ='Юнит 13-19.04'!Q$24 -> 5 | H22: ='Юнит 13-19.04'!S$24 -> 165503 | I22: ='Юнит 13-19.04'!T$24 -> -13500 | J22: =H22+I22 -> 152003 | K22: ='Юнит 13-19.04'!W$24 -> 7010.34 | L22: ='Юнит 13-19.04'!Z$24 -> 17537.62 | M22: ='Юнит 13-19.04'!X$24 -> 72969.29 | Q22: ='Юнит 13-19.04'!AA$24 -> 33345.95 | R22: 3085.13 | S22: 60 | T22: 0 | W22: 1292 | X22: ='Юнит 13-19.04'!$AD$24 -> 593.31 | Y22: =J22-SUM(L22:T22)-K22-V22+U22+W22 -> 19286.67 | Z22: =Y22-X22 -> 18693.36 | AB22: =K22/J22 -> 0.046119748 | AC22: =Z22/K22 -> 2.6665411 | AD22: =Z22/J22 -> 0.1229802 | AE22: =Q22/J22 -> 0.21937692
B23: 20-26.04 | C23: 17 | D23: =J23-SUM(L23:T23)+U23+V23 -> 14054.27 | E23: ='Юнит 20-26.04'!K$24 -> 72 | F23: ='Юнит 20-26.04'!P$24 -> 38 | G23: ='Юнит 20-26.04'!Q$24 -> 2 | H23: ='Юнит 20-26.04'!S$24 -> 106520 | I23: ='Юнит 20-26.04'!T$24 -> -5320 | J23: =H23+I23 -> 101200 | K23: ='Юнит 20-26.04'!W$24 -> 4921.56 | L23: ='Юнит 20-26.04'!Z$24 -> 12223.2 | M23: ='Юнит 20-26.04'!X$24 -> 48451 | Q23: ='Юнит 20-26.04'!AA$24 -> 24263.68 | R23: 2182.85 | S23: 25 | T23: 0 | X23: ='Юнит 20-26.04'!$AD$24 -> 396.25 | Y23: =J23-SUM(L23:T23)-K23-V23+U23+W23 -> 9132.71 | Z23: =Y23-X23 -> 8736.46 | AB23: =K23/J23 -> 0.048632016 | AC23: =Z23/K23 -> 1.7751404 | AD23: =Z23/J23 -> 0.086328656 | AE23: =Q23/J23 -> 0.23975968
B24: 27-30.04 | C24: 18 | D24: =J24-SUM(L24:T24)+U24+V24 -> 3003.97 | E24: ='Юнит 27-30.04'!K$24 -> 45 | F24: ='Юнит 27-30.04'!P$24 -> 24 | G24: ='Юнит 27-30.04'!Q$24 -> 3 | H24: ='Юнит 27-30.04'!S$24 -> 67540 | I24: ='Юнит 27-30.04'!T$24 -> -8460 | J24: =H24+I24 -> 59080 | K24: ='Юнит 27-30.04'!W$24 -> 2781.54 | L24: ='Юнит 27-30.04'!Z$24 -> 5101.96 | M24: ='Юнит 27-30.04'!X$24 -> 28358.4 | Q24: ='Юнит 27-30.04'!AA$24 -> 21519.32 | R24: 996.35 | S24: 100 | T24: 0 | X24: ='Юнит 27-30.04'!$AD$24 -> 245.4 | Y24: =J24-SUM(L24:T24)-K24-V24+U24+W24 -> 222.43 | Z24: =Y24-X24 -> -22.97 | AB24: =(K24+K25)/(J24+J25) -> 0.047392062 | AC24: =(Z24+Z25)/(K24+K25) -> 0.76293999 | AD24: =(Z24+Z25)/(J24+J25) -> 0.036157299 | AE24: =(Q24+Q25)/(J24+J25) -> 0.34100484
A25: Май | B25: 01.05-03.05 | C25: 18 | D25: =J25-SUM(L25:T25)+U25+V25 -> 5199.96 | E25: ='Юнит 01-03.05'!K$24 -> 53 | F25: ='Юнит 01-03.05'!P$24 -> 18 | G25: ='Юнит 01-03.05'!Q$24 -> 0 | H25: ='Юнит 01-03.05'!S$24 -> 50520 | I25: ='Юнит 01-03.05'!T$24 -> 0 | J25: =H25+I25 -> 50520 | K25: ='Юнит 01-03.05'!W$24 -> 2412.63 | L25: ='Юнит 01-03.05'!Z$24 -> 4346.6 | M25: ='Юнит 01-03.05'!X$24 -> 24249.6 | Q25: ='Юнит 01-03.05'!AA$24 -> 15854.81 | R25: 864.03 | S25: 5 | T25: 0 | W25: 1382 | X25: ='Юнит 01-03.05'!$AD$24 -> 183.52 | Y25: =J25-SUM(L25:T25)-K25-V25+U25+W25 -> 4169.33 | Z25: =Y25-X25 -> 3985.81
AB31: =K31/J31 -> #DIV/0! | AC31: =Z31/K31 -> #DIV/0! | AD31: =Z31/J31 -> #DIV/0! | AE31: =Q31/J31 -> #DIV/0!
A32: Итого | D32: =SUM(D4:D19) -> 550107.41 | E32: =SUM(E4:E19) -> 2429 | F32: =SUM(F4:F19) -> 1472 | G32: =SUM(G4:G19) -> 62 | H32: =SUM(H4:H19) -> 3052264 | I32: =SUM(I4:I19) -> -131402 | J32: =SUM(J4:J19) -> 2920862 | K32: =SUM(K4:K19) -> 180695.82 | ... Q32: =SUM(Q4:Q19) -> 699049.12 | R32: =SUM(R4:R21) -> 68031.66 | S32: =SUM(S4:S25) -> 920 | T32: =SUM(T4:T21) -> 78549.5 | U32: =SUM(U4:U19) -> 3696.61 | V32: =SUM(V4:V19) -> 7000 | W32: =SUM(W4:W19) -> 22319 | X32: =SUM(X4:X19) -> 12081.192 | Y32: =SUM(Y4:Y19) -> 377730.59 | Z32: =SUM(Z4:Z19) -> 365649.4 | AA32: =SUM(AA4:AA19) -> 365649.4 | AB32: =K32/J32 -> 0.061863868 | AC32: =Z32/K32 -> 2.0235631 | AD32: =Z32/J32 -> 0.12518544 | AE32: =Q32/J32 -> 0.23932973
H33: % от выручки за весь период
I34: =-I32/H32 -> 0.043050667 | K34: =K32/$J$32 -> 0.061863868 | L34: =L32/$J$32 -> 0.097505675 | M34: =M32/$J$32 -> 0.43 | Q34: =Q32/$J$32 -> 0.23932973 | R34: =R32/$J$32 -> 0.023291638 | S34: =S32/$J$32 -> 0.00031497551 | T34: =T32/$J$32 -> 0.026892575 | U34: =U32/$J$32 -> 0.0012655887 | V34: =V32/$J$32 -> 0.0023965528 | W34: =W32/$J$32 -> 0.0076412374 | X34: =X32/$J$32 -> 0.0041361734 | Z34: =Z32/K32 -> 2.0235631 | AA34: Маржинальность, % | AB34: =Z32/J32 -> 0.12518544
A36: январь | D36: =SUM(D4:D8) -> 123225.19 | E36: =SUM(E4:E8) -> 803 | F36: =SUM(F4:F8) -> 544 | G36: =SUM(G4:G8) -> 15 | H36: =SUM(H4:H8) -> 936447 | I36: =SUM(I4:I8) -> -25467 | J36: =SUM(J4:J8) -> 910980 | K36: =SUM(K4:K8) -> 66570.99 | ... AA36: =SUM(AA4:AA8) -> 49559.258
I37: =-I36/H36 -> 0.027195346 | K37: =K36/$J$36 -> 0.073076237 | L37: =L36/$J$36 -> 0.10826828 | M37: =M36/$J$36 -> 0.43 | Q37: =Q36/$J$36 -> 0.26269438 | R37: =R36/$J$36 -> 0.018634031 | S37: =S36/$J$36 -> 0.00027442974 | T37: =T36/$J$36 -> 0.053770665 | V37: =V36/$J$36 -> 0.0076840326 | W37: =W36/$J$36 -> 0.011402007 | X37: =X36/$J$36 -> 0.0038221932 | Y37: =Y36/J36 -> 0.05822433 | Z37: =Z36/J36 -> 0.054402137 | AA37: =AA36/J36 -> 0.054402137
A39: 5 неделя | K39: =(K8+K9)/($J$8+$J$9) -> 0.070282074 | L39: =(L8+L9)/($J$8+$J$9) -> 0.10463693 | M39: =(M8+M9)/($J$8+$J$9) -> 0.43 | N39: =(N8+N9)/($J$8+$J$9) -> 0 | O39: =(O8+O9)/($J$8+$J$9) -> 0 | P39: =(P8+P9)/($J$8+$J$9) -> 0 | Q39: =(Q8+Q9)/($J$8+$J$9) -> 0.25406002 | R39: =(R8+S8+T8+R9+S9+T9)/($J$8+$J$9) -> 0.21054564 | U39: =(U8+U9)/($J$8+$J$9) -> 0.0048582878 | V39: =(V8+V9)/($J$8+$J$9) -> 0 | W39: =(W8+W9)/($J$8+$J$9) -> 0.021042315 | X39: =(X8+X9)/($J$8+$J$9) -> 0.0038902544 | Y39: =(Y8+Y9)/($J$8+$J$9) -> -0.043624061 | Z39: =(Z8+Z9)/($J$8+$J$9) -> -0.047514315
A40: 6 неделя | K40: =K10/$J$10 -> 0.066026147 | L40: =L10/$J$10 -> 0.10353458 | M40: =M10/$J$10 -> 0.43 | Q40: =Q10/$J$10 -> 0.22200333 | R40: =(R10+S10+T10)/$J$10 -> 0.11123316 | V40: =V10/$J$10 -> 0 | W40: =W10/$J$10 -> 0 | X40: =X10/$J$10 -> 0.0043011894 | Y40: =Y10/J10 -> 0.067202788 | Z40: =Z10/J10 -> 0.062901598
A41: 7 неделя | K41: =K11/$J$11 -> 0.056032823 | L41: =L11/$J$11 -> 0.088563171 | M41: =M11/$J$11 -> 0.43 | Q41: =Q11/$J$11 -> 0.22356573 | R41: =(R11+S11+T11)/$J$11 -> 0.029021394 | V41: =V11/$J$11 -> 0 | W41: =W11/$J$11 -> 0 | X41: =X11/$J$11 -> 0.0043011894 | Y41: =Y11/J11 -> 0.17281688 | Z41: =Z11/J11 -> 0.16851569
A42: 8 неделя | K42: =K12/$J$12 -> 0.054130814 | L42: =L12/$J$12 -> 0.089548728 | M42: =M12/$J$12 -> 0.43 | Q42: =Q12/$J$12 -> 0.22547462 | R42: =(R12+S12+T12)/$J$12 -> 0.022696381 | V42: =V12/$J$12 -> 0 | W42: =W12/$J$12 -> 0.012257431 | X42: =X12/$J$12 -> 0.0043011894 | Y42: =Y12/J12 -> 0.19040689 | Z42: =Z12/J12 -> 0.1861057
A43: 9 неделя | K43: =(K13+K14)/($J$13+$J$14) -> 0.052676864 | L43: =(L13+L14)/($J$13+$J$14) -> 0.10278102 | M43: =(M13+M14)/($J$13+$J$14) -> 0.43 | N43: =(N13+N14)/($J$13+$J$14) -> 0 | O43: =(O13+O14)/($J$13+$J$14) -> 0 | P43: =(P13+P14)/($J$13+$J$14) -> 0 | Q43: =(Q13+Q14)/($J$13+$J$14) -> 0.26870709 | R43: =(R13+R14)/($J$13+$J$14) -> 0.026189725 | V43: =(V13+V14)/($J$13+$J$14) -> 0 | W43: =(W13+W14)/($J$13+$J$14) -> 0.0048485458 | X43: =(X13+X14)/($J$13+$J$14) -> 0.0042950151 | Y43: =(Y13+Y14)/($J$13+$J$14) -> 0.13376434 | Z43: =(Z13+Z14)/($J$13+$J$14) -> 0.12946932
A45: февраль | D45: =SUM(D9:D13) -> 240130.04 | E45: =SUM(E9:E13) -> 958 | F45: =SUM(F9:F13) -> 579 | G45: =SUM(G9:G13) -> 30 | H45: =SUM(H9:H13) -> 1275436 | I45: =SUM(I9:I13) -> -66124 | J45: =SUM(J9:J13) -> 1209312 | K45: =SUM(K9:K13) -> 69788.85 | ... AA45: =SUM(AA9:AA13) -> 174317.71
A47: март | D47: =SUM(D14:D19) -> 186752.18 | E47: =SUM(E14:E19) -> 668 | F47: =SUM(F14:F19) -> 349 | G47: =SUM(G14:G19) -> 17 | H47: =SUM(H14:H19) -> 840381 | I47: =SUM(I14:I19) -> -39811 | J47: =SUM(J14:J19) -> 800570 | K47: =SUM(K14:K19) -> 44335.98 | ... AA47: =SUM(AA14:AA19) -> 141772.43
A49: апрель | D49: =SUM(D20:D24) -> 113281.95 | E49: =SUM(E20:E24) -> 478 | F49: =SUM(F20:F24) -> 258 | G49: =SUM(G20:G24) -> 13 | H49: =SUM(H20:H24) -> 693821 | I49: =SUM(I20:I24) -> -34333 | J49: =SUM(J20:J24) -> 659488 | K49: =SUM(K20:K24) -> 31844.19 | ... AA49: =SUM(AA20:AA24) -> 86718.86

Sheet АВС 04-10.05
B2: ОЧКИ
C3: Прибыль | D3: % прибыль | E3: Доля | F3: ABC прибыль | G3: ABC кол-во | J3: Кол-во | K3: % кол-во | L3: Доля | M3: ABC кол-во
B4: черные с железкой классика | D4: =C4/C$18 -> #DIV/0! | E4: =D4 -> #DIV/0! | F4: =IF(AND(E4<=0),"C",IF(E4<=0.8,"A",IF(E4<=0.95,"B","C"))) -> #DIV/0! | G4: =VLOOKUP(B$4:B$17,I$4:M$17,5,0) -> #DIV/0! | I4: черные с железкой классика | K4: =J4/J$18 -> #DIV/0! | L4: =K4 -> #DIV/0! | M4: =_xlfn.IFS(L4<80%,"A",L4<=95%,"B",L4>95%,"C") -> #DIV/0!
B5: qs черные | D5: =C5/C$18 -> #DIV/0! | E5: =D5+E4 -> #DIV/0! | F5: =IF(AND(E5<=0),"C",IF(E5<=0.8,"A",IF(E5<=0.95,"B","C"))) -> #DIV/0! | G5: =VLOOKUP(B$4:B$17,I$4:M$17,5,0) -> #DIV/0! | I5: qs черные | K5: =J5/J$18 -> #DIV/0! | L5: =K5+L4 -> #DIV/0! | M5: =_xlfn.IFS(L5<80%,"A",L5<=95%,"B",L5>95%,"C") -> #DIV/0!
B6: qs синие | D6: =C6/C$18 -> #DIV/0! | E6: =D6+E5 -> #DIV/0! | F6: =IF(AND(E6<=0),"C",IF(E6<=0.8,"A",IF(E6<=0.95,"B","C"))) -> #DIV/0! | G6: =VLOOKUP(B$4:B$17,I$4:M$17,5,0) -> #DIV/0! | I6: qs синие | K6: =J6/J$18 -> #DIV/0! | L6: =K6+L5 -> #DIV/0! | M6: =_xlfn.IFS(L6<80%,"A",L6<=95%,"B",L6>95%,"C") -> #DIV/0!
B7: qs желтые | D7: =C7/C$18 -> #DIV/0! | E7: =D7+E6 -> #DIV/0! | F7: =IF(AND(E7<=0),"C",IF(E7<=0.8,"A",IF(E7<=0.95,"B","C"))) -> #DIV/0! | G7: =VLOOKUP(B$4:B$17,I$4:M$17,5,0) -> #DIV/0! | I7: qs желтые | K7: =J7/J$18 -> #DIV/0! | L7: =K7+L6 -> #DIV/0! | M7: =_xlfn.IFS(L7<80%,"A",L7<=95%,"B",L7>95%,"C") -> #DIV/0!
B8: qs коричневые | D8: =C8/C$18 -> #DIV/0! | E8: =D8+E7 -> #DIV/0! | F8: =IF(AND(E8<=0),"C",IF(E8<=0.8,"A",IF(E8<=0.95,"B","C"))) -> #DIV/0! | G8: =VLOOKUP(B$4:B$17,I$4:M$17,5,0) -> #DIV/0! | I8: qs коричневые | K8: =J8/J$18 -> #DIV/0! | L8: =K8+L7 -> #DIV/0! | M8: =_xlfn.IFS(L8<80%,"A",L8<=95%,"B",L8>95%,"C") -> #DIV/0!
B9: MR8854 C2 | D9: =C9/C$18 -> #DIV/0! | E9: =D9+E8 -> #DIV/0! | F9: =IF(AND(E9<=0),"C",IF(E9<=0.8,"A",IF(E9<=0.95,"B","C"))) -> #DIV/0! | G9: =VLOOKUP(B$4:B$17,I$4:M$17,5,0) -> #DIV/0! | I9: MR8854 C2 | K9: =J9/J$18 -> #DIV/0! | L9: =K9+L8 -> #DIV/0! | M9: =_xlfn.IFS(L9<80%,"A",L9<=95%,"B",L9>95%,"C") -> #DIV/0!
B10: th черн | D10: =C10/C$18 -> #DIV/0! | E10: =D10+E9 -> #DIV/0! | F10: =IF(AND(E10<=0),"C",IF(E10<=0.8,"A",IF(E10<=0.95,"B","C"))) -> #DIV/0! | G10: =VLOOKUP(B$4:B$17,I$4:M$17,5,0) -> #DIV/0! | I10: th черн | K10: =J10/J$18 -> #DIV/0! | L10: =K10+L9 -> #DIV/0! | M10: =_xlfn.IFS(L10<80%,"A",L10<=95%,"B",L10>95%,"C") -> #DIV/0!
B11: th син | D11: =C11/C$18 -> #DIV/0! | E11: =D11+E10 -> #DIV/0! | F11: =IF(AND(E11<=0),"C",IF(E11<=0.8,"A",IF(E11<=0.95,"B","C"))) -> #DIV/0! | G11: =VLOOKUP(B$4:B$17,I$4:M$17,5,0) -> #DIV/0! | I11: th син | K11: =J11/J$18 -> #DIV/0! | L11: =K11+L10 -> #DIV/0! | M11: =_xlfn.IFS(L11<80%,"A",L11<=95%,"B",L11>95%,"C") -> #DIV/0!
B12: th желт | D12: =C12/C$18 -> #DIV/0! | E12: =D12+E5 -> #DIV/0! | F12: =IF(AND(E12<=0),"C",IF(E12<=0.8,"A",IF(E12<=0.95,"B","C"))) -> #DIV/0! | G12: =VLOOKUP(B$4:B$17,I$4:M$17,5,0) -> #DIV/0! | I12: th желт | K12: =J12/J$18 -> #DIV/0! | L12: =K12+L5 -> #DIV/0! | M12: =_xlfn.IFS(L12<80%,"A",L12<=95%,"B",L12>95%,"C") -> #DIV/0!
B13: th коричн | D13: =C13/C$18 -> #DIV/0! | E13: =D13+E12 -> #DIV/0! | F13: =IF(AND(E13<=0),"C",IF(E13<=0.8,"A",IF(E13<=0.95,"B","C"))) -> #DIV/0! | G13: =VLOOKUP(B$4:B$17,I$4:M$17,5,0) -> #DIV/0! | I13: th коричн | K13: =J13/J$18 -> #DIV/0! | L13: =K13+L12 -> #DIV/0! | M13: =_xlfn.IFS(L13<80%,"A",L13<=95%,"B",L13>95%,"C") -> #DIV/0!
B14: flip черный | D14: =C14/C$18 -> #DIV/0! | E14: =D14+E13 -> #DIV/0! | F14: =IF(AND(E14<=0),"C",IF(E14<=0.8,"A",IF(E14<=0.95,"B","C"))) -> #DIV/0! | G14: =VLOOKUP(B$4:B$17,I$4:M$17,5,0) -> #DIV/0! | I14: flip черный | K14: =J14/J$18 -> #DIV/0! | L14: =K14+L13 -> #DIV/0! | M14: =_xlfn.IFS(L14<80%,"A",L14<=95%,"B",L14>95%,"C") -> #DIV/0!
B15: flip синий | D15: =C15/C$18 -> #DIV/0! | E15: =D15+E14 -> #DIV/0! | F15: =IF(AND(E15<=0),"C",IF(E15<=0.8,"A",IF(E15<=0.95,"B","C"))) -> #DIV/0! | G15: =VLOOKUP(B$4:B$17,I$4:M$17,5,0) -> #DIV/0! | I15: flip синий | K15: =J15/J$18 -> #DIV/0! | L15: =K15+L14 -> #DIV/0! | M15: =_xlfn.IFS(L15<80%,"A",L15<=95%,"B",L15>95%,"C") -> #DIV/0!
B16: flip жел | D16: =C16/C$18 -> #DIV/0! | E16: =D16+E15 -> #DIV/0! | F16: =IF(AND(E16<=0),"C",IF(E16<=0.8,"A",IF(E16<=0.95,"B","C"))) -> #DIV/0! | G16: =VLOOKUP(B$4:B$17,I$4:M$17,5,0) -> #DIV/0! | I16: flip жел | K16: =J16/J$18 -> #DIV/0! | L16: =K16+L15 -> #DIV/0! | M16: =_xlfn.IFS(L16<80%,"A",L16<=95%,"B",L16>95%,"C") -> #DIV/0!
B17: flip коричневый | D17: =C17/C$18 -> #DIV/0! | E17: =D17+E14 -> #DIV/0! | F17: =IF(AND(E17<=0),"C",IF(E17<=0.8,"A",IF(E17<=0.95,"B","C"))) -> #DIV/0! | G17: =VLOOKUP(B$4:B$17,I$4:M$17,5,0) -> #DIV/0! | I17: flip коричневый | K17: =J17/J$18 -> #DIV/0! | L17: =K17+L14 -> #DIV/0! | M17: =_xlfn.IFS(L17<80%,"A",L17<=95%,"B",L17>95%,"C") -> #DIV/0!
C18: =SUM(C4:C17) -> 0 | D18: =SUM(D4:D17) -> #DIV/0! | J18: =SUM(J4:J17) -> 0 | K18: =SUM(K4:K17) -> #DIV/0!
C21: Прибыль | D21: % прибыль | E21: Доля | F21: ABC прибыль | G21: ABC кол-во | J21: Кол-во | K21: % кол-во | L21: Доля | M21: ABC кол-во
D22: =C22/C$42 -> #DIV/0! | E22: =D22 -> #DIV/0! | F22: =IF(AND(E22<=0),"C",IF(E22<=0.8,"A",IF(E22<=0.95,"B","C"))) -> #DIV/0! | G22: =VLOOKUP(B$22:B$42,I$22:M$42,5,0) -> #N/A | K22: =J22/J$42 -> #DIV/0! | L22: =K22 -> #DIV/0! | M22: =_xlfn.IFS(L22<80%,"A",L22<=95%,"B",L22>95%,"C") -> #DIV/0!
D23: =C23/C$42 -> #DIV/0! | E23: =D23+E22 -> #DIV/0! | F23: =IF(AND(E23<=0),"C",IF(E23<=0.8,"A",IF(E23<=0.95,"B","C"))) -> #DIV/0! | G23: =VLOOKUP(B$22:B$42,I$22:M$42,5,0) -> #N/A | K23: =J23/J$42 -> #DIV/0! | L23: =K23+L22 -> #DIV/0! | M23: =_xlfn.IFS(L23<80%,"A",L23<=95%,"B",L23>95%,"C") -> #DIV/0!
D24: =C24/C$42 -> #DIV/0! | E24: =D24+E23 -> #DIV/0! | F24: =IF(AND(E24<=0),"C",IF(E24<=0.8,"A",IF(E24<=0.95,"B","C"))) -> #DIV/0! | G24: =VLOOKUP(B$22:B$42,I$22:M$42,5,0) -> #N/A | K24: =J24/J$42 -> #DIV/0! | L24: =K24+L23 -> #DIV/0! | M24: =_xlfn.IFS(L24<80%,"A",L24<=95%,"B",L24>95%,"C") -> #DIV/0!
D25: =C25/C$42 -> #DIV/0! | E25: =D25+E24 -> #DIV/0! | F25: =IF(AND(E25<=0),"C",IF(E25<=0.8,"A",IF(E25<=0.95,"B","C"))) -> #DIV/0! | G25: =VLOOKUP(B$22:B$42,I$22:M$42,5,0) -> #N/A | K25: =J25/J$42 -> #DIV/0! | L25: =K25+L24 -> #DIV/0! | M25: =_xlfn.IFS(L25<80%,"A",L25<=95%,"B",L25>95%,"C") -> #DIV/0!
D26: =C26/C$42 -> #DIV/0! | E26: =D26+E25 -> #DIV/0! | F26: =IF(AND(E26<=0),"C",IF(E26<=0.8,"A",IF(E26<=0.95,"B","C"))) -> #DIV/0! | G26: =VLOOKUP(B$22:B$42,I$22:M$42,5,0) -> #N/A | K26: =J26/J$42 -> #DIV/0! | L26: =K26+L25 -> #DIV/0! | M26: =_xlfn.IFS(L26<80%,"A",L26<=95%,"B",L26>95%,"C") -> #DIV/0!
D27: =C27/C$42 -> #DIV/0! | E27: =D27+E26 -> #DIV/0! | F27: =IF(AND(E27<=0),"C",IF(E27<=0.8,"A",IF(E27<=0.95,"B","C"))) -> #DIV/0! | G27: =VLOOKUP(B$22:B$42,I$22:M$42,5,0) -> #N/A | K27: =J27/J$42 -> #DIV/0! | L27: =K27+L26 -> #DIV/0! | M27: =_xlfn.IFS(L27<80%,"A",L27<=95%,"B",L27>95%,"C") -> #DIV/0!
D28: =C28/C$42 -> #DIV/0! | E28: =D28+E27 -> #DIV/0! | F28: =IF(AND(E28<=0),"C",IF(E28<=0.8,"A",IF(E28<=0.95,"B","C"))) -> #DIV/0! | G28: =VLOOKUP(B$22:B$42,I$22:M$42,5,0) -> #N/A | K28: =J28/J$42 -> #DIV/0! | L28: =K28+L27 -> #DIV/0! | M28: =_xlfn.IFS(L28<80%,"A",L28<=95%,"B",L28>95%,"C") -> #DIV/0!
D29: =C29/C$42 -> #DIV/0! | E29: =D29+E28 -> #DIV/0! | F29: =IF(AND(E29<=0),"C",IF(E29<=0.8,"A",IF(E29<=0.95,"B","C"))) -> #DIV/0! | G29: =VLOOKUP(B$22:B$42,I$22:M$42,5,0) -> #N/A | K29: =J29/J$42 -> #DIV/0! | L29: =K29+L28 -> #DIV/0! | M29: =_xlfn.IFS(L29<80%,"A",L29<=95%,"B",L29>95%,"C") -> #DIV/0!
D30: =C30/C$42 -> #DIV/0! | E30: =D30+E29 -> #DIV/0! | F30: =IF(AND(E30<=0),"C",IF(E30<=0.8,"A",IF(E30<=0.95,"B","C"))) -> #DIV/0! | G30: =VLOOKUP(B$22:B$42,I$22:M$42,5,0) -> #N/A | K30: =J30/J$42 -> #DIV/0! | L30: =K30+L29 -> #DIV/0! | M30: =_xlfn.IFS(L30<80%,"A",L30<=95%,"B",L30>95%,"C") -> #DIV/0!
D31: =C31/C$42 -> #DIV/0! | E31: =D31+E30 -> #DIV/0! | F31: =IF(AND(E31<=0),"C",IF(E31<=0.8,"A",IF(E31<=0.95,"B","C"))) -> #DIV/0! | G31: =VLOOKUP(B$22:B$42,I$22:M$42,5,0) -> #N/A | K31: =J31/J$42 -> #DIV/0! | L31: =K31+L30 -> #DIV/0! | M31: =_xlfn.IFS(L31<80%,"A",L31<=95%,"B",L31>95%,"C") -> #DIV/0!
D32: =C32/C$42 -> #DIV/0! | E32: =D32+E31 -> #DIV/0! | F32: =IF(AND(E32<=0),"C",IF(E32<=0.8,"A",IF(E32<=0.95,"B","C"))) -> #DIV/0! | G32: =VLOOKUP(B$22:B$42,I$22:M$42,5,0) -> #N/A | K32: =J32/J$42 -> #DIV/0! | L32: =K32+L31 -> #DIV/0! | M32: =_xlfn.IFS(L32<80%,"A",L32<=95%,"B",L32>95%,"C") -> #DIV/0!
D33: =C33/C$42 -> #DIV/0! | E33: =D33+E32 -> #DIV/0! | F33: =IF(AND(E33<=0),"C",IF(E33<=0.8,"A",IF(E33<=0.95,"B","C"))) -> #DIV/0! | G33: =VLOOKUP(B$22:B$42,I$22:M$42,5,0) -> #N/A | K33: =J33/J$42 -> #DIV/0! | L33: =K33+L32 -> #DIV/0! | M33: =_xlfn.IFS(L33<80%,"A",L33<=95%,"B",L33>95%,"C") -> #DIV/0!
D34: =C34/C$42 -> #DIV/0! | E34: =D34+E33 -> #DIV/0! | F34: =IF(AND(E34<=0),"C",IF(E34<=0.8,"A",IF(E34<=0.95,"B","C"))) -> #DIV/0! | G34: =VLOOKUP(B$22:B$42,I$22:M$42,5,0) -> #N/A | K34: =J34/J$42 -> #DIV/0! | L34: =K34+L33 -> #DIV/0! | M34: =_xlfn.IFS(L34<80%,"A",L34<=95%,"B",L34>95%,"C") -> #DIV/0!
... D41: =C41/C$42 -> #DIV/0! | E41: =D41+E40 -> #DIV/0! | F41: =IF(AND(E41<=0),"C",IF(E41<=0.8,"A",IF(E41<=0.95,"B","C"))) -> #DIV/0! | G41: =VLOOKUP(B$22:B$42,I$22:M$42,5,0) -> #N/A | K41: =J41/J$42 -> #DIV/0! | L41: =K41+L40 -> #DIV/0! | M41: =_xlfn.IFS(L41<80%,"A",L41<=95%,"B",L41>95%,"C") -> #DIV/0!
C42: =SUM(C22:C41) -> 0 | D42: =SUM(D22:D41) -> #DIV/0! | J42: =SUM(J22:J41) -> 0 | K42: =SUM(K22:K41) -> #DIV/0!

Sheet АВС АПРЕЛЬ
B2: ОЧКИ
C3: Прибыль | D3: % прибыль | E3: Доля | F3: ABC прибыль | G3: ABC кол-во | J3: Кол-во | K3: % кол-во | L3: Доля | M3: ABC кол-во
B4: MR8854 C2 | C4: =АПРЕЛЬ!AE8 -> 51269.371 | D4: =C4/C$18 -> 0.29166505 | E4: =D4 -> 0.29166505 | F4: =IF(AND(E4<=0),"C",IF(E4<=0.8,"A",IF(E4<=0.95,"B","C"))) -> A | G4: =VLOOKUP(B$4:B$17,I$4:M$17,5,0) -> A | I4: MR8854 C2 | J4: =АПРЕЛЬ!R8 -> 81 | K4: =J4/J$18 -> 0.2439759 | L4: =K4 -> 0.2439759 | M4: =_xlfn.IFS(L4<80%,"A",L4<=95%,"B",L4>95%,"C") -> A
B5: qs коричневые | C5: =АПРЕЛЬ!AE7 -> 20625.734 | D5: =C5/C$18 -> 0.11733723 | E5: =D5+E4 -> 0.40900227 | F5: =IF(AND(E5<=0),"C",IF(E5<=0.8,"A",IF(E5<=0.95,"B","C"))) -> A | G5: =VLOOKUP(B$4:B$17,I$4:M$17,5,0) -> A | I5: qs коричневые | J5: =АПРЕЛЬ!R7 -> 41 | K5: =J5/J$18 -> 0.12349398 | L5: =K5+L4 -> 0.36746988 | M5: =_xlfn.IFS(L5<80%,"A",L5<=95%,"B",L5>95%,"C") -> A
B6: flip черный | C6: =АПРЕЛЬ!AE13 -> 19840.708 | D6: =C6/C$18 -> 0.11287131 | E6: =D6+E5 -> 0.52187358 | F6: =IF(AND(E6<=0),"C",IF(E6<=0.8,"A",IF(E6<=0.95,"B","C"))) -> A | G6: =VLOOKUP(B$4:B$17,I$4:M$17,5,0) -> A | I6: flip жел | J6: =АПРЕЛЬ!R15 -> 38 | K6: =J6/J$18 -> 0.11445783 | L6: =K6+L5 -> 0.48192771 | M6: =_xlfn.IFS(L6<80%,"A",L6<=95%,"B",L6>95%,"C") -> A
B7: flip жел | C7: =АПРЕЛЬ!AE15 -> 18752.445 | D7: =C7/C$18 -> 0.10668032 | E7: =D7+E6 -> 0.6285539 | F7: =IF(AND(E7<=0),"C",IF(E7<=0.8,"A",IF(E7<=0.95,"B","C"))) -> A | G7: =VLOOKUP(B$4:B$17,I$4:M$17,5,0) -> A | I7: flip черный | J7: =АПРЕЛЬ!R13 -> 28 | K7: =J7/J$18 -> 0.084337349 | L7: =K7+L6 -> 0.56626506 | M7: =_xlfn.IFS(L7<80%,"A",L7<=95%,"B",L7>95%,"C") -> A
B8: flip коричневый | C8: =АПРЕЛЬ!AE16 -> 12366.329 | D8: =C8/C$18 -> 0.070350504 | E8: =D8+E7 -> 0.6989044 | F8: =IF(AND(E8<=0),"C",IF(E8<=0.8,"A",IF(E8<=0.95,"B","C"))) -> A | G8: =VLOOKUP(B$4:B$17,I$4:M$17,5,0) -> A | I8: flip коричневый | J8: =АПРЕЛЬ!R16 -> 28 | K8: =J8/J$18 -> 0.084337349 | L8: =K8+L7 -> 0.65060241 | M8: =_xlfn.IFS(L8<80%,"A",L8<=95%,"B",L8>95%,"C") -> A
B9: qs желтые | C9: =АПРЕЛЬ!AE6 -> 11302.478 | D9: =C9/C$18 -> 0.064298383 | E9: =D9+E8 -> 0.76320278 | F9: =IF(AND(E9<=0),"C",IF(E9<=0.8,"A",IF(E9<=0.95,"B","C"))) -> A | G9: =VLOOKUP(B$4:B$17,I$4:M$17,5,0) -> A | I9: qs желтые | J9: =АПРЕЛЬ!R6 -> 23 | K9: =J9/J$18 -> 0.069277108 | L9: =K9+L8 -> 0.71987952 | M9: =_xlfn.IFS(L9<80%,"A",L9<=95%,"B",L9>95%,"C") -> A
B10: th желт | C10: =АПРЕЛЬ!AE11 -> 11208.546 | D10: =C10/C$18 -> 0.063764016 | E10: =D10+E9 -> 0.8269668 | F10: =IF(AND(E10<=0),"C",IF(E10<=0.8,"A",IF(E10<=0.95,"B","C"))) -> B | G10: =VLOOKUP(B$4:B$17,I$4:M$17,5,0) -> A | I10: th желт | J10: =АПРЕЛЬ!R11 -> 23 | K10: =J10/J$18 -> 0.069277108 | L10: =K10+L9 -> 0.78915663 | M10: =_xlfn.IFS(L10<80%,"A",L10<=95%,"B",L10>95%,"C") -> A
B11: th черн | C11: =АПРЕЛЬ!AE9 -> 8442.6927 | D11: =C11/C$18 -> 0.048029424 | E11: =D11+E10 -> 0.87499622 | F11: =IF(AND(E11<=0),"C",IF(E11<=0.8,"A",IF(E11<=0.95,"B","C"))) -> B | G11: =VLOOKUP(B$4:B$17,I$4:M$17,5,0) -> A | I11: qs черные | J11: =АПРЕЛЬ!R4 -> 15 | K11: =J11/J$18 -> 0.045180723 | L11: =K11+L10 -> 0.83433735 | M11: =_xlfn.IFS(L11<80%,"A",L11<=95%,"B",L11>95%,"C") -> B
B12: qs синие | C12: =АПРЕЛЬ!AE5 -> 8049.3409 | D12: =C12/C$18 -> 0.045791695 | E12: =D12+E5 -> 0.45479397 | F12: =IF(AND(E12<=0),"C",IF(E12<=0.8,"A",IF(E12<=0.95,"B","C"))) -> A | G12: =VLOOKUP(B$4:B$17,I$4:M$17,5,0) -> A | I12: th коричн | J12: =АПРЕЛЬ!R12 -> 13 | K12: =J12/J$18 -> 0.039156627 | L12: =K12+L5 -> 0.40662651 | M12: =_xlfn.IFS(L12<80%,"A",L12<=95%,"B",L12>95%,"C") -> A
B13: th син | C13: =АПРЕЛЬ!AE10 -> 6801.883 | D13: =C13/C$18 -> 0.038695063 | E13: =D13+E12 -> 0.49348903 | F13: =IF(AND(E13<=0),"C",IF(E13<=0.8,"A",IF(E13<=0.95,"B","C"))) -> A | G13: =VLOOKUP(B$4:B$17,I$4:M$17,5,0) -> A | I13: th син | J13: =АПРЕЛЬ!R10 -> 12 | K13: =J13/J$18 -> 0.036144578 | L13: =K13+L12 -> 0.44277108 | M13: =_xlfn.IFS(L13<80%,"A",L13<=95%,"B",L13>95%,"C") -> A
B14: qs черные | C14: =АПРЕЛЬ!AE4 -> 5615.7015 | D14: =C14/C$18 -> 0.031947024 | E14: =D14+E13 -> 0.52543605 | F14: =IF(AND(E14<=0),"C",IF(E14<=0.8,"A",IF(E14<=0.95,"B","C"))) -> A | G14: =VLOOKUP(B$4:B$17,I$4:M$17,5,0) -> B | I14: th черн | J14: =АПРЕЛЬ!R9 -> 10 | K14: =J14/J$18 -> 0.030120482 | L14: =K14+L13 -> 0.47289157 | M14: =_xlfn.IFS(L14<80%,"A",L14<=95%,"B",L14>95%,"C") -> A
B15: th коричн | C15: =АПРЕЛЬ!AE12 -> 4966.3282 | D15: =C15/C$18 -> 0.028252821 | E15: =D15+E14 -> 0.55368888 | F15: =IF(AND(E15<=0),"C",IF(E15<=0.8,"A",IF(E15<=0.95,"B","C"))) -> A | G15: =VLOOKUP(B$4:B$17,I$4:M$17,5,0) -> A | I15: черные с железкой классика | J15: =АПРЕЛЬ!R3 -> 9 | K15: =J15/J$18 -> 0.027108434 | L15: =K15+L14 -> 0.5 | M15: =_xlfn.IFS(L15<80%,"A",L15<=95%,"B",L15>95%,"C") -> A
B16: flip синий | C16: =АПРЕЛЬ!AE14 -> 1003.9555 | D16: =C16/C$18 -> 0.0057113772 | E16: =D16+E15 -> 0.55940025 | F16: =IF(AND(E16<=0),"C",IF(E16<=0.8,"A",IF(E16<=0.95,"B","C"))) -> A | G16: =VLOOKUP(B$4:B$17,I$4:M$17,5,0) -> A | I16: qs синие | J16: =АПРЕЛЬ!R5 -> 9 | K16: =J16/J$18 -> 0.027108434 | L16: =K16+L15 -> 0.52710843 | M16: =_xlfn.IFS(L16<80%,"A",L16<=95%,"B",L16>95%,"C") -> A
B17: черные с железкой классика | C17: =АПРЕЛЬ!AE3 -> -4463.8355 | D17: =C17/C$18 -> -0.025394203 | E17: =D17+E14 -> 0.50004185 | F17: =IF(AND(E17<=0),"C",IF(E17<=0.8,"A",IF(E17<=0.95,"B","C"))) -> A | G17: =VLOOKUP(B$4:B$17,I$4:M$17,5,0) -> A | I17: flip синий | J17: =АПРЕЛЬ!R14 -> 2 | K17: =J17/J$18 -> 0.0060240964 | L17: =K17+L14 -> 0.47891566 | M17: =_xlfn.IFS(L17<80%,"A",L17<=95%,"B",L17>95%,"C") -> A
C18: =SUM(C4:C17) -> 175781.68 | D18: =SUM(D4:D17) -> 1 | J18: =SUM(J4:J17) -> 332 | K18: =SUM(K4:K17) -> 1
C21: Прибыль | D21: % прибыль | E21: Доля | F21: ABC прибыль | G21: ABC кол-во | J21: Кол-во | K21: % кол-во | L21: Доля | M21: ABC кол-во
D22: =C22/C$42 -> #DIV/0! | E22: =D22 -> #DIV/0! | F22: =IF(AND(E22<=0),"C",IF(E22<=0.8,"A",IF(E22<=0.95,"B","C"))) -> #DIV/0! | G22: =VLOOKUP(B$22:B$42,I$22:M$42,5,0) -> #N/A | K22: =J22/J$42 -> #DIV/0! | L22: =K22 -> #DIV/0! | M22: =_xlfn.IFS(L22<80%,"A",L22<=95%,"B",L22>95%,"C") -> #DIV/0!
D23: =C23/C$42 -> #DIV/0! | E23: =D23+E22 -> #DIV/0! | F23: =IF(AND(E23<=0),"C",IF(E23<=0.8,"A",IF(E23<=0.95,"B","C"))) -> #DIV/0! | G23: =VLOOKUP(B$22:B$42,I$22:M$42,5,0) -> #N/A | K23: =J23/J$42 -> #DIV/0! | L23: =K23+L22 -> #DIV/0! | M23: =_xlfn.IFS(L23<80%,"A",L23<=95%,"B",L23>95%,"C") -> #DIV/0!
D24: =C24/C$42 -> #DIV/0! | E24: =D24+E23 -> #DIV/0! | F24: =IF(AND(E24<=0),"C",IF(E24<=0.8,"A",IF(E24<=0.95,"B","C"))) -> #DIV/0! | G24: =VLOOKUP(B$22:B$42,I$22:M$42,5,0) -> #N/A | K24: =J24/J$42 -> #DIV/0! | L24: =K24+L23 -> #DIV/0! | M24: =_xlfn.IFS(L24<80%,"A",L24<=95%,"B",L24>95%,"C") -> #DIV/0!
D25: =C25/C$42 -> #DIV/0! | E25: =D25+E24 -> #DIV/0! | F25: =IF(AND(E25<=0),"C",IF(E25<=0.8,"A",IF(E25<=0.95,"B","C"))) -> #DIV/0! | G25: =VLOOKUP(B$22:B$42,I$22:M$42,5,0) -> #N/A | K25: =J25/J$42 -> #DIV/0! | L25: =K25+L24 -> #DIV/0! | M25: =_xlfn.IFS(L25<80%,"A",L25<=95%,"B",L25>95%,"C") -> #DIV/0!
D26: =C26/C$42 -> #DIV/0! | E26: =D26+E25 -> #DIV/0! | F26: =IF(AND(E26<=0),"C",IF(E26<=0.8,"A",IF(E26<=0.95,"B","C"))) -> #DIV/0! | G26: =VLOOKUP(B$22:B$42,I$22:M$42,5,0) -> #N/A | K26: =J26/J$42 -> #DIV/0! | L26: =K26+L25 -> #DIV/0! | M26: =_xlfn.IFS(L26<80%,"A",L26<=95%,"B",L26>95%,"C") -> #DIV/0!
D27: =C27/C$42 -> #DIV/0! | E27: =D27+E26 -> #DIV/0! | F27: =IF(AND(E27<=0),"C",IF(E27<=0.8,"A",IF(E27<=0.95,"B","C"))) -> #DIV/0! | G27: =VLOOKUP(B$22:B$42,I$22:M$42,5,0) -> #N/A | K27: =J27/J$42 -> #DIV/0! | L27: =K27+L26 -> #DIV/0! | M27: =_xlfn.IFS(L27<80%,"A",L27<=95%,"B",L27>95%,"C") -> #DIV/0!
D28: =C28/C$42 -> #DIV/0! | E28: =D28+E27 -> #DIV/0! | F28: =IF(AND(E28<=0),"C",IF(E28<=0.8,"A",IF(E28<=0.95,"B","C"))) -> #DIV/0! | G28: =VLOOKUP(B$22:B$42,I$22:M$42,5,0) -> #N/A | K28: =J28/J$42 -> #DIV/0! | L28: =K28+L27 -> #DIV/0! | M28: =_xlfn.IFS(L28<80%,"A",L28<=95%,"B",L28>95%,"C") -> #DIV/0!
D29: =C29/C$42 -> #DIV/0! | E29: =D29+E28 -> #DIV/0! | F29: =IF(AND(E29<=0),"C",IF(E29<=0.8,"A",IF(E29<=0.95,"B","C"))) -> #DIV/0! | G29: =VLOOKUP(B$22:B$42,I$22:M$42,5,0) -> #N/A | K29: =J29/J$42 -> #DIV/0! | L29: =K29+L28 -> #DIV/0! | M29: =_xlfn.IFS(L29<80%,"A",L29<=95%,"B",L29>95%,"C") -> #DIV/0!
D30: =C30/C$42 -> #DIV/0! | E30: =D30+E29 -> #DIV/0! | F30: =IF(AND(E30<=0),"C",IF(E30<=0.8,"A",IF(E30<=0.95,"B","C"))) -> #DIV/0! | G30: =VLOOKUP(B$22:B$42,I$22:M$42,5,0) -> #N/A | K30: =J30/J$42 -> #DIV/0! | L30: =K30+L29 -> #DIV/0! | M30: =_xlfn.IFS(L30<80%,"A",L30<=95%,"B",L30>95%,"C") -> #DIV/0!
D31: =C31/C$42 -> #DIV/0! | E31: =D31+E30 -> #DIV/0! | F31: =IF(AND(E31<=0),"C",IF(E31<=0.8,"A",IF(E31<=0.95,"B","C"))) -> #DIV/0! | G31: =VLOOKUP(B$22:B$42,I$22:M$42,5,0) -> #N/A | K31: =J31/J$42 -> #DIV/0! | L31: =K31+L30 -> #DIV/0! | M31: =_xlfn.IFS(L31<80%,"A",L31<=95%,"B",L31>95%,"C") -> #DIV/0!
D32: =C32/C$42 -> #DIV/0! | E32: =D32+E31 -> #DIV/0! | F32: =IF(AND(E32<=0),"C",IF(E32<=0.8,"A",IF(E32<=0.95,"B","C"))) -> #DIV/0! | G32: =VLOOKUP(B$22:B$42,I$22:M$42,5,0) -> #N/A | K32: =J32/J$42 -> #DIV/0! | L32: =K32+L31 -> #DIV/0! | M32: =_xlfn.IFS(L32<80%,"A",L32<=95%,"B",L32>95%,"C") -> #DIV/0!
D33: =C33/C$42 -> #DIV/0! | E33: =D33+E32 -> #DIV/0! | F33: =IF(AND(E33<=0),"C",IF(E33<=0.8,"A",IF(E33<=0.95,"B","C"))) -> #DIV/0! | G33: =VLOOKUP(B$22:B$42,I$22:M$42,5,0) -> #N/A | K33: =J33/J$42 -> #DIV/0! | L33: =K33+L32 -> #DIV/0! | M33: =_xlfn.IFS(L33<80%,"A",L33<=95%,"B",L33>95%,"C") -> #DIV/0!
D34: =C34/C$42 -> #DIV/0! | E34: =D34+E33 -> #DIV/0! | F34: =IF(AND(E34<=0),"C",IF(E34<=0.8,"A",IF(E34<=0.95,"B","C"))) -> #DIV/0! | G34: =VLOOKUP(B$22:B$42,I$22:M$42,5,0) -> #N/A | K34: =J34/J$42 -> #DIV/0! | L34: =K34+L33 -> #DIV/0! | M34: =_xlfn.IFS(L34<80%,"A",L34<=95%,"B",L34>95%,"C") -> #DIV/0!
... D41: =C41/C$42 -> #DIV/0! | E41: =D41+E40 -> #DIV/0! | F41: =IF(AND(E41<=0),"C",IF(E41<=0.8,"A",IF(E41<=0.95,"B","C"))) -> #DIV/0! | G41: =VLOOKUP(B$22:B$42,I$22:M$42,5,0) -> #N/A | K41: =J41/J$42 -> #DIV/0! | L41: =K41+L40 -> #DIV/0! | M41: =_xlfn.IFS(L41<80%,"A",L41<=95%,"B",L41>95%,"C") -> #DIV/0!
C42: =SUM(C22:C41) -> 0 | D42: =SUM(D22:D41) -> #DIV/0! | J42: =SUM(J22:J41) -> 0 | K42: =SUM(K22:K41) -> #DIV/0!

Sheet АВС 27.04-03.05
B2: ОЧКИ
C3: Прибыль | D3: % прибыль | E3: Доля | F3: ABC прибыль | G3: ABC кол-во | J3: Кол-во | K3: % кол-во | L3: Доля | M3: ABC кол-во
B4: MR8854 C2 | C4: ='Юнит 27.04-03.05'!AE8 -> 7669.0155 | D4: =C4/C$18 -> 0.70327279 | E4: =D4 -> 0.70327279 | F4: =IF(AND(E4<=0),"C",IF(E4<=0.8,"A",IF(E4<=0.95,"B","C"))) -> A | G4: =VLOOKUP(B$4:B$17,I$4:M$17,5,0) -> A | I4: MR8854 C2 | J4: ='Юнит 27.04-03.05'!R8 -> 10 | K4: =J4/J$18 -> 0.25641026 | L4: =K4 -> 0.25641026 | M4: =_xlfn.IFS(L4<80%,"A",L4<=95%,"B",L4>95%,"C") -> A
B5: flip коричневый | C5: ='Юнит 27.04-03.05'!AE16 -> 4329.046 | D5: =C5/C$18 -> 0.3969871 | E5: =D5+E4 -> 1.1002599 | F5: =IF(AND(E5<=0),"C",IF(E5<=0.8,"A",IF(E5<=0.95,"B","C"))) -> C | G5: =VLOOKUP(B$4:B$17,I$4:M$17,5,0) -> A | I5: flip коричневый | J5: ='Юнит 27.04-03.05'!R16 -> 8 | K5: =J5/J$18 -> 0.20512821 | L5: =K5+L4 -> 0.46153846 | M5: =_xlfn.IFS(L5<80%,"A",L5<=95%,"B",L5>95%,"C") -> A
B6: flip черный | C6: ='Юнит 27.04-03.05'!AE13 -> 2163.6437 | D6: =C6/C$18 -> 0.19841291 | E6: =D6+E5 -> 1.2986728 | F6: =IF(AND(E6<=0),"C",IF(E6<=0.8,"A",IF(E6<=0.95,"B","C"))) -> C | G6: =VLOOKUP(B$4:B$17,I$4:M$17,5,0) -> A | I6: th коричн | J6: ='Юнит 27.04-03.05'!R12 -> 4 | K6: =J6/J$18 -> 0.1025641 | L6: =K6+L5 -> 0.56410256 | M6: =_xlfn.IFS(L6<80%,"A",L6<=95%,"B",L6>95%,"C") -> A
B7: flip синий | C7: ='Юнит 27.04-03.05'!AE14 -> 1607.7511 | D7: =C7/C$18 -> 0.14743582 | E7: =D7+E6 -> 1.4461086 | F7: =IF(AND(E7<=0),"C",IF(E7<=0.8,"A",IF(E7<=0.95,"B","C"))) -> C | G7: =VLOOKUP(B$4:B$17,I$4:M$17,5,0) -> A | I7: flip черный | J7: ='Юнит 27.04-03.05'!R13 -> 4 | K7: =J7/J$18 -> 0.1025641 | L7: =K7+L6 -> 0.66666667 | M7: =_xlfn.IFS(L7<80%,"A",L7<=95%,"B",L7>95%,"C") -> A
B8: qs черные | C8: ='Юнит 27.04-03.05'!AE4 -> 1494.0485 | D8: =C8/C$18 -> 0.13700893 | E8: =D8+E7 -> 1.5831176 | F8: =IF(AND(E8<=0),"C",IF(E8<=0.8,"A",IF(E8<=0.95,"B","C"))) -> C | G8: =VLOOKUP(B$4:B$17,I$4:M$17,5,0) -> A | I8: flip синий | J8: ='Юнит 27.04-03.05'!R14 -> 3 | K8: =J8/J$18 -> 0.076923077 | L8: =K8+L7 -> 0.74358974 | M8: =_xlfn.IFS(L8<80%,"A",L8<=95%,"B",L8>95%,"C") -> A
B9: th черн | C9: ='Юнит 27.04-03.05'!AE9 -> 1481.39 | D9: =C9/C$18 -> 0.13584811 | E9: =D9+E8 -> 1.7189657 | F9: =IF(AND(E9<=0),"C",IF(E9<=0.8,"A",IF(E9<=0.95,"B","C"))) -> C | G9: =VLOOKUP(B$4:B$17,I$4:M$17,5,0) -> B | I9: qs черные | J9: ='Юнит 27.04-03.05'!R4 -> 2 | K9: =J9/J$18 -> 0.051282051 | L9: =K9+L8 -> 0.79487179 | M9: =_xlfn.IFS(L9<80%,"A",L9<=95%,"B",L9>95%,"C") -> A
B10: th коричн | C10: ='Юнит 27.04-03.05'!AE12 -> 726.32 | D10: =C10/C$18 -> 0.066605823 | E10: =D10+E9 -> 1.7855715 | F10: =IF(AND(E10<=0),"C",IF(E10<=0.8,"A",IF(E10<=0.95,"B","C"))) -> C | G10: =VLOOKUP(B$4:B$17,I$4:M$17,5,0) -> A | I10: th черн | J10: ='Юнит 27.04-03.05'!R9 -> 2 | K10: =J10/J$18 -> 0.051282051 | L10: =K10+L9 -> 0.84615385 | M10: =_xlfn.IFS(L10<80%,"A",L10<=95%,"B",L10>95%,"C") -> B
B11: th син | C11: ='Юнит 27.04-03.05'!AE10 -> -110.76661 | D11: =C11/C$18 -> -0.010157646 | E11: =D11+E10 -> 1.7754138 | F11: =IF(AND(E11<=0),"C",IF(E11<=0.8,"A",IF(E11<=0.95,"B","C"))) -> C | G11: =VLOOKUP(B$4:B$17,I$4:M$17,5,0) -> A | I11: th желт | J11: ='Юнит 27.04-03.05'!R11 -> 2 | K11: =J11/J$18 -> 0.051282051 | L11: =K11+L10 -> 0.8974359 | M11: =_xlfn.IFS(L11<80%,"A",L11<=95%,"B",L11>95%,"C") -> B
B12: flip жел | C12: ='Юнит 27.04-03.05'!AE15 -> -302.98724 | D12: =C12/C$18 -> -0.027784881 | E12: =D12+E5 -> 1.072475 | F12: =IF(AND(E12<=0),"C",IF(E12<=0.8,"A",IF(E12<=0.95,"B","C"))) -> C | G12: =VLOOKUP(B$4:B$17,I$4:M$17,5,0) -> A | I12: flip жел | J12: ='Юнит 27.04-03.05'!R15 -> 2 | K12: =J12/J$18 -> 0.051282051 | L12: =K12+L5 -> 0.51282051 | M12: =_xlfn.IFS(L12<80%,"A",L12<=95%,"B",L12>95%,"C") -> A
B13: th желт | C13: ='Юнит 27.04-03.05'!AE11 -> -364.19507 | D13: =C13/C$18 -> -0.03339783 | E13: =D13+E12 -> 1.0390772 | F13: =IF(AND(E13<=0),"C",IF(E13<=0.8,"A",IF(E13<=0.95,"B","C"))) -> C | G13: =VLOOKUP(B$4:B$17,I$4:M$17,5,0) -> B | I13: qs синие | J13: ='Юнит 27.04-03.05'!R5 -> 1 | K13: =J13/J$18 -> 0.025641026 | L13: =K13+L12 -> 0.53846154 | M13: =_xlfn.IFS(L13<80%,"A",L13<=95%,"B",L13>95%,"C") -> A
B14: черные с железкой классика | C14: ='Юнит 27.04-03.05'!AE3 -> -1682.1187 | D14: =C14/C$18 -> -0.15425556 | E14: =D14+E13 -> 0.88482162 | F14: =IF(AND(E14<=0),"C",IF(E14<=0.8,"A",IF(E14<=0.95,"B","C"))) -> B | G14: =VLOOKUP(B$4:B$17,I$4:M$17,5,0) -> A | I14: th син | J14: ='Юнит 27.04-03.05'!R10 -> 1 | K14: =J14/J$18 -> 0.025641026 | L14: =K14+L13 -> 0.56410256 | M14: =_xlfn.IFS(L14<80%,"A",L14<=95%,"B",L14>95%,"C") -> A
B15: qs синие | C15: ='Юнит 27.04-03.05'!AE5 -> -1848.952 | D15: =C15/C$18 -> -0.1695547 | E15: =D15+E14 -> 0.71526692 | F15: =IF(AND(E15<=0),"C",IF(E15<=0.8,"A",IF(E15<=0.95,"B","C"))) -> A | G15: =VLOOKUP(B$4:B$17,I$4:M$17,5,0) -> A | I15: черные с железкой классика | J15: ='Юнит 27.04-03.05'!R3 -> 0 | K15: =J15/J$18 -> 0 | L15: =K15+L14 -> 0.56410256 | M15: =_xlfn.IFS(L15<80%,"A",L15<=95%,"B",L15>95%,"C") -> A
B16: qs желтые | C16: ='Юнит 27.04-03.05'!AE6 -> -2099.3921 | D16: =C16/C$18 -> -0.19252084 | E16: =D16+E15 -> 0.52274608 | F16: =IF(AND(E16<=0),"C",IF(E16<=0.8,"A",IF(E16<=0.95,"B","C"))) -> A | G16: =VLOOKUP(B$4:B$17,I$4:M$17,5,0) -> A | I16: qs желтые | J16: ='Юнит 27.04-03.05'!R6 -> 0 | K16: =J16/J$18 -> 0 | L16: =K16+L15 -> 0.56410256 | M16: =_xlfn.IFS(L16<80%,"A",L16<=95%,"B",L16>95%,"C") -> A
B17: qs коричневые | C17: ='Юнит 27.04-03.05'!AE7 -> -2158.0508 | D17: =C17/C$18 -> -0.19790003 | E17: =D17+E14 -> 0.68692158 | F17: =IF(AND(E17<=0),"C",IF(E17<=0.8,"A",IF(E17<=0.95,"B","C"))) -> A | G17: =VLOOKUP(B$4:B$17,I$4:M$17,5,0) -> A | I17: qs коричневые | J17: ='Юнит 27.04-03.05'!R7 -> 0 | K17: =J17/J$18 -> 0 | L17: =K17+L14 -> 0.56410256 | M17: =_xlfn.IFS(L17<80%,"A",L17<=95%,"B",L17>95%,"C") -> A
C18: =SUM(C4:C17) -> 10904.752 | D18: =SUM(D4:D17) -> 1 | J18: =SUM(J4:J17) -> 39 | K18: =SUM(K4:K17) -> 1
C21: Прибыль | D21: % прибыль | E21: Доля | F21: ABC прибыль | G21: ABC кол-во | J21: Кол-во | K21: % кол-во | L21: Доля | M21: ABC кол-во
D22: =C22/C$42 -> #DIV/0! | E22: =D22 -> #DIV/0! | F22: =IF(AND(E22<=0),"C",IF(E22<=0.8,"A",IF(E22<=0.95,"B","C"))) -> #DIV/0! | G22: =VLOOKUP(B$22:B$42,I$22:M$42,5,0) -> #N/A | K22: =J22/J$42 -> #DIV/0! | L22: =K22 -> #DIV/0! | M22: =_xlfn.IFS(L22<80%,"A",L22<=95%,"B",L22>95%,"C") -> #DIV/0!
D23: =C23/C$42 -> #DIV/0! | E23: =D23+E22 -> #DIV/0! | F23: =IF(AND(E23<=0),"C",IF(E23<=0.8,"A",IF(E23<=0.95,"B","C"))) -> #DIV/0! | G23: =VLOOKUP(B$22:B$42,I$22:M$42,5,0) -> #N/A | K23: =J23/J$42 -> #DIV/0! | L23: =K23+L22 -> #DIV/0! | M23: =_xlfn.IFS(L23<80%,"A",L23<=95%,"B",L23>95%,"C") -> #DIV/0!
D24: =C24/C$42 -> #DIV/0! | E24: =D24+E23 -> #DIV/0! | F24: =IF(AND(E24<=0),"C",IF(E24<=0.8,"A",IF(E24<=0.95,"B","C"))) -> #DIV/0! | G24: =VLOOKUP(B$22:B$42,I$22:M$42,5,0) -> #N/A | K24: =J24/J$42 -> #DIV/0! | L24: =K24+L23 -> #DIV/0! | M24: =_xlfn.IFS(L24<80%,"A",L24<=95%,"B",L24>95%,"C") -> #DIV/0!
D25: =C25/C$42 -> #DIV/0! | E25: =D25+E24 -> #DIV/0! | F25: =IF(AND(E25<=0),"C",IF(E25<=0.8,"A",IF(E25<=0.95,"B","C"))) -> #DIV/0! | G25: =VLOOKUP(B$22:B$42,I$22:M$42,5,0) -> #N/A | K25: =J25/J$42 -> #DIV/0! | L25: =K25+L24 -> #DIV/0! | M25: =_xlfn.IFS(L25<80%,"A",L25<=95%,"B",L25>95%,"C") -> #DIV/0!
D26: =C26/C$42 -> #DIV/0! | E26: =D26+E25 -> #DIV/0! | F26: =IF(AND(E26<=0),"C",IF(E26<=0.8,"A",IF(E26<=0.95,"B","C"))) -> #DIV/0! | G26: =VLOOKUP(B$22:B$42,I$22:M$42,5,0) -> #N/A | K26: =J26/J$42 -> #DIV/0! | L26: =K26+L25 -> #DIV/0! | M26: =_xlfn.IFS(L26<80%,"A",L26<=95%,"B",L26>95%,"C") -> #DIV/0!
D27: =C27/C$42 -> #DIV/0! | E27: =D27+E26 -> #DIV/0! | F27: =IF(AND(E27<=0),"C",IF(E27<=0.8,"A",IF(E27<=0.95,"B","C"))) -> #DIV/0! | G27: =VLOOKUP(B$22:B$42,I$22:M$42,5,0) -> #N/A | K27: =J27/J$42 -> #DIV/0! | L27: =K27+L26 -> #DIV/0! | M27: =_xlfn.IFS(L27<80%,"A",L27<=95%,"B",L27>95%,"C") -> #DIV/0!
D28: =C28/C$42 -> #DIV/0! | E28: =D28+E27 -> #DIV/0! | F28: =IF(AND(E28<=0),"C",IF(E28<=0.8,"A",IF(E28<=0.95,"B","C"))) -> #DIV/0! | G28: =VLOOKUP(B$22:B$42,I$22:M$42,5,0) -> #N/A | K28: =J28/J$42 -> #DIV/0! | L28: =K28+L27 -> #DIV/0! | M28: =_xlfn.IFS(L28<80%,"A",L28<=95%,"B",L28>95%,"C") -> #DIV/0!
D29: =C29/C$42 -> #DIV/0! | E29: =D29+E28 -> #DIV/0! | F29: =IF(AND(E29<=0),"C",IF(E29<=0.8,"A",IF(E29<=0.95,"B","C"))) -> #DIV/0! | G29: =VLOOKUP(B$22:B$42,I$22:M$42,5,0) -> #N/A | K29: =J29/J$42 -> #DIV/0! | L29: =K29+L28 -> #DIV/0! | M29: =_xlfn.IFS(L29<80%,"A",L29<=95%,"B",L29>95%,"C") -> #DIV/0!
D30: =C30/C$42 -> #DIV/0! | E30: =D30+E29 -> #DIV/0! | F30: =IF(AND(E30<=0),"C",IF(E30<=0.8,"A",IF(E30<=0.95,"B","C"))) -> #DIV/0! | G30: =VLOOKUP(B$22:B$42,I$22:M$42,5,0) -> #N/A | K30: =J30/J$42 -> #DIV/0! | L30: =K30+L29 -> #DIV/0! | M30: =_xlfn.IFS(L30<80%,"A",L30<=95%,"B",L30>95%,"C") -> #DIV/0!
D31: =C31/C$42 -> #DIV/0! | E31: =D31+E30 -> #DIV/0! | F31: =IF(AND(E31<=0),"C",IF(E31<=0.8,"A",IF(E31<=0.95,"B","C"))) -> #DIV/0! | G31: =VLOOKUP(B$22:B$42,I$22:M$42,5,0) -> #N/A | K31: =J31/J$42 -> #DIV/0! | L31: =K31+L30 -> #DIV/0! | M31: =_xlfn.IFS(L31<80%,"A",L31<=95%,"B",L31>95%,"C") -> #DIV/0!
D32: =C32/C$42 -> #DIV/0! | E32: =D32+E31 -> #DIV/0! | F32: =IF(AND(E32<=0),"C",IF(E32<=0.8,"A",IF(E32<=0.95,"B","C"))) -> #DIV/0! | G32: =VLOOKUP(B$22:B$42,I$22:M$42,5,0) -> #N/A | K32: =J32/J$42 -> #DIV/0! | L32: =K32+L31 -> #DIV/0! | M32: =_xlfn.IFS(L32<80%,"A",L32<=95%,"B",L32>95%,"C") -> #DIV/0!
D33: =C33/C$42 -> #DIV/0! | E33: =D33+E32 -> #DIV/0! | F33: =IF(AND(E33<=0),"C",IF(E33<=0.8,"A",IF(E33<=0.95,"B","C"))) -> #DIV/0! | G33: =VLOOKUP(B$22:B$42,I$22:M$42,5,0) -> #N/A | K33: =J33/J$42 -> #DIV/0! | L33: =K33+L32 -> #DIV/0! | M33: =_xlfn.IFS(L33<80%,"A",L33<=95%,"B",L33>95%,"C") -> #DIV/0!
D34: =C34/C$42 -> #DIV/0! | E34: =D34+E33 -> #DIV/0! | F34: =IF(AND(E34<=0),"C",IF(E34<=0.8,"A",IF(E34<=0.95,"B","C"))) -> #DIV/0! | G34: =VLOOKUP(B$22:B$42,I$22:M$42,5,0) -> #N/A | K34: =J34/J$42 -> #DIV/0! | L34: =K34+L33 -> #DIV/0! | M34: =_xlfn.IFS(L34<80%,"A",L34<=95%,"B",L34>95%,"C") -> #DIV/0!
... D41: =C41/C$42 -> #DIV/0! | E41: =D41+E40 -> #DIV/0! | F41: =IF(AND(E41<=0),"C",IF(E41<=0.8,"A",IF(E41<=0.95,"B","C"))) -> #DIV/0! | G41: =VLOOKUP(B$22:B$42,I$22:M$42,5,0) -> #N/A | K41: =J41/J$42 -> #DIV/0! | L41: =K41+L40 -> #DIV/0! | M41: =_xlfn.IFS(L41<80%,"A",L41<=95%,"B",L41>95%,"C") -> #DIV/0!
C42: =SUM(C22:C41) -> 0 | D42: =SUM(D22:D41) -> #DIV/0! | J42: =SUM(J22:J41) -> 0 | K42: =SUM(K22:K41) -> #DIV/0!

Sheet АВС 20-26.04
B2: ОЧКИ
C3: Прибыль | D3: % прибыль | E3: Доля | F3: ABC прибыль | G3: ABC кол-во | J3: Кол-во | K3: % кол-во | L3: Доля | M3: ABC кол-во
B4: MR8854 C2 | C4: ='Юнит 20-26.04'!AE8 -> 9074.2386 | D4: =C4/C$18 -> 0.57883583 | E4: =D4 -> 0.57883583 | F4: =IF(AND(E4<=0),"C",IF(E4<=0.8,"A",IF(E4<=0.95,"B","C"))) -> A | G4: =VLOOKUP(B$4:B$17,I$4:M$17,5,0) -> A | I4: MR8854 C2 | J4: ='Юнит 20-26.04'!R8 -> 12 | K4: =J4/J$18 -> 0.33333333 | L4: =K4 -> 0.33333333 | M4: =_xlfn.IFS(L4<80%,"A",L4<=95%,"B",L4>95%,"C") -> A
B5: flip коричневый | C5: ='Юнит 20-26.04'!AE16 -> 3982.1712 | D5: =C5/C$18 -> 0.25401838 | E5: =D5+E4 -> 0.8328542 | F5: =IF(AND(E5<=0),"C",IF(E5<=0.8,"A",IF(E5<=0.95,"B","C"))) -> B | G5: =VLOOKUP(B$4:B$17,I$4:M$17,5,0) -> A | I5: flip коричневый | J5: ='Юнит 20-26.04'!R16 -> 7 | K5: =J5/J$18 -> 0.19444444 | L5: =K5+L4 -> 0.52777778 | M5: =_xlfn.IFS(L5<80%,"A",L5<=95%,"B",L5>95%,"C") -> A
B6: qs коричневые | C6: ='Юнит 20-26.04'!AE7 -> 2844.3806 | D6: =C6/C$18 -> 0.18143995 | E6: =D6+E5 -> 1.0142942 | F6: =IF(AND(E6<=0),"C",IF(E6<=0.8,"A",IF(E6<=0.95,"B","C"))) -> C | G6: =VLOOKUP(B$4:B$17,I$4:M$17,5,0) -> A | I6: th коричн | J6: ='Юнит 20-26.04'!R12 -> 5 | K6: =J6/J$18 -> 0.13888889 | L6: =K6+L5 -> 0.66666667 | M6: =_xlfn.IFS(L6<80%,"A",L6<=95%,"B",L6>95%,"C") -> A
B7: th коричн | C7: ='Юнит 20-26.04'!AE12 -> 2346.3737 | D7: =C7/C$18 -> 0.14967263 | E7: =D7+E6 -> 1.1639668 | F7: =IF(AND(E7<=0),"C",IF(E7<=0.8,"A",IF(E7<=0.95,"B","C"))) -> C | G7: =VLOOKUP(B$4:B$17,I$4:M$17,5,0) -> A | I7: qs коричневые | J7: ='Юнит 20-26.04'!R7 -> 3 | K7: =J7/J$18 -> 0.083333333 | L7: =K7+L6 -> 0.75 | M7: =_xlfn.IFS(L7<80%,"A",L7<=95%,"B",L7>95%,"C") -> A
B8: th син | C8: ='Юнит 20-26.04'!AE10 -> 1016.4912 | D8: =C8/C$18 -> 0.064840871 | E8: =D8+E7 -> 1.2288077 | F8: =IF(AND(E8<=0),"C",IF(E8<=0.8,"A",IF(E8<=0.95,"B","C"))) -> C | G8: =VLOOKUP(B$4:B$17,I$4:M$17,5,0) -> A | I8: flip черный | J8: ='Юнит 20-26.04'!R13 -> 3 | K8: =J8/J$18 -> 0.083333333 | L8: =K8+L7 -> 0.83333333 | M8: =_xlfn.IFS(L8<80%,"A",L8<=95%,"B",L8>95%,"C") -> B
B9: th черн | C9: ='Юнит 20-26.04'!AE9 -> 380.08184 | D9: =C9/C$18 -> 0.024245008 | E9: =D9+E8 -> 1.2530527 | F9: =IF(AND(E9<=0),"C",IF(E9<=0.8,"A",IF(E9<=0.95,"B","C"))) -> C | G9: =VLOOKUP(B$4:B$17,I$4:M$17,5,0) -> A | I9: черные с железкой классика | J9: ='Юнит 20-26.04'!R3 -> 1 | K9: =J9/J$18 -> 0.027777778 | L9: =K9+L8 -> 0.86111111 | M9: =_xlfn.IFS(L9<80%,"A",L9<=95%,"B",L9>95%,"C") -> B
B10: flip черный | C10: ='Юнит 20-26.04'!AE13 -> 259.78018 | D10: =C10/C$18 -> 0.016571096 | E10: =D10+E9 -> 1.2696238 | F10: =IF(AND(E10<=0),"C",IF(E10<=0.8,"A",IF(E10<=0.95,"B","C"))) -> C | G10: =VLOOKUP(B$4:B$17,I$4:M$17,5,0) -> B | I10: qs черные | J10: ='Юнит 20-26.04'!R4 -> 1 | K10: =J10/J$18 -> 0.027777778 | L10: =K10+L9 -> 0.88888889 | M10: =_xlfn.IFS(L10<80%,"A",L10<=95%,"B",L10>95%,"C") -> B
B11: черные с железкой классика | C11: ='Юнит 20-26.04'!AE3 -> 145.88777 | D11: =C11/C$18 -> 0.0093060227 | E11: =D11+E10 -> 1.2789298 | F11: =IF(AND(E11<=0),"C",IF(E11<=0.8,"A",IF(E11<=0.95,"B","C"))) -> C | G11: =VLOOKUP(B$4:B$17,I$4:M$17,5,0) -> B | I11: qs синие | J11: ='Юнит 20-26.04'!R5 -> 1 | K11: =J11/J$18 -> 0.027777778 | L11: =K11+L10 -> 0.91666667 | M11: =_xlfn.IFS(L11<80%,"A",L11<=95%,"B",L11>95%,"C") -> B
B12: flip синий | C12: ='Юнит 20-26.04'!AE14 -> -148 | D12: =C12/C$18 -> -0.0094407593 | E12: =D12+E5 -> 0.82341345 | F12: =IF(AND(E12<=0),"C",IF(E12<=0.8,"A",IF(E12<=0.95,"B","C"))) -> B | G12: =VLOOKUP(B$4:B$17,I$4:M$17,5,0) -> A | I12: th черн | J12: ='Юнит 20-26.04'!R9 -> 1 | K12: =J12/J$18 -> 0.027777778 | L12: =K12+L5 -> 0.55555556 | M12: =_xlfn.IFS(L12<80%,"A",L12<=95%,"B",L12>95%,"C") -> A
B13: qs желтые | C13: ='Юнит 20-26.04'!AE6 -> -369.15267 | D13: =C13/C$18 -> -0.023547848 | E13: =D13+E12 -> 0.7998656 | F13: =IF(AND(E13<=0),"C",IF(E13<=0.8,"A",IF(E13<=0.95,"B","C"))) -> A | G13: =VLOOKUP(B$4:B$17,I$4:M$17,5,0) -> A | I13: th син | J13: ='Юнит 20-26.04'!R10 -> 1 | K13: =J13/J$18 -> 0.027777778 | L13: =K13+L12 -> 0.58333333 | M13: =_xlfn.IFS(L13<80%,"A",L13<=95%,"B",L13>95%,"C") -> A
B14: th желт | C14: ='Юнит 20-26.04'!AE11 -> -436.36797 | D14: =C14/C$18 -> -0.027835439 | E14: =D14+E13 -> 0.77203016 | F14: =IF(AND(E14<=0),"C",IF(E14<=0.8,"A",IF(E14<=0.95,"B","C"))) -> A | G14: =VLOOKUP(B$4:B$17,I$4:M$17,5,0) -> A | I14: th желт | J14: ='Юнит 20-26.04'!R11 -> 1 | K14: =J14/J$18 -> 0.027777778 | L14: =K14+L13 -> 0.61111111 | M14: =_xlfn.IFS(L14<80%,"A",L14<=95%,"B",L14>95%,"C") -> A
B15: qs синие | C15: ='Юнит 20-26.04'!AE5 -> -866.40135 | D15: =C15/C$18 -> -0.055266802 | E15: =D15+E14 -> 0.71676336 | F15: =IF(AND(E15<=0),"C",IF(E15<=0.8,"A",IF(E15<=0.95,"B","C"))) -> A | G15: =VLOOKUP(B$4:B$17,I$4:M$17,5,0) -> B | I15: qs желтые | J15: ='Юнит 20-26.04'!R6 -> 0 | K15: =J15/J$18 -> 0 | L15: =K15+L14 -> 0.61111111 | M15: =_xlfn.IFS(L15<80%,"A",L15<=95%,"B",L15>95%,"C") -> A
B16: flip жел | C16: ='Юнит 20-26.04'!AE15 -> -999.75776 | D16: =C16/C$18 -> -0.063773462 | E16: =D16+E15 -> 0.65298989 | F16: =IF(AND(E16<=0),"C",IF(E16<=0.8,"A",IF(E16<=0.95,"B","C"))) -> A | G16: =VLOOKUP(B$4:B$17,I$4:M$17,5,0) -> A | I16: flip синий | J16: ='Юнит 20-26.04'!R14 -> 0 | K16: =J16/J$18 -> 0 | L16: =K16+L15 -> 0.61111111 | M16: =_xlfn.IFS(L16<80%,"A",L16<=95%,"B",L16>95%,"C") -> A
B17: qs черные | C17: ='Юнит 20-26.04'!AE4 -> -1553.0202 | D17: =C17/C$18 -> -0.099065474 | E17: =D17+E14 -> 0.67296468 | F17: =IF(AND(E17<=0),"C",IF(E17<=0.8,"A",IF(E17<=0.95,"B","C"))) -> A | G17: =VLOOKUP(B$4:B$17,I$4:M$17,5,0) -> B | I17: flip жел | J17: ='Юнит 20-26.04'!R15 -> 0 | K17: =J17/J$18 -> 0 | L17: =K17+L14 -> 0.61111111 | M17: =_xlfn.IFS(L17<80%,"A",L17<=95%,"B",L17>95%,"C") -> A
C18: =SUM(C4:C17) -> 15676.705 | D18: =SUM(D4:D17) -> 1 | J18: =SUM(J4:J17) -> 36 | K18: =SUM(K4:K17) -> 1
C21: Прибыль | D21: % прибыль | E21: Доля | F21: ABC прибыль | G21: ABC кол-во | J21: Кол-во | K21: % кол-во | L21: Доля | M21: ABC кол-во
D22: =C22/C$42 -> #DIV/0! | E22: =D22 -> #DIV/0! | F22: =IF(AND(E22<=0),"C",IF(E22<=0.8,"A",IF(E22<=0.95,"B","C"))) -> #DIV/0! | G22: =VLOOKUP(B$22:B$42,I$22:M$42,5,0) -> #N/A | K22: =J22/J$42 -> #DIV/0! | L22: =K22 -> #DIV/0! | M22: =_xlfn.IFS(L22<80%,"A",L22<=95%,"B",L22>95%,"C") -> #DIV/0!
D23: =C23/C$42 -> #DIV/0! | E23: =D23+E22 -> #DIV/0! | F23: =IF(AND(E23<=0),"C",IF(E23<=0.8,"A",IF(E23<=0.95,"B","C"))) -> #DIV/0! | G23: =VLOOKUP(B$22:B$42,I$22:M$42,5,0) -> #N/A | K23: =J23/J$42 -> #DIV/0! | L23: =K23+L22 -> #DIV/0! | M23: =_xlfn.IFS(L23<80%,"A",L23<=95%,"B",L23>95%,"C") -> #DIV/0!
D24: =C24/C$42 -> #DIV/0! | E24: =D24+E23 -> #DIV/0! | F24: =IF(AND(E24<=0),"C",IF(E24<=0.8,"A",IF(E24<=0.95,"B","C"))) -> #DIV/0! | G24: =VLOOKUP(B$22:B$42,I$22:M$42,5,0) -> #N/A | K24: =J24/J$42 -> #DIV/0! | L24: =K24+L23 -> #DIV/0! | M24: =_xlfn.IFS(L24<80%,"A",L24<=95%,"B",L24>95%,"C") -> #DIV/0!
D25: =C25/C$42 -> #DIV/0! | E25: =D25+E24 -> #DIV/0! | F25: =IF(AND(E25<=0),"C",IF(E25<=0.8,"A",IF(E25<=0.95,"B","C"))) -> #DIV/0! | G25: =VLOOKUP(B$22:B$42,I$22:M$42,5,0) -> #N/A | K25: =J25/J$42 -> #DIV/0! | L25: =K25+L24 -> #DIV/0! | M25: =_xlfn.IFS(L25<80%,"A",L25<=95%,"B",L25>95%,"C") -> #DIV/0!
D26: =C26/C$42 -> #DIV/0! | E26: =D26+E25 -> #DIV/0! | F26: =IF(AND(E26<=0),"C",IF(E26<=0.8,"A",IF(E26<=0.95,"B","C"))) -> #DIV/0! | G26: =VLOOKUP(B$22:B$42,I$22:M$42,5,0) -> #N/A | K26: =J26/J$42 -> #DIV/0! | L26: =K26+L25 -> #DIV/0! | M26: =_xlfn.IFS(L26<80%,"A",L26<=95%,"B",L26>95%,"C") -> #DIV/0!
D27: =C27/C$42 -> #DIV/0! | E27: =D27+E26 -> #DIV/0! | F27: =IF(AND(E27<=0),"C",IF(E27<=0.8,"A",IF(E27<=0.95,"B","C"))) -> #DIV/0! | G27: =VLOOKUP(B$22:B$42,I$22:M$42,5,0) -> #N/A | K27: =J27/J$42 -> #DIV/0! | L27: =K27+L26 -> #DIV/0! | M27: =_xlfn.IFS(L27<80%,"A",L27<=95%,"B",L27>95%,"C") -> #DIV/0!
D28: =C28/C$42 -> #DIV/0! | E28: =D28+E27 -> #DIV/0! | F28: =IF(AND(E28<=0),"C",IF(E28<=0.8,"A",IF(E28<=0.95,"B","C"))) -> #DIV/0! | G28: =VLOOKUP(B$22:B$42,I$22:M$42,5,0) -> #N/A | K28: =J28/J$42 -> #DIV/0! | L28: =K28+L27 -> #DIV/0! | M28: =_xlfn.IFS(L28<80%,"A",L28<=95%,"B",L28>95%,"C") -> #DIV/0!
