Workbook

Sheet Сводная
A1: Период | D1: Итого к перечислению на счет, руб | E1: шт. | H1: Выручка | K1: Себестоимость продаж | L1: Логистика | M1: Комиссия | N1: Хранение | O1: Платная приемка | P1: Штрафы | Q1: Реклама Ozon | R1: Услуги партнёров | S1: Другие услуги и штрафы | T1: Услуги FBO | U1: Компенсировано | V1: Пополнение рекламного кабинета | W1: ЕАЭС | X1: Налог | Y1: Прибыль до вычета налогов | Z1: Прибыль после вычета налогов | AA1: Итог месяц | AB1: % Cебестоимости | AC1: Маржинальность, % | AD1: Рентабельность, % | AE1: Доля рекламы, %
A2: Месяц | B2: Даты | C2: Нед | E2: Заказы | F2: Продажи | G2: Возвраты | H2: Продажи | I2: Возвраты | J2: Общая
A3: Январь | B3: 01-04.01 | C3: 1 | D3: =J3-SUM(L3:T3)+U3+V3 -> 1074.71 | E3: ='Юнит 01-04.01'!K$24 -> 122 | F3: ='Юнит 01-04.01'!P$24 -> 51 | G3: ='Юнит 01-04.01'!Q$24 -> 1 | H3: ='Юнит 01-04.01'!S$24 -> 85937 | I3: ='Юнит 01-04.01'!T$24 -> -1600 | J3: =H3+I3 -> 84337 | K3: ='Юнит 01-04.01'!W$24 -> 6252.96 | L3: ='Юнит 01-04.01'!Z$24 -> 8548.62 | M3: ='Юнит 01-04.01'!X$24 -> 36264.91 | Q3: ='Юнит 01-04.01'!AA$24 -> 36772.95 | R3: 1675.81 | W3: 5252 | X3: =3481.9416*J3/SUM($J$3:$J$7) -> 322.35231 | Y3: =J3-SUM(L3:T3)-K3-V3+U3+W3 -> 73.75 | Z3: =Y3-X3 -> -248.60231 | AA3: =SUM(Z3:Z7) -> 49559.258 | AB3: =K3/J3 -> 0.074142547 | AC3: =Z3/K3 -> -0.039757541 | AD3: =Z3/J3 -> -0.0029477253 | AE3: =Q3/J3 -> 0.43602393
B4: 05-11.01 | C4: 2 | D4: =J4-SUM(L4:T4)+U4+V4 -> 57707.57 | E4: ='Юнит 05-11.01'!K$24 -> 183 | F4: ='Юнит 05-11.01'!P$24 -> 168 | G4: ='Юнит 05-11.01'!Q$24 -> 8 | H4: ='Юнит 05-11.01'!S$24 -> 277715 | I4: ='Юнит 05-11.01'!T$24 -> -13822 | J4: =H4+I4 -> 263893 | K4: ='Юнит 05-11.01'!W$24 -> 20205.96 | L4: ='Юнит 05-11.01'!Z$24 -> 28076.33 | M4: ='Юнит 05-11.01'!X$24 -> 113473.99 | Q4: ='Юнит 05-11.01'!AA$24 -> 56365.38 | R4: 4144.33 | S4: 75 | T4: 4050.4 | X4: =3481.9416*J4/SUM($J$3:$J$7) -> 1008.65 | Y4: =J4-SUM(L4:T4)-K4-V4+U4+W4 -> 37501.61 | Z4: =Y4-X4 -> 36492.96 | AB4: =K4/J4 -> 0.076568761 | AC4: =Z4/K4 -> 1.8060493 | AD4: =Z4/J4 -> 0.13828696 | AE4: =Q4/J4 -> 0.2135918
B5: 12-18.01 | C5: 3 | D5: =J5-SUM(L5:T5)+U5+V5 -> 36064.15 | E5: ='Юнит 12-18.01'!K$24 -> 144 | F5: ='Юнит 12-18.01'!P$24 -> 122 | G5: ='Юнит 12-18.01'!Q$24 -> 2 | H5: ='Юнит 12-18.01'!S$24 -> 211029 | I5: ='Юнит 12-18.01'!T$24 -> -3221 | J5: =H5+I5 -> 207808 | K5: ='Юнит 12-18.01'!W$24 -> 15093.09 | L5: ='Юнит 12-18.01'!Z$24 -> 24172.28 | M5: ='Юнит 12-18.01'!X$24 -> 89357.44 | Q5: ='Юнит 12-18.01'!AA$24 -> 53249.12 | R5: 4025.01 | S5: 0 | T5: 940 | W5: 5135 | X5: =3481.9416*J5/SUM($J$3:$J$7) -> 794.28233 | Y5: =J5-SUM(L5:T5)-K5-V5+U5+W5 -> 26106.06 | Z5: =Y5-X5 -> 25311.778 | AB5: =K5/J5 -> 0.072629976 | AC5: =Z5/K5 -> 1.6770441 | AD5: =Z5/J5 -> 0.12180367 | AE5: =Q5/J5 -> 0.25624192
B6: 19-25.01 | C6: 4 | D6: =J6-SUM(L6:T6)+U6+V6 -> 34413.47 | E6: ='Юнит 19-25.01'!K$24 -> 154 | F6: ='Юнит 19-25.01'!P$24 -> 91 | G6: ='Юнит 19-25.01'!Q$24 -> 2 | H6: ='Юнит 19-25.01'!S$24 -> 161208 | I6: ='Юнит 19-25.01'!T$24 -> -3229 | J6: =H6+I6 -> 157979 | K6: ='Юнит 19-25.01'!W$24 -> 11132.49 | L6: ='Юнит 19-25.01'!Z$24 -> 16989.46 | M6: ='Юнит 19-25.01'!X$24 -> 67930.97 | Q6: ='Юнит 19-25.01'!AA$24 -> 42151.21 | R6: 3468.89 | S6: 25 | V6: 7000 | X6: =3481.9416*J6/SUM($J$3:$J$7) -> 603.82627 | Y6: =J6-SUM(L6:T6)-K6-V6+U6+W6 -> 9280.98 | Z6: =Y6-X6 -> 8677.1537 | AB6: =K6/J6 -> 0.070468163 | AC6: =Z6/K6 -> 0.77944411 | AD6: =Z6/J6 -> 0.054925995 | AE6: =Q6/J6 -> 0.26681527
B7: 26-31.01 | C7: 5 | D7: =J7-SUM(L7:T7)+U7+V7 -> -6034.71 | E7: ='Юнит 26-31.01'!K$24 -> 200 | F7: ='Юнит 26-31.01'!P$24 -> 112 | G7: ='Юнит 26-31.01'!Q$24 -> 2 | H7: ='Юнит 26-31.01'!S$24 -> 200558 | I7: ='Юнит 26-31.01'!T$24 -> -3595 | J7: =H7+I7 -> 196963 | K7: ='Юнит 26-31.01'!W$24 -> 13886.49 | L7: ='Юнит 26-31.01'!Z$24 -> 20843.55 | M7: ='Юнит 26-31.01'!X$24 -> 84694.09 | Q7: ='Юнит 26-31.01'!AA$24 -> 50770.67 | R7: 3661.19 | S7: 150 | T7: 43993.6 | U7: 1115.39 | X7: =3481.9416*J7/SUM($J$3:$J$7) -> 752.83065 | Y7: =J7-SUM(L7:T7)-K7-V7+U7+W7 -> -19921.2 | Z7: =Y7-X7 -> -20674.031 | AB7: =(K7+K8)/(J7+J8) -> 0.070282074 | AC7: =(Z7+Z8)/(K7+K8) -> -0.67605169 | AD7: =(Z7+Z8)/(J7+J8) -> -0.047514315 | AE7: =(Q7+Q8)/(J7+J8) -> 0.25406002
A8: Февраль | B8: 01.02-01.02 | C8: 5 | D8: =J8-SUM(L8:T8)+U8+V8 -> 7323.99 | E8: ='Юнит 01.02'!K$24 -> 36 | F8: ='Юнит 01.02'!P$24 -> 19 | G8: ='Юнит 01.02'!Q$24 -> 1 | H8: ='Юнит 01.02'!S$24 -> 34372 | I8: ='Юнит 01.02'!T$24 -> -1750 | J8: =H8+I8 -> 32622 | K8: ='Юнит 01.02'!W$24 -> 2249.22 | L8: ='Юнит 01.02'!Z$24 -> 3179.52 | M8: ='Юнит 01.02'!X$24 -> 14027.46 | Q8: ='Юнит 01.02'!AA$24 -> 7557.7 | R8: 533.33 | W8: 4831 | X8: =5201.48*J8/SUM($J$8:$J$12) -> 140.3134 | Y8: =J8-SUM(L8:T8)-K8-V8+U8+W8 -> 9905.77 | Z8: =Y8-X8 -> 9765.4566 | AA8: =SUM(Z8:Z12) -> 174317.71
B9: 02.02-08.02 | C9: 6 | D9: =J9-SUM(L9:T9)+U9+V9 -> 40049.95 | E9: ='Юнит 02-08.02'!K$24 -> 225 | F9: ='Юнит 02-08.02'!P$24 -> 167 | G9: ='Юнит 02-08.02'!Q$24 -> 11 | H9: ='Юнит 02-08.02'!S$24 -> 323134 | I9: ='Юнит 02-08.02'!T$24 -> -22524 | J9: =H9+I9 -> 300610 | K9: ='Юнит 02-08.02'!W$24 -> 19848.12 | L9: ='Юнит 02-08.02'!Z$24 -> 31123.53 | M9: ='Юнит 02-08.02'!X$24 -> 129262.3 | Q9: ='Юнит 02-08.02'!AA$24 -> 66736.42 | R9: 5825.9 | T9: 27611.9 | X9: =5201.48*J9/SUM($J$8:$J$12) -> 1292.9806 | Y9: =J9-SUM(L9:T9)-K9-V9+U9+W9 -> 20201.83 | Z9: =Y9-X9 -> 18908.849 | AB9: =K9/J9 -> 0.066026147 | AC9: =Z9/K9 -> 0.9526771 | AD9: =Z9/J9 -> 0.062901598 | AE9: =Q9/J9 -> 0.22200333
B10: 09-15.02 | C10: 7 | D10: =J10-SUM(L10:T10)+U10+V10 -> 62513.5 | E10: ='Юнит 09-15.02'!K$24 -> 240 | F10: ='Юнит 09-15.02'!P$24 -> 125 | G10: ='Юнит 09-15.02'!Q$24 -> 4 | H10: ='Юнит 09-15.02'!S$24 -> 282164 | I10: ='Юнит 09-15.02'!T$24 -> -9000 | J10: =H10+I10 -> 273164 | K10: ='Юнит 09-15.02'!W$24 -> 15306.15 | L10: ='Юнит 09-15.02'!Z$24 -> 24192.27 | M10: ='Юнит 09-15.02'!X$24 -> 117460.52 | Q10: ='Юнит 09-15.02'!AA$24 -> 61070.11 | R10: 5828.6 | S10: 175 | T10: 1924 | X10: =5201.48*J10/SUM($J$8:$J$12) -> 1174.9301 | Y10: =J10-SUM(L10:T10)-K10-V10+U10+W10 -> 47207.35 | Z10: =Y10-X10 -> 46032.42 | AB10: =K10/J10 -> 0.056032823 | AC10: =Z10/K10 -> 3.007446 | AD10: =Z10/J10 -> 0.16851569 | AE10: =Q10/J10 -> 0.22356573
B11: 16-22.02 | C11: 8 | D11: =J11-SUM(L11:T11)+U11+V11 -> 82376.34 | E11: ='Юнит 16-22.02'!K$24 -> 298 | F11: ='Юнит 16-22.02'!P$24 -> 161 | G11: ='Юнит 16-22.02'!Q$24 -> 8 | H11: ='Юнит 16-22.02'!S$24 -> 373392 | I11: ='Юнит 16-22.02'!T$24 -> -18750 | J11: =H11+I11 -> 354642 | K11: ='Юнит 16-22.02'!W$24 -> 19197.06 | L11: ='Юнит 16-22.02'!Z$24 -> 31757.74 | M11: ='Юнит 16-22.02'!X$24 -> 152496.06 | Q11: ='Юнит 16-22.02'!AA$24 -> 79962.77 | R11: 8049.09 | W11: 4347 | X11: =5201.48*J11/SUM($J$8:$J$12) -> 1525.3824 | Y11: =J11-SUM(L11:T11)-K11-V11+U11+W11 -> 67526.28 | Z11: =Y11-X11 -> 66000.898 | AB11: =K11/J11 -> 0.054130814 | AC11: =Z11/K11 -> 3.4380732 | AD11: =Z11/J11 -> 0.1861057 | AE11: =Q11/J11 -> 0.22547462
B12: 23-28.02 | C12: 9 | D12: =J12-SUM(L12:T12)+U12+V12 -> 47866.26 | E12: ='Юнит 23-28.02'!K$24 -> 159 | F12: ='Юнит 23-28.02'!P$24 -> 107 | G12: ='Юнит 23-28.02'!Q$24 -> 6 | H12: ='Юнит 23-28.02'!S$24 -> 262374 | I12: ='Юнит 23-28.02'!T$24 -> -14100 | J12: =H12+I12 -> 248274 | K12: ='Юнит 23-28.02'!W$24 -> 13188.3 | L12: ='Юнит 23-28.02'!Z$24 -> 25365.95 | M12: ='Юнит 23-28.02'!X$24 -> 106757.82 | Q12: ='Юнит 23-28.02'!AA$24 -> 64457.72 | R12: 6407.47 | U12: 2581.22 | X12: =5201.48*J12/SUM($J$8:$J$12) -> 1067.8735 | Y12: =J12-SUM(L12:T12)-K12-V12+U12+W12 -> 34677.96 | Z12: =Y12-X12 -> 33610.086 | AB12: =(K12+K13)/(J12+J13) -> 0.052676864 | AC12: =(Z12+Z13)/(K12+K13) -> 2.4579118 | AD12: =(Z12+Z13)/(J12+J13) -> 0.12947509 | AE12: =(Q12+Q13)/(J12+J13) -> 0.26870709
A13: Март | B13: 46082 | C13: 9 | D13: =J13-SUM(L13:T13)+U13+V13 -> 2695.31 | E13: ='Юнит 01.03'!K$24 -> 36 | F13: ='Юнит 01.03'!P$24 -> 13 | G13: ='Юнит 01.03'!Q$24 -> 1 | H13: ='Юнит 01.03'!S$24 -> 32560 | I13: ='Юнит 01.03'!T$24 -> -2400 | J13: =H13+I13 -> 30160 | K13: ='Юнит 01.03'!W$24 -> 1478.73 | L13: ='Юнит 01.03'!Z$24 -> 3251.78 | M13: ='Юнит 01.03'!X$24 -> 12968.8 | Q13: ='Юнит 01.03'!AA$24 -> 10359.47 | R13: 884.64 | W13: 1350 | X13: ='Юнит 01.03'!$AD$24 -> 126.4 | Y13: =J13-SUM(L13:T13)-K13-V13+U13+W13 -> 2566.58 | Z13: =Y13-X13 -> 2440.18 | AA13: =SUM(Z13:Z18) -> 129879.34
B14: 02.03-08.03 | C14: 10 | D14: =J14-SUM(L14:T14)+U14+V14 -> 31422.07 | E14: ='Юнит 02-08.03'!K$24 -> 179 | F14: ='Юнит 02-08.03'!P$24 -> 93 | G14: ='Юнит 02-08.03'!Q$24 -> 4 | H14: ='Юнит 02-08.03'!S$24 -> 221439 | I14: ='Юнит 02-08.03'!T$24 -> -9910 | J14: =H14+I14 -> 211529 | K14: ='Юнит 02-08.03'!W$24 -> 11497.53 | L14: ='Юнит 02-08.03'!Z$24 -> 18516.49 | M14: ='Юнит 02-08.03'!X$24 -> 90957.47 | Q14: ='Юнит 02-08.03'!AA$24 -> 65685.91 | R14: 4902.06 | S14: 45 | T14: 0 | X14: ='Юнит 02-08.03'!$AD$24 -> 848.57 | Y14: =J14-SUM(L14:T14)-K14-V14+U14+W14 -> 19924.54 | Z14: =Y14-X14 -> 19075.97 | AB14: =(K14+K15)/(J14+J15) -> 0.054517064 | AC14: =(Z14+Z15)/(K14+K15) -> 2.8174678 | AD14: =(Z14+Z15)/(J14+J15) -> 0.15360007 | AE14: =(Q14+Q15)/(J14+J15) -> 0.24591639
B15: 09-15.03 | C15: 11 | D15: =J15-SUM(L15:T15)+U15+V15 -> 61950.07 | E15: ='Юнит 09-15.03'!K$24 -> 156 | F15: ='Юнит 09-15.03'!P$24 -> 97 | G15: ='Юнит 09-15.03'!Q$24 -> 5 | H15: ='Юнит 09-15.03'!S$24 -> 240785 | I15: ='Юнит 09-15.03'!T$24 -> -11873 | J15: =H15+I15 -> 228912 | K15: ='Юнит 09-15.03'!W$24 -> 12514.02 | L15: ='Юнит 09-15.03'!Z$24 -> 20045.39 | M15: ='Юнит 09-15.03'!X$24 -> 98432.16 | Q15: ='Юнит 09-15.03'!AA$24 -> 42625.75 | R15: 5778.63 | S15: 80 | T15: 0 | X15: ='Юнит 09-15.03'!$AD$24 -> 860.25 | Y15: =J15-SUM(L15:T15)-K15-V15+U15+W15 -> 49436.05 | Z15: =Y15-X15 -> 48575.8 | AB15: =(K15+K17)/(J15+J17) -> 0.055790521 | AC15: =(Z15+Z17)/(K15+K17) -> 3.7409589 | AD15: =(Z15+Z17)/(J15+J17) -> 0.20871005 | AE15: =(Q15+Q17)/(J15+J17) -> 0.19505485
B16: 16-22.03 | C16: 12 | D16: =J16-SUM(L16:T16)+U16+V16 -> 41865.51 | E16: ='Юнит 16-22.03'!K$24 -> 109 | F16: ='Юнит 16-22.03'!P$24 -> 61 | G16: ='Юнит 16-22.03'!Q$24 -> 2 | H16: ='Юнит 16-22.03'!S$24 -> 148955 | I16: ='Юнит 16-22.03'!T$24 -> -4939 | J16: =H16+I16 -> 144016 | K16: ='Юнит 16-22.03'!W$24 -> 8173.8 | L16: ='Юнит 16-22.03'!Z$24 -> 13537.32 | M16: ='Юнит 16-22.03'!X$24 -> 61926.88 | Q16: ='Юнит 16-22.03'!AA$24 -> 22870.89 | R16: 3785.4 | S16: 30 | T16: 0 | W16: 1404 | X16: ='Юнит 16-22.03'!$AD$24 -> 662.21 | Y16: =J16-SUM(L16:T16)-K16-V16+U16+W16 -> 35095.71 | Z16: =Y16-X16 -> 34433.5 | AB16: =(K16+K18)/(J16+J18) -> 0.056756194 | AC16: =(Z16+Z18)/(K16+K18) -> 4.2126673 | AD16: =(Z16+Z18)/(J16+J18) -> 0.23909496 | AE16: =(Q16+Q18)/(J16+J18) -> 0.15880798
B17: 23-29.03 | C17: 13 | D17: =J17-SUM(L17:T17)+U17+V17 -> 31815.03 | E17: ='Юнит 23-29.03'!K$24 -> 136 | F17: ='Юнит 23-29.03'!P$24 -> 59 | G17: ='Юнит 23-29.03'!Q$24 -> 5 | H17: ='Юнит 23-29.03'!S$24 -> 135999 | I17: ='Юнит 23-29.03'!T$24 -> -10689 | J17: =H17+I17 -> 125310 | K17: ='Юнит 23-29.03'!W$24 -> 7248.21 | L17: ='Юнит 23-29.03'!Z$24 -> 10759.15 | M17: ='Юнит 23-29.03'!X$24 -> 53883.3 | Q17: ='Юнит 23-29.03'!AA$24 -> 26466.97 | R17: 2330.55 | S17: 55 | T17: 0 | W17: 1404 | X17: ='Юнит 23-29.03'!$AD$24 -> 616.93 | Y17: =J17-SUM(L17:T17)-K17-V17+U17+W17 -> 25970.82 | Z17: =Y17-X17 -> 25353.89
B18: 30-31.03 | C18: 14
A19: Итого | D19: =SUM(D3:D18) -> 533103.22 | E19: =SUM(E3:E18) -> 2377 | F19: =SUM(F3:F18) -> 1446 | G19: =SUM(G3:G18) -> 62 | H19: =SUM(H3:H18) -> 2991621 | I19: =SUM(I3:I18) -> -131402 | J19: =SUM(J3:J18) -> 2860219 | K19: =SUM(K3:K18) -> 177272.13 | ... AA19: =SUM(AA3:AA18) -> 353756.31 | AB19: =K19/J19 -> 0.061978516 | AC19: =Z19/K19 -> 1.9955551 | AD19: =Z19/J19 -> 0.12368155 | AE19: =Q19/J19 -> 0.24022742
H20: % от выручки за весь период
I21: =-I19/H19 -> 0.043923345 | K21: =K19/$J$19 -> 0.061978516 | L21: =L19/$J$19 -> 0.098020249 | M21: =M19/$J$19 -> 0.43 | Q21: =Q19/$J$19 -> 0.24022742 | R21: =R19/$J$19 -> 0.02143224 | S21: =S19/$J$19 -> 0.00022201097 | T21: =T19/$J$19 -> 0.027452408 | U21: =U19/$J$19 -> 0.001292422 | V21: =V19/$J$19 -> 0.002447365 | W21: =W19/$J$19 -> 0.0082941201 | X21: =X19/$J$19 -> 0.0041247826 | Z21: =Z19/K19 -> 1.9955551 | AA21: Маржинальность, % | AB21: =Z19/J19 -> 0.12368155
A23: январь | D23: =SUM(D3:D7) -> 123225.19 | E23: =SUM(E3:E7) -> 803 | F23: =SUM(F3:F7) -> 544 | G23: =SUM(G3:G7) -> 15 | H23: =SUM(H3:H7) -> 936447 | I23: =SUM(I3:I7) -> -25467 | J23: =SUM(J3:J7) -> 910980 | K23: =SUM(K3:K7) -> 66570.99 | ... AA23: =SUM(AA3:AA7) -> 49559.258
I24: =-I23/H23 -> 0.027195346 | K24: =K23/$J$23 -> 0.073076237 | L24: =L23/$J$23 -> 0.10826828 | M24: =M23/$J$23 -> 0.43 | Q24: =Q23/$J$23 -> 0.26269438 | R24: =R23/$J$23 -> 0.018634031 | S24: =S23/$J$23 -> 0.00027442974 | T24: =T23/$J$23 -> 0.053770665 | V24: =V23/$J$23 -> 0.0076840326 | W24: =W23/$J$23 -> 0.011402007 | X24: =X23/$J$23 -> 0.0038221932 | Y24: =Y23/J23 -> 0.05822433 | Z24: =Z23/J23 -> 0.054402137 | AA24: =AA23/J23 -> 0.054402137
A26: 5 неделя | K26: =(K7+K8)/($J$7+$J$8) -> 0.070282074 | L26: =(L7+L8)/($J$7+$J$8) -> 0.10463693 | M26: =(M7+M8)/($J$7+$J$8) -> 0.43 | N26: =(N7+N8)/($J$7+$J$8) -> 0 | O26: =(O7+O8)/($J$7+$J$8) -> 0 | P26: =(P7+P8)/($J$7+$J$8) -> 0 | Q26: =(Q7+Q8)/($J$7+$J$8) -> 0.25406002 | R26: =(R7+S7+T7+R8+S8+T8)/($J$7+$J$8) -> 0.21054564 | U26: =(U7+U8)/($J$7+$J$8) -> 0.0048582878 | V26: =(V7+V8)/($J$7+$J$8) -> 0 | W26: =(W7+W8)/($J$7+$J$8) -> 0.021042315 | X26: =(X7+X8)/($J$7+$J$8) -> 0.0038902544 | Y26: =(Y7+Y8)/($J$7+$J$8) -> -0.043624061 | Z26: =(Z7+Z8)/($J$7+$J$8) -> -0.047514315
A27: 6 неделя | K27: =K9/$J$9 -> 0.066026147 | L27: =L9/$J$9 -> 0.10353458 | M27: =M9/$J$9 -> 0.43 | Q27: =Q9/$J$9 -> 0.22200333 | R27: =(R9+S9+T9)/$J$9 -> 0.11123316 | V27: =V9/$J$9 -> 0 | W27: =W9/$J$9 -> 0 | X27: =X9/$J$9 -> 0.0043011894 | Y27: =Y9/J9 -> 0.067202788 | Z27: =Z9/J9 -> 0.062901598
A28: 7 неделя | K28: =K10/$J$10 -> 0.056032823 | L28: =L10/$J$10 -> 0.088563171 | M28: =M10/$J$10 -> 0.43 | Q28: =Q10/$J$10 -> 0.22356573 | R28: =(R10+S10+T10)/$J$10 -> 0.029021394 | V28: =V10/$J$10 -> 0 | W28: =W10/$J$10 -> 0 | X28: =X10/$J$10 -> 0.0043011894 | Y28: =Y10/J10 -> 0.17281688 | Z28: =Z10/J10 -> 0.16851569
A29: 8 неделя | K29: =K11/$J$11 -> 0.054130814 | L29: =L11/$J$11 -> 0.089548728 | M29: =M11/$J$11 -> 0.43 | Q29: =Q11/$J$11 -> 0.22547462 | R29: =(R11+S11+T11)/$J$11 -> 0.022696381 | V29: =V11/$J$11 -> 0 | W29: =W11/$J$11 -> 0.012257431 | X29: =X11/$J$11 -> 0.0043011894 | Y29: =Y11/J11 -> 0.19040689 | Z29: =Z11/J11 -> 0.1861057
A30: 9 неделя | K30: =(K12+K13)/($J$12+$J$13) -> 0.052676864 | L30: =(L12+L13)/($J$12+$J$13) -> 0.10278102 | M30: =(M12+M13)/($J$12+$J$13) -> 0.43 | N30: =(N12+N13)/($J$12+$J$13) -> 0 | O30: =(O12+O13)/($J$12+$J$13) -> 0 | P30: =(P12+P13)/($J$12+$J$13) -> 0 | Q30: =(Q12+Q13)/($J$12+$J$13) -> 0.26870709 | R30: =(R12+R13)/($J$12+$J$13) -> 0.026189725 | V30: =(V12+V13)/($J$12+$J$13) -> 0 | W30: =(W12+W13)/($J$12+$J$13) -> 0.0048485458 | X30: =(X12+X13)/($J$12+$J$13) -> 0.0042892517 | Y30: =(Y12+Y13)/($J$12+$J$13) -> 0.13376434 | Z30: =(Z12+Z13)/($J$12+$J$13) -> 0.12947509
A32: февраль | D32: =SUM(D8:D12) -> 240130.04 | E32: =SUM(E8:E12) -> 958 | F32: =SUM(F8:F12) -> 579 | G32: =SUM(G8:G12) -> 30 | H32: =SUM(H8:H12) -> 1275436 | I32: =SUM(I8:I12) -> -66124 | J32: =SUM(J8:J12) -> 1209312 | K32: =SUM(K8:K12) -> 69788.85 | ... AA32: =SUM(AA8:AA12) -> 174317.71
A34: март | D34: =SUM(D13:D18) -> 169747.99 | E34: =SUM(E13:E18) -> 616 | F34: =SUM(F13:F18) -> 323 | G34: =SUM(G13:G18) -> 17 | H34: =SUM(H13:H18) -> 779738 | I34: =SUM(I13:I18) -> -39811 | J34: =SUM(J13:J18) -> 739927 | K34: =SUM(K13:K18) -> 40912.29 | ... AA34: =SUM(AA13:AA18) -> 129879.34

Sheet АВС МАРТ
B2: ОЧКИ
C3: Прибыль | D3: % прибыль | E3: Доля | F3: ABC прибыль | G3: ABC кол-во | J3: Кол-во | K3: % кол-во | L3: Доля | M3: ABC кол-во
B4: черные с железкой классика | D4: =C4/C$18 -> #DIV/0! | E4: =D4 -> #DIV/0! | F4: =IF(AND(E4<=0),"C",IF(E4<=0.8,"A",IF(E4<=0.95,"B","C"))) -> #DIV/0! | G4: =VLOOKUP(B$4:B$17,I$4:M$17,5,0) -> #DIV/0! | I4: черные с железкой классика | K4: =J4/J$18 -> #DIV/0! | L4: =K4 -> #DIV/0! | M4: =_xlfn.IFS(L4<80%,"A",L4<=95%,"B",L4>95%,"C") -> #DIV/0!
B5: qs черные | D5: =C5/C$18 -> #DIV/0! | E5: =D5+E4 -> #DIV/0! | F5: =IF(AND(E5<=0),"C",IF(E5<=0.8,"A",IF(E5<=0.95,"B","C"))) -> #DIV/0! | G5: =VLOOKUP(B$4:B$17,I$4:M$17,5,0) -> #DIV/0! | I5: qs черные | K5: =J5/J$18 -> #DIV/0! | L5: =K5+L4 -> #DIV/0! | M5: =_xlfn.IFS(L5<80%,"A",L5<=95%,"B",L5>95%,"C") -> #DIV/0!
B6: qs синие | D6: =C6/C$18 -> #DIV/0! | E6: =D6+E5 -> #DIV/0! | F6: =IF(AND(E6<=0),"C",IF(E6<=0.8,"A",IF(E6<=0.95,"B","C"))) -> #DIV/0! | G6: =VLOOKUP(B$4:B$17,I$4:M$17,5,0) -> #DIV/0! | I6: qs синие | K6: =J6/J$18 -> #DIV/0! | L6: =K6+L5 -> #DIV/0! | M6: =_xlfn.IFS(L6<80%,"A",L6<=95%,"B",L6>95%,"C") -> #DIV/0!
B7: qs желтые | D7: =C7/C$18 -> #DIV/0! | E7: =D7+E6 -> #DIV/0! | F7: =IF(AND(E7<=0),"C",IF(E7<=0.8,"A",IF(E7<=0.95,"B","C"))) -> #DIV/0! | G7: =VLOOKUP(B$4:B$17,I$4:M$17,5,0) -> #DIV/0! | I7: qs желтые | K7: =J7/J$18 -> #DIV/0! | L7: =K7+L6 -> #DIV/0! | M7: =_xlfn.IFS(L7<80%,"A",L7<=95%,"B",L7>95%,"C") -> #DIV/0!
B8: qs коричневые | D8: =C8/C$18 -> #DIV/0! | E8: =D8+E7 -> #DIV/0! | F8: =IF(AND(E8<=0),"C",IF(E8<=0.8,"A",IF(E8<=0.95,"B","C"))) -> #DIV/0! | G8: =VLOOKUP(B$4:B$17,I$4:M$17,5,0) -> #DIV/0! | I8: qs коричневые | K8: =J8/J$18 -> #DIV/0! | L8: =K8+L7 -> #DIV/0! | M8: =_xlfn.IFS(L8<80%,"A",L8<=95%,"B",L8>95%,"C") -> #DIV/0!
B9: MR8854 C2 | D9: =C9/C$18 -> #DIV/0! | E9: =D9+E8 -> #DIV/0! | F9: =IF(AND(E9<=0),"C",IF(E9<=0.8,"A",IF(E9<=0.95,"B","C"))) -> #DIV/0! | G9: =VLOOKUP(B$4:B$17,I$4:M$17,5,0) -> #DIV/0! | I9: MR8854 C2 | K9: =J9/J$18 -> #DIV/0! | L9: =K9+L8 -> #DIV/0! | M9: =_xlfn.IFS(L9<80%,"A",L9<=95%,"B",L9>95%,"C") -> #DIV/0!
B10: th черн | D10: =C10/C$18 -> #DIV/0! | E10: =D10+E9 -> #DIV/0! | F10: =IF(AND(E10<=0),"C",IF(E10<=0.8,"A",IF(E10<=0.95,"B","C"))) -> #DIV/0! | G10: =VLOOKUP(B$4:B$17,I$4:M$17,5,0) -> #DIV/0! | I10: th черн | K10: =J10/J$18 -> #DIV/0! | L10: =K10+L9 -> #DIV/0! | M10: =_xlfn.IFS(L10<80%,"A",L10<=95%,"B",L10>95%,"C") -> #DIV/0!
B11: th син | D11: =C11/C$18 -> #DIV/0! | E11: =D11+E10 -> #DIV/0! | F11: =IF(AND(E11<=0),"C",IF(E11<=0.8,"A",IF(E11<=0.95,"B","C"))) -> #DIV/0! | G11: =VLOOKUP(B$4:B$17,I$4:M$17,5,0) -> #DIV/0! | I11: th син | K11: =J11/J$18 -> #DIV/0! | L11: =K11+L10 -> #DIV/0! | M11: =_xlfn.IFS(L11<80%,"A",L11<=95%,"B",L11>95%,"C") -> #DIV/0!
B12: th желт | D12: =C12/C$18 -> #DIV/0! | E12: =D12+E5 -> #DIV/0! | F12: =IF(AND(E12<=0),"C",IF(E12<=0.8,"A",IF(E12<=0.95,"B","C"))) -> #DIV/0! | G12: =VLOOKUP(B$4:B$17,I$4:M$17,5,0) -> #DIV/0! | I12: th желт | K12: =J12/J$18 -> #DIV/0! | L12: =K12+L5 -> #DIV/0! | M12: =_xlfn.IFS(L12<80%,"A",L12<=95%,"B",L12>95%,"C") -> #DIV/0!
B13: th коричн | D13: =C13/C$18 -> #DIV/0! | E13: =D13+E12 -> #DIV/0! | F13: =IF(AND(E13<=0),"C",IF(E13<=0.8,"A",IF(E13<=0.95,"B","C"))) -> #DIV/0! | G13: =VLOOKUP(B$4:B$17,I$4:M$17,5,0) -> #DIV/0! | I13: th коричн | K13: =J13/J$18 -> #DIV/0! | L13: =K13+L12 -> #DIV/0! | M13: =_xlfn.IFS(L13<80%,"A",L13<=95%,"B",L13>95%,"C") -> #DIV/0!
B14: flip черный | D14: =C14/C$18 -> #DIV/0! | E14: =D14+E13 -> #DIV/0! | F14: =IF(AND(E14<=0),"C",IF(E14<=0.8,"A",IF(E14<=0.95,"B","C"))) -> #DIV/0! | G14: =VLOOKUP(B$4:B$17,I$4:M$17,5,0) -> #DIV/0! | I14: flip черный | K14: =J14/J$18 -> #DIV/0! | L14: =K14+L13 -> #DIV/0! | M14: =_xlfn.IFS(L14<80%,"A",L14<=95%,"B",L14>95%,"C") -> #DIV/0!
B15: flip синий | D15: =C15/C$18 -> #DIV/0! | E15: =D15+E14 -> #DIV/0! | F15: =IF(AND(E15<=0),"C",IF(E15<=0.8,"A",IF(E15<=0.95,"B","C"))) -> #DIV/0! | G15: =VLOOKUP(B$4:B$17,I$4:M$17,5,0) -> #DIV/0! | I15: flip синий | K15: =J15/J$18 -> #DIV/0! | L15: =K15+L14 -> #DIV/0! | M15: =_xlfn.IFS(L15<80%,"A",L15<=95%,"B",L15>95%,"C") -> #DIV/0!
B16: flip жел | D16: =C16/C$18 -> #DIV/0! | E16: =D16+E15 -> #DIV/0! | F16: =IF(AND(E16<=0),"C",IF(E16<=0.8,"A",IF(E16<=0.95,"B","C"))) -> #DIV/0! | G16: =VLOOKUP(B$4:B$17,I$4:M$17,5,0) -> #DIV/0! | I16: flip жел | K16: =J16/J$18 -> #DIV/0! | L16: =K16+L15 -> #DIV/0! | M16: =_xlfn.IFS(L16<80%,"A",L16<=95%,"B",L16>95%,"C") -> #DIV/0!
B17: flip коричневый | D17: =C17/C$18 -> #DIV/0! | E17: =D17+E14 -> #DIV/0! | F17: =IF(AND(E17<=0),"C",IF(E17<=0.8,"A",IF(E17<=0.95,"B","C"))) -> #DIV/0! | G17: =VLOOKUP(B$4:B$17,I$4:M$17,5,0) -> #DIV/0! | I17: flip коричневый | K17: =J17/J$18 -> #DIV/0! | L17: =K17+L14 -> #DIV/0! | M17: =_xlfn.IFS(L17<80%,"A",L17<=95%,"B",L17>95%,"C") -> #DIV/0!
C18: =SUM(C4:C17) -> 0 | D18: =SUM(D4:D17) -> #DIV/0! | J18: =SUM(J4:J17) -> 0 | K18: =SUM(K4:K17) -> #DIV/0!
C21: Прибыль | D21: % прибыль | E21: Доля | F21: ABC прибыль | G21: ABC кол-во | J21: Кол-во | K21: % кол-во | L21: Доля | M21: ABC кол-во
D22: =C22/C$42 -> #DIV/0! | E22: =D22 -> #DIV/0! | F22: =IF(AND(E22<=0),"C",IF(E22<=0.8,"A",IF(E22<=0.95,"B","C"))) -> #DIV/0! | G22: =VLOOKUP(B$22:B$42,I$22:M$42,5,0) -> #N/A | K22: =J22/J$42 -> #DIV/0! | L22: =K22 -> #DIV/0! | M22: =_xlfn.IFS(L22<80%,"A",L22<=95%,"B",L22>95%,"C") -> #DIV/0!
D23: =C23/C$42 -> #DIV/0! | E23: =D23+E22 -> #DIV/0! | F23: =IF(AND(E23<=0),"C",IF(E23<=0.8,"A",IF(E23<=0.95,"B","C"))) -> #DIV/0! | G23: =VLOOKUP(B$22:B$42,I$22:M$42,5,0) -> #N/A | K23: =J23/J$42 -> #DIV/0! | L23: =K23+L22 -> #DIV/0! | M23: =_xlfn.IFS(L23<80%,"A",L23<=95%,"B",L23>95%,"C") -> #DIV/0!
D24: =C24/C$42 -> #DIV/0! | E24: =D24+E23 -> #DIV/0! | F24: =IF(AND(E24<=0),"C",IF(E24<=0.8,"A",IF(E24<=0.95,"B","C"))) -> #DIV/0! | G24: =VLOOKUP(B$22:B$42,I$22:M$42,5,0) -> #N/A | K24: =J24/J$42 -> #DIV/0! | L24: =K24+L23 -> #DIV/0! | M24: =_xlfn.IFS(L24<80%,"A",L24<=95%,"B",L24>95%,"C") -> #DIV/0!
D25: =C25/C$42 -> #DIV/0! | E25: =D25+E24 -> #DIV/0! | F25: =IF(AND(E25<=0),"C",IF(E25<=0.8,"A",IF(E25<=0.95,"B","C"))) -> #DIV/0! | G25: =VLOOKUP(B$22:B$42,I$22:M$42,5,0) -> #N/A | K25: =J25/J$42 -> #DIV/0! | L25: =K25+L24 -> #DIV/0! | M25: =_xlfn.IFS(L25<80%,"A",L25<=95%,"B",L25>95%,"C") -> #DIV/0!
D26: =C26/C$42 -> #DIV/0! | E26: =D26+E25 -> #DIV/0! | F26: =IF(AND(E26<=0),"C",IF(E26<=0.8,"A",IF(E26<=0.95,"B","C"))) -> #DIV/0! | G26: =VLOOKUP(B$22:B$42,I$22:M$42,5,0) -> #N/A | K26: =J26/J$42 -> #DIV/0! | L26: =K26+L25 -> #DIV/0! | M26: =_xlfn.IFS(L26<80%,"A",L26<=95%,"B",L26>95%,"C") -> #DIV/0!
D27: =C27/C$42 -> #DIV/0! | E27: =D27+E26 -> #DIV/0! | F27: =IF(AND(E27<=0),"C",IF(E27<=0.8,"A",IF(E27<=0.95,"B","C"))) -> #DIV/0! | G27: =VLOOKUP(B$22:B$42,I$22:M$42,5,0) -> #N/A | K27: =J27/J$42 -> #DIV/0! | L27: =K27+L26 -> #DIV/0! | M27: =_xlfn.IFS(L27<80%,"A",L27<=95%,"B",L27>95%,"C") -> #DIV/0!
D28: =C28/C$42 -> #DIV/0! | E28: =D28+E27 -> #DIV/0! | F28: =IF(AND(E28<=0),"C",IF(E28<=0.8,"A",IF(E28<=0.95,"B","C"))) -> #DIV/0! | G28: =VLOOKUP(B$22:B$42,I$22:M$42,5,0) -> #N/A | K28: =J28/J$42 -> #DIV/0! | L28: =K28+L27 -> #DIV/0! | M28: =_xlfn.IFS(L28<80%,"A",L28<=95%,"B",L28>95%,"C") -> #DIV/0!
D29: =C29/C$42 -> #DIV/0! | E29: =D29+E28 -> #DIV/0! | F29: =IF(AND(E29<=0),"C",IF(E29<=0.8,"A",IF(E29<=0.95,"B","C"))) -> #DIV/0! | G29: =VLOOKUP(B$22:B$42,I$22:M$42,5,0) -> #N/A | K29: =J29/J$42 -> #DIV/0! | L29: =K29+L28 -> #DIV/0! | M29: =_xlfn.IFS(L29<80%,"A",L29<=95%,"B",L29>95%,"C") -> #DIV/0!
D30: =C30/C$42 -> #DIV/0! | E30: =D30+E29 -> #DIV/0! | F30: =IF(AND(E30<=0),"C",IF(E30<=0.8,"A",IF(E30<=0.95,"B","C"))) -> #DIV/0! | G30: =VLOOKUP(B$22:B$42,I$22:M$42,5,0) -> #N/A | K30: =J30/J$42 -> #DIV/0! | L30: =K30+L29 -> #DIV/0! | M30: =_xlfn.IFS(L30<80%,"A",L30<=95%,"B",L30>95%,"C") -> #DIV/0!
D31: =C31/C$42 -> #DIV/0! | E31: =D31+E30 -> #DIV/0! | F31: =IF(AND(E31<=0),"C",IF(E31<=0.8,"A",IF(E31<=0.95,"B","C"))) -> #DIV/0! | G31: =VLOOKUP(B$22:B$42,I$22:M$42,5,0) -> #N/A | K31: =J31/J$42 -> #DIV/0! | L31: =K31+L30 -> #DIV/0! | M31: =_xlfn.IFS(L31<80%,"A",L31<=95%,"B",L31>95%,"C") -> #DIV/0!
D32: =C32/C$42 -> #DIV/0! | E32: =D32+E31 -> #DIV/0! | F32: =IF(AND(E32<=0),"C",IF(E32<=0.8,"A",IF(E32<=0.95,"B","C"))) -> #DIV/0! | G32: =VLOOKUP(B$22:B$42,I$22:M$42,5,0) -> #N/A | K32: =J32/J$42 -> #DIV/0! | L32: =K32+L31 -> #DIV/0! | M32: =_xlfn.IFS(L32<80%,"A",L32<=95%,"B",L32>95%,"C") -> #DIV/0!
D33: =C33/C$42 -> #DIV/0! | E33: =D33+E32 -> #DIV/0! | F33: =IF(AND(E33<=0),"C",IF(E33<=0.8,"A",IF(E33<=0.95,"B","C"))) -> #DIV/0! | G33: =VLOOKUP(B$22:B$42,I$22:M$42,5,0) -> #N/A | K33: =J33/J$42 -> #DIV/0! | L33: =K33+L32 -> #DIV/0! | M33: =_xlfn.IFS(L33<80%,"A",L33<=95%,"B",L33>95%,"C") -> #DIV/0!
D34: =C34/C$42 -> #DIV/0! | E34: =D34+E33 -> #DIV/0! | F34: =IF(AND(E34<=0),"C",IF(E34<=0.8,"A",IF(E34<=0.95,"B","C"))) -> #DIV/0! | G34: =VLOOKUP(B$22:B$42,I$22:M$42,5,0) -> #N/A | K34: =J34/J$42 -> #DIV/0! | L34: =K34+L33 -> #DIV/0! | M34: =_xlfn.IFS(L34<80%,"A",L34<=95%,"B",L34>95%,"C") -> #DIV/0!
... D41: =C41/C$42 -> #DIV/0! | E41: =D41+E40 -> #DIV/0! | F41: =IF(AND(E41<=0),"C",IF(E41<=0.8,"A",IF(E41<=0.95,"B","C"))) -> #DIV/0! | G41: =VLOOKUP(B$22:B$42,I$22:M$42,5,0) -> #N/A | K41: =J41/J$42 -> #DIV/0! | L41: =K41+L40 -> #DIV/0! | M41: =_xlfn.IFS(L41<80%,"A",L41<=95%,"B",L41>95%,"C") -> #DIV/0!
C42: =SUM(C22:C41) -> 0 | D42: =SUM(D22:D41) -> #DIV/0! | J42: =SUM(J22:J41) -> 0 | K42: =SUM(K22:K41) -> #DIV/0!

Sheet АВС 30-31.03
B2: ОЧКИ
C3: Прибыль | D3: % прибыль | E3: Доля | F3: ABC прибыль | G3: ABC кол-во | J3: Кол-во | K3: % кол-во | L3: Доля | M3: ABC кол-во
B4: черные с железкой классика | D4: =C4/C$18 -> #DIV/0! | E4: =D4 -> #DIV/0! | F4: =IF(AND(E4<=0),"C",IF(E4<=0.8,"A",IF(E4<=0.95,"B","C"))) -> #DIV/0! | G4: =VLOOKUP(B$4:B$17,I$4:M$17,5,0) -> #DIV/0! | I4: черные с железкой классика | K4: =J4/J$18 -> #DIV/0! | L4: =K4 -> #DIV/0! | M4: =_xlfn.IFS(L4<80%,"A",L4<=95%,"B",L4>95%,"C") -> #DIV/0!
B5: qs черные | D5: =C5/C$18 -> #DIV/0! | E5: =D5+E4 -> #DIV/0! | F5: =IF(AND(E5<=0),"C",IF(E5<=0.8,"A",IF(E5<=0.95,"B","C"))) -> #DIV/0! | G5: =VLOOKUP(B$4:B$17,I$4:M$17,5,0) -> #DIV/0! | I5: qs черные | K5: =J5/J$18 -> #DIV/0! | L5: =K5+L4 -> #DIV/0! | M5: =_xlfn.IFS(L5<80%,"A",L5<=95%,"B",L5>95%,"C") -> #DIV/0!
B6: qs синие | D6: =C6/C$18 -> #DIV/0! | E6: =D6+E5 -> #DIV/0! | F6: =IF(AND(E6<=0),"C",IF(E6<=0.8,"A",IF(E6<=0.95,"B","C"))) -> #DIV/0! | G6: =VLOOKUP(B$4:B$17,I$4:M$17,5,0) -> #DIV/0! | I6: qs синие | K6: =J6/J$18 -> #DIV/0! | L6: =K6+L5 -> #DIV/0! | M6: =_xlfn.IFS(L6<80%,"A",L6<=95%,"B",L6>95%,"C") -> #DIV/0!
B7: qs желтые | D7: =C7/C$18 -> #DIV/0! | E7: =D7+E6 -> #DIV/0! | F7: =IF(AND(E7<=0),"C",IF(E7<=0.8,"A",IF(E7<=0.95,"B","C"))) -> #DIV/0! | G7: =VLOOKUP(B$4:B$17,I$4:M$17,5,0) -> #DIV/0! | I7: qs желтые | K7: =J7/J$18 -> #DIV/0! | L7: =K7+L6 -> #DIV/0! | M7: =_xlfn.IFS(L7<80%,"A",L7<=95%,"B",L7>95%,"C") -> #DIV/0!
B8: qs коричневые | D8: =C8/C$18 -> #DIV/0! | E8: =D8+E7 -> #DIV/0! | F8: =IF(AND(E8<=0),"C",IF(E8<=0.8,"A",IF(E8<=0.95,"B","C"))) -> #DIV/0! | G8: =VLOOKUP(B$4:B$17,I$4:M$17,5,0) -> #DIV/0! | I8: qs коричневые | K8: =J8/J$18 -> #DIV/0! | L8: =K8+L7 -> #DIV/0! | M8: =_xlfn.IFS(L8<80%,"A",L8<=95%,"B",L8>95%,"C") -> #DIV/0!
B9: MR8854 C2 | D9: =C9/C$18 -> #DIV/0! | E9: =D9+E8 -> #DIV/0! | F9: =IF(AND(E9<=0),"C",IF(E9<=0.8,"A",IF(E9<=0.95,"B","C"))) -> #DIV/0! | G9: =VLOOKUP(B$4:B$17,I$4:M$17,5,0) -> #DIV/0! | I9: MR8854 C2 | K9: =J9/J$18 -> #DIV/0! | L9: =K9+L8 -> #DIV/0! | M9: =_xlfn.IFS(L9<80%,"A",L9<=95%,"B",L9>95%,"C") -> #DIV/0!
B10: th черн | D10: =C10/C$18 -> #DIV/0! | E10: =D10+E9 -> #DIV/0! | F10: =IF(AND(E10<=0),"C",IF(E10<=0.8,"A",IF(E10<=0.95,"B","C"))) -> #DIV/0! | G10: =VLOOKUP(B$4:B$17,I$4:M$17,5,0) -> #DIV/0! | I10: th черн | K10: =J10/J$18 -> #DIV/0! | L10: =K10+L9 -> #DIV/0! | M10: =_xlfn.IFS(L10<80%,"A",L10<=95%,"B",L10>95%,"C") -> #DIV/0!
B11: th син | D11: =C11/C$18 -> #DIV/0! | E11: =D11+E10 -> #DIV/0! | F11: =IF(AND(E11<=0),"C",IF(E11<=0.8,"A",IF(E11<=0.95,"B","C"))) -> #DIV/0! | G11: =VLOOKUP(B$4:B$17,I$4:M$17,5,0) -> #DIV/0! | I11: th син | K11: =J11/J$18 -> #DIV/0! | L11: =K11+L10 -> #DIV/0! | M11: =_xlfn.IFS(L11<80%,"A",L11<=95%,"B",L11>95%,"C") -> #DIV/0!
B12: th желт | D12: =C12/C$18 -> #DIV/0! | E12: =D12+E5 -> #DIV/0! | F12: =IF(AND(E12<=0),"C",IF(E12<=0.8,"A",IF(E12<=0.95,"B","C"))) -> #DIV/0! | G12: =VLOOKUP(B$4:B$17,I$4:M$17,5,0) -> #DIV/0! | I12: th желт | K12: =J12/J$18 -> #DIV/0! | L12: =K12+L5 -> #DIV/0! | M12: =_xlfn.IFS(L12<80%,"A",L12<=95%,"B",L12>95%,"C") -> #DIV/0!
B13: th коричн | D13: =C13/C$18 -> #DIV/0! | E13: =D13+E12 -> #DIV/0! | F13: =IF(AND(E13<=0),"C",IF(E13<=0.8,"A",IF(E13<=0.95,"B","C"))) -> #DIV/0! | G13: =VLOOKUP(B$4:B$17,I$4:M$17,5,0) -> #DIV/0! | I13: th коричн | K13: =J13/J$18 -> #DIV/0! | L13: =K13+L12 -> #DIV/0! | M13: =_xlfn.IFS(L13<80%,"A",L13<=95%,"B",L13>95%,"C") -> #DIV/0!
B14: flip черный | D14: =C14/C$18 -> #DIV/0! | E14: =D14+E13 -> #DIV/0! | F14: =IF(AND(E14<=0),"C",IF(E14<=0.8,"A",IF(E14<=0.95,"B","C"))) -> #DIV/0! | G14: =VLOOKUP(B$4:B$17,I$4:M$17,5,0) -> #DIV/0! | I14: flip черный | K14: =J14/J$18 -> #DIV/0! | L14: =K14+L13 -> #DIV/0! | M14: =_xlfn.IFS(L14<80%,"A",L14<=95%,"B",L14>95%,"C") -> #DIV/0!
B15: flip синий | D15: =C15/C$18 -> #DIV/0! | E15: =D15+E14 -> #DIV/0! | F15: =IF(AND(E15<=0),"C",IF(E15<=0.8,"A",IF(E15<=0.95,"B","C"))) -> #DIV/0! | G15: =VLOOKUP(B$4:B$17,I$4:M$17,5,0) -> #DIV/0! | I15: flip синий | K15: =J15/J$18 -> #DIV/0! | L15: =K15+L14 -> #DIV/0! | M15: =_xlfn.IFS(L15<80%,"A",L15<=95%,"B",L15>95%,"C") -> #DIV/0!
B16: flip жел | D16: =C16/C$18 -> #DIV/0! | E16: =D16+E15 -> #DIV/0! | F16: =IF(AND(E16<=0),"C",IF(E16<=0.8,"A",IF(E16<=0.95,"B","C"))) -> #DIV/0! | G16: =VLOOKUP(B$4:B$17,I$4:M$17,5,0) -> #DIV/0! | I16: flip жел | K16: =J16/J$18 -> #DIV/0! | L16: =K16+L15 -> #DIV/0! | M16: =_xlfn.IFS(L16<80%,"A",L16<=95%,"B",L16>95%,"C") -> #DIV/0!
B17: flip коричневый | D17: =C17/C$18 -> #DIV/0! | E17: =D17+E14 -> #DIV/0! | F17: =IF(AND(E17<=0),"C",IF(E17<=0.8,"A",IF(E17<=0.95,"B","C"))) -> #DIV/0! | G17: =VLOOKUP(B$4:B$17,I$4:M$17,5,0) -> #DIV/0! | I17: flip коричневый | K17: =J17/J$18 -> #DIV/0! | L17: =K17+L14 -> #DIV/0! | M17: =_xlfn.IFS(L17<80%,"A",L17<=95%,"B",L17>95%,"C") -> #DIV/0!
C18: =SUM(C4:C17) -> 0 | D18: =SUM(D4:D17) -> #DIV/0! | J18: =SUM(J4:J17) -> 0 | K18: =SUM(K4:K17) -> #DIV/0!
C21: Прибыль | D21: % прибыль | E21: Доля | F21: ABC прибыль | G21: ABC кол-во | J21: Кол-во | K21: % кол-во | L21: Доля | M21: ABC кол-во
D22: =C22/C$42 -> #DIV/0! | E22: =D22 -> #DIV/0! | F22: =IF(AND(E22<=0),"C",IF(E22<=0.8,"A",IF(E22<=0.95,"B","C"))) -> #DIV/0! | G22: =VLOOKUP(B$22:B$42,I$22:M$42,5,0) -> #N/A | K22: =J22/J$42 -> #DIV/0! | L22: =K22 -> #DIV/0! | M22: =_xlfn.IFS(L22<80%,"A",L22<=95%,"B",L22>95%,"C") -> #DIV/0!
D23: =C23/C$42 -> #DIV/0! | E23: =D23+E22 -> #DIV/0! | F23: =IF(AND(E23<=0),"C",IF(E23<=0.8,"A",IF(E23<=0.95,"B","C"))) -> #DIV/0! | G23: =VLOOKUP(B$22:B$42,I$22:M$42,5,0) -> #N/A | K23: =J23/J$42 -> #DIV/0! | L23: =K23+L22 -> #DIV/0! | M23: =_xlfn.IFS(L23<80%,"A",L23<=95%,"B",L23>95%,"C") -> #DIV/0!
D24: =C24/C$42 -> #DIV/0! | E24: =D24+E23 -> #DIV/0! | F24: =IF(AND(E24<=0),"C",IF(E24<=0.8,"A",IF(E24<=0.95,"B","C"))) -> #DIV/0! | G24: =VLOOKUP(B$22:B$42,I$22:M$42,5,0) -> #N/A | K24: =J24/J$42 -> #DIV/0! | L24: =K24+L23 -> #DIV/0! | M24: =_xlfn.IFS(L24<80%,"A",L24<=95%,"B",L24>95%,"C") -> #DIV/0!
D25: =C25/C$42 -> #DIV/0! | E25: =D25+E24 -> #DIV/0! | F25: =IF(AND(E25<=0),"C",IF(E25<=0.8,"A",IF(E25<=0.95,"B","C"))) -> #DIV/0! | G25: =VLOOKUP(B$22:B$42,I$22:M$42,5,0) -> #N/A | K25: =J25/J$42 -> #DIV/0! | L25: =K25+L24 -> #DIV/0! | M25: =_xlfn.IFS(L25<80%,"A",L25<=95%,"B",L25>95%,"C") -> #DIV/0!
D26: =C26/C$42 -> #DIV/0! | E26: =D26+E25 -> #DIV/0! | F26: =IF(AND(E26<=0),"C",IF(E26<=0.8,"A",IF(E26<=0.95,"B","C"))) -> #DIV/0! | G26: =VLOOKUP(B$22:B$42,I$22:M$42,5,0) -> #N/A | K26: =J26/J$42 -> #DIV/0! | L26: =K26+L25 -> #DIV/0! | M26: =_xlfn.IFS(L26<80%,"A",L26<=95%,"B",L26>95%,"C") -> #DIV/0!
D27: =C27/C$42 -> #DIV/0! | E27: =D27+E26 -> #DIV/0! | F27: =IF(AND(E27<=0),"C",IF(E27<=0.8,"A",IF(E27<=0.95,"B","C"))) -> #DIV/0! | G27: =VLOOKUP(B$22:B$42,I$22:M$42,5,0) -> #N/A | K27: =J27/J$42 -> #DIV/0! | L27: =K27+L26 -> #DIV/0! | M27: =_xlfn.IFS(L27<80%,"A",L27<=95%,"B",L27>95%,"C") -> #DIV/0!
D28: =C28/C$42 -> #DIV/0! | E28: =D28+E27 -> #DIV/0! | F28: =IF(AND(E28<=0),"C",IF(E28<=0.8,"A",IF(E28<=0.95,"B","C"))) -> #DIV/0! | G28: =VLOOKUP(B$22:B$42,I$22:M$42,5,0) -> #N/A | K28: =J28/J$42 -> #DIV/0! | L28: =K28+L27 -> #DIV/0! | M28: =_xlfn.IFS(L28<80%,"A",L28<=95%,"B",L28>95%,"C") -> #DIV/0!
D29: =C29/C$42 -> #DIV/0! | E29: =D29+E28 -> #DIV/0! | F29: =IF(AND(E29<=0),"C",IF(E29<=0.8,"A",IF(E29<=0.95,"B","C"))) -> #DIV/0! | G29: =VLOOKUP(B$22:B$42,I$22:M$42,5,0) -> #N/A | K29: =J29/J$42 -> #DIV/0! | L29: =K29+L28 -> #DIV/0! | M29: =_xlfn.IFS(L29<80%,"A",L29<=95%,"B",L29>95%,"C") -> #DIV/0!
D30: =C30/C$42 -> #DIV/0! | E30: =D30+E29 -> #DIV/0! | F30: =IF(AND(E30<=0),"C",IF(E30<=0.8,"A",IF(E30<=0.95,"B","C"))) -> #DIV/0! | G30: =VLOOKUP(B$22:B$42,I$22:M$42,5,0) -> #N/A | K30: =J30/J$42 -> #DIV/0! | L30: =K30+L29 -> #DIV/0! | M30: =_xlfn.IFS(L30<80%,"A",L30<=95%,"B",L30>95%,"C") -> #DIV/0!
D31: =C31/C$42 -> #DIV/0! | E31: =D31+E30 -> #DIV/0! | F31: =IF(AND(E31<=0),"C",IF(E31<=0.8,"A",IF(E31<=0.95,"B","C"))) -> #DIV/0! | G31: =VLOOKUP(B$22:B$42,I$22:M$42,5,0) -> #N/A | K31: =J31/J$42 -> #DIV/0! | L31: =K31+L30 -> #DIV/0! | M31: =_xlfn.IFS(L31<80%,"A",L31<=95%,"B",L31>95%,"C") -> #DIV/0!
D32: =C32/C$42 -> #DIV/0! | E32: =D32+E31 -> #DIV/0! | F32: =IF(AND(E32<=0),"C",IF(E32<=0.8,"A",IF(E32<=0.95,"B","C"))) -> #DIV/0! | G32: =VLOOKUP(B$22:B$42,I$22:M$42,5,0) -> #N/A | K32: =J32/J$42 -> #DIV/0! | L32: =K32+L31 -> #DIV/0! | M32: =_xlfn.IFS(L32<80%,"A",L32<=95%,"B",L32>95%,"C") -> #DIV/0!
D33: =C33/C$42 -> #DIV/0! | E33: =D33+E32 -> #DIV/0! | F33: =IF(AND(E33<=0),"C",IF(E33<=0.8,"A",IF(E33<=0.95,"B","C"))) -> #DIV/0! | G33: =VLOOKUP(B$22:B$42,I$22:M$42,5,0) -> #N/A | K33: =J33/J$42 -> #DIV/0! | L33: =K33+L32 -> #DIV/0! | M33: =_xlfn.IFS(L33<80%,"A",L33<=95%,"B",L33>95%,"C") -> #DIV/0!
D34: =C34/C$42 -> #DIV/0! | E34: =D34+E33 -> #DIV/0! | F34: =IF(AND(E34<=0),"C",IF(E34<=0.8,"A",IF(E34<=0.95,"B","C"))) -> #DIV/0! | G34: =VLOOKUP(B$22:B$42,I$22:M$42,5,0) -> #N/A | K34: =J34/J$42 -> #DIV/0! | L34: =K34+L33 -> #DIV/0! | M34: =_xlfn.IFS(L34<80%,"A",L34<=95%,"B",L34>95%,"C") -> #DIV/0!
... D41: =C41/C$42 -> #DIV/0! | E41: =D41+E40 -> #DIV/0! | F41: =IF(AND(E41<=0),"C",IF(E41<=0.8,"A",IF(E41<=0.95,"B","C"))) -> #DIV/0! | G41: =VLOOKUP(B$22:B$42,I$22:M$42,5,0) -> #N/A | K41: =J41/J$42 -> #DIV/0! | L41: =K41+L40 -> #DIV/0! | M41: =_xlfn.IFS(L41<80%,"A",L41<=95%,"B",L41>95%,"C") -> #DIV/0!
C42: =SUM(C22:C41) -> 0 | D42: =SUM(D22:D41) -> #DIV/0! | J42: =SUM(J22:J41) -> 0 | K42: =SUM(K22:K41) -> #DIV/0!

Sheet АВС 23-29.03
B2: ОЧКИ
C3: Прибыль | D3: % прибыль | E3: Доля | F3: ABC прибыль | G3: ABC кол-во | J3: Кол-во | K3: % кол-во | L3: Доля | M3: ABC кол-во
B4: MR8854 C2 | C4: ='Юнит 23-29.03'!AE8 -> 9920.539 | D4: =C4/C$18 -> 0.32860621 | E4: =D4 -> 0.32860621 | F4: =IF(AND(E4<=0),"C",IF(E4<=0.8,"A",IF(E4<=0.95,"B","C"))) -> A | G4: =VLOOKUP(B$4:B$17,I$4:M$17,5,0) -> A | I4: MR8854 C2 | J4: ='Юнит 23-29.03'!R8 -> 14 | K4: =J4/J$18 -> 0.25925926 | L4: =K4 -> 0.25925926 | M4: =_xlfn.IFS(L4<80%,"A",L4<=95%,"B",L4>95%,"C") -> A
B5: flip черный | C5: ='Юнит 23-29.03'!AE13 -> 4886.6796 | D5: =C5/C$18 -> 0.16186553 | E5: =D5+E4 -> 0.49047174 | F5: =IF(AND(E5<=0),"C",IF(E5<=0.8,"A",IF(E5<=0.95,"B","C"))) -> A | G5: =VLOOKUP(B$4:B$17,I$4:M$17,5,0) -> A | I5: flip черный | J5: ='Юнит 23-29.03'!R13 -> 6 | K5: =J5/J$18 -> 0.11111111 | L5: =K5+L4 -> 0.37037037 | M5: =_xlfn.IFS(L5<80%,"A",L5<=95%,"B",L5>95%,"C") -> A
B6: qs синие | C6: ='Юнит 23-29.03'!AE5 -> 3925.109 | D6: =C6/C$18 -> 0.13001463 | E6: =D6+E5 -> 0.62048637 | F6: =IF(AND(E6<=0),"C",IF(E6<=0.8,"A",IF(E6<=0.95,"B","C"))) -> A | G6: =VLOOKUP(B$4:B$17,I$4:M$17,5,0) -> A | I6: flip коричневый | J6: ='Юнит 23-29.03'!R16 -> 6 | K6: =J6/J$18 -> 0.11111111 | L6: =K6+L5 -> 0.48148148 | M6: =_xlfn.IFS(L6<80%,"A",L6<=95%,"B",L6>95%,"C") -> A
B7: flip коричневый | C7: ='Юнит 23-29.03'!AE16 -> 2631.9007 | D7: =C7/C$18 -> 0.087178622 | E7: =D7+E6 -> 0.70766499 | F7: =IF(AND(E7<=0),"C",IF(E7<=0.8,"A",IF(E7<=0.95,"B","C"))) -> A | G7: =VLOOKUP(B$4:B$17,I$4:M$17,5,0) -> A | I7: qs черные | J7: ='Юнит 23-29.03'!R4 -> 5 | K7: =J7/J$18 -> 0.092592593 | L7: =K7+L6 -> 0.57407407 | M7: =_xlfn.IFS(L7<80%,"A",L7<=95%,"B",L7>95%,"C") -> A
B8: qs коричневые | C8: ='Юнит 23-29.03'!AE7 -> 2535.5044 | D8: =C8/C$18 -> 0.083985606 | E8: =D8+E7 -> 0.79165059 | F8: =IF(AND(E8<=0),"C",IF(E8<=0.8,"A",IF(E8<=0.95,"B","C"))) -> A | G8: =VLOOKUP(B$4:B$17,I$4:M$17,5,0) -> B | I8: th желт | J8: ='Юнит 23-29.03'!R11 -> 5 | K8: =J8/J$18 -> 0.092592593 | L8: =K8+L7 -> 0.66666667 | M8: =_xlfn.IFS(L8<80%,"A",L8<=95%,"B",L8>95%,"C") -> A
B9: qs черные | C9: ='Юнит 23-29.03'!AE4 -> 2033.3117 | D9: =C9/C$18 -> 0.067351063 | E9: =D9+E8 -> 0.85900166 | F9: =IF(AND(E9<=0),"C",IF(E9<=0.8,"A",IF(E9<=0.95,"B","C"))) -> B | G9: =VLOOKUP(B$4:B$17,I$4:M$17,5,0) -> A | I9: qs синие | J9: ='Юнит 23-29.03'!R5 -> 4 | K9: =J9/J$18 -> 0.074074074 | L9: =K9+L8 -> 0.74074074 | M9: =_xlfn.IFS(L9<80%,"A",L9<=95%,"B",L9>95%,"C") -> A
B10: th син | C10: ='Юнит 23-29.03'!AE10 -> 1980.0886 | D10: =C10/C$18 -> 0.065588112 | E10: =D10+E9 -> 0.92458977 | F10: =IF(AND(E10<=0),"C",IF(E10<=0.8,"A",IF(E10<=0.95,"B","C"))) -> B | G10: =VLOOKUP(B$4:B$17,I$4:M$17,5,0) -> A | I10: qs коричневые | J10: ='Юнит 23-29.03'!R7 -> 4 | K10: =J10/J$18 -> 0.074074074 | L10: =K10+L9 -> 0.81481481 | M10: =_xlfn.IFS(L10<80%,"A",L10<=95%,"B",L10>95%,"C") -> B
B11: th черн | C11: ='Юнит 23-29.03'!AE9 -> 1951.8173 | D11: =C11/C$18 -> 0.064651656 | E11: =D11+E10 -> 0.98924142 | F11: =IF(AND(E11<=0),"C",IF(E11<=0.8,"A",IF(E11<=0.95,"B","C"))) -> C | G11: =VLOOKUP(B$4:B$17,I$4:M$17,5,0) -> B | I11: th черн | J11: ='Юнит 23-29.03'!R9 -> 2 | K11: =J11/J$18 -> 0.037037037 | L11: =K11+L10 -> 0.85185185 | M11: =_xlfn.IFS(L11<80%,"A",L11<=95%,"B",L11>95%,"C") -> B
B12: flip жел | C12: ='Юнит 23-29.03'!AE15 -> 1845.8299 | D12: =C12/C$18 -> 0.06114095 | E12: =D12+E5 -> 0.55161269 | F12: =IF(AND(E12<=0),"C",IF(E12<=0.8,"A",IF(E12<=0.95,"B","C"))) -> A | G12: =VLOOKUP(B$4:B$17,I$4:M$17,5,0) -> A | I12: th син | J12: ='Юнит 23-29.03'!R10 -> 2 | K12: =J12/J$18 -> 0.037037037 | L12: =K12+L5 -> 0.40740741 | M12: =_xlfn.IFS(L12<80%,"A",L12<=95%,"B",L12>95%,"C") -> A
B13: flip синий | C13: ='Юнит 23-29.03'!AE14 -> 1153.505 | D13: =C13/C$18 -> 0.0382085 | E13: =D13+E12 -> 0.58982119 | F13: =IF(AND(E13<=0),"C",IF(E13<=0.8,"A",IF(E13<=0.95,"B","C"))) -> A | G13: =VLOOKUP(B$4:B$17,I$4:M$17,5,0) -> A | I13: th коричн | J13: ='Юнит 23-29.03'!R12 -> 2 | K13: =J13/J$18 -> 0.037037037 | L13: =K13+L12 -> 0.44444444 | M13: =_xlfn.IFS(L13<80%,"A",L13<=95%,"B",L13>95%,"C") -> A
B14: th желт | C14: ='Юнит 23-29.03'!AE11 -> 993.43114 | D14: =C14/C$18 -> 0.032906241 | E14: =D14+E13 -> 0.62272743 | F14: =IF(AND(E14<=0),"C",IF(E14<=0.8,"A",IF(E14<=0.95,"B","C"))) -> A | G14: =VLOOKUP(B$4:B$17,I$4:M$17,5,0) -> A | I14: flip жел | J14: ='Юнит 23-29.03'!R15 -> 2 | K14: =J14/J$18 -> 0.037037037 | L14: =K14+L13 -> 0.48148148 | M14: =_xlfn.IFS(L14<80%,"A",L14<=95%,"B",L14>95%,"C") -> A
B15: черные с железкой классика | C15: ='Юнит 23-29.03'!AE3 -> -1106.9801 | D15: =C15/C$18 -> -0.036667417 | E15: =D15+E14 -> 0.58606001 | F15: =IF(AND(E15<=0),"C",IF(E15<=0.8,"A",IF(E15<=0.95,"B","C"))) -> A | G15: =VLOOKUP(B$4:B$17,I$4:M$17,5,0) -> A | I15: черные с железкой классика | J15: ='Юнит 23-29.03'!R3 -> 1 | K15: =J15/J$18 -> 0.018518519 | L15: =K15+L14 -> 0.5 | M15: =_xlfn.IFS(L15<80%,"A",L15<=95%,"B",L15>95%,"C") -> A
B16: th коричн | C16: ='Юнит 23-29.03'!AE12 -> -1246.1138 | D16: =C16/C$18 -> -0.041276056 | E16: =D16+E15 -> 0.54478395 | F16: =IF(AND(E16<=0),"C",IF(E16<=0.8,"A",IF(E16<=0.95,"B","C"))) -> A | G16: =VLOOKUP(B$4:B$17,I$4:M$17,5,0) -> A | I16: flip синий | J16: ='Юнит 23-29.03'!R14 -> 1 | K16: =J16/J$18 -> 0.018518519 | L16: =K16+L15 -> 0.51851852 | M16: =_xlfn.IFS(L16<80%,"A",L16<=95%,"B",L16>95%,"C") -> A
B17: qs желтые | C17: ='Юнит 23-29.03'!AE6 -> -1314.8735 | D17: =C17/C$18 -> -0.043553642 | E17: =D17+E14 -> 0.57917379 | F17: =IF(AND(E17<=0),"C",IF(E17<=0.8,"A",IF(E17<=0.95,"B","C"))) -> A | G17: =VLOOKUP(B$4:B$17,I$4:M$17,5,0) -> A | I17: qs желтые | J17: ='Юнит 23-29.03'!R6 -> 0 | K17: =J17/J$18 -> 0 | L17: =K17+L14 -> 0.48148148 | M17: =_xlfn.IFS(L17<80%,"A",L17<=95%,"B",L17>95%,"C") -> A
C18: =SUM(C4:C17) -> 30189.749 | D18: =SUM(D4:D17) -> 1 | J18: =SUM(J4:J17) -> 54 | K18: =SUM(K4:K17) -> 1
C21: Прибыль | D21: % прибыль | E21: Доля | F21: ABC прибыль | G21: ABC кол-во | J21: Кол-во | K21: % кол-во | L21: Доля | M21: ABC кол-во
D22: =C22/C$42 -> #DIV/0! | E22: =D22 -> #DIV/0! | F22: =IF(AND(E22<=0),"C",IF(E22<=0.8,"A",IF(E22<=0.95,"B","C"))) -> #DIV/0! | G22: =VLOOKUP(B$22:B$42,I$22:M$42,5,0) -> #N/A | K22: =J22/J$42 -> #DIV/0! | L22: =K22 -> #DIV/0! | M22: =_xlfn.IFS(L22<80%,"A",L22<=95%,"B",L22>95%,"C") -> #DIV/0!
D23: =C23/C$42 -> #DIV/0! | E23: =D23+E22 -> #DIV/0! | F23: =IF(AND(E23<=0),"C",IF(E23<=0.8,"A",IF(E23<=0.95,"B","C"))) -> #DIV/0! | G23: =VLOOKUP(B$22:B$42,I$22:M$42,5,0) -> #N/A | K23: =J23/J$42 -> #DIV/0! | L23: =K23+L22 -> #DIV/0! | M23: =_xlfn.IFS(L23<80%,"A",L23<=95%,"B",L23>95%,"C") -> #DIV/0!
D24: =C24/C$42 -> #DIV/0! | E24: =D24+E23 -> #DIV/0! | F24: =IF(AND(E24<=0),"C",IF(E24<=0.8,"A",IF(E24<=0.95,"B","C"))) -> #DIV/0! | G24: =VLOOKUP(B$22:B$42,I$22:M$42,5,0) -> #N/A | K24: =J24/J$42 -> #DIV/0! | L24: =K24+L23 -> #DIV/0! | M24: =_xlfn.IFS(L24<80%,"A",L24<=95%,"B",L24>95%,"C") -> #DIV/0!
D25: =C25/C$42 -> #DIV/0! | E25: =D25+E24 -> #DIV/0! | F25: =IF(AND(E25<=0),"C",IF(E25<=0.8,"A",IF(E25<=0.95,"B","C"))) -> #DIV/0! | G25: =VLOOKUP(B$22:B$42,I$22:M$42,5,0) -> #N/A | K25: =J25/J$42 -> #DIV/0! | L25: =K25+L24 -> #DIV/0! | M25: =_xlfn.IFS(L25<80%,"A",L25<=95%,"B",L25>95%,"C") -> #DIV/0!
D26: =C26/C$42 -> #DIV/0! | E26: =D26+E25 -> #DIV/0! | F26: =IF(AND(E26<=0),"C",IF(E26<=0.8,"A",IF(E26<=0.95,"B","C"))) -> #DIV/0! | G26: =VLOOKUP(B$22:B$42,I$22:M$42,5,0) -> #N/A | K26: =J26/J$42 -> #DIV/0! | L26: =K26+L25 -> #DIV/0! | M26: =_xlfn.IFS(L26<80%,"A",L26<=95%,"B",L26>95%,"C") -> #DIV/0!
D27: =C27/C$42 -> #DIV/0! | E27: =D27+E26 -> #DIV/0! | F27: =IF(AND(E27<=0),"C",IF(E27<=0.8,"A",IF(E27<=0.95,"B","C"))) -> #DIV/0! | G27: =VLOOKUP(B$22:B$42,I$22:M$42,5,0) -> #N/A | K27: =J27/J$42 -> #DIV/0! | L27: =K27+L26 -> #DIV/0! | M27: =_xlfn.IFS(L27<80%,"A",L27<=95%,"B",L27>95%,"C") -> #DIV/0!
D28: =C28/C$42 -> #DIV/0! | E28: =D28+E27 -> #DIV/0! | F28: =IF(AND(E28<=0),"C",IF(E28<=0.8,"A",IF(E28<=0.95,"B","C"))) -> #DIV/0! | G28: =VLOOKUP(B$22:B$42,I$22:M$42,5,0) -> #N/A | K28: =J28/J$42 -> #DIV/0! | L28: =K28+L27 -> #DIV/0! | M28: =_xlfn.IFS(L28<80%,"A",L28<=95%,"B",L28>95%,"C") -> #DIV/0!
D29: =C29/C$42 -> #DIV/0! | E29: =D29+E28 -> #DIV/0! | F29: =IF(AND(E29<=0),"C",IF(E29<=0.8,"A",IF(E29<=0.95,"B","C"))) -> #DIV/0! | G29: =VLOOKUP(B$22:B$42,I$22:M$42,5,0) -> #N/A | K29: =J29/J$42 -> #DIV/0! | L29: =K29+L28 -> #DIV/0! | M29: =_xlfn.IFS(L29<80%,"A",L29<=95%,"B",L29>95%,"C") -> #DIV/0!
D30: =C30/C$42 -> #DIV/0! | E30: =D30+E29 -> #DIV/0! | F30: =IF(AND(E30<=0),"C",IF(E30<=0.8,"A",IF(E30<=0.95,"B","C"))) -> #DIV/0! | G30: =VLOOKUP(B$22:B$42,I$22:M$42,5,0) -> #N/A | K30: =J30/J$42 -> #DIV/0! | L30: =K30+L29 -> #DIV/0! | M30: =_xlfn.IFS(L30<80%,"A",L30<=95%,"B",L30>95%,"C") -> #DIV/0!
D31: =C31/C$42 -> #DIV/0! | E31: =D31+E30 -> #DIV/0! | F31: =IF(AND(E31<=0),"C",IF(E31<=0.8,"A",IF(E31<=0.95,"B","C"))) -> #DIV/0! | G31: =VLOOKUP(B$22:B$42,I$22:M$42,5,0) -> #N/A | K31: =J31/J$42 -> #DIV/0! | L31: =K31+L30 -> #DIV/0! | M31: =_xlfn.IFS(L31<80%,"A",L31<=95%,"B",L31>95%,"C") -> #DIV/0!
D32: =C32/C$42 -> #DIV/0! | E32: =D32+E31 -> #DIV/0! | F32: =IF(AND(E32<=0),"C",IF(E32<=0.8,"A",IF(E32<=0.95,"B","C"))) -> #DIV/0! | G32: =VLOOKUP(B$22:B$42,I$22:M$42,5,0) -> #N/A | K32: =J32/J$42 -> #DIV/0! | L32: =K32+L31 -> #DIV/0! | M32: =_xlfn.IFS(L32<80%,"A",L32<=95%,"B",L32>95%,"C") -> #DIV/0!
D33: =C33/C$42 -> #DIV/0! | E33: =D33+E32 -> #DIV/0! | F33: =IF(AND(E33<=0),"C",IF(E33<=0.8,"A",IF(E33<=0.95,"B","C"))) -> #DIV/0! | G33: =VLOOKUP(B$22:B$42,I$22:M$42,5,0) -> #N/A | K33: =J33/J$42 -> #DIV/0! | L33: =K33+L32 -> #DIV/0! | M33: =_xlfn.IFS(L33<80%,"A",L33<=95%,"B",L33>95%,"C") -> #DIV/0!
D34: =C34/C$42 -> #DIV/0! | E34: =D34+E33 -> #DIV/0! | F34: =IF(AND(E34<=0),"C",IF(E34<=0.8,"A",IF(E34<=0.95,"B","C"))) -> #DIV/0! | G34: =VLOOKUP(B$22:B$42,I$22:M$42,5,0) -> #N/A | K34: =J34/J$42 -> #DIV/0! | L34: =K34+L33 -> #DIV/0! | M34: =_xlfn.IFS(L34<80%,"A",L34<=95%,"B",L34>95%,"C") -> #DIV/0!
... D41: =C41/C$42 -> #DIV/0! | E41: =D41+E40 -> #DIV/0! | F41: =IF(AND(E41<=0),"C",IF(E41<=0.8,"A",IF(E41<=0.95,"B","C"))) -> #DIV/0! | G41: =VLOOKUP(B$22:B$42,I$22:M$42,5,0) -> #N/A | K41: =J41/J$42 -> #DIV/0! | L41: =K41+L40 -> #DIV/0! | M41: =_xlfn.IFS(L41<80%,"A",L41<=95%,"B",L41>95%,"C") -> #DIV/0!
C42: =SUM(C22:C41) -> 0 | D42: =SUM(D22:D41) -> #DIV/0! | J42: =SUM(J22:J41) -> 0 | K42: =SUM(K22:K41) -> #DIV/0!

Sheet АВС 16-22.03
B2: ОЧКИ
C3: Прибыль | D3: % прибыль | E3: Доля | F3: ABC прибыль | G3: ABC кол-во | J3: Кол-во | K3: % кол-во | L3: Доля | M3: ABC кол-во
B4: MR8854 C2 | C4: ='Юнит 16-22.03'!AE8 -> 17327.034 | D4: =C4/C$18 -> 0.42309671 | E4: =D4 -> 0.42309671 | F4: =IF(AND(E4<=0),"C",IF(E4<=0.8,"A",IF(E4<=0.95,"B","C"))) -> A | G4: =VLOOKUP(B$4:B$17,I$4:M$17,5,0) -> A | I4: MR8854 C2 | J4: ='Юнит 16-22.03'!R8 -> 21 | K4: =J4/J$18 -> 0.3559322 | L4: =K4 -> 0.3559322 | M4: =_xlfn.IFS(L4<80%,"A",L4<=95%,"B",L4>95%,"C") -> A
B5: flip жел | C5: ='Юнит 16-22.03'!AE15 -> 8577.8162 | D5: =C5/C$18 -> 0.20945569 | E5: =D5+E4 -> 0.63255239 | F5: =IF(AND(E5<=0),"C",IF(E5<=0.8,"A",IF(E5<=0.95,"B","C"))) -> A | G5: =VLOOKUP(B$4:B$17,I$4:M$17,5,0) -> A | I5: flip жел | J5: ='Юнит 16-22.03'!R15 -> 11 | K5: =J5/J$18 -> 0.18644068 | L5: =K5+L4 -> 0.54237288 | M5: =_xlfn.IFS(L5<80%,"A",L5<=95%,"B",L5>95%,"C") -> A
B6: flip коричневый | C6: ='Юнит 16-22.03'!AE16 -> 5015.337 | D6: =C6/C$18 -> 0.122466 | E6: =D6+E5 -> 0.7550184 | F6: =IF(AND(E6<=0),"C",IF(E6<=0.8,"A",IF(E6<=0.95,"B","C"))) -> A | G6: =VLOOKUP(B$4:B$17,I$4:M$17,5,0) -> A | I6: qs коричневые | J6: ='Юнит 16-22.03'!R7 -> 7 | K6: =J6/J$18 -> 0.11864407 | L6: =K6+L5 -> 0.66101695 | M6: =_xlfn.IFS(L6<80%,"A",L6<=95%,"B",L6>95%,"C") -> A
B7: qs коричневые | C7: ='Юнит 16-22.03'!AE7 -> 4914.6606 | D7: =C7/C$18 -> 0.12000766 | E7: =D7+E6 -> 0.87502606 | F7: =IF(AND(E7<=0),"C",IF(E7<=0.8,"A",IF(E7<=0.95,"B","C"))) -> B | G7: =VLOOKUP(B$4:B$17,I$4:M$17,5,0) -> A | I7: flip коричневый | J7: ='Юнит 16-22.03'!R16 -> 6 | K7: =J7/J$18 -> 0.10169492 | L7: =K7+L6 -> 0.76271186 | M7: =_xlfn.IFS(L7<80%,"A",L7<=95%,"B",L7>95%,"C") -> A
B8: qs желтые | C8: ='Юнит 16-22.03'!AE6 -> 3383.0169 | D8: =C8/C$18 -> 0.08260752 | E8: =D8+E7 -> 0.95763358 | F8: =IF(AND(E8<=0),"C",IF(E8<=0.8,"A",IF(E8<=0.95,"B","C"))) -> C | G8: =VLOOKUP(B$4:B$17,I$4:M$17,5,0) -> B | I8: qs желтые | J8: ='Юнит 16-22.03'!R6 -> 5 | K8: =J8/J$18 -> 0.084745763 | L8: =K8+L7 -> 0.84745763 | M8: =_xlfn.IFS(L8<80%,"A",L8<=95%,"B",L8>95%,"C") -> B
B9: flip черный | C9: ='Юнит 16-22.03'!AE13 -> 2165.3465 | D9: =C9/C$18 -> 0.052874079 | E9: =D9+E8 -> 1.0105077 | F9: =IF(AND(E9<=0),"C",IF(E9<=0.8,"A",IF(E9<=0.95,"B","C"))) -> C | G9: =VLOOKUP(B$4:B$17,I$4:M$17,5,0) -> A | I9: th син | J9: ='Юнит 16-22.03'!R10 -> 2 | K9: =J9/J$18 -> 0.033898305 | L9: =K9+L8 -> 0.88135593 | M9: =_xlfn.IFS(L9<80%,"A",L9<=95%,"B",L9>95%,"C") -> B
B10: th коричн | C10: ='Юнит 16-22.03'!AE12 -> 2025.0928 | D10: =C10/C$18 -> 0.049449324 | E10: =D10+E9 -> 1.059957 | F10: =IF(AND(E10<=0),"C",IF(E10<=0.8,"A",IF(E10<=0.95,"B","C"))) -> C | G10: =VLOOKUP(B$4:B$17,I$4:M$17,5,0) -> B | I10: th желт | J10: ='Юнит 16-22.03'!R11 -> 2 | K10: =J10/J$18 -> 0.033898305 | L10: =K10+L9 -> 0.91525424 | M10: =_xlfn.IFS(L10<80%,"A",L10<=95%,"B",L10>95%,"C") -> B
B11: черные с железкой классика | C11: ='Юнит 16-22.03'!AE3 -> 1064.1149 | D11: =C11/C$18 -> 0.025983876 | E11: =D11+E10 -> 1.0859409 | F11: =IF(AND(E11<=0),"C",IF(E11<=0.8,"A",IF(E11<=0.95,"B","C"))) -> C | G11: =VLOOKUP(B$4:B$17,I$4:M$17,5,0) -> A | I11: th коричн | J11: ='Юнит 16-22.03'!R12 -> 2 | K11: =J11/J$18 -> 0.033898305 | L11: =K11+L10 -> 0.94915254 | M11: =_xlfn.IFS(L11<80%,"A",L11<=95%,"B",L11>95%,"C") -> B
B12: th син | C12: ='Юнит 16-22.03'!AE10 -> 487.15649 | D12: =C12/C$18 -> 0.011895533 | E12: =D12+E5 -> 0.64444793 | F12: =IF(AND(E12<=0),"C",IF(E12<=0.8,"A",IF(E12<=0.95,"B","C"))) -> A | G12: =VLOOKUP(B$4:B$17,I$4:M$17,5,0) -> B | I12: flip черный | J12: ='Юнит 16-22.03'!R13 -> 2 | K12: =J12/J$18 -> 0.033898305 | L12: =K12+L5 -> 0.57627119 | M12: =_xlfn.IFS(L12<80%,"A",L12<=95%,"B",L12>95%,"C") -> A
B13: th черн | C13: ='Юнит 16-22.03'!AE9 -> -227.76 | D13: =C13/C$18 -> -0.005561512 | E13: =D13+E12 -> 0.63888642 | F13: =IF(AND(E13<=0),"C",IF(E13<=0.8,"A",IF(E13<=0.95,"B","C"))) -> A | G13: =VLOOKUP(B$4:B$17,I$4:M$17,5,0) -> A | I13: черные с железкой классика | J13: ='Юнит 16-22.03'!R3 -> 1 | K13: =J13/J$18 -> 0.016949153 | L13: =K13+L12 -> 0.59322034 | M13: =_xlfn.IFS(L13<80%,"A",L13<=95%,"B",L13>95%,"C") -> A
B14: flip синий | C14: ='Юнит 16-22.03'!AE14 -> -227.76 | D14: =C14/C$18 -> -0.005561512 | E14: =D14+E13 -> 0.6333249 | F14: =IF(AND(E14<=0),"C",IF(E14<=0.8,"A",IF(E14<=0.95,"B","C"))) -> A | G14: =VLOOKUP(B$4:B$17,I$4:M$17,5,0) -> A | I14: qs черные | J14: ='Юнит 16-22.03'!R4 -> 0 | K14: =J14/J$18 -> 0 | L14: =K14+L13 -> 0.59322034 | M14: =_xlfn.IFS(L14<80%,"A",L14<=95%,"B",L14>95%,"C") -> A
B15: th желт | C15: ='Юнит 16-22.03'!AE11 -> -532.03327 | D15: =C15/C$18 -> -0.012991348 | E15: =D15+E14 -> 0.62033356 | F15: =IF(AND(E15<=0),"C",IF(E15<=0.8,"A",IF(E15<=0.95,"B","C"))) -> A | G15: =VLOOKUP(B$4:B$17,I$4:M$17,5,0) -> B | I15: qs синие | J15: ='Юнит 16-22.03'!R5 -> 0 | K15: =J15/J$18 -> 0 | L15: =K15+L14 -> 0.59322034 | M15: =_xlfn.IFS(L15<80%,"A",L15<=95%,"B",L15>95%,"C") -> A
B16: qs синие | C16: ='Юнит 16-22.03'!AE5 -> -846.19408 | D16: =C16/C$18 -> -0.020662621 | E16: =D16+E15 -> 0.59967094 | F16: =IF(AND(E16<=0),"C",IF(E16<=0.8,"A",IF(E16<=0.95,"B","C"))) -> A | G16: =VLOOKUP(B$4:B$17,I$4:M$17,5,0) -> A | I16: th черн | J16: ='Юнит 16-22.03'!R9 -> 0 | K16: =J16/J$18 -> 0 | L16: =K16+L15 -> 0.59322034 | M16: =_xlfn.IFS(L16<80%,"A",L16<=95%,"B",L16>95%,"C") -> A
B17: qs черные | C17: ='Юнит 16-22.03'!AE4 -> -2172.9357 | D17: =C17/C$18 -> -0.053059395 | E17: =D17+E14 -> 0.58026551 | F17: =IF(AND(E17<=0),"C",IF(E17<=0.8,"A",IF(E17<=0.95,"B","C"))) -> A | G17: =VLOOKUP(B$4:B$17,I$4:M$17,5,0) -> A | I17: flip синий | J17: ='Юнит 16-22.03'!R14 -> 0 | K17: =J17/J$18 -> 0 | L17: =K17+L14 -> 0.59322034 | M17: =_xlfn.IFS(L17<80%,"A",L17<=95%,"B",L17>95%,"C") -> A
C18: =SUM(C4:C17) -> 40952.892 | D18: =SUM(D4:D17) -> 1 | J18: =SUM(J4:J17) -> 59 | K18: =SUM(K4:K17) -> 1
C21: Прибыль | D21: % прибыль | E21: Доля | F21: ABC прибыль | G21: ABC кол-во | J21: Кол-во | K21: % кол-во | L21: Доля | M21: ABC кол-во
D22: =C22/C$42 -> #DIV/0! | E22: =D22 -> #DIV/0! | F22: =IF(AND(E22<=0),"C",IF(E22<=0.8,"A",IF(E22<=0.95,"B","C"))) -> #DIV/0! | G22: =VLOOKUP(B$22:B$42,I$22:M$42,5,0) -> #N/A | K22: =J22/J$42 -> #DIV/0! | L22: =K22 -> #DIV/0! | M22: =_xlfn.IFS(L22<80%,"A",L22<=95%,"B",L22>95%,"C") -> #DIV/0!
D23: =C23/C$42 -> #DIV/0! | E23: =D23+E22 -> #DIV/0! | F23: =IF(AND(E23<=0),"C",IF(E23<=0.8,"A",IF(E23<=0.95,"B","C"))) -> #DIV/0! | G23: =VLOOKUP(B$22:B$42,I$22:M$42,5,0) -> #N/A | K23: =J23/J$42 -> #DIV/0! | L23: =K23+L22 -> #DIV/0! | M23: =_xlfn.IFS(L23<80%,"A",L23<=95%,"B",L23>95%,"C") -> #DIV/0!
D24: =C24/C$42 -> #DIV/0! | E24: =D24+E23 -> #DIV/0! | F24: =IF(AND(E24<=0),"C",IF(E24<=0.8,"A",IF(E24<=0.95,"B","C"))) -> #DIV/0! | G24: =VLOOKUP(B$22:B$42,I$22:M$42,5,0) -> #N/A | K24: =J24/J$42 -> #DIV/0! | L24: =K24+L23 -> #DIV/0! | M24: =_xlfn.IFS(L24<80%,"A",L24<=95%,"B",L24>95%,"C") -> #DIV/0!
D25: =C25/C$42 -> #DIV/0! | E25: =D25+E24 -> #DIV/0! | F25: =IF(AND(E25<=0),"C",IF(E25<=0.8,"A",IF(E25<=0.95,"B","C"))) -> #DIV/0! | G25: =VLOOKUP(B$22:B$42,I$22:M$42,5,0) -> #N/A | K25: =J25/J$42 -> #DIV/0! | L25: =K25+L24 -> #DIV/0! | M25: =_xlfn.IFS(L25<80%,"A",L25<=95%,"B",L25>95%,"C") -> #DIV/0!
D26: =C26/C$42 -> #DIV/0! | E26: =D26+E25 -> #DIV/0! | F26: =IF(AND(E26<=0),"C",IF(E26<=0.8,"A",IF(E26<=0.95,"B","C"))) -> #DIV/0! | G26: =VLOOKUP(B$22:B$42,I$22:M$42,5,0) -> #N/A | K26: =J26/J$42 -> #DIV/0! | L26: =K26+L25 -> #DIV/0! | M26: =_xlfn.IFS(L26<80%,"A",L26<=95%,"B",L26>95%,"C") -> #DIV/0!
D27: =C27/C$42 -> #DIV/0! | E27: =D27+E26 -> #DIV/0! | F27: =IF(AND(E27<=0),"C",IF(E27<=0.8,"A",IF(E27<=0.95,"B","C"))) -> #DIV/0! | G27: =VLOOKUP(B$22:B$42,I$22:M$42,5,0) -> #N/A | K27: =J27/J$42 -> #DIV/0! | L27: =K27+L26 -> #DIV/0! | M27: =_xlfn.IFS(L27<80%,"A",L27<=95%,"B",L27>95%,"C") -> #DIV/0!
D28: =C28/C$42 -> #DIV/0! | E28: =D28+E27 -> #DIV/0! | F28: =IF(AND(E28<=0),"C",IF(E28<=0.8,"A",IF(E28<=0.95,"B","C"))) -> #DIV/0! | G28: =VLOOKUP(B$22:B$42,I$22:M$42,5,0) -> #N/A | K28: =J28/J$42 -> #DIV/0! | L28: =K28+L27 -> #DIV/0! | M28: =_xlfn.IFS(L28<80%,"A",L28<=95%,"B",L28>95%,"C") -> #DIV/0!
D29: =C29/C$42 -> #DIV/0! | E29: =D29+E28 -> #DIV/0! | F29: =IF(AND(E29<=0),"C",IF(E29<=0.8,"A",IF(E29<=0.95,"B","C"))) -> #DIV/0! | G29: =VLOOKUP(B$22:B$42,I$22:M$42,5,0) -> #N/A | K29: =J29/J$42 -> #DIV/0! | L29: =K29+L28 -> #DIV/0! | M29: =_xlfn.IFS(L29<80%,"A",L29<=95%,"B",L29>95%,"C") -> #DIV/0!
D30: =C30/C$42 -> #DIV/0! | E30: =D30+E29 -> #DIV/0! | F30: =IF(AND(E30<=0),"C",IF(E30<=0.8,"A",IF(E30<=0.95,"B","C"))) -> #DIV/0! | G30: =VLOOKUP(B$22:B$42,I$22:M$42,5,0) -> #N/A | K30: =J30/J$42 -> #DIV/0! | L30: =K30+L29 -> #DIV/0! | M30: =_xlfn.IFS(L30<80%,"A",L30<=95%,"B",L30>95%,"C") -> #DIV/0!
D31: =C31/C$42 -> #DIV/0! | E31: =D31+E30 -> #DIV/0! | F31: =IF(AND(E31<=0),"C",IF(E31<=0.8,"A",IF(E31<=0.95,"B","C"))) -> #DIV/0! | G31: =VLOOKUP(B$22:B$42,I$22:M$42,5,0) -> #N/A | K31: =J31/J$42 -> #DIV/0! | L31: =K31+L30 -> #DIV/0! | M31: =_xlfn.IFS(L31<80%,"A",L31<=95%,"B",L31>95%,"C") -> #DIV/0!
D32: =C32/C$42 -> #DIV/0! | E32: =D32+E31 -> #DIV/0! | F32: =IF(AND(E32<=0),"C",IF(E32<=0.8,"A",IF(E32<=0.95,"B","C"))) -> #DIV/0! | G32: =VLOOKUP(B$22:B$42,I$22:M$42,5,0) -> #N/A | K32: =J32/J$42 -> #DIV/0! | L32: =K32+L31 -> #DIV/0! | M32: =_xlfn.IFS(L32<80%,"A",L32<=95%,"B",L32>95%,"C") -> #DIV/0!
D33: =C33/C$42 -> #DIV/0! | E33: =D33+E32 -> #DIV/0! | F33: =IF(AND(E33<=0),"C",IF(E33<=0.8,"A",IF(E33<=0.95,"B","C"))) -> #DIV/0! | G33: =VLOOKUP(B$22:B$42,I$22:M$42,5,0) -> #N/A | K33: =J33/J$42 -> #DIV/0! | L33: =K33+L32 -> #DIV/0! | M33: =_xlfn.IFS(L33<80%,"A",L33<=95%,"B",L33>95%,"C") -> #DIV/0!
D34: =C34/C$42 -> #DIV/0! | E34: =D34+E33 -> #DIV/0! | F34: =IF(AND(E34<=0),"C",IF(E34<=0.8,"A",IF(E34<=0.95,"B","C"))) -> #DIV/0! | G34: =VLOOKUP(B$22:B$42,I$22:M$42,5,0) -> #N/A | K34: =J34/J$42 -> #DIV/0! | L34: =K34+L33 -> #DIV/0! | M34: =_xlfn.IFS(L34<80%,"A",L34<=95%,"B",L34>95%,"C") -> #DIV/0!
... D41: =C41/C$42 -> #DIV/0! | E41: =D41+E40 -> #DIV/0! | F41: =IF(AND(E41<=0),"C",IF(E41<=0.8,"A",IF(E41<=0.95,"B","C"))) -> #DIV/0! | G41: =VLOOKUP(B$22:B$42,I$22:M$42,5,0) -> #N/A | K41: =J41/J$42 -> #DIV/0! | L41: =K41+L40 -> #DIV/0! | M41: =_xlfn.IFS(L41<80%,"A",L41<=95%,"B",L41>95%,"C") -> #DIV/0!
C42: =SUM(C22:C41) -> 0 | D42: =SUM(D22:D41) -> #DIV/0! | J42: =SUM(J22:J41) -> 0 | K42: =SUM(K22:K41) -> #DIV/0!

Sheet АВС 09-15.03
B2: ОЧКИ
C3: Прибыль | D3: % прибыль | E3: Доля | F3: ABC прибыль | G3: ABC кол-во | J3: Кол-во | K3: % кол-во | L3: Доля | M3: ABC кол-во
B4: MR8854 C2 | C4: ='Юнит 09-15.03'!AE8 -> 17647.861 | D4: =C4/C$18 -> 0.31065247 | E4: =D4 -> 0.31065247 | F4: =IF(AND(E4<=0),"C",IF(E4<=0.8,"A",IF(E4<=0.95,"B","C"))) -> A | G4: =VLOOKUP(B$4:B$17,I$4:M$17,5,0) -> A | I4: MR8854 C2 | J4: ='Юнит 09-15.03'!R8 -> 27 | K4: =J4/J$18 -> 0.29347826 | L4: =K4 -> 0.29347826 | M4: =_xlfn.IFS(L4<80%,"A",L4<=95%,"B",L4>95%,"C") -> A
B5: flip черный | C5: ='Юнит 09-15.03'!AE13 -> 8759.325 | D5: =C5/C$18 -> 0.154189 | E5: =D5+E4 -> 0.46484147 | F5: =IF(AND(E5<=0),"C",IF(E5<=0.8,"A",IF(E5<=0.95,"B","C"))) -> A | G5: =VLOOKUP(B$4:B$17,I$4:M$17,5,0) -> A | I5: flip жел | J5: ='Юнит 09-15.03'!R15 -> 13 | K5: =J5/J$18 -> 0.14130435 | L5: =K5+L4 -> 0.43478261 | M5: =_xlfn.IFS(L5<80%,"A",L5<=95%,"B",L5>95%,"C") -> A
B6: flip жел | C6: ='Юнит 09-15.03'!AE15 -> 6988.5675 | D6: =C6/C$18 -> 0.12301863 | E6: =D6+E5 -> 0.5878601 | F6: =IF(AND(E6<=0),"C",IF(E6<=0.8,"A",IF(E6<=0.95,"B","C"))) -> A | G6: =VLOOKUP(B$4:B$17,I$4:M$17,5,0) -> A | I6: qs коричневые | J6: ='Юнит 09-15.03'!R7 -> 12 | K6: =J6/J$18 -> 0.13043478 | L6: =K6+L5 -> 0.56521739 | M6: =_xlfn.IFS(L6<80%,"A",L6<=95%,"B",L6>95%,"C") -> A
B7: qs коричневые | C7: ='Юнит 09-15.03'!AE7 -> 4618.0378 | D7: =C7/C$18 -> 0.08129058 | E7: =D7+E6 -> 0.66915069 | F7: =IF(AND(E7<=0),"C",IF(E7<=0.8,"A",IF(E7<=0.95,"B","C"))) -> A | G7: =VLOOKUP(B$4:B$17,I$4:M$17,5,0) -> A | I7: flip черный | J7: ='Юнит 09-15.03'!R13 -> 10 | K7: =J7/J$18 -> 0.10869565 | L7: =K7+L6 -> 0.67391304 | M7: =_xlfn.IFS(L7<80%,"A",L7<=95%,"B",L7>95%,"C") -> A
B8: qs желтые | C8: ='Юнит 09-15.03'!AE6 -> 3849.3728 | D8: =C8/C$18 -> 0.067759893 | E8: =D8+E7 -> 0.73691058 | F8: =IF(AND(E8<=0),"C",IF(E8<=0.8,"A",IF(E8<=0.95,"B","C"))) -> A | G8: =VLOOKUP(B$4:B$17,I$4:M$17,5,0) -> A | I8: qs желтые | J8: ='Юнит 09-15.03'!R6 -> 7 | K8: =J8/J$18 -> 0.076086957 | L8: =K8+L7 -> 0.75 | M8: =_xlfn.IFS(L8<80%,"A",L8<=95%,"B",L8>95%,"C") -> A
B9: th коричн | C9: ='Юнит 09-15.03'!AE12 -> 3706.648 | D9: =C9/C$18 -> 0.065247531 | E9: =D9+E8 -> 0.80215811 | F9: =IF(AND(E9<=0),"C",IF(E9<=0.8,"A",IF(E9<=0.95,"B","C"))) -> B | G9: =VLOOKUP(B$4:B$17,I$4:M$17,5,0) -> B | I9: flip коричневый | J9: ='Юнит 09-15.03'!R16 -> 6 | K9: =J9/J$18 -> 0.065217391 | L9: =K9+L8 -> 0.81521739 | M9: =_xlfn.IFS(L9<80%,"A",L9<=95%,"B",L9>95%,"C") -> B
B10: qs синие | C10: ='Юнит 09-15.03'!AE5 -> 3561.3402 | D10: =C10/C$18 -> 0.062689702 | E10: =D10+E9 -> 0.86484781 | F10: =IF(AND(E10<=0),"C",IF(E10<=0.8,"A",IF(E10<=0.95,"B","C"))) -> B | G10: =VLOOKUP(B$4:B$17,I$4:M$17,5,0) -> A | I10: th коричн | J10: ='Юнит 09-15.03'!R12 -> 4 | K10: =J10/J$18 -> 0.043478261 | L10: =K10+L9 -> 0.85869565 | M10: =_xlfn.IFS(L10<80%,"A",L10<=95%,"B",L10>95%,"C") -> B
B11: flip коричневый | C11: ='Юнит 09-15.03'!AE16 -> 3184.4268 | D11: =C11/C$18 -> 0.056054956 | E11: =D11+E10 -> 0.92090277 | F11: =IF(AND(E11<=0),"C",IF(E11<=0.8,"A",IF(E11<=0.95,"B","C"))) -> B | G11: =VLOOKUP(B$4:B$17,I$4:M$17,5,0) -> B | I11: черные с железкой классика | J11: ='Юнит 09-15.03'!R3 -> 3 | K11: =J11/J$18 -> 0.032608696 | L11: =K11+L10 -> 0.89130435 | M11: =_xlfn.IFS(L11<80%,"A",L11<=95%,"B",L11>95%,"C") -> B
B12: qs черные | C12: ='Юнит 09-15.03'!AE4 -> 2163.9007 | D12: =C12/C$18 -> 0.038090797 | E12: =D12+E5 -> 0.50293227 | F12: =IF(AND(E12<=0),"C",IF(E12<=0.8,"A",IF(E12<=0.95,"B","C"))) -> A | G12: =VLOOKUP(B$4:B$17,I$4:M$17,5,0) -> A | I12: qs черные | J12: ='Юнит 09-15.03'!R4 -> 3 | K12: =J12/J$18 -> 0.032608696 | L12: =K12+L5 -> 0.4673913 | M12: =_xlfn.IFS(L12<80%,"A",L12<=95%,"B",L12>95%,"C") -> A
B13: черные с железкой классика | C13: ='Юнит 09-15.03'!AE3 -> 1187.0783 | D13: =C13/C$18 -> 0.02089595 | E13: =D13+E12 -> 0.52382822 | F13: =IF(AND(E13<=0),"C",IF(E13<=0.8,"A",IF(E13<=0.95,"B","C"))) -> A | G13: =VLOOKUP(B$4:B$17,I$4:M$17,5,0) -> B | I13: qs синие | J13: ='Юнит 09-15.03'!R5 -> 3 | K13: =J13/J$18 -> 0.032608696 | L13: =K13+L12 -> 0.5 | M13: =_xlfn.IFS(L13<80%,"A",L13<=95%,"B",L13>95%,"C") -> A
B14: th черн | C14: ='Юнит 09-15.03'!AE9 -> 865.64118 | D14: =C14/C$18 -> 0.015237743 | E14: =D14+E13 -> 0.53906596 | F14: =IF(AND(E14<=0),"C",IF(E14<=0.8,"A",IF(E14<=0.95,"B","C"))) -> A | G14: =VLOOKUP(B$4:B$17,I$4:M$17,5,0) -> A | I14: th черн | J14: ='Юнит 09-15.03'!R9 -> 2 | K14: =J14/J$18 -> 0.02173913 | L14: =K14+L13 -> 0.52173913 | M14: =_xlfn.IFS(L14<80%,"A",L14<=95%,"B",L14>95%,"C") -> A
B15: th син | C15: ='Юнит 09-15.03'!AE10 -> 378.06795 | D15: =C15/C$18 -> 0.0066550697 | E15: =D15+E14 -> 0.54572103 | F15: =IF(AND(E15<=0),"C",IF(E15<=0.8,"A",IF(E15<=0.95,"B","C"))) -> A | G15: =VLOOKUP(B$4:B$17,I$4:M$17,5,0) -> A | I15: th син | J15: ='Юнит 09-15.03'!R10 -> 1 | K15: =J15/J$18 -> 0.010869565 | L15: =K15+L14 -> 0.5326087 | M15: =_xlfn.IFS(L15<80%,"A",L15<=95%,"B",L15>95%,"C") -> A
