Workbook

Sheet Реклама
B2: БАЛАНС | E2: СЧЕТ | H2: ПРОМОБОНУСЫ | K2: Неделя
B3: Номер документа | C3: Сумма | D3: Даты | E3: Номер документа | F3: Сумма | G3: Даты | H3: Номер документа | I3: Сумма | J3: Даты
B4: 277433850 | C4: 1376 | D4: 28-31.12 | E4: 277433847 | F4: 25829 | G4: 28-31.12 | H4: 0 | I4: 109 | J4: 29-31.12 | K4: 1
B5: 277539131 | C5: 1150 | D5: 36951 | E5: 277609313 | F5: 21489 | G5: 36982 | H5: 0 | I5: 363 | J5: 36982
B6: 279208603 | C6: 3455 | D6: 37168 | E6: 279208599 | F6: 51313 | G6: 37199 | H6: 0 | I6: 569 | J6: 37200 | K6: 2
B7: 280269091 | C7: 10268 | D7: 11-18.01 | E7: 280221209 | F7: 99763 | G7: 11-18.01 | H7: 0 | I7: 557 | J7: 12-18.01 | K7: 3
B8: 281267335 | C8: 70408 | D8: 19-25.01 | E8: 281348313 | F8: 67741 | G8: 18-25.01 | H8: 0 | I8: 195 | J8: 19-25.01 | K8: 4
B9: 282258474 | C9: 25521 | D9: 25-31.01 | E9: 282345086 | F9: 133680 | G9: 25-31.01 | H9: 0 | I9: 80 | J9: 26-31.01 | K9: 5
B10: 282365257 | C10: 1268 | D10: 46054 | E10: 282392960 | F10: 4672 | G10: 46054
B11: 283332206 | C11: 111419 | D11: 37469 | E11: 283415801 | F11: 126688 | G11: 37469 | H11: 0 | I11: 3554 | J11: 37440 | K11: 6
B12: 284423647 | C12: 145581 | D12: 08-15.02 | E12: 284416459 | F12: 138670 | G12: 08-15.02 | H12: 0 | I12: 44 | J12: 46063 | K12: 7
B13: 285348588 | C13: 50989 | D13: 15-22.02 | E13: 285348587 | F13: 265182 | G13: 15-22.02 | K13: 8
B14: 286343097 | C14: 232417 | D14: 22-28.02 | E14: 286343091 | F14: 72806 | G14: 22-28.02 | H14: 0 | I14: 26 | J14: 46081 | K14: 9
B15: 286459024 | C15: 1243 | D15: 46082 | E15: 286489905 | F15: 5815 | G15: 46082
B16: 287708507 | C16: 74484 | D16: 01.03-08.03 | E16: 287655729 | F16: 252853 | G16: 01.03-08.03 | K16: 10
B17: 288763309 | C17: 304803 | D17: 08-15.03 | E17: 288777227 | F17: 178004 | G17: 08-15.03 | H17: 0 | I17: 46 | J17: 46091 | K17: 11
H39: .

Sheet Сводная
B2: Период | E2: Дата поступления дс | F2: Итого к перечислению на счет, руб | G2: шт. | J2: ВБ реализовал товар (выручка с СПП) | M2: Выручка до вычета комиссии ВБ | P2: Себестоимость продаж | Q2: Логистика WB | R2: Комиссия WB | S2: Хранение WB | T2: Платная приемка WB | U2: Штрафы WB | V2: Прочие удержания WB | W2: Реклама БАЛАНС | X2: Реклама СЧЕТ | Y2: Блогеры | Z2: Налог | AA2: Прочие поступления WB | AB2: Прибыль до вычета налогов | AC2: Прибыль после вычета налогов | AD2: Итог месяц | AE2: % Cебестоимости | AF2: Маржинальность, % | AG2: Рентабельность, % | AH2: Доля рекламы, %
B3: Месяц | C3: Даты | D3: Нед | G3: Заказы | H3: Продажи | I3: Возвраты | J3: Продажи | K3: Возвраты | L3: Общая | M3: Продажи | N3: Возвраты | O3: Общая
B4: Декабрь очки | C4: 29-31.12 | D4: 1 | F4: =IFERROR(O4-SUM(Q4:W4)+AA4,0) -> 62313.298 | G4: =ДЕКАБРЬ!N100 -> 129 | H4: =ДЕКАБРЬ!S100 -> 127 | I4: =ДЕКАБРЬ!T100 -> -5 | J4: =ДЕКАБРЬ!V100 -> 118047.57 | K4: =ДЕКАБРЬ!W100 -> -6409 | L4: =IFERROR(J4+K4,0) -> 111638.57 | M4: =ДЕКАБРЬ!Y100 -> 138964.57 | N4: =ДЕКАБРЬ!Z100 -> -7526 | O4: =IFERROR(M4+N4,0) -> 131438.57 | P4: =ДЕКАБРЬ!AD100 -> 15240.45 | Q4: =ДЕКАБРЬ!AG100 -> 17381.1 | R4: =ДЕКАБРЬ!AE100 -> 48126.54 | S4: =ДЕКАБРЬ!AL100 -> 3615.9322 | T4: 1.7 | U4: =ДЕКАБРЬ!AM100 -> 0 | W4: =ДЕКАБРЬ!AH100 -> 0 | X4: =ДЕКАБРЬ!AI100 -> 0 | Y4: =ДЕКАБРЬ!AK100 -> 0 | Z4: =ДЕКАБРЬ!AN100 -> 6117.8 | AB4: =O4-SUM(P4:Y4)+AA4 -> 47072.848 | AC4: =O4-SUM(P4:Z4)+AA4 -> 40955.048 | AD4: =SUM(AC4:AC5) -> 40954.76 | AE4: =P4/O4 -> 0.11595112 | AF4: =AC4/P4 -> 2.6872597 | AG4: =AC4/O4 -> 0.31159079 | AH4: =(W4+X4+Y4)/O4 -> 0
B5: Декабрь туники | C5: 29-31.12 | D5: 1 | F5: =IFERROR(O5-SUM(Q5:W5)+AA5,0) -> -0.28775523 | G5: =ДЕКАБРЬ!N108 -> 0 | H5: =ДЕКАБРЬ!S108 -> 0 | I5: =ДЕКАБРЬ!T108 -> 0 | J5: =ДЕКАБРЬ!V108 -> 0 | K5: =ДЕКАБРЬ!W108 -> 0 | L5: =IFERROR(J5+K5,0) -> 0 | M5: =ДЕКАБРЬ!Y108 -> 0 | N5: =ДЕКАБРЬ!Z108 -> 0 | O5: =IFERROR(M5+N5,0) -> 0 | P5: =ДЕКАБРЬ!AD108 -> 0 | Q5: =ДЕКАБРЬ!AG108 -> 0 | R5: =ДЕКАБРЬ!AE108 -> 0 | S5: =ДЕКАБРЬ!AL108 -> 0.28775523 | U5: =ДЕКАБРЬ!AM108 -> 0 | W5: =ДЕКАБРЬ!AH108 -> 0 | X5: =ДЕКАБРЬ!AI108 -> 0 | Y5: =ДЕКАБРЬ!AK108 -> 0 | Z5: =ДЕКАБРЬ!AN108 -> 0 | AB5: =O5-SUM(P5:Y5)+AA5 -> -0.28775523 | AC5: =O5-SUM(P5:Z5)+AA5 -> -0.28775523 | AE5: =P5/O5 -> #DIV/0! | AF5: =AC5/P5 -> #DIV/0! | AG5: =AC5/O5 -> #DIV/0! | AH5: =(W5+X5+Y5)/O5 -> #DIV/0!
B6: Январь очки | C6: 01.01-01.02 | D6: 1-5 | F6: =IFERROR(O6-SUM(Q6:W6)+AA6,0) -> 955718.86 | G6: =ЯНВАРЬ!N100 -> 4961 | H6: =ЯНВАРЬ!S100 -> 2362 | I6: =ЯНВАРЬ!T100 -> -53 | J6: =ЯНВАРЬ!V100 -> 1728382.8 | K6: =ЯНВАРЬ!W100 -> -44657.88 | L6: =IFERROR(J6+K6,0) -> 1683724.9 | M6: =ЯНВАРЬ!Y100 -> 2303342.1 | N6: =ЯНВАРЬ!Z100 -> -58267.04 | O6: =IFERROR(M6+N6,0) -> 2245075 | P6: =ЯНВАРЬ!AD100 -> 292876.64 | Q6: =ЯНВАРЬ!AG100 -> 276475.65 | R6: =ЯНВАРЬ!AE100 -> 833669.77 | S6: =ЯНВАРЬ!AL100 -> 40333.14 | U6: =ЯНВАРЬ!AM100 -> 0 | V6: 25431.6 | W6: =ЯНВАРЬ!AH100 -> 113446 | X6: =ЯНВАРЬ!AI100 -> 404487 | Y6: =ЯНВАРЬ!AK100 -> 0 | Z6: =ЯНВАРЬ!AN100 -> 96625.98 | AB6: =O6-SUM(P6:Y6)+AA6 -> 258355.22 | AC6: =O6-SUM(P6:Z6)+AA6 -> 161729.24 | AD6: =SUM(AC6:AC8) -> 161369.85 | AE6: =P6/O6 -> 0.13045294 | AF6: =AC6/P6 -> 0.55220942 | AG6: =AC6/O6 -> 0.072037343 | AH6: =(W6+X6+Y6)/O6 -> 0.23069741
B7: Январь туники | C7: 01.01-01.02 | D7: 1-5 | F7: =IFERROR(O7-SUM(Q7:W7)+AA7,0) -> -186.4297 | G7: =ЯНВАРЬ!N108 -> 1 | H7: =ЯНВАРЬ!S108 -> 0 | I7: =ЯНВАРЬ!T108 -> 0 | J7: =ЯНВАРЬ!V108 -> 0 | K7: =ЯНВАРЬ!W108 -> 0 | L7: =IFERROR(J7+K7,0) -> 0 | M7: =ЯНВАРЬ!Y108 -> 0 | N7: =ЯНВАРЬ!Z108 -> 0 | O7: =IFERROR(M7+N7,0) -> 0 | P7: =ЯНВАРЬ!AD108 -> 0 | Q7: =ЯНВАРЬ!AG108 -> 183.22 | R7: =ЯНВАРЬ!AE108 -> 0 | S7: =ЯНВАРЬ!AL108 -> 3.209704 | U7: =ЯНВАРЬ!AM108 -> 0 | W7: =ЯНВАРЬ!AH108 -> 0 | X7: =ЯНВАРЬ!AI108 -> 0 | Y7: =ЯНВАРЬ!AK108 -> 0 | Z7: =ЯНВАРЬ!AN108 -> 0 | AB7: =O7-SUM(P7:Y7)+AA7 -> -186.4297 | AC7: =O7-SUM(P7:Z7)+AA7 -> -186.4297 | AE7: =P7/O7 -> #DIV/0! | AF7: =AC7/P7 -> #DIV/0! | AG7: =AC7/O7 -> #DIV/0! | AH7: =(W7+X7+Y7)/O7 -> #DIV/0!
B8: Январь шапки | C8: 01.01-01.02 | D8: 1-5 | F8: =IFERROR(O8-SUM(Q8:W8)+AA8,0) -> -172.96 | G8: =ЯНВАРЬ!N119 -> 0 | H8: =ЯНВАРЬ!S119 -> 0 | I8: =ЯНВАРЬ!T119 -> 0 | J8: =ЯНВАРЬ!V119 -> 0 | K8: =ЯНВАРЬ!W119 -> 0 | L8: =IFERROR(J8+K8,0) -> 0 | M8: =ЯНВАРЬ!Y119 -> 0 | N8: =ЯНВАРЬ!Z119 -> 0 | O8: =IFERROR(M8+N8,0) -> 0 | P8: =ЯНВАРЬ!AD119 -> 0 | Q8: =ЯНВАРЬ!AG119 -> 172.96 | R8: =ЯНВАРЬ!AE119 -> 0 | S8: =ЯНВАРЬ!AL119 -> 0 | U8: =ЯНВАРЬ!AM119 -> 0 | W8: =ЯНВАРЬ!AH119 -> 0 | X8: =ЯНВАРЬ!AI119 -> 0 | Y8: =ЯНВАРЬ!AK119 -> 0 | Z8: =ЯНВАРЬ!AN119 -> 0 | AB8: =O8-SUM(P8:Y8)+AA8 -> -172.96 | AC8: =O8-SUM(P8:Z8)+AA8 -> -172.96 | AE8: =P8/O8 -> #DIV/0! | AF8: =AC8/P8 -> #DIV/0! | AG8: =AC8/O8 -> #DIV/0! | AH8: =(W8+X8+Y8)/O8 -> #DIV/0!
B9: Февраль 1 очки | C9: 02-08.02 | D9: 6 | F9: =IFERROR(O9-SUM(Q9:W9)+AA9,0) -> 539419.19 | G9: ='Юнит 6'!N105 -> 2829 | H9: ='Юнит 6'!S105 -> 1418 | I9: ='Юнит 6'!T105 -> -25 | J9: ='Юнит 6'!V105 -> 894889.93 | K9: ='Юнит 6'!W105 -> -16453.5 | L9: =IFERROR(J9+K9,0) -> 878436.43 | M9: ='Юнит 6'!Y105 -> 1357375 | N9: ='Юнит 6'!Z105 -> -24887.06 | O9: =IFERROR(M9+N9,0) -> 1332487.9 | P9: ='Юнит 6'!AD105 -> 175437.39 | Q9: ='Юнит 6'!AG105 -> 153486.12 | R9: ='Юнит 6'!AE105 -> 495216.11 | S9: ='Юнит 6'!AL105 -> 8160.06 | U9: ='Юнит 6'!AM105 -> 0 | V9: =5797.44+18990 -> 24787.44 | W9: ='Юнит 6'!AH105 -> 111419 | X9: ='Юнит 6'!AI105 -> 126688 | Y9: ='Юнит 6'!AK105 -> 0 | Z9: =307190.66*O9/SUM(O$9:O$16) -> 48306.676 | AB9: =O9-SUM(P9:Y9)+AA9 -> 237293.8 | AC9: =O9-SUM(P9:Z9)+AA9 -> 188987.12 | AD9: =SUM(AC9:AC16) -> 1874018 | AE9: =P9/O9 -> 0.13166152 | AF9: =AC9/P9 -> 1.077234 | AG9: =AC9/O9 -> 0.14183027 | AH9: =(W9+X9+Y9)/O9 -> 0.17869355
B10: Февраль 1 туники | C10: 02-08.02 | D10: 6 | F10: =IFERROR(O10-SUM(Q10:W10)+AA10,0) -> 0 | G10: ='Юнит 6'!N113 -> 1 | H10: ='Юнит 6'!S113 -> 0 | I10: ='Юнит 6'!T113 -> 0 | J10: ='Юнит 6'!V113 -> 0 | K10: ='Юнит 6'!W113 -> 0 | L10: =IFERROR(J10+K10,0) -> 0 | M10: ='Юнит 6'!Y113 -> 0 | N10: ='Юнит 6'!Z113 -> 0 | O10: =IFERROR(M10+N10,0) -> 0 | P10: ='Юнит 6'!AD113 -> 0 | Q10: ='Юнит 6'!AG113 -> 0 | R10: ='Юнит 6'!AE113 -> 0 | S10: ='Юнит 6'!AL113 -> 0 | U10: ='Юнит 6'!AM113 -> 0 | W10: ='Юнит 6'!AH113 -> 0 | X10: ='Юнит 6'!AI113 -> 0 | Y10: ='Юнит 6'!AK113 -> 0 | Z10: =307190.66*O10/SUM(O$9:O$16) -> 0 | AB10: =O10-SUM(P10:Y10)+AA10 -> 0 | AC10: =O10-SUM(P10:Z10)+AA10 -> 0 | AE10: =P10/O10 -> #DIV/0! | AF10: =AC10/P10 -> #DIV/0! | AG10: =AC10/O10 -> #DIV/0! | AH10: =(W10+X10+Y10)/O10 -> #DIV/0!
B11: Февраль 2 очки | C11: 09-15.02 | D11: 7 | F11: =IFERROR(O11-SUM(Q11:W11)+AA11,0) -> 811496.75 | G11: ='Юнит 7'!N105 -> 3325 | H11: ='Юнит 7'!S105 -> 1882 | I11: ='Юнит 7'!T105 -> -40 | J11: ='Юнит 7'!V105 -> 1236743.8 | K11: ='Юнит 7'!W105 -> -26582.27 | L11: =IFERROR(J11+K11,0) -> 1210161.6 | M11: ='Юнит 7'!Y105 -> 1920260.7 | N11: ='Юнит 7'!Z105 -> -41194.47 | O11: =IFERROR(M11+N11,0) -> 1879066.2 | P11: ='Юнит 7'!AD105 -> 230374.86 | Q11: ='Юнит 7'!AG105 -> 212380.68 | R11: ='Юнит 7'!AE105 -> 695831.51 | S11: ='Юнит 7'!AL105 -> 8132.98 | T11: 30 | U11: ='Юнит 7'!AM105 -> 826 | V11: 4787.28 | W11: ='Юнит 7'!AH105 -> 145581 | X11: ='Юнит 7'!AI105 -> 138670 | Y11: ='Юнит 7'!AK105 -> 0 | Z11: =307190.66*O11/SUM(O$9:O$16) -> 68121.775 | AB11: =O11-SUM(P11:Y11)+AA11 -> 442451.89 | AC11: =O11-SUM(P11:Z11)+AA11 -> 374330.11 | AE11: =P11/O11 -> 0.12260072 | AF11: =AC11/P11 -> 1.624874 | AG11: =AC11/O11 -> 0.19921071 | AH11: =(W11+X11+Y11)/O11 -> 0.15127248
B12: Февраль 2 туники | C12: 09-15.02 | D12: 7 | F12: =IFERROR(O12-SUM(Q12:W12)+AA12,0) -> 1191.57 | G12: ='Юнит 7'!N113 -> 0 | H12: ='Юнит 7'!S113 -> 1 | I12: ='Юнит 7'!T113 -> 0 | J12: ='Юнит 7'!V113 -> 1407 | K12: ='Юнит 7'!W113 -> 0 | L12: =IFERROR(J12+K12,0) -> 1407 | M12: ='Юнит 7'!Y113 -> 2079 | N12: ='Юнит 7'!Z113 -> 0 | O12: =IFERROR(M12+N12,0) -> 2079 | P12: ='Юнит 7'!AD113 -> 579.18 | Q12: ='Юнит 7'!AG113 -> 124.34 | R12: ='Юнит 7'!AE113 -> 763.09 | S12: ='Юнит 7'!AL113 -> 0 | U12: ='Юнит 7'!AM113 -> 0 | W12: ='Юнит 7'!AH113 -> 0 | X12: ='Юнит 7'!AI113 -> 0 | Y12: ='Юнит 7'!AK113 -> 0 | Z12: =307190.66*O12/SUM(O$9:O$16) -> 75.369974 | AB12: =O12-SUM(P12:Y12)+AA12 -> 612.39 | AC12: =O12-SUM(P12:Z12)+AA12 -> 537.02003 | AE12: =P12/O12 -> 0.27858586 | AF12: =AC12/P12 -> 0.92720748 | AG12: =AC12/O12 -> 0.25830689 | AH12: =(W12+X12+Y12)/O12 -> 0
B13: Февраль 3 очки | C13: 16-22.02 | D13: 8 | F13: =IFERROR(O13-SUM(Q13:W13)+AA13,0) -> 1204943.2 | G13: ='Юнит 8'!N$105 -> 4413 | H13: ='Юнит 8'!S$105 -> 2295 | I13: ='Юнит 8'!T$105 -> -43 | J13: ='Юнит 8'!V$105 -> 1593380.1 | K13: ='Юнит 8'!W$105 -> -29254.63 | L13: =IFERROR(J13+K13,0) -> 1564125.5 | M13: ='Юнит 8'!Y$105 -> 2501418.9 | N13: ='Юнит 8'!Z$105 -> -47007.29 | O13: =IFERROR(M13+N13,0) -> 2454411.6 | P13: ='Юнит 8'!AD$105 -> 280478.83 | Q13: ='Юнит 8'!AG$105 -> 267875.33 | R13: ='Юнит 8'!AE$105 -> 918234.84 | S13: ='Юнит 8'!AL$105 -> 8623.9028 | U13: ='Юнит 8'!AM$105 -> 466 | V13: 3279.36 | W13: ='Юнит 8'!AH$105 -> 50989 | X13: ='Юнит 8'!AI$105 -> 265182 | Y13: ='Юнит 8'!AK$105 -> 0 | Z13: =307190.66*O13/SUM(O$9:O$16) -> 88979.768 | AB13: =O13-SUM(P13:Y13)+AA13 -> 659282.34 | AC13: =O13-SUM(P13:Z13)+AA13 -> 570302.57 | AE13: =P13/O13 -> 0.11427538 | AF13: =AC13/P13 -> 2.0333177 | AG13: =AC13/O13 -> 0.23235816 | AH13: =(W13+X13+Y13)/O13 -> 0.12881743
B14: Февраль 3 туники | C14: 16-22.02 | D14: 8 | F14: =IFERROR(O14-SUM(Q14:W14)+AA14,0) -> -0.86724686 | G14: ='Юнит 8'!N113 -> 0 | H14: ='Юнит 8'!S113 -> 0 | I14: ='Юнит 8'!T113 -> 0 | J14: ='Юнит 8'!V113 -> 0 | K14: ='Юнит 8'!W113 -> 0 | L14: =IFERROR(J14+K14,0) -> 0 | M14: ='Юнит 8'!Y113 -> 0 | N14: ='Юнит 8'!Z113 -> 0 | O14: =IFERROR(M14+N14,0) -> 0 | P14: ='Юнит 8'!AD113 -> 0 | Q14: ='Юнит 8'!AG113 -> 0 | R14: ='Юнит 8'!AE113 -> 0 | S14: ='Юнит 8'!AL113 -> 0.86724686 | U14: ='Юнит 8'!AM113 -> 0 | W14: ='Юнит 8'!AH113 -> 0 | X14: ='Юнит 8'!AI113 -> 0 | Y14: ='Юнит 8'!AK113 -> 0 | Z14: =307190.66*O14/SUM(O$9:O$16) -> 0 | AB14: =O14-SUM(P14:Y14)+AA14 -> -0.86724686 | AC14: =O14-SUM(P14:Z14)+AA14 -> -0.86724686 | AE14: =P14/O14 -> #DIV/0! | AF14: =AC14/P14 -> #DIV/0! | AG14: =AC14/O14 -> #DIV/0! | AH14: =(W14+X14+Y14)/O14 -> #DIV/0!
B15: Февраль 4 очки | C15: 23.02-01.03 | D15: 9 | F15: =IFERROR(O15-SUM(Q15:W15)+AA15,0) -> 1208387.9 | G15: ='Юнит 9'!N$105 -> 3950 | H15: ='Юнит 9'!S$105 -> 2372 | I15: ='Юнит 9'!T$105 -> -63 | J15: ='Юнит 9'!V$105 -> 1818463.8 | K15: ='Юнит 9'!W$105 -> -46702.77 | L15: =IFERROR(J15+K15,0) -> 1771761 | M15: ='Юнит 9'!Y$105 -> 2879025.2 | N15: ='Юнит 9'!Z$105 -> -73544.64 | O15: =IFERROR(M15+N15,0) -> 2805480.6 | P15: ='Юнит 9'!AD$105 -> 288027.84 | Q15: ='Юнит 9'!AG$105 -> 299415.53 | R15: ='Юнит 9'!AE$105 -> 1051752.7 | S15: ='Юнит 9'!AL$105 -> 8471.4 | U15: ='Юнит 9'!AM$105 -> 1392.11 | V15: 2400.96 | W15: ='Юнит 9'!AH$105 -> 233660 | X15: ='Юнит 9'!AI$105 -> 78621 | Y15: ='Юнит 9'!AK$105 -> 0 | Z15: =307190.66*O15/SUM(O$9:O$16) -> 101707.07 | AB15: =O15-SUM(P15:Y15)+AA15 -> 841739.09 | AC15: =O15-SUM(P15:Z15)+AA15 -> 740032.02 | AE15: =P15/O15 -> 0.10266613 | AF15: =AC15/P15 -> 2.5693073 | AG15: =AC15/O15 -> 0.26378084 | AH15: =(W15+X15+Y15)/O15 -> 0.11131105
B16: Февраль 4 прочее | C16: 23.02-01.03 | D16: 9 | F16: =IFERROR(O16-SUM(Q16:W16)+AA16,0) -> -170 | Q16: ='Юнит 9'!AG125 -> 170 | Z16: =307190.66*O16/SUM(O$9:O$16) -> 0 | AB16: =O16-SUM(P16:Y16)+AA16 -> -170 | AC16: =O16-SUM(P16:Z16)+AA16 -> -170 | AE16: =P16/O16 -> #DIV/0! | AF16: =AC16/P16 -> #DIV/0! | AG16: =AC16/O16 -> #DIV/0! | AH16: =(W16+X16+Y16)/O16 -> #DIV/0!
B17: Март 1 очки | C17: 02-08.02 | D17: 10 | F17: =IFERROR(O17-SUM(Q17:W17)+AA17,0) -> 1238601.7 | G17: ='Юнит 10'!N$105 -> 3795 | H17: ='Юнит 10'!S$105 -> 2096 | I17: ='Юнит 10'!T$105 -> -53 | J17: ='Юнит 10'!V$105 -> 1702514.8 | K17: ='Юнит 10'!W$105 -> -41251 | L17: =IFERROR(J17+K17,0) -> 1661263.8 | M17: ='Юнит 10'!Y$105 -> 2657773.4 | N17: ='Юнит 10'!Z$105 -> -65375.4 | O17: =IFERROR(M17+N17,0) -> 2592398 | P17: ='Юнит 10'!AD$105 -> 254974.68 | Q17: ='Юнит 10'!AG$105 -> 270558.84 | R17: ='Юнит 10'!AE$105 -> 972977.25 | S17: ='Юнит 10'!AL$105 -> 11702.83 | U17: ='Юнит 10'!AM$105 -> 0 | V17: =1083.36+22990 -> 24073.36 | W17: ='Юнит 10'!AH$105 -> 74484 | X17: ='Юнит 10'!AI$105 -> 252853 | Y17: ='Юнит 10'!AK$105 -> 0 | Z17: ='Юнит 10'!AN$105 -> 94858.164 | AB17: =O17-SUM(P17:Y17)+AA17 -> 730774.06 | AC17: =O17-SUM(P17:Z17)+AA17 -> 635915.9 | AD17: =SUM(AC17:AC20) -> 1965834.1 | AE17: =P17/O17 -> 0.098354758 | AF17: =AC17/P17 -> 2.4940355 | AG17: =AC17/O17 -> 0.24530026 | AH17: =(W17+X17+Y17)/O17 -> 0.12626803
B18: Март 2 очки | C18: 09-15.02 | D18: 11 | F18: =IFERROR(O18-SUM(Q18:W18)+AA18,0) -> 2101556.8 | G18: ='Юнит 11'!N$105 -> 8243 | H18: ='Юнит 11'!S$105 -> 3480 | I18: ='Юнит 11'!T$105 -> -60 | J18: ='Юнит 11'!V$105 -> 3014405.3 | K18: ='Юнит 11'!W$105 -> -49269.89 | L18: =IFERROR(J18+K18,0) -> 2965135.4 | M18: ='Юнит 11'!Y$105 -> 4668001.6 | N18: ='Юнит 11'!Z$105 -> -76772.74 | O18: =IFERROR(M18+N18,0) -> 4591228.8 | P18: ='Юнит 11'!AD$105 -> 424325.4 | Q18: ='Юнит 11'!AG$105 -> 445765.14 | R18: ='Юнит 11'!AE$105 -> 1726243.8 | S18: ='Юнит 11'!AL$105 -> 9729.77 | U18: ='Юнит 11'!AM$105 -> 1842 | V18: 1288.32 | W18: ='Юнит 11'!AH$105 -> 304803 | X18: ='Юнит 11'!AI$105 -> 178004 | Y18: ='Юнит 11'!AK$105 -> 0 | Z18: ='Юнит 11'!AN$105 -> 169309.23 | AB18: =O18-SUM(P18:Y18)+AA18 -> 1499227.4 | AC18: =O18-SUM(P18:Z18)+AA18 -> 1329918.2 | AE18: =P18/O18 -> 0.092420878 | AF18: =AC18/P18 -> 3.1341942 | AG18: =AC18/O18 -> 0.28966498 | AH18: =(W18+X18+Y18)/O18 -> 0.10515856
B19: Март 3 очки | C19: 16-22.02 | D19: 12 | AE19: =P19/O19 -> #DIV/0! | AF19: =AC19/P19 -> #DIV/0! | AG19: =AC19/O19 -> #DIV/0! | AH19: =(W19+X19+Y19)/O19 -> #DIV/0!
B20: Март 4 очки | C20: 23-29.02 | D20: 13 | AE20: =P20/O20 -> #DIV/0! | AF20: =AC20/P20 -> #DIV/0! | AG20: =AC20/O20 -> #DIV/0! | AH20: =(W20+X20+Y20)/O20 -> #DIV/0!
B25: Итого | F25: =SUM(F4:F20) -> 8123098.8 | G25: =SUM(G4:G20) -> 31647 | H25: =SUM(H4:H20) -> 16033 | I25: =SUM(I4:I20) -> -342 | J25: =SUM(J4:J20) -> 12108235 | K25: =SUM(K4:K20) -> -260580.94 | L25: =SUM(L4:L20) -> 11847654 | M25: =SUM(M4:M20) -> 18428240 | ... AD25: =SUM(AD4:AD20) -> 4042176.7 | AE25: =P25/O25 -> 0.108814 | AF25: =AC25/P25 -> 2.0599018 | AG25: =AC25/O25 -> 0.22414615 | AH25: =(W25+X25+Y25)/O25 -> 0.13745885
M26: % от выручки за весь период
N27: =-N25/M25 -> 0.021411412 | P27: =P25/$O$25 -> 0.108814 | Q27: =Q25/$O$25 -> 0.10779777 | R27: =R25/$O$25 -> 0.37390155 | S27: =S25/$O$25 -> 0.0054772214 | T27: =T25/$O$25 -> 1.7578234e-06 | U27: =U25/$O$25 -> 0.00025098114 | V27: =V25/$O$25 -> 0.0047715379 | W27: =W25/$O$25 -> 0.057358388 | ... Z27: =Z25/$O$25 -> 0.037380189 | AD27: =AC25/P25 -> 2.0599018 | AE27: Маржинальность, %
W28: =(W25+X25)/O25 -> 0.13745885 | AD28: =AC25/O25 -> 0.22414615 | AE28: Рентабельность, %
B30: ЯНВАРЬ очки | G30: =G6 -> 4961 | H30: =H6 -> 2362 | I30: =I6 -> -53 | J30: =J6 -> 1728382.8 | K30: =K6 -> -44657.88 | L30: =L6 -> 1683724.9 | M30: =M6 -> 2303342.1 | N30: =N6 -> -58267.04 | ... AC30: =AC6 -> 161729.24
N31: =-N30/M30 -> 0.025296738 | P31: =P30/$O$30 -> 0.13045294 | Q31: =Q30/$O$30 -> 0.12314762 | R31: =R30/$O$30 -> 0.3713327 | S31: =S30/$O$30 -> 0.017965164 | T31: =T30/$O$30 -> 0 | U31: =U30/$O$30 -> 0 | V31: =V30/$O$30 -> 0.011327728 | W31: =W30/$O$30 -> 0.050531051 | ... AA31: =AA30/$O$30 -> 0 | AC31: =AC30/O30 -> 0.072037343
B33: 7 нед очки | P33: =P11/$O$11 -> 0.12260072 | Q33: =Q11/$O$11 -> 0.11302459 | R33: =R11/$O$11 -> 0.37030708 | S33: =S11/$O$11 -> 0.004328203 | T33: =T11/$O$11 -> 1.5965377e-05 | U33: =U11/$O$11 -> 0.00043958004 | V33: =V11/$O$11 -> 0.002547691 | W33: =W11/$O$11 -> 0.077475184 | ... AA33: =AA11/$O$11 -> 0 | AD33: =AC11/P11 -> 1.624874 | AE33: Маржинальность, %
AD34: =AC11/O11 -> 0.19921071 | AE34: Рентабельность, %
B36: ФЕВРАЛЬ очки | G36: =G9+G11+G13+G15 -> 14517 | H36: =H9+H11+H13+H15 -> 7967 | I36: =I9+I11+I13+I15 -> -171 | J36: =J9+J11+J13+J15 -> 5543477.6 | K36: =K9+K11+K13+K15 -> -118993.17 | L36: =L9+L11+L13+L15 -> 5424484.4 | M36: =M9+M11+M13+M15 -> 8658079.8 | N36: =N9+N11+N13+N15 -> -186633.46 | ... AC36: =AC9+AC11+AC13+AC15 -> 1873651.8
N37: =-N36/M36 -> 0.021555988 | P37: =P36/$O$36 -> 0.11501211 | Q37: =Q36/$O$36 -> 0.11015329 | R37: =R36/$O$36 -> 0.37313996 | S37: =S36/$O$36 -> 0.0039412801 | T37: =T36/$O$36 -> 3.5413079e-06 | U37: =U36/$O$36 -> 0.000316842 | V37: =V36/$O$36 -> 0.0041616317 | W37: =W36/$O$36 -> 0.063938196 | ... AA37: =AA36/$O$36 -> 0 | AC37: =AC36/O36 -> 0.2211726
B39: 9 нед очки | P39: =P15/$O$15 -> 0.10266613 | Q39: =Q15/$O$15 -> 0.10672522 | R39: =R15/$O$15 -> 0.37489216 | S39: =S15/$O$15 -> 0.0030195896 | T39: =T15/$O$15 -> 0 | U39: =U15/$O$15 -> 0.00049621088 | V39: =V15/$O$15 -> 0.00085581058 | W39: =W15/$O$15 -> 0.083286977 | ... AA39: =AA15/$O$15 -> 0 | AD39: =AC15/P15 -> 2.5693073 | AE39: Маржинальность, %
AD40: =AC15/O15 -> 0.26378084 | AE40: Рентабельность, %
B42: МАРТ очки | G42: =SUM(G17:G20) -> 12038 | H42: =SUM(H17:H20) -> 5576 | I42: =SUM(I17:I20) -> -113 | J42: =SUM(J17:J20) -> 4716920.1 | K42: =SUM(K17:K20) -> -90520.89 | L42: =SUM(L17:L20) -> 4626399.2 | M42: =SUM(M17:M20) -> 7325775 | N42: =SUM(N17:N20) -> -142148.14 | ... AC42: =SUM(AC17:AC20) -> 1965834.1

Sheet АВС 12
B2: ОЧКИ
C3: Прибыль | D3: % прибыль | E3: Доля | F3: ABC прибыль | G3: ABC кол-во | J3: Кол-во | K3: % кол-во | L3: Доля | M3: ABC кол-во
B4: черные с железкой классика | D4: =C4/C$105 -> #DIV/0! | E4: =D4 -> #DIV/0! | F4: =IF(AND(E4<=0),"C",IF(E4<=0.8,"A",IF(E4<=0.95,"B","C"))) -> #DIV/0! | G4: =VLOOKUP(B$4:B$104,I$4:M$104,5,0) -> #DIV/0! | I4: черные с железкой классика | K4: =J4/J$105 -> #DIV/0! | L4: =K4 -> #DIV/0! | M4: =_xlfn.IFS(L4<80%,"A",L4<=95%,"B",L4>95%,"C") -> #DIV/0! | P4: A | Q4: 0.8
B5: QS черные PZ | D5: =C5/C$105 -> #DIV/0! | E5: =E4+D5 -> #DIV/0! | F5: =IF(AND(E5<=0),"C",IF(E5<=0.8,"A",IF(E5<=0.95,"B","C"))) -> #DIV/0! | G5: =VLOOKUP(B$4:B$104,I$4:M$104,5,0) -> #DIV/0! | I5: QS черные PZ | K5: =J5/J$105 -> #DIV/0! | L5: =L4+K5 -> #DIV/0! | M5: =_xlfn.IFS(L5<80%,"A",L5<=95%,"B",L5>95%,"C") -> #DIV/0! | P5: B | Q5: 0.15
B6: QS синие PZ | D6: =C6/C$105 -> #DIV/0! | E6: =E5+D6 -> #DIV/0! | F6: =IF(AND(E6<=0),"C",IF(E6<=0.8,"A",IF(E6<=0.95,"B","C"))) -> #DIV/0! | G6: =VLOOKUP(B$4:B$104,I$4:M$104,5,0) -> #DIV/0! | I6: QS синие PZ | K6: =J6/J$105 -> #DIV/0! | L6: =L5+K6 -> #DIV/0! | M6: =_xlfn.IFS(L6<80%,"A",L6<=95%,"B",L6>95%,"C") -> #DIV/0! | P6: C | Q6: 0.05
B7: QS желтые PZ | D7: =C7/C$105 -> #DIV/0! | E7: =E6+D7 -> #DIV/0! | F7: =IF(AND(E7<=0),"C",IF(E7<=0.8,"A",IF(E7<=0.95,"B","C"))) -> #DIV/0! | G7: =VLOOKUP(B$4:B$104,I$4:M$104,5,0) -> #DIV/0! | I7: QS желтые PZ | K7: =J7/J$105 -> #DIV/0! | L7: =L6+K7 -> #DIV/0! | M7: =_xlfn.IFS(L7<80%,"A",L7<=95%,"B",L7>95%,"C") -> #DIV/0!
B8: QS коричневые PZ | D8: =C8/C$105 -> #DIV/0! | E8: =E7+D8 -> #DIV/0! | F8: =IF(AND(E8<=0),"C",IF(E8<=0.8,"A",IF(E8<=0.95,"B","C"))) -> #DIV/0! | G8: =VLOOKUP(B$4:B$104,I$4:M$104,5,0) -> #DIV/0! | I8: QS коричневые PZ | K8: =J8/J$105 -> #DIV/0! | L8: =L7+K8 -> #DIV/0! | M8: =_xlfn.IFS(L8<80%,"A",L8<=95%,"B",L8>95%,"C") -> #DIV/0!
B9: MR8854 C2 Жен | D9: =C9/C$105 -> #DIV/0! | E9: =E8+D9 -> #DIV/0! | F9: =IF(AND(E9<=0),"C",IF(E9<=0.8,"A",IF(E9<=0.95,"B","C"))) -> #DIV/0! | G9: =VLOOKUP(B$4:B$104,I$4:M$104,5,0) -> #DIV/0! | I9: MR8854 C2 Жен | K9: =J9/J$105 -> #DIV/0! | L9: =L8+K9 -> #DIV/0! | M9: =_xlfn.IFS(L9<80%,"A",L9<=95%,"B",L9>95%,"C") -> #DIV/0!
B10: th черн | D10: =C10/C$105 -> #DIV/0! | E10: =E9+D10 -> #DIV/0! | F10: =IF(AND(E10<=0),"C",IF(E10<=0.8,"A",IF(E10<=0.95,"B","C"))) -> #DIV/0! | G10: =VLOOKUP(B$4:B$104,I$4:M$104,5,0) -> #DIV/0! | I10: th черн | K10: =J10/J$105 -> #DIV/0! | L10: =L9+K10 -> #DIV/0! | M10: =_xlfn.IFS(L10<80%,"A",L10<=95%,"B",L10>95%,"C") -> #DIV/0!
B11: th син | D11: =C11/C$105 -> #DIV/0! | E11: =E10+D11 -> #DIV/0! | F11: =IF(AND(E11<=0),"C",IF(E11<=0.8,"A",IF(E11<=0.95,"B","C"))) -> #DIV/0! | G11: =VLOOKUP(B$4:B$104,I$4:M$104,5,0) -> #DIV/0! | I11: th син | K11: =J11/J$105 -> #DIV/0! | L11: =L10+K11 -> #DIV/0! | M11: =_xlfn.IFS(L11<80%,"A",L11<=95%,"B",L11>95%,"C") -> #DIV/0!
B12: th желт | D12: =C12/C$105 -> #DIV/0! | E12: =E11+D12 -> #DIV/0! | F12: =IF(AND(E12<=0),"C",IF(E12<=0.8,"A",IF(E12<=0.95,"B","C"))) -> #DIV/0! | G12: =VLOOKUP(B$4:B$104,I$4:M$104,5,0) -> #DIV/0! | I12: th желт | K12: =J12/J$105 -> #DIV/0! | L12: =L11+K12 -> #DIV/0! | M12: =_xlfn.IFS(L12<80%,"A",L12<=95%,"B",L12>95%,"C") -> #DIV/0!
B13: th коричн | D13: =C13/C$105 -> #DIV/0! | E13: =E12+D13 -> #DIV/0! | F13: =IF(AND(E13<=0),"C",IF(E13<=0.8,"A",IF(E13<=0.95,"B","C"))) -> #DIV/0! | G13: =VLOOKUP(B$4:B$104,I$4:M$104,5,0) -> #DIV/0! | I13: th коричн | K13: =J13/J$105 -> #DIV/0! | L13: =L12+K13 -> #DIV/0! | M13: =_xlfn.IFS(L13<80%,"A",L13<=95%,"B",L13>95%,"C") -> #DIV/0!
B14: flip черные | D14: =C14/C$105 -> #DIV/0! | E14: =E13+D14 -> #DIV/0! | F14: =IF(AND(E14<=0),"C",IF(E14<=0.8,"A",IF(E14<=0.95,"B","C"))) -> #DIV/0! | G14: =VLOOKUP(B$4:B$104,I$4:M$104,5,0) -> #DIV/0! | I14: flip черные | K14: =J14/J$105 -> #DIV/0! | L14: =L13+K14 -> #DIV/0! | M14: =_xlfn.IFS(L14<80%,"A",L14<=95%,"B",L14>95%,"C") -> #DIV/0!
B15: flip синие | D15: =C15/C$105 -> #DIV/0! | E15: =E14+D15 -> #DIV/0! | F15: =IF(AND(E15<=0),"C",IF(E15<=0.8,"A",IF(E15<=0.95,"B","C"))) -> #DIV/0! | G15: =VLOOKUP(B$4:B$104,I$4:M$104,5,0) -> #DIV/0! | I15: flip синие | K15: =J15/J$105 -> #DIV/0! | L15: =L14+K15 -> #DIV/0! | M15: =_xlfn.IFS(L15<80%,"A",L15<=95%,"B",L15>95%,"C") -> #DIV/0!
B16: flip желтые | D16: =C16/C$105 -> #DIV/0! | E16: =E15+D16 -> #DIV/0! | F16: =IF(AND(E16<=0),"C",IF(E16<=0.8,"A",IF(E16<=0.95,"B","C"))) -> #DIV/0! | G16: =VLOOKUP(B$4:B$104,I$4:M$104,5,0) -> #DIV/0! | I16: flip желтые | K16: =J16/J$105 -> #DIV/0! | L16: =L15+K16 -> #DIV/0! | M16: =_xlfn.IFS(L16<80%,"A",L16<=95%,"B",L16>95%,"C") -> #DIV/0!
B17: flip коричневые | D17: =C17/C$105 -> #DIV/0! | E17: =E16+D17 -> #DIV/0! | F17: =IF(AND(E17<=0),"C",IF(E17<=0.8,"A",IF(E17<=0.95,"B","C"))) -> #DIV/0! | G17: =VLOOKUP(B$4:B$104,I$4:M$104,5,0) -> #DIV/0! | I17: flip коричневые | K17: =J17/J$105 -> #DIV/0! | L17: =L16+K17 -> #DIV/0! | M17: =_xlfn.IFS(L17<80%,"A",L17<=95%,"B",L17>95%,"C") -> #DIV/0!
B18: wwl8032 коричневые золото | D18: =C18/C$105 -> #DIV/0! | E18: =E17+D18 -> #DIV/0! | F18: =IF(AND(E18<=0),"C",IF(E18<=0.8,"A",IF(E18<=0.95,"B","C"))) -> #DIV/0! | G18: =VLOOKUP(B$4:B$104,I$4:M$104,5,0) -> #DIV/0! | I18: wwl8032 коричневые золото | K18: =J18/J$105 -> #DIV/0! | L18: =L17+K18 -> #DIV/0! | M18: =_xlfn.IFS(L18<80%,"A",L18<=95%,"B",L18>95%,"C") -> #DIV/0!
... B38: sh13 | D38: =C38/C$105 -> #DIV/0! | E38: =E37+D38 -> #DIV/0! | F38: =IF(AND(E38<=0),"C",IF(E38<=0.8,"A",IF(E38<=0.95,"B","C"))) -> #DIV/0! | G38: =VLOOKUP(B$4:B$104,I$4:M$104,5,0) -> #DIV/0! | I38: sh13 | K38: =J38/J$105 -> #DIV/0! | L38: =L37+K38 -> #DIV/0! | M38: =_xlfn.IFS(L38<80%,"A",L38<=95%,"B",L38>95%,"C") -> #DIV/0!
B39: sh14 | D39: =C39/C$105 -> #DIV/0! | E39: =E35+D39 -> #DIV/0! | F39: =IF(AND(E39<=0),"C",IF(E39<=0.8,"A",IF(E39<=0.95,"B","C"))) -> #DIV/0! | G39: =VLOOKUP(B$4:B$104,I$4:M$104,5,0) -> #DIV/0! | I39: sh14 | K39: =J39/J$105 -> #DIV/0! | L39: =L35+K39 -> #DIV/0! | M39: =_xlfn.IFS(L39<80%,"A",L39<=95%,"B",L39>95%,"C") -> #DIV/0!
B40: sh15 | D40: =C40/C$105 -> #DIV/0! | E40: =E39+D40 -> #DIV/0! | F40: =IF(AND(E40<=0),"C",IF(E40<=0.8,"A",IF(E40<=0.95,"B","C"))) -> #DIV/0! | G40: =VLOOKUP(B$4:B$104,I$4:M$104,5,0) -> #DIV/0! | I40: sh15 | K40: =J40/J$105 -> #DIV/0! | L40: =L39+K40 -> #DIV/0! | M40: =_xlfn.IFS(L40<80%,"A",L40<=95%,"B",L40>95%,"C") -> #DIV/0!
B41: sh16 | D41: =C41/C$105 -> #DIV/0! | E41: =E40+D41 -> #DIV/0! | F41: =IF(AND(E41<=0),"C",IF(E41<=0.8,"A",IF(E41<=0.95,"B","C"))) -> #DIV/0! | G41: =VLOOKUP(B$4:B$104,I$4:M$104,5,0) -> #DIV/0! | I41: sh16 | K41: =J41/J$105 -> #DIV/0! | L41: =L40+K41 -> #DIV/0! | M41: =_xlfn.IFS(L41<80%,"A",L41<=95%,"B",L41>95%,"C") -> #DIV/0!
B42: sh17 | D42: =C42/C$105 -> #DIV/0! | E42: =E41+D42 -> #DIV/0! | F42: =IF(AND(E42<=0),"C",IF(E42<=0.8,"A",IF(E42<=0.95,"B","C"))) -> #DIV/0! | G42: =VLOOKUP(B$4:B$104,I$4:M$104,5,0) -> #DIV/0! | I42: sh17 | K42: =J42/J$105 -> #DIV/0! | L42: =L41+K42 -> #DIV/0! | M42: =_xlfn.IFS(L42<80%,"A",L42<=95%,"B",L42>95%,"C") -> #DIV/0!
B43: sh18 | D43: =C43/C$105 -> #DIV/0! | E43: =E42+D43 -> #DIV/0! | F43: =IF(AND(E43<=0),"C",IF(E43<=0.8,"A",IF(E43<=0.95,"B","C"))) -> #DIV/0! | G43: =VLOOKUP(B$4:B$104,I$4:M$104,5,0) -> #DIV/0! | I43: sh18 | K43: =J43/J$105 -> #DIV/0! | L43: =L42+K43 -> #DIV/0! | M43: =_xlfn.IFS(L43<80%,"A",L43<=95%,"B",L43>95%,"C") -> #DIV/0!
B44: sh19 | D44: =C44/C$105 -> #DIV/0! | E44: =E43+D44 -> #DIV/0! | F44: =IF(AND(E44<=0),"C",IF(E44<=0.8,"A",IF(E44<=0.95,"B","C"))) -> #DIV/0! | G44: =VLOOKUP(B$4:B$104,I$4:M$104,5,0) -> #DIV/0! | I44: sh19 | K44: =J44/J$105 -> #DIV/0! | L44: =L43+K44 -> #DIV/0! | M44: =_xlfn.IFS(L44<80%,"A",L44<=95%,"B",L44>95%,"C") -> #DIV/0!
B45: ww 203 черные | D45: =C45/C$105 -> #DIV/0! | E45: =E44+D45 -> #DIV/0! | F45: =IF(AND(E45<=0),"C",IF(E45<=0.8,"A",IF(E45<=0.95,"B","C"))) -> #DIV/0! | G45: =VLOOKUP(B$4:B$104,I$4:M$104,5,0) -> #DIV/0! | I45: ww 203 черные | K45: =J45/J$105 -> #DIV/0! | L45: =L44+K45 -> #DIV/0! | M45: =_xlfn.IFS(L45<80%,"A",L45<=95%,"B",L45>95%,"C") -> #DIV/0!
B46: ww 1022 черные | D46: =C46/C$105 -> #DIV/0! | E46: =E45+D46 -> #DIV/0! | F46: =IF(AND(E46<=0),"C",IF(E46<=0.8,"A",IF(E46<=0.95,"B","C"))) -> #DIV/0! | G46: =VLOOKUP(B$4:B$104,I$4:M$104,5,0) -> #DIV/0! | I46: ww 1022 черные | K46: =J46/J$105 -> #DIV/0! | L46: =L45+K46 -> #DIV/0! | M46: =_xlfn.IFS(L46<80%,"A",L46<=95%,"B",L46>95%,"C") -> #DIV/0!
B47: ww 1022 черн-серебро | D47: =C47/C$105 -> #DIV/0! | E47: =E46+D47 -> #DIV/0! | F47: =IF(AND(E47<=0),"C",IF(E47<=0.8,"A",IF(E47<=0.95,"B","C"))) -> #DIV/0! | G47: =VLOOKUP(B$4:B$104,I$4:M$104,5,0) -> #DIV/0! | I47: ww 1022 черн-серебро | K47: =J47/J$105 -> #DIV/0! | L47: =L46+K47 -> #DIV/0! | M47: =_xlfn.IFS(L47<80%,"A",L47<=95%,"B",L47>95%,"C") -> #DIV/0!
B48: ww 1022 желтые | D48: =C48/C$105 -> #DIV/0! | E48: =E47+D48 -> #DIV/0! | F48: =IF(AND(E48<=0),"C",IF(E48<=0.8,"A",IF(E48<=0.95,"B","C"))) -> #DIV/0! | G48: =VLOOKUP(B$4:B$104,I$4:M$104,5,0) -> #DIV/0! | I48: ww 1022 желтые | K48: =J48/J$105 -> #DIV/0! | L48: =L47+K48 -> #DIV/0! | M48: =_xlfn.IFS(L48<80%,"A",L48<=95%,"B",L48>95%,"C") -> #DIV/0!
B49: ww 1022 коричневые | D49: =C49/C$105 -> #DIV/0! | E49: =E48+D49 -> #DIV/0! | F49: =IF(AND(E49<=0),"C",IF(E49<=0.8,"A",IF(E49<=0.95,"B","C"))) -> #DIV/0! | G49: =VLOOKUP(B$4:B$104,I$4:M$104,5,0) -> #DIV/0! | I49: ww 1022 коричневые | K49: =J49/J$105 -> #DIV/0! | L49: =L48+K49 -> #DIV/0! | M49: =_xlfn.IFS(L49<80%,"A",L49<=95%,"B",L49>95%,"C") -> #DIV/0!
B50: ww 2018 черные | D50: =C50/C$105 -> #DIV/0! | E50: =E49+D50 -> #DIV/0! | F50: =IF(AND(E50<=0),"C",IF(E50<=0.8,"A",IF(E50<=0.95,"B","C"))) -> #DIV/0! | G50: =VLOOKUP(B$4:B$104,I$4:M$104,5,0) -> #DIV/0! | I50: ww 2018 черные | K50: =J50/J$105 -> #DIV/0! | L50: =L49+K50 -> #DIV/0! | M50: =_xlfn.IFS(L50<80%,"A",L50<=95%,"B",L50>95%,"C") -> #DIV/0!
B51: ww 2018 желтые | D51: =C51/C$105 -> #DIV/0! | E51: =E50+D51 -> #DIV/0! | F51: =IF(AND(E51<=0),"C",IF(E51<=0.8,"A",IF(E51<=0.95,"B","C"))) -> #DIV/0! | G51: =VLOOKUP(B$4:B$104,I$4:M$104,5,0) -> #DIV/0! | I51: ww 2018 желтые | K51: =J51/J$105 -> #DIV/0! | L51: =L50+K51 -> #DIV/0! | M51: =_xlfn.IFS(L51<80%,"A",L51<=95%,"B",L51>95%,"C") -> #DIV/0!
... B75: MANNA2121 | D75: =C75/C$105 -> #DIV/0! | E75: =E74+D75 -> #DIV/0! | F75: =IF(AND(E75<=0),"C",IF(E75<=0.8,"A",IF(E75<=0.95,"B","C"))) -> #DIV/0! | G75: =VLOOKUP(B$4:B$104,I$4:M$104,5,0) -> #DIV/0! | I75: MANNA2121 | K75: =J75/J$105 -> #DIV/0! | L75: =L74+K75 -> #DIV/0! | M75: =_xlfn.IFS(L75<80%,"A",L75<=95%,"B",L75>95%,"C") -> #DIV/0!
B76: MANNA2122 | D76: =C76/C$105 -> #DIV/0! | E76: =E49+D76 -> #DIV/0! | F76: =IF(AND(E76<=0),"C",IF(E76<=0.8,"A",IF(E76<=0.95,"B","C"))) -> #DIV/0! | G76: =VLOOKUP(B$4:B$104,I$4:M$104,5,0) -> #DIV/0! | I76: MANNA2122 | K76: =J76/J$105 -> #DIV/0! | L76: =L49+K76 -> #DIV/0! | M76: =_xlfn.IFS(L76<80%,"A",L76<=95%,"B",L76>95%,"C") -> #DIV/0!
B77: Chenlong черные | D77: =C77/C$105 -> #DIV/0! | E77: =E76+D77 -> #DIV/0! | F77: =IF(AND(E77<=0),"C",IF(E77<=0.8,"A",IF(E77<=0.95,"B","C"))) -> #DIV/0! | G77: =VLOOKUP(B$4:B$104,I$4:M$104,5,0) -> #DIV/0! | I77: Chenlong черные | K77: =J77/J$105 -> #DIV/0! | L77: =L76+K77 -> #DIV/0! | M77: =_xlfn.IFS(L77<80%,"A",L77<=95%,"B",L77>95%,"C") -> #DIV/0!
B78: Chenlong коричневые | D78: =C78/C$105 -> #DIV/0! | E78: =E77+D78 -> #DIV/0! | F78: =IF(AND(E78<=0),"C",IF(E78<=0.8,"A",IF(E78<=0.95,"B","C"))) -> #DIV/0! | G78: =VLOOKUP(B$4:B$104,I$4:M$104,5,0) -> #DIV/0! | I78: Chenlong коричневые | K78: =J78/J$105 -> #DIV/0! | L78: =L77+K78 -> #DIV/0! | M78: =_xlfn.IFS(L78<80%,"A",L78<=95%,"B",L78>95%,"C") -> #DIV/0!
B79: Chenlong белые | D79: =C79/C$105 -> #DIV/0! | E79: =E78+D79 -> #DIV/0! | F79: =IF(AND(E79<=0),"C",IF(E79<=0.8,"A",IF(E79<=0.95,"B","C"))) -> #DIV/0! | G79: =VLOOKUP(B$4:B$104,I$4:M$104,5,0) -> #DIV/0! | I79: Chenlong белые | K79: =J79/J$105 -> #DIV/0! | L79: =L78+K79 -> #DIV/0! | M79: =_xlfn.IFS(L79<80%,"A",L79<=95%,"B",L79>95%,"C") -> #DIV/0!
B80: Guangdu золото серая линза | D80: =C80/C$105 -> #DIV/0! | E80: =E79+D80 -> #DIV/0! | F80: =IF(AND(E80<=0),"C",IF(E80<=0.8,"A",IF(E80<=0.95,"B","C"))) -> #DIV/0! | G80: =VLOOKUP(B$4:B$104,I$4:M$104,5,0) -> #DIV/0! | I80: Guangdu золото серая линза | K80: =J80/J$105 -> #DIV/0! | L80: =L79+K80 -> #DIV/0! | M80: =_xlfn.IFS(L80<80%,"A",L80<=95%,"B",L80>95%,"C") -> #DIV/0!
B81: Guangdu серебро серая линза | D81: =C81/C$105 -> #DIV/0! | E81: =E80+D81 -> #DIV/0! | F81: =IF(AND(E81<=0),"C",IF(E81<=0.8,"A",IF(E81<=0.95,"B","C"))) -> #DIV/0! | G81: =VLOOKUP(B$4:B$104,I$4:M$104,5,0) -> #DIV/0! | I81: Guangdu серебро серая линза | K81: =J81/J$105 -> #DIV/0! | L81: =L80+K81 -> #DIV/0! | M81: =_xlfn.IFS(L81<80%,"A",L81<=95%,"B",L81>95%,"C") -> #DIV/0!
B82: Hengda Optical черные | D82: =C82/C$105 -> #DIV/0! | E82: =E81+D82 -> #DIV/0! | F82: =IF(AND(E82<=0),"C",IF(E82<=0.8,"A",IF(E82<=0.95,"B","C"))) -> #DIV/0! | G82: =VLOOKUP(B$4:B$104,I$4:M$104,5,0) -> #DIV/0! | I82: Hengda Optical черные | K82: =J82/J$105 -> #DIV/0! | L82: =L81+K82 -> #DIV/0! | M82: =_xlfn.IFS(L82<80%,"A",L82<=95%,"B",L82>95%,"C") -> #DIV/0!
B83: Hengda Optical леопард | D83: =C83/C$105 -> #DIV/0! | E83: =E82+D83 -> #DIV/0! | F83: =IF(AND(E83<=0),"C",IF(E83<=0.8,"A",IF(E83<=0.95,"B","C"))) -> #DIV/0! | G83: =VLOOKUP(B$4:B$104,I$4:M$104,5,0) -> #DIV/0! | I83: Hengda Optical леопард | K83: =J83/J$105 -> #DIV/0! | L83: =L82+K83 -> #DIV/0! | M83: =_xlfn.IFS(L83<80%,"A",L83<=95%,"B",L83>95%,"C") -> #DIV/0!
...

Sheet АВС 11
B2: ОЧКИ
C3: Прибыль | D3: % прибыль | E3: Доля | F3: ABC прибыль | G3: ABC кол-во | J3: Кол-во | K3: % кол-во | L3: Доля | M3: ABC кол-во
B4: QS черные PZ | C4: ='Юнит 11'!AO4 -> 372695.38 | D4: =C4/C$105 -> 0.27996811 | E4: =D4 -> 0.27996811 | F4: =IF(AND(E4<=0),"C",IF(E4<=0.8,"A",IF(E4<=0.95,"B","C"))) -> A | G4: =VLOOKUP(B$4:B$104,I$4:M$104,5,0) -> A | I4: QS черные PZ | J4: ='Юнит 11'!U4 -> 758 | K4: =J4/J$105 -> 0.22163743 | L4: =K4 -> 0.22163743 | M4: =_xlfn.IFS(L4<80%,"A",L4<=95%,"B",L4>95%,"C") -> A | P4: A | Q4: 0.8
B5: th черн | C5: ='Юнит 11'!AO9 -> 101443.23 | D5: =C5/C$105 -> 0.076203977 | E5: =E4+D5 -> 0.35617209 | F5: =IF(AND(E5<=0),"C",IF(E5<=0.8,"A",IF(E5<=0.95,"B","C"))) -> A | G5: =VLOOKUP(B$4:B$104,I$4:M$104,5,0) -> A | I5: flip черные | J5: ='Юнит 11'!U13 -> 244 | K5: =J5/J$105 -> 0.071345029 | L5: =L4+K5 -> 0.29298246 | M5: =_xlfn.IFS(L5<80%,"A",L5<=95%,"B",L5>95%,"C") -> A | P5: B | Q5: 0.15
B6: flip черные | C6: ='Юнит 11'!AO13 -> 98640.755 | D6: =C6/C$105 -> 0.074098761 | E6: =E5+D6 -> 0.43027085 | F6: =IF(AND(E6<=0),"C",IF(E6<=0.8,"A",IF(E6<=0.95,"B","C"))) -> A | G6: =VLOOKUP(B$4:B$104,I$4:M$104,5,0) -> A | I6: th черн | J6: ='Юнит 11'!U9 -> 237 | K6: =J6/J$105 -> 0.069298246 | L6: =L5+K6 -> 0.3622807 | M6: =_xlfn.IFS(L6<80%,"A",L6<=95%,"B",L6>95%,"C") -> A | P6: C | Q6: 0.05
B7: QS коричневые PZ | C7: ='Юнит 11'!AO7 -> 90179.079 | D7: =C7/C$105 -> 0.067742366 | E7: =E6+D7 -> 0.49801322 | F7: =IF(AND(E7<=0),"C",IF(E7<=0.8,"A",IF(E7<=0.95,"B","C"))) -> A | G7: =VLOOKUP(B$4:B$104,I$4:M$104,5,0) -> A | I7: flip коричневые | J7: ='Юнит 11'!U16 -> 213 | K7: =J7/J$105 -> 0.062280702 | L7: =L6+K7 -> 0.4245614 | M7: =_xlfn.IFS(L7<80%,"A",L7<=95%,"B",L7>95%,"C") -> A
B8: flip коричневые | C8: ='Юнит 11'!AO16 -> 85947.698 | D8: =C8/C$105 -> 0.064563759 | E8: =E7+D8 -> 0.56257698 | F8: =IF(AND(E8<=0),"C",IF(E8<=0.8,"A",IF(E8<=0.95,"B","C"))) -> A | G8: =VLOOKUP(B$4:B$104,I$4:M$104,5,0) -> A | I8: QS коричневые PZ | J8: ='Юнит 11'!U7 -> 212 | K8: =J8/J$105 -> 0.061988304 | L8: =L7+K8 -> 0.48654971 | M8: =_xlfn.IFS(L8<80%,"A",L8<=95%,"B",L8>95%,"C") -> A
B9: черные с железкой классика | C9: ='Юнит 11'!AO3 -> 83816.677 | D9: =C9/C$105 -> 0.06296294 | E9: =E8+D9 -> 0.62553992 | F9: =IF(AND(E9<=0),"C",IF(E9<=0.8,"A",IF(E9<=0.95,"B","C"))) -> A | G9: =VLOOKUP(B$4:B$104,I$4:M$104,5,0) -> A | I9: th син | J9: ='Юнит 11'!U10 -> 199 | K9: =J9/J$105 -> 0.058187135 | L9: =L8+K9 -> 0.54473684 | M9: =_xlfn.IFS(L9<80%,"A",L9<=95%,"B",L9>95%,"C") -> A
B10: QS синие PZ | C10: ='Юнит 11'!AO5 -> 76669.887 | D10: =C10/C$105 -> 0.057594284 | E10: =E9+D10 -> 0.6831342 | F10: =IF(AND(E10<=0),"C",IF(E10<=0.8,"A",IF(E10<=0.95,"B","C"))) -> A | G10: =VLOOKUP(B$4:B$104,I$4:M$104,5,0) -> A | I10: QS синие PZ | J10: ='Юнит 11'!U5 -> 189 | K10: =J10/J$105 -> 0.055263158 | L10: =L9+K10 -> 0.6 | M10: =_xlfn.IFS(L10<80%,"A",L10<=95%,"B",L10>95%,"C") -> A
B11: th син | C11: ='Юнит 11'!AO10 -> 65001.22 | D11: =C11/C$105 -> 0.048828802 | E11: =E10+D11 -> 0.731963 | F11: =IF(AND(E11<=0),"C",IF(E11<=0.8,"A",IF(E11<=0.95,"B","C"))) -> A | G11: =VLOOKUP(B$4:B$104,I$4:M$104,5,0) -> A | I11: черные с железкой классика | J11: ='Юнит 11'!U3 -> 174 | K11: =J11/J$105 -> 0.050877193 | L11: =L10+K11 -> 0.65087719 | M11: =_xlfn.IFS(L11<80%,"A",L11<=95%,"B",L11>95%,"C") -> A
B12: th коричн | C12: ='Юнит 11'!AO12 -> 47119.494 | D12: =C12/C$105 -> 0.035396081 | E12: =E11+D12 -> 0.76735908 | F12: =IF(AND(E12<=0),"C",IF(E12<=0.8,"A",IF(E12<=0.95,"B","C"))) -> A | G12: =VLOOKUP(B$4:B$104,I$4:M$104,5,0) -> A | I12: sh3 | J12: ='Юнит 11'!U28 -> 161 | K12: =J12/J$105 -> 0.047076023 | L12: =L11+K12 -> 0.69795322 | M12: =_xlfn.IFS(L12<80%,"A",L12<=95%,"B",L12>95%,"C") -> A
B13: sh3 | C13: ='Юнит 11'!AO28 -> 46993.254 | D13: =C13/C$105 -> 0.035301249 | E13: =E12+D13 -> 0.80266033 | F13: =IF(AND(E13<=0),"C",IF(E13<=0.8,"A",IF(E13<=0.95,"B","C"))) -> B | G13: =VLOOKUP(B$4:B$104,I$4:M$104,5,0) -> A | I13: th коричн | J13: ='Юнит 11'!U12 -> 131 | K13: =J13/J$105 -> 0.038304094 | L13: =L12+K13 -> 0.73625731 | M13: =_xlfn.IFS(L13<80%,"A",L13<=95%,"B",L13>95%,"C") -> A
B14: QS желтые PZ | C14: ='Юнит 11'!AO6 -> 41935.561 | D14: =C14/C$105 -> 0.03150192 | E14: =E13+D14 -> 0.83416225 | F14: =IF(AND(E14<=0),"C",IF(E14<=0.8,"A",IF(E14<=0.95,"B","C"))) -> B | G14: =VLOOKUP(B$4:B$104,I$4:M$104,5,0) -> A | I14: QS желтые PZ | J14: ='Юнит 11'!U6 -> 116 | K14: =J14/J$105 -> 0.033918129 | L14: =L13+K14 -> 0.77017544 | M14: =_xlfn.IFS(L14<80%,"A",L14<=95%,"B",L14>95%,"C") -> A
B15: th желт | C15: ='Юнит 11'!AO11 -> 36095.771 | D15: =C15/C$105 -> 0.02711508 | E15: =E14+D15 -> 0.86127733 | F15: =IF(AND(E15<=0),"C",IF(E15<=0.8,"A",IF(E15<=0.95,"B","C"))) -> B | G15: =VLOOKUP(B$4:B$104,I$4:M$104,5,0) -> B | I15: th желт | J15: ='Юнит 11'!U11 -> 103 | K15: =J15/J$105 -> 0.030116959 | L15: =L14+K15 -> 0.8002924 | M15: =_xlfn.IFS(L15<80%,"A",L15<=95%,"B",L15>95%,"C") -> B
B16: ww 1022 коричневые | C16: ='Юнит 11'!AO48 -> 30869.087 | D16: =C16/C$105 -> 0.023188804 | E16: =E15+D16 -> 0.88446614 | F16: =IF(AND(E16<=0),"C",IF(E16<=0.8,"A",IF(E16<=0.95,"B","C"))) -> B | G16: =VLOOKUP(B$4:B$104,I$4:M$104,5,0) -> B | I16: wwl8032 хром металл | J16: ='Юнит 11'!U18 -> 80 | K16: =J16/J$105 -> 0.023391813 | L16: =L15+K16 -> 0.82368421 | M16: =_xlfn.IFS(L16<80%,"A",L16<=95%,"B",L16>95%,"C") -> B
B17: wwl8032 хром металл | C17: ='Юнит 11'!AO18 -> 29336.565 | D17: =C17/C$105 -> 0.022037576 | E17: =E16+D17 -> 0.90650371 | F17: =IF(AND(E17<=0),"C",IF(E17<=0.8,"A",IF(E17<=0.95,"B","C"))) -> B | G17: =VLOOKUP(B$4:B$104,I$4:M$104,5,0) -> B | I17: ww 1022 коричневые | J17: ='Юнит 11'!U48 -> 78 | K17: =J17/J$105 -> 0.022807018 | L17: =L16+K17 -> 0.84649123 | M17: =_xlfn.IFS(L17<80%,"A",L17<=95%,"B",L17>95%,"C") -> B
B18: flip синие | C18: ='Юнит 11'!AO14 -> 22061.684 | D18: =C18/C$105 -> 0.016572698 | E18: =E17+D18 -> 0.92307641 | F18: =IF(AND(E18<=0),"C",IF(E18<=0.8,"A",IF(E18<=0.95,"B","C"))) -> B | G18: =VLOOKUP(B$4:B$104,I$4:M$104,5,0) -> B | I18: ww 1022 черные | J18: ='Юнит 11'!U45 -> 65 | K18: =J18/J$105 -> 0.019005848 | L18: =L17+K18 -> 0.86549708 | M18: =_xlfn.IFS(L18<80%,"A",L18<=95%,"B",L18>95%,"C") -> B
B19: MR8854 C2 Жен | C19: ='Юнит 11'!AO8 -> 18609.356 | D19: =C19/C$105 -> 0.013979316 | E19: =E18+D19 -> 0.93705573 | F19: =IF(AND(E19<=0),"C",IF(E19<=0.8,"A",IF(E19<=0.95,"B","C"))) -> B | G19: =VLOOKUP(B$4:B$104,I$4:M$104,5,0) -> B | I19: flip синие | J19: ='Юнит 11'!U14 -> 59 | K19: =J19/J$105 -> 0.017251462 | L19: =L18+K19 -> 0.88274854 | M19: =_xlfn.IFS(L19<80%,"A",L19<=95%,"B",L19>95%,"C") -> B
B20: flip желтые | C20: ='Юнит 11'!AO15 -> 17310.689 | D20: =C20/C$105 -> 0.013003759 | E20: =E19+D20 -> 0.95005949 | F20: =IF(AND(E20<=0),"C",IF(E20<=0.8,"A",IF(E20<=0.95,"B","C"))) -> C | G20: =VLOOKUP(B$4:B$104,I$4:M$104,5,0) -> B | I20: sh1 | J20: ='Юнит 11'!U26 -> 47 | K20: =J20/J$105 -> 0.01374269 | L20: =L19+K20 -> 0.89649123 | M20: =_xlfn.IFS(L20<80%,"A",L20<=95%,"B",L20>95%,"C") -> B
B21: ww 1022 черные | C21: ='Юнит 11'!AO45 -> 16241.369 | D21: =C21/C$105 -> 0.012200488 | E21: =E20+D21 -> 0.96225997 | F21: =IF(AND(E21<=0),"C",IF(E21<=0.8,"A",IF(E21<=0.95,"B","C"))) -> C | G21: =VLOOKUP(B$4:B$104,I$4:M$104,5,0) -> B | I21: flip желтые | J21: ='Юнит 11'!U15 -> 45 | K21: =J21/J$105 -> 0.013157895 | L21: =L20+K21 -> 0.90964912 | M21: =_xlfn.IFS(L21<80%,"A",L21<=95%,"B",L21>95%,"C") -> B
B22: ww 2018 желтые | C22: ='Юнит 11'!AO50 -> 12918.717 | D22: =C22/C$105 -> 0.0097045174 | E22: =E21+D22 -> 0.97196449 | F22: =IF(AND(E22<=0),"C",IF(E22<=0.8,"A",IF(E22<=0.95,"B","C"))) -> C | G22: =VLOOKUP(B$4:B$104,I$4:M$104,5,0) -> B | I22: ww 2018 черные | J22: ='Юнит 11'!U49 -> 41 | K22: =J22/J$105 -> 0.011988304 | L22: =L21+K22 -> 0.92163743 | M22: =_xlfn.IFS(L22<80%,"A",L22<=95%,"B",L22>95%,"C") -> B
B23: ww 2018 черные | C23: ='Юнит 11'!AO49 -> 9394.169 | D23: =C23/C$105 -> 0.0070568832 | E23: =E22+D23 -> 0.97902137 | F23: =IF(AND(E23<=0),"C",IF(E23<=0.8,"A",IF(E23<=0.95,"B","C"))) -> C | G23: =VLOOKUP(B$4:B$104,I$4:M$104,5,0) -> B | I23: MR8854 C2 Жен | J23: ='Юнит 11'!U8 -> 40 | K23: =J23/J$105 -> 0.011695906 | L23: =L22+K23 -> 0.93333333 | M23: =_xlfn.IFS(L23<80%,"A",L23<=95%,"B",L23>95%,"C") -> B
B24: ww 1022 желтые | C24: ='Юнит 11'!AO47 -> 7539.9411 | D24: =C24/C$105 -> 0.0056639905 | E24: =E23+D24 -> 0.98468537 | F24: =IF(AND(E24<=0),"C",IF(E24<=0.8,"A",IF(E24<=0.95,"B","C"))) -> C | G24: =VLOOKUP(B$4:B$104,I$4:M$104,5,0) -> C | I24: ww 2018 желтые | J24: ='Юнит 11'!U50 -> 40 | K24: =J24/J$105 -> 0.011695906 | L24: =L23+K24 -> 0.94502924 | M24: =_xlfn.IFS(L24<80%,"A",L24<=95%,"B",L24>95%,"C") -> B
B25: ww 203 черные | C25: ='Юнит 11'!AO44 -> 7503.8357 | D25: =C25/C$105 -> 0.0056368682 | E25: =E24+D25 -> 0.99032223 | F25: =IF(AND(E25<=0),"C",IF(E25<=0.8,"A",IF(E25<=0.95,"B","C"))) -> C | G25: =VLOOKUP(B$4:B$104,I$4:M$104,5,0) -> C | I25: ww 203 черные | J25: ='Юнит 11'!U44 -> 31 | K25: =J25/J$105 -> 0.0090643275 | L25: =L24+K25 -> 0.95409357 | M25: =_xlfn.IFS(L25<80%,"A",L25<=95%,"B",L25>95%,"C") -> C
B26: кс_черные_женские | C26: ='Юнит 11'!AO102 -> 6221.3993 | D26: =C26/C$105 -> 0.0046735042 | E26: =E25+D26 -> 0.99499574 | F26: =IF(AND(E26<=0),"C",IF(E26<=0.8,"A",IF(E26<=0.95,"B","C"))) -> C | G26: =VLOOKUP(B$4:B$104,I$4:M$104,5,0) -> C | I26: ww 1022 желтые | J26: ='Юнит 11'!U47 -> 24 | K26: =J26/J$105 -> 0.0070175439 | L26: =L25+K26 -> 0.96111111 | M26: =_xlfn.IFS(L26<80%,"A",L26<=95%,"B",L26>95%,"C") -> C
B27: wwl8032 коричневые золото | C27: ='Юнит 11'!AO17 -> 4815.3401 | D27: =C27/C$105 -> 0.003617275 | E27: =E26+D27 -> 0.99861301 | F27: =IF(AND(E27<=0),"C",IF(E27<=0.8,"A",IF(E27<=0.95,"B","C"))) -> C | G27: =VLOOKUP(B$4:B$104,I$4:M$104,5,0) -> C | I27: wwl8032 коричневые золото | J27: ='Юнит 11'!U17 -> 19 | K27: =J27/J$105 -> 0.0055555556 | L27: =L26+K27 -> 0.96666667 | M27: =_xlfn.IFS(L27<80%,"A",L27<=95%,"B",L27>95%,"C") -> C
B28: sh19 | C28: ='Юнит 11'!AO43 -> 4196.4358 | D28: =C28/C$105 -> 0.0031523552 | E28: =E27+D28 -> 1.0017654 | F28: =IF(AND(E28<=0),"C",IF(E28<=0.8,"A",IF(E28<=0.95,"B","C"))) -> C | G28: =VLOOKUP(B$4:B$104,I$4:M$104,5,0) -> C | I28: кс_черные_женские | J28: ='Юнит 11'!U102 -> 17 | K28: =J28/J$105 -> 0.0049707602 | L28: =L27+K28 -> 0.97163743 | M28: =_xlfn.IFS(L28<80%,"A",L28<=95%,"B",L28>95%,"C") -> C
B29: sh15 | C29: ='Юнит 11'!AO39 -> 2682.254 | D29: =C29/C$105 -> 0.0020149045 | E29: =E28+D29 -> 1.0037803 | F29: =IF(AND(E29<=0),"C",IF(E29<=0.8,"A",IF(E29<=0.95,"B","C"))) -> C | G29: =VLOOKUP(B$4:B$104,I$4:M$104,5,0) -> C | I29: sh2 | J29: ='Юнит 11'!U27 -> 12 | K29: =J29/J$105 -> 0.0035087719 | L29: =L28+K29 -> 0.9751462 | M29: =_xlfn.IFS(L29<80%,"A",L29<=95%,"B",L29>95%,"C") -> C
B30: Linhai Baiyi розовая линза | C30: ='Юнит 11'!AO88 -> 2197.8883 | D30: =C30/C$105 -> 0.0016510499 | E30: =E29+D30 -> 1.0054313 | F30: =IF(AND(E30<=0),"C",IF(E30<=0.8,"A",IF(E30<=0.95,"B","C"))) -> C | G30: =VLOOKUP(B$4:B$104,I$4:M$104,5,0) -> C | I30: sh19 | J30: ='Юнит 11'!U43 -> 12 | K30: =J30/J$105 -> 0.0035087719 | L30: =L29+K30 -> 0.97865497 | M30: =_xlfn.IFS(L30<80%,"A",L30<=95%,"B",L30>95%,"C") -> C
B31: sh18 | C31: ='Юнит 11'!AO42 -> 2188.725 | D31: =C31/C$105 -> 0.0016441664 | E31: =E30+D31 -> 1.0070755 | F31: =IF(AND(E31<=0),"C",IF(E31<=0.8,"A",IF(E31<=0.95,"B","C"))) -> C | G31: =VLOOKUP(B$4:B$104,I$4:M$104,5,0) -> C | I31: sh15 | J31: ='Юнит 11'!U39 -> 10 | K31: =J31/J$105 -> 0.0029239766 | L31: =L30+K31 -> 0.98157895 | M31: =_xlfn.IFS(L31<80%,"A",L31<=95%,"B",L31>95%,"C") -> C
B32: ww 8010 черные | C32: ='Юнит 11'!AO51 -> 1306.853 | D32: =C32/C$105 -> 0.00098170567 | E32: =E31+D32 -> 1.0080572 | F32: =IF(AND(E32<=0),"C",IF(E32<=0.8,"A",IF(E32<=0.95,"B","C"))) -> C | G32: =VLOOKUP(B$4:B$104,I$4:M$104,5,0) -> C | I32: sh18 | J32: ='Юнит 11'!U42 -> 5 | K32: =J32/J$105 -> 0.0014619883 | L32: =L31+K32 -> 0.98304094 | M32: =_xlfn.IFS(L32<80%,"A",L32<=95%,"B",L32>95%,"C") -> C
B33: sh16 | C33: ='Юнит 11'!AO40 -> 1276.7088 | D33: =C33/C$105 -> 0.00095906141 | E33: =E32+D33 -> 1.0090163 | F33: =IF(AND(E33<=0),"C",IF(E33<=0.8,"A",IF(E33<=0.95,"B","C"))) -> C | G33: =VLOOKUP(B$4:B$104,I$4:M$104,5,0) -> C | I33: MANNA2105 | J33: ='Юнит 11'!U58 -> 5 | K33: =J33/J$105 -> 0.0014619883 | L33: =L32+K33 -> 0.98450292 | M33: =_xlfn.IFS(L33<80%,"A",L33<=95%,"B",L33>95%,"C") -> C
B34: Linhai Baiyi коричневая линза | C34: ='Юнит 11'!AO86 -> 1271.0432 | D34: =C34/C$105 -> 0.00095480545 | E34: =E33+D34 -> 1.0099711 | F34: =IF(AND(E34<=0),"C",IF(E34<=0.8,"A",IF(E34<=0.95,"B","C"))) -> C | G34: =VLOOKUP(B$4:B$104,I$4:M$104,5,0) -> C | I34: MANNA2122 | J34: ='Юнит 11'!U75 -> 5 | K34: =J34/J$105 -> 0.0014619883 | L34: =L33+K34 -> 0.98596491 | M34: =_xlfn.IFS(L34<80%,"A",L34<=95%,"B",L34>95%,"C") -> C
B35: MR Р1894 черные | C35: ='Юнит 11'!AO89 -> 1130.3385 | D35: =C35/C$105 -> 0.00084910831 | E35: =E34+D35 -> 1.0108202 | F35: =IF(AND(E35<=0),"C",IF(E35<=0.8,"A",IF(E35<=0.95,"B","C"))) -> C | G35: =VLOOKUP(B$4:B$104,I$4:M$104,5,0) -> C | I35: Linhai Baiyi серая линза | J35: ='Юнит 11'!U87 -> 5 | K35: =J35/J$105 -> 0.0014619883 | L35: =L34+K35 -> 0.9874269 | M35: =_xlfn.IFS(L35<80%,"A",L35<=95%,"B",L35>95%,"C") -> C
B36: Keming Aishi коричневые | C36: ='Юнит 11'!AO85 -> 1055.4695 | D36: =C36/C$105 -> 0.00079286682 | E36: =E35+D36 -> 1.011613 | F36: =IF(AND(E36<=0),"C",IF(E36<=0.8,"A",IF(E36<=0.95,"B","C"))) -> C | G36: =VLOOKUP(B$4:B$104,I$4:M$104,5,0) -> C | I36: Linhai Baiyi розовая линза | J36: ='Юнит 11'!U88 -> 5 | K36: =J36/J$105 -> 0.0014619883 | L36: =L35+K36 -> 0.98888889 | M36: =_xlfn.IFS(L36<80%,"A",L36<=95%,"B",L36>95%,"C") -> C
B37: ЧСЖ_женские | C37: ='Юнит 11'!AO100 -> 800.73503 | D37: =C37/C$105 -> 0.00060151074 | E37: =E36+D37 -> 1.0122145 | F37: =IF(AND(E37<=0),"C",IF(E37<=0.8,"A",IF(E37<=0.95,"B","C"))) -> C | G37: =VLOOKUP(B$4:B$104,I$4:M$104,5,0) -> C | I37: Keming Aishi коричневые | J37: ='Юнит 11'!U85 -> 4 | K37: =J37/J$105 -> 0.0011695906 | L37: =L36+K37 -> 0.99005848 | M37: =_xlfn.IFS(L37<80%,"A",L37<=95%,"B",L37>95%,"C") -> C
B38: MANNA2119 | C38: ='Юнит 11'!AO72 -> 537.4095 | D38: =C38/C$105 -> 0.00040370107 | E38: =E37+D38 -> 1.0126182 | F38: =IF(AND(E38<=0),"C",IF(E38<=0.8,"A",IF(E38<=0.95,"B","C"))) -> C | G38: =VLOOKUP(B$4:B$104,I$4:M$104,5,0) -> C | I38: sh16 | J38: ='Юнит 11'!U40 -> 3 | K38: =J38/J$105 -> 0.00087719298 | L38: =L37+K38 -> 0.99093567 | M38: =_xlfn.IFS(L38<80%,"A",L38<=95%,"B",L38>95%,"C") -> C
B39: MAIERSHA 03898 C9-08 | C39: ='Юнит 11'!AO94 -> 311.817 | D39: =C39/C$105 -> 0.00023423638 | E39: =E35+D39 -> 1.0110544 | F39: =IF(AND(E39<=0),"C",IF(E39<=0.8,"A",IF(E39<=0.95,"B","C"))) -> C | G39: =VLOOKUP(B$4:B$104,I$4:M$104,5,0) -> C | I39: ww 8010 черные | J39: ='Юнит 11'!U51 -> 3 | K39: =J39/J$105 -> 0.00087719298 | L39: =L35+K39 -> 0.98830409 | M39: =_xlfn.IFS(L39<80%,"A",L39<=95%,"B",L39>95%,"C") -> C
B40: Chenlong черные | C40: ='Юнит 11'!AO76 -> 292.84346 | D40: =C40/C$105 -> 0.00021998349 | E40: =E39+D40 -> 1.0112744 | F40: =IF(AND(E40<=0),"C",IF(E40<=0.8,"A",IF(E40<=0.95,"B","C"))) -> C | G40: =VLOOKUP(B$4:B$104,I$4:M$104,5,0) -> C | I40: MANNA2118 | J40: ='Юнит 11'!U71 -> 3 | K40: =J40/J$105 -> 0.00087719298 | L40: =L39+K40 -> 0.98918129 | M40: =_xlfn.IFS(L40<80%,"A",L40<=95%,"B",L40>95%,"C") -> C
B41: MANNA2107 | C41: ='Юнит 11'!AO60 -> 273.02262 | D41: =C41/C$105 -> 0.00020509411 | E41: =E40+D41 -> 1.0114795 | F41: =IF(AND(E41<=0),"C",IF(E41<=0.8,"A",IF(E41<=0.95,"B","C"))) -> C | G41: =VLOOKUP(B$4:B$104,I$4:M$104,5,0) -> C | I41: Linhai Baiyi коричневая линза | J41: ='Юнит 11'!U86 -> 3 | K41: =J41/J$105 -> 0.00087719298 | L41: =L40+K41 -> 0.99005848 | M41: =_xlfn.IFS(L41<80%,"A",L41<=95%,"B",L41>95%,"C") -> C
...

Sheet АВС 10
B2: ОЧКИ
C3: Прибыль | D3: % прибыль | E3: Доля | F3: ABC прибыль | G3: ABC кол-во | J3: Кол-во | K3: % кол-во | L3: Доля | M3: ABC кол-во
B4: QS черные PZ | C4: ='Юнит 10'!AO4 -> 180713.27 | D4: =C4/C$105 -> 0.27381245 | E4: =D4 -> 0.27381245 | F4: =IF(AND(E4<=0),"C",IF(E4<=0.8,"A",IF(E4<=0.95,"B","C"))) -> A | G4: =VLOOKUP(B$4:B$104,I$4:M$104,5,0) -> A | I4: QS черные PZ | J4: ='Юнит 10'!U4 -> 427 | K4: =J4/J$105 -> 0.20900636 | L4: =K4 -> 0.20900636 | M4: =_xlfn.IFS(L4<80%,"A",L4<=95%,"B",L4>95%,"C") -> A | P4: A | Q4: 0.8
B5: QS синие PZ | C5: ='Юнит 10'!AO5 -> 59221.135 | D5: =C5/C$105 -> 0.089730454 | E5: =E4+D5 -> 0.3635429 | F5: =IF(AND(E5<=0),"C",IF(E5<=0.8,"A",IF(E5<=0.95,"B","C"))) -> A | G5: =VLOOKUP(B$4:B$104,I$4:M$104,5,0) -> A | I5: QS синие PZ | J5: ='Юнит 10'!U5 -> 143 | K5: =J5/J$105 -> 0.069995105 | L5: =L4+K5 -> 0.27900147 | M5: =_xlfn.IFS(L5<80%,"A",L5<=95%,"B",L5>95%,"C") -> A | P5: B | Q5: 0.15
B6: QS коричневые PZ | C6: ='Юнит 10'!AO7 -> 56821.8 | D6: =C6/C$105 -> 0.086095038 | E6: =E5+D6 -> 0.44963794 | F6: =IF(AND(E6<=0),"C",IF(E6<=0.8,"A",IF(E6<=0.95,"B","C"))) -> A | G6: =VLOOKUP(B$4:B$104,I$4:M$104,5,0) -> A | I6: QS коричневые PZ | J6: ='Юнит 10'!U7 -> 139 | K6: =J6/J$105 -> 0.0680372 | L6: =L5+K6 -> 0.34703867 | M6: =_xlfn.IFS(L6<80%,"A",L6<=95%,"B",L6>95%,"C") -> A | P6: C | Q6: 0.05
B7: flip черные | C7: ='Юнит 10'!AO13 -> 48751.577 | D7: =C7/C$105 -> 0.073867228 | E7: =E6+D7 -> 0.52350516 | F7: =IF(AND(E7<=0),"C",IF(E7<=0.8,"A",IF(E7<=0.95,"B","C"))) -> A | G7: =VLOOKUP(B$4:B$104,I$4:M$104,5,0) -> A | I7: flip черные | J7: ='Юнит 10'!U13 -> 132 | K7: =J7/J$105 -> 0.064610866 | L7: =L6+K7 -> 0.41164953 | M7: =_xlfn.IFS(L7<80%,"A",L7<=95%,"B",L7>95%,"C") -> A
B8: th черн | C8: ='Юнит 10'!AO9 -> 38157.585 | D8: =C8/C$105 -> 0.057815464 | E8: =E7+D8 -> 0.58132063 | F8: =IF(AND(E8<=0),"C",IF(E8<=0.8,"A",IF(E8<=0.95,"B","C"))) -> A | G8: =VLOOKUP(B$4:B$104,I$4:M$104,5,0) -> A | I8: sh3 | J8: ='Юнит 10'!U28 -> 112 | K8: =J8/J$105 -> 0.054821341 | L8: =L7+K8 -> 0.46647088 | M8: =_xlfn.IFS(L8<80%,"A",L8<=95%,"B",L8>95%,"C") -> A
B9: flip коричневые | C9: ='Юнит 10'!AO16 -> 36602.996 | D9: =C9/C$105 -> 0.055459987 | E9: =E8+D9 -> 0.63678062 | F9: =IF(AND(E9<=0),"C",IF(E9<=0.8,"A",IF(E9<=0.95,"B","C"))) -> A | G9: =VLOOKUP(B$4:B$104,I$4:M$104,5,0) -> A | I9: th син | J9: ='Юнит 10'!U10 -> 111 | K9: =J9/J$105 -> 0.054331865 | L9: =L8+K9 -> 0.52080274 | M9: =_xlfn.IFS(L9<80%,"A",L9<=95%,"B",L9>95%,"C") -> A
B10: QS желтые PZ | C10: ='Юнит 10'!AO6 -> 35164.892 | D10: =C10/C$105 -> 0.053281007 | E10: =E9+D10 -> 0.69006162 | F10: =IF(AND(E10<=0),"C",IF(E10<=0.8,"A",IF(E10<=0.95,"B","C"))) -> A | G10: =VLOOKUP(B$4:B$104,I$4:M$104,5,0) -> A | I10: flip коричневые | J10: ='Юнит 10'!U16 -> 111 | K10: =J10/J$105 -> 0.054331865 | L10: =L9+K10 -> 0.57513461 | M10: =_xlfn.IFS(L10<80%,"A",L10<=95%,"B",L10>95%,"C") -> A
B11: черные с железкой классика | C11: ='Юнит 10'!AO3 -> 34966.219 | D11: =C11/C$105 -> 0.052979982 | E11: =E10+D11 -> 0.74304161 | F11: =IF(AND(E11<=0),"C",IF(E11<=0.8,"A",IF(E11<=0.95,"B","C"))) -> A | G11: =VLOOKUP(B$4:B$104,I$4:M$104,5,0) -> A | I11: th черн | J11: ='Юнит 10'!U9 -> 107 | K11: =J11/J$105 -> 0.05237396 | L11: =L10+K11 -> 0.62750857 | M11: =_xlfn.IFS(L11<80%,"A",L11<=95%,"B",L11>95%,"C") -> A
B12: sh3 | C12: ='Юнит 10'!AO28 -> 30976.089 | D12: =C12/C$105 -> 0.046934232 | E12: =E11+D12 -> 0.78997584 | F12: =IF(AND(E12<=0),"C",IF(E12<=0.8,"A",IF(E12<=0.95,"B","C"))) -> A | G12: =VLOOKUP(B$4:B$104,I$4:M$104,5,0) -> A | I12: QS желтые PZ | J12: ='Юнит 10'!U6 -> 105 | K12: =J12/J$105 -> 0.051395007 | L12: =L11+K12 -> 0.67890357 | M12: =_xlfn.IFS(L12<80%,"A",L12<=95%,"B",L12>95%,"C") -> A
B13: th желт | C13: ='Юнит 10'!AO11 -> 23552.911 | D13: =C13/C$105 -> 0.03568681 | E13: =E12+D13 -> 0.82566265 | F13: =IF(AND(E13<=0),"C",IF(E13<=0.8,"A",IF(E13<=0.95,"B","C"))) -> B | G13: =VLOOKUP(B$4:B$104,I$4:M$104,5,0) -> A | I13: черные с железкой классика | J13: ='Юнит 10'!U3 -> 101 | K13: =J13/J$105 -> 0.049437102 | L13: =L12+K13 -> 0.72834068 | M13: =_xlfn.IFS(L13<80%,"A",L13<=95%,"B",L13>95%,"C") -> A
B14: th син | C14: ='Юнит 10'!AO10 -> 22578.741 | D14: =C14/C$105 -> 0.03421077 | E14: =E13+D14 -> 0.85987342 | F14: =IF(AND(E14<=0),"C",IF(E14<=0.8,"A",IF(E14<=0.95,"B","C"))) -> B | G14: =VLOOKUP(B$4:B$104,I$4:M$104,5,0) -> A | I14: th желт | J14: ='Юнит 10'!U11 -> 62 | K14: =J14/J$105 -> 0.030347528 | L14: =L13+K14 -> 0.7586882 | M14: =_xlfn.IFS(L14<80%,"A",L14<=95%,"B",L14>95%,"C") -> A
B15: th коричн | C15: ='Юнит 10'!AO12 -> 19945.773 | D15: =C15/C$105 -> 0.03022136 | E15: =E14+D15 -> 0.89009478 | F15: =IF(AND(E15<=0),"C",IF(E15<=0.8,"A",IF(E15<=0.95,"B","C"))) -> B | G15: =VLOOKUP(B$4:B$104,I$4:M$104,5,0) -> A | I15: th коричн | J15: ='Юнит 10'!U12 -> 61 | K15: =J15/J$105 -> 0.029858052 | L15: =L14+K15 -> 0.78854626 | M15: =_xlfn.IFS(L15<80%,"A",L15<=95%,"B",L15>95%,"C") -> A
B16: MR8854 C2 Жен | C16: ='Юнит 10'!AO8 -> 14201.921 | D16: =C16/C$105 -> 0.021518412 | E16: =E15+D16 -> 0.91161319 | F16: =IF(AND(E16<=0),"C",IF(E16<=0.8,"A",IF(E16<=0.95,"B","C"))) -> B | G16: =VLOOKUP(B$4:B$104,I$4:M$104,5,0) -> B | I16: sh1 | J16: ='Юнит 10'!U26 -> 53 | K16: =J16/J$105 -> 0.025942242 | L16: =L15+K16 -> 0.8144885 | M16: =_xlfn.IFS(L16<80%,"A",L16<=95%,"B",L16>95%,"C") -> B
B17: ww 1022 черные | C17: ='Юнит 10'!AO45 -> 13864.821 | D17: =C17/C$105 -> 0.021007647 | E17: =E16+D17 -> 0.93262084 | F17: =IF(AND(E17<=0),"C",IF(E17<=0.8,"A",IF(E17<=0.95,"B","C"))) -> B | G17: =VLOOKUP(B$4:B$104,I$4:M$104,5,0) -> B | I17: MR8854 C2 Жен | J17: ='Юнит 10'!U8 -> 43 | K17: =J17/J$105 -> 0.021047479 | L17: =L16+K17 -> 0.83553598 | M17: =_xlfn.IFS(L17<80%,"A",L17<=95%,"B",L17>95%,"C") -> B
B18: flip синие | C18: ='Юнит 10'!AO14 -> 11037.77 | D18: =C18/C$105 -> 0.016724166 | E18: =E17+D18 -> 0.949345 | F18: =IF(AND(E18<=0),"C",IF(E18<=0.8,"A",IF(E18<=0.95,"B","C"))) -> B | G18: =VLOOKUP(B$4:B$104,I$4:M$104,5,0) -> B | I18: wwl8032 хром металл | J18: ='Юнит 10'!U18 -> 41 | K18: =J18/J$105 -> 0.020068527 | L18: =L17+K18 -> 0.8556045 | M18: =_xlfn.IFS(L18<80%,"A",L18<=95%,"B",L18>95%,"C") -> B
B19: wwl8032 хром металл | C19: ='Юнит 10'!AO18 -> 8534.8232 | D19: =C19/C$105 -> 0.012931761 | E19: =E18+D19 -> 0.96227676 | F19: =IF(AND(E19<=0),"C",IF(E19<=0.8,"A",IF(E19<=0.95,"B","C"))) -> C | G19: =VLOOKUP(B$4:B$104,I$4:M$104,5,0) -> B | I19: ww 1022 черные | J19: ='Юнит 10'!U45 -> 39 | K19: =J19/J$105 -> 0.019089574 | L19: =L18+K19 -> 0.87469408 | M19: =_xlfn.IFS(L19<80%,"A",L19<=95%,"B",L19>95%,"C") -> B
B20: flip желтые | C20: ='Юнит 10'!AO15 -> 8514.253 | D20: =C20/C$105 -> 0.012900593 | E20: =E19+D20 -> 0.97517736 | F20: =IF(AND(E20<=0),"C",IF(E20<=0.8,"A",IF(E20<=0.95,"B","C"))) -> C | G20: =VLOOKUP(B$4:B$104,I$4:M$104,5,0) -> B | I20: flip синие | J20: ='Юнит 10'!U14 -> 35 | K20: =J20/J$105 -> 0.017131669 | L20: =L19+K20 -> 0.89182575 | M20: =_xlfn.IFS(L20<80%,"A",L20<=95%,"B",L20>95%,"C") -> B
B21: ww 1022 коричневые | C21: ='Юнит 10'!AO48 -> 8417.1211 | D21: =C21/C$105 -> 0.012753421 | E21: =E20+D21 -> 0.98793078 | F21: =IF(AND(E21<=0),"C",IF(E21<=0.8,"A",IF(E21<=0.95,"B","C"))) -> C | G21: =VLOOKUP(B$4:B$104,I$4:M$104,5,0) -> B | I21: ww 1022 коричневые | J21: ='Юнит 10'!U48 -> 28 | K21: =J21/J$105 -> 0.013705335 | L21: =L20+K21 -> 0.90553108 | M21: =_xlfn.IFS(L21<80%,"A",L21<=95%,"B",L21>95%,"C") -> B
B22: ww 2018 черные | C22: ='Юнит 10'!AO49 -> 6809.9373 | D22: =C22/C$105 -> 0.010318255 | E22: =E21+D22 -> 0.99824903 | F22: =IF(AND(E22<=0),"C",IF(E22<=0.8,"A",IF(E22<=0.95,"B","C"))) -> C | G22: =VLOOKUP(B$4:B$104,I$4:M$104,5,0) -> B | I22: flip желтые | J22: ='Юнит 10'!U15 -> 25 | K22: =J22/J$105 -> 0.012236907 | L22: =L21+K22 -> 0.91776799 | M22: =_xlfn.IFS(L22<80%,"A",L22<=95%,"B",L22>95%,"C") -> B
B23: wwl8032 коричневые золото | C23: ='Юнит 10'!AO17 -> 6424.1933 | D23: =C23/C$105 -> 0.0097337847 | E23: =E22+D23 -> 1.0079828 | F23: =IF(AND(E23<=0),"C",IF(E23<=0.8,"A",IF(E23<=0.95,"B","C"))) -> C | G23: =VLOOKUP(B$4:B$104,I$4:M$104,5,0) -> B | I23: ww 2018 черные | J23: ='Юнит 10'!U49 -> 25 | K23: =J23/J$105 -> 0.012236907 | L23: =L22+K23 -> 0.93000489 | M23: =_xlfn.IFS(L23<80%,"A",L23<=95%,"B",L23>95%,"C") -> B
B24: ww 1022 желтые | C24: ='Юнит 10'!AO47 -> 4786.2281 | D24: =C24/C$105 -> 0.0072519788 | E24: =E23+D24 -> 1.0152348 | F24: =IF(AND(E24<=0),"C",IF(E24<=0.8,"A",IF(E24<=0.95,"B","C"))) -> C | G24: =VLOOKUP(B$4:B$104,I$4:M$104,5,0) -> C | I24: wwl8032 коричневые золото | J24: ='Юнит 10'!U17 -> 19 | K24: =J24/J$105 -> 0.0093000489 | L24: =L23+K24 -> 0.93930494 | M24: =_xlfn.IFS(L24<80%,"A",L24<=95%,"B",L24>95%,"C") -> B
B25: ww 2018 желтые | C25: ='Юнит 10'!AO50 -> 4625.2657 | D25: =C25/C$105 -> 0.0070080924 | E25: =E24+D25 -> 1.0222429 | F25: =IF(AND(E25<=0),"C",IF(E25<=0.8,"A",IF(E25<=0.95,"B","C"))) -> C | G25: =VLOOKUP(B$4:B$104,I$4:M$104,5,0) -> C | I25: sh19 | J25: ='Юнит 10'!U43 -> 17 | K25: =J25/J$105 -> 0.0083210964 | L25: =L24+K25 -> 0.94762604 | M25: =_xlfn.IFS(L25<80%,"A",L25<=95%,"B",L25>95%,"C") -> B
B26: sh19 | C26: ='Юнит 10'!AO43 -> 3584.3455 | D26: =C26/C$105 -> 0.0054309149 | E26: =E25+D26 -> 1.0276738 | F26: =IF(AND(E26<=0),"C",IF(E26<=0.8,"A",IF(E26<=0.95,"B","C"))) -> C | G26: =VLOOKUP(B$4:B$104,I$4:M$104,5,0) -> B | I26: ww 2018 желтые | J26: ='Юнит 10'!U50 -> 16 | K26: =J26/J$105 -> 0.0078316202 | L26: =L25+K26 -> 0.95545766 | M26: =_xlfn.IFS(L26<80%,"A",L26<=95%,"B",L26>95%,"C") -> C
B27: ww 203 черные | C27: ='Юнит 10'!AO44 -> 2519.735 | D27: =C27/C$105 -> 0.0038178425 | E27: =E26+D27 -> 1.0314916 | F27: =IF(AND(E27<=0),"C",IF(E27<=0.8,"A",IF(E27<=0.95,"B","C"))) -> C | G27: =VLOOKUP(B$4:B$104,I$4:M$104,5,0) -> C | I27: ww 203 черные | J27: ='Юнит 10'!U44 -> 14 | K27: =J27/J$105 -> 0.0068526676 | L27: =L26+K27 -> 0.96231033 | M27: =_xlfn.IFS(L27<80%,"A",L27<=95%,"B",L27>95%,"C") -> C
B28: sh13 | C28: ='Юнит 10'!AO37 -> 1158.0127 | D28: =C28/C$105 -> 0.0017545932 | E28: =E27+D28 -> 1.0332462 | F28: =IF(AND(E28<=0),"C",IF(E28<=0.8,"A",IF(E28<=0.95,"B","C"))) -> C | G28: =VLOOKUP(B$4:B$104,I$4:M$104,5,0) -> C | I28: ww 1022 желтые | J28: ='Юнит 10'!U47 -> 14 | K28: =J28/J$105 -> 0.0068526676 | L28: =L27+K28 -> 0.969163 | M28: =_xlfn.IFS(L28<80%,"A",L28<=95%,"B",L28>95%,"C") -> C
B29: sh18 | C29: ='Юнит 10'!AO42 -> 885.19153 | D29: =C29/C$105 -> 0.0013412211 | E29: =E28+D29 -> 1.0345875 | F29: =IF(AND(E29<=0),"C",IF(E29<=0.8,"A",IF(E29<=0.95,"B","C"))) -> C | G29: =VLOOKUP(B$4:B$104,I$4:M$104,5,0) -> C | I29: sh2 | J29: ='Юнит 10'!U27 -> 10 | K29: =J29/J$105 -> 0.0048947626 | L29: =L28+K29 -> 0.97405776 | M29: =_xlfn.IFS(L29<80%,"A",L29<=95%,"B",L29>95%,"C") -> C
B30: Chenlong черные | C30: ='Юнит 10'!AO76 -> 863.21771 | D30: =C30/C$105 -> 0.0013079269 | E30: =E29+D30 -> 1.0358954 | F30: =IF(AND(E30<=0),"C",IF(E30<=0.8,"A",IF(E30<=0.95,"B","C"))) -> C | G30: =VLOOKUP(B$4:B$104,I$4:M$104,5,0) -> C | I30: Linhai Baiyi серая линза | J30: ='Юнит 10'!U87 -> 8 | K30: =J30/J$105 -> 0.0039158101 | L30: =L29+K30 -> 0.97797357 | M30: =_xlfn.IFS(L30<80%,"A",L30<=95%,"B",L30>95%,"C") -> C
B31: MANNA2119 | C31: ='Юнит 10'!AO72 -> 824.1899 | D31: =C31/C$105 -> 0.0012487929 | E31: =E30+D31 -> 1.0371442 | F31: =IF(AND(E31<=0),"C",IF(E31<=0.8,"A",IF(E31<=0.95,"B","C"))) -> C | G31: =VLOOKUP(B$4:B$104,I$4:M$104,5,0) -> C | I31: sh15 | J31: ='Юнит 10'!U39 -> 7 | K31: =J31/J$105 -> 0.0034263338 | L31: =L30+K31 -> 0.9813999 | M31: =_xlfn.IFS(L31<80%,"A",L31<=95%,"B",L31>95%,"C") -> C
B32: WW 3055 черный | C32: ='Юнит 10'!AO52 -> 644.0974 | D32: =C32/C$105 -> 0.00097592104 | E32: =E31+D32 -> 1.0381201 | F32: =IF(AND(E32<=0),"C",IF(E32<=0.8,"A",IF(E32<=0.95,"B","C"))) -> C | G32: =VLOOKUP(B$4:B$104,I$4:M$104,5,0) -> C | I32: sh13 | J32: ='Юнит 10'!U37 -> 4 | K32: =J32/J$105 -> 0.001957905 | L32: =L31+K32 -> 0.98335781 | M32: =_xlfn.IFS(L32<80%,"A",L32<=95%,"B",L32>95%,"C") -> C
