Workbook

Sheet Реклама
B2: БАЛАНС | E2: СЧЕТ | H2: ПРОМОБОНУСЫ | K2: Неделя
B3: Номер документа | C3: Сумма | D3: Даты | E3: Номер документа | F3: Сумма | G3: Даты | H3: Номер документа | I3: Сумма | J3: Даты
B4: 277433850 | C4: 1376 | D4: 28-31.12 | E4: 277433847 | F4: 25829 | G4: 28-31.12 | H4: 0 | I4: 109 | J4: 29-31.12 | K4: 1
B5: 277539131 | C5: 1150 | D5: 36951 | E5: 277609313 | F5: 21489 | G5: 36982 | H5: 0 | I5: 363 | J5: 36982
B6: 279208603 | C6: 3455 | D6: 37168 | E6: 279208599 | F6: 51313 | G6: 37199 | H6: 0 | I6: 569 | J6: 37200 | K6: 2
B7: 280269091 | C7: 10268 | D7: 11-18.01 | E7: 280221209 | F7: 99763 | G7: 11-18.01 | H7: 0 | I7: 557 | J7: 12-18.01 | K7: 3
B8: 281267335 | C8: 70408 | D8: 19-25.01 | E8: 281348313 | F8: 67741 | G8: 18-25.01 | H8: 0 | I8: 195 | J8: 19-25.01 | K8: 4
B9: 282258474 | C9: 25521 | D9: 25-31.01 | E9: 282345086 | F9: 133680 | G9: 25-31.01 | H9: 0 | I9: 80 | J9: 26-31.01 | K9: 5
B10: 282365257 | C10: 1268 | D10: 46054 | E10: 282392960 | F10: 4672 | G10: 46054
B11: 283332206 | C11: 111419 | D11: 37469 | E11: 283415801 | F11: 126688 | G11: 37469 | H11: 0 | I11: 3554 | J11: 37440 | K11: 6
B12: 284423647 | C12: 145581 | D12: 08-15.02 | E12: 284416459 | F12: 138670 | G12: 08-15.02 | H12: 0 | I12: 44 | J12: 46063 | K12: 7
B13: 285348588 | C13: 50989 | D13: 15-22.02 | E13: 285348587 | F13: 265182 | G13: 15-22.02 | K13: 8
B14: 286343097 | C14: 232417 | D14: 22-28.02 | E14: 286343091 | F14: 72806 | G14: 22-28.02 | H14: 0 | I14: 26 | J14: 46081 | K14: 9
B15: 286459024 | C15: 1243 | D15: 46082 | E15: 286489905 | F15: 5815 | G15: 46082
B16: 287708507 | C16: 74484 | D16: 01.03-08.03 | E16: 287655729 | F16: 252853 | G16: 01.03-08.03 | K16: 10
B17: 288763309 | C17: 304803 | D17: 08-15.03 | E17: 288777227 | F17: 178004 | G17: 08-15.03 | H17: 0 | I17: 46 | J17: 46091 | K17: 11
B18: 289700671 | C18: 48225 | D18: 15-22.03 | E18: 289749174 | F18: 468432 | G18: 15-22.03 | K18: 12
B19: 290703200 | C19: 88346 | D19: 22-29.03 | E19: 290753220 | F19: 464760 | G19: 22-29.03 | K19: 13
B20: 291680098 | C20: 7470 | D20: 29-31.03 | E20: 291680097 | F20: 197884 | G20: 29-31.03 | K20: 14
B21: 291826234 | C21: 2212 | D21: 1.04-05.04 | E21: 291909845 | F21: 303004 | G21: 01.04-05.04
B22: 292843081 | C22: 2405 | D22: 05.04-10.04 | E22: 292896526 | F22: 301236 | G22: 05.10-12.04 | K22: 15
B23: 293929962 | C23: 43580 | D23: 12-19.04 | E23: 293877308 | F23: 287584 | G23: 12-19.04 | K23: 16
B24: 294860190 | C24: 6217 | D24: 19-26.04 | E24: 294949927 | F24: 172288 | G24: 19-26.04 | H24: 0 | I24: 215420 | J24: 22-26.04 | K24: 17
H39: .

Sheet Сводная_план
B2: Период | E2: Дата поступления дс | F2: Итого к перечислению на счет, руб | G2: шт. | J2: ВБ реализовал товар (выручка с СПП) | M2: Выручка до вычета комиссии ВБ | P2: Себестоимость продаж | Q2: Логистика WB | R2: Комиссия WB | S2: Хранение WB | T2: Платная приемка WB | U2: Штрафы WB | V2: Прочие удержания WB | W2: Реклама БАЛАНС | X2: Реклама СЧЕТ | Y2: Реклама ПРОМОБОНУСЫ | Z2: Блогеры | AA2: Стоимость участия в программе лояльности | AB2: Сумма удержанная за начисленные баллы программы лояльности | AC2: Налог | AD2: Прочие поступления WB | AE2: Прибыль до вычета налогов | AF2: Прибыль после вычета налогов | AG2: Итог месяц | AH2: % Cебестоимости | AI2: Маржинальность, % | AJ2: Рентабельность, % | AK2: Доля рекламы, %
B3: Месяц | C3: Даты | D3: Нед | G3: Заказы | H3: Продажи | I3: Возвраты | J3: Продажи | K3: Возвраты | L3: Общая | M3: Продажи | N3: Возвраты | O3: Общая
B4: Декабрь очки | C4: 29-31.12 | D4: 1 | F4: =IFERROR(O4-SUM(Q4:W4)+AD4,0) -> 0 | AG4: =SUM(AF4:AF5) -> 0 | AH4: =P4/O4 -> #DIV/0! | AI4: =AF4/P4 -> #DIV/0! | AJ4: =AF4/O4 -> #DIV/0! | AK4: =(W4+X4+Z4)/O4 -> #DIV/0!
B5: Декабрь туники | C5: 29-31.12 | D5: 1 | F5: =IFERROR(O5-SUM(Q5:W5)+AD5,0) -> 0 | AH5: =P5/O5 -> #DIV/0! | AI5: =AF5/P5 -> #DIV/0! | AJ5: =AF5/O5 -> #DIV/0! | AK5: =(W5+X5+Z5)/O5 -> #DIV/0!
B6: Январь очки | C6: 01.01-01.02 | D6: 1-5 | F6: =IFERROR(O6-SUM(Q6:W6)+AD6,0) -> 0 | AG6: =SUM(AF6:AF8) -> 0 | AH6: =P6/O6 -> #DIV/0! | AI6: =AF6/P6 -> #DIV/0! | AJ6: =AF6/O6 -> #DIV/0! | AK6: =(W6+X6+Z6)/O6 -> #DIV/0!
B7: Январь туники | C7: 01.01-01.02 | D7: 1-5 | F7: =IFERROR(O7-SUM(Q7:W7)+AD7,0) -> 0 | AH7: =P7/O7 -> #DIV/0! | AI7: =AF7/P7 -> #DIV/0! | AJ7: =AF7/O7 -> #DIV/0! | AK7: =(W7+X7+Z7)/O7 -> #DIV/0!
B8: Январь шапки | C8: 01.01-01.02 | D8: 1-5 | F8: =IFERROR(O8-SUM(Q8:W8)+AD8,0) -> 0 | AH8: =P8/O8 -> #DIV/0! | AI8: =AF8/P8 -> #DIV/0! | AJ8: =AF8/O8 -> #DIV/0! | AK8: =(W8+X8+Z8)/O8 -> #DIV/0!
B9: Февраль 1 очки | C9: 02-08.02 | D9: 6 | F9: =IFERROR(O9-SUM(Q9:W9)+AD9,0) -> 0 | AG9: =SUM(AF9:AF16) -> 0 | AH9: =P9/O9 -> #DIV/0! | AI9: =AF9/P9 -> #DIV/0! | AJ9: =AF9/O9 -> #DIV/0! | AK9: =(W9+X9+Z9)/O9 -> #DIV/0!
B10: Февраль 1 туники | C10: 02-08.02 | D10: 6 | F10: =IFERROR(O10-SUM(Q10:W10)+AD10,0) -> 0 | AH10: =P10/O10 -> #DIV/0! | AI10: =AF10/P10 -> #DIV/0! | AJ10: =AF10/O10 -> #DIV/0! | AK10: =(W10+X10+Z10)/O10 -> #DIV/0!
B11: Февраль 2 очки | C11: 09-15.02 | D11: 7 | F11: =IFERROR(O11-SUM(Q11:W11)+AD11,0) -> 0 | AH11: =P11/O11 -> #DIV/0! | AI11: =AF11/P11 -> #DIV/0! | AJ11: =AF11/O11 -> #DIV/0! | AK11: =(W11+X11+Z11)/O11 -> #DIV/0!
B12: Февраль 2 туники | C12: 09-15.02 | D12: 7 | F12: =IFERROR(O12-SUM(Q12:W12)+AD12,0) -> 0 | AH12: =P12/O12 -> #DIV/0! | AI12: =AF12/P12 -> #DIV/0! | AJ12: =AF12/O12 -> #DIV/0! | AK12: =(W12+X12+Z12)/O12 -> #DIV/0!
B13: Февраль 3 очки | C13: 16-22.02 | D13: 8 | F13: =IFERROR(O13-SUM(Q13:W13)+AD13,0) -> 0 | AH13: =P13/O13 -> #DIV/0! | AI13: =AF13/P13 -> #DIV/0! | AJ13: =AF13/O13 -> #DIV/0! | AK13: =(W13+X13+Z13)/O13 -> #DIV/0!
B14: Февраль 3 туники | C14: 16-22.02 | D14: 8 | F14: =IFERROR(O14-SUM(Q14:W14)+AD14,0) -> 0 | AH14: =P14/O14 -> #DIV/0! | AI14: =AF14/P14 -> #DIV/0! | AJ14: =AF14/O14 -> #DIV/0! | AK14: =(W14+X14+Z14)/O14 -> #DIV/0!
B15: Февраль 4 очки | C15: 23.02-01.03 | D15: 9 | F15: =IFERROR(O15-SUM(Q15:W15)+AD15,0) -> 0 | AH15: =P15/O15 -> #DIV/0! | AI15: =AF15/P15 -> #DIV/0! | AJ15: =AF15/O15 -> #DIV/0! | AK15: =(W15+X15+Z15)/O15 -> #DIV/0!
B16: Февраль 4 прочее | C16: 23.02-01.03 | D16: 9 | F16: =IFERROR(O16-SUM(Q16:W16)+AD16,0) -> 0 | AH16: =P16/O16 -> #DIV/0! | AI16: =AF16/P16 -> #DIV/0! | AJ16: =AF16/O16 -> #DIV/0! | AK16: =(W16+X16+Z16)/O16 -> #DIV/0!
B17: Март 1 очки | C17: 02-08.03 | D17: 10 | F17: =IFERROR(O17-SUM(Q17:W17)+AD17,0) -> 0 | AG17: =SUM(AF17:AF20) -> 0 | AH17: =P17/O17 -> #DIV/0! | AI17: =AF17/P17 -> #DIV/0! | AJ17: =AF17/O17 -> #DIV/0! | AK17: =(W17+X17+Z17)/O17 -> #DIV/0!
B18: Март 2 очки | C18: 09-15.03 | D18: 11 | F18: =IFERROR(O18-SUM(Q18:W18)+AD18,0) -> 0 | AH18: =P18/O18 -> #DIV/0! | AI18: =AF18/P18 -> #DIV/0! | AJ18: =AF18/O18 -> #DIV/0! | AK18: =(W18+X18+Z18)/O18 -> #DIV/0!
B19: Март 3 очки | C19: 16-22.03 | D19: 12 | F19: =IFERROR(O19-SUM(Q19:W19)+AD19,0) -> 0 | AH19: =P19/O19 -> #DIV/0! | AI19: =AF19/P19 -> #DIV/0! | AJ19: =AF19/O19 -> #DIV/0! | AK19: =(W19+X19+Z19)/O19 -> #DIV/0!
B20: Март 4 очки | C20: 23-29.03 | D20: 13 | F20: =IFERROR(O20-SUM(Q20:W20)+AD20,0) -> 0 | AH20: =P20/O20 -> #DIV/0! | AI20: =AF20/P20 -> #DIV/0! | AJ20: =AF20/O20 -> #DIV/0! | AK20: =(W20+X20+Z20)/O20 -> #DIV/0!
B21: Апрель 1 очки | C21: 30.03-05.04 | D21: 14 | F21: =IFERROR(O21-SUM(Q21:W21)-AA21-AB21+AD21,0) -> 2248396 | G21: ='Юнит 14'!N$125 -> 4971 | H21: ='Юнит 14'!S$125 -> 2810 | I21: ='Юнит 14'!T$125 -> -71 | J21: ='Юнит 14'!V$125 -> 2849625.8 | K21: ='Юнит 14'!W$125 -> -71864.03 | L21: =IFERROR(J21+K21,0) -> 2777761.8 | M21: ='Юнит 14'!Y$125 -> 4320373.6 | N21: ='Юнит 14'!Z$125 -> -108465.8 | O21: =IFERROR(M21+N21,0) -> 4211907.8 | P21: ='Юнит 14'!AD$125 -> 339512.76 | Q21: ='Юнит 14'!AG$125 -> 363484.23 | R21: ='Юнит 14'!AE$125 -> 1585688.2 | S21: ='Юнит 14'!AL$125 -> 6774.7746 | U21: ='Юнит 14'!AM$125 -> 950 | V21: 702.72 | W21: ='Юнит 14'!AH$125 -> 4494 | X21: ='Юнит 14'!AI$125 -> 455354 | Z21: ='Юнит 14'!AK$125 -> 0 | AA21: 128.9 | AB21: 1289 | AC21: ='Юнит 14'!AN$125 -> 158610.2 | AE21: =O21-SUM(P21:AB21)+AD21 -> 1453529.2 | AF21: =O21-SUM(P21:AC21)+AD21 -> 1294919 | AH21: =P21/O21 -> 0.080607833 | AI21: =AF21/P21 -> 3.8140511 | AJ21: =AF21/O21 -> 0.30744239 | AK21: =(W21+X21+Z21)/O21 -> 0.10917808
B22: Апрель 2 очки | C22: 06-12.04 | D22: 15 | F22: =IFERROR(O22-SUM(Q22:W22)-AA22-AB22+AD22,0) -> 1600934.5 | G22: ='Юнит 15'!N$125 -> 3297 | H22: ='Юнит 15'!S$125 -> 2059 | I22: ='Юнит 15'!T$125 -> -47 | J22: ='Юнит 15'!V$125 -> 2106763.1 | K22: ='Юнит 15'!W$125 -> -48891.37 | L22: =IFERROR(J22+K22,0) -> 2057871.7 | M22: ='Юнит 15'!Y$125 -> 3166314.9 | N22: ='Юнит 15'!Z$125 -> -74091.17 | O22: =IFERROR(M22+N22,0) -> 3092223.7 | P22: ='Юнит 15'!AD$125 -> 248851.65 | Q22: ='Юнит 15'!AG$125 -> 274874.64 | R22: ='Юнит 15'!AE$125 -> 1169082.7 | S22: ='Юнит 15'!AL$125 -> 7404.9464 | U22: ='Юнит 15'!AM$125 -> 4873.98 | V22: 22990 | W22: ='Юнит 15'!AH$125 -> 2405 | X22: ='Юнит 15'!AI$125 -> 289210 | Z22: ='Юнит 15'!AK$125 -> 0 | AA22: 878 | AB22: 8780 | AC22: ='Юнит 15'!AN$125 -> 117504.47 | AE22: =O22-SUM(P22:AB22)+AD22 -> 1062872.9 | AF22: =O22-SUM(P22:AC22)+AD22 -> 945368.38 | AH22: =P22/O22 -> 0.080476599 | AI22: =AF22/P22 -> 3.7989235 | AJ22: =AF22/O22 -> 0.30572444 | AK22: =(W22+X22+Z22)/O22 -> 0.094305918
B23: Апрель 3 очки | C23: 13-19.04 | D23: 16 | F23: =IFERROR(O23-SUM(Q23:W23)-AA23-AB23+AD23,0) -> 1437469 | G23: ='Юнит 16'!N$126 -> 3224 | H23: ='Юнит 16'!S$126 -> 1892 | I23: ='Юнит 16'!T$126 -> -41 | J23: ='Юнит 16'!V$126 -> 1903067.3 | K23: ='Юнит 16'!W$126 -> -40767.59 | L23: =IFERROR(J23+K23,0) -> 1862299.7 | M23: ='Юнит 16'!Y$126 -> 2844861.5 | N23: ='Юнит 16'!Z$126 -> -60944.33 | O23: =IFERROR(M23+N23,0) -> 2783917.2 | P23: ='Юнит 16'!AD$126 -> 228955.77 | Q23: ='Юнит 16'!AG$126 -> 234083.09 | R23: ='Юнит 16'!AE$126 -> 1050005.8 | S23: ='Юнит 16'!AL$126 -> 9009.0466 | U23: ='Юнит 16'!AM$126 -> 2269 | W23: ='Юнит 16'!AH$126 -> 41816 | X23: ='Юнит 16'!AI$126 -> 275395 | Z23: ='Юнит 16'!AK$126 -> 0 | AA23: 842.3 | AB23: 8423 | AC23: ='Юнит 16'!AN$126 -> 106337.31 | AE23: =O23-SUM(P23:AB23)+AD23 -> 933118.2 | AF23: =O23-SUM(P23:AC23)+AD23 -> 826780.89 | AH23: =P23/O23 -> 0.082242306 | AI23: =AF23/P23 -> 3.6110944 | AJ23: =AF23/O23 -> 0.29698473 | AK23: =(W23+X23+Z23)/O23 -> 0.11394412
B24: Апрель 4 очки | C24: 20-26.04 | D24: 17 | F24: =IFERROR(O24-SUM(Q24:W24)-AA24-AB24+AD24,0) -> 1205095.8 | G24: ='Юнит 17'!N$126 -> 2848 | H24: ='Юнит 17'!S$126 -> 1645 | I24: ='Юнит 17'!T$126 -> -32 | J24: ='Юнит 17'!V$126 -> 1612009.3 | K24: ='Юнит 17'!W$126 -> -33188 | L24: =IFERROR(J24+K24,0) -> 1578821.3 | M24: ='Юнит 17'!Y$126 -> 2353906.9 | N24: ='Юнит 17'!Z$126 -> -49562.13 | O24: =IFERROR(M24+N24,0) -> 2304344.8 | P24: ='Юнит 17'!AD$126 -> 199750.44 | Q24: ='Юнит 17'!AG$126 -> 210197.66 | R24: ='Юнит 17'!AE$126 -> 872396.09 | S24: ='Юнит 17'!AL$126 -> 8583.5482 | U24: ='Юнит 17'!AM$126 -> 1310 | W24: ='Юнит 17'!AH$126 -> 5159 | X24: ='Юнит 17'!AI$126 -> 163766 | Y24: ='Юнит 17'!AJ126 -> 212040 | Z24: ='Юнит 17'!AK$126 -> 0 | AA24: 145.7 | AB24: 1457 | AC24: ='Юнит 17'!AN$126 -> 90150.697 | AE24: =O24-SUM(P24:AB24)+AD24 -> 629539.36 | AF24: =O24-SUM(P24:AC24)+AD24 -> 539388.66 | AH24: =P24/O24 -> 0.086684267 | AI24: =AF24/P24 -> 2.7003128 | AJ24: =AF24/O24 -> 0.23407463 | AK24: =(W24+X24+Z24)/O24 -> 0.073307172
B29: Итого | F29: =SUM(F4:F28) -> 6491895.3 | G29: =SUM(G4:G28) -> 14340 | H29: =SUM(H4:H28) -> 8406 | I29: =SUM(I4:I28) -> -191 | J29: =SUM(J4:J28) -> 8471465.4 | K29: =SUM(K4:K28) -> -194710.99 | L29: =SUM(L4:L28) -> 8276754.5 | M29: =SUM(M4:M28) -> 12685457 | ... X29: =SUM(X4:X28) -> 1183725 | Z29: =SUM(Z4:Z28) -> 0 | AC29: =SUM(AC4:AC28) -> 472602.68 | AD29: =SUM(AD4:AD28) -> 0 | AE29: =SUM(AE4:AE28) -> 4079059.6 | AF29: =SUM(AF4:AF28) -> 3606457 | AG29: =SUM(AG4:AG28) -> 0 | AH29: =P29/O29 -> 0.082072169 | AI29: =AF29/P29 -> 3.5459258 | AJ29: =AF29/O29 -> 0.29102182 | AK29: =(W29+X29+Z29)/O29 -> 0.099867632
M30: % от выручки за весь период
N31: =-N29/M29 -> 0.023102316 | P31: =P29/$O$29 -> 0.082072169 | Q31: =Q29/$O$29 -> 0.087363238 | R31: =R29/$O$29 -> 0.37742287 | S31: =S29/$O$29 -> 0.0025638563 | T31: =T29/$O$29 -> 0 | U31: =U29/$O$29 -> 0.00075877029 | V31: =V29/$O$29 -> 0.001911876 | W31: =W29/$O$29 -> 0.0043473442 | X31: =X29/$O$29 -> 0.095520288 | Z31: =Z29/$O$29 -> 0 | AC31: =AC29/$O$29 -> 0.038136513 | AG31: =AF29/P29 -> 3.5459258 | AH31: Маржинальность, %
W32: =(W29+X29)/O29 -> 0.099867632 | AG32: =AF29/O29 -> 0.29102182 | AH32: Рентабельность, %
B35: 14 нед | W35: =W21/O21 -> 0.0010669749 | X35: =X21/O21 -> 0.1081111
B36: 15 нед | W36: =W22/O22 -> 0.00077775743 | X36: =X22/O22 -> 0.093528161
B37: 16 нед | W37: =W23/O23 -> 0.015020562 | X37: =X23/O23 -> 0.09892356
B38: 17 нед | W38: =W24/O24 -> 0.0022388143 | X38: =X24/O24 -> 0.071068357 | Y38: =Y24/O24 -> 0.092017479

Sheet Сводная
B2: Период | E2: Дата поступления дс | F2: Итого к перечислению на счет, руб | G2: шт. | J2: ВБ реализовал товар (выручка с СПП) | M2: Выручка до вычета комиссии ВБ | P2: Себестоимость продаж | Q2: Логистика WB | R2: Комиссия WB | S2: Хранение WB | T2: Платная приемка WB | U2: Штрафы WB | V2: Прочие удержания WB | W2: Реклама БАЛАНС | X2: Реклама СЧЕТ | Y2: Реклама ПРОМОБОНУСЫ | Z2: Блогеры | AA2: Стоимость участия в программе лояльности | AB2: Сумма удержанная за начисленные баллы программы лояльности | AC2: Налог | AD2: Прочие поступления WB | AE2: Прибыль до вычета налогов | AF2: Прибыль после вычета налогов | AG2: Итог месяц | AH2: % Cебестоимости | AI2: Маржинальность, % | AJ2: Рентабельность, % | AK2: Доля рекламы, %
B3: Месяц | C3: Даты | D3: Нед | G3: Заказы | H3: Продажи | I3: Возвраты | J3: Продажи | K3: Возвраты | L3: Общая | M3: Продажи | N3: Возвраты | O3: Общая
B4: Декабрь очки | C4: 29-31.12 | D4: 1 | F4: =IFERROR(O4-SUM(Q4:W4)+AD4,0) -> 62313.298 | G4: =ДЕКАБРЬ!N100 -> 129 | H4: =ДЕКАБРЬ!S100 -> 127 | I4: =ДЕКАБРЬ!T100 -> -5 | J4: =ДЕКАБРЬ!V100 -> 118047.57 | K4: =ДЕКАБРЬ!W100 -> -6409 | L4: =IFERROR(J4+K4,0) -> 111638.57 | M4: =ДЕКАБРЬ!Y100 -> 138964.57 | N4: =ДЕКАБРЬ!Z100 -> -7526 | O4: =IFERROR(M4+N4,0) -> 131438.57 | P4: =ДЕКАБРЬ!AD100 -> 15240.45 | Q4: =ДЕКАБРЬ!AG100 -> 17381.1 | R4: =ДЕКАБРЬ!AE100 -> 48126.54 | S4: =ДЕКАБРЬ!AL100 -> 3615.9322 | T4: 1.7 | U4: =ДЕКАБРЬ!AM100 -> 0 | W4: =ДЕКАБРЬ!AH100 -> 0 | X4: =ДЕКАБРЬ!AI100 -> 0 | Z4: =ДЕКАБРЬ!AK100 -> 0 | AC4: =ДЕКАБРЬ!AN100 -> 6067.24 | AE4: =O4-SUM(P4:Z4)+AD4 -> 47072.848 | AF4: =O4-SUM(P4:AC4)+AD4 -> 41005.608 | AG4: =SUM(AF4:AF5) -> 41005.32 | AH4: =P4/O4 -> 0.11595112 | AI4: =AF4/P4 -> 2.6905772 | AJ4: =AF4/O4 -> 0.31197546 | AK4: =(W4+X4+Z4)/O4 -> 0
B5: Декабрь туники | C5: 29-31.12 | D5: 1 | F5: =IFERROR(O5-SUM(Q5:W5)+AD5,0) -> -0.28775523 | G5: =ДЕКАБРЬ!N108 -> 0 | H5: =ДЕКАБРЬ!S108 -> 0 | I5: =ДЕКАБРЬ!T108 -> 0 | J5: =ДЕКАБРЬ!V108 -> 0 | K5: =ДЕКАБРЬ!W108 -> 0 | L5: =IFERROR(J5+K5,0) -> 0 | M5: =ДЕКАБРЬ!Y108 -> 0 | N5: =ДЕКАБРЬ!Z108 -> 0 | O5: =IFERROR(M5+N5,0) -> 0 | P5: =ДЕКАБРЬ!AD108 -> 0 | Q5: =ДЕКАБРЬ!AG108 -> 0 | R5: =ДЕКАБРЬ!AE108 -> 0 | S5: =ДЕКАБРЬ!AL108 -> 0.28775523 | U5: =ДЕКАБРЬ!AM108 -> 0 | W5: =ДЕКАБРЬ!AH108 -> 0 | X5: =ДЕКАБРЬ!AI108 -> 0 | Z5: =ДЕКАБРЬ!AK108 -> 0 | AC5: =ДЕКАБРЬ!AN108 -> 0 | AE5: =O5-SUM(P5:Z5)+AD5 -> -0.28775523 | AF5: =O5-SUM(P5:AC5)+AD5 -> -0.28775523 | AH5: =P5/O5 -> #DIV/0! | AI5: =AF5/P5 -> #DIV/0! | AJ5: =AF5/O5 -> #DIV/0! | AK5: =(W5+X5+Z5)/O5 -> #DIV/0!
B6: Январь очки | C6: 01.01-01.02 | D6: 1-5 | F6: =IFERROR(O6-SUM(Q6:W6)+AD6,0) -> 955718.86 | G6: =ЯНВАРЬ!N100 -> 4961 | H6: =ЯНВАРЬ!S100 -> 2362 | I6: =ЯНВАРЬ!T100 -> -53 | J6: =ЯНВАРЬ!V100 -> 1728382.8 | K6: =ЯНВАРЬ!W100 -> -44657.88 | L6: =IFERROR(J6+K6,0) -> 1683724.9 | M6: =ЯНВАРЬ!Y100 -> 2303342.1 | N6: =ЯНВАРЬ!Z100 -> -58267.04 | O6: =IFERROR(M6+N6,0) -> 2245075 | P6: =ЯНВАРЬ!AD100 -> 292876.64 | Q6: =ЯНВАРЬ!AG100 -> 276475.65 | R6: =ЯНВАРЬ!AE100 -> 833669.77 | S6: =ЯНВАРЬ!AL100 -> 40333.14 | U6: =ЯНВАРЬ!AM100 -> 0 | V6: 25431.6 | W6: =ЯНВАРЬ!AH100 -> 113446 | X6: =ЯНВАРЬ!AI100 -> 404487 | Z6: =ЯНВАРЬ!AK100 -> 0 | AC6: =ЯНВАРЬ!AN100 -> 95827.42 | AE6: =O6-SUM(P6:Z6)+AD6 -> 258355.22 | AF6: =O6-SUM(P6:AC6)+AD6 -> 162527.8 | AG6: =SUM(AF6:AF8) -> 162168.41 | AH6: =P6/O6 -> 0.13045294 | AI6: =AF6/P6 -> 0.55493603 | AJ6: =AF6/O6 -> 0.072393037 | AK6: =(W6+X6+Z6)/O6 -> 0.23069741
B7: Январь туники | C7: 01.01-01.02 | D7: 1-5 | F7: =IFERROR(O7-SUM(Q7:W7)+AD7,0) -> -186.4297 | G7: =ЯНВАРЬ!N108 -> 1 | H7: =ЯНВАРЬ!S108 -> 0 | I7: =ЯНВАРЬ!T108 -> 0 | J7: =ЯНВАРЬ!V108 -> 0 | K7: =ЯНВАРЬ!W108 -> 0 | L7: =IFERROR(J7+K7,0) -> 0 | M7: =ЯНВАРЬ!Y108 -> 0 | N7: =ЯНВАРЬ!Z108 -> 0 | O7: =IFERROR(M7+N7,0) -> 0 | P7: =ЯНВАРЬ!AD108 -> 0 | Q7: =ЯНВАРЬ!AG108 -> 183.22 | R7: =ЯНВАРЬ!AE108 -> 0 | S7: =ЯНВАРЬ!AL108 -> 3.209704 | U7: =ЯНВАРЬ!AM108 -> 0 | W7: =ЯНВАРЬ!AH108 -> 0 | X7: =ЯНВАРЬ!AI108 -> 0 | Z7: =ЯНВАРЬ!AK108 -> 0 | AC7: =ЯНВАРЬ!AN108 -> 0 | AE7: =O7-SUM(P7:Z7)+AD7 -> -186.4297 | AF7: =O7-SUM(P7:AC7)+AD7 -> -186.4297 | AH7: =P7/O7 -> #DIV/0! | AI7: =AF7/P7 -> #DIV/0! | AJ7: =AF7/O7 -> #DIV/0! | AK7: =(W7+X7+Z7)/O7 -> #DIV/0!
B8: Январь шапки | C8: 01.01-01.02 | D8: 1-5 | F8: =IFERROR(O8-SUM(Q8:W8)+AD8,0) -> -172.96 | G8: =ЯНВАРЬ!N119 -> 0 | H8: =ЯНВАРЬ!S119 -> 0 | I8: =ЯНВАРЬ!T119 -> 0 | J8: =ЯНВАРЬ!V119 -> 0 | K8: =ЯНВАРЬ!W119 -> 0 | L8: =IFERROR(J8+K8,0) -> 0 | M8: =ЯНВАРЬ!Y119 -> 0 | N8: =ЯНВАРЬ!Z119 -> 0 | O8: =IFERROR(M8+N8,0) -> 0 | P8: =ЯНВАРЬ!AD119 -> 0 | Q8: =ЯНВАРЬ!AG119 -> 172.96 | R8: =ЯНВАРЬ!AE119 -> 0 | S8: =ЯНВАРЬ!AL119 -> 0 | U8: =ЯНВАРЬ!AM119 -> 0 | W8: =ЯНВАРЬ!AH119 -> 0 | X8: =ЯНВАРЬ!AI119 -> 0 | Z8: =ЯНВАРЬ!AK119 -> 0 | AC8: =ЯНВАРЬ!AN119 -> 0 | AE8: =O8-SUM(P8:Z8)+AD8 -> -172.96 | AF8: =O8-SUM(P8:AC8)+AD8 -> -172.96 | AH8: =P8/O8 -> #DIV/0! | AI8: =AF8/P8 -> #DIV/0! | AJ8: =AF8/O8 -> #DIV/0! | AK8: =(W8+X8+Z8)/O8 -> #DIV/0!
B9: Февраль 1 очки | C9: 02-08.02 | D9: 6 | F9: =IFERROR(O9-SUM(Q9:W9)+AD9,0) -> 539419.19 | G9: ='Юнит 6'!N105 -> 2829 | H9: ='Юнит 6'!S105 -> 1418 | I9: ='Юнит 6'!T105 -> -25 | J9: ='Юнит 6'!V105 -> 894889.93 | K9: ='Юнит 6'!W105 -> -16453.5 | L9: =IFERROR(J9+K9,0) -> 878436.43 | M9: ='Юнит 6'!Y105 -> 1357375 | N9: ='Юнит 6'!Z105 -> -24887.06 | O9: =IFERROR(M9+N9,0) -> 1332487.9 | P9: ='Юнит 6'!AD105 -> 175437.39 | Q9: ='Юнит 6'!AG105 -> 153486.12 | R9: ='Юнит 6'!AE105 -> 495216.11 | S9: ='Юнит 6'!AL105 -> 8160.06 | U9: ='Юнит 6'!AM105 -> 0 | V9: =5797.44+18990 -> 24787.44 | W9: ='Юнит 6'!AH105 -> 111419 | X9: ='Юнит 6'!AI105 -> 126688 | Z9: ='Юнит 6'!AK105 -> 0 | AC9: =304652.46*O9/SUM(O$9:O$16) -> 47907.536 | AE9: =O9-SUM(P9:Z9)+AD9 -> 237293.8 | AF9: =O9-SUM(P9:AC9)+AD9 -> 189386.26 | AG9: =SUM(AF9:AF16) -> 1876556.2 | AH9: =P9/O9 -> 0.13166152 | AI9: =AF9/P9 -> 1.0795091 | AJ9: =AF9/O9 -> 0.14212982 | AK9: =(W9+X9+Z9)/O9 -> 0.17869355
B10: Февраль 1 туники | C10: 02-08.02 | D10: 6 | F10: =IFERROR(O10-SUM(Q10:W10)+AD10,0) -> 0 | G10: ='Юнит 6'!N113 -> 1 | H10: ='Юнит 6'!S113 -> 0 | I10: ='Юнит 6'!T113 -> 0 | J10: ='Юнит 6'!V113 -> 0 | K10: ='Юнит 6'!W113 -> 0 | L10: =IFERROR(J10+K10,0) -> 0 | M10: ='Юнит 6'!Y113 -> 0 | N10: ='Юнит 6'!Z113 -> 0 | O10: =IFERROR(M10+N10,0) -> 0 | P10: ='Юнит 6'!AD113 -> 0 | Q10: ='Юнит 6'!AG113 -> 0 | R10: ='Юнит 6'!AE113 -> 0 | S10: ='Юнит 6'!AL113 -> 0 | U10: ='Юнит 6'!AM113 -> 0 | W10: ='Юнит 6'!AH113 -> 0 | X10: ='Юнит 6'!AI113 -> 0 | Z10: ='Юнит 6'!AK113 -> 0 | AC10: =304652.46*O10/SUM(O$9:O$16) -> 0 | AE10: =O10-SUM(P10:Z10)+AD10 -> 0 | AF10: =O10-SUM(P10:AC10)+AD10 -> 0 | AH10: =P10/O10 -> #DIV/0! | AI10: =AF10/P10 -> #DIV/0! | AJ10: =AF10/O10 -> #DIV/0! | AK10: =(W10+X10+Z10)/O10 -> #DIV/0!
B11: Февраль 2 очки | C11: 09-15.02 | D11: 7 | F11: =IFERROR(O11-SUM(Q11:W11)+AD11,0) -> 811496.75 | G11: ='Юнит 7'!N105 -> 3325 | H11: ='Юнит 7'!S105 -> 1882 | I11: ='Юнит 7'!T105 -> -40 | J11: ='Юнит 7'!V105 -> 1236743.8 | K11: ='Юнит 7'!W105 -> -26582.27 | L11: =IFERROR(J11+K11,0) -> 1210161.6 | M11: ='Юнит 7'!Y105 -> 1920260.7 | N11: ='Юнит 7'!Z105 -> -41194.47 | O11: =IFERROR(M11+N11,0) -> 1879066.2 | P11: ='Юнит 7'!AD105 -> 230374.86 | Q11: ='Юнит 7'!AG105 -> 212380.68 | R11: ='Юнит 7'!AE105 -> 695831.51 | S11: ='Юнит 7'!AL105 -> 8132.98 | T11: 30 | U11: ='Юнит 7'!AM105 -> 826 | V11: 4787.28 | W11: ='Юнит 7'!AH105 -> 145581 | X11: ='Юнит 7'!AI105 -> 138670 | Z11: ='Юнит 7'!AK105 -> 0 | AC11: =304652.46*O11/SUM(O$9:O$16) -> 67558.911 | AE11: =O11-SUM(P11:Z11)+AD11 -> 442451.89 | AF11: =O11-SUM(P11:AC11)+AD11 -> 374892.98 | AH11: =P11/O11 -> 0.12260072 | AI11: =AF11/P11 -> 1.6273172 | AJ11: =AF11/O11 -> 0.19951026 | AK11: =(W11+X11+Z11)/O11 -> 0.15127248
B12: Февраль 2 туники | C12: 09-15.02 | D12: 7 | F12: =IFERROR(O12-SUM(Q12:W12)+AD12,0) -> 1191.57 | G12: ='Юнит 7'!N113 -> 0 | H12: ='Юнит 7'!S113 -> 1 | I12: ='Юнит 7'!T113 -> 0 | J12: ='Юнит 7'!V113 -> 1407 | K12: ='Юнит 7'!W113 -> 0 | L12: =IFERROR(J12+K12,0) -> 1407 | M12: ='Юнит 7'!Y113 -> 2079 | N12: ='Юнит 7'!Z113 -> 0 | O12: =IFERROR(M12+N12,0) -> 2079 | P12: ='Юнит 7'!AD113 -> 579.18 | Q12: ='Юнит 7'!AG113 -> 124.34 | R12: ='Юнит 7'!AE113 -> 763.09 | S12: ='Юнит 7'!AL113 -> 0 | U12: ='Юнит 7'!AM113 -> 0 | W12: ='Юнит 7'!AH113 -> 0 | X12: ='Юнит 7'!AI113 -> 0 | Z12: ='Юнит 7'!AK113 -> 0 | AC12: =304652.46*O12/SUM(O$9:O$16) -> 74.74722 | AE12: =O12-SUM(P12:Z12)+AD12 -> 612.39 | AF12: =O12-SUM(P12:AC12)+AD12 -> 537.64278 | AH12: =P12/O12 -> 0.27858586 | AI12: =AF12/P12 -> 0.92828271 | AJ12: =AF12/O12 -> 0.25860644 | AK12: =(W12+X12+Z12)/O12 -> 0
B13: Февраль 3 очки | C13: 16-22.02 | D13: 8 | F13: =IFERROR(O13-SUM(Q13:W13)+AD13,0) -> 1204943.2 | G13: ='Юнит 8'!N$105 -> 4413 | H13: ='Юнит 8'!S$105 -> 2295 | I13: ='Юнит 8'!T$105 -> -43 | J13: ='Юнит 8'!V$105 -> 1593380.1 | K13: ='Юнит 8'!W$105 -> -29254.63 | L13: =IFERROR(J13+K13,0) -> 1564125.5 | M13: ='Юнит 8'!Y$105 -> 2501418.9 | N13: ='Юнит 8'!Z$105 -> -47007.29 | O13: =IFERROR(M13+N13,0) -> 2454411.6 | P13: ='Юнит 8'!AD$105 -> 280478.83 | Q13: ='Юнит 8'!AG$105 -> 267875.33 | R13: ='Юнит 8'!AE$105 -> 918234.84 | S13: ='Юнит 8'!AL$105 -> 8623.9028 | U13: ='Юнит 8'!AM$105 -> 466 | V13: 3279.36 | W13: ='Юнит 8'!AH$105 -> 50989 | X13: ='Юнит 8'!AI$105 -> 265182 | Z13: ='Юнит 8'!AK$105 -> 0 | AC13: =304652.46*O13/SUM(O$9:O$16) -> 88244.562 | AE13: =O13-SUM(P13:Z13)+AD13 -> 659282.34 | AF13: =O13-SUM(P13:AC13)+AD13 -> 571037.78 | AH13: =P13/O13 -> 0.11427538 | AI13: =AF13/P13 -> 2.035939 | AJ13: =AF13/O13 -> 0.23265771 | AK13: =(W13+X13+Z13)/O13 -> 0.12881743
B14: Февраль 3 туники | C14: 16-22.02 | D14: 8 | F14: =IFERROR(O14-SUM(Q14:W14)+AD14,0) -> -0.86724686 | G14: ='Юнит 8'!N113 -> 0 | H14: ='Юнит 8'!S113 -> 0 | I14: ='Юнит 8'!T113 -> 0 | J14: ='Юнит 8'!V113 -> 0 | K14: ='Юнит 8'!W113 -> 0 | L14: =IFERROR(J14+K14,0) -> 0 | M14: ='Юнит 8'!Y113 -> 0 | N14: ='Юнит 8'!Z113 -> 0 | O14: =IFERROR(M14+N14,0) -> 0 | P14: ='Юнит 8'!AD113 -> 0 | Q14: ='Юнит 8'!AG113 -> 0 | R14: ='Юнит 8'!AE113 -> 0 | S14: ='Юнит 8'!AL113 -> 0.86724686 | U14: ='Юнит 8'!AM113 -> 0 | W14: ='Юнит 8'!AH113 -> 0 | X14: ='Юнит 8'!AI113 -> 0 | Z14: ='Юнит 8'!AK113 -> 0 | AC14: =304652.46*O14/SUM(O$9:O$16) -> 0 | AE14: =O14-SUM(P14:Z14)+AD14 -> -0.86724686 | AF14: =O14-SUM(P14:AC14)+AD14 -> -0.86724686 | AH14: =P14/O14 -> #DIV/0! | AI14: =AF14/P14 -> #DIV/0! | AJ14: =AF14/O14 -> #DIV/0! | AK14: =(W14+X14+Z14)/O14 -> #DIV/0!
B15: Февраль 4 очки | C15: 23.02-01.03 | D15: 9 | F15: =IFERROR(O15-SUM(Q15:W15)+AD15,0) -> 1208387.9 | G15: ='Юнит 9'!N$105 -> 3950 | H15: ='Юнит 9'!S$105 -> 2372 | I15: ='Юнит 9'!T$105 -> -63 | J15: ='Юнит 9'!V$105 -> 1818463.8 | K15: ='Юнит 9'!W$105 -> -46702.77 | L15: =IFERROR(J15+K15,0) -> 1771761 | M15: ='Юнит 9'!Y$105 -> 2879025.2 | N15: ='Юнит 9'!Z$105 -> -73544.64 | O15: =IFERROR(M15+N15,0) -> 2805480.6 | P15: ='Юнит 9'!AD$105 -> 288027.84 | Q15: ='Юнит 9'!AG$105 -> 299415.53 | R15: ='Юнит 9'!AE$105 -> 1051752.7 | S15: ='Юнит 9'!AL$105 -> 8471.4 | U15: ='Юнит 9'!AM$105 -> 1392.11 | V15: 2400.96 | W15: ='Юнит 9'!AH$105 -> 233660 | X15: ='Юнит 9'!AI$105 -> 78621 | Z15: ='Юнит 9'!AK$105 -> 0 | AC15: =304652.46*O15/SUM(O$9:O$16) -> 100866.7 | AE15: =O15-SUM(P15:Z15)+AD15 -> 841739.09 | AF15: =O15-SUM(P15:AC15)+AD15 -> 740872.39 | AH15: =P15/O15 -> 0.10266613 | AI15: =AF15/P15 -> 2.5722249 | AJ15: =AF15/O15 -> 0.26408038 | AK15: =(W15+X15+Z15)/O15 -> 0.11131105
B16: Февраль 4 прочее | C16: 23.02-01.03 | D16: 9 | F16: =IFERROR(O16-SUM(Q16:W16)+AD16,0) -> -170 | Q16: ='Юнит 9'!AG125 -> 170 | AC16: =304652.46*O16/SUM(O$9:O$16) -> 0 | AE16: =O16-SUM(P16:Z16)+AD16 -> -170 | AF16: =O16-SUM(P16:AC16)+AD16 -> -170 | AH16: =P16/O16 -> #DIV/0! | AI16: =AF16/P16 -> #DIV/0! | AJ16: =AF16/O16 -> #DIV/0! | AK16: =(W16+X16+Z16)/O16 -> #DIV/0!
B17: Март 1 очки | C17: 02-08.03 | D17: 10 | F17: =IFERROR(O17-SUM(Q17:W17)+AD17,0) -> 1238601.7 | G17: ='Юнит 10'!N$105 -> 3795 | H17: ='Юнит 10'!S$105 -> 2096 | I17: ='Юнит 10'!T$105 -> -53 | J17: ='Юнит 10'!V$105 -> 1702514.8 | K17: ='Юнит 10'!W$105 -> -41251 | L17: =IFERROR(J17+K17,0) -> 1661263.8 | M17: ='Юнит 10'!Y$105 -> 2657773.4 | N17: ='Юнит 10'!Z$105 -> -65375.4 | O17: =IFERROR(M17+N17,0) -> 2592398 | P17: ='Юнит 10'!AD$105 -> 254974.68 | Q17: ='Юнит 10'!AG$105 -> 270558.84 | R17: ='Юнит 10'!AE$105 -> 972977.25 | S17: ='Юнит 10'!AL$105 -> 11702.83 | U17: ='Юнит 10'!AM$105 -> 0 | V17: =1083.36+22990 -> 24073.36 | W17: ='Юнит 10'!AH$105 -> 74484 | X17: ='Юнит 10'!AI$105 -> 252853 | Z17: ='Юнит 10'!AK$105 -> 0 | AC17: =666212.62*O17/SUM(O$17:O$20) -> 94861.253 | AE17: =O17-SUM(P17:Z17)+AD17 -> 730774.06 | AF17: =O17-SUM(P17:AC17)+AD17 -> 635912.81 | AG17: =SUM(AF17:AF20) -> 5396896.8 | AH17: =P17/O17 -> 0.098354758 | AI17: =AF17/P17 -> 2.4940234 | AJ17: =AF17/O17 -> 0.24529906 | AK17: =(W17+X17+Z17)/O17 -> 0.12626803
B18: Март 2 очки | C18: 09-15.03 | D18: 11 | F18: =IFERROR(O18-SUM(Q18:W18)+AD18,0) -> 2101556.8 | G18: ='Юнит 11'!N$105 -> 8243 | H18: ='Юнит 11'!S$105 -> 3480 | I18: ='Юнит 11'!T$105 -> -60 | J18: ='Юнит 11'!V$105 -> 3014405.3 | K18: ='Юнит 11'!W$105 -> -49269.89 | L18: =IFERROR(J18+K18,0) -> 2965135.4 | M18: ='Юнит 11'!Y$105 -> 4668001.6 | N18: ='Юнит 11'!Z$105 -> -76772.74 | O18: =IFERROR(M18+N18,0) -> 4591228.8 | P18: ='Юнит 11'!AD$105 -> 424325.4 | Q18: ='Юнит 11'!AG$105 -> 445765.14 | R18: ='Юнит 11'!AE$105 -> 1726243.8 | S18: ='Юнит 11'!AL$105 -> 9729.77 | U18: ='Юнит 11'!AM$105 -> 1842 | V18: 1288.32 | W18: ='Юнит 11'!AH$105 -> 304803 | X18: ='Юнит 11'!AI$105 -> 178004 | Z18: ='Юнит 11'!AK$105 -> 0 | AC18: =666212.62*O18/SUM(O$17:O$20) -> 168002.64 | AE18: =O18-SUM(P18:Z18)+AD18 -> 1499227.4 | AF18: =O18-SUM(P18:AC18)+AD18 -> 1331224.8 | AH18: =P18/O18 -> 0.092420878 | AI18: =AF18/P18 -> 3.1372734 | AJ18: =AF18/O18 -> 0.28994956 | AK18: =(W18+X18+Z18)/O18 -> 0.10515856
B19: Март 3 очки | C19: 16-22.03 | D19: 12 | F19: =IFERROR(O19-SUM(Q19:W19)+AD19,0) -> 2992995 | G19: ='Юнит 12'!N$105 -> 6902 | H19: ='Юнит 12'!S$105 -> 4072 | I19: ='Юнит 12'!T$105 -> -94 | J19: ='Юнит 12'!V$105 -> 3910621.8 | K19: ='Юнит 12'!W$105 -> -85755 | L19: =IFERROR(J19+K19,0) -> 3824866.8 | M19: ='Юнит 12'!Y$105 -> 5914054.7 | N19: ='Юнит 12'!Z$105 -> -132706.71 | O19: =IFERROR(M19+N19,0) -> 5781348 | P19: ='Юнит 12'!AD$105 -> 494039.24 | Q19: ='Юнит 12'!AG$105 -> 557216.52 | R19: ='Юнит 12'!AE$105 -> 2176223 | S19: ='Юнит 12'!AL$105 -> 6558.48 | U19: ='Юнит 12'!AM$105 -> 130 | W19: ='Юнит 12'!AH$105 -> 48225 | X19: ='Юнит 12'!AI$105 -> 468432 | Z19: ='Юнит 12'!AK$105 -> 0 | AC19: =666212.62*O19/SUM(O$17:O$20) -> 211551.59 | AE19: =O19-SUM(P19:Z19)+AD19 -> 2030523.7 | AF19: =O19-SUM(P19:AC19)+AD19 -> 1818972.1 | AH19: =P19/O19 -> 0.085453988 | AI19: =AF19/P19 -> 3.6818374 | AJ19: =AF19/O19 -> 0.31462768 | AK19: =(W19+X19+Z19)/O19 -> 0.089366182
B20: Март 4 очки | C20: 23-29.03 | D20: 13 | F20: =IFERROR(O20-SUM(Q20:W20)+AD20,0) -> 2696708.9 | G20: ='Юнит 13'!N$105 -> 6707 | H20: ='Юнит 13'!S$105 -> 3565 | I20: ='Юнит 13'!T$105 -> -97 | J20: ='Юнит 13'!V$105 -> 3582763.6 | K20: ='Юнит 13'!W$105 -> -97407.33 | L20: =IFERROR(J20+K20,0) -> 3485356.2 | M20: ='Юнит 13'!Y$105 -> 5387638.1 | N20: ='Юнит 13'!Z$105 -> -146145.86 | O20: =IFERROR(M20+N20,0) -> 5241492.2 | P20: ='Юнит 13'!AD$105 -> 429364.71 | Q20: ='Юнит 13'!AG$105 -> 472771.32 | R20: ='Юнит 13'!AE$105 -> 1975944.8 | S20: ='Юнит 13'!AL$105 -> 8091.54 | U20: ='Юнит 13'!AM$105 -> -1073 | V20: 702.72 | W20: ='Юнит 13'!AH$105 -> 88346 | X20: ='Юнит 13'!AI$105 -> 464760 | Z20: ='Юнит 13'!AK$105 -> 0 | AC20: =666212.62*O20/SUM(O$17:O$20) -> 191797.14 | AE20: =O20-SUM(P20:Z20)+AD20 -> 1802584.2 | AF20: =O20-SUM(P20:AC20)+AD20 -> 1610787.1 | AH20: =P20/O20 -> 0.081916502 | AI20: =AF20/P20 -> 3.751559 | AJ20: =AF20/O20 -> 0.30731459 | AK20: =(W20+X20+Z20)/O20 -> 0.10552453
B21: Апрель 1 очки | C21: 30.03-05.04 | D21: 14 | F21: =IFERROR(O21-SUM(Q21:W21)-AA21-AB21+AD21,0) -> 2335595.7 | G21: ='Юнит 14'!N$105 -> 5475 | H21: ='Юнит 14'!S$105 -> 3012 | I21: ='Юнит 14'!T$105 -> -85 | J21: ='Юнит 14'!V$105 -> 3007932.1 | K21: ='Юнит 14'!W$105 -> -82412.17 | L21: =IFERROR(J21+K21,0) -> 2925519.9 | M21: ='Юнит 14'!Y$105 -> 4561244.2 | N21: ='Юнит 14'!Z$105 -> -124396.78 | O21: =IFERROR(M21+N21,0) -> 4436847.4 | P21: ='Юнит 14'!AD$105 -> 363233.15 | Q21: ='Юнит 14'!AG$105 -> 409675.01 | R21: ='Юнит 14'!AE$105 -> 1670278 | S21: ='Юнит 14'!AL$105 -> 8536.1 | U21: ='Юнит 14'!AM$105 -> 960 | V21: 702.72 | W21: ='Юнит 14'!AH$105 -> 9682 | X21: ='Юнит 14'!AI$105 -> 500888 | Z21: ='Юнит 14'!AK$105 -> 0 | AA21: 128.9 | AB21: 1289 | AC21: ='Юнит 14'!AN$105 -> 167047.19 | AE21: =O21-SUM(P21:AB21)+AD21 -> 1471474.5 | AF21: =O21-SUM(P21:AC21)+AD21 -> 1304427.3 | AG21: =SUM(AF21:AF25) -> 3664800.2 | AH21: =P21/O21 -> 0.081867397 | AI21: =AF21/P21 -> 3.5911572 | AJ21: =AF21/O21 -> 0.29399869 | AK21: =(W21+X21+Z21)/O21 -> 0.11507495
B22: Апрель 2 очки | C22: 06-12.04 | D22: 15 | F22: =IFERROR(O22-SUM(Q22:W22)-AA22-AB22+AD22,0) -> 1648542.8 | G22: ='Юнит 15'!N$105 -> 3532 | H22: ='Юнит 15'!S$105 -> 2176 | I22: ='Юнит 15'!T$105 -> -59 | J22: ='Юнит 15'!V$105 -> 2198880.5 | K22: ='Юнит 15'!W$105 -> -57961.37 | L22: =IFERROR(J22+K22,0) -> 2140919.2 | M22: ='Юнит 15'!Y$105 -> 3303471.3 | N22: ='Юнит 15'!Z$105 -> -87984.17 | O22: =IFERROR(M22+N22,0) -> 3215487.2 | P22: ='Юнит 15'!AD$105 -> 261816.2 | Q22: ='Юнит 15'!AG$105 -> 302367.43 | R22: ='Юнит 15'!AE$105 -> 1215469.6 | S22: ='Юнит 15'!AL$105 -> 9130.33 | U22: ='Юнит 15'!AM$105 -> 4923.98 | V22: 22990 | W22: ='Юнит 15'!AH$105 -> 2405 | X22: ='Юнит 15'!AI$105 -> 301236 | Z22: ='Юнит 15'!AK$105 -> 0 | AA22: 878 | AB22: 8780 | AC22: ='Юнит 15'!AN$105 -> 122246.48 | AE22: =O22-SUM(P22:AB22)+AD22 -> 1085490.6 | AF22: =O22-SUM(P22:AC22)+AD22 -> 963244.12 | AH22: =P22/O22 -> 0.081423494 | AI22: =AF22/P22 -> 3.6790852 | AJ22: =AF22/O22 -> 0.29956397 | AK22: =(W22+X22+Z22)/O22 -> 0.094430792
B23: Апрель 3 очки | C23: 13-19.04 | D23: 16 | F23: =IFERROR(O23-SUM(Q23:W23)-AA23-AB23+AD23,0) -> 1468778.3 | G23: ='Юнит 16'!N$106 -> 3479 | H23: ='Юнит 16'!S$106 -> 1972 | I23: ='Юнит 16'!T$106 -> -47 | J23: ='Юнит 16'!V$106 -> 1966605.2 | K23: ='Юнит 16'!W$106 -> -45569.59 | L23: =IFERROR(J23+K23,0) -> 1921035.6 | M23: ='Юнит 16'!Y$106 -> 2939167.4 | N23: ='Юнит 16'!Z$106 -> -68089.33 | O23: =IFERROR(M23+N23,0) -> 2871078.1 | P23: ='Юнит 16'!AD$106 -> 238729.31 | Q23: ='Юнит 16'!AG$106 -> 252691.82 | R23: ='Юнит 16'!AE$106 -> 1082608.5 | S23: ='Юнит 16'!AL$106 -> 11044.13 | U23: ='Юнит 16'!AM$106 -> 3110 | W23: ='Юнит 16'!AH$106 -> 43580 | X23: ='Юнит 16'!AI$106 -> 287584 | Z23: ='Юнит 16'!AK$106 -> 0 | AA23: 842.3 | AB23: 8423 | AC23: ='Юнит 16'!AN$106 -> 109691.13 | AE23: =O23-SUM(P23:AB23)+AD23 -> 942465 | AF23: =O23-SUM(P23:AC23)+AD23 -> 832773.87 | AH23: =P23/O23 -> 0.08314971 | AI23: =AF23/P23 -> 3.4883604 | AJ23: =AF23/O23 -> 0.29005616 | AK23: =(W23+X23+Z23)/O23 -> 0.11534483
B24: Апрель 4 очки | C24: 20-26.04 | D24: 17 | F24: =IFERROR(O24-SUM(Q24:W24)-AA24-AB24+AD24,0) -> 1257598.6 | G24: ='Юнит 17'!N$106 -> 3101 | H24: ='Юнит 17'!S$106 -> 1730 | I24: ='Юнит 17'!T$106 -> -35 | J24: ='Юнит 17'!V$106 -> 1694803.1 | K24: ='Юнит 17'!W$106 -> -35587.44 | L24: =IFERROR(J24+K24,0) -> 1659215.6 | M24: ='Юнит 17'!Y$106 -> 2465283.2 | N24: ='Юнит 17'!Z$106 -> -52946.24 | O24: =IFERROR(M24+N24,0) -> 2412337 | P24: ='Юнит 17'!AD$106 -> 210794.5 | Q24: ='Юнит 17'!AG$106 -> 226778.55 | R24: ='Юнит 17'!AE$106 -> 908073.2 | S24: ='Юнит 17'!AL$106 -> 10756.94 | U24: ='Юнит 17'!AM$106 -> 1310 | W24: ='Юнит 17'!AH$106 -> 6217 | X24: ='Юнит 17'!AI$106 -> 172288 | Y24: ='Юнит 17'!AJ106 -> 215420 | Z24: ='Юнит 17'!AK$106 -> 0 | AA24: 145.7 | AB24: 1457 | AC24: ='Юнит 17'!AN$106 -> 94741.212 | AE24: =O24-SUM(P24:AB24)+AD24 -> 659096.12 | AF24: =O24-SUM(P24:AC24)+AD24 -> 564354.91 | AH24: =P24/O24 -> 0.087381862 | AI24: =AF24/P24 -> 2.6772753 | AJ24: =AF24/O24 -> 0.2339453 | AK24: =(W24+X24+Z24)/O24 -> 0.073996709
B25: Апрель 5 очки | C25: 27.04-03.05 | D25: 18 | AH25: =P25/O25 -> #DIV/0! | AI25: =AF25/P25 -> #DIV/0! | AJ25: =AF25/O25 -> #DIV/0! | AK25: =(W25+X25+Z25)/O25 -> #DIV/0!
B28: Итого | F28: =SUM(F4:F27) -> 20523318 | G28: =SUM(G4:G27) -> 60843 | H28: =SUM(H4:H27) -> 32560 | I28: =SUM(I4:I27) -> -759 | J28: =SUM(J4:J27) -> 28469841 | K28: =SUM(K4:K27) -> -665273.84 | L28: =SUM(L4:L27) -> 27804567 | M28: =SUM(M4:M27) -> 42999099 | ... X28: =SUM(X4:X27) -> 3639693 | Z28: =SUM(Z4:Z27) -> 0 | AC28: =SUM(AC4:AC27) -> 1566485.8 | AD28: =SUM(AD4:AD27) -> 0 | AE28: =SUM(AE4:AE27) -> 12707913 | AF28: =SUM(AF4:AF27) -> 11141427 | AG28: =SUM(AG4:AG27) -> 11141427 | AH28: =P28/O28 -> 0.094310065 | AI28: =AF28/P28 -> 2.8132839 | AJ28: =AF28/O28 -> 0.26532099 | AK28: =(W28+X28+Z28)/O28 -> 0.11603401
M29: % от выручки за весь период
N30: =-N28/M28 -> 0.023415461 | P30: =P28/$O$28 -> 0.094310065 | Q30: =Q28/$O$28 -> 0.099196614 | R30: =R28/$O$28 -> 0.37557908 | S30: =S28/$O$28 -> 0.0036409547 | T30: =T28/$O$28 -> 7.549011e-07 | U30: =U28/$O$28 -> 0.00033070598 | V30: =V28/$O$28 -> 0.0026300983 | W30: =W28/$O$28 -> 0.029358675 | X30: =X28/$O$28 -> 0.086675339 | Z30: =Z28/$O$28 -> 0 | AC30: =AC28/$O$28 -> 0.037304158 | AG30: =AF28/P28 -> 2.8132839 | AH30: Маржинальность, %
W31: =(W28+X28)/O28 -> 0.11603401 | AG31: =AF28/O28 -> 0.26532099 | AH31: Рентабельность, %
B33: ЯНВАРЬ очки | G33: =G6 -> 4961 | H33: =H6 -> 2362 | I33: =I6 -> -53 | J33: =J6 -> 1728382.8 | K33: =K6 -> -44657.88 | L33: =L6 -> 1683724.9 | M33: =M6 -> 2303342.1 | N33: =N6 -> -58267.04 | ... X33: =X6 -> 404487 | Z33: =Z6 -> 0 | AC33: =AC6 -> 95827.42 | AD33: =AD6 -> 0 | AE33: =AE6 -> 258355.22 | AF33: =AF6 -> 162527.8 | AG33: =AF33/P33 -> 0.55493603
N34: =-N33/M33 -> 0.025296738 | P34: =P33/$O$33 -> 0.13045294 | Q34: =Q33/$O$33 -> 0.12314762 | R34: =R33/$O$33 -> 0.3713327 | S34: =S33/$O$33 -> 0.017965164 | T34: =T33/$O$33 -> 0 | U34: =U33/$O$33 -> 0 | V34: =V33/$O$33 -> 0.011327728 | W34: =W33/$O$33 -> 0.050531051 | X34: =X33/$O$33 -> 0.18016636 | Z34: =Z33/$O$33 -> 0 | AC34: =AC33/$O$33 -> 0.042683393 | AD34: =AD33/$O$33 -> 0 | AF34: =AF33/O33 -> 0.072393037 | AG34: =AF33/O33 -> 0.072393037
B36: 7 нед очки | P36: =P11/$O$11 -> 0.12260072 | Q36: =Q11/$O$11 -> 0.11302459 | R36: =R11/$O$11 -> 0.37030708 | S36: =S11/$O$11 -> 0.004328203 | T36: =T11/$O$11 -> 1.5965377e-05 | U36: =U11/$O$11 -> 0.00043958004 | V36: =V11/$O$11 -> 0.002547691 | W36: =W11/$O$11 -> 0.077475184 | X36: =X11/$O$11 -> 0.073797294 | Z36: =Z11/$O$11 -> 0 | AC36: =AC11/$O$11 -> 0.035953449 | AD36: =AD11/$O$11 -> 0 | AG36: =AF11/P11 -> 1.6273172 | AH36: Маржинальность, %
AG37: =AF11/O11 -> 0.19951026 | AH37: Рентабельность, %
B39: ФЕВРАЛЬ очки | G39: =G9+G11+G13+G15 -> 14517 | H39: =H9+H11+H13+H15 -> 7967 | I39: =I9+I11+I13+I15 -> -171 | J39: =J9+J11+J13+J15 -> 5543477.6 | K39: =K9+K11+K13+K15 -> -118993.17 | L39: =L9+L11+L13+L15 -> 5424484.4 | M39: =M9+M11+M13+M15 -> 8658079.8 | N39: =N9+N11+N13+N15 -> -186633.46 | ... X39: =X9+X11+X13+X15 -> 609161 | Z39: =Z9+Z11+Z13+Z15 -> 0 | AC39: =AC9+AC11+AC13+AC15 -> 304577.71 | AD39: =AD9+AD11+AD13+AD15 -> 0 | AE39: =AE9+AE11+AE13+AE15 -> 2180767.1 | AF39: =AF9+AF11+AF13+AF15 -> 1876189.4 | AG39: =AF39/P39 -> 1.925642
N40: =-N39/M39 -> 0.021555988 | P40: =P39/$O$39 -> 0.11501211 | Q40: =Q39/$O$39 -> 0.11015329 | R40: =R39/$O$39 -> 0.37313996 | S40: =S39/$O$39 -> 0.0039412801 | T40: =T39/$O$39 -> 3.5413079e-06 | U40: =U39/$O$39 -> 0.000316842 | V40: =V39/$O$39 -> 0.0041616317 | W40: =W39/$O$39 -> 0.063938196 | X40: =X39/$O$39 -> 0.071907556 | Z40: =Z39/$O$39 -> 0 | AC40: =AC39/$O$39 -> 0.035953449 | AD40: =AD39/$O$39 -> 0 | AF40: =AF39/O39 -> 0.22147215 | AG40: =AF39/O39 -> 0.22147215
B42: 9 нед очки | P42: =P15/$O$15 -> 0.10266613 | Q42: =Q15/$O$15 -> 0.10672522 | R42: =R15/$O$15 -> 0.37489216 | S42: =S15/$O$15 -> 0.0030195896 | T42: =T15/$O$15 -> 0 | U42: =U15/$O$15 -> 0.00049621088 | V42: =V15/$O$15 -> 0.00085581058 | W42: =W15/$O$15 -> 0.083286977 | X42: =X15/$O$15 -> 0.028024075 | Z42: =Z15/$O$15 -> 0 | AC42: =AC15/$O$15 -> 0.035953449 | AD42: =AD15/$O$15 -> 0 | AG42: =AF15/P15 -> 2.5722249 | AH42: Маржинальность, %
AG43: =AF15/O15 -> 0.26408038 | AH43: Рентабельность, %
B45: МАРТ очки | G45: =SUM(G17:G20) -> 25647 | H45: =SUM(H17:H20) -> 13213 | I45: =SUM(I17:I20) -> -304 | J45: =SUM(J17:J20) -> 12210305 | K45: =SUM(K17:K20) -> -273683.22 | L45: =SUM(L17:L20) -> 11936622 | M45: =SUM(M17:M20) -> 18627468 | N45: =SUM(N17:N20) -> -421000.71 | ... X45: =SUM(X17:X20) -> 1364049 | Z45: =SUM(Z17:Z20) -> 0 | AC45: =SUM(AC17:AC20) -> 666212.62 | AD45: =SUM(AD17:AD20) -> 0 | AE45: =SUM(AE17:AE20) -> 6063109.4 | AF45: =SUM(AF17:AF20) -> 5396896.8 | AG45: =AF45/P45 -> 3.3673696 | AH45: Маржинальность, %
P46: =P45/$O$45 -> 0.088029381 | Q46: =Q45/$O$45 -> 0.095917116 | R46: =R45/$O$45 -> 0.37631622 | S46: =S45/$O$45 -> 0.0019818573 | T46: =T45/$O$45 -> 0 | U46: =U45/$O$45 -> 4.9378059e-05 | V46: =V45/$O$45 -> 0.0014316012 | W46: =W45/$O$45 -> 0.028333778 | X46: =X45/$O$45 -> 0.074921125 | Z46: =Z45/$O$45 -> 0 | AC46: =AC45/$O$45 -> 0.036592087 | AD46: =AD45/$O$45 -> 0 | AF46: =AF45/O45 -> 0.29642746 | AG46: =AF45/O45 -> 0.29642746 | AH46: Рентабельность, %

Sheet АВС 18
B2: ОЧКИ
C3: Прибыль | D3: % прибыль | E3: Доля | F3: ABC прибыль | G3: ABC кол-во | J3: Кол-во | K3: % кол-во | L3: Доля | M3: ABC кол-во
B4: черные с железкой классика | D4: =C4/C$106 -> #DIV/0! | E4: =D4 -> #DIV/0! | F4: =IF(AND(E4<=0),"C",IF(E4<=0.8,"A",IF(E4<=0.95,"B","C"))) -> #DIV/0! | G4: =VLOOKUP(B$4:B$104,I$4:M$104,5,0) -> #DIV/0! | I4: черные с железкой классика | K4: =J4/J$106 -> #DIV/0! | L4: =K4 -> #DIV/0! | M4: =_xlfn.IFS(L4<80%,"A",L4<=95%,"B",L4>95%,"C") -> #DIV/0! | P4: A | Q4: 0.8
B5: QS черные PZ | D5: =C5/C$106 -> #DIV/0! | E5: =E4+D5 -> #DIV/0! | F5: =IF(AND(E5<=0),"C",IF(E5<=0.8,"A",IF(E5<=0.95,"B","C"))) -> #DIV/0! | G5: =VLOOKUP(B$4:B$104,I$4:M$104,5,0) -> #DIV/0! | I5: QS черные PZ | K5: =J5/J$106 -> #DIV/0! | L5: =L4+K5 -> #DIV/0! | M5: =_xlfn.IFS(L5<80%,"A",L5<=95%,"B",L5>95%,"C") -> #DIV/0! | P5: B | Q5: 0.15
B6: QS синие PZ | D6: =C6/C$106 -> #DIV/0! | E6: =E5+D6 -> #DIV/0! | F6: =IF(AND(E6<=0),"C",IF(E6<=0.8,"A",IF(E6<=0.95,"B","C"))) -> #DIV/0! | G6: =VLOOKUP(B$4:B$104,I$4:M$104,5,0) -> #DIV/0! | I6: QS синие PZ | K6: =J6/J$106 -> #DIV/0! | L6: =L5+K6 -> #DIV/0! | M6: =_xlfn.IFS(L6<80%,"A",L6<=95%,"B",L6>95%,"C") -> #DIV/0! | P6: C | Q6: 0.05
B7: QS желтые PZ | D7: =C7/C$106 -> #DIV/0! | E7: =E6+D7 -> #DIV/0! | F7: =IF(AND(E7<=0),"C",IF(E7<=0.8,"A",IF(E7<=0.95,"B","C"))) -> #DIV/0! | G7: =VLOOKUP(B$4:B$104,I$4:M$104,5,0) -> #DIV/0! | I7: QS желтые PZ | K7: =J7/J$106 -> #DIV/0! | L7: =L6+K7 -> #DIV/0! | M7: =_xlfn.IFS(L7<80%,"A",L7<=95%,"B",L7>95%,"C") -> #DIV/0!
B8: QS коричневые PZ | D8: =C8/C$106 -> #DIV/0! | E8: =E7+D8 -> #DIV/0! | F8: =IF(AND(E8<=0),"C",IF(E8<=0.8,"A",IF(E8<=0.95,"B","C"))) -> #DIV/0! | G8: =VLOOKUP(B$4:B$104,I$4:M$104,5,0) -> #DIV/0! | I8: QS коричневые PZ | K8: =J8/J$106 -> #DIV/0! | L8: =L7+K8 -> #DIV/0! | M8: =_xlfn.IFS(L8<80%,"A",L8<=95%,"B",L8>95%,"C") -> #DIV/0!
B9: MR8854 C2 Жен | D9: =C9/C$106 -> #DIV/0! | E9: =E8+D9 -> #DIV/0! | F9: =IF(AND(E9<=0),"C",IF(E9<=0.8,"A",IF(E9<=0.95,"B","C"))) -> #DIV/0! | G9: =VLOOKUP(B$4:B$104,I$4:M$104,5,0) -> #DIV/0! | I9: MR8854 C2 Жен | K9: =J9/J$106 -> #DIV/0! | L9: =L8+K9 -> #DIV/0! | M9: =_xlfn.IFS(L9<80%,"A",L9<=95%,"B",L9>95%,"C") -> #DIV/0!
B10: th черн | D10: =C10/C$106 -> #DIV/0! | E10: =E9+D10 -> #DIV/0! | F10: =IF(AND(E10<=0),"C",IF(E10<=0.8,"A",IF(E10<=0.95,"B","C"))) -> #DIV/0! | G10: =VLOOKUP(B$4:B$104,I$4:M$104,5,0) -> #DIV/0! | I10: th черн | K10: =J10/J$106 -> #DIV/0! | L10: =L9+K10 -> #DIV/0! | M10: =_xlfn.IFS(L10<80%,"A",L10<=95%,"B",L10>95%,"C") -> #DIV/0!
B11: th син | D11: =C11/C$106 -> #DIV/0! | E11: =E10+D11 -> #DIV/0! | F11: =IF(AND(E11<=0),"C",IF(E11<=0.8,"A",IF(E11<=0.95,"B","C"))) -> #DIV/0! | G11: =VLOOKUP(B$4:B$104,I$4:M$104,5,0) -> #DIV/0! | I11: th син | K11: =J11/J$106 -> #DIV/0! | L11: =L10+K11 -> #DIV/0! | M11: =_xlfn.IFS(L11<80%,"A",L11<=95%,"B",L11>95%,"C") -> #DIV/0!
B12: th желт | D12: =C12/C$106 -> #DIV/0! | E12: =E11+D12 -> #DIV/0! | F12: =IF(AND(E12<=0),"C",IF(E12<=0.8,"A",IF(E12<=0.95,"B","C"))) -> #DIV/0! | G12: =VLOOKUP(B$4:B$104,I$4:M$104,5,0) -> #DIV/0! | I12: th желт | K12: =J12/J$106 -> #DIV/0! | L12: =L11+K12 -> #DIV/0! | M12: =_xlfn.IFS(L12<80%,"A",L12<=95%,"B",L12>95%,"C") -> #DIV/0!
B13: th коричн | D13: =C13/C$106 -> #DIV/0! | E13: =E12+D13 -> #DIV/0! | F13: =IF(AND(E13<=0),"C",IF(E13<=0.8,"A",IF(E13<=0.95,"B","C"))) -> #DIV/0! | G13: =VLOOKUP(B$4:B$104,I$4:M$104,5,0) -> #DIV/0! | I13: th коричн | K13: =J13/J$106 -> #DIV/0! | L13: =L12+K13 -> #DIV/0! | M13: =_xlfn.IFS(L13<80%,"A",L13<=95%,"B",L13>95%,"C") -> #DIV/0!
B14: flip черные | D14: =C14/C$106 -> #DIV/0! | E14: =E13+D14 -> #DIV/0! | F14: =IF(AND(E14<=0),"C",IF(E14<=0.8,"A",IF(E14<=0.95,"B","C"))) -> #DIV/0! | G14: =VLOOKUP(B$4:B$104,I$4:M$104,5,0) -> #DIV/0! | I14: flip черные | K14: =J14/J$106 -> #DIV/0! | L14: =L13+K14 -> #DIV/0! | M14: =_xlfn.IFS(L14<80%,"A",L14<=95%,"B",L14>95%,"C") -> #DIV/0!
B15: flip синие | D15: =C15/C$106 -> #DIV/0! | E15: =E14+D15 -> #DIV/0! | F15: =IF(AND(E15<=0),"C",IF(E15<=0.8,"A",IF(E15<=0.95,"B","C"))) -> #DIV/0! | G15: =VLOOKUP(B$4:B$104,I$4:M$104,5,0) -> #DIV/0! | I15: flip синие | K15: =J15/J$106 -> #DIV/0! | L15: =L14+K15 -> #DIV/0! | M15: =_xlfn.IFS(L15<80%,"A",L15<=95%,"B",L15>95%,"C") -> #DIV/0!
B16: flip желтые | D16: =C16/C$106 -> #DIV/0! | E16: =E15+D16 -> #DIV/0! | F16: =IF(AND(E16<=0),"C",IF(E16<=0.8,"A",IF(E16<=0.95,"B","C"))) -> #DIV/0! | G16: =VLOOKUP(B$4:B$104,I$4:M$104,5,0) -> #DIV/0! | I16: flip желтые | K16: =J16/J$106 -> #DIV/0! | L16: =L15+K16 -> #DIV/0! | M16: =_xlfn.IFS(L16<80%,"A",L16<=95%,"B",L16>95%,"C") -> #DIV/0!
B17: flip коричневые | D17: =C17/C$106 -> #DIV/0! | E17: =E16+D17 -> #DIV/0! | F17: =IF(AND(E17<=0),"C",IF(E17<=0.8,"A",IF(E17<=0.95,"B","C"))) -> #DIV/0! | G17: =VLOOKUP(B$4:B$104,I$4:M$104,5,0) -> #DIV/0! | I17: flip коричневые | K17: =J17/J$106 -> #DIV/0! | L17: =L16+K17 -> #DIV/0! | M17: =_xlfn.IFS(L17<80%,"A",L17<=95%,"B",L17>95%,"C") -> #DIV/0!
B18: wwl8032 коричневые золото | D18: =C18/C$106 -> #DIV/0! | E18: =E17+D18 -> #DIV/0! | F18: =IF(AND(E18<=0),"C",IF(E18<=0.8,"A",IF(E18<=0.95,"B","C"))) -> #DIV/0! | G18: =VLOOKUP(B$4:B$104,I$4:M$104,5,0) -> #DIV/0! | I18: wwl8032 коричневые золото | K18: =J18/J$106 -> #DIV/0! | L18: =L17+K18 -> #DIV/0! | M18: =_xlfn.IFS(L18<80%,"A",L18<=95%,"B",L18>95%,"C") -> #DIV/0!
... B38: sh13 | D38: =C38/C$106 -> #DIV/0! | E38: =E37+D38 -> #DIV/0! | F38: =IF(AND(E38<=0),"C",IF(E38<=0.8,"A",IF(E38<=0.95,"B","C"))) -> #DIV/0! | G38: =VLOOKUP(B$4:B$104,I$4:M$104,5,0) -> #DIV/0! | I38: sh13 | K38: =J38/J$106 -> #DIV/0! | L38: =L37+K38 -> #DIV/0! | M38: =_xlfn.IFS(L38<80%,"A",L38<=95%,"B",L38>95%,"C") -> #DIV/0!
B39: sh14 | D39: =C39/C$106 -> #DIV/0! | E39: =E35+D39 -> #DIV/0! | F39: =IF(AND(E39<=0),"C",IF(E39<=0.8,"A",IF(E39<=0.95,"B","C"))) -> #DIV/0! | G39: =VLOOKUP(B$4:B$104,I$4:M$104,5,0) -> #DIV/0! | I39: sh14 | K39: =J39/J$106 -> #DIV/0! | L39: =L35+K39 -> #DIV/0! | M39: =_xlfn.IFS(L39<80%,"A",L39<=95%,"B",L39>95%,"C") -> #DIV/0!
B40: sh15 | D40: =C40/C$106 -> #DIV/0! | E40: =E39+D40 -> #DIV/0! | F40: =IF(AND(E40<=0),"C",IF(E40<=0.8,"A",IF(E40<=0.95,"B","C"))) -> #DIV/0! | G40: =VLOOKUP(B$4:B$104,I$4:M$104,5,0) -> #DIV/0! | I40: sh15 | K40: =J40/J$106 -> #DIV/0! | L40: =L39+K40 -> #DIV/0! | M40: =_xlfn.IFS(L40<80%,"A",L40<=95%,"B",L40>95%,"C") -> #DIV/0!
B41: sh16 | D41: =C41/C$106 -> #DIV/0! | E41: =E40+D41 -> #DIV/0! | F41: =IF(AND(E41<=0),"C",IF(E41<=0.8,"A",IF(E41<=0.95,"B","C"))) -> #DIV/0! | G41: =VLOOKUP(B$4:B$104,I$4:M$104,5,0) -> #DIV/0! | I41: sh16 | K41: =J41/J$106 -> #DIV/0! | L41: =L40+K41 -> #DIV/0! | M41: =_xlfn.IFS(L41<80%,"A",L41<=95%,"B",L41>95%,"C") -> #DIV/0!
B42: sh17 | D42: =C42/C$106 -> #DIV/0! | E42: =E41+D42 -> #DIV/0! | F42: =IF(AND(E42<=0),"C",IF(E42<=0.8,"A",IF(E42<=0.95,"B","C"))) -> #DIV/0! | G42: =VLOOKUP(B$4:B$104,I$4:M$104,5,0) -> #DIV/0! | I42: sh17 | K42: =J42/J$106 -> #DIV/0! | L42: =L41+K42 -> #DIV/0! | M42: =_xlfn.IFS(L42<80%,"A",L42<=95%,"B",L42>95%,"C") -> #DIV/0!
B43: sh18 | D43: =C43/C$106 -> #DIV/0! | E43: =E42+D43 -> #DIV/0! | F43: =IF(AND(E43<=0),"C",IF(E43<=0.8,"A",IF(E43<=0.95,"B","C"))) -> #DIV/0! | G43: =VLOOKUP(B$4:B$104,I$4:M$104,5,0) -> #DIV/0! | I43: sh18 | K43: =J43/J$106 -> #DIV/0! | L43: =L42+K43 -> #DIV/0! | M43: =_xlfn.IFS(L43<80%,"A",L43<=95%,"B",L43>95%,"C") -> #DIV/0!
B44: sh19 | D44: =C44/C$106 -> #DIV/0! | E44: =E43+D44 -> #DIV/0! | F44: =IF(AND(E44<=0),"C",IF(E44<=0.8,"A",IF(E44<=0.95,"B","C"))) -> #DIV/0! | G44: =VLOOKUP(B$4:B$104,I$4:M$104,5,0) -> #DIV/0! | I44: sh19 | K44: =J44/J$106 -> #DIV/0! | L44: =L43+K44 -> #DIV/0! | M44: =_xlfn.IFS(L44<80%,"A",L44<=95%,"B",L44>95%,"C") -> #DIV/0!
B45: ww 203 черные | D45: =C45/C$106 -> #DIV/0! | E45: =E44+D45 -> #DIV/0! | F45: =IF(AND(E45<=0),"C",IF(E45<=0.8,"A",IF(E45<=0.95,"B","C"))) -> #DIV/0! | G45: =VLOOKUP(B$4:B$104,I$4:M$104,5,0) -> #DIV/0! | I45: ww 203 черные | K45: =J45/J$106 -> #DIV/0! | L45: =L44+K45 -> #DIV/0! | M45: =_xlfn.IFS(L45<80%,"A",L45<=95%,"B",L45>95%,"C") -> #DIV/0!
B46: ww 1022 черные | D46: =C46/C$106 -> #DIV/0! | E46: =E45+D46 -> #DIV/0! | F46: =IF(AND(E46<=0),"C",IF(E46<=0.8,"A",IF(E46<=0.95,"B","C"))) -> #DIV/0! | G46: =VLOOKUP(B$4:B$104,I$4:M$104,5,0) -> #DIV/0! | I46: ww 1022 черные | K46: =J46/J$106 -> #DIV/0! | L46: =L45+K46 -> #DIV/0! | M46: =_xlfn.IFS(L46<80%,"A",L46<=95%,"B",L46>95%,"C") -> #DIV/0!
B47: ww 1022 черн-серебро | D47: =C47/C$106 -> #DIV/0! | E47: =E46+D47 -> #DIV/0! | F47: =IF(AND(E47<=0),"C",IF(E47<=0.8,"A",IF(E47<=0.95,"B","C"))) -> #DIV/0! | G47: =VLOOKUP(B$4:B$104,I$4:M$104,5,0) -> #DIV/0! | I47: ww 1022 черн-серебро | K47: =J47/J$106 -> #DIV/0! | L47: =L46+K47 -> #DIV/0! | M47: =_xlfn.IFS(L47<80%,"A",L47<=95%,"B",L47>95%,"C") -> #DIV/0!
B48: ww 1022 желтые | D48: =C48/C$106 -> #DIV/0! | E48: =E47+D48 -> #DIV/0! | F48: =IF(AND(E48<=0),"C",IF(E48<=0.8,"A",IF(E48<=0.95,"B","C"))) -> #DIV/0! | G48: =VLOOKUP(B$4:B$104,I$4:M$104,5,0) -> #DIV/0! | I48: ww 1022 желтые | K48: =J48/J$106 -> #DIV/0! | L48: =L47+K48 -> #DIV/0! | M48: =_xlfn.IFS(L48<80%,"A",L48<=95%,"B",L48>95%,"C") -> #DIV/0!
B49: ww 1022 коричневые | D49: =C49/C$106 -> #DIV/0! | E49: =E48+D49 -> #DIV/0! | F49: =IF(AND(E49<=0),"C",IF(E49<=0.8,"A",IF(E49<=0.95,"B","C"))) -> #DIV/0! | G49: =VLOOKUP(B$4:B$104,I$4:M$104,5,0) -> #DIV/0! | I49: ww 1022 коричневые | K49: =J49/J$106 -> #DIV/0! | L49: =L48+K49 -> #DIV/0! | M49: =_xlfn.IFS(L49<80%,"A",L49<=95%,"B",L49>95%,"C") -> #DIV/0!
B50: ww 2018 черные | D50: =C50/C$106 -> #DIV/0! | E50: =E49+D50 -> #DIV/0! | F50: =IF(AND(E50<=0),"C",IF(E50<=0.8,"A",IF(E50<=0.95,"B","C"))) -> #DIV/0! | G50: =VLOOKUP(B$4:B$104,I$4:M$104,5,0) -> #DIV/0! | I50: ww 2018 черные | K50: =J50/J$106 -> #DIV/0! | L50: =L49+K50 -> #DIV/0! | M50: =_xlfn.IFS(L50<80%,"A",L50<=95%,"B",L50>95%,"C") -> #DIV/0!
B51: ww 2018 желтые | D51: =C51/C$106 -> #DIV/0! | E51: =E50+D51 -> #DIV/0! | F51: =IF(AND(E51<=0),"C",IF(E51<=0.8,"A",IF(E51<=0.95,"B","C"))) -> #DIV/0! | G51: =VLOOKUP(B$4:B$104,I$4:M$104,5,0) -> #DIV/0! | I51: ww 2018 желтые | K51: =J51/J$106 -> #DIV/0! | L51: =L50+K51 -> #DIV/0! | M51: =_xlfn.IFS(L51<80%,"A",L51<=95%,"B",L51>95%,"C") -> #DIV/0!
... B75: MANNA2121 | D75: =C75/C$106 -> #DIV/0! | E75: =E74+D75 -> #DIV/0! | F75: =IF(AND(E75<=0),"C",IF(E75<=0.8,"A",IF(E75<=0.95,"B","C"))) -> #DIV/0! | G75: =VLOOKUP(B$4:B$104,I$4:M$104,5,0) -> #DIV/0! | I75: MANNA2121 | K75: =J75/J$106 -> #DIV/0! | L75: =L74+K75 -> #DIV/0! | M75: =_xlfn.IFS(L75<80%,"A",L75<=95%,"B",L75>95%,"C") -> #DIV/0!
B76: MANNA2122 | D76: =C76/C$106 -> #DIV/0! | E76: =E49+D76 -> #DIV/0! | F76: =IF(AND(E76<=0),"C",IF(E76<=0.8,"A",IF(E76<=0.95,"B","C"))) -> #DIV/0! | G76: =VLOOKUP(B$4:B$104,I$4:M$104,5,0) -> #DIV/0! | I76: MANNA2122 | K76: =J76/J$106 -> #DIV/0! | L76: =L49+K76 -> #DIV/0! | M76: =_xlfn.IFS(L76<80%,"A",L76<=95%,"B",L76>95%,"C") -> #DIV/0!
B77: Chenlong черные | D77: =C77/C$106 -> #DIV/0! | E77: =E76+D77 -> #DIV/0! | F77: =IF(AND(E77<=0),"C",IF(E77<=0.8,"A",IF(E77<=0.95,"B","C"))) -> #DIV/0! | G77: =VLOOKUP(B$4:B$104,I$4:M$104,5,0) -> #DIV/0! | I77: Chenlong черные | K77: =J77/J$106 -> #DIV/0! | L77: =L76+K77 -> #DIV/0! | M77: =_xlfn.IFS(L77<80%,"A",L77<=95%,"B",L77>95%,"C") -> #DIV/0!
B78: Chenlong коричневые | D78: =C78/C$106 -> #DIV/0! | E78: =E77+D78 -> #DIV/0! | F78: =IF(AND(E78<=0),"C",IF(E78<=0.8,"A",IF(E78<=0.95,"B","C"))) -> #DIV/0! | G78: =VLOOKUP(B$4:B$104,I$4:M$104,5,0) -> #DIV/0! | I78: Chenlong коричневые | K78: =J78/J$106 -> #DIV/0! | L78: =L77+K78 -> #DIV/0! | M78: =_xlfn.IFS(L78<80%,"A",L78<=95%,"B",L78>95%,"C") -> #DIV/0!
B79: Chenlong белые | D79: =C79/C$106 -> #DIV/0! | E79: =E78+D79 -> #DIV/0! | F79: =IF(AND(E79<=0),"C",IF(E79<=0.8,"A",IF(E79<=0.95,"B","C"))) -> #DIV/0! | G79: =VLOOKUP(B$4:B$104,I$4:M$104,5,0) -> #DIV/0! | I79: Chenlong белые | K79: =J79/J$106 -> #DIV/0! | L79: =L78+K79 -> #DIV/0! | M79: =_xlfn.IFS(L79<80%,"A",L79<=95%,"B",L79>95%,"C") -> #DIV/0!
B80: Guangdu золото серая линза | D80: =C80/C$106 -> #DIV/0! | E80: =E79+D80 -> #DIV/0! | F80: =IF(AND(E80<=0),"C",IF(E80<=0.8,"A",IF(E80<=0.95,"B","C"))) -> #DIV/0! | G80: =VLOOKUP(B$4:B$104,I$4:M$104,5,0) -> #DIV/0! | I80: Guangdu золото серая линза | K80: =J80/J$106 -> #DIV/0! | L80: =L79+K80 -> #DIV/0! | M80: =_xlfn.IFS(L80<80%,"A",L80<=95%,"B",L80>95%,"C") -> #DIV/0!
B81: Guangdu серебро серая линза | D81: =C81/C$106 -> #DIV/0! | E81: =E80+D81 -> #DIV/0! | F81: =IF(AND(E81<=0),"C",IF(E81<=0.8,"A",IF(E81<=0.95,"B","C"))) -> #DIV/0! | G81: =VLOOKUP(B$4:B$104,I$4:M$104,5,0) -> #DIV/0! | I81: Guangdu серебро серая линза | K81: =J81/J$106 -> #DIV/0! | L81: =L80+K81 -> #DIV/0! | M81: =_xlfn.IFS(L81<80%,"A",L81<=95%,"B",L81>95%,"C") -> #DIV/0!
B82: Hengda Optical черные | D82: =C82/C$106 -> #DIV/0! | E82: =E81+D82 -> #DIV/0! | F82: =IF(AND(E82<=0),"C",IF(E82<=0.8,"A",IF(E82<=0.95,"B","C"))) -> #DIV/0! | G82: =VLOOKUP(B$4:B$104,I$4:M$104,5,0) -> #DIV/0! | I82: Hengda Optical черные | K82: =J82/J$106 -> #DIV/0! | L82: =L81+K82 -> #DIV/0! | M82: =_xlfn.IFS(L82<80%,"A",L82<=95%,"B",L82>95%,"C") -> #DIV/0!
B83: Hengda Optical леопард | D83: =C83/C$106 -> #DIV/0! | E83: =E82+D83 -> #DIV/0! | F83: =IF(AND(E83<=0),"C",IF(E83<=0.8,"A",IF(E83<=0.95,"B","C"))) -> #DIV/0! | G83: =VLOOKUP(B$4:B$104,I$4:M$104,5,0) -> #DIV/0! | I83: Hengda Optical леопард | K83: =J83/J$106 -> #DIV/0! | L83: =L82+K83 -> #DIV/0! | M83: =_xlfn.IFS(L83<80%,"A",L83<=95%,"B",L83>95%,"C") -> #DIV/0!
...

Sheet АВС 17
B2: ОЧКИ
C3: Прибыль | D3: % прибыль | E3: Доля | F3: ABC прибыль | G3: ABC кол-во | J3: Кол-во | K3: % кол-во | L3: Доля | M3: ABC кол-во
B4: QS черные PZ | C4: ='Юнит 17'!AO4 -> 123838.64 | D4: =C4/C$106 -> 0.21881256 | E4: =D4 -> 0.21881256 | F4: =IF(AND(E4<=0),"C",IF(E4<=0.8,"A",IF(E4<=0.95,"B","C"))) -> A | G4: =VLOOKUP(B$4:B$104,I$4:M$104,5,0) -> A | I4: QS черные PZ | J4: ='Юнит 17'!U4 -> 327 | K4: =J4/J$106 -> 0.19292035 | L4: =K4 -> 0.19292035 | M4: =_xlfn.IFS(L4<80%,"A",L4<=95%,"B",L4>95%,"C") -> A | P4: A | Q4: 0.8
B5: flip коричневые | C5: ='Юнит 17'!AO16 -> 61360.969 | D5: =C5/C$106 -> 0.10841973 | E5: =E4+D5 -> 0.32723229 | F5: =IF(AND(E5<=0),"C",IF(E5<=0.8,"A",IF(E5<=0.95,"B","C"))) -> A | G5: =VLOOKUP(B$4:B$104,I$4:M$104,5,0) -> A | I5: flip черные | J5: ='Юнит 17'!U13 -> 184 | K5: =J5/J$106 -> 0.10855457 | L5: =L4+K5 -> 0.30147493 | M5: =_xlfn.IFS(L5<80%,"A",L5<=95%,"B",L5>95%,"C") -> A | P5: B | Q5: 0.15
B6: flip черные | C6: ='Юнит 17'!AO13 -> 43494.59 | D6: =C6/C$106 -> 0.076851321 | E6: =E5+D6 -> 0.40408361 | F6: =IF(AND(E6<=0),"C",IF(E6<=0.8,"A",IF(E6<=0.95,"B","C"))) -> A | G6: =VLOOKUP(B$4:B$104,I$4:M$104,5,0) -> A | I6: th черн | J6: ='Юнит 17'!U9 -> 156 | K6: =J6/J$106 -> 0.092035398 | L6: =L5+K6 -> 0.39351032 | M6: =_xlfn.IFS(L6<80%,"A",L6<=95%,"B",L6>95%,"C") -> A | P6: C | Q6: 0.05
B7: th черн | C7: ='Юнит 17'!AO9 -> 39870.964 | D7: =C7/C$106 -> 0.070448675 | E7: =E6+D7 -> 0.47453229 | F7: =IF(AND(E7<=0),"C",IF(E7<=0.8,"A",IF(E7<=0.95,"B","C"))) -> A | G7: =VLOOKUP(B$4:B$104,I$4:M$104,5,0) -> A | I7: flip коричневые | J7: ='Юнит 17'!U16 -> 135 | K7: =J7/J$106 -> 0.079646018 | L7: =L6+K7 -> 0.47315634 | M7: =_xlfn.IFS(L7<80%,"A",L7<=95%,"B",L7>95%,"C") -> A
B8: QS синие PZ | C8: ='Юнит 17'!AO5 -> 33241.337 | D8: =C8/C$106 -> 0.058734677 | E8: =E7+D8 -> 0.53326696 | F8: =IF(AND(E8<=0),"C",IF(E8<=0.8,"A",IF(E8<=0.95,"B","C"))) -> A | G8: =VLOOKUP(B$4:B$104,I$4:M$104,5,0) -> A | I8: th син | J8: ='Юнит 17'!U10 -> 110 | K8: =J8/J$106 -> 0.064896755 | L8: =L7+K8 -> 0.5380531 | M8: =_xlfn.IFS(L8<80%,"A",L8<=95%,"B",L8>95%,"C") -> A
B9: QS коричневые PZ | C9: ='Юнит 17'!AO7 -> 32082.786 | D9: =C9/C$106 -> 0.056687613 | E9: =E8+D9 -> 0.58995458 | F9: =IF(AND(E9<=0),"C",IF(E9<=0.8,"A",IF(E9<=0.95,"B","C"))) -> A | G9: =VLOOKUP(B$4:B$104,I$4:M$104,5,0) -> A | I9: черные с железкой классика | J9: ='Юнит 17'!U3 -> 101 | K9: =J9/J$106 -> 0.059587021 | L9: =L8+K9 -> 0.59764012 | M9: =_xlfn.IFS(L9<80%,"A",L9<=95%,"B",L9>95%,"C") -> A
B10: th коричн | C10: ='Юнит 17'!AO12 -> 31242.105 | D10: =C10/C$106 -> 0.0552022 | E10: =E9+D10 -> 0.64515678 | F10: =IF(AND(E10<=0),"C",IF(E10<=0.8,"A",IF(E10<=0.95,"B","C"))) -> A | G10: =VLOOKUP(B$4:B$104,I$4:M$104,5,0) -> A | I10: QS синие PZ | J10: ='Юнит 17'!U5 -> 89 | K10: =J10/J$106 -> 0.052507375 | L10: =L9+K10 -> 0.65014749 | M10: =_xlfn.IFS(L10<80%,"A",L10<=95%,"B",L10>95%,"C") -> A
B11: черные с железкой классика | C11: ='Юнит 17'!AO3 -> 26574.335 | D11: =C11/C$106 -> 0.046954639 | E11: =E10+D11 -> 0.69211141 | F11: =IF(AND(E11<=0),"C",IF(E11<=0.8,"A",IF(E11<=0.95,"B","C"))) -> A | G11: =VLOOKUP(B$4:B$104,I$4:M$104,5,0) -> A | I11: th коричн | J11: ='Юнит 17'!U12 -> 77 | K11: =J11/J$106 -> 0.045427729 | L11: =L10+K11 -> 0.69557522 | M11: =_xlfn.IFS(L11<80%,"A",L11<=95%,"B",L11>95%,"C") -> A
B12: th син | C12: ='Юнит 17'!AO10 -> 23782.119 | D12: =C12/C$106 -> 0.042021026 | E12: =E11+D12 -> 0.73413244 | F12: =IF(AND(E12<=0),"C",IF(E12<=0.8,"A",IF(E12<=0.95,"B","C"))) -> A | G12: =VLOOKUP(B$4:B$104,I$4:M$104,5,0) -> A | I12: QS коричневые PZ | J12: ='Юнит 17'!U7 -> 74 | K12: =J12/J$106 -> 0.043657817 | L12: =L11+K12 -> 0.73923304 | M12: =_xlfn.IFS(L12<80%,"A",L12<=95%,"B",L12>95%,"C") -> A
B13: QS желтые PZ | C13: ='Юнит 17'!AO6 -> 22574.93 | D13: =C13/C$106 -> 0.039888023 | E13: =E12+D13 -> 0.77402046 | F13: =IF(AND(E13<=0),"C",IF(E13<=0.8,"A",IF(E13<=0.95,"B","C"))) -> A | G13: =VLOOKUP(B$4:B$104,I$4:M$104,5,0) -> B | I13: th желт | J13: ='Юнит 17'!U11 -> 60 | K13: =J13/J$106 -> 0.03539823 | L13: =L12+K13 -> 0.77463127 | M13: =_xlfn.IFS(L13<80%,"A",L13<=95%,"B",L13>95%,"C") -> A
B14: th желт | C14: ='Юнит 17'!AO11 -> 20625.479 | D14: =C14/C$106 -> 0.036443505 | E14: =E13+D14 -> 0.81046397 | F14: =IF(AND(E14<=0),"C",IF(E14<=0.8,"A",IF(E14<=0.95,"B","C"))) -> B | G14: =VLOOKUP(B$4:B$104,I$4:M$104,5,0) -> A | I14: QS желтые PZ | J14: ='Юнит 17'!U6 -> 50 | K14: =J14/J$106 -> 0.029498525 | L14: =L13+K14 -> 0.80412979 | M14: =_xlfn.IFS(L14<80%,"A",L14<=95%,"B",L14>95%,"C") -> B
B15: flip желтые | C15: ='Юнит 17'!AO15 -> 20118.65 | D15: =C15/C$106 -> 0.03554798 | E15: =E14+D15 -> 0.84601195 | F15: =IF(AND(E15<=0),"C",IF(E15<=0.8,"A",IF(E15<=0.95,"B","C"))) -> B | G15: =VLOOKUP(B$4:B$104,I$4:M$104,5,0) -> B | I15: flip желтые | J15: ='Юнит 17'!U15 -> 43 | K15: =J15/J$106 -> 0.025368732 | L15: =L14+K15 -> 0.82949853 | M15: =_xlfn.IFS(L15<80%,"A",L15<=95%,"B",L15>95%,"C") -> B
B16: ridges brand 01 | C16: ='Юнит 17'!AO104 -> 19543.819 | D16: =C16/C$106 -> 0.034532302 | E16: =E15+D16 -> 0.88054425 | F16: =IF(AND(E16<=0),"C",IF(E16<=0.8,"A",IF(E16<=0.95,"B","C"))) -> B | G16: =VLOOKUP(B$4:B$104,I$4:M$104,5,0) -> C | I16: ww 1022 коричневые | J16: ='Юнит 17'!U48 -> 30 | K16: =J16/J$106 -> 0.017699115 | L16: =L15+K16 -> 0.84719764 | M16: =_xlfn.IFS(L16<80%,"A",L16<=95%,"B",L16>95%,"C") -> B
B17: wwl8032 коричневые золото | C17: ='Юнит 17'!AO17 -> 13512.606 | D17: =C17/C$106 -> 0.023875651 | E17: =E16+D17 -> 0.9044199 | F17: =IF(AND(E17<=0),"C",IF(E17<=0.8,"A",IF(E17<=0.95,"B","C"))) -> B | G17: =VLOOKUP(B$4:B$104,I$4:M$104,5,0) -> B | I17: wwl8032 коричневые золото | J17: ='Юнит 17'!U17 -> 27 | K17: =J17/J$106 -> 0.015929204 | L17: =L16+K17 -> 0.86312684 | M17: =_xlfn.IFS(L17<80%,"A",L17<=95%,"B",L17>95%,"C") -> B
B18: ww 2018 желтые | C18: ='Юнит 17'!AO50 -> 13346.652 | D18: =C18/C$106 -> 0.023582423 | E18: =E17+D18 -> 0.92800232 | F18: =IF(AND(E18<=0),"C",IF(E18<=0.8,"A",IF(E18<=0.95,"B","C"))) -> B | G18: =VLOOKUP(B$4:B$104,I$4:M$104,5,0) -> B | I18: ww 2018 желтые | J18: ='Юнит 17'!U50 -> 26 | K18: =J18/J$106 -> 0.015339233 | L18: =L17+K18 -> 0.87846608 | M18: =_xlfn.IFS(L18<80%,"A",L18<=95%,"B",L18>95%,"C") -> B
B19: ww 1022 коричневые | C19: ='Юнит 17'!AO48 -> 13296.046 | D19: =C19/C$106 -> 0.023493007 | E19: =E18+D19 -> 0.95149533 | F19: =IF(AND(E19<=0),"C",IF(E19<=0.8,"A",IF(E19<=0.95,"B","C"))) -> C | G19: =VLOOKUP(B$4:B$104,I$4:M$104,5,0) -> B | I19: ww 2018 черные | J19: ='Юнит 17'!U49 -> 23 | K19: =J19/J$106 -> 0.013569322 | L19: =L18+K19 -> 0.8920354 | M19: =_xlfn.IFS(L19<80%,"A",L19<=95%,"B",L19>95%,"C") -> B
B20: ww 2018 черные | C20: ='Юнит 17'!AO49 -> 10258.196 | D20: =C20/C$106 -> 0.018125379 | E20: =E19+D20 -> 0.96962071 | F20: =IF(AND(E20<=0),"C",IF(E20<=0.8,"A",IF(E20<=0.95,"B","C"))) -> C | G20: =VLOOKUP(B$4:B$104,I$4:M$104,5,0) -> B | I20: MR8854 C2 Жен | J20: ='Юнит 17'!U8 -> 22 | K20: =J20/J$106 -> 0.012979351 | L20: =L19+K20 -> 0.90501475 | M20: =_xlfn.IFS(L20<80%,"A",L20<=95%,"B",L20>95%,"C") -> B
B21: MR8854 C2 Жен | C21: ='Юнит 17'!AO8 -> 9350.0704 | D21: =C21/C$106 -> 0.016520796 | E21: =E20+D21 -> 0.98614151 | F21: =IF(AND(E21<=0),"C",IF(E21<=0.8,"A",IF(E21<=0.95,"B","C"))) -> C | G21: =VLOOKUP(B$4:B$104,I$4:M$104,5,0) -> B | I21: flip синие | J21: ='Юнит 17'!U14 -> 22 | K21: =J21/J$106 -> 0.012979351 | L21: =L20+K21 -> 0.9179941 | M21: =_xlfn.IFS(L21<80%,"A",L21<=95%,"B",L21>95%,"C") -> B
B22: flip синие | C22: ='Юнит 17'!AO14 -> 7721.7316 | D22: =C22/C$106 -> 0.013643657 | E22: =E21+D22 -> 0.99978516 | F22: =IF(AND(E22<=0),"C",IF(E22<=0.8,"A",IF(E22<=0.95,"B","C"))) -> C | G22: =VLOOKUP(B$4:B$104,I$4:M$104,5,0) -> B | I22: sh3 | J22: ='Юнит 17'!U28 -> 21 | K22: =J22/J$106 -> 0.012389381 | L22: =L21+K22 -> 0.93038348 | M22: =_xlfn.IFS(L22<80%,"A",L22<=95%,"B",L22>95%,"C") -> B
B23: ww 203 черные | C23: ='Юнит 17'!AO44 -> 5766.4422 | D23: =C23/C$106 -> 0.010188824 | E23: =E22+D23 -> 1.009974 | F23: =IF(AND(E23<=0),"C",IF(E23<=0.8,"A",IF(E23<=0.95,"B","C"))) -> C | G23: =VLOOKUP(B$4:B$104,I$4:M$104,5,0) -> B | I23: wwl8032 хром металл | J23: ='Юнит 17'!U18 -> 18 | K23: =J23/J$106 -> 0.010619469 | L23: =L22+K23 -> 0.94100295 | M23: =_xlfn.IFS(L23<80%,"A",L23<=95%,"B",L23>95%,"C") -> B
B24: sports зеленые | C24: ='Юнит 17'!AO21 -> 2379.5724 | D24: =C24/C$106 -> 0.0042045065 | E24: =E23+D24 -> 1.0141785 | F24: =IF(AND(E24<=0),"C",IF(E24<=0.8,"A",IF(E24<=0.95,"B","C"))) -> C | G24: =VLOOKUP(B$4:B$104,I$4:M$104,5,0) -> C | I24: ww 203 черные | J24: ='Юнит 17'!U44 -> 15 | K24: =J24/J$106 -> 0.0088495575 | L24: =L23+K24 -> 0.94985251 | M24: =_xlfn.IFS(L24<80%,"A",L24<=95%,"B",L24>95%,"C") -> B
