Workbook

Sheet Реклама
B2: БАЛАНС | E2: СЧЕТ | H2: ПРОМОБОНУСЫ | K2: Неделя
B3: Номер документа | C3: Сумма | D3: Даты | E3: Номер документа | F3: Сумма | G3: Даты | H3: Номер документа | I3: Сумма | J3: Даты
B4: 277433850 | C4: 1376 | D4: 28-31.12 | E4: 277433847 | F4: 25829 | G4: 28-31.12 | H4: 0 | I4: 109 | J4: 29-31.12 | K4: 1
B5: 277539131 | C5: 1150 | D5: 36951 | E5: 277609313 | F5: 21489 | G5: 36982 | H5: 0 | I5: 363 | J5: 36982
B6: 279208603 | C6: 3455 | D6: 37168 | E6: 279208599 | F6: 51313 | G6: 37199 | H6: 0 | I6: 569 | J6: 37200 | K6: 2
B7: 280269091 | C7: 10268 | D7: 11-18.01 | E7: 280221209 | F7: 99763 | G7: 11-18.01 | H7: 0 | I7: 557 | J7: 12-18.01 | K7: 3
B8: 281267335 | C8: 70408 | D8: 19-25.01 | E8: 281348313 | F8: 67741 | G8: 18-25.01 | H8: 0 | I8: 195 | J8: 19-25.01 | K8: 4
B9: 282258474 | C9: 25521 | D9: 25-31.01 | E9: 282345086 | F9: 133680 | G9: 25-31.01 | H9: 0 | I9: 80 | J9: 26-31.01 | K9: 5
B10: 282365257 | C10: 1268 | D10: 46054 | E10: 282392960 | F10: 4672 | G10: 46054 | K10: 6
B11: 283332206 | C11: 111419 | D11: 37469 | E11: 283415801 | F11: 126688 | G11: 37469 | H11: 0 | I11: 3554 | J11: 37440
B12: 284423647 | C12: 145581 | D12: 08-15.02 | E12: 284416459 | F12: 138670 | G12: 08-15.02 | H12: 0 | I12: 44 | J12: 46063 | K12: 7
B13: 285348588 | C13: 50989 | D13: 15-22.02 | E13: 285348587 | F13: 265182 | G13: 15-22.02 | K13: 8
H39: .

Sheet Сводная
B2: Период | E2: Дата поступления дс | F2: Итого к перечислению на счет, руб | G2: шт. | J2: ВБ реализовал товар (выручка с СПП) | M2: Выручка до вычета комиссии ВБ | P2: Себестоимость продаж | Q2: Логистика WB | R2: Комиссия WB | S2: Хранение WB | T2: Платная приемка WB | U2: Штрафы WB | V2: Прочие удержания WB | W2: Реклама БАЛАНС | X2: Реклама СЧЕТ | Y2: Блогеры | Z2: Налог | AA2: Прочие поступления WB | AB2: Прибыль до вычета налогов | AC2: Прибыль после вычета налогов | AD2: Итог месяц | AE2: % Cебестоимости | AF2: Маржинальность, % | AG2: Рентабельность, % | AH2: Доля рекламы, %
B3: Месяц | C3: Даты | D3: Нед | G3: Заказы | H3: Продажи | I3: Возвраты | J3: Продажи | K3: Возвраты | L3: Общая | M3: Продажи | N3: Возвраты | O3: Общая
B4: Декабрь очки | C4: 29-31.12 | D4: 1 | F4: =IFERROR(O4-SUM(Q4:W4)+AA4,0) -> 62313.298 | G4: =ДЕКАБРЬ!N100 -> 129 | H4: =ДЕКАБРЬ!S100 -> 127 | I4: =ДЕКАБРЬ!T100 -> -5 | J4: =ДЕКАБРЬ!V100 -> 118047.57 | K4: =ДЕКАБРЬ!W100 -> -6409 | L4: =IFERROR(J4+K4,0) -> 111638.57 | M4: =ДЕКАБРЬ!Y100 -> 138964.57 | N4: =ДЕКАБРЬ!Z100 -> -7526 | O4: =IFERROR(M4+N4,0) -> 131438.57 | P4: =ДЕКАБРЬ!AD100 -> 15240.45 | Q4: =ДЕКАБРЬ!AG100 -> 17381.1 | R4: =ДЕКАБРЬ!AE100 -> 48126.54 | S4: =ДЕКАБРЬ!AL100 -> 3615.9322 | T4: 1.7 | U4: =ДЕКАБРЬ!AM100 -> 0 | W4: =ДЕКАБРЬ!AH100 -> 0 | X4: =ДЕКАБРЬ!AI100 -> 0 | Y4: =ДЕКАБРЬ!AK100 -> 0 | Z4: =ДЕКАБРЬ!AN100 -> 6374.5623 | AB4: =O4-SUM(P4:Y4)+AA4 -> 47072.848 | AC4: =O4-SUM(P4:Z4)+AA4 -> 40698.285 | AD4: =SUM(AC4:AC5) -> 40697.998 | AE4: =P4/O4 -> 0.11595112 | AF4: =AC4/P4 -> 2.6704123 | AG4: =AC4/O4 -> 0.30963731 | AH4: =(W4+X4+Y4)/O4 -> 0
B5: Декабрь туники | C5: 29-31.12 | D5: 1 | F5: =IFERROR(O5-SUM(Q5:W5)+AA5,0) -> -0.28775523 | G5: =ДЕКАБРЬ!N108 -> 0 | H5: =ДЕКАБРЬ!S108 -> 0 | I5: =ДЕКАБРЬ!T108 -> 0 | J5: =ДЕКАБРЬ!V108 -> 0 | K5: =ДЕКАБРЬ!W108 -> 0 | L5: =IFERROR(J5+K5,0) -> 0 | M5: =ДЕКАБРЬ!Y108 -> 0 | N5: =ДЕКАБРЬ!Z108 -> 0 | O5: =IFERROR(M5+N5,0) -> 0 | P5: =ДЕКАБРЬ!AD108 -> 0 | Q5: =ДЕКАБРЬ!AG108 -> 0 | R5: =ДЕКАБРЬ!AE108 -> 0 | S5: =ДЕКАБРЬ!AL108 -> 0.28775523 | U5: =ДЕКАБРЬ!AM108 -> 0 | W5: =ДЕКАБРЬ!AH108 -> 0 | X5: =ДЕКАБРЬ!AI108 -> 0 | Y5: =ДЕКАБРЬ!AK108 -> 0 | Z5: =ДЕКАБРЬ!AN108 -> 0 | AB5: =O5-SUM(P5:Y5)+AA5 -> -0.28775523 | AC5: =O5-SUM(P5:Z5)+AA5 -> -0.28775523 | AE5: =P5/O5 -> #DIV/0! | AF5: =AC5/P5 -> #DIV/0! | AG5: =AC5/O5 -> #DIV/0! | AH5: =(W5+X5+Y5)/O5 -> #DIV/0!
B6: Январь очки | C6: 01.01-01.02 | D6: 1-5 | F6: =IFERROR(O6-SUM(Q6:W6)+AA6,0) -> 955718.86 | G6: =ЯНВАРЬ!N100 -> 4961 | H6: =ЯНВАРЬ!S100 -> 2362 | I6: =ЯНВАРЬ!T100 -> -53 | J6: =ЯНВАРЬ!V100 -> 1728382.8 | K6: =ЯНВАРЬ!W100 -> -44657.88 | L6: =IFERROR(J6+K6,0) -> 1683724.9 | M6: =ЯНВАРЬ!Y100 -> 2303342.1 | N6: =ЯНВАРЬ!Z100 -> -58267.04 | O6: =IFERROR(M6+N6,0) -> 2245075 | P6: =ЯНВАРЬ!AD100 -> 292876.64 | Q6: =ЯНВАРЬ!AG100 -> 276475.65 | R6: =ЯНВАРЬ!AE100 -> 833669.77 | S6: =ЯНВАРЬ!AL100 -> 40333.14 | U6: =ЯНВАРЬ!AM100 -> 0 | V6: 25431.6 | W6: =ЯНВАРЬ!AH100 -> 113446 | X6: =ЯНВАРЬ!AI100 -> 404487 | Y6: =ЯНВАРЬ!AK100 -> 0 | Z6: =ЯНВАРЬ!AN100 -> 96140.692 | AB6: =O6-SUM(P6:Y6)+AA6 -> 258355.22 | AC6: =O6-SUM(P6:Z6)+AA6 -> 162214.53 | AD6: =SUM(AC6:AC8) -> 161855.14 | AE6: =P6/O6 -> 0.13045294 | AF6: =AC6/P6 -> 0.55386639 | AG6: =AC6/O6 -> 0.0722535 | AH6: =(W6+X6+Y6)/O6 -> 0.23069741
B7: Январь туники | C7: 01.01-01.02 | D7: 1-5 | F7: =IFERROR(O7-SUM(Q7:W7)+AA7,0) -> -186.4297 | G7: =ЯНВАРЬ!N108 -> 1 | H7: =ЯНВАРЬ!S108 -> 0 | I7: =ЯНВАРЬ!T108 -> 0 | J7: =ЯНВАРЬ!V108 -> 0 | K7: =ЯНВАРЬ!W108 -> 0 | L7: =IFERROR(J7+K7,0) -> 0 | M7: =ЯНВАРЬ!Y108 -> 0 | N7: =ЯНВАРЬ!Z108 -> 0 | O7: =IFERROR(M7+N7,0) -> 0 | P7: =ЯНВАРЬ!AD108 -> 0 | Q7: =ЯНВАРЬ!AG108 -> 183.22 | R7: =ЯНВАРЬ!AE108 -> 0 | S7: =ЯНВАРЬ!AL108 -> 3.209704 | U7: =ЯНВАРЬ!AM108 -> 0 | W7: =ЯНВАРЬ!AH108 -> 0 | X7: =ЯНВАРЬ!AI108 -> 0 | Y7: =ЯНВАРЬ!AK108 -> 0 | Z7: =ЯНВАРЬ!AN108 -> 0 | AB7: =O7-SUM(P7:Y7)+AA7 -> -186.4297 | AC7: =O7-SUM(P7:Z7)+AA7 -> -186.4297 | AE7: =P7/O7 -> #DIV/0! | AF7: =AC7/P7 -> #DIV/0! | AG7: =AC7/O7 -> #DIV/0! | AH7: =(W7+X7+Y7)/O7 -> #DIV/0!
B8: Январь шапки | C8: 01.01-01.02 | D8: 1-5 | F8: =IFERROR(O8-SUM(Q8:W8)+AA8,0) -> -172.96 | G8: =ЯНВАРЬ!N119 -> 0 | H8: =ЯНВАРЬ!S119 -> 0 | I8: =ЯНВАРЬ!T119 -> 0 | J8: =ЯНВАРЬ!V119 -> 0 | K8: =ЯНВАРЬ!W119 -> 0 | L8: =IFERROR(J8+K8,0) -> 0 | M8: =ЯНВАРЬ!Y119 -> 0 | N8: =ЯНВАРЬ!Z119 -> 0 | O8: =IFERROR(M8+N8,0) -> 0 | P8: =ЯНВАРЬ!AD119 -> 0 | Q8: =ЯНВАРЬ!AG119 -> 172.96 | R8: =ЯНВАРЬ!AE119 -> 0 | S8: =ЯНВАРЬ!AL119 -> 0 | U8: =ЯНВАРЬ!AM119 -> 0 | W8: =ЯНВАРЬ!AH119 -> 0 | X8: =ЯНВАРЬ!AI119 -> 0 | Y8: =ЯНВАРЬ!AK119 -> 0 | Z8: =ЯНВАРЬ!AN119 -> 0 | AB8: =O8-SUM(P8:Y8)+AA8 -> -172.96 | AC8: =O8-SUM(P8:Z8)+AA8 -> -172.96 | AE8: =P8/O8 -> #DIV/0! | AF8: =AC8/P8 -> #DIV/0! | AG8: =AC8/O8 -> #DIV/0! | AH8: =(W8+X8+Y8)/O8 -> #DIV/0!
B9: Февраль 1 | C9: 02-08.02 | D9: 6 | AD9: =SUM(AC9:AC13) -> 569969.91 | AE9: =P9/O9 -> #DIV/0! | AF9: =AC9/P9 -> #DIV/0! | AG9: =AC9/O9 -> #DIV/0! | AH9: =(W9+X9+Y9)/O9 -> #DIV/0!
B10: Февраль 2 | C10: 09-15.02 | D10: 7 | AE10: =P10/O10 -> #DIV/0! | AF10: =AC10/P10 -> #DIV/0! | AG10: =AC10/O10 -> #DIV/0! | AH10: =(W10+X10+Y10)/O10 -> #DIV/0!
B11: Февраль 3 очки | C11: 16-22.02 | D11: 8 | F11: =IFERROR(O11-SUM(Q11:W11)+AA11,0) -> 1204943.2 | G11: ='Юнит 8'!N105 -> 4413 | H11: ='Юнит 8'!S105 -> 2295 | I11: ='Юнит 8'!T105 -> -43 | J11: ='Юнит 8'!V105 -> 1593380.1 | K11: ='Юнит 8'!W105 -> -29254.63 | L11: =IFERROR(J11+K11,0) -> 1564125.5 | M11: ='Юнит 8'!Y105 -> 2501418.9 | N11: ='Юнит 8'!Z105 -> -47007.29 | O11: =IFERROR(M11+N11,0) -> 2454411.6 | P11: ='Юнит 8'!AD105 -> 280478.83 | Q11: ='Юнит 8'!AG105 -> 267875.33 | R11: ='Юнит 8'!AE105 -> 918234.84 | S11: ='Юнит 8'!AL105 -> 8623.9028 | U11: ='Юнит 8'!AM105 -> 466 | V11: 3279.36 | W11: ='Юнит 8'!AH105 -> 50989 | X11: ='Юнит 8'!AI105 -> 265182 | Y11: ='Юнит 8'!AK105 -> 0 | Z11: ='Юнит 8'!AN105 -> 89311.563 | AB11: =O11-SUM(P11:Y11)+AA11 -> 659282.34 | AC11: =O11-SUM(P11:Z11)+AA11 -> 569970.77 | AE11: =P11/O11 -> 0.11427538 | AF11: =AC11/P11 -> 2.0321347 | AG11: =AC11/O11 -> 0.23222298 | AH11: =(W11+X11+Y11)/O11 -> 0.12881743
B12: Февраль 3 туники | C12: 16-22.02 | D12: 8 | F12: =IFERROR(O12-SUM(Q12:W12)+AA12,0) -> -0.86724686 | G12: ='Юнит 8'!N113 -> 0 | H12: ='Юнит 8'!S113 -> 0 | I12: ='Юнит 8'!T113 -> 0 | J12: ='Юнит 8'!V113 -> 0 | K12: ='Юнит 8'!W113 -> 0 | L12: =IFERROR(J12+K12,0) -> 0 | M12: ='Юнит 8'!Y113 -> 0 | N12: ='Юнит 8'!Z113 -> 0 | O12: =IFERROR(M12+N12,0) -> 0 | P12: ='Юнит 8'!AD113 -> 0 | Q12: ='Юнит 8'!AG113 -> 0 | R12: ='Юнит 8'!AE113 -> 0 | S12: ='Юнит 8'!AL113 -> 0.86724686 | U12: ='Юнит 8'!AM113 -> 0 | W12: ='Юнит 8'!AH113 -> 0 | X12: ='Юнит 8'!AI113 -> 0 | Y12: ='Юнит 8'!AK113 -> 0 | Z12: ='Юнит 8'!AN113 -> 0 | AB12: =O12-SUM(P12:Y12)+AA12 -> -0.86724686 | AC12: =O12-SUM(P12:Z12)+AA12 -> -0.86724686 | AE12: =P12/O12 -> #DIV/0! | AF12: =AC12/P12 -> #DIV/0! | AG12: =AC12/O12 -> #DIV/0! | AH12: =(W12+X12+Y12)/O12 -> #DIV/0!
B13: Февраль 4 | C13: 23.02-01.03 | D13: 9 | AB13: =O13-SUM(P13:Y13)+AA13 -> 0 | AC13: =O13-SUM(P13:Z13)+AA13 -> 0 | AE13: =P13/O13 -> #DIV/0! | AF13: =AC13/P13 -> #DIV/0! | AG13: =AC13/O13 -> #DIV/0! | AH13: =(W13+X13+Y13)/O13 -> #DIV/0!
AB14: =O14-SUM(P14:Y14)+AA14 -> 0 | AC14: =O14-SUM(P14:Z14)+AA14 -> 0 | AE14: =P14/O14 -> #DIV/0! | AF14: =AC14/P14 -> #DIV/0! | AG14: =AC14/O14 -> #DIV/0! | AH14: =(W14+X14+Y14)/O14 -> #DIV/0!
B15: Итого | F15: =SUM(F8:F14) -> 1204769.3 | G15: =SUM(G8:G14) -> 4413 | H15: =SUM(H8:H14) -> 2295 | I15: =SUM(I8:I14) -> -43 | J15: =SUM(J8:J14) -> 1593380.1 | K15: =SUM(K8:K14) -> -29254.63 | L15: =SUM(L8:L14) -> 1564125.5 | M15: =SUM(M8:M14) -> 2501418.9 | ... AD15: =SUM(AD8:AD14) -> 569969.91 | AE15: =P15/O15 -> 0.11427538 | AF15: =AC15/P15 -> 2.031515 | AG15: =AC15/O15 -> 0.23215216 | AH15: =(W15+X15+Y15)/O15 -> 0.12881743
M16: % от выручки за весь период
N17: =-N15/M15 -> 0.01879225 | P17: =P15/$O$15 -> 0.11427538 | Q17: =Q15/$O$15 -> 0.10921081 | R17: =R15/$O$15 -> 0.37411608 | S17: =S15/$O$15 -> 0.0035139868 | T17: =T15/$O$15 -> 0 | U17: =U15/$O$15 -> 0.00018986221 | V17: =V15/$O$15 -> 0.0013361084 | W17: =W15/$O$15 -> 0.020774429 | ... Z17: =Z15/$O$15 -> 0.036388177 | AC17: =AC15/P15 -> 2.031515 | AD17: Маржинальность, %
W18: =(W15+X15)/O15 -> 0.12881743 | AC18: =AC15/O15 -> 0.23215216 | AD18: Рентабельность, %
B19: ЯНВАРЬ очки | G19: =G6 -> 4961 | H19: =H6 -> 2362 | I19: =I6 -> -53 | J19: =J6 -> 1728382.8 | K19: =K6 -> -44657.88 | L19: =L6 -> 1683724.9 | M19: =M6 -> 2303342.1 | N19: =N6 -> -58267.04 | ... AC19: =AC6 -> 162214.53
N20: =-N19/M19 -> 0.025296738 | P20: =P19/$O$19 -> 0.13045294 | Q20: =Q19/$O$19 -> 0.12314762 | R20: =R19/$O$19 -> 0.3713327 | S20: =S19/$O$19 -> 0.017965164 | T20: =T19/$O$19 -> 0 | U20: =U19/$O$19 -> 0 | V20: =V19/$O$19 -> 0.011327728 | W20: =W19/$O$19 -> 0.050531051 | ... AA20: =AA19/$O$19 -> 0 | AC20: =AC19/O19 -> 0.0722535

Sheet АВС 8
B2: ОЧКИ
C3: Прибыль | D3: % прибыль | E3: Доля | F3: ABC прибыль | G3: ABC кол-во | J3: Кол-во | K3: % кол-во | L3: Доля | M3: ABC кол-во
B4: QS черные PZ | C4: ='Юнит 8'!AO4 -> 187586.52 | D4: =C4/C$105 -> 0.32723328 | E4: =D4 -> 0.32723328 | F4: =IF(AND(E4<=0),"C",IF(E4<=0.8,"A",IF(E4<=0.95,"B","C"))) -> A | G4: =VLOOKUP(B$4:B$104,I$4:M$104,5,0) -> A | I4: QS черные PZ | J4: ='Юнит 8'!U4 -> 553 | K4: =J4/J$105 -> 0.2455595 | L4: =K4 -> 0.2455595 | M4: =_xlfn.IFS(L4<80%,"A",L4<=95%,"B",L4>95%,"C") -> A | P4: A | Q4: 0.8
B5: QS коричневые PZ | C5: ='Юнит 8'!AO7 -> 67172.51 | D5: =C5/C$105 -> 0.11717836 | E5: =E4+D5 -> 0.44441164 | F5: =IF(AND(E5<=0),"C",IF(E5<=0.8,"A",IF(E5<=0.95,"B","C"))) -> A | G5: =VLOOKUP(B$4:B$104,I$4:M$104,5,0) -> A | I5: QS коричневые PZ | J5: ='Юнит 8'!U7 -> 206 | K5: =J5/J$105 -> 0.091474245 | L5: =L4+K5 -> 0.33703375 | M5: =_xlfn.IFS(L5<80%,"A",L5<=95%,"B",L5>95%,"C") -> A | P5: B | Q5: 0.15
B6: th черн | C6: ='Юнит 8'!AO9 -> 42084.801 | D6: =C6/C$105 -> 0.073414376 | E6: =E5+D6 -> 0.51782601 | F6: =IF(AND(E6<=0),"C",IF(E6<=0.8,"A",IF(E6<=0.95,"B","C"))) -> A | G6: =VLOOKUP(B$4:B$104,I$4:M$104,5,0) -> A | I6: th син | J6: ='Юнит 8'!U10 -> 165 | K6: =J6/J$105 -> 0.073268206 | L6: =L5+K6 -> 0.41030195 | M6: =_xlfn.IFS(L6<80%,"A",L6<=95%,"B",L6>95%,"C") -> A | P6: C | Q6: 0.05
B7: QS синие PZ | C7: ='Юнит 8'!AO5 -> 41232.197 | D7: =C7/C$105 -> 0.071927061 | E7: =E6+D7 -> 0.58975308 | F7: =IF(AND(E7<=0),"C",IF(E7<=0.8,"A",IF(E7<=0.95,"B","C"))) -> A | G7: =VLOOKUP(B$4:B$104,I$4:M$104,5,0) -> A | I7: QS синие PZ | J7: ='Юнит 8'!U5 -> 151 | K7: =J7/J$105 -> 0.06705151 | L7: =L6+K7 -> 0.47735346 | M7: =_xlfn.IFS(L7<80%,"A",L7<=95%,"B",L7>95%,"C") -> A
B8: th син | C8: ='Юнит 8'!AO10 -> 35943.92 | D8: =C8/C$105 -> 0.062701983 | E8: =E7+D8 -> 0.65245506 | F8: =IF(AND(E8<=0),"C",IF(E8<=0.8,"A",IF(E8<=0.95,"B","C"))) -> A | G8: =VLOOKUP(B$4:B$104,I$4:M$104,5,0) -> A | I8: th черн | J8: ='Юнит 8'!U9 -> 135 | K8: =J8/J$105 -> 0.059946714 | L8: =L7+K8 -> 0.53730018 | M8: =_xlfn.IFS(L8<80%,"A",L8<=95%,"B",L8>95%,"C") -> A
B9: QS желтые PZ | C9: ='Юнит 8'!AO6 -> 35702.024 | D9: =C9/C$105 -> 0.06228001 | E9: =E8+D9 -> 0.71473507 | F9: =IF(AND(E9<=0),"C",IF(E9<=0.8,"A",IF(E9<=0.95,"B","C"))) -> A | G9: =VLOOKUP(B$4:B$104,I$4:M$104,5,0) -> A | I9: QS желтые PZ | J9: ='Юнит 8'!U6 -> 126 | K9: =J9/J$105 -> 0.055950266 | L9: =L8+K9 -> 0.59325044 | M9: =_xlfn.IFS(L9<80%,"A",L9<=95%,"B",L9>95%,"C") -> A
B10: flip коричневые | C10: ='Юнит 8'!AO16 -> 24641.241 | D10: =C10/C$105 -> 0.042985147 | E10: =E9+D10 -> 0.75772022 | F10: =IF(AND(E10<=0),"C",IF(E10<=0.8,"A",IF(E10<=0.95,"B","C"))) -> A | G10: =VLOOKUP(B$4:B$104,I$4:M$104,5,0) -> A | I10: sh3 | J10: ='Юнит 8'!U28 -> 96 | K10: =J10/J$105 -> 0.042628774 | L10: =L9+K10 -> 0.63587922 | M10: =_xlfn.IFS(L10<80%,"A",L10<=95%,"B",L10>95%,"C") -> A
B11: flip черные | C11: ='Юнит 8'!AO13 -> 22233.993 | D11: =C11/C$105 -> 0.03878585 | E11: =E10+D11 -> 0.79650607 | F11: =IF(AND(E11<=0),"C",IF(E11<=0.8,"A",IF(E11<=0.95,"B","C"))) -> A | G11: =VLOOKUP(B$4:B$104,I$4:M$104,5,0) -> A | I11: flip черные | J11: ='Юнит 8'!U13 -> 92 | K11: =J11/J$105 -> 0.040852575 | L11: =L10+K11 -> 0.67673179 | M11: =_xlfn.IFS(L11<80%,"A",L11<=95%,"B",L11>95%,"C") -> A
B12: sh3 | C12: ='Юнит 8'!AO28 -> 21229.534 | D12: =C12/C$105 -> 0.03703363 | E12: =E11+D12 -> 0.8335397 | F12: =IF(AND(E12<=0),"C",IF(E12<=0.8,"A",IF(E12<=0.95,"B","C"))) -> B | G12: =VLOOKUP(B$4:B$104,I$4:M$104,5,0) -> A | I12: flip коричневые | J12: ='Юнит 8'!U16 -> 85 | K12: =J12/J$105 -> 0.037744227 | L12: =L11+K12 -> 0.71447602 | M12: =_xlfn.IFS(L12<80%,"A",L12<=95%,"B",L12>95%,"C") -> A
B13: th коричн | C13: ='Юнит 8'!AO12 -> 16922.863 | D13: =C13/C$105 -> 0.029520905 | E13: =E12+D13 -> 0.8630606 | F13: =IF(AND(E13<=0),"C",IF(E13<=0.8,"A",IF(E13<=0.95,"B","C"))) -> B | G13: =VLOOKUP(B$4:B$104,I$4:M$104,5,0) -> B | I13: черные с железкой классика | J13: ='Юнит 8'!U3 -> 74 | K13: =J13/J$105 -> 0.03285968 | L13: =L12+K13 -> 0.7473357 | M13: =_xlfn.IFS(L13<80%,"A",L13<=95%,"B",L13>95%,"C") -> A
B14: MR8854 C2 Жен | C14: ='Юнит 8'!AO8 -> 15508.025 | D14: =C14/C$105 -> 0.027052807 | E14: =E13+D14 -> 0.89011341 | F14: =IF(AND(E14<=0),"C",IF(E14<=0.8,"A",IF(E14<=0.95,"B","C"))) -> B | G14: =VLOOKUP(B$4:B$104,I$4:M$104,5,0) -> A | I14: MR8854 C2 Жен | J14: ='Юнит 8'!U8 -> 68 | K14: =J14/J$105 -> 0.030195382 | L14: =L13+K14 -> 0.77753108 | M14: =_xlfn.IFS(L14<80%,"A",L14<=95%,"B",L14>95%,"C") -> A
B15: th желт | C15: ='Юнит 8'!AO11 -> 12076.316 | D15: =C15/C$105 -> 0.021066399 | E15: =E14+D15 -> 0.91117981 | F15: =IF(AND(E15<=0),"C",IF(E15<=0.8,"A",IF(E15<=0.95,"B","C"))) -> B | G15: =VLOOKUP(B$4:B$104,I$4:M$104,5,0) -> B | I15: th коричн | J15: ='Юнит 8'!U12 -> 68 | K15: =J15/J$105 -> 0.030195382 | L15: =L14+K15 -> 0.80772647 | M15: =_xlfn.IFS(L15<80%,"A",L15<=95%,"B",L15>95%,"C") -> B
B16: wwl8032 коричневые золото | C16: ='Юнит 8'!AO17 -> 9301.5132 | D16: =C16/C$105 -> 0.016225924 | E16: =E15+D16 -> 0.92740573 | F16: =IF(AND(E16<=0),"C",IF(E16<=0.8,"A",IF(E16<=0.95,"B","C"))) -> B | G16: =VLOOKUP(B$4:B$104,I$4:M$104,5,0) -> B | I16: ww 1022 черные | J16: ='Юнит 8'!U45 -> 67 | K16: =J16/J$105 -> 0.029751332 | L16: =L15+K16 -> 0.8374778 | M16: =_xlfn.IFS(L16<80%,"A",L16<=95%,"B",L16>95%,"C") -> B
B17: flip синие | C17: ='Юнит 8'!AO14 -> 9186.5031 | D17: =C17/C$105 -> 0.016025296 | E17: =E16+D17 -> 0.94343103 | F17: =IF(AND(E17<=0),"C",IF(E17<=0.8,"A",IF(E17<=0.95,"B","C"))) -> B | G17: =VLOOKUP(B$4:B$104,I$4:M$104,5,0) -> B | I17: th желт | J17: ='Юнит 8'!U11 -> 42 | K17: =J17/J$105 -> 0.018650089 | L17: =L16+K17 -> 0.85612789 | M17: =_xlfn.IFS(L17<80%,"A",L17<=95%,"B",L17>95%,"C") -> B
B18: ww 1022 коричневые | C18: ='Юнит 8'!AO48 -> 9125.125 | D18: =C18/C$105 -> 0.015918226 | E18: =E17+D18 -> 0.95934925 | F18: =IF(AND(E18<=0),"C",IF(E18<=0.8,"A",IF(E18<=0.95,"B","C"))) -> C | G18: =VLOOKUP(B$4:B$104,I$4:M$104,5,0) -> B | I18: wwl8032 хром металл | J18: ='Юнит 8'!U18 -> 41 | K18: =J18/J$105 -> 0.018206039 | L18: =L17+K18 -> 0.87433393 | M18: =_xlfn.IFS(L18<80%,"A",L18<=95%,"B",L18>95%,"C") -> B
B19: ww 1022 черные | C19: ='Юнит 8'!AO45 -> 8595.4514 | D19: =C19/C$105 -> 0.014994242 | E19: =E18+D19 -> 0.97434349 | F19: =IF(AND(E19<=0),"C",IF(E19<=0.8,"A",IF(E19<=0.95,"B","C"))) -> C | G19: =VLOOKUP(B$4:B$104,I$4:M$104,5,0) -> B | I19: flip синие | J19: ='Юнит 8'!U14 -> 34 | K19: =J19/J$105 -> 0.015097691 | L19: =L18+K19 -> 0.88943162 | M19: =_xlfn.IFS(L19<80%,"A",L19<=95%,"B",L19>95%,"C") -> B
B20: wwl8032 хром металл | C20: ='Юнит 8'!AO18 -> 7347.995 | D20: =C20/C$105 -> 0.012818131 | E20: =E19+D20 -> 0.98716162 | F20: =IF(AND(E20<=0),"C",IF(E20<=0.8,"A",IF(E20<=0.95,"B","C"))) -> C | G20: =VLOOKUP(B$4:B$104,I$4:M$104,5,0) -> B | I20: flip желтые | J20: ='Юнит 8'!U15 -> 32 | K20: =J20/J$105 -> 0.014209591 | L20: =L19+K20 -> 0.90364121 | M20: =_xlfn.IFS(L20<80%,"A",L20<=95%,"B",L20>95%,"C") -> B
B21: flip желтые | C21: ='Юнит 8'!AO15 -> 6832.1996 | D21: =C21/C$105 -> 0.011918357 | E21: =E20+D21 -> 0.99907998 | F21: =IF(AND(E21<=0),"C",IF(E21<=0.8,"A",IF(E21<=0.95,"B","C"))) -> C | G21: =VLOOKUP(B$4:B$104,I$4:M$104,5,0) -> B | I21: ww 1022 коричневые | J21: ='Юнит 8'!U48 -> 31 | K21: =J21/J$105 -> 0.013765542 | L21: =L20+K21 -> 0.91740675 | M21: =_xlfn.IFS(L21<80%,"A",L21<=95%,"B",L21>95%,"C") -> B
B22: ww 2018 черные | C22: ='Юнит 8'!AO49 -> 6086.6702 | D22: =C22/C$105 -> 0.010617826 | E22: =E21+D22 -> 1.0096978 | F22: =IF(AND(E22<=0),"C",IF(E22<=0.8,"A",IF(E22<=0.95,"B","C"))) -> C | G22: =VLOOKUP(B$4:B$104,I$4:M$104,5,0) -> B | I22: wwl8032 коричневые золото | J22: ='Юнит 8'!U17 -> 30 | K22: =J22/J$105 -> 0.013321492 | L22: =L21+K22 -> 0.93072824 | M22: =_xlfn.IFS(L22<80%,"A",L22<=95%,"B",L22>95%,"C") -> B
B23: ww 1022 желтые | C23: ='Юнит 8'!AO47 -> 4570.1747 | D23: =C23/C$105 -> 0.0079723919 | E23: =E22+D23 -> 1.0176702 | F23: =IF(AND(E23<=0),"C",IF(E23<=0.8,"A",IF(E23<=0.95,"B","C"))) -> C | G23: =VLOOKUP(B$4:B$104,I$4:M$104,5,0) -> C | I23: ww 2018 черные | J23: ='Юнит 8'!U49 -> 29 | K23: =J23/J$105 -> 0.012877442 | L23: =L22+K23 -> 0.94360568 | M23: =_xlfn.IFS(L23<80%,"A",L23<=95%,"B",L23>95%,"C") -> B
B24: MR Р1894 черные | C24: ='Юнит 8'!AO89 -> 2625.4827 | D24: =C24/C$105 -> 0.004579995 | E24: =E23+D24 -> 1.0222502 | F24: =IF(AND(E24<=0),"C",IF(E24<=0.8,"A",IF(E24<=0.95,"B","C"))) -> C | G24: =VLOOKUP(B$4:B$104,I$4:M$104,5,0) -> C | I24: sh1 | J24: ='Юнит 8'!U26 -> 26 | K24: =J24/J$105 -> 0.011545293 | L24: =L23+K24 -> 0.95515098 | M24: =_xlfn.IFS(L24<80%,"A",L24<=95%,"B",L24>95%,"C") -> C
B25: Chenlong черные | C25: ='Юнит 8'!AO76 -> 945.21524 | D25: =C25/C$105 -> 0.0016488705 | E25: =E24+D25 -> 1.0238991 | F25: =IF(AND(E25<=0),"C",IF(E25<=0.8,"A",IF(E25<=0.95,"B","C"))) -> C | G25: =VLOOKUP(B$4:B$104,I$4:M$104,5,0) -> C | I25: ww 1022 желтые | J25: ='Юнит 8'!U47 -> 13 | K25: =J25/J$105 -> 0.0057726465 | L25: =L24+K25 -> 0.96092362 | M25: =_xlfn.IFS(L25<80%,"A",L25<=95%,"B",L25>95%,"C") -> C
B26: sportlife красные | C26: ='Юнит 8'!AO25 -> 749.7631 | D26: =C26/C$105 -> 0.0013079161 | E26: =E25+D26 -> 1.025207 | F26: =IF(AND(E26<=0),"C",IF(E26<=0.8,"A",IF(E26<=0.95,"B","C"))) -> C | G26: =VLOOKUP(B$4:B$104,I$4:M$104,5,0) -> C | I26: ww 203 черные | J26: ='Юнит 8'!U44 -> 9 | K26: =J26/J$105 -> 0.0039964476 | L26: =L25+K26 -> 0.96492007 | M26: =_xlfn.IFS(L26<80%,"A",L26<=95%,"B",L26>95%,"C") -> C
B27: MANNA2114 | C27: ='Юнит 8'!AO67 -> 701.1945 | D27: =C27/C$105 -> 0.0012231912 | E27: =E26+D27 -> 1.0264302 | F27: =IF(AND(E27<=0),"C",IF(E27<=0.8,"A",IF(E27<=0.95,"B","C"))) -> C | G27: =VLOOKUP(B$4:B$104,I$4:M$104,5,0) -> C | I27: sh09 | J27: ='Юнит 8'!U33 -> 8 | K27: =J27/J$105 -> 0.0035523979 | L27: =L26+K27 -> 0.96847247 | M27: =_xlfn.IFS(L27<80%,"A",L27<=95%,"B",L27>95%,"C") -> C
B28: Linhai Baiyi розовая линза | C28: ='Юнит 8'!AO88 -> 653.61643 | D28: =C28/C$105 -> 0.0011401941 | E28: =E27+D28 -> 1.0275704 | F28: =IF(AND(E28<=0),"C",IF(E28<=0.8,"A",IF(E28<=0.95,"B","C"))) -> C | G28: =VLOOKUP(B$4:B$104,I$4:M$104,5,0) -> C | I28: ww 2018 желтые | J28: ='Юнит 8'!U50 -> 7 | K28: =J28/J$105 -> 0.0031083481 | L28: =L27+K28 -> 0.97158082 | M28: =_xlfn.IFS(L28<80%,"A",L28<=95%,"B",L28>95%,"C") -> C
B29: кс_черные_тест | C29: ='Юнит 8'!AO101 -> 617.01293 | D29: =C29/C$105 -> 0.0010763415 | E29: =E28+D29 -> 1.0286467 | F29: =IF(AND(E29<=0),"C",IF(E29<=0.8,"A",IF(E29<=0.95,"B","C"))) -> C | G29: =VLOOKUP(B$4:B$104,I$4:M$104,5,0) -> C | I29: sh2 | J29: ='Юнит 8'!U27 -> 6 | K29: =J29/J$105 -> 0.0026642984 | L29: =L28+K29 -> 0.97424512 | M29: =_xlfn.IFS(L29<80%,"A",L29<=95%,"B",L29>95%,"C") -> C
B30: MANNA2107 | C30: ='Юнит 8'!AO60 -> 587.15632 | D30: =C30/C$105 -> 0.0010242585 | E30: =E29+D30 -> 1.029671 | F30: =IF(AND(E30<=0),"C",IF(E30<=0.8,"A",IF(E30<=0.95,"B","C"))) -> C | G30: =VLOOKUP(B$4:B$104,I$4:M$104,5,0) -> C | I30: Hengda Optical черные | J30: ='Юнит 8'!U81 -> 6 | K30: =J30/J$105 -> 0.0026642984 | L30: =L29+K30 -> 0.97690941 | M30: =_xlfn.IFS(L30<80%,"A",L30<=95%,"B",L30>95%,"C") -> C
B31: ww 8010 черные | C31: ='Юнит 8'!AO51 -> 506.35831 | D31: =C31/C$105 -> 0.00088331127 | E31: =E30+D31 -> 1.0305543 | F31: =IF(AND(E31<=0),"C",IF(E31<=0.8,"A",IF(E31<=0.95,"B","C"))) -> C | G31: =VLOOKUP(B$4:B$104,I$4:M$104,5,0) -> C | I31: sh10 | J31: ='Юнит 8'!U34 -> 5 | K31: =J31/J$105 -> 0.0022202487 | L31: =L30+K31 -> 0.97912966 | M31: =_xlfn.IFS(L31<80%,"A",L31<=95%,"B",L31>95%,"C") -> C
B32: sh15 | C32: ='Юнит 8'!AO39 -> 506.18738 | D32: =C32/C$105 -> 0.00088301311 | E32: =E31+D32 -> 1.0314373 | F32: =IF(AND(E32<=0),"C",IF(E32<=0.8,"A",IF(E32<=0.95,"B","C"))) -> C | G32: =VLOOKUP(B$4:B$104,I$4:M$104,5,0) -> C | I32: MR Р1894 черные | J32: ='Юнит 8'!U89 -> 4 | K32: =J32/J$105 -> 0.0017761989 | L32: =L31+K32 -> 0.98090586 | M32: =_xlfn.IFS(L32<80%,"A",L32<=95%,"B",L32>95%,"C") -> C
B33: MANNA2119 | C33: ='Юнит 8'!AO72 -> 459.0738 | D33: =C33/C$105 -> 0.00080082633 | E33: =E32+D33 -> 1.0322381 | F33: =IF(AND(E33<=0),"C",IF(E33<=0.8,"A",IF(E33<=0.95,"B","C"))) -> C | G33: =VLOOKUP(B$4:B$104,I$4:M$104,5,0) -> C | I33: MANNA2119 | J33: ='Юнит 8'!U72 -> 3 | K33: =J33/J$105 -> 0.0013321492 | L33: =L32+K33 -> 0.98223801 | M33: =_xlfn.IFS(L33<80%,"A",L33<=95%,"B",L33>95%,"C") -> C
B34: sh09 | C34: ='Юнит 8'!AO33 -> 436.78676 | D34: =C34/C$105 -> 0.00076194794 | E34: =E33+D34 -> 1.0330001 | F34: =IF(AND(E34<=0),"C",IF(E34<=0.8,"A",IF(E34<=0.95,"B","C"))) -> C | G34: =VLOOKUP(B$4:B$104,I$4:M$104,5,0) -> C | I34: MANNA2120 | J34: ='Юнит 8'!U73 -> 3 | K34: =J34/J$105 -> 0.0013321492 | L34: =L33+K34 -> 0.98357016 | M34: =_xlfn.IFS(L34<80%,"A",L34<=95%,"B",L34>95%,"C") -> C
B35: Linhai Baiyi серая линза | C35: ='Юнит 8'!AO87 -> 430.51833 | D35: =C35/C$105 -> 0.00075101305 | E35: =E34+D35 -> 1.0337511 | F35: =IF(AND(E35<=0),"C",IF(E35<=0.8,"A",IF(E35<=0.95,"B","C"))) -> C | G35: =VLOOKUP(B$4:B$104,I$4:M$104,5,0) -> C | I35: Chenlong черные | J35: ='Юнит 8'!U76 -> 3 | K35: =J35/J$105 -> 0.0013321492 | L35: =L34+K35 -> 0.98490231 | M35: =_xlfn.IFS(L35<80%,"A",L35<=95%,"B",L35>95%,"C") -> C
B36: sh19 | C36: ='Юнит 8'!AO43 -> 376.87501 | D36: =C36/C$105 -> 0.00065743554 | E36: =E35+D36 -> 1.0344085 | F36: =IF(AND(E36<=0),"C",IF(E36<=0.8,"A",IF(E36<=0.95,"B","C"))) -> C | G36: =VLOOKUP(B$4:B$104,I$4:M$104,5,0) -> C | I36: Linhai Baiyi розовая линза | J36: ='Юнит 8'!U88 -> 3 | K36: =J36/J$105 -> 0.0013321492 | L36: =L35+K36 -> 0.98623446 | M36: =_xlfn.IFS(L36<80%,"A",L36<=95%,"B",L36>95%,"C") -> C
B37: sh10 | C37: ='Юнит 8'!AO34 -> 370.3062 | D37: =C37/C$105 -> 0.00064597664 | E37: =E36+D37 -> 1.0350545 | F37: =IF(AND(E37<=0),"C",IF(E37<=0.8,"A",IF(E37<=0.95,"B","C"))) -> C | G37: =VLOOKUP(B$4:B$104,I$4:M$104,5,0) -> C | I37: sportlife красные | J37: ='Юнит 8'!U25 -> 2 | K37: =J37/J$105 -> 0.00088809947 | L37: =L36+K37 -> 0.98712256 | M37: =_xlfn.IFS(L37<80%,"A",L37<=95%,"B",L37>95%,"C") -> C
B38: Иу Диту серый | C38: ='Юнит 8'!AO91 -> 324.66858 | D38: =C38/C$105 -> 0.0005663646 | E38: =E37+D38 -> 1.0356209 | F38: =IF(AND(E38<=0),"C",IF(E38<=0.8,"A",IF(E38<=0.95,"B","C"))) -> C | G38: =VLOOKUP(B$4:B$104,I$4:M$104,5,0) -> C | I38: sh07 | J38: ='Юнит 8'!U31 -> 2 | K38: =J38/J$105 -> 0.00088809947 | L38: =L37+K38 -> 0.98801066 | M38: =_xlfn.IFS(L38<80%,"A",L38<=95%,"B",L38>95%,"C") -> C
B39: sports красные | C39: ='Юнит 8'!AO22 -> 319.18295 | D39: =C39/C$105 -> 0.00055679525 | E39: =E35+D39 -> 1.0343079 | F39: =IF(AND(E39<=0),"C",IF(E39<=0.8,"A",IF(E39<=0.95,"B","C"))) -> C | G39: =VLOOKUP(B$4:B$104,I$4:M$104,5,0) -> C | I39: sh15 | J39: ='Юнит 8'!U39 -> 2 | K39: =J39/J$105 -> 0.00088809947 | L39: =L35+K39 -> 0.98579041 | M39: =_xlfn.IFS(L39<80%,"A",L39<=95%,"B",L39>95%,"C") -> C
B40: MANNA2120 | C40: ='Юнит 8'!AO73 -> 293.2309 | D40: =C40/C$105 -> 0.00051152347 | E40: =E39+D40 -> 1.0348194 | F40: =IF(AND(E40<=0),"C",IF(E40<=0.8,"A",IF(E40<=0.95,"B","C"))) -> C | G40: =VLOOKUP(B$4:B$104,I$4:M$104,5,0) -> C | I40: sh19 | J40: ='Юнит 8'!U43 -> 2 | K40: =J40/J$105 -> 0.00088809947 | L40: =L39+K40 -> 0.98667851 | M40: =_xlfn.IFS(L40<80%,"A",L40<=95%,"B",L40>95%,"C") -> C
B41: ww 203 черные | C41: ='Юнит 8'!AO44 -> 285.19976 | D41: =C41/C$105 -> 0.00049751364 | E41: =E40+D41 -> 1.0353169 | F41: =IF(AND(E41<=0),"C",IF(E41<=0.8,"A",IF(E41<=0.95,"B","C"))) -> C | G41: =VLOOKUP(B$4:B$104,I$4:M$104,5,0) -> C | I41: ww 8010 черные | J41: ='Юнит 8'!U51 -> 2 | K41: =J41/J$105 -> 0.00088809947 | L41: =L40+K41 -> 0.98756661 | M41: =_xlfn.IFS(L41<80%,"A",L41<=95%,"B",L41>95%,"C") -> C
...

Sheet АВС ЯНВАРЬ
B2: ОЧКИ
C3: Прибыль | D3: % прибыль | E3: Доля | F3: ABC прибыль | G3: ABC кол-во | J3: Кол-во | K3: % кол-во | L3: Доля | M3: ABC кол-во
B4: QS черные PZ | C4: =ЯНВАРЬ!AO4 -> 95522.058 | D4: =C4/C$100 -> 0.50905425 | E4: =D4 -> 0.50905425 | F4: =IF(AND(E4<=0),"C",IF(E4<=0.8,"A",IF(E4<=0.95,"B","C"))) -> A | G4: =VLOOKUP(B$4:B$99,I$4:M$99,5,0) -> A | I4: QS черные PZ | J4: =ЯНВАРЬ!U4 -> 602 | K4: =J4/J$100 -> 0.26071893 | L4: =K4 -> 0.26071893 | M4: =_xlfn.IFS(L4<80%,"A",L4<=95%,"B",L4>95%,"C") -> A | P4: A | Q4: 0.8
B5: QS синие PZ | C5: =ЯНВАРЬ!AO5 -> 47515.951 | D5: =C5/C$100 -> 0.25322106 | E5: =E4+D5 -> 0.76227531 | F5: =IF(AND(E5<=0),"C",IF(E5<=0.8,"A",IF(E5<=0.95,"B","C"))) -> A | G5: =VLOOKUP(B$4:B$99,I$4:M$99,5,0) -> A | I5: QS синие PZ | J5: =ЯНВАРЬ!U5 -> 201 | K5: =J5/J$100 -> 0.087050671 | L5: =L4+K5 -> 0.3477696 | M5: =_xlfn.IFS(L5<80%,"A",L5<=95%,"B",L5>95%,"C") -> A | P5: B | Q5: 0.15
B6: QS коричневые PZ | C6: =ЯНВАРЬ!AO7 -> 29383.213 | D6: =C6/C$100 -> 0.15658843 | E6: =E5+D6 -> 0.91886374 | F6: =IF(AND(E6<=0),"C",IF(E6<=0.8,"A",IF(E6<=0.95,"B","C"))) -> B | G6: =VLOOKUP(B$4:B$99,I$4:M$99,5,0) -> A | I6: QS желтые PZ | J6: =ЯНВАРЬ!U6 -> 177 | K6: =J6/J$100 -> 0.076656561 | L6: =L5+K6 -> 0.42442616 | M6: =_xlfn.IFS(L6<80%,"A",L6<=95%,"B",L6>95%,"C") -> A | P6: C | Q6: 0.05
B7: QS желтые PZ | C7: =ЯНВАРЬ!AO6 -> 29252.999 | D7: =C7/C$100 -> 0.1558945 | E7: =E6+D7 -> 1.0747582 | F7: =IF(AND(E7<=0),"C",IF(E7<=0.8,"A",IF(E7<=0.95,"B","C"))) -> C | G7: =VLOOKUP(B$4:B$99,I$4:M$99,5,0) -> A | I7: QS коричневые PZ | J7: =ЯНВАРЬ!U7 -> 159 | K7: =J7/J$100 -> 0.068860979 | L7: =L6+K7 -> 0.49328714 | M7: =_xlfn.IFS(L7<80%,"A",L7<=95%,"B",L7>95%,"C") -> A
B8: черные с железкой классика | C8: =ЯНВАРЬ!AO3 -> 22546.743 | D8: =C8/C$100 -> 0.12015565 | E8: =E7+D8 -> 1.1949139 | F8: =IF(AND(E8<=0),"C",IF(E8<=0.8,"A",IF(E8<=0.95,"B","C"))) -> C | G8: =VLOOKUP(B$4:B$99,I$4:M$99,5,0) -> A | I8: черные с железкой классика | J8: =ЯНВАРЬ!U3 -> 158 | K8: =J8/J$100 -> 0.068427891 | L8: =L7+K8 -> 0.56171503 | M8: =_xlfn.IFS(L8<80%,"A",L8<=95%,"B",L8>95%,"C") -> A
B9: th желт | C9: =ЯНВАРЬ!AO11 -> 15165.975 | D9: =C9/C$100 -> 0.080822214 | E9: =E8+D9 -> 1.2757361 | F9: =IF(AND(E9<=0),"C",IF(E9<=0.8,"A",IF(E9<=0.95,"B","C"))) -> C | G9: =VLOOKUP(B$4:B$99,I$4:M$99,5,0) -> A | I9: th черн | J9: =ЯНВАРЬ!U9 -> 122 | K9: =J9/J$100 -> 0.052836726 | L9: =L8+K9 -> 0.61455175 | M9: =_xlfn.IFS(L9<80%,"A",L9<=95%,"B",L9>95%,"C") -> A
B10: wwl8032 хром металл | C10: =ЯНВАРЬ!AO18 -> 6208.6752 | D10: =C10/C$100 -> 0.033087148 | E10: =E9+D10 -> 1.3088233 | F10: =IF(AND(E10<=0),"C",IF(E10<=0.8,"A",IF(E10<=0.95,"B","C"))) -> C | G10: =VLOOKUP(B$4:B$99,I$4:M$99,5,0) -> B | I10: MR8854 C2 Жен | J10: =ЯНВАРЬ!U8 -> 119 | K10: =J10/J$100 -> 0.051537462 | L10: =L9+K10 -> 0.66608922 | M10: =_xlfn.IFS(L10<80%,"A",L10<=95%,"B",L10>95%,"C") -> A
B11: flip черные | C11: =ЯНВАРЬ!AO13 -> 5861.1284 | D11: =C11/C$100 -> 0.031235009 | E11: =E10+D11 -> 1.3400583 | F11: =IF(AND(E11<=0),"C",IF(E11<=0.8,"A",IF(E11<=0.95,"B","C"))) -> C | G11: =VLOOKUP(B$4:B$99,I$4:M$99,5,0) -> A | I11: th син | J11: =ЯНВАРЬ!U10 -> 88 | K11: =J11/J$100 -> 0.038111737 | L11: =L10+K11 -> 0.70420095 | M11: =_xlfn.IFS(L11<80%,"A",L11<=95%,"B",L11>95%,"C") -> A
B12: th черн | C12: =ЯНВАРЬ!AO9 -> 5654.8891 | D12: =C12/C$100 -> 0.030135922 | E12: =E11+D12 -> 1.3701942 | F12: =IF(AND(E12<=0),"C",IF(E12<=0.8,"A",IF(E12<=0.95,"B","C"))) -> C | G12: =VLOOKUP(B$4:B$99,I$4:M$99,5,0) -> A | I12: th желт | J12: =ЯНВАРЬ!U11 -> 80 | K12: =J12/J$100 -> 0.034647033 | L12: =L11+K12 -> 0.73884799 | M12: =_xlfn.IFS(L12<80%,"A",L12<=95%,"B",L12>95%,"C") -> A
B13: ww 1022 черные | C13: =ЯНВАРЬ!AO45 -> 3561.3363 | D13: =C13/C$100 -> 0.018979002 | E13: =E12+D13 -> 1.3891732 | F13: =IF(AND(E13<=0),"C",IF(E13<=0.8,"A",IF(E13<=0.95,"B","C"))) -> C | G13: =VLOOKUP(B$4:B$99,I$4:M$99,5,0) -> C | I13: flip черные | J13: =ЯНВАРЬ!U13 -> 71 | K13: =J13/J$100 -> 0.030749242 | L13: =L12+K13 -> 0.76959723 | M13: =_xlfn.IFS(L13<80%,"A",L13<=95%,"B",L13>95%,"C") -> A
B14: sportlife красные | C14: =ЯНВАРЬ!AO25 -> 1753.7595 | D14: =C14/C$100 -> 0.0093461001 | E14: =E13+D14 -> 1.3985193 | F14: =IF(AND(E14<=0),"C",IF(E14<=0.8,"A",IF(E14<=0.95,"B","C"))) -> C | G14: =VLOOKUP(B$4:B$99,I$4:M$99,5,0) -> C | I14: sh3 | J14: =ЯНВАРЬ!U28 -> 62 | K14: =J14/J$100 -> 0.026851451 | L14: =L13+K14 -> 0.79644868 | M14: =_xlfn.IFS(L14<80%,"A",L14<=95%,"B",L14>95%,"C") -> A
B15: MANNA2121 | C15: =ЯНВАРЬ!AO74 -> 1363.8837 | D15: =C15/C$100 -> 0.0072683817 | E15: =E14+D15 -> 1.4057877 | F15: =IF(AND(E15<=0),"C",IF(E15<=0.8,"A",IF(E15<=0.95,"B","C"))) -> C | G15: =VLOOKUP(B$4:B$99,I$4:M$99,5,0) -> C | I15: flip коричневые | J15: =ЯНВАРЬ!U16 -> 58 | K15: =J15/J$100 -> 0.025119099 | L15: =L14+K15 -> 0.82156778 | M15: =_xlfn.IFS(L15<80%,"A",L15<=95%,"B",L15>95%,"C") -> B
B16: sportlife синие | C16: =ЯНВАРЬ!AO24 -> 1344.7674 | D16: =C16/C$100 -> 0.0071665076 | E16: =E15+D16 -> 1.4129542 | F16: =IF(AND(E16<=0),"C",IF(E16<=0.8,"A",IF(E16<=0.95,"B","C"))) -> C | G16: =VLOOKUP(B$4:B$99,I$4:M$99,5,0) -> C | I16: th коричн | J16: =ЯНВАРЬ!U12 -> 47 | K16: =J16/J$100 -> 0.020355132 | L16: =L15+K16 -> 0.84192291 | M16: =_xlfn.IFS(L16<80%,"A",L16<=95%,"B",L16>95%,"C") -> B
B17: ww 1022 желтые | C17: =ЯНВАРЬ!AO47 -> 1290.9451 | D17: =C17/C$100 -> 0.0068796789 | E17: =E16+D17 -> 1.4198339 | F17: =IF(AND(E17<=0),"C",IF(E17<=0.8,"A",IF(E17<=0.95,"B","C"))) -> C | G17: =VLOOKUP(B$4:B$99,I$4:M$99,5,0) -> C | I17: wwl8032 хром металл | J17: =ЯНВАРЬ!U18 -> 32 | K17: =J17/J$100 -> 0.013858813 | L17: =L16+K17 -> 0.85578172 | M17: =_xlfn.IFS(L17<80%,"A",L17<=95%,"B",L17>95%,"C") -> B
B18: flip коричневые | C18: =ЯНВАРЬ!AO16 -> 1251.1714 | D18: =C18/C$100 -> 0.0066677174 | E18: =E17+D18 -> 1.4265016 | F18: =IF(AND(E18<=0),"C",IF(E18<=0.8,"A",IF(E18<=0.95,"B","C"))) -> C | G18: =VLOOKUP(B$4:B$99,I$4:M$99,5,0) -> B | I18: ww 2018 черные | J18: =ЯНВАРЬ!U49 -> 32 | K18: =J18/J$100 -> 0.013858813 | L18: =L17+K18 -> 0.86964054 | M18: =_xlfn.IFS(L18<80%,"A",L18<=95%,"B",L18>95%,"C") -> B
B19: Linhai Baiyi коричневая линза | C19: =ЯНВАРЬ!AO86 -> 1123.957 | D19: =C19/C$100 -> 0.0059897692 | E19: =E18+D19 -> 1.4324913 | F19: =IF(AND(E19<=0),"C",IF(E19<=0.8,"A",IF(E19<=0.95,"B","C"))) -> C | G19: =VLOOKUP(B$4:B$99,I$4:M$99,5,0) -> C | I19: flip желтые | J19: =ЯНВАРЬ!U15 -> 29 | K19: =J19/J$100 -> 0.01255955 | L19: =L18+K19 -> 0.88220009 | M19: =_xlfn.IFS(L19<80%,"A",L19<=95%,"B",L19>95%,"C") -> B
B20: MANNA2122 | C20: =ЯНВАРЬ!AO75 -> 1087.5869 | D20: =C20/C$100 -> 0.0057959464 | E20: =E19+D20 -> 1.4382873 | F20: =IF(AND(E20<=0),"C",IF(E20<=0.8,"A",IF(E20<=0.95,"B","C"))) -> C | G20: =VLOOKUP(B$4:B$99,I$4:M$99,5,0) -> B | I20: wwl8032 коричневые золото | J20: =ЯНВАРЬ!U17 -> 29 | K20: =J20/J$100 -> 0.01255955 | L20: =L19+K20 -> 0.89475964 | M20: =_xlfn.IFS(L20<80%,"A",L20<=95%,"B",L20>95%,"C") -> B
B21: Linhai Baiyi серая линза | C21: =ЯНВАРЬ!AO87 -> 994.37752 | D21: =C21/C$100 -> 0.0052992168 | E21: =E20+D21 -> 1.4435865 | F21: =IF(AND(E21<=0),"C",IF(E21<=0.8,"A",IF(E21<=0.95,"B","C"))) -> C | G21: =VLOOKUP(B$4:B$99,I$4:M$99,5,0) -> C | I21: ww 2018 желтые | J21: =ЯНВАРЬ!U50 -> 26 | K21: =J21/J$100 -> 0.011260286 | L21: =L20+K21 -> 0.90601992 | M21: =_xlfn.IFS(L21<80%,"A",L21<=95%,"B",L21>95%,"C") -> B
B22: MANNA2114 | C22: =ЯНВАРЬ!AO67 -> 915.87686 | D22: =C22/C$100 -> 0.0048808727 | E22: =E21+D22 -> 1.4484674 | F22: =IF(AND(E22<=0),"C",IF(E22<=0.8,"A",IF(E22<=0.95,"B","C"))) -> C | G22: =VLOOKUP(B$4:B$99,I$4:M$99,5,0) -> C | I22: flip синие | J22: =ЯНВАРЬ!U14 -> 25 | K22: =J22/J$100 -> 0.010827198 | L22: =L21+K22 -> 0.91684712 | M22: =_xlfn.IFS(L22<80%,"A",L22<=95%,"B",L22>95%,"C") -> B
B23: MANNA2117 | C23: =ЯНВАРЬ!AO70 -> 904.89566 | D23: =C23/C$100 -> 0.0048223519 | E23: =E22+D23 -> 1.4532897 | F23: =IF(AND(E23<=0),"C",IF(E23<=0.8,"A",IF(E23<=0.95,"B","C"))) -> C | G23: =VLOOKUP(B$4:B$99,I$4:M$99,5,0) -> C | I23: MANNA2122 | J23: =ЯНВАРЬ!U75 -> 23 | K23: =J23/J$100 -> 0.0099610221 | L23: =L22+K23 -> 0.92680814 | M23: =_xlfn.IFS(L23<80%,"A",L23<=95%,"B",L23>95%,"C") -> B
B24: sh17 | C24: =ЯНВАРЬ!AO41 -> 765.23691 | D24: =C24/C$100 -> 0.0040780853 | E24: =E23+D24 -> 1.4573678 | F24: =IF(AND(E24<=0),"C",IF(E24<=0.8,"A",IF(E24<=0.95,"B","C"))) -> C | G24: =VLOOKUP(B$4:B$99,I$4:M$99,5,0) -> C | I24: sh1 | J24: =ЯНВАРЬ!U26 -> 22 | K24: =J24/J$100 -> 0.0095279342 | L24: =L23+K24 -> 0.93633608 | M24: =_xlfn.IFS(L24<80%,"A",L24<=95%,"B",L24>95%,"C") -> B
B25: ww 1022 коричневые | C25: =ЯНВАРЬ!AO48 -> 639.44127 | D25: =C25/C$100 -> 0.0034076977 | E25: =E24+D25 -> 1.4607755 | F25: =IF(AND(E25<=0),"C",IF(E25<=0.8,"A",IF(E25<=0.95,"B","C"))) -> C | G25: =VLOOKUP(B$4:B$99,I$4:M$99,5,0) -> C | I25: sh06 | J25: =ЯНВАРЬ!U30 -> 17 | K25: =J25/J$100 -> 0.0073624946 | L25: =L24+K25 -> 0.94369857 | M25: =_xlfn.IFS(L25<80%,"A",L25<=95%,"B",L25>95%,"C") -> B
B26: Chenlong белые | C26: =ЯНВАРЬ!AO78 -> 302.23318 | D26: =C26/C$100 -> 0.001610655 | E26: =E25+D26 -> 1.4623862 | F26: =IF(AND(E26<=0),"C",IF(E26<=0.8,"A",IF(E26<=0.95,"B","C"))) -> C | G26: =VLOOKUP(B$4:B$99,I$4:M$99,5,0) -> C | I26: sh07 | J26: =ЯНВАРЬ!U31 -> 17 | K26: =J26/J$100 -> 0.0073624946 | L26: =L25+K26 -> 0.95106107 | M26: =_xlfn.IFS(L26<80%,"A",L26<=95%,"B",L26>95%,"C") -> C
B27: MANNA2105 | C27: =ЯНВАРЬ!AO58 -> 252.9664 | D27: =C27/C$100 -> 0.0013481035 | E27: =E26+D27 -> 1.4637343 | F27: =IF(AND(E27<=0),"C",IF(E27<=0.8,"A",IF(E27<=0.95,"B","C"))) -> C | G27: =VLOOKUP(B$4:B$99,I$4:M$99,5,0) -> C | I27: Linhai Baiyi розовая линза | J27: =ЯНВАРЬ!U88 -> 17 | K27: =J27/J$100 -> 0.0073624946 | L27: =L26+K27 -> 0.95842356 | M27: =_xlfn.IFS(L27<80%,"A",L27<=95%,"B",L27>95%,"C") -> C
B28: sh13 | C28: =ЯНВАРЬ!AO37 -> 215.41374 | D28: =C28/C$100 -> 0.0011479786 | E28: =E27+D28 -> 1.4648822 | F28: =IF(AND(E28<=0),"C",IF(E28<=0.8,"A",IF(E28<=0.95,"B","C"))) -> C | G28: =VLOOKUP(B$4:B$99,I$4:M$99,5,0) -> C | I28: ww 1022 коричневые | J28: =ЯНВАРЬ!U48 -> 13 | K28: =J28/J$100 -> 0.0056301429 | L28: =L27+K28 -> 0.9640537 | M28: =_xlfn.IFS(L28<80%,"A",L28<=95%,"B",L28>95%,"C") -> C
B29: sh08 | C29: =ЯНВАРЬ!AO32 -> 156.7243 | D29: =C29/C$100 -> 0.00083521203 | E29: =E28+D29 -> 1.4657175 | F29: =IF(AND(E29<=0),"C",IF(E29<=0.8,"A",IF(E29<=0.95,"B","C"))) -> C | G29: =VLOOKUP(B$4:B$99,I$4:M$99,5,0) -> C | I29: ww 1022 черные | J29: =ЯНВАРЬ!U45 -> 12 | K29: =J29/J$100 -> 0.005197055 | L29: =L28+K29 -> 0.96925076 | M29: =_xlfn.IFS(L29<80%,"A",L29<=95%,"B",L29>95%,"C") -> C
B30: wwl8032 коричневые золото | C30: =ЯНВАРЬ!AO17 -> 147.05787 | D30: =C30/C$100 -> 0.00078369786 | E30: =E29+D30 -> 1.4665012 | F30: =IF(AND(E30<=0),"C",IF(E30<=0.8,"A",IF(E30<=0.95,"B","C"))) -> C | G30: =VLOOKUP(B$4:B$99,I$4:M$99,5,0) -> B | I30: ww 8010 черные | J30: =ЯНВАРЬ!U51 -> 12 | K30: =J30/J$100 -> 0.005197055 | L30: =L29+K30 -> 0.97444781 | M30: =_xlfn.IFS(L30<80%,"A",L30<=95%,"B",L30>95%,"C") -> C
B31: MANNA2120 | C31: =ЯНВАРЬ!AO73 -> 141.36734 | D31: =C31/C$100 -> 0.00075337199 | E31: =E30+D31 -> 1.4672545 | F31: =IF(AND(E31<=0),"C",IF(E31<=0.8,"A",IF(E31<=0.95,"B","C"))) -> C | G31: =VLOOKUP(B$4:B$99,I$4:M$99,5,0) -> C | I31: ww 1022 желтые | J31: =ЯНВАРЬ!U47 -> 6 | K31: =J31/J$100 -> 0.0025985275 | L31: =L30+K31 -> 0.97704634 | M31: =_xlfn.IFS(L31<80%,"A",L31<=95%,"B",L31>95%,"C") -> C
B32: sh16 | C32: =ЯНВАРЬ!AO40 -> 121.42311 | D32: =C32/C$100 -> 0.00064708563 | E32: =E31+D32 -> 1.4679016 | F32: =IF(AND(E32<=0),"C",IF(E32<=0.8,"A",IF(E32<=0.95,"B","C"))) -> C | G32: =VLOOKUP(B$4:B$99,I$4:M$99,5,0) -> C | I32: MANNA2121 | J32: =ЯНВАРЬ!U74 -> 6 | K32: =J32/J$100 -> 0.0025985275 | L32: =L31+K32 -> 0.97964487 | M32: =_xlfn.IFS(L32<80%,"A",L32<=95%,"B",L32>95%,"C") -> C
B33: MARSTON 7171 C1 | C33: =ЯНВАРЬ!AO96 -> 113.1339 | D33: =C33/C$100 -> 0.0006029109 | E33: =E32+D33 -> 1.4685045 | F33: =IF(AND(E33<=0),"C",IF(E33<=0.8,"A",IF(E33<=0.95,"B","C"))) -> C | G33: =VLOOKUP(B$4:B$99,I$4:M$99,5,0) -> C | I33: Keming Aishi коричневые | J33: =ЯНВАРЬ!U85 -> 6 | K33: =J33/J$100 -> 0.0025985275 | L33: =L32+K33 -> 0.9822434 | M33: =_xlfn.IFS(L33<80%,"A",L33<=95%,"B",L33>95%,"C") -> C
B34: MANNA2101 | C34: =ЯНВАРЬ!AO54 -> 104.92238 | D34: =C34/C$100 -> 0.00055915026 | E34: =E33+D34 -> 1.4690637 | F34: =IF(AND(E34<=0),"C",IF(E34<=0.8,"A",IF(E34<=0.95,"B","C"))) -> C | G34: =VLOOKUP(B$4:B$99,I$4:M$99,5,0) -> C | I34: sportlife красные | J34: =ЯНВАРЬ!U25 -> 5 | K34: =J34/J$100 -> 0.0021654396 | L34: =L33+K34 -> 0.98440883 | M34: =_xlfn.IFS(L34<80%,"A",L34<=95%,"B",L34>95%,"C") -> C
B35: MANNA2119 | C35: =ЯНВАРЬ!AO72 -> 103.18015 | D35: =C35/C$100 -> 0.00054986559 | E35: =E34+D35 -> 1.4696135 | F35: =IF(AND(E35<=0),"C",IF(E35<=0.8,"A",IF(E35<=0.95,"B","C"))) -> C | G35: =VLOOKUP(B$4:B$99,I$4:M$99,5,0) -> C | I35: sportlife синие | J35: =ЯНВАРЬ!U24 -> 4 | K35: =J35/J$100 -> 0.0017323517 | L35: =L34+K35 -> 0.98614119 | M35: =_xlfn.IFS(L35<80%,"A",L35<=95%,"B",L35>95%,"C") -> C
B36: WW 3055 коричневый | C36: =ЯНВАРЬ!AO53 -> 71.165605 | D36: =C36/C$100 -> 0.00037925432 | E36: =E35+D36 -> 1.4699928 | F36: =IF(AND(E36<=0),"C",IF(E36<=0.8,"A",IF(E36<=0.95,"B","C"))) -> C | G36: =VLOOKUP(B$4:B$99,I$4:M$99,5,0) -> C | I36: sh08 | J36: =ЯНВАРЬ!U32 -> 4 | K36: =J36/J$100 -> 0.0017323517 | L36: =L35+K36 -> 0.98787354 | M36: =_xlfn.IFS(L36<80%,"A",L36<=95%,"B",L36>95%,"C") -> C
B37: wwl8032 черные серебро | C37: =ЯНВАРЬ!AO19 -> 0 | D37: =C37/C$100 -> 0 | E37: =E36+D37 -> 1.4699928 | F37: =IF(AND(E37<=0),"C",IF(E37<=0.8,"A",IF(E37<=0.95,"B","C"))) -> C | G37: =VLOOKUP(B$4:B$99,I$4:M$99,5,0) -> C | I37: MANNA2114 | J37: =ЯНВАРЬ!U67 -> 3 | K37: =J37/J$100 -> 0.0012992638 | L37: =L36+K37 -> 0.9891728 | M37: =_xlfn.IFS(L37<80%,"A",L37<=95%,"B",L37>95%,"C") -> C
B38: sports синие | C38: =ЯНВАРЬ!AO20 -> 0 | D38: =C38/C$100 -> 0 | E38: =E37+D38 -> 1.4699928 | F38: =IF(AND(E38<=0),"C",IF(E38<=0.8,"A",IF(E38<=0.95,"B","C"))) -> C | G38: =VLOOKUP(B$4:B$99,I$4:M$99,5,0) -> C | I38: sh09 | J38: =ЯНВАРЬ!U33 -> 2 | K38: =J38/J$100 -> 0.00086617583 | L38: =L37+K38 -> 0.99003898 | M38: =_xlfn.IFS(L38<80%,"A",L38<=95%,"B",L38>95%,"C") -> C
B39: sportlife черные | C39: =ЯНВАРЬ!AO23 -> 0 | D39: =C39/C$100 -> 0 | E39: =E35+D39 -> 1.4696135 | F39: =IF(AND(E39<=0),"C",IF(E39<=0.8,"A",IF(E39<=0.95,"B","C"))) -> C | G39: =VLOOKUP(B$4:B$99,I$4:M$99,5,0) -> C | I39: sh17 | J39: =ЯНВАРЬ!U41 -> 2 | K39: =J39/J$100 -> 0.00086617583 | L39: =L35+K39 -> 0.98700736 | M39: =_xlfn.IFS(L39<80%,"A",L39<=95%,"B",L39>95%,"C") -> C
B40: sh11 | C40: =ЯНВАРЬ!AO35 -> 0 | D40: =C40/C$100 -> 0 | E40: =E39+D40 -> 1.4696135 | F40: =IF(AND(E40<=0),"C",IF(E40<=0.8,"A",IF(E40<=0.95,"B","C"))) -> C | G40: =VLOOKUP(B$4:B$99,I$4:M$99,5,0) -> C | I40: MANNA2117 | J40: =ЯНВАРЬ!U70 -> 2 | K40: =J40/J$100 -> 0.00086617583 | L40: =L39+K40 -> 0.98787354 | M40: =_xlfn.IFS(L40<80%,"A",L40<=95%,"B",L40>95%,"C") -> C
B41: sh12 | C41: =ЯНВАРЬ!AO36 -> 0 | D41: =C41/C$100 -> 0 | E41: =E40+D41 -> 1.4696135 | F41: =IF(AND(E41<=0),"C",IF(E41<=0.8,"A",IF(E41<=0.95,"B","C"))) -> C | G41: =VLOOKUP(B$4:B$99,I$4:M$99,5,0) -> C | I41: MANNA2119 | J41: =ЯНВАРЬ!U72 -> 2 | K41: =J41/J$100 -> 0.00086617583 | L41: =L40+K41 -> 0.98873971 | M41: =_xlfn.IFS(L41<80%,"A",L41<=95%,"B",L41>95%,"C") -> C
...

Sheet Юнит 9
A1: 16-22.02_8 нед | F1: Отчет по остаткам 3,4,5 | I1: Мой склад | M1: Цены и скидки 6 | N1: Воронка продаж 20,54,36 | AJ1: Без учета в прибыли | AL1: Вставить в Итого | AQ1: на 1 единицу проданного товара
A2: Бренд | B2: SKU | C2: Артикул поставщика | D2: Предмет | E2: Остаток на | F2: В пути до клиента | G2: В пути от клиента | H2: Итого по складам ВБ | I2: Остаток на осн. складе | J2: Остаток на фф | K2: Себетоимость на 1 ед на 29.09.25 | L2: Себестоимость остатков | M2: Оборачива-емость, дн | N2: Заказы, шт 32 дня | O2: Средняя цена, руб | P2: % выкупа за 7 дней | Q2: Скорость заказов | R2: Скорость продаж | S2: Кол-во ПРОДАЖИ | T2: Кол-во ВОЗВРАТЫ | U2: Кол-во ПРОДАЖИ-ВОЗВРАТЫ | V2: Выручка ВБ ПРОДАЖИ | W2: Выручка ВБ ВОЗВРАТЫ | X2: Выручка с учетом СПП ПРОДАЖИ - ВОЗВРАТЫ | Y2: Выручка ПРОДАЖИ | Z2: Выручка ВОЗВРАТЫ | AA2: Выручка с учетом согласованной скидки ПРОДАЖИ - ВОЗВРАТЫ | AB2: Выручка потенциальная | AC2: Доля выручки, % от общего объема | AD2: Себестоимость продаж | AE2: Комиссия, руб | AF2: Комиссия, % | AG2: Логистика | AH2: Реклама БАЛАНС | AI2: Реклама СЧЕТ | AJ2: Реклама Промо бонусы | AK2: Блогеры | AL2: Хранение | AM2: Штрафы | AN2: Налог 1%+ НДС 5% | AO2: Прибыль | AQ2: Выручка на 1 ед (средняя цена продажи со скидкой) | AR2: Себестоимость на 1 ед | AS2: Комиссия на 1 ед | AT2: Логистика на 1 ед | AU2: Реклама на 1 ед | AV2: Прибыль на 1 ед | AW2: Маржиналь-ность, % | AX2: Рентабель-ность, % | AZ2: Прибыль с остатков
A3: Ridges | B3: 170499929 | C3: черные с железкой классика | D3: Солнцезащитные очки | E3: =SUM(F3:J3) -> 0 | K3: 142.98 | L3: =E3*K3 -> 0 | Q3: =N3/32 -> 0 | R3: =U3/32 -> 0 | U3: =S3+T3 -> 0 | X3: =V3+W3 -> 0 | AA3: =Y3+Z3 -> 0 | AB3: =N3*O3*P3/100 -> 0 | AC3: =AA3/$AA$121 -> #DIV/0! | AD3: =U3*K3 -> 0 | AF3: =IF(AA3=0,0,AE3/AA3) -> 0 | AL3: =IFERROR($AL$121*H3/$H$121,0) -> 0 | AN3: =X3*5.71% -> 0 | AO3: =AA3-AD3-AE3-AG3-AH3-AI3-AK3-AL3-AN3-AM3 -> 0 | AQ3: =IF(U3=0,0,AA3/U3) -> 0 | AR3: =K3 -> 142.98 | AS3: =IF(U3=0,0,AE3/U3) -> 0 | AT3: =IF(S3=0,AG3/1,AG3/S3) -> 0 | AU3: =IF(S3=0,0,(AH3+AI3+AJ3)/S3) -> 0 | AV3: =_xlfn.IFS(U3=0,AO3,U3<0,AO3/-U3,U3>0,AO3/U3) -> 0 | AW3: =IF(AQ3=0,0,AV3/AQ3) -> 0 | AX3: =IF(AR3=0,0,AV3/AR3) -> 0 | AZ3: =AV3*E3 -> 0
A4: Ridges | B4: 170500631 | C4: QS черные PZ | D4: Солнцезащитные очки | E4: =SUM(F4:J4) -> 0 | K4: 123.09 | L4: =E4*K4 -> 0 | Q4: =N4/32 -> 0 | R4: =U4/32 -> 0 | U4: =S4+T4 -> 0 | X4: =V4+W4 -> 0 | AA4: =Y4+Z4 -> 0 | AB4: =N4*O4*P4/100 -> 0 | AC4: =AA4/$AA$121 -> #DIV/0! | AD4: =U4*K4 -> 0 | AF4: =IF(AA4=0,0,AE4/AA4) -> 0 | AL4: =IFERROR($AL$121*H4/$H$121,0) -> 0 | AN4: =X4*5.71% -> 0 | AO4: =AA4-AD4-AE4-AG4-AH4-AI4-AK4-AL4-AN4-AM4 -> 0 | AQ4: =IF(U4=0,0,AA4/U4) -> 0 | AR4: =K4 -> 123.09 | AS4: =IF(U4=0,0,AE4/U4) -> 0 | AT4: =IF(S4=0,AG4/1,AG4/S4) -> 0 | AU4: =IF(S4=0,0,(AH4+AI4+AJ4)/S4) -> 0 | AV4: {=_xlfn.IFS(U4=0,AO4,U4<0,AO4/-U4,U4>0,AO4/U4)} -> 0 | AW4: =IF(AQ4=0,0,AV4/AQ4) -> 0 | AX4: =IF(AR4=0,0,AV4/AR4) -> 0 | AZ4: =AV4*E4 -> 0
A5: Ridges | B5: 170500399 | C5: QS синие PZ | D5: Солнцезащитные очки | E5: =SUM(F5:J5) -> 0 | K5: 123.09 | L5: =E5*K5 -> 0 | Q5: =N5/32 -> 0 | R5: =U5/32 -> 0 | U5: =S5+T5 -> 0 | X5: =V5+W5 -> 0 | AA5: =Y5+Z5 -> 0 | AB5: =N5*O5*P5/100 -> 0 | AC5: =AA5/$AA$121 -> #DIV/0! | AD5: =U5*K5 -> 0 | AF5: =IF(AA5=0,0,AE5/AA5) -> 0 | AL5: =IFERROR($AL$121*H5/$H$121,0) -> 0 | AN5: =X5*5.71% -> 0 | AO5: =AA5-AD5-AE5-AG5-AH5-AI5-AK5-AL5-AN5-AM5 -> 0 | AQ5: =IF(U5=0,0,AA5/U5) -> 0 | AR5: =K5 -> 123.09 | AS5: =IF(U5=0,0,AE5/U5) -> 0 | AT5: =IF(S5=0,AG5/1,AG5/S5) -> 0 | AU5: =IF(S5=0,0,(AH5+AI5+AJ5)/S5) -> 0 | AV5: {=_xlfn.IFS(U5=0,AO5,U5<0,AO5/-U5,U5>0,AO5/U5)} -> 0 | AW5: =IF(AQ5=0,0,AV5/AQ5) -> 0 | AX5: =IF(AR5=0,0,AV5/AR5) -> 0 | AZ5: =AV5*E5 -> 0
A6: Ridges | B6: 170500725 | C6: QS желтые PZ | D6: Солнцезащитные очки | E6: =SUM(F6:J6) -> 0 | K6: 123.09 | L6: =E6*K6 -> 0 | Q6: =N6/32 -> 0 | R6: =U6/32 -> 0 | U6: =S6+T6 -> 0 | X6: =V6+W6 -> 0 | AA6: =Y6+Z6 -> 0 | AB6: =N6*O6*P6/100 -> 0 | AC6: =AA6/$AA$121 -> #DIV/0! | AD6: =U6*K6 -> 0 | AF6: =IF(AA6=0,0,AE6/AA6) -> 0 | AL6: =IFERROR($AL$121*H6/$H$121,0) -> 0 | AN6: =X6*5.71% -> 0 | AO6: =AA6-AD6-AE6-AG6-AH6-AI6-AK6-AL6-AN6-AM6 -> 0 | AQ6: =IF(U6=0,0,AA6/U6) -> 0 | AR6: =K6 -> 123.09 | AS6: =IF(U6=0,0,AE6/U6) -> 0 | AT6: =IF(S6=0,AG6/1,AG6/S6) -> 0 | AU6: =IF(S6=0,0,(AH6+AI6+AJ6)/S6) -> 0 | AV6: {=_xlfn.IFS(U6=0,AO6,U6<0,AO6/-U6,U6>0,AO6/U6)} -> 0 | AW6: =IF(AQ6=0,0,AV6/AQ6) -> 0 | AX6: =IF(AR6=0,0,AV6/AR6) -> 0 | AZ6: =AV6*E6 -> 0
A7: Ridges | B7: 246275459 | C7: QS коричневые PZ | D7: Солнцезащитные очки | E7: =SUM(F7:J7) -> 0 | K7: 117.24 | L7: =E7*K7 -> 0 | Q7: =N7/32 -> 0 | R7: =U7/32 -> 0 | U7: =S7+T7 -> 0 | X7: =V7+W7 -> 0 | AA7: =Y7+Z7 -> 0 | AB7: =N7*O7*P7/100 -> 0 | AC7: =AA7/$AA$121 -> #DIV/0! | AD7: =U7*K7 -> 0 | AF7: =IF(AA7=0,0,AE7/AA7) -> 0 | AL7: =IFERROR($AL$121*H7/$H$121,0) -> 0 | AN7: =X7*5.71% -> 0 | AO7: =AA7-AD7-AE7-AG7-AH7-AI7-AK7-AL7-AN7-AM7 -> 0 | AQ7: =IF(U7=0,0,AA7/U7) -> 0 | AR7: =K7 -> 117.24 | AS7: =IF(U7=0,0,AE7/U7) -> 0 | AT7: =IF(S7=0,AG7/1,AG7/S7) -> 0 | AU7: =IF(S7=0,0,(AH7+AI7+AJ7)/S7) -> 0 | AV7: {=_xlfn.IFS(U7=0,AO7,U7<0,AO7/-U7,U7>0,AO7/U7)} -> 0 | AW7: =IF(AQ7=0,0,AV7/AQ7) -> 0 | AX7: =IF(AR7=0,0,AV7/AR7) -> 0 | AZ7: =AV7*E7 -> 0
A8: Ridges | B8: 159900625 | C8: MR8854 C2 Жен | D8: Солнцезащитные очки | E8: =SUM(F8:J8) -> 0 | K8: 169.89 | L8: =E8*K8 -> 0 | Q8: =N8/32 -> 0 | R8: =U8/32 -> 0 | U8: =S8+T8 -> 0 | X8: =V8+W8 -> 0 | AA8: =Y8+Z8 -> 0 | AB8: =N8*O8*P8/100 -> 0 | AC8: =AA8/$AA$121 -> #DIV/0! | AD8: =U8*K8 -> 0 | AF8: =IF(AA8=0,0,AE8/AA8) -> 0 | AL8: =IFERROR($AL$121*H8/$H$121,0) -> 0 | AN8: =X8*5.71% -> 0 | AO8: =AA8-AD8-AE8-AG8-AH8-AI8-AK8-AL8-AN8-AM8 -> 0 | AQ8: =IF(U8=0,0,AA8/U8) -> 0 | AR8: =K8 -> 169.89 | AS8: =IF(U8=0,0,AE8/U8) -> 0 | AT8: =IF(S8=0,AG8/1,AG8/S8) -> 0 | AU8: =IF(S8=0,0,(AH8+AI8+AJ8)/S8) -> 0 | AV8: {=_xlfn.IFS(U8=0,AO8,U8<0,AO8/-U8,U8>0,AO8/U8)} -> 0 | AW8: =IF(AQ8=0,0,AV8/AQ8) -> 0 | AX8: =IF(AR8=0,0,AV8/AR8) -> 0 | AZ8: =AV8*E8 -> 0
A9: Ridges | B9: 251467353 | C9: th черн | D9: Солнцезащитные очки | E9: =SUM(F9:J9) -> 0 | K9: 123.09 | L9: =E9*K9 -> 0 | Q9: =N9/32 -> 0 | R9: =U9/32 -> 0 | U9: =S9+T9 -> 0 | X9: =V9+W9 -> 0 | AA9: =Y9+Z9 -> 0 | AB9: =N9*O9*P9/100 -> 0 | AC9: =AA9/$AA$121 -> #DIV/0! | AD9: =U9*K9 -> 0 | AF9: =IF(AA9=0,0,AE9/AA9) -> 0 | AL9: =IFERROR($AL$121*H9/$H$121,0) -> 0 | AN9: =X9*5.71% -> 0 | AO9: =AA9-AD9-AE9-AG9-AH9-AI9-AK9-AL9-AN9-AM9 -> 0 | AQ9: =IF(U9=0,0,AA9/U9) -> 0 | AR9: =K9 -> 123.09 | AS9: =IF(U9=0,0,AE9/U9) -> 0 | AT9: =IF(S9=0,AG9/1,AG9/S9) -> 0 | AU9: =IF(S9=0,0,(AH9+AI9+AJ9)/S9) -> 0 | AV9: {=_xlfn.IFS(U9=0,AO9,U9<0,AO9/-U9,U9>0,AO9/U9)} -> 0 | AW9: =IF(AQ9=0,0,AV9/AQ9) -> 0 | AX9: =IF(AR9=0,0,AV9/AR9) -> 0 | AZ9: =AV9*E9 -> 0
A10: Ridges | B10: 251467354 | C10: th син | D10: Солнцезащитные очки | E10: =SUM(F10:J10) -> 0 | K10: 123.09 | L10: =E10*K10 -> 0 | Q10: =N10/32 -> 0 | R10: =U10/32 -> 0 | U10: =S10+T10 -> 0 | X10: =V10+W10 -> 0 | AA10: =Y10+Z10 -> 0 | AB10: =N10*O10*P10/100 -> 0 | AC10: =AA10/$AA$121 -> #DIV/0! | AD10: =U10*K10 -> 0 | AF10: =IF(AA10=0,0,AE10/AA10) -> 0 | AL10: =IFERROR($AL$121*H10/$H$121,0) -> 0 | AN10: =X10*5.71% -> 0 | AO10: =AA10-AD10-AE10-AG10-AH10-AI10-AK10-AL10-AN10-AM10 -> 0 | AQ10: =IF(U10=0,0,AA10/U10) -> 0 | AR10: =K10 -> 123.09 | AS10: =IF(U10=0,0,AE10/U10) -> 0 | AT10: =IF(S10=0,AG10/1,AG10/S10) -> 0 | AU10: =IF(S10=0,0,(AH10+AI10+AJ10)/S10) -> 0 | AV10: {=_xlfn.IFS(U10=0,AO10,U10<0,AO10/-U10,U10>0,AO10/U10)} -> 0 | AW10: =IF(AQ10=0,0,AV10/AQ10) -> 0 | AX10: =IF(AR10=0,0,AV10/AR10) -> 0 | AZ10: =AV10*E10 -> 0
A11: Ridges | B11: 251467355 | C11: th желт | D11: Солнцезащитные очки | E11: =SUM(F11:J11) -> 0 | K11: 123.09 | L11: =E11*K11 -> 0 | Q11: =N11/32 -> 0 | R11: =U11/32 -> 0 | U11: =S11+T11 -> 0 | X11: =V11+W11 -> 0 | AA11: =Y11+Z11 -> 0 | AB11: =N11*O11*P11/100 -> 0 | AC11: =AA11/$AA$121 -> #DIV/0! | AD11: =U11*K11 -> 0 | AF11: =IF(AA11=0,0,AE11/AA11) -> 0 | AL11: =IFERROR($AL$121*H11/$H$121,0) -> 0 | AN11: =X11*5.71% -> 0 | AO11: =AA11-AD11-AE11-AG11-AH11-AI11-AK11-AL11-AN11-AM11 -> 0 | AQ11: =IF(U11=0,0,AA11/U11) -> 0 | AR11: =K11 -> 123.09 | AS11: =IF(U11=0,0,AE11/U11) -> 0 | AT11: =IF(S11=0,AG11/1,AG11/S11) -> 0 | AU11: =IF(S11=0,0,(AH11+AI11+AJ11)/S11) -> 0 | AV11: {=_xlfn.IFS(U11=0,AO11,U11<0,AO11/-U11,U11>0,AO11/U11)} -> 0 | AW11: =IF(AQ11=0,0,AV11/AQ11) -> 0 | AX11: =IF(AR11=0,0,AV11/AR11) -> 0 | AZ11: =AV11*E11 -> 0
A12: Ridges | B12: 303941289 | C12: th коричн | D12: Солнцезащитные очки | E12: =SUM(F12:J12) -> 0 | K12: 117.24 | L12: =E12*K12 -> 0 | Q12: =N12/32 -> 0 | R12: =U12/32 -> 0 | U12: =S12+T12 -> 0 | X12: =V12+W12 -> 0 | AA12: =Y12+Z12 -> 0 | AB12: =N12*O12*P12/100 -> 0 | AC12: =AA12/$AA$121 -> #DIV/0! | AD12: =U12*K12 -> 0 | AF12: =IF(AA12=0,0,AE12/AA12) -> 0 | AL12: =IFERROR($AL$121*H12/$H$121,0) -> 0 | AN12: =X12*5.71% -> 0 | AO12: =AA12-AD12-AE12-AG12-AH12-AI12-AK12-AL12-AN12-AM12 -> 0 | AQ12: =IF(U12=0,0,AA12/U12) -> 0 | AR12: =K12 -> 117.24 | AS12: =IF(U12=0,0,AE12/U12) -> 0 | AT12: =IF(S12=0,AG12/1,AG12/S12) -> 0 | AU12: =IF(S12=0,0,(AH12+AI12+AJ12)/S12) -> 0 | AV12: {=_xlfn.IFS(U12=0,AO12,U12<0,AO12/-U12,U12>0,AO12/U12)} -> 0 | AW12: =IF(AQ12=0,0,AV12/AQ12) -> 0 | AX12: =IF(AR12=0,0,AV12/AR12) -> 0 | AZ12: =AV12*E12 -> 0
A13: Ridges | B13: 274218038 | C13: flip черные | D13: Солнцезащитные очки | E13: =SUM(F13:J13) -> 0 | K13: 123.09 | L13: =E13*K13 -> 0 | Q13: =N13/32 -> 0 | R13: =U13/32 -> 0 | U13: =S13+T13 -> 0 | X13: =V13+W13 -> 0 | AA13: =Y13+Z13 -> 0 | AB13: =N13*O13*P13/100 -> 0 | AC13: =AA13/$AA$121 -> #DIV/0! | AD13: =U13*K13 -> 0 | AF13: =IF(AA13=0,0,AE13/AA13) -> 0 | AL13: =IFERROR($AL$121*H13/$H$121,0) -> 0 | AN13: =X13*5.71% -> 0 | AO13: =AA13-AD13-AE13-AG13-AH13-AI13-AK13-AL13-AN13-AM13 -> 0 | AQ13: =IF(U13=0,0,AA13/U13) -> 0 | AR13: =K13 -> 123.09 | AS13: =IF(U13=0,0,AE13/U13) -> 0 | AT13: =IF(S13=0,AG13/1,AG13/S13) -> 0 | AU13: =IF(S13=0,0,(AH13+AI13+AJ13)/S13) -> 0 | AV13: {=_xlfn.IFS(U13=0,AO13,U13<0,AO13/-U13,U13>0,AO13/U13)} -> 0 | AW13: =IF(AQ13=0,0,AV13/AQ13) -> 0 | AX13: =IF(AR13=0,0,AV13/AR13) -> 0 | AZ13: =AV13*E13 -> 0
A14: Ridges | B14: 274219203 | C14: flip синие | D14: Солнцезащитные очки | E14: =SUM(F14:J14) -> 0 | K14: 123.09 | L14: =E14*K14 -> 0 | Q14: =N14/32 -> 0 | R14: =U14/32 -> 0 | U14: =S14+T14 -> 0 | X14: =V14+W14 -> 0 | AA14: =Y14+Z14 -> 0 | AB14: =N14*O14*P14/100 -> 0 | AC14: =AA14/$AA$121 -> #DIV/0! | AD14: =U14*K14 -> 0 | AF14: =IF(AA14=0,0,AE14/AA14) -> 0 | AL14: =IFERROR($AL$121*H14/$H$121,0) -> 0 | AN14: =X14*5.71% -> 0 | AO14: =AA14-AD14-AE14-AG14-AH14-AI14-AK14-AL14-AN14-AM14 -> 0 | AQ14: =IF(U14=0,0,AA14/U14) -> 0 | AR14: =K14 -> 123.09 | AS14: =IF(U14=0,0,AE14/U14) -> 0 | AT14: =IF(S14=0,AG14/1,AG14/S14) -> 0 | AU14: =IF(S14=0,0,(AH14+AI14+AJ14)/S14) -> 0 | AV14: {=_xlfn.IFS(U14=0,AO14,U14<0,AO14/-U14,U14>0,AO14/U14)} -> 0 | AW14: =IF(AQ14=0,0,AV14/AQ14) -> 0 | AX14: =IF(AR14=0,0,AV14/AR14) -> 0 | AZ14: =AV14*E14 -> 0
A15: Ridges | B15: 274190322 | C15: flip желтые | D15: Солнцезащитные очки | E15: =SUM(F15:J15) -> 0 | K15: 123.09 | L15: =E15*K15 -> 0 | Q15: =N15/32 -> 0 | R15: =U15/32 -> 0 | U15: =S15+T15 -> 0 | X15: =V15+W15 -> 0 | AA15: =Y15+Z15 -> 0 | AB15: =N15*O15*P15/100 -> 0 | AC15: =AA15/$AA$121 -> #DIV/0! | AD15: =U15*K15 -> 0 | AF15: =IF(AA15=0,0,AE15/AA15) -> 0 | AL15: =IFERROR($AL$121*H15/$H$121,0) -> 0 | AN15: =X15*5.71% -> 0 | AO15: =AA15-AD15-AE15-AG15-AH15-AI15-AK15-AL15-AN15-AM15 -> 0 | AQ15: =IF(U15=0,0,AA15/U15) -> 0 | AR15: =K15 -> 123.09 | AS15: =IF(U15=0,0,AE15/U15) -> 0 | AT15: =IF(S15=0,AG15/1,AG15/S15) -> 0 | AU15: =IF(S15=0,0,(AH15+AI15+AJ15)/S15) -> 0 | AV15: {=_xlfn.IFS(U15=0,AO15,U15<0,AO15/-U15,U15>0,AO15/U15)} -> 0 | AW15: =IF(AQ15=0,0,AV15/AQ15) -> 0 | AX15: =IF(AR15=0,0,AV15/AR15) -> 0 | AZ15: =AV15*E15 -> 0
... A27: Ridges | B27: 207984027 | C27: sh2 | D27: Солнцезащитные очки | E27: =SUM(F27:J27) -> 0 | K27: 181.59 | L27: =E27*K27 -> 0 | Q27: =N27/32 -> 0 | R27: =U27/32 -> 0 | U27: =S27+T27 -> 0 | X27: =V27+W27 -> 0 | AA27: =Y27+Z27 -> 0 | AB27: =N27*O27*P27/100 -> 0 | AC27: =AA27/$AA$121 -> #DIV/0! | AD27: =U27*K27 -> 0 | AF27: =IF(AA27=0,0,AE27/AA27) -> 0 | AL27: =IFERROR($AL$121*H27/$H$121,0) -> 0 | AN27: =X27*5.71% -> 0 | AO27: =AA27-AD27-AE27-AG27-AH27-AI27-AK27-AL27-AN27-AM27 -> 0 | AQ27: =IF(U27=0,0,AA27/U27) -> 0 | AR27: =K27 -> 181.59 | AS27: =IF(U27=0,0,AE27/U27) -> 0 | AT27: =IF(S27=0,AG27/1,AG27/S27) -> 0 | AU27: =IF(S27=0,0,(AH27+AI27+AJ27)/S27) -> 0 | AV27: {=_xlfn.IFS(U27=0,AO27,U27<0,AO27/-U27,U27>0,AO27/U27)} -> 0 | AW27: =IF(AQ27=0,0,AV27/AQ27) -> 0 | AX27: =IF(AR27=0,0,AV27/AR27) -> 0 | AZ27: =AV27*E27 -> 0
A28: Ridges | B28: 207984028 | C28: sh3 | D28: Солнцезащитные очки | E28: =SUM(F28:J28) -> 0 | K28: 133.62 | L28: =E28*K28 -> 0 | Q28: =N28/32 -> 0 | R28: =U28/32 -> 0 | U28: =S28+T28 -> 0 | X28: =V28+W28 -> 0 | AA28: =Y28+Z28 -> 0 | AB28: =N28*O28*P28/100 -> 0 | AC28: =AA28/$AA$121 -> #DIV/0! | AD28: =U28*K28 -> 0 | AF28: =IF(AA28=0,0,AE28/AA28) -> 0 | AL28: =IFERROR($AL$121*H28/$H$121,0) -> 0 | AN28: =X28*5.71% -> 0 | AO28: =AA28-AD28-AE28-AG28-AH28-AI28-AK28-AL28-AN28-AM28 -> 0 | AQ28: =IF(U28=0,0,AA28/U28) -> 0 | AR28: =K28 -> 133.62 | AS28: =IF(U28=0,0,AE28/U28) -> 0 | AT28: =IF(S28=0,AG28/1,AG28/S28) -> 0 | AU28: =IF(S28=0,0,(AH28+AI28+AJ28)/S28) -> 0 | AV28: =_xlfn.IFS(U28=0,AO28,U28<0,AO28/-U28,U28>0,AO28/U28) -> 0 | AW28: =IF(AQ28=0,0,AV28/AQ28) -> 0 | AX28: =IF(AR28=0,0,AV28/AR28) -> 0 | AZ28: =AV28*E28 -> 0
A29: Ridges | B29: 207984029 | C29: sh4 | D29: Солнцезащитные очки | E29: =SUM(F29:J29) -> 0 | K29: 111.39 | L29: =E29*K29 -> 0 | Q29: =N29/32 -> 0 | R29: =U29/32 -> 0 | U29: =S29+T29 -> 0 | X29: =V29+W29 -> 0 | AA29: =Y29+Z29 -> 0 | AB29: =N29*O29*P29/100 -> 0 | AC29: =AA29/$AA$121 -> #DIV/0! | AD29: =U29*K29 -> 0 | AF29: =IF(AA29=0,0,AE29/AA29) -> 0 | AL29: =IFERROR($AL$121*H29/$H$121,0) -> 0 | AN29: =X29*5.71% -> 0 | AO29: =AA29-AD29-AE29-AG29-AH29-AI29-AK29-AL29-AN29-AM29 -> 0 | AQ29: =IF(U29=0,0,AA29/U29) -> 0 | AR29: =K29 -> 111.39 | AS29: =IF(U29=0,0,AE29/U29) -> 0 | AT29: =IF(S29=0,AG29/1,AG29/S29) -> 0 | AU29: =IF(S29=0,0,(AH29+AI29+AJ29)/S29) -> 0 | AV29: {=_xlfn.IFS(U29=0,AO29,U29<0,AO29/-U29,U29>0,AO29/U29)} -> 0 | AW29: =IF(AQ29=0,0,AV29/AQ29) -> 0 | AX29: =IF(AR29=0,0,AV29/AR29) -> 0 | AZ29: =AV29*E29 -> 0
A30: Ridges | B30: 233496972 | C30: sh06 | D30: Солнцезащитные очки | E30: =SUM(F30:J30) -> 0 | K30: 111.39 | L30: =E30*K30 -> 0 | Q30: =N30/32 -> 0 | R30: =U30/32 -> 0 | U30: =S30+T30 -> 0 | X30: =V30+W30 -> 0 | AA30: =Y30+Z30 -> 0 | AB30: =N30*O30*P30/100 -> 0 | AC30: =AA30/$AA$121 -> #DIV/0! | AD30: =U30*K30 -> 0 | AF30: =IF(AA30=0,0,AE30/AA30) -> 0 | AL30: =IFERROR($AL$121*H30/$H$121,0) -> 0 | AN30: =X30*5.71% -> 0 | AO30: =AA30-AD30-AE30-AG30-AH30-AI30-AK30-AL30-AN30-AM30 -> 0 | AQ30: =IF(U30=0,0,AA30/U30) -> 0 | AR30: =K30 -> 111.39 | AS30: =IF(U30=0,0,AE30/U30) -> 0 | AT30: =IF(S30=0,AG30/1,AG30/S30) -> 0 | AU30: =IF(S30=0,0,(AH30+AI30+AJ30)/S30) -> 0 | AV30: {=_xlfn.IFS(U30=0,AO30,U30<0,AO30/-U30,U30>0,AO30/U30)} -> 0 | AW30: =IF(AQ30=0,0,AV30/AQ30) -> 0 | AX30: =IF(AR30=0,0,AV30/AR30) -> 0 | AZ30: =AV30*E30 -> 0
A31: Ridges | B31: 233497520 | C31: sh07 | D31: Солнцезащитные очки | E31: =SUM(F31:J31) -> 0 | K31: 105.54 | L31: =E31*K31 -> 0 | Q31: =N31/32 -> 0 | R31: =U31/32 -> 0 | U31: =S31+T31 -> 0 | X31: =V31+W31 -> 0 | AA31: =Y31+Z31 -> 0 | AB31: =N31*O31*P31/100 -> 0 | AC31: =AA31/$AA$121 -> #DIV/0! | AD31: =U31*K31 -> 0 | AF31: =IF(AA31=0,0,AE31/AA31) -> 0 | AL31: =IFERROR($AL$121*H31/$H$121,0) -> 0 | AN31: =X31*5.71% -> 0 | AO31: =AA31-AD31-AE31-AG31-AH31-AI31-AK31-AL31-AN31-AM31 -> 0 | AQ31: =IF(U31=0,0,AA31/U31) -> 0 | AR31: =K31 -> 105.54 | AS31: =IF(U31=0,0,AE31/U31) -> 0 | AT31: =IF(S31=0,AG31/1,AG31/S31) -> 0 | AU31: =IF(S31=0,0,(AH31+AI31+AJ31)/S31) -> 0 | AV31: {=_xlfn.IFS(U31=0,AO31,U31<0,AO31/-U31,U31>0,AO31/U31)} -> 0 | AW31: =IF(AQ31=0,0,AV31/AQ31) -> 0 | AX31: =IF(AR31=0,0,AV31/AR31) -> 0 | AZ31: =AV31*E31 -> 0
A32: Ridges | B32: 233498313 | C32: sh08 | D32: Солнцезащитные очки | E32: =SUM(F32:J32) -> 0 | K32: 140.64 | L32: =E32*K32 -> 0 | Q32: =N32/32 -> 0 | R32: =U32/32 -> 0 | U32: =S32+T32 -> 0 | X32: =V32+W32 -> 0 | AA32: =Y32+Z32 -> 0 | AB32: =N32*O32*P32/100 -> 0 | AC32: =AA32/$AA$121 -> #DIV/0! | AD32: =U32*K32 -> 0 | AF32: =IF(AA32=0,0,AE32/AA32) -> 0 | AL32: =IFERROR($AL$121*H32/$H$121,0) -> 0 | AN32: =X32*5.71% -> 0 | AO32: =AA32-AD32-AE32-AG32-AH32-AI32-AK32-AL32-AN32-AM32 -> 0 | AQ32: =IF(U32=0,0,AA32/U32) -> 0 | AR32: =K32 -> 140.64 | AS32: =IF(U32=0,0,AE32/U32) -> 0 | AT32: =IF(S32=0,AG32/1,AG32/S32) -> 0 | AU32: =IF(S32=0,0,(AH32+AI32+AJ32)/S32) -> 0 | AV32: {=_xlfn.IFS(U32=0,AO32,U32<0,AO32/-U32,U32>0,AO32/U32)} -> 0 | AW32: =IF(AQ32=0,0,AV32/AQ32) -> 0 | AX32: =IF(AR32=0,0,AV32/AR32) -> 0 | AZ32: =AV32*E32 -> 0
A33: Ridges | B33: 233499847 | C33: sh09 | D33: Солнцезащитные очки | E33: =SUM(F33:J33) -> 0 | K33: 123.09 | L33: =E33*K33 -> 0 | Q33: =N33/32 -> 0 | R33: =U33/32 -> 0 | U33: =S33+T33 -> 0 | X33: =V33+W33 -> 0 | AA33: =Y33+Z33 -> 0 | AB33: =N33*O33*P33/100 -> 0 | AC33: =AA33/$AA$121 -> #DIV/0! | AD33: =U33*K33 -> 0 | AF33: =IF(AA33=0,0,AE33/AA33) -> 0 | AL33: =IFERROR($AL$121*H33/$H$121,0) -> 0 | AN33: =X33*5.71% -> 0 | AO33: =AA33-AD33-AE33-AG33-AH33-AI33-AK33-AL33-AN33-AM33 -> 0 | AQ33: =IF(U33=0,0,AA33/U33) -> 0 | AR33: =K33 -> 123.09 | AS33: =IF(U33=0,0,AE33/U33) -> 0 | AT33: =IF(S33=0,AG33/1,AG33/S33) -> 0 | AU33: =IF(S33=0,0,(AH33+AI33+AJ33)/S33) -> 0 | AV33: {=_xlfn.IFS(U33=0,AO33,U33<0,AO33/-U33,U33>0,AO33/U33)} -> 0 | AW33: =IF(AQ33=0,0,AV33/AQ33) -> 0 | AX33: =IF(AR33=0,0,AV33/AR33) -> 0 | AZ33: =AV33*E33 -> 0
A34: Ridges | B34: 233500274 | C34: sh10 | D34: Солнцезащитные очки | E34: =SUM(F34:J34) -> 0 | K34: 117.24 | L34: =E34*K34 -> 0 | Q34: =N34/32 -> 0 | R34: =U34/32 -> 0 | U34: =S34+T34 -> 0 | X34: =V34+W34 -> 0 | AA34: =Y34+Z34 -> 0 | AB34: =N34*O34*P34/100 -> 0 | AC34: =AA34/$AA$121 -> #DIV/0! | AD34: =U34*K34 -> 0 | AF34: =IF(AA34=0,0,AE34/AA34) -> 0 | AL34: =IFERROR($AL$121*H34/$H$121,0) -> 0 | AN34: =X34*5.71% -> 0 | AO34: =AA34-AD34-AE34-AG34-AH34-AI34-AK34-AL34-AN34-AM34 -> 0 | AQ34: =IF(U34=0,0,AA34/U34) -> 0 | AR34: =K34 -> 117.24 | AS34: =IF(U34=0,0,AE34/U34) -> 0 | AT34: =IF(S34=0,AG34/1,AG34/S34) -> 0 | AU34: =IF(S34=0,0,(AH34+AI34+AJ34)/S34) -> 0 | AV34: {=_xlfn.IFS(U34=0,AO34,U34<0,AO34/-U34,U34>0,AO34/U34)} -> 0 | AW34: =IF(AQ34=0,0,AV34/AQ34) -> 0 | AX34: =IF(AR34=0,0,AV34/AR34) -> 0 | AZ34: =AV34*E34 -> 0
