Workbook

Sheet Реклама
B2: ПЕРИОД | C2: БАЛАНС | F2: СЧЕТ | I2: Неделя
C3: Номер документа | D3: Сумма | E3: Даты | F3: Номер документа | G3: Сумма | H3: Даты
B4: 01-04.01 | F4: 277607349 | G4: 4738 | H4: 01-04.01 | I4: 1
B5: 04-11.01 | F5: 279228154 | G5: 6535 | H5: 04-11.01 | I5: 2
B6: 11-18.01 | C6: 280305485 | D6: 2922 | E6: 14-18.01 | F6: 280297200 | G6: 3464 | H6: 11-17.01 | I6: 3
B7: 18-25.01 | C7: 281290485 | D7: 5916 | E7: 18-23.01 | F7: 281290488 | G7: 2033 | H7: 18-25.01 | I7: 4
B8: 25.01-01.02 | C8: 282283796 | D8: 12613 | E8: 27-31.01 | F8: 282343451 | G8: 9553 | H8: 25-31.01 | I8: 5
C9: 282375547 | D9: 1000 | E9: 01.02 | F9: 282385566 | G9: 79 | H9: 01.02
B10: 01-08.02 | C10: 283356234 | D10: 9526 | E10: 01-04.02 | F10: 283392061 | G10: 17308 | H10: 01-08.02 | I10: 6
B11: 08-15.02 | C11: 284419876 | D11: 16968 | E11: 09-12.02 | F11: 284354982 | G11: 25029 | H11: 08-15.02 | I11: 7
B12: 15-22.02 | C12: 285375130 | D12: 19000 | E12: 16-21.02 | F12: 285375131 | G12: 43359 | H12: 16-22.02 | I12: 8
B13: 22.02-01.03 | C13: 286365345 | D13: 20188 | E13: 23-28.02 | F13: 286438626 | G13: 41519 | H13: 22-28.02 | I13: 9
F14: 286502032 | G14: 8252 | H14: 01.03
B15: 01-08.03 | C15: 287719816 | D15: 55356 | E15: 01.03-08.03 | F15: 287759820 | G15: 14284 | H15: 01.03-05.03 | I15: 10
B16: 08-15.03 | C16: 288712526 | D16: 117662 | E16: 08-15.03 | I16: 11
B17: 15-22.03 | C17: 289759802 | D17: 121051 | E17: 15-22.03 | I17: 12
B18: 22-29.03 | C18: 290725778 | D18: 128912 | E18: 22-29.03 | I18: 13
B19: 29.03-05.04 | C19: 291768435 | D19: 65325 | E19: 29-31.03 | I19: 14
C20: 291883504 | D20: 80610 | E20: 01-05.04 | F20: 291847775 | G20: 788 | H20: 04.02
I21: 15
H33: .

Sheet Сводная
B2: Период | E2: Дата поступления дс | F2: Итого к перечислению на счет, руб | G2: шт. | J2: ВБ реализовал товар (выручка с СПП) | M2: Выручка до вычета комиссии ВБ | P2: Себестоимость продаж | Q2: Логистика WB | R2: Комиссия WB | S2: Хранение WB | T2: Платная приемка WB | U2: Штрафы WB | V2: Прочие удержания WB | W2: Реклама БАЛАНС | X2: Реклама СЧЕТ | Y2: Блогеры | Z2: Налог | AA2: Прочие поступления WB | AB2: Прибыль до вычета налогов | AC2: Прибыль после вычета налогов | AD2: Итог месяц | AE2: % Cебестоимости | AF2: Маржинальность, % | AG2: Рентабельность, % | AH2: Доля рекламы, %
B3: Месяц | C3: Даты | D3: Нед | G3: Заказы | H3: Продажи | I3: Возвраты | J3: Продажи | K3: Возвраты | L3: Общая | M3: Продажи | N3: Возвраты | O3: Общая
B4: Январь 1 | C4: 29-31.12 | D4: 1 | F4: =IFERROR(O4-SUM(Q4:W4)+AA4,0) -> 21116.17 | G4: ='Юнит 1 29-31.12'!L$17 -> 29 | H4: ='Юнит 1 29-31.12'!Q$17 -> 31 | I4: ='Юнит 1 29-31.12'!R$17 -> 0 | J4: ='Юнит 1 29-31.12'!T$74 -> 31859.55 | K4: ='Юнит 1 29-31.12'!U$74 -> 0 | L4: =IFERROR(J4+K4,0) -> 31859.55 | M4: ='Юнит 1 29-31.12'!W$74 -> 37862.85 | N4: ='Юнит 1 29-31.12'!X$74 -> 0 | O4: =IFERROR(M4+N4,0) -> 37862.85 | P4: ='Юнит 1 29-31.12'!AB$74 -> 3949.17 | Q4: ='Юнит 1 29-31.12'!AE$74 -> 2587.3 | R4: ='Юнит 1 29-31.12'!AC$74 -> 13659.08 | S4: ='Юнит 1 29-31.12'!AI$74 -> 413.9 | U4: ='Юнит 1 29-31.12'!AJ$74 -> 0 | V4: 86.4 | W4: ='Юнит 1 29-31.12'!AF$74 -> 0 | X4: ='Юнит 1 29-31.12'!AG$74 -> 0 | Y4: ='Юнит 1 29-31.12'!AH84 -> 0 | Z4: 313.33 | AB4: =O4-SUM(P4:Y4)+AA4 -> 17167 | AC4: =O4-SUM(P4:Z4)+AA4 -> 16853.67 | AD4: =SUM(AC4:AC9) -> 67154.08 | AE4: =P4/O4 -> 0.10430197 | AF4: =AC4/P4 -> 4.2676486 | AG4: =AC4/O4 -> 0.44512418 | AH4: =(W4+X4+Y4)/O4 -> 0
C5: 01-04.01 | D5: 1 | F5: =IFERROR(O5-SUM(Q5:W5)+AA5,0) -> 8163.47 | G5: ='Юнит 1 01-04.01'!L$17 -> 37 | H5: ='Юнит 1 01-04.01'!Q$17 -> 14 | I5: ='Юнит 1 01-04.01'!R$17 -> 0 | J5: ='Юнит 1 01-04.01'!T$74 -> 14286.08 | K5: ='Юнит 1 01-04.01'!U$74 -> 0 | L5: =IFERROR(J5+K5,0) -> 14286.08 | M5: ='Юнит 1 01-04.01'!W$74 -> 17125.77 | N5: ='Юнит 1 01-04.01'!X$74 -> 0 | O5: =IFERROR(M5+N5,0) -> 17125.77 | P5: ='Юнит 1 01-04.01'!AB$74 -> 1763.04 | Q5: ='Юнит 1 01-04.01'!AE$74 -> 1955.75 | R5: ='Юнит 1 01-04.01'!AC$74 -> 6195.14 | S5: ='Юнит 1 01-04.01'!AI$74 -> 635.73 | U5: ='Юнит 1 01-04.01'!AJ$74 -> 0 | V5: 175.68 | W5: ='Юнит 1 01-04.01'!AF$74 -> 0 | X5: ='Юнит 1 01-04.01'!AG$74 -> 4738 | Y5: ='Юнит 1 01-04.01'!AH85 -> 0 | Z5: 144.56 | AB5: =O5-SUM(P5:Y5)+AA5 -> 1662.43 | AC5: =O5-SUM(P5:Z5)+AA5 -> 1517.87
B6: Январь 2 | C6: 05-11.01 | D6: 2 | F6: =IFERROR(O6-SUM(Q6:W6)+AA6,0) -> 25524.23 | G6: ='Юнит 2'!L$17 -> 86 | H6: ='Юнит 2'!Q$17 -> 43 | I6: ='Юнит 2'!R$17 -> -1 | J6: ='Юнит 2'!T$74 -> 43245.32 | K6: ='Юнит 2'!U$74 -> -931 | L6: =IFERROR(J6+K6,0) -> 42314.32 | M6: ='Юнит 2'!W$74 -> 52197.86 | N6: ='Юнит 2'!X$74 -> -1199 | O6: =IFERROR(M6+N6,0) -> 50998.86 | P6: ='Юнит 2'!AB$74 -> 5562.9 | Q6: ='Юнит 2'!AE$74 -> 5752.8 | R6: ='Юнит 2'!AC$74 -> 18463.04 | S6: ='Юнит 2'!AI$74 -> 1083.11 | U6: ='Юнит 2'!AJ$74 -> 0 | V6: 175.68 | W6: ='Юнит 2'!AF$74 -> 0 | X6: ='Юнит 2'!AG$74 -> 6535 | Y6: ='Юнит 2'!AH85 -> 0 | Z6: 416.28 | AB6: =O6-SUM(P6:Y6)+AA6 -> 13426.33 | AC6: =O6-SUM(P6:Z6)+AA6 -> 13010.05 | AE6: =P6/O6 -> 0.10907891 | AF6: =AC6/P6 -> 2.3387172 | AG6: =AC6/O6 -> 0.25510472 | AH6: =(W6+X6+Y6)/O6 -> 0.12814012
B7: Январь 3 | C7: 12-18.01 | D7: 3 | F7: =IFERROR(O7-SUM(Q7:W7)+AA7,0) -> 25982.83 | G7: ='Юнит 3'!L$17 -> 62 | H7: ='Юнит 3'!Q$17 -> 49 | I7: ='Юнит 3'!R$17 -> -1 | J7: ='Юнит 3'!T$74 -> 45785.47 | K7: ='Юнит 3'!U$74 -> -948 | L7: =IFERROR(J7+K7,0) -> 44837.47 | M7: ='Юнит 3'!W$74 -> 56919.74 | N7: ='Юнит 3'!X$74 -> -1174 | O7: =IFERROR(M7+N7,0) -> 55745.74 | P7: ='Юнит 3'!AB$74 -> 6528.42 | Q7: ='Юнит 3'!AE$74 -> 6055.25 | R7: ='Юнит 3'!AC$74 -> 19306.86 | S7: ='Юнит 3'!AI$74 -> 1361.68 | U7: ='Юнит 3'!AJ$74 -> 0 | V7: 117.12 | W7: ='Юнит 3'!AF$74 -> 2922 | X7: ='Юнит 3'!AG$74 -> 3464 | Y7: ='Юнит 3'!AH86 -> 0 | Z7: 467.24 | AB7: =O7-SUM(P7:Y7)+AA7 -> 15990.41 | AC7: =O7-SUM(P7:Z7)+AA7 -> 15523.17 | AE7: =P7/O7 -> 0.11711065 | AF7: =AC7/P7 -> 2.3777836 | AG7: =AC7/O7 -> 0.27846379 | AH7: =(W7+X7+Y7)/O7 -> 0.11455584
B8: Январь 4 | C8: 19-25.01 | D8: 4 | F8: =IFERROR(O8-SUM(Q8:W8)+AA8,0) -> 22836.85 | G8: ='Юнит 4'!L$17 -> 86 | H8: ='Юнит 4'!Q$17 -> 49 | I8: ='Юнит 4'!R$17 -> -2 | J8: ='Юнит 4'!T$74 -> 44338.88 | K8: ='Юнит 4'!U$74 -> -1888 | L8: =IFERROR(J8+K8,0) -> 42450.88 | M8: ='Юнит 4'!W$74 -> 59321.67 | N8: ='Юнит 4'!X$74 -> -2412 | O8: =IFERROR(M8+N8,0) -> 56909.67 | P8: ='Юнит 4'!AB$74 -> 6764.52 | Q8: ='Юнит 4'!AE$74 -> 6115.35 | R8: ='Юнит 4'!AC$74 -> 20543.92 | S8: ='Юнит 4'!AI$74 -> 1438.99 | U8: ='Юнит 4'!AJ$74 -> 0 | V8: 58.56 | W8: ='Юнит 4'!AF$74 -> 5916 | X8: ='Юнит 4'!AG$74 -> 2033 | Y8: ='Юнит 4'!AH87 -> 0 | Z8: 456.13 | AB8: =O8-SUM(P8:Y8)+AA8 -> 14039.33 | AC8: =O8-SUM(P8:Z8)+AA8 -> 13583.2 | AE8: =P8/O8 -> 0.11886416 | AF8: =AC8/P8 -> 2.0080065 | AG8: =AC8/O8 -> 0.23868 | AH8: =(W8+X8+Y8)/O8 -> 0.13967749
B9: Январь 5 | C9: 26.01-01.02 | D9: 5 | F9: =IFERROR(O9-SUM(Q9:W9)+AA9,0) -> 26541.81 | G9: ='Юнит 5'!L$17 -> 157 | H9: ='Юнит 5'!Q$17 -> 70 | I9: ='Юнит 5'!R$17 -> -1 | J9: ='Юнит 5'!T$74 -> 53707.42 | K9: ='Юнит 5'!U$74 -> -813 | L9: =IFERROR(J9+K9,0) -> 52894.42 | M9: ='Юнит 5'!W$74 -> 80352 | N9: ='Юнит 5'!X$74 -> -1238 | O9: =IFERROR(M9+N9,0) -> 79114 | P9: ='Юнит 5'!AB$74 -> 9760.32 | Q9: ='Юнит 5'!AE$74 -> 8509.6 | R9: ='Юнит 5'!AC$74 -> 28720.66 | S9: ='Юнит 5'!AI$74 -> 1377.57 | U9: ='Юнит 5'!AJ$74 -> 0 | V9: 351.36 | W9: ='Юнит 5'!AF$74 -> 13613 | X9: ='Юнит 5'!AG$74 -> 9632 | Y9: ='Юнит 5'!AH88 -> 0 | Z9: 483.37 | AB9: =O9-SUM(P9:Y9)+AA9 -> 7149.49 | AC9: =O9-SUM(P9:Z9)+AA9 -> 6666.12 | AE9: =P9/O9 -> 0.12337033 | AF9: =AC9/P9 -> 0.68298171 | AG9: =AC9/O9 -> 0.084259676 | AH9: =(W9+X9+Y9)/O9 -> 0.29381652
B10: Февраль 1 | C10: 02-08.02 | D10: 6 | F10: =IFERROR(O10-SUM(Q10:W10)+AA10,0) -> 59865 | G10: ='Юнит 6'!L$45 -> 286 | H10: ='Юнит 6'!Q$45 -> 118 | I10: ='Юнит 6'!R$45 -> -1 | J10: ='Юнит 6'!T$102 -> 85982.96 | K10: ='Юнит 6'!U$102 -> -777 | L10: =IFERROR(J10+K10,0) -> 85205.96 | M10: ='Юнит 6'!W$102 -> 132376.93 | N10: ='Юнит 6'!X$102 -> -1238 | O10: =IFERROR(M10+N10,0) -> 131138.93 | P10: ='Юнит 6'!AB$102 -> 15974.01 | Q10: ='Юнит 6'!AE$102 -> 12544.65 | R10: ='Юнит 6'!AC$102 -> 47795.47 | S10: ='Юнит 6'!AI$102 -> 1261.41 | U10: ='Юнит 6'!AJ$102 -> 0 | V10: 146.4 | W10: ='Юнит 6'!AF$102 -> 9526 | X10: ='Юнит 6'!AG$102 -> 17308 | Y10: ='Юнит 6'!AH117 -> 0 | Z10: 922.79 | AB10: =O10-SUM(P10:Y10)+AA10 -> 26582.99 | AC10: =O10-SUM(P10:Z10)+AA10 -> 25660.2 | AD10: =SUM(AC10:AC13) -> 265557.06 | AE10: =P10/O10 -> 0.12180982 | AF10: =AC10/P10 -> 1.6063719 | AG10: =AC10/O10 -> 0.19567187 | AH10: =(W10+X10+Y10)/O10 -> 0.20462269
B11: Февраль 2 | C11: 09-15.02 | D11: 7 | F11: =IFERROR(O11-SUM(Q11:W11)+AA11,0) -> 105982.04 | G11: ='Юнит 7'!L$45 -> 388 | H11: ='Юнит 7'!Q$45 -> 212 | I11: ='Юнит 7'!R$45 -> -2 | J11: ='Юнит 7'!T$102 -> 149383.2 | K11: ='Юнит 7'!U$102 -> -1458 | L11: =IFERROR(J11+K11,0) -> 147925.2 | M11: ='Юнит 7'!W$102 -> 234275.74 | N11: ='Юнит 7'!X$102 -> -2388 | O11: =IFERROR(M11+N11,0) -> 231887.74 | P11: ='Юнит 7'!AB$102 -> 27919.8 | Q11: ='Юнит 7'!AE$102 -> 22767.8 | R11: ='Юнит 7'!AC$102 -> 84374.68 | S11: ='Юнит 7'!AI$102 -> 1132.46 | T11: 165 | U11: ='Юнит 7'!AJ$102 -> 0 | V11: 497.76 | W11: ='Юнит 7'!AF$102 -> 16968 | X11: ='Юнит 7'!AG$102 -> 25029 | Y11: ='Юнит 7'!AH118 -> 0 | Z11: 1478.16 | AB11: =O11-SUM(P11:Y11)+AA11 -> 53033.24 | AC11: =O11-SUM(P11:Z11)+AA11 -> 51555.08 | AE11: =P11/O11 -> 0.12040223 | AF11: =AC11/P11 -> 1.8465419 | AG11: =AC11/O11 -> 0.22232775 | AH11: =(W11+X11+Y11)/O11 -> 0.18110919
B12: Февраль 3 | C12: 16-22.02 | D12: 8 | F12: =IFERROR(O12-SUM(Q12:W12)+AA12,0) -> 168699.24 | G12: ='Юнит 8'!L$45 -> 640 | H12: ='Юнит 8'!Q$45 -> 332 | I12: ='Юнит 8'!R$45 -> -3 | J12: ='Юнит 8'!T$102 -> 231517.83 | K12: ='Юнит 8'!U$102 -> -2178 | L12: =IFERROR(J12+K12,0) -> 229339.83 | M12: ='Юнит 8'!W$102 -> 360665.46 | N12: ='Юнит 8'!X$102 -> -3466 | O12: =IFERROR(M12+N12,0) -> 357199.46 | P12: ='Юнит 8'!AB$102 -> 44360.03 | Q12: ='Юнит 8'!AE$102 -> 32716.08 | R12: ='Юнит 8'!AC$102 -> 132861.28 | S12: ='Юнит 8'!AI$102 -> 1284.66 | T12: 1905 | U12: ='Юнит 8'!AJ$102 -> 294 | V12: 439.2 | W12: ='Юнит 8'!AF$102 -> 19000 | X12: ='Юнит 8'!AG$102 -> 43359 | Y12: ='Юнит 8'!AH119 -> 0 | Z12: 2261.26 | AB12: =O12-SUM(P12:Y12)+AA12 -> 80980.21 | AC12: =O12-SUM(P12:Z12)+AA12 -> 78718.95 | AE12: =P12/O12 -> 0.1241884 | AF12: =AC12/P12 -> 1.7745468 | AG12: =AC12/O12 -> 0.22037813 | AH12: =(W12+X12+Y12)/O12 -> 0.17457753
B13: Февраль 4 | C13: 23.02-01.03 | D13: 9 | F13: =IFERROR(O13-SUM(Q13:W13)+AA13,0) -> 214108.03 | G13: ='Юнит 9'!L$45 -> 632 | H13: ='Юнит 9'!Q$45 -> 399 | I13: ='Юнит 9'!R$45 -> -9 | J13: ='Юнит 9'!T$102 -> 296481.4 | K13: ='Юнит 9'!U$102 -> -6522 | L13: =IFERROR(J13+K13,0) -> 289959.4 | M13: ='Юнит 9'!W$102 -> 464446.44 | N13: ='Юнит 9'!X$102 -> -10316 | O13: =IFERROR(M13+N13,0) -> 454130.44 | P13: ='Юнит 9'!AB$102 -> 51789.51 | Q13: ='Юнит 9'!AE$102 -> 45998.58 | R13: ='Юнит 9'!AC$102 -> 171766.49 | S13: ='Юнит 9'!AI$102 -> 1545.78 | T13: 465 | U13: ='Юнит 9'!AJ$102 -> 0 | V13: 58.56 | W13: ='Юнит 9'!AF$102 -> 20188 | X13: ='Юнит 9'!AG$102 -> 49771 | Y13: ='Юнит 9'!AH120 -> 0 | Z13: 2924.69 | AB13: =O13-SUM(P13:Y13)+AA13 -> 112547.52 | AC13: =O13-SUM(P13:Z13)+AA13 -> 109622.83 | AE13: =P13/O13 -> 0.11404105 | AF13: =AC13/P13 -> 2.1166995 | AG13: =AC13/O13 -> 0.24139062 | AH13: =(W13+X13+Y13)/O13 -> 0.15405045
B14: Март 1 очки | C14: 02-08.03 | D14: 10 | F14: =IFERROR(O14-SUM(Q14:W14)+AA14,0) -> 183388.28 | G14: ='Юнит 10'!L$58 -> 833 | H14: ='Юнит 10'!Q$58 -> 382 | I14: ='Юнит 10'!R$58 -> -8 | J14: ='Юнит 10'!T$58 -> 300005.62 | K14: ='Юнит 10'!U$58 -> -6272.41 | L14: =IFERROR(J14+K14,0) -> 293733.21 | M14: ='Юнит 10'!W$58 -> 466843.39 | N14: ='Юнит 10'!X$58 -> -9947.95 | O14: =IFERROR(M14+N14,0) -> 456895.44 | P14: ='Юнит 10'!AB$58 -> 49184.92 | Q14: ='Юнит 10'!AE$58 -> 46676.69 | R14: ='Юнит 10'!AC$58 -> 172521.44 | S14: ='Юнит 10'!AI$58 -> 2108.03 | T14: 735 | U14: ='Юнит 10'!AJ$58 -> 30 | W14: ='Юнит 10'!AF$58 -> 51436 | X14: ='Юнит 10'!AG$58 -> 14284 | Y14: ='Юнит 10'!AH134 -> 0 | Z14: =IFERROR((L14)*0.01,0) -> 2937.3321 | AB14: =O14-SUM(P14:Y14)+AA14 -> 119919.36 | AC14: =O14-SUM(P14:Z14)+AA14 -> 116982.03 | AD14: =SUM(AC14:AC21) -> 1089390.4 | AE14: =P14/O14 -> 0.10765028 | AF14: =AC14/P14 -> 2.3784125 | AG14: =AC14/O14 -> 0.25603676 | AH14: =(W14+X14+Y14)/O14 -> 0.14384035
B15: Март 1 шапки | C15: 02-08.03 | D15: 10 | F15: =IFERROR(O15-SUM(Q15:W15)+AA15,0) -> -3920 | G15: ='Юнит 10'!L$68 -> 2 | H15: ='Юнит 10'!Q$68 -> 0 | I15: ='Юнит 10'!R$68 -> 0 | J15: ='Юнит 10'!T$68 -> 0 | K15: ='Юнит 10'!U$68 -> 0 | L15: =IFERROR(J15+K15,0) -> 0 | M15: ='Юнит 10'!W$68 -> 0 | N15: ='Юнит 10'!X$68 -> 0 | O15: =IFERROR(M15+N15,0) -> 0 | P15: ='Юнит 10'!AB$68 -> 0 | Q15: ='Юнит 10'!AE$68 -> 0 | R15: ='Юнит 10'!AC$68 -> 0 | S15: ='Юнит 10'!AI$68 -> 0 | U15: ='Юнит 10'!AJ$68 -> 0 | W15: ='Юнит 10'!AF$68 -> 3920 | X15: ='Юнит 10'!AG$68 -> 0 | Y15: ='Юнит 10'!AH135 -> 0 | Z15: =IFERROR((L15)*0.01,0) -> 0 | AB15: =O15-SUM(P15:Y15)+AA15 -> -3920 | AC15: =O15-SUM(P15:Z15)+AA15 -> -3920 | AE15: =P15/O15 -> #DIV/0! | AF15: =AC15/P15 -> #DIV/0! | AG15: =AC15/O15 -> #DIV/0! | AH15: =(W15+X15+Y15)/O15 -> #DIV/0!
B16: Март 2 очки | C16: 09-15.03 | D16: 11 | F16: =IFERROR(O16-SUM(Q16:W16)+AA16,0) -> 370668.61 | G16: ='Юнит 11'!L$58 -> 1503 | H16: ='Юнит 11'!Q$58 -> 797 | I16: ='Юнит 11'!R$58 -> -13 | J16: ='Юнит 11'!T$58 -> 612594.65 | K16: ='Юнит 11'!U$58 -> -10314 | L16: =IFERROR(J16+K16,0) -> 602280.65 | M16: ='Юнит 11'!W$58 -> 943118.99 | N16: ='Юнит 11'!X$58 -> -15997 | O16: =IFERROR(M16+N16,0) -> 927121.99 | P16: ='Юнит 11'!AB$58 -> 103751.9 | Q16: ='Юнит 11'!AE$58 -> 97317.48 | R16: ='Юнит 11'!AC$58 -> 349180.58 | S16: ='Юнит 11'!AI$58 -> 1851.28 | T16: 165 | U16: ='Юнит 11'!AJ$58 -> 0 | V16: 2357.04 | W16: ='Юнит 11'!AF$58 -> 105582 | X16: ='Юнит 11'!AG$58 -> 0 | Y16: ='Юнит 11'!AH136 -> 0 | Z16: =IFERROR((L16)*0.01,0) -> 6022.8065 | AB16: =O16-SUM(P16:Y16)+AA16 -> 266916.71 | AC16: =O16-SUM(P16:Z16)+AA16 -> 260893.9 | AE16: =P16/O16 -> 0.1119075 | AF16: =AC16/P16 -> 2.514594 | AG16: =AC16/O16 -> 0.28140192 | AH16: =(W16+X16+Y16)/O16 -> 0.11388145
B17: Март 2 шапки | C17: 09-15.03 | D17: 11 | F17: =IFERROR(O17-SUM(Q17:W17)+AA17,0) -> -12473.82 | G17: ='Юнит 11'!L$68 -> 16 | H17: ='Юнит 11'!Q$68 -> 0 | I17: ='Юнит 11'!R$68 -> 0 | J17: ='Юнит 11'!T$68 -> 0 | K17: ='Юнит 11'!U$68 -> 0 | L17: =IFERROR(J17+K17,0) -> 0 | M17: ='Юнит 11'!W$68 -> 0 | N17: ='Юнит 11'!X$68 -> 0 | O17: =IFERROR(M17+N17,0) -> 0 | P17: ='Юнит 11'!AB$68 -> 0 | Q17: ='Юнит 11'!AE$68 -> 198.82 | R17: ='Юнит 11'!AC$68 -> 0 | S17: ='Юнит 11'!AI$68 -> 0 | T17: 195 | U17: ='Юнит 11'!AJ$68 -> 0 | W17: ='Юнит 11'!AF$68 -> 12080 | X17: ='Юнит 11'!AG$68 -> 0 | Y17: ='Юнит 11'!AH137 -> 0 | Z17: =IFERROR((L17)*0.01,0) -> 0 | AB17: =O17-SUM(P17:Y17)+AA17 -> -12473.82 | AC17: =O17-SUM(P17:Z17)+AA17 -> -12473.82 | AE17: =P17/O17 -> #DIV/0! | AF17: =AC17/P17 -> #DIV/0! | AG17: =AC17/O17 -> #DIV/0! | AH17: =(W17+X17+Y17)/O17 -> #DIV/0!
B18: Март 3 очки | C18: 16-22.03 | D18: 12 | F18: =IFERROR(O18-SUM(Q18:W18)+AA18,0) -> 460743.49 | G18: ='Юнит 12'!L$58 -> 1912 | H18: ='Юнит 12'!Q$58 -> 947 | I18: ='Юнит 12'!R$58 -> -22 | J18: ='Юнит 12'!T$58 -> 770335.74 | K18: ='Юнит 12'!U$58 -> -17585.11 | L18: =IFERROR(J18+K18,0) -> 752750.63 | M18: ='Юнит 12'!W$58 -> 1160661.8 | N18: ='Юнит 12'!X$58 -> -26564.08 | O18: =IFERROR(M18+N18,0) -> 1134097.7 | P18: ='Юнит 12'!AB$58 -> 122764.06 | Q18: ='Юнит 12'!AE$58 -> 116519.87 | R18: ='Юнит 12'!AC$58 -> 428981.74 | S18: ='Юнит 12'!AI$58 -> 2973.3315 | T18: 300 | U18: ='Юнит 12'!AJ$58 -> 0 | V18: 3528.24 | W18: ='Юнит 12'!AF$58 -> 121051 | X18: ='Юнит 12'!AG$58 -> 0 | Y18: ='Юнит 12'!AH138 -> 0 | Z18: =IFERROR((L18)*0.01,0) -> 7527.5063 | AB18: =O18-SUM(P18:Y18)+AA18 -> 337979.43 | AC18: =O18-SUM(P18:Z18)+AA18 -> 330451.92 | AE18: =P18/O18 -> 0.10824823 | AF18: =AC18/P18 -> 2.6917644 | AG18: =AC18/O18 -> 0.29137872 | AH18: =(W18+X18+Y18)/O18 -> 0.10673772
B19: Март 3 шапки | C19: 16-22.03 | D19: 12 | F19: =IFERROR(O19-SUM(Q19:W19)+AA19,0) -> -2556.9685 | G19: ='Юнит 12'!L$68 -> 4 | H19: ='Юнит 12'!Q$68 -> 3 | I19: ='Юнит 12'!R$68 -> 0 | J19: ='Юнит 12'!T$68 -> 4468 | K19: ='Юнит 12'!U$68 -> 0 | L19: =IFERROR(J19+K19,0) -> 4468 | M19: ='Юнит 12'!W$68 -> 6680 | N19: ='Юнит 12'!X$68 -> 0 | O19: =IFERROR(M19+N19,0) -> 6680 | P19: ='Юнит 12'!AB$68 -> 1187.34 | Q19: ='Юнит 12'!AE$68 -> 2459.75 | R19: ='Юнит 12'!AC$68 -> 2953.15 | S19: ='Юнит 12'!AI$68 -> 3.7884878 | T19: 75 | U19: ='Юнит 12'!AJ$68 -> 3745.28 | W19: ='Юнит 12'!AF$68 -> 0 | X19: ='Юнит 12'!AG$68 -> 0 | Y19: ='Юнит 12'!AH139 -> 0 | Z19: =IFERROR((L19)*0.01,0) -> 44.68 | AB19: =O19-SUM(P19:Y19)+AA19 -> -3744.3085 | AC19: =O19-SUM(P19:Z19)+AA19 -> -3788.9885 | AE19: =P19/O19 -> 0.17774551 | AF19: =AC19/P19 -> -3.1911571 | AG19: =AC19/O19 -> -0.56721385 | AH19: =(W19+X19+Y19)/O19 -> 0
B20: Март 4 очки | C20: 23-29.03 | D20: 13 | F20: =IFERROR(O20-SUM(Q20:W20)+AA20,0) -> 545173.78 | G20: ='Юнит 13'!L$58 -> 1741 | H20: ='Юнит 13'!Q$58 -> 1033 | I20: ='Юнит 13'!R$58 -> -22 | J20: ='Юнит 13'!T$58 -> 894331.41 | K20: ='Юнит 13'!U$58 -> -18419.39 | L20: =IFERROR(J20+K20,0) -> 875912.02 | M20: ='Юнит 13'!W$58 -> 1343124.6 | N20: ='Юнит 13'!X$58 -> -28012.89 | O20: =IFERROR(M20+N20,0) -> 1315111.7 | P20: ='Юнит 13'!AB$58 -> 133965.07 | Q20: ='Юнит 13'!AE$58 -> 138495.53 | R20: ='Юнит 13'!AC$58 -> 495515.23 | S20: ='Юнит 13'!AI$58 -> 5304.7482 | T20: 30 | U20: ='Юнит 13'!AJ$58 -> 70 | V20: 1610.4 | W20: ='Юнит 13'!AF$58 -> 128912 | X20: ='Юнит 13'!AG$58 -> 0 | Y20: ='Юнит 13'!AH140 -> 0 | Z20: =IFERROR((L20)*0.01,0) -> 8759.1202 | AB20: =O20-SUM(P20:Y20)+AA20 -> 411208.71 | AC20: =O20-SUM(P20:Z20)+AA20 -> 402449.59 | AE20: =P20/O20 -> 0.10186593 | AF20: =AC20/P20 -> 3.0041383 | AG20: =AC20/O20 -> 0.30601932 | AH20: =(W20+X20+Y20)/O20 -> 0.098023613
B21: Март 4 шапки | C21: 23-29.03 | D21: 13 | F21: =IFERROR(O21-SUM(Q21:W21)+AA21,0) -> -1204.2518 | G21: ='Юнит 13'!L$68 -> 0 | H21: ='Юнит 13'!Q$68 -> 0 | I21: ='Юнит 13'!R$68 -> 0 | J21: ='Юнит 13'!T$68 -> 0 | K21: ='Юнит 13'!U$68 -> 0 | L21: =IFERROR(J21+K21,0) -> 0 | M21: ='Юнит 13'!W$68 -> 0 | N21: ='Юнит 13'!X$68 -> 0 | O21: =IFERROR(M21+N21,0) -> 0 | P21: ='Юнит 13'!AB$68 -> 0 | Q21: ='Юнит 13'!AE$68 -> 1195.55 | R21: ='Юнит 13'!AC$68 -> 0 | S21: ='Юнит 13'!AI$68 -> 8.7017952 | U21: ='Юнит 13'!AJ$68 -> 0 | W21: ='Юнит 13'!AF$68 -> 0 | X21: ='Юнит 13'!AG$68 -> 0 | Y21: ='Юнит 13'!AH141 -> 0 | Z21: =IFERROR((L21)*0.01,0) -> 0 | AB21: =O21-SUM(P21:Y21)+AA21 -> -1204.2518 | AC21: =O21-SUM(P21:Z21)+AA21 -> -1204.2518 | AE21: =P21/O21 -> #DIV/0! | AF21: =AC21/P21 -> #DIV/0! | AG21: =AC21/O21 -> #DIV/0! | AH21: =(W21+X21+Y21)/O21 -> #DIV/0!
B22: Апрель 1 очки | C22: 30.03-05.04 | D22: 14 | F22: =IFERROR(O22-SUM(Q22:W22)+AA22,0) -> 458789.03 | G22: ='Юнит 14'!L$58 -> 1458 | H22: ='Юнит 14'!Q$58 -> 957 | I22: ='Юнит 14'!R$58 -> -29 | J22: ='Юнит 14'!T$58 -> 818298.19 | K22: ='Юнит 14'!U$58 -> -24782 | L22: =IFERROR(J22+K22,0) -> 793516.19 | M22: ='Юнит 14'!W$58 -> 1234216.1 | N22: ='Юнит 14'!X$58 -> -37862 | O22: =IFERROR(M22+N22,0) -> 1196354.1 | P22: ='Юнит 14'!AB$58 -> 123010.15 | Q22: ='Юнит 14'!AE$58 -> 131915.07 | R22: ='Юнит 14'!AC$58 -> 450831.19 | S22: ='Юнит 14'!AI$58 -> 7319.828 | U22: ='Юнит 14'!AJ$58 -> 100 | V22: 1464 | W22: ='Юнит 14'!AF$58 -> 145935 | X22: ='Юнит 14'!AG$58 -> 788 | Y22: ='Юнит 14'!AH142 -> 0 | Z22: =IFERROR((L22)*0.01,0) -> 7935.1619 | AB22: =O22-SUM(P22:Y22)+AA22 -> 334990.88 | AC22: =O22-SUM(P22:Z22)+AA22 -> 327055.72 | AE22: =P22/O22 -> 0.10282085 | AF22: =AC22/P22 -> 2.6587702 | AG22: =AC22/O22 -> 0.27337702 | AH22: =(W22+X22+Y22)/O22 -> 0.12264178
B23: Апрель 1 шапки | C23: 30.03-05.04 | D23: 14 | F23: =IFERROR(O23-SUM(Q23:W23)+AA23,0) -> -211.39204 | G23: ='Юнит 14'!L$68 -> 1 | H23: ='Юнит 14'!Q$68 -> 0 | I23: ='Юнит 14'!R$68 -> 0 | J23: ='Юнит 14'!T$68 -> 0 | K23: ='Юнит 14'!U$68 -> 0 | L23: =IFERROR(J23+K23,0) -> 0 | M23: ='Юнит 14'!W$68 -> 0 | N23: ='Юнит 14'!X$68 -> 0 | O23: =IFERROR(M23+N23,0) -> 0 | P23: ='Юнит 14'!AB$68 -> 0 | Q23: ='Юнит 14'!AE$68 -> 198.82 | R23: ='Юнит 14'!AC$68 -> 0 | S23: ='Юнит 14'!AI$68 -> 12.572039 | U23: ='Юнит 14'!AJ$68 -> 0 | W23: ='Юнит 14'!AF$68 -> 0 | X23: ='Юнит 14'!AG$68 -> 0 | Y23: ='Юнит 14'!AH143 -> 0 | Z23: =IFERROR((L23)*0.01,0) -> 0 | AB23: =O23-SUM(P23:Y23)+AA23 -> -211.39204 | AC23: =O23-SUM(P23:Z23)+AA23 -> -211.39204 | AE23: =P23/O23 -> #DIV/0! | AF23: =AC23/P23 -> #DIV/0! | AG23: =AC23/O23 -> #DIV/0! | AH23: =(W23+X23+Y23)/O23 -> #DIV/0!
AB26: =O26-SUM(P26:Y26)+AA26 -> 0 | AC26: =O26-SUM(P26:Z26)+AA26 -> 0 | AE26: =P26/O26 -> #DIV/0! | AF26: =AC26/P26 -> #DIV/0! | AG26: =AC26/O26 -> #DIV/0! | AH26: =(W26+X26+Y26)/O26 -> #DIV/0!
B27: Итого | F27: =SUM(F4:F26) -> 2677216.4 | G27: =SUM(G4:G26) -> 9873 | H27: =SUM(H4:H26) -> 5436 | I27: =SUM(I4:I26) -> -114 | J27: =SUM(J4:J26) -> 4396621.7 | K27: =SUM(K4:K26) -> -92887.91 | L27: =SUM(L4:L26) -> 4303733.8 | M27: =SUM(M4:M26) -> 6650189.3 | ... AD27: =SUM(AD4:AD26) -> 1422101.5 | AE27: =P27/O27 -> 0.10881906 | AF27: =AC27/P27 -> 2.4694423 | AG27: =AC27/O27 -> 0.26872238 | AH27: =(W27+X27+Y27)/O27 -> 0.12814106
M28: % от выручки за весь период
N29: =-N27/M27 -> 0.021324945 | P29: =P27/$O$27 -> 0.10881906 | Q29: =Q27/$O$27 -> 0.10447782 | R29: =R27/$O$27 -> 0.37546549 | S29: =S27/$O$27 -> 0.0047811586 | T29: =T27/$O$27 -> 0.00061997048 | U29: =U27/$O$27 -> 0.00065135774 | V29: =V27/$O$27 -> 0.0017003324 | W29: =W27/$O$27 -> 0.1009544 | ... Z29: =Z27/$O$27 -> 0.0066213796 | AD29: =AC27/P27 -> 2.4694423 | AE29: Маржинальность, %
W30: =(W27+X27)/O27 -> 0.12814106 | AD30: =AC27/O27 -> 0.26872238 | AE30: Рентабельность, %
B32: ЯНВАРЬ | G32: =SUM(G4:G9) -> 457 | H32: =SUM(H4:H9) -> 256 | I32: =SUM(I4:I9) -> -5 | J32: =SUM(J4:J9) -> 233222.72 | K32: =SUM(K4:K9) -> -4580 | L32: =SUM(L4:L9) -> 228642.72 | M32: =SUM(M4:M9) -> 303779.89 | N32: =SUM(N4:N9) -> -6023 | ... AA32: =SUM(AA4:AA9) -> 0 | AC32: =SUM(AC4:AC9) -> 67154.08 | AD32: =AC32/P32 -> 1.9562269
N33: =-N32/M32 -> 0.019826856 | P33: =P32/$O$32 -> 0.11528993 | Q33: =Q32/$O$32 -> 0.10403135 | R33: =R32/$O$32 -> 0.35897977 | S33: =S32/$O$32 -> 0.021195076 | T33: =T32/$O$32 -> 0 | U33: =U32/$O$32 -> 0 | V33: =V32/$O$32 -> 0.0032402273 | W33: =W32/$O$32 -> 0.075400438 | ... AA33: =AA32/$O$32 -> 0 | AC33: =AC32/O32 -> 0.22553325 | AD33: =AC32/O32 -> 0.22553325
B35: ФЕВРАЛЬ | G35: =SUM(G10:G13) -> 1946 | H35: =SUM(H10:H13) -> 1061 | I35: =SUM(I10:I13) -> -15 | J35: =SUM(J10:J13) -> 763365.39 | K35: =SUM(K10:K13) -> -10935 | L35: =SUM(L10:L13) -> 752430.39 | M35: =SUM(M10:M13) -> 1191764.6 | N35: =SUM(N10:N13) -> -17408 | ... AC35: =SUM(AC10:AC13) -> 265557.06 | AD35: =AC35/P35 -> 1.896249
N36: =-N35/M35 -> 0.014606912 | P36: =P35/$O$35 -> 0.11925113 | Q36: =Q35/$O$35 -> 0.09709752 | R36: =R35/$O$35 -> 0.37194659 | S36: =S35/$O$35 -> 0.0044486574 | T36: =T35/$O$35 -> 0.0021586289 | U36: =U35/$O$35 -> 0.00025034986 | V36: =V35/$O$35 -> 0.00097237928 | W36: =W35/$O$35 -> 0.055930202 | ... AA36: =AA35/$O$35 -> 0 | AC36: =AC35/O35 -> 0.22612984 | AD36: =AC35/O35 -> 0.22612984
B38: 11 нед очки | G38: =G16 -> 1503 | H38: =H16 -> 797 | I38: =I16 -> -13 | J38: =J16 -> 612594.65 | K38: =K16 -> -10314 | L38: =L16 -> 602280.65 | M38: =M16 -> 943118.99 | N38: =N16 -> -15997 | ... AC38: =AC16 -> 260893.9 | AD38: =AC16/P16 -> 2.514594
N39: =-N38/$M$38 -> 0.016961805 | P39: =P38/$O$38 -> 0.1119075 | Q39: =Q38/$O$38 -> 0.10496729 | R39: =R38/$O$38 -> 0.37662852 | S39: =S38/$O$38 -> 0.001996803 | T39: =T38/$O$38 -> 0.00017797011 | U39: =U38/$O$38 -> 0 | V39: =V38/$O$38 -> 0.0025423192 | W39: =W38/$O$38 -> 0.11388145 | ... AC39: =AC38/$O$38 -> 0.28140192 | AD39: =AC16/O16 -> 0.28140192
B41: 12 нед очки | G41: =G18 -> 1912 | H41: =H18 -> 947 | I41: =I18 -> -22 | J41: =J18 -> 770335.74 | K41: =K18 -> -17585.11 | L41: =L18 -> 752750.63 | M41: =M18 -> 1160661.8 | N41: =N18 -> -26564.08 | ... AC41: =AC18 -> 330451.92 | AD41: =AC18/P18 -> 2.6917644
N42: =-N41/$M$41 -> 0.022887013 | P42: =P41/$O$41 -> 0.10824823 | Q42: =Q41/$O$41 -> 0.10274236 | R42: =R41/$O$41 -> 0.3782582 | S42: =S41/$O$41 -> 0.0026217597 | T42: =T41/$O$41 -> 0.00026452748 | U42: =U41/$O$41 -> 0 | V42: =V41/$O$41 -> 0.0031110548 | W42: =W41/$O$41 -> 0.10673772 | ... AC42: =AC41/$O$41 -> 0.29137872 | AD42: =AC18/O18 -> 0.29137872
B44: 13 нед очки | G44: =G20 -> 1741 | H44: =H20 -> 1033 | I44: =I20 -> -22 | J44: =J20 -> 894331.41 | K44: =K20 -> -18419.39 | L44: =L20 -> 875912.02 | M44: =M20 -> 1343124.6 | N44: =N20 -> -28012.89 | ... AC44: =AC20 -> 402449.59 | AD44: =AC20/P20 -> 3.0041383
N45: =-N44/$M$44 -> 0.020856509 | P45: =P44/$O$44 -> 0.10186593 | Q45: =Q44/$O$44 -> 0.10531085 | R45: =R44/$O$44 -> 0.37678566 | S45: =S44/$O$44 -> 0.0040336865 | T45: =T44/$O$44 -> 2.2811751e-05 | U45: =U44/$O$44 -> 5.3227418e-05 | V45: =V44/$O$44 -> 0.0012245348 | W45: =W44/$O$44 -> 0.098023613 | ... AC45: =AC44/$O$44 -> 0.30601932 | AD45: =AC20/O20 -> 0.30601932
B47: МАРТ очки | G47: =G14+G16+G18+G20 -> 5989 | H47: =H14+H16+H18+H20 -> 3159 | I47: =I14+I16+I18+I20 -> -65 | J47: =J14+J16+J18+J20 -> 2577267.4 | K47: =K14+K16+K18+K20 -> -52590.91 | L47: =L14+L16+L18+L20 -> 2524676.5 | M47: =M14+M16+M18+M20 -> 3913748.7 | N47: =N14+N16+N18+N20 -> -80521.92 | ... AC47: =AC14+AC16+AC18+AC20 -> 1110777.4 | AD47: =AC47/P47 -> 2.7114224
N48: =-N47/M47 -> 0.020574116 | P48: =P47/$O47 -> 0.10687235 | Q48: =Q47/$O47 -> 0.10409235 | R48: =R47/$O47 -> 0.37727979 | S48: =S47/$O47 -> 0.0031924513 | T48: =T47/$O47 -> 0.00032087848 | U48: =U47/$O47 -> 2.6087682e-05 | V48: =V47/$O47 -> 0.0019554491 | W48: =W47/$O47 -> 0.10617191 | ... AA48: =AA47/$O47 -> 0 | AC48: =AC47/O47 -> 0.28977608 | AD48: =AC47/O47 -> 0.28977608
B50: МАРТ шапки | G50: =G15+G17+G19+G21 -> 22 | H50: =H15+H17+H19+H21 -> 3 | I50: =I15+I17+I19+I21 -> 0 | J50: =J15+J17+J19+J21 -> 4468 | K50: =K15+K17+K19+K21 -> 0 | L50: =L15+L17+L19+L21 -> 4468 | M50: =M15+M17+M19+M21 -> 6680 | N50: =N15+N17+N19+N21 -> 0 | ... AC50: =AC15+AC17+AC19+AC21 -> -21387.06 | AD50: =AC50/P50 -> -18.012583
...

Sheet АВС 15
B2: ОЧКИ
C3: Прибыль | D3: % прибыль | E3: Доля | F3: ABC прибыль | G3: ABC кол-во | J3: Кол-во | K3: % кол-во | L3: Доля | M3: ABC кол-во
B4: Черные с железкой Сул | D4: =C4/C$58 -> #DIV/0! | E4: =D4 -> #DIV/0! | F4: =IF(AND(E4<=0),"C",IF(E4<=0.8,"A",IF(E4<=0.95,"B","C"))) -> #DIV/0! | G4: =VLOOKUP(B$4:B$57,I$4:M$57,5,0) -> #DIV/0! | I4: Черные с железкой Сул | K4: =J4/J$58 -> #DIV/0! | L4: =K4 -> #DIV/0! | M4: =_xlfn.IFS(L4<80%,"A",L4<=95%,"B",L4>95%,"C") -> #DIV/0! | P4: A | Q4: 0.8
B5: Qs черн Сул | D5: =C5/C$58 -> #DIV/0! | E5: =E4+D5 -> #DIV/0! | F5: =IF(AND(E5<=0),"C",IF(E5<=0.8,"A",IF(E5<=0.95,"B","C"))) -> #DIV/0! | G5: =VLOOKUP(B$4:B$57,I$4:M$57,5,0) -> #DIV/0! | I5: Qs черн Сул | K5: =J5/J$58 -> #DIV/0! | L5: =L4+K5 -> #DIV/0! | M5: =_xlfn.IFS(L5<80%,"A",L5<=95%,"B",L5>95%,"C") -> #DIV/0! | P5: B | Q5: 0.15
B6: Qs син Сул | D6: =C6/C$58 -> #DIV/0! | E6: =E5+D6 -> #DIV/0! | F6: =IF(AND(E6<=0),"C",IF(E6<=0.8,"A",IF(E6<=0.95,"B","C"))) -> #DIV/0! | G6: =VLOOKUP(B$4:B$57,I$4:M$57,5,0) -> #DIV/0! | I6: Qs син Сул | K6: =J6/J$58 -> #DIV/0! | L6: =L5+K6 -> #DIV/0! | M6: =_xlfn.IFS(L6<80%,"A",L6<=95%,"B",L6>95%,"C") -> #DIV/0! | P6: C | Q6: 0.05
B7: Qs желт Сул | D7: =C7/C$58 -> #DIV/0! | E7: =E6+D7 -> #DIV/0! | F7: =IF(AND(E7<=0),"C",IF(E7<=0.8,"A",IF(E7<=0.95,"B","C"))) -> #DIV/0! | G7: =VLOOKUP(B$4:B$57,I$4:M$57,5,0) -> #DIV/0! | I7: Qs желт Сул | K7: =J7/J$58 -> #DIV/0! | L7: =L6+K7 -> #DIV/0! | M7: =_xlfn.IFS(L7<80%,"A",L7<=95%,"B",L7>95%,"C") -> #DIV/0!
B8: flip черные Сул | D8: =C8/C$58 -> #DIV/0! | E8: =E7+D8 -> #DIV/0! | F8: =IF(AND(E8<=0),"C",IF(E8<=0.8,"A",IF(E8<=0.95,"B","C"))) -> #DIV/0! | G8: =VLOOKUP(B$4:B$57,I$4:M$57,5,0) -> #DIV/0! | I8: flip черные Сул | K8: =J8/J$58 -> #DIV/0! | L8: =L7+K8 -> #DIV/0! | M8: =_xlfn.IFS(L8<80%,"A",L8<=95%,"B",L8>95%,"C") -> #DIV/0!
B9: flip желтые Сул | D9: =C9/C$58 -> #DIV/0! | E9: =E8+D9 -> #DIV/0! | F9: =IF(AND(E9<=0),"C",IF(E9<=0.8,"A",IF(E9<=0.95,"B","C"))) -> #DIV/0! | G9: =VLOOKUP(B$4:B$57,I$4:M$57,5,0) -> #DIV/0! | I9: flip желтые Сул | K9: =J9/J$58 -> #DIV/0! | L9: =L8+K9 -> #DIV/0! | M9: =_xlfn.IFS(L9<80%,"A",L9<=95%,"B",L9>95%,"C") -> #DIV/0!
B10: MR8854 C2 Сул | D10: =C10/C$58 -> #DIV/0! | E10: =E9+D10 -> #DIV/0! | F10: =IF(AND(E10<=0),"C",IF(E10<=0.8,"A",IF(E10<=0.95,"B","C"))) -> #DIV/0! | G10: =VLOOKUP(B$4:B$57,I$4:M$57,5,0) -> #DIV/0! | I10: MR8854 C2 Сул | K10: =J10/J$58 -> #DIV/0! | L10: =L9+K10 -> #DIV/0! | M10: =_xlfn.IFS(L10<80%,"A",L10<=95%,"B",L10>95%,"C") -> #DIV/0!
B11: MR 1819 черн | D11: =C11/C$58 -> #DIV/0! | E11: =E10+D11 -> #DIV/0! | F11: =IF(AND(E11<=0),"C",IF(E11<=0.8,"A",IF(E11<=0.95,"B","C"))) -> #DIV/0! | G11: =VLOOKUP(B$4:B$57,I$4:M$57,5,0) -> #DIV/0! | I11: MR 1819 черн | K11: =J11/J$58 -> #DIV/0! | L11: =L10+K11 -> #DIV/0! | M11: =_xlfn.IFS(L11<80%,"A",L11<=95%,"B",L11>95%,"C") -> #DIV/0!
B12: MR 1819 корич | D12: =C12/C$58 -> #DIV/0! | E12: =E11+D12 -> #DIV/0! | F12: =IF(AND(E12<=0),"C",IF(E12<=0.8,"A",IF(E12<=0.95,"B","C"))) -> #DIV/0! | G12: =VLOOKUP(B$4:B$57,I$4:M$57,5,0) -> #DIV/0! | I12: MR 1819 корич | K12: =J12/J$58 -> #DIV/0! | L12: =L11+K12 -> #DIV/0! | M12: =_xlfn.IFS(L12<80%,"A",L12<=95%,"B",L12>95%,"C") -> #DIV/0!
B13: MR Р1874 черн | D13: =C13/C$58 -> #DIV/0! | E13: =E12+D13 -> #DIV/0! | F13: =IF(AND(E13<=0),"C",IF(E13<=0.8,"A",IF(E13<=0.95,"B","C"))) -> #DIV/0! | G13: =VLOOKUP(B$4:B$57,I$4:M$57,5,0) -> #DIV/0! | I13: MR Р1874 черн | K13: =J13/J$58 -> #DIV/0! | L13: =L12+K13 -> #DIV/0! | M13: =_xlfn.IFS(L13<80%,"A",L13<=95%,"B",L13>95%,"C") -> #DIV/0!
B14: MR Р1874 корич | D14: =C14/C$58 -> #DIV/0! | E14: =E13+D14 -> #DIV/0! | F14: =IF(AND(E14<=0),"C",IF(E14<=0.8,"A",IF(E14<=0.95,"B","C"))) -> #DIV/0! | G14: =VLOOKUP(B$4:B$57,I$4:M$57,5,0) -> #DIV/0! | I14: MR Р1874 корич | K14: =J14/J$58 -> #DIV/0! | L14: =L13+K14 -> #DIV/0! | M14: =_xlfn.IFS(L14<80%,"A",L14<=95%,"B",L14>95%,"C") -> #DIV/0!
B15: MR Р1886 черн | D15: =C15/C$58 -> #DIV/0! | E15: =E14+D15 -> #DIV/0! | F15: =IF(AND(E15<=0),"C",IF(E15<=0.8,"A",IF(E15<=0.95,"B","C"))) -> #DIV/0! | G15: =VLOOKUP(B$4:B$57,I$4:M$57,5,0) -> #DIV/0! | I15: MR Р1886 черн | K15: =J15/J$58 -> #DIV/0! | L15: =L14+K15 -> #DIV/0! | M15: =_xlfn.IFS(L15<80%,"A",L15<=95%,"B",L15>95%,"C") -> #DIV/0!
B16: MR Р1886 корич | D16: =C16/C$58 -> #DIV/0! | E16: =E15+D16 -> #DIV/0! | F16: =IF(AND(E16<=0),"C",IF(E16<=0.8,"A",IF(E16<=0.95,"B","C"))) -> #DIV/0! | G16: =VLOOKUP(B$4:B$57,I$4:M$57,5,0) -> #DIV/0! | I16: MR Р1886 корич | K16: =J16/J$58 -> #DIV/0! | L16: =L15+K16 -> #DIV/0! | M16: =_xlfn.IFS(L16<80%,"A",L16<=95%,"B",L16>95%,"C") -> #DIV/0!
B17: MR 1890 черн | D17: =C17/C$58 -> #DIV/0! | E17: =E16+D17 -> #DIV/0! | F17: =IF(AND(E17<=0),"C",IF(E17<=0.8,"A",IF(E17<=0.95,"B","C"))) -> #DIV/0! | G17: =VLOOKUP(B$4:B$57,I$4:M$57,5,0) -> #DIV/0! | I17: MR 1890 черн | K17: =J17/J$58 -> #DIV/0! | L17: =L16+K17 -> #DIV/0! | M17: =_xlfn.IFS(L17<80%,"A",L17<=95%,"B",L17>95%,"C") -> #DIV/0!
B18: MR 1890 желт | D18: =C18/C$58 -> #DIV/0! | E18: =E17+D18 -> #DIV/0! | F18: =IF(AND(E18<=0),"C",IF(E18<=0.8,"A",IF(E18<=0.95,"B","C"))) -> #DIV/0! | G18: =VLOOKUP(B$4:B$57,I$4:M$57,5,0) -> #DIV/0! | I18: MR 1890 желт | K18: =J18/J$58 -> #DIV/0! | L18: =L17+K18 -> #DIV/0! | M18: =_xlfn.IFS(L18<80%,"A",L18<=95%,"B",L18>95%,"C") -> #DIV/0!
... B27: qs009 | D27: =C27/C$58 -> #DIV/0! | E27: =E26+D27 -> #DIV/0! | F27: =IF(AND(E27<=0),"C",IF(E27<=0.8,"A",IF(E27<=0.95,"B","C"))) -> #DIV/0! | G27: =VLOOKUP(B$4:B$57,I$4:M$57,5,0) -> #DIV/0! | I27: qs009 | K27: =J27/J$58 -> #DIV/0! | L27: =L26+K27 -> #DIV/0! | M27: =_xlfn.IFS(L27<80%,"A",L27<=95%,"B",L27>95%,"C") -> #DIV/0!
B28: qs010 | D28: =C28/C$58 -> #DIV/0! | E28: =E24+D28 -> #DIV/0! | F28: =IF(AND(E28<=0),"C",IF(E28<=0.8,"A",IF(E28<=0.95,"B","C"))) -> #DIV/0! | G28: =VLOOKUP(B$4:B$57,I$4:M$57,5,0) -> #DIV/0! | I28: qs010 | K28: =J28/J$58 -> #DIV/0! | L28: =L24+K28 -> #DIV/0! | M28: =_xlfn.IFS(L28<80%,"A",L28<=95%,"B",L28>95%,"C") -> #DIV/0!
B29: qs011 | D29: =C29/C$58 -> #DIV/0! | E29: =E28+D29 -> #DIV/0! | F29: =IF(AND(E29<=0),"C",IF(E29<=0.8,"A",IF(E29<=0.95,"B","C"))) -> #DIV/0! | G29: =VLOOKUP(B$4:B$57,I$4:M$57,5,0) -> #DIV/0! | I29: qs011 | K29: =J29/J$58 -> #DIV/0! | L29: =L28+K29 -> #DIV/0! | M29: =_xlfn.IFS(L29<80%,"A",L29<=95%,"B",L29>95%,"C") -> #DIV/0!
B30: qs012 | D30: =C30/C$58 -> #DIV/0! | E30: =E29+D30 -> #DIV/0! | F30: =IF(AND(E30<=0),"C",IF(E30<=0.8,"A",IF(E30<=0.95,"B","C"))) -> #DIV/0! | G30: =VLOOKUP(B$4:B$57,I$4:M$57,5,0) -> #DIV/0! | I30: qs012 | K30: =J30/J$58 -> #DIV/0! | L30: =L29+K30 -> #DIV/0! | M30: =_xlfn.IFS(L30<80%,"A",L30<=95%,"B",L30>95%,"C") -> #DIV/0!
B31: qs013 | D31: =C31/C$58 -> #DIV/0! | E31: =E30+D31 -> #DIV/0! | F31: =IF(AND(E31<=0),"C",IF(E31<=0.8,"A",IF(E31<=0.95,"B","C"))) -> #DIV/0! | G31: =VLOOKUP(B$4:B$57,I$4:M$57,5,0) -> #DIV/0! | I31: qs013 | K31: =J31/J$58 -> #DIV/0! | L31: =L30+K31 -> #DIV/0! | M31: =_xlfn.IFS(L31<80%,"A",L31<=95%,"B",L31>95%,"C") -> #DIV/0!
B32: qs014 | D32: =C32/C$58 -> #DIV/0! | E32: =E31+D32 -> #DIV/0! | F32: =IF(AND(E32<=0),"C",IF(E32<=0.8,"A",IF(E32<=0.95,"B","C"))) -> #DIV/0! | G32: =VLOOKUP(B$4:B$57,I$4:M$57,5,0) -> #DIV/0! | I32: qs014 | K32: =J32/J$58 -> #DIV/0! | L32: =L31+K32 -> #DIV/0! | M32: =_xlfn.IFS(L32<80%,"A",L32<=95%,"B",L32>95%,"C") -> #DIV/0!
B33: qs015 | D33: =C33/C$58 -> #DIV/0! | E33: =E32+D33 -> #DIV/0! | F33: =IF(AND(E33<=0),"C",IF(E33<=0.8,"A",IF(E33<=0.95,"B","C"))) -> #DIV/0! | G33: =VLOOKUP(B$4:B$57,I$4:M$57,5,0) -> #DIV/0! | I33: qs015 | K33: =J33/J$58 -> #DIV/0! | L33: =L32+K33 -> #DIV/0! | M33: =_xlfn.IFS(L33<80%,"A",L33<=95%,"B",L33>95%,"C") -> #DIV/0!
B34: qs001 Ж | D34: =C34/C$58 -> #DIV/0! | E34: =E33+D34 -> #DIV/0! | F34: =IF(AND(E34<=0),"C",IF(E34<=0.8,"A",IF(E34<=0.95,"B","C"))) -> #DIV/0! | G34: =VLOOKUP(B$4:B$57,I$4:M$57,5,0) -> #DIV/0! | I34: qs001 Ж | K34: =J34/J$58 -> #DIV/0! | L34: =L33+K34 -> #DIV/0! | M34: =_xlfn.IFS(L34<80%,"A",L34<=95%,"B",L34>95%,"C") -> #DIV/0!
B35: qs010ж | D35: =C35/C$58 -> #DIV/0! | E35: =E34+D35 -> #DIV/0! | F35: =IF(AND(E35<=0),"C",IF(E35<=0.8,"A",IF(E35<=0.95,"B","C"))) -> #DIV/0! | G35: =VLOOKUP(B$4:B$57,I$4:M$57,5,0) -> #DIV/0! | I35: qs010ж | K35: =J35/J$58 -> #DIV/0! | L35: =L34+K35 -> #DIV/0! | M35: =_xlfn.IFS(L35<80%,"A",L35<=95%,"B",L35>95%,"C") -> #DIV/0!
B36: qs011ж | D36: =C36/C$58 -> #DIV/0! | E36: =E35+D36 -> #DIV/0! | F36: =IF(AND(E36<=0),"C",IF(E36<=0.8,"A",IF(E36<=0.95,"B","C"))) -> #DIV/0! | G36: =VLOOKUP(B$4:B$57,I$4:M$57,5,0) -> #DIV/0! | I36: qs011ж | K36: =J36/J$58 -> #DIV/0! | L36: =L35+K36 -> #DIV/0! | M36: =_xlfn.IFS(L36<80%,"A",L36<=95%,"B",L36>95%,"C") -> #DIV/0!
B37: qs012ж | D37: =C37/C$58 -> #DIV/0! | E37: =E36+D37 -> #DIV/0! | F37: =IF(AND(E37<=0),"C",IF(E37<=0.8,"A",IF(E37<=0.95,"B","C"))) -> #DIV/0! | G37: =VLOOKUP(B$4:B$57,I$4:M$57,5,0) -> #DIV/0! | I37: qs012ж | K37: =J37/J$58 -> #DIV/0! | L37: =L36+K37 -> #DIV/0! | M37: =_xlfn.IFS(L37<80%,"A",L37<=95%,"B",L37>95%,"C") -> #DIV/0!
B38: 2038ч/б | D38: =C38/C$58 -> #DIV/0! | E38: =E37+D38 -> #DIV/0! | F38: =IF(AND(E38<=0),"C",IF(E38<=0.8,"A",IF(E38<=0.95,"B","C"))) -> #DIV/0! | G38: =VLOOKUP(B$4:B$57,I$4:M$57,5,0) -> #DIV/0! | I38: 2038ч/б | K38: =J38/J$58 -> #DIV/0! | L38: =L37+K38 -> #DIV/0! | M38: =_xlfn.IFS(L38<80%,"A",L38<=95%,"B",L38>95%,"C") -> #DIV/0!
B39: 2038красный | D39: =C39/C$58 -> #DIV/0! | E39: =E38+D39 -> #DIV/0! | F39: =IF(AND(E39<=0),"C",IF(E39<=0.8,"A",IF(E39<=0.95,"B","C"))) -> #DIV/0! | G39: =VLOOKUP(B$4:B$57,I$4:M$57,5,0) -> #DIV/0! | I39: 2038красный | K39: =J39/J$58 -> #DIV/0! | L39: =L38+K39 -> #DIV/0! | M39: =_xlfn.IFS(L39<80%,"A",L39<=95%,"B",L39>95%,"C") -> #DIV/0!
B40: 2100черный | D40: =C40/C$58 -> #DIV/0! | E40: =E39+D40 -> #DIV/0! | F40: =IF(AND(E40<=0),"C",IF(E40<=0.8,"A",IF(E40<=0.95,"B","C"))) -> #DIV/0! | G40: =VLOOKUP(B$4:B$57,I$4:M$57,5,0) -> #DIV/0! | I40: 2100черный | K40: =J40/J$58 -> #DIV/0! | L40: =L39+K40 -> #DIV/0! | M40: =_xlfn.IFS(L40<80%,"A",L40<=95%,"B",L40>95%,"C") -> #DIV/0!
... B57: 8852 | D57: =C57/C$58 -> #DIV/0! | E57: =E56+D57 -> #DIV/0! | F57: =IF(AND(E57<=0),"C",IF(E57<=0.8,"A",IF(E57<=0.95,"B","C"))) -> #DIV/0! | G57: =VLOOKUP(B$4:B$57,I$4:M$57,5,0) -> #DIV/0! | I57: 8852 | K57: =J57/J$58 -> #DIV/0! | L57: =L56+K57 -> #DIV/0! | M57: =_xlfn.IFS(L57<80%,"A",L57<=95%,"B",L57>95%,"C") -> #DIV/0!
C58: =SUM(C4:C57) -> 0 | D58: =SUM(D4:D44) -> #DIV/0! | J58: =SUM(J4:J57) -> 0 | K58: =SUM(K4:K44) -> #DIV/0!
C61: Прибыль | D61: % прибыль | E61: Доля | F61: ABC прибыль | G61: ABC кол-во | J61: Кол-во | K61: % кол-во | L61: Доля | M61: ABC кол-во
D62: =C62/C$114 -> #DIV/0! | E62: =D62 -> #DIV/0! | F62: =IF(AND(E62<=0),"C",IF(E62<=0.8,"A",IF(E62<=0.95,"B","C"))) -> #DIV/0! | G62: =VLOOKUP(B62:B113,I$62:M$113,5,0) -> #N/A | K62: =J62/J$114 -> #DIV/0! | L62: =K62 -> #DIV/0! | M62: =_xlfn.IFS(L62<80%,"A",L62<=95%,"B",L62>95%,"C") -> #DIV/0!
D63: =C63/C$114 -> #DIV/0! | E63: =D63+E62 -> #DIV/0! | F63: =IF(AND(E63<=0),"C",IF(E63<=0.8,"A",IF(E63<=0.95,"B","C"))) -> #DIV/0! | G63: =VLOOKUP(B63:B114,I$62:M$113,5,0) -> #N/A | K63: =J63/J$114 -> #DIV/0! | L63: =K63+L62 -> #DIV/0! | M63: =_xlfn.IFS(L63<80%,"A",L63<=95%,"B",L63>95%,"C") -> #DIV/0!
D64: =C64/C$114 -> #DIV/0! | E64: =D64+E63 -> #DIV/0! | F64: =IF(AND(E64<=0),"C",IF(E64<=0.8,"A",IF(E64<=0.95,"B","C"))) -> #DIV/0! | G64: =VLOOKUP(B64:B115,I$62:M$113,5,0) -> #N/A | K64: =J64/J$114 -> #DIV/0! | L64: =K64+L63 -> #DIV/0! | M64: =_xlfn.IFS(L64<80%,"A",L64<=95%,"B",L64>95%,"C") -> #DIV/0!
D65: =C65/C$114 -> #DIV/0! | E65: =D65+E64 -> #DIV/0! | F65: =IF(AND(E65<=0),"C",IF(E65<=0.8,"A",IF(E65<=0.95,"B","C"))) -> #DIV/0! | G65: =VLOOKUP(B65:B116,I$62:M$113,5,0) -> #N/A | K65: =J65/J$114 -> #DIV/0! | L65: =K65+L64 -> #DIV/0! | M65: =_xlfn.IFS(L65<80%,"A",L65<=95%,"B",L65>95%,"C") -> #DIV/0!
D66: =C66/C$114 -> #DIV/0! | E66: =D66+E65 -> #DIV/0! | F66: =IF(AND(E66<=0),"C",IF(E66<=0.8,"A",IF(E66<=0.95,"B","C"))) -> #DIV/0! | G66: =VLOOKUP(B66:B117,I$62:M$113,5,0) -> #N/A | K66: =J66/J$114 -> #DIV/0! | L66: =K66+L65 -> #DIV/0! | M66: =_xlfn.IFS(L66<80%,"A",L66<=95%,"B",L66>95%,"C") -> #DIV/0!
D67: =C67/C$114 -> #DIV/0! | E67: =D67+E66 -> #DIV/0! | F67: =IF(AND(E67<=0),"C",IF(E67<=0.8,"A",IF(E67<=0.95,"B","C"))) -> #DIV/0! | G67: =VLOOKUP(B67:B118,I$62:M$113,5,0) -> #N/A | K67: =J67/J$114 -> #DIV/0! | L67: =K67+L66 -> #DIV/0! | M67: =_xlfn.IFS(L67<80%,"A",L67<=95%,"B",L67>95%,"C") -> #DIV/0!
...

Sheet АВС 14
B2: ОЧКИ
C3: Прибыль | D3: % прибыль | E3: Доля | F3: ABC прибыль | G3: ABC кол-во | J3: Кол-во | K3: % кол-во | L3: Доля | M3: ABC кол-во
B4: Qs черн Сул | C4: ='Юнит 14'!AL4 -> 165227.83 | D4: =C4/C$58 -> 0.50294646 | E4: =D4 -> 0.50294646 | F4: =IF(AND(E4<=0),"C",IF(E4<=0.8,"A",IF(E4<=0.95,"B","C"))) -> A | G4: =VLOOKUP(B$4:B$57,I$4:M$57,5,0) -> A | I4: Qs черн Сул | J4: ='Юнит 14'!S4 -> 390 | K4: =J4/J$58 -> 0.42025862 | L4: =K4 -> 0.42025862 | M4: =_xlfn.IFS(L4<80%,"A",L4<=95%,"B",L4>95%,"C") -> A | P4: A | Q4: 0.8
B5: Черные с железкой Сул | C5: ='Юнит 14'!AL3 -> 32127.895 | D5: =C5/C$58 -> 0.097795939 | E5: =E4+D5 -> 0.6007424 | F5: =IF(AND(E5<=0),"C",IF(E5<=0.8,"A",IF(E5<=0.95,"B","C"))) -> A | G5: =VLOOKUP(B$4:B$57,I$4:M$57,5,0) -> A | I5: Черные с железкой Сул | J5: ='Юнит 14'!S3 -> 128 | K5: =J5/J$58 -> 0.13793103 | L5: =L4+K5 -> 0.55818966 | M5: =_xlfn.IFS(L5<80%,"A",L5<=95%,"B",L5>95%,"C") -> A | P5: B | Q5: 0.15
B6: flip желтые Сул | C6: ='Юнит 14'!AL8 -> 25927.588 | D6: =C6/C$58 -> 0.078922471 | E6: =E5+D6 -> 0.67966487 | F6: =IF(AND(E6<=0),"C",IF(E6<=0.8,"A",IF(E6<=0.95,"B","C"))) -> A | G6: =VLOOKUP(B$4:B$57,I$4:M$57,5,0) -> A | I6: flip желтые Сул | J6: ='Юнит 14'!S8 -> 69 | K6: =J6/J$58 -> 0.074353448 | L6: =L5+K6 -> 0.6325431 | M6: =_xlfn.IFS(L6<80%,"A",L6<=95%,"B",L6>95%,"C") -> A | P6: C | Q6: 0.05
B7: Qs желт Сул | C7: ='Юнит 14'!AL6 -> 22975.286 | D7: =C7/C$58 -> 0.069935791 | E7: =E6+D7 -> 0.74960066 | F7: =IF(AND(E7<=0),"C",IF(E7<=0.8,"A",IF(E7<=0.95,"B","C"))) -> A | G7: =VLOOKUP(B$4:B$57,I$4:M$57,5,0) -> A | I7: Qs син Сул | J7: ='Юнит 14'!S5 -> 51 | K7: =J7/J$58 -> 0.054956897 | L7: =L6+K7 -> 0.6875 | M7: =_xlfn.IFS(L7<80%,"A",L7<=95%,"B",L7>95%,"C") -> A
B8: MR8854 C2 Сул | C8: ='Юнит 14'!AL9 -> 14844.446 | D8: =C8/C$58 -> 0.045185859 | E8: =E7+D8 -> 0.79478652 | F8: =IF(AND(E8<=0),"C",IF(E8<=0.8,"A",IF(E8<=0.95,"B","C"))) -> A | G8: =VLOOKUP(B$4:B$57,I$4:M$57,5,0) -> B | I8: Qs желт Сул | J8: ='Юнит 14'!S6 -> 47 | K8: =J8/J$58 -> 0.050646552 | L8: =L7+K8 -> 0.73814655 | M8: =_xlfn.IFS(L8<80%,"A",L8<=95%,"B",L8>95%,"C") -> A
B9: Qs син Сул | C9: ='Юнит 14'!AL5 -> 12932.698 | D9: =C9/C$58 -> 0.03936658 | E9: =E8+D9 -> 0.8341531 | F9: =IF(AND(E9<=0),"C",IF(E9<=0.8,"A",IF(E9<=0.95,"B","C"))) -> B | G9: =VLOOKUP(B$4:B$57,I$4:M$57,5,0) -> A | I9: flip черные Сул | J9: ='Юнит 14'!S7 -> 35 | K9: =J9/J$58 -> 0.037715517 | L9: =L8+K9 -> 0.77586207 | M9: =_xlfn.IFS(L9<80%,"A",L9<=95%,"B",L9>95%,"C") -> A
B10: flip черные Сул | C10: ='Юнит 14'!AL7 -> 10118.137 | D10: =C10/C$58 -> 0.030799178 | E10: =E9+D10 -> 0.86495228 | F10: =IF(AND(E10<=0),"C",IF(E10<=0.8,"A",IF(E10<=0.95,"B","C"))) -> B | G10: =VLOOKUP(B$4:B$57,I$4:M$57,5,0) -> A | I10: MR 1890 корич | J10: ='Юнит 14'!S18 -> 27 | K10: =J10/J$58 -> 0.029094828 | L10: =L9+K10 -> 0.8049569 | M10: =_xlfn.IFS(L10<80%,"A",L10<=95%,"B",L10>95%,"C") -> B
B11: qs006 | C11: ='Юнит 14'!AL23 -> 7757.7302 | D11: =C11/C$58 -> 0.0236142 | E11: =E10+D11 -> 0.88856648 | F11: =IF(AND(E11<=0),"C",IF(E11<=0.8,"A",IF(E11<=0.95,"B","C"))) -> B | G11: =VLOOKUP(B$4:B$57,I$4:M$57,5,0) -> B | I11: MR8854 C2 Сул | J11: ='Юнит 14'!S9 -> 26 | K11: =J11/J$58 -> 0.028017241 | L11: =L10+K11 -> 0.83297414 | M11: =_xlfn.IFS(L11<80%,"A",L11<=95%,"B",L11>95%,"C") -> B
B12: qs002 | C12: ='Юнит 14'!AL20 -> 6099.3729 | D12: =C12/C$58 -> 0.018566231 | E12: =E11+D12 -> 0.90713271 | F12: =IF(AND(E12<=0),"C",IF(E12<=0.8,"A",IF(E12<=0.95,"B","C"))) -> B | G12: =VLOOKUP(B$4:B$57,I$4:M$57,5,0) -> B | I12: MR 1890 черн | J12: ='Юнит 14'!S16 -> 20 | K12: =J12/J$58 -> 0.021551724 | L12: =L11+K12 -> 0.85452586 | M12: =_xlfn.IFS(L12<80%,"A",L12<=95%,"B",L12>95%,"C") -> B
B13: MR 1890 черн | C13: ='Юнит 14'!AL16 -> 5316.6237 | D13: =C13/C$58 -> 0.016183575 | E13: =E12+D13 -> 0.92331628 | F13: =IF(AND(E13<=0),"C",IF(E13<=0.8,"A",IF(E13<=0.95,"B","C"))) -> B | G13: =VLOOKUP(B$4:B$57,I$4:M$57,5,0) -> B | I13: qs006 | J13: ='Юнит 14'!S23 -> 17 | K13: =J13/J$58 -> 0.018318966 | L13: =L12+K13 -> 0.87284483 | M13: =_xlfn.IFS(L13<80%,"A",L13<=95%,"B",L13>95%,"C") -> B
B14: qs015 | C14: ='Юнит 14'!AL32 -> 4944.637 | D14: =C14/C$58 -> 0.015051264 | E14: =E13+D14 -> 0.93836755 | F14: =IF(AND(E14<=0),"C",IF(E14<=0.8,"A",IF(E14<=0.95,"B","C"))) -> B | G14: =VLOOKUP(B$4:B$57,I$4:M$57,5,0) -> B | I14: MR 1890 желт | J14: ='Юнит 14'!S17 -> 16 | K14: =J14/J$58 -> 0.017241379 | L14: =L13+K14 -> 0.89008621 | M14: =_xlfn.IFS(L14<80%,"A",L14<=95%,"B",L14>95%,"C") -> B
B15: qs007 | C15: ='Юнит 14'!AL24 -> 4035.1863 | D15: =C15/C$58 -> 0.012282935 | E15: =E14+D15 -> 0.95065048 | F15: =IF(AND(E15<=0),"C",IF(E15<=0.8,"A",IF(E15<=0.95,"B","C"))) -> C | G15: =VLOOKUP(B$4:B$57,I$4:M$57,5,0) -> B | I15: qs002 | J15: ='Юнит 14'!S20 -> 13 | K15: =J15/J$58 -> 0.014008621 | L15: =L14+K15 -> 0.90409483 | M15: =_xlfn.IFS(L15<80%,"A",L15<=95%,"B",L15>95%,"C") -> B
B16: MR 1819 корич | C16: ='Юнит 14'!AL11 -> 4015.8329 | D16: =C16/C$58 -> 0.012224024 | E16: =E15+D16 -> 0.96287451 | F16: =IF(AND(E16<=0),"C",IF(E16<=0.8,"A",IF(E16<=0.95,"B","C"))) -> C | G16: =VLOOKUP(B$4:B$57,I$4:M$57,5,0) -> B | I16: MR 1819 корич | J16: ='Юнит 14'!S11 -> 11 | K16: =J16/J$58 -> 0.011853448 | L16: =L15+K16 -> 0.91594828 | M16: =_xlfn.IFS(L16<80%,"A",L16<=95%,"B",L16>95%,"C") -> B
B17: MR 1890 корич | C17: ='Юнит 14'!AL18 -> 3904.2016 | D17: =C17/C$58 -> 0.011884223 | E17: =E16+D17 -> 0.97475873 | F17: =IF(AND(E17<=0),"C",IF(E17<=0.8,"A",IF(E17<=0.95,"B","C"))) -> C | G17: =VLOOKUP(B$4:B$57,I$4:M$57,5,0) -> B | I17: qs015 | J17: ='Юнит 14'!S32 -> 10 | K17: =J17/J$58 -> 0.010775862 | L17: =L16+K17 -> 0.92672414 | M17: =_xlfn.IFS(L17<80%,"A",L17<=95%,"B",L17>95%,"C") -> B
B18: qs014 | C18: ='Юнит 14'!AL31 -> 3447.7758 | D18: =C18/C$58 -> 0.010494882 | E18: =E17+D18 -> 0.98525361 | F18: =IF(AND(E18<=0),"C",IF(E18<=0.8,"A",IF(E18<=0.95,"B","C"))) -> C | G18: =VLOOKUP(B$4:B$57,I$4:M$57,5,0) -> B | I18: qs007 | J18: ='Юнит 14'!S24 -> 9 | K18: =J18/J$58 -> 0.0096982759 | L18: =L17+K18 -> 0.93642241 | M18: =_xlfn.IFS(L18<80%,"A",L18<=95%,"B",L18>95%,"C") -> B
B19: qs010ж | C19: ='Юнит 14'!AL34 -> 3158.554 | D19: =C19/C$58 -> 0.0096145034 | E19: =E18+D19 -> 0.99486812 | F19: =IF(AND(E19<=0),"C",IF(E19<=0.8,"A",IF(E19<=0.95,"B","C"))) -> C | G19: =VLOOKUP(B$4:B$57,I$4:M$57,5,0) -> C | I19: qs014 | J19: ='Юнит 14'!S31 -> 7 | K19: =J19/J$58 -> 0.0075431034 | L19: =L18+K19 -> 0.94396552 | M19: =_xlfn.IFS(L19<80%,"A",L19<=95%,"B",L19>95%,"C") -> B
B20: qs013 | C20: ='Юнит 14'!AL30 -> 2415.9 | D20: =C20/C$58 -> 0.0073538964 | E20: =E19+D20 -> 1.002222 | F20: =IF(AND(E20<=0),"C",IF(E20<=0.8,"A",IF(E20<=0.95,"B","C"))) -> C | G20: =VLOOKUP(B$4:B$57,I$4:M$57,5,0) -> C | I20: qs010ж | J20: ='Юнит 14'!S34 -> 6 | K20: =J20/J$58 -> 0.0064655172 | L20: =L19+K20 -> 0.95043103 | M20: =_xlfn.IFS(L20<80%,"A",L20<=95%,"B",L20>95%,"C") -> C
B21: qs001 | C21: ='Юнит 14'!AL19 -> 2250.1129 | D21: =C21/C$58 -> 0.0068492476 | E21: =E20+D21 -> 1.0090713 | F21: =IF(AND(E21<=0),"C",IF(E21<=0.8,"A",IF(E21<=0.95,"B","C"))) -> C | G21: =VLOOKUP(B$4:B$57,I$4:M$57,5,0) -> C | I21: qs003 | J21: ='Юнит 14'!S21 -> 5 | K21: =J21/J$58 -> 0.005387931 | L21: =L20+K21 -> 0.95581897 | M21: =_xlfn.IFS(L21<80%,"A",L21<=95%,"B",L21>95%,"C") -> C
B22: qs003 | C22: ='Юнит 14'!AL21 -> 2026.676 | D22: =C22/C$58 -> 0.0061691152 | E22: =E21+D22 -> 1.0152404 | F22: =IF(AND(E22<=0),"C",IF(E22<=0.8,"A",IF(E22<=0.95,"B","C"))) -> C | G22: =VLOOKUP(B$4:B$57,I$4:M$57,5,0) -> C | I22: qs008 | J22: ='Юнит 14'!S25 -> 5 | K22: =J22/J$58 -> 0.005387931 | L22: =L21+K22 -> 0.9612069 | M22: =_xlfn.IFS(L22<80%,"A",L22<=95%,"B",L22>95%,"C") -> C
B23: qs009 | C23: ='Юнит 14'!AL26 -> 1212.7861 | D23: =C23/C$58 -> 0.0036916691 | E23: =E22+D23 -> 1.018932 | F23: =IF(AND(E23<=0),"C",IF(E23<=0.8,"A",IF(E23<=0.95,"B","C"))) -> C | G23: =VLOOKUP(B$4:B$57,I$4:M$57,5,0) -> C | I23: qs013 | J23: ='Юнит 14'!S30 -> 5 | K23: =J23/J$58 -> 0.005387931 | L23: =L22+K23 -> 0.96659483 | M23: =_xlfn.IFS(L23<80%,"A",L23<=95%,"B",L23>95%,"C") -> C
B24: MR Р1886 корич | C24: ='Юнит 14'!AL15 -> 1151.8749 | D24: =C24/C$58 -> 0.003506258 | E24: =E23+D24 -> 1.0224383 | F24: =IF(AND(E24<=0),"C",IF(E24<=0.8,"A",IF(E24<=0.95,"B","C"))) -> C | G24: =VLOOKUP(B$4:B$57,I$4:M$57,5,0) -> C | I24: qs001 | J24: ='Юнит 14'!S19 -> 4 | K24: =J24/J$58 -> 0.0043103448 | L24: =L23+K24 -> 0.97090517 | M24: =_xlfn.IFS(L24<80%,"A",L24<=95%,"B",L24>95%,"C") -> C
B25: MR Р1886 черн | C25: ='Юнит 14'!AL14 -> 1070.9863 | D25: =C25/C$58 -> 0.0032600364 | E25: =E24+D25 -> 1.0256983 | F25: =IF(AND(E25<=0),"C",IF(E25<=0.8,"A",IF(E25<=0.95,"B","C"))) -> C | G25: =VLOOKUP(B$4:B$57,I$4:M$57,5,0) -> C | I25: MR 1819 черн | J25: ='Юнит 14'!S10 -> 3 | K25: =J25/J$58 -> 0.0032327586 | L25: =L24+K25 -> 0.97413793 | M25: =_xlfn.IFS(L25<80%,"A",L25<=95%,"B",L25>95%,"C") -> C
B26: qs010 | C26: ='Юнит 14'!AL27 -> 883.9954 | D26: =C26/C$58 -> 0.0026908443 | E26: =E25+D26 -> 1.0283892 | F26: =IF(AND(E26<=0),"C",IF(E26<=0.8,"A",IF(E26<=0.95,"B","C"))) -> C | G26: =VLOOKUP(B$4:B$57,I$4:M$57,5,0) -> C | I26: MR Р1886 черн | J26: ='Юнит 14'!S14 -> 3 | K26: =J26/J$58 -> 0.0032327586 | L26: =L25+K26 -> 0.97737069 | M26: =_xlfn.IFS(L26<80%,"A",L26<=95%,"B",L26>95%,"C") -> C
B27: MR 1819 черн | C27: ='Юнит 14'!AL10 -> 859.70936 | D27: =C27/C$58 -> 0.0026169186 | E27: =E26+D27 -> 1.0310061 | F27: =IF(AND(E27<=0),"C",IF(E27<=0.8,"A",IF(E27<=0.95,"B","C"))) -> C | G27: =VLOOKUP(B$4:B$57,I$4:M$57,5,0) -> C | I27: MR Р1886 корич | J27: ='Юнит 14'!S15 -> 3 | K27: =J27/J$58 -> 0.0032327586 | L27: =L26+K27 -> 0.98060345 | M27: =_xlfn.IFS(L27<80%,"A",L27<=95%,"B",L27>95%,"C") -> C
B28: MR 1890 желт | C28: ='Юнит 14'!AL17 -> 566.26853 | D28: =C28/C$58 -> 0.0017236972 | E28: =E24+D28 -> 1.024162 | F28: =IF(AND(E28<=0),"C",IF(E28<=0.8,"A",IF(E28<=0.95,"B","C"))) -> C | G28: =VLOOKUP(B$4:B$57,I$4:M$57,5,0) -> B | I28: qs009 | J28: ='Юнит 14'!S26 -> 3 | K28: =J28/J$58 -> 0.0032327586 | L28: =L24+K28 -> 0.97413793 | M28: =_xlfn.IFS(L28<80%,"A",L28<=95%,"B",L28>95%,"C") -> C
B29: qs008 | C29: ='Юнит 14'!AL25 -> 408.34901 | D29: =C29/C$58 -> 0.0012429969 | E29: =E28+D29 -> 1.025405 | F29: =IF(AND(E29<=0),"C",IF(E29<=0.8,"A",IF(E29<=0.95,"B","C"))) -> C | G29: =VLOOKUP(B$4:B$57,I$4:M$57,5,0) -> C | I29: qs010 | J29: ='Юнит 14'!S27 -> 2 | K29: =J29/J$58 -> 0.0021551724 | L29: =L28+K29 -> 0.9762931 | M29: =_xlfn.IFS(L29<80%,"A",L29<=95%,"B",L29>95%,"C") -> C
B30: 180ч/б | C30: ='Юнит 14'!AL46 -> 388.29804 | D30: =C30/C$58 -> 0.0011819627 | E30: =E29+D30 -> 1.026587 | F30: =IF(AND(E30<=0),"C",IF(E30<=0.8,"A",IF(E30<=0.95,"B","C"))) -> C | G30: =VLOOKUP(B$4:B$57,I$4:M$57,5,0) -> C | I30: 2100красный | J30: ='Юнит 14'!S40 -> 2 | K30: =J30/J$58 -> 0.0021551724 | L30: =L29+K30 -> 0.97844828 | M30: =_xlfn.IFS(L30<80%,"A",L30<=95%,"B",L30>95%,"C") -> C
B31: qs012ж | C31: ='Юнит 14'!AL36 -> 327.14388 | D31: =C31/C$58 -> 0.00099581201 | E31: =E30+D31 -> 1.0275828 | F31: =IF(AND(E31<=0),"C",IF(E31<=0.8,"A",IF(E31<=0.95,"B","C"))) -> C | G31: =VLOOKUP(B$4:B$57,I$4:M$57,5,0) -> C | I31: 180ч/б | J31: ='Юнит 14'!S46 -> 2 | K31: =J31/J$58 -> 0.0021551724 | L31: =L30+K31 -> 0.98060345 | M31: =_xlfn.IFS(L31<80%,"A",L31<=95%,"B",L31>95%,"C") -> C
B32: qs011ж | C32: ='Юнит 14'!AL35 -> 325.06096 | D32: =C32/C$58 -> 0.00098947169 | E32: =E31+D32 -> 1.0285722 | F32: =IF(AND(E32<=0),"C",IF(E32<=0.8,"A",IF(E32<=0.95,"B","C"))) -> C | G32: =VLOOKUP(B$4:B$57,I$4:M$57,5,0) -> C | I32: MR Р1874 черн | J32: ='Юнит 14'!S12 -> 1 | K32: =J32/J$58 -> 0.0010775862 | L32: =L31+K32 -> 0.98168103 | M32: =_xlfn.IFS(L32<80%,"A",L32<=95%,"B",L32>95%,"C") -> C
B33: MR Р1874 черн | C33: ='Юнит 14'!AL12 -> 296.7 | D33: =C33/C$58 -> 0.00090314213 | E33: =E32+D33 -> 1.0294754 | F33: =IF(AND(E33<=0),"C",IF(E33<=0.8,"A",IF(E33<=0.95,"B","C"))) -> C | G33: =VLOOKUP(B$4:B$57,I$4:M$57,5,0) -> C | I33: qs011ж | J33: ='Юнит 14'!S35 -> 1 | K33: =J33/J$58 -> 0.0010775862 | L33: =L32+K33 -> 0.98275862 | M33: =_xlfn.IFS(L33<80%,"A",L33<=95%,"B",L33>95%,"C") -> C
B34: MR Р1874 корич | C34: ='Юнит 14'!AL13 -> 0 | D34: =C34/C$58 -> 0 | E34: =E33+D34 -> 1.0294754 | F34: =IF(AND(E34<=0),"C",IF(E34<=0.8,"A",IF(E34<=0.95,"B","C"))) -> C | G34: =VLOOKUP(B$4:B$57,I$4:M$57,5,0) -> C | I34: qs012ж | J34: ='Юнит 14'!S36 -> 1 | K34: =J34/J$58 -> 0.0010775862 | L34: =L33+K34 -> 0.98383621 | M34: =_xlfn.IFS(L34<80%,"A",L34<=95%,"B",L34>95%,"C") -> C
B35: qs001 Ж | C35: ='Юнит 14'!AL33 -> 0 | D35: =C35/C$58 -> 0 | E35: =E34+D35 -> 1.0294754 | F35: =IF(AND(E35<=0),"C",IF(E35<=0.8,"A",IF(E35<=0.95,"B","C"))) -> C | G35: =VLOOKUP(B$4:B$57,I$4:M$57,5,0) -> C | I35: 2038красный | J35: ='Юнит 14'!S38 -> 1 | K35: =J35/J$58 -> 0.0010775862 | L35: =L34+K35 -> 0.98491379 | M35: =_xlfn.IFS(L35<80%,"A",L35<=95%,"B",L35>95%,"C") -> C
B36: qs012 | C36: ='Юнит 14'!AL29 -> -0.96707993 | D36: =C36/C$58 -> -2.94375e-06 | E36: =E35+D36 -> 1.0294724 | F36: =IF(AND(E36<=0),"C",IF(E36<=0.8,"A",IF(E36<=0.95,"B","C"))) -> C | G36: =VLOOKUP(B$4:B$57,I$4:M$57,5,0) -> C | I36: 2100черный | J36: ='Юнит 14'!S39 -> 1 | K36: =J36/J$58 -> 0.0010775862 | L36: =L35+K36 -> 0.98599138 | M36: =_xlfn.IFS(L36<80%,"A",L36<=95%,"B",L36>95%,"C") -> C
B37: 2084 | C37: ='Юнит 14'!AL54 -> -13.539119 | D37: =C37/C$58 -> -4.12125e-05 | E37: =E36+D37 -> 1.0294312 | F37: =IF(AND(E37<=0),"C",IF(E37<=0.8,"A",IF(E37<=0.95,"B","C"))) -> C | G37: =VLOOKUP(B$4:B$57,I$4:M$57,5,0) -> C | I37: 123метал | J37: ='Юнит 14'!S45 -> 1 | K37: =J37/J$58 -> 0.0010775862 | L37: =L36+K37 -> 0.98706897 | M37: =_xlfn.IFS(L37<80%,"A",L37<=95%,"B",L37>95%,"C") -> C
B38: 2100красный | C38: ='Юнит 14'!AL40 -> -17.153719 | D38: =C38/C$58 -> -5.2215189e-05 | E38: =E37+D38 -> 1.029379 | F38: =IF(AND(E38<=0),"C",IF(E38<=0.8,"A",IF(E38<=0.95,"B","C"))) -> C | G38: =VLOOKUP(B$4:B$57,I$4:M$57,5,0) -> C | I38: 2064коричневые | J38: ='Юнит 14'!S51 -> 1 | K38: =J38/J$58 -> 0.0010775862 | L38: =L37+K38 -> 0.98814655 | M38: =_xlfn.IFS(L38<80%,"A",L38<=95%,"B",L38>95%,"C") -> C
B39: 2064ч/б | C39: ='Юнит 14'!AL50 -> -17.407439 | D39: =C39/C$58 -> -5.29875e-05 | E39: =E38+D39 -> 1.029326 | F39: =IF(AND(E39<=0),"C",IF(E39<=0.8,"A",IF(E39<=0.95,"B","C"))) -> C | G39: =VLOOKUP(B$4:B$57,I$4:M$57,5,0) -> C | I39: 2064фиолетовые | J39: ='Юнит 14'!S52 -> 1 | K39: =J39/J$58 -> 0.0010775862 | L39: =L38+K39 -> 0.98922414 | M39: =_xlfn.IFS(L39<80%,"A",L39<=95%,"B",L39>95%,"C") -> C
B40: 123черный | C40: ='Юнит 14'!AL44 -> -36.749037 | D40: =C40/C$58 -> -0.0001118625 | E40: =E39+D40 -> 1.0292142 | F40: =IF(AND(E40<=0),"C",IF(E40<=0.8,"A",IF(E40<=0.95,"B","C"))) -> C | G40: =VLOOKUP(B$4:B$57,I$4:M$57,5,0) -> C | I40: 2084 (+1.75) | J40: ='Юнит 14'!S55 -> 1 | K40: =J40/J$58 -> 0.0010775862 | L40: =L39+K40 -> 0.99030172 | M40: =_xlfn.IFS(L40<80%,"A",L40<=95%,"B",L40>95%,"C") -> C
B41: 580черный | C41: ='Юнит 14'!AL48 -> -36.749037 | D41: =C41/C$58 -> -0.0001118625 | E41: =E40+D41 -> 1.0291023 | F41: =IF(AND(E41<=0),"C",IF(E41<=0.8,"A",IF(E41<=0.95,"B","C"))) -> C | G41: =VLOOKUP(B$4:B$57,I$4:M$57,5,0) -> C | I41: MR Р1874 корич | J41: ='Юнит 14'!S13 -> 0 | K41: =J41/J$58 -> 0 | L41: =L40+K41 -> 0.99030172 | M41: =_xlfn.IFS(L41<80%,"A",L41<=95%,"B",L41>95%,"C") -> C
...

Sheet АВС МАРТ
B2: ОЧКИ
C3: Прибыль | D3: % прибыль | E3: Доля | F3: ABC прибыль | G3: ABC кол-во | J3: Кол-во | K3: % кол-во | L3: Доля | M3: ABC кол-во
B4: Qs черн Сул | C4: =МАРТ!AL4 -> 445216.21 | D4: =C4/C$58 -> 0.39769091 | E4: =D4 -> 0.39769091 | F4: =IF(AND(E4<=0),"C",IF(E4<=0.8,"A",IF(E4<=0.95,"B","C"))) -> A | G4: =VLOOKUP(B$4:B$57,I$4:M$57,5,0) -> A | I4: Qs черн Сул | J4: =МАРТ!S4 -> 1110 | K4: =J4/J$58 -> 0.35875889 | L4: =K4 -> 0.35875889 | M4: =_xlfn.IFS(L4<80%,"A",L4<=95%,"B",L4>95%,"C") -> A | P4: A | Q4: 0.8
B5: Черные с железкой Сул | C5: =МАРТ!AL3 -> 138481.85 | D5: =C5/C$58 -> 0.12369939 | E5: =E4+D5 -> 0.5213903 | F5: =IF(AND(E5<=0),"C",IF(E5<=0.8,"A",IF(E5<=0.95,"B","C"))) -> A | G5: =VLOOKUP(B$4:B$57,I$4:M$57,5,0) -> A | I5: Черные с железкой Сул | J5: =МАРТ!S3 -> 405 | K5: =J5/J$58 -> 0.13089851 | L5: =L4+K5 -> 0.4896574 | M5: =_xlfn.IFS(L5<80%,"A",L5<=95%,"B",L5>95%,"C") -> A | P5: B | Q5: 0.15
B6: flip желтые Сул | C6: =МАРТ!AL8 -> 84230.707 | D6: =C6/C$58 -> 0.075239367 | E6: =E5+D6 -> 0.59662967 | F6: =IF(AND(E6<=0),"C",IF(E6<=0.8,"A",IF(E6<=0.95,"B","C"))) -> A | G6: =VLOOKUP(B$4:B$57,I$4:M$57,5,0) -> A | I6: flip желтые Сул | J6: =МАРТ!S8 -> 221 | K6: =J6/J$58 -> 0.071428571 | L6: =L5+K6 -> 0.56108597 | M6: =_xlfn.IFS(L6<80%,"A",L6<=95%,"B",L6>95%,"C") -> A | P6: C | Q6: 0.05
B7: Qs желт Сул | C7: =МАРТ!AL6 -> 78445.62 | D7: =C7/C$58 -> 0.070071818 | E7: =E6+D7 -> 0.66670148 | F7: =IF(AND(E7<=0),"C",IF(E7<=0.8,"A",IF(E7<=0.95,"B","C"))) -> A | G7: =VLOOKUP(B$4:B$57,I$4:M$57,5,0) -> A | I7: Qs желт Сул | J7: =МАРТ!S6 -> 181 | K7: =J7/J$58 -> 0.058500323 | L7: =L6+K7 -> 0.6195863 | M7: =_xlfn.IFS(L7<80%,"A",L7<=95%,"B",L7>95%,"C") -> A
B8: qs002 | C8: =МАРТ!AL20 -> 63715.264 | D8: =C8/C$58 -> 0.056913878 | E8: =E7+D8 -> 0.72361536 | F8: =IF(AND(E8<=0),"C",IF(E8<=0.8,"A",IF(E8<=0.95,"B","C"))) -> A | G8: =VLOOKUP(B$4:B$57,I$4:M$57,5,0) -> A | I8: Qs син Сул | J8: =МАРТ!S5 -> 173 | K8: =J8/J$58 -> 0.055914674 | L8: =L7+K8 -> 0.67550097 | M8: =_xlfn.IFS(L8<80%,"A",L8<=95%,"B",L8>95%,"C") -> A
B9: MR8854 C2 Сул | C9: =МАРТ!AL9 -> 60864.708 | D9: =C9/C$58 -> 0.054367609 | E9: =E8+D9 -> 0.77798297 | F9: =IF(AND(E9<=0),"C",IF(E9<=0.8,"A",IF(E9<=0.95,"B","C"))) -> A | G9: =VLOOKUP(B$4:B$57,I$4:M$57,5,0) -> A | I9: qs002 | J9: =МАРТ!S20 -> 132 | K9: =J9/J$58 -> 0.042663219 | L9: =L8+K9 -> 0.71816419 | M9: =_xlfn.IFS(L9<80%,"A",L9<=95%,"B",L9>95%,"C") -> A
B10: Qs син Сул | C10: =МАРТ!AL5 -> 46874.767 | D10: =C10/C$58 -> 0.041871047 | E10: =E9+D10 -> 0.81985402 | F10: =IF(AND(E10<=0),"C",IF(E10<=0.8,"A",IF(E10<=0.95,"B","C"))) -> B | G10: =VLOOKUP(B$4:B$57,I$4:M$57,5,0) -> A | I10: MR8854 C2 Сул | J10: =МАРТ!S9 -> 117 | K10: =J10/J$58 -> 0.037815126 | L10: =L9+K10 -> 0.75597931 | M10: =_xlfn.IFS(L10<80%,"A",L10<=95%,"B",L10>95%,"C") -> A
B11: qs001 | C11: =МАРТ!AL19 -> 36930.111 | D11: =C11/C$58 -> 0.032987948 | E11: =E10+D11 -> 0.85284197 | F11: =IF(AND(E11<=0),"C",IF(E11<=0.8,"A",IF(E11<=0.95,"B","C"))) -> B | G11: =VLOOKUP(B$4:B$57,I$4:M$57,5,0) -> B | I11: flip черные Сул | J11: =МАРТ!S7 -> 72 | K11: =J11/J$58 -> 0.023270847 | L11: =L10+K11 -> 0.77925016 | M11: =_xlfn.IFS(L11<80%,"A",L11<=95%,"B",L11>95%,"C") -> A
B12: qs014 | C12: =МАРТ!AL31 -> 25925.693 | D12: =C12/C$58 -> 0.023158214 | E12: =E11+D12 -> 0.87600018 | F12: =IF(AND(E12<=0),"C",IF(E12<=0.8,"A",IF(E12<=0.95,"B","C"))) -> B | G12: =VLOOKUP(B$4:B$57,I$4:M$57,5,0) -> B | I12: qs001 | J12: =МАРТ!S19 -> 72 | K12: =J12/J$58 -> 0.023270847 | L12: =L11+K12 -> 0.80252101 | M12: =_xlfn.IFS(L12<80%,"A",L12<=95%,"B",L12>95%,"C") -> B
B13: qs006 | C13: =МАРТ!AL23 -> 21810.077 | D13: =C13/C$58 -> 0.019481926 | E13: =E12+D13 -> 0.89548211 | F13: =IF(AND(E13<=0),"C",IF(E13<=0.8,"A",IF(E13<=0.95,"B","C"))) -> B | G13: =VLOOKUP(B$4:B$57,I$4:M$57,5,0) -> B | I13: MR 1890 черн | J13: =МАРТ!S16 -> 69 | K13: =J13/J$58 -> 0.022301228 | L13: =L12+K13 -> 0.82482224 | M13: =_xlfn.IFS(L13<80%,"A",L13<=95%,"B",L13>95%,"C") -> B
B14: qs013 | C14: =МАРТ!AL30 -> 13212.341 | D14: =C14/C$58 -> 0.011801969 | E14: =E13+D14 -> 0.90728407 | F14: =IF(AND(E14<=0),"C",IF(E14<=0.8,"A",IF(E14<=0.95,"B","C"))) -> B | G14: =VLOOKUP(B$4:B$57,I$4:M$57,5,0) -> B | I14: qs014 | J14: =МАРТ!S31 -> 56 | K14: =J14/J$58 -> 0.018099548 | L14: =L13+K14 -> 0.84292178 | M14: =_xlfn.IFS(L14<80%,"A",L14<=95%,"B",L14>95%,"C") -> B
B15: flip черные Сул | C15: =МАРТ!AL7 -> 12804.989 | D15: =C15/C$58 -> 0.0114381 | E15: =E14+D15 -> 0.91872217 | F15: =IF(AND(E15<=0),"C",IF(E15<=0.8,"A",IF(E15<=0.95,"B","C"))) -> B | G15: =VLOOKUP(B$4:B$57,I$4:M$57,5,0) -> A | I15: qs006 | J15: =МАРТ!S23 -> 46 | K15: =J15/J$58 -> 0.014867485 | L15: =L14+K15 -> 0.85778927 | M15: =_xlfn.IFS(L15<80%,"A",L15<=95%,"B",L15>95%,"C") -> B
B16: MR 1890 корич | C16: =МАРТ!AL18 -> 12463.808 | D16: =C16/C$58 -> 0.011133339 | E16: =E15+D16 -> 0.92985551 | F16: =IF(AND(E16<=0),"C",IF(E16<=0.8,"A",IF(E16<=0.95,"B","C"))) -> B | G16: =VLOOKUP(B$4:B$57,I$4:M$57,5,0) -> B | I16: MR 1890 желт | J16: =МАРТ!S17 -> 44 | K16: =J16/J$58 -> 0.014221073 | L16: =L15+K16 -> 0.87201034 | M16: =_xlfn.IFS(L16<80%,"A",L16<=95%,"B",L16>95%,"C") -> B
B17: qs010ж | C17: =МАРТ!AL34 -> 11978.076 | D17: =C17/C$58 -> 0.010699458 | E17: =E16+D17 -> 0.94055497 | F17: =IF(AND(E17<=0),"C",IF(E17<=0.8,"A",IF(E17<=0.95,"B","C"))) -> B | G17: =VLOOKUP(B$4:B$57,I$4:M$57,5,0) -> B | I17: qs007 | J17: =МАРТ!S24 -> 40 | K17: =J17/J$58 -> 0.012928248 | L17: =L16+K17 -> 0.88493859 | M17: =_xlfn.IFS(L17<80%,"A",L17<=95%,"B",L17>95%,"C") -> B
B18: MR 1890 черн | C18: =МАРТ!AL16 -> 10426.101 | D18: =C18/C$58 -> 0.0093131503 | E18: =E17+D18 -> 0.94986812 | F18: =IF(AND(E18<=0),"C",IF(E18<=0.8,"A",IF(E18<=0.95,"B","C"))) -> B | G18: =VLOOKUP(B$4:B$57,I$4:M$57,5,0) -> B | I18: qs013 | J18: =МАРТ!S30 -> 38 | K18: =J18/J$58 -> 0.012281836 | L18: =L17+K18 -> 0.89722043 | M18: =_xlfn.IFS(L18<80%,"A",L18<=95%,"B",L18>95%,"C") -> B
B19: MR Р1874 черн | C19: =МАРТ!AL12 -> 10060.001 | D19: =C19/C$58 -> 0.0089861299 | E19: =E18+D19 -> 0.95885425 | F19: =IF(AND(E19<=0),"C",IF(E19<=0.8,"A",IF(E19<=0.95,"B","C"))) -> C | G19: =VLOOKUP(B$4:B$57,I$4:M$57,5,0) -> B | I19: qs010ж | J19: =МАРТ!S34 -> 38 | K19: =J19/J$58 -> 0.012281836 | L19: =L18+K19 -> 0.90950226 | M19: =_xlfn.IFS(L19<80%,"A",L19<=95%,"B",L19>95%,"C") -> B
B20: qs003 | C20: =МАРТ!AL21 -> 8453.5027 | D20: =C20/C$58 -> 0.0075511203 | E20: =E19+D20 -> 0.96640537 | F20: =IF(AND(E20<=0),"C",IF(E20<=0.8,"A",IF(E20<=0.95,"B","C"))) -> C | G20: =VLOOKUP(B$4:B$57,I$4:M$57,5,0) -> C | I20: MR 1890 корич | J20: =МАРТ!S18 -> 36 | K20: =J20/J$58 -> 0.011635423 | L20: =L19+K20 -> 0.92113769 | M20: =_xlfn.IFS(L20<80%,"A",L20<=95%,"B",L20>95%,"C") -> B
