Workbook

Sheet Сводная
A1: Период | D1: Дата поступления дс | E1: Итого к перечислению на счет, руб | F1: шт. | I1: Выручка | L1: Себестоимость продаж | M1: Логистика | N1: Комиссия | O1: Хранение | P1: Платная приемка | Q1: Штрафы | R1: Реклама Ozon | S1: Прочее | T1: Доп. услуги | U1: Услуги FBO | V1: Компенсировано | W1: Пополнение рекламного кабинета | X1: Прочие начисления | Y1: Налог | Z1: Итого | AA1: Итог месяц | AB1: % Cебестоимости | AC1: Маржинальность, % | AD1: Рентабельность, % | AE1: Доля рекламы, % | AG1: Данные для построения диаграмм
A2: Месяц | B2: Даты | C2: Нед | F2: Заказы | G2: Продажи | H2: Возвраты | I2: Продажи | J2: Возвраты | K2: Общая | AG2: Нед | AH2: По магазину | AI2: По очкам | AJ2: По туникам
A3: Январь | B3: 01-04.01 очки | E3: =K3-SUM(M3:U3)+V3+W3+X3 -> 6689.7486 | F3: ='Юнит 01-04.01'!K$26 -> 44 | G3: ='Юнит 01-04.01'!P$26 -> 28 | H3: ='Юнит 01-04.01'!Q$26 -> 0 | I3: ='Юнит 01-04.01'!S$26 -> 45978 | J3: ='Юнит 01-04.01'!T$26 -> 0 | K3: =I3+J3 -> 45978 | L3: ='Юнит 01-04.01'!W$26 -> 4528.66 | M3: ='Юнит 01-04.01'!Z$26 -> 3709.34 | N3: ='Юнит 01-04.01'!X$26 -> 19770.54 | R3: ='Юнит 01-04.01'!AA$26 -> 14387.481 | T3: 808.39 | U3: 612.5 | Y3: =(K3)*0.01 -> 459.78 | Z3: =K3-SUM(M3:U3)-L3-Y3+V3+X3 -> 1701.3086 | AA3: =SUM(Z3:Z12) -> 33354.59 | AB3: =L3/K3 -> 0.098496237 | AC3: =Z3/L3 -> 0.37567594 | AD3: =Z3/K3 -> 0.037002667 | AE3: =R3/K3 -> 0.31292099
B4: 01-04.01 туники | E4: =K4-SUM(M4:U4)+V4+W4+X4 -> 1720.7514 | F4: ='Юнит 01-04.01'!K$49 -> 5 | G4: ='Юнит 01-04.01'!P$49 -> 1 | H4: ='Юнит 01-04.01'!Q$49 -> 0 | I4: ='Юнит 01-04.01'!S$49 -> 4247 | J4: ='Юнит 01-04.01'!T$49 -> 0 | K4: =I4+J4 -> 4247 | L4: ='Юнит 01-04.01'!W$49 -> 597 | M4: ='Юнит 01-04.01'!Z$49 -> 186.2 | N4: ='Юнит 01-04.01'!X$49 -> 1826.21 | R4: ='Юнит 01-04.01'!AA$49 -> 513.83862 | Y4: =(K4)*0.01 -> 42.47 | Z4: =K4-SUM(M4:U4)-L4-Y4+V4+X4 -> 1081.2814 | AB4: =L4/K4 -> 0.14056981 | AC4: =Z4/L4 -> 1.8111916 | AD4: =Z4/K4 -> 0.25459886 | AE4: =R4/K4 -> 0.12098861
B5: 05-11.01 очки | E5: =K5-SUM(M5:U5)+V5+W5+X5 -> 15120.024 | F5: ='Юнит 05-11.01'!K$26 -> 74 | G5: ='Юнит 05-11.01'!P$26 -> 58 | H5: ='Юнит 05-11.01'!Q$26 -> 4 | I5: ='Юнит 05-11.01'!S$26 -> 92160 | J5: ='Юнит 05-11.01'!T$26 -> -6799 | K5: =I5+J5 -> 85361 | L5: ='Юнит 05-11.01'!W$26 -> 7651.8 | M5: ='Юнит 05-11.01'!Z$26 -> 9950.27 | N5: ='Юнит 05-11.01'!X$26 -> 36705.23 | R5: ='Юнит 05-11.01'!AA$26 -> 20346.216 | S5: 5 | T5: 1918.46 | U5: 1315.8 | Y5: =(K5)*0.01 -> 853.61 | Z5: =K5-SUM(M5:U5)-L5-Y5+V5+X5 -> 6614.6137 | AB5: =L5/K5 -> 0.089640468 | AC5: =Z5/L5 -> 0.86445198 | AD5: =Z5/K5 -> 0.07748988 | AE5: =R5/K5 -> 0.23835494
B6: 05-11.01 туники | E6: =K6-SUM(M6:U6)+V6+W6+X6 -> 4389.7863 | F6: ='Юнит 05-11.01'!K$49 -> 4 | G6: ='Юнит 05-11.01'!P$49 -> 2 | H6: ='Юнит 05-11.01'!Q$49 -> 0 | I6: ='Юнит 05-11.01'!S$49 -> 10524 | J6: ='Юнит 05-11.01'!T$49 -> 0 | K6: =I6+J6 -> 10524 | L6: ='Юнит 05-11.01'!W$49 -> 1329 | M6: ='Юнит 05-11.01'!Z$49 -> 907.3 | N6: ='Юнит 05-11.01'!X$49 -> 4525.32 | R6: ='Юнит 05-11.01'!AA$49 -> 701.59367 | Y6: =(K6)*0.01 -> 105.24 | Z6: =K6-SUM(M6:U6)-L6-Y6+V6+X6 -> 2955.5463 | AB6: =L6/K6 -> 0.12628278 | AC6: =Z6/L6 -> 2.2238874 | AD6: =Z6/K6 -> 0.28083869 | AE6: =R6/K6 -> 0.066666065
B7: 12-18.01 очки | E7: =K7-SUM(M7:U7)+V7+W7+X7 -> 23997.298 | F7: ='Юнит 12-18.01'!K$26 -> 96 | G7: ='Юнит 12-18.01'!P$26 -> 56 | H7: ='Юнит 12-18.01'!Q$26 -> 0 | I7: ='Юнит 12-18.01'!S$26 -> 91762 | J7: ='Юнит 12-18.01'!T$26 -> 0 | K7: =I7+J7 -> 91762 | L7: ='Юнит 12-18.01'!W$26 -> 7841.91 | M7: ='Юнит 12-18.01'!Z$26 -> 9811.64 | N7: ='Юнит 12-18.01'!X$26 -> 39457.66 | R7: ='Юнит 12-18.01'!AA$26 -> 22526.532 | T7: 2168.87 | U7: 800 | W7: 7000 | Y7: =(K7)*0.01 -> 917.62 | Z7: =K7-SUM(M7:U7)-L7-Y7+V7+X7 -> 8237.7675 | AB7: =L7/K7 -> 0.085459231 | AC7: =Z7/L7 -> 1.0504797 | AD7: =Z7/K7 -> 0.089773191 | AE7: =R7/K7 -> 0.24548868
B8: 12-18.01 туники | E8: =K8-SUM(M8:U8)+V8+W8+X8 -> 8441.1125 | F8: ='Юнит 12-18.01'!K$49 -> 30 | G8: ='Юнит 12-18.01'!P$49 -> 5 | H8: ='Юнит 12-18.01'!Q$49 -> 0 | I8: ='Юнит 12-18.01'!S$49 -> 21020 | J8: ='Юнит 12-18.01'!T$49 -> 0 | K8: =I8+J8 -> 21020 | L8: ='Юнит 12-18.01'!W$49 -> 3435 | M8: ='Юнит 12-18.01'!Z$49 -> 1528.99 | N8: ='Юнит 12-18.01'!X$49 -> 9038.6 | R8: ='Юнит 12-18.01'!AA$49 -> 2011.2975 | Y8: =(K8)*0.01 -> 210.2 | Z8: =K8-SUM(M8:U8)-L8-Y8+V8+X8 -> 4795.9125 | AB8: =L8/K8 -> 0.16341579 | AC8: =Z8/L8 -> 1.3961899 | AD8: =Z8/K8 -> 0.22815949 | AE8: =R8/K8 -> 0.095684945
B9: 19-25.01 очки | E9: =K9-SUM(M9:U9)+V9+W9+X9 -> 15283.413 | F9: ='Юнит 19-25.01'!K$26 -> 119 | G9: ='Юнит 19-25.01'!P$26 -> 64 | H9: ='Юнит 19-25.01'!Q$26 -> 1 | I9: ='Юнит 19-25.01'!S$26 -> 104586 | J9: ='Юнит 19-25.01'!T$26 -> -1670 | K9: =I9+J9 -> 102916 | L9: ='Юнит 19-25.01'!W$26 -> 9494.98 | M9: ='Юнит 19-25.01'!Z$26 -> 12870.13 | N9: ='Юнит 19-25.01'!X$26 -> 44253.88 | R9: ='Юнит 19-25.01'!AA$26 -> 31721.257 | S9: 15 | T9: 3536.42 | U9: 2235.9 | W9: 7000 | Y9: =(K9)*0.01 -> 1029.16 | Z9: =K9-SUM(M9:U9)-L9-Y9+V9+X9 -> -2240.7266 | AB9: =L9/K9 -> 0.092259513 | AC9: =Z9/L9 -> -0.23599066 | AD9: =Z9/K9 -> -0.021772383 | AE9: =R9/K9 -> 0.30822473
B10: 19-25.01 туники | E10: =K10-SUM(M10:U10)+V10+W10+X10 -> 20301.697 | F10: ='Юнит 19-25.01'!K$49 -> 66 | G10: ='Юнит 19-25.01'!P$49 -> 18 | H10: ='Юнит 19-25.01'!Q$49 -> 4 | I10: ='Юнит 19-25.01'!S$49 -> 80413 | J10: ='Юнит 19-25.01'!T$49 -> -17932 | K10: =I10+J10 -> 62481 | L10: ='Юнит 19-25.01'!W$49 -> 9468 | M10: ='Юнит 19-25.01'!Z$49 -> 6390.87 | N10: ='Юнит 19-25.01'!X$49 -> 26866.83 | R10: ='Юнит 19-25.01'!AA$49 -> 8921.6034 | Y10: =(K10)*0.01 -> 624.81 | Z10: =K10-SUM(M10:U10)-L10-Y10+V10+X10 -> 10208.887 | AB10: =L10/K10 -> 0.15153407 | AC10: =Z10/L10 -> 1.0782516 | AD10: =Z10/K10 -> 0.16339186 | AE10: =R10/K10 -> 0.14278906
B11: 26-31.01 очки | E11: =K11-SUM(M11:U11)+V11+W11+X11 -> 0 | F11: ='Юнит 26-31.01'!K$26 -> 0 | G11: ='Юнит 26-31.01'!P$26 -> 0 | H11: ='Юнит 26-31.01'!Q$26 -> 0 | I11: ='Юнит 26-31.01'!S$26 -> 0 | J11: ='Юнит 26-31.01'!T$26 -> 0 | K11: =I11+J11 -> 0 | L11: ='Юнит 26-31.01'!W$26 -> 0 | M11: ='Юнит 26-31.01'!Z$26 -> 0 | N11: ='Юнит 26-31.01'!X$26 -> 0 | R11: ='Юнит 26-31.01'!AA$26 -> 0 | Y11: =(K11)*0.01 -> 0 | Z11: =K11-SUM(M11:U11)-L11-Y11+V11+X11 -> 0 | AB11: =L11/K11 -> #DIV/0! | AC11: =Z11/L11 -> #DIV/0! | AD11: =Z11/K11 -> #DIV/0! | AE11: =R11/K11 -> #DIV/0!
B12: 26-31.01 туники | E12: =K12-SUM(M12:U12)+V12+W12+X12 -> 0 | F12: ='Юнит 26-31.01'!K$49 -> 0 | G12: ='Юнит 26-31.01'!P$49 -> 0 | H12: ='Юнит 26-31.01'!Q$49 -> 0 | I12: ='Юнит 26-31.01'!S$49 -> 0 | J12: ='Юнит 26-31.01'!T$49 -> 0 | K12: =I12+J12 -> 0 | L12: ='Юнит 26-31.01'!W$26 -> 0 | M12: ='Юнит 26-31.01'!Z$49 -> 0 | N12: ='Юнит 26-31.01'!X$49 -> 0 | R12: ='Юнит 26-31.01'!AA$49 -> 0 | Y12: =(K12)*0.01 -> 0 | Z12: =K12-SUM(M12:U12)-L12-Y12+V12+X12 -> 0 | AB12: =L12/K12 -> #DIV/0! | AC12: =Z12/L12 -> #DIV/0! | AD12: =Z12/K12 -> #DIV/0! | AE12: =R12/K12 -> #DIV/0!
A13: Итого | E13: =SUM(E3:E12) -> 95943.83 | F13: =SUM(F3:F12) -> 438 | G13: =SUM(G3:G12) -> 232 | H13: =SUM(H3:H12) -> 9 | I13: =SUM(I3:I12) -> 450690 | J13: =SUM(J3:J12) -> -26401 | K13: =SUM(K3:K12) -> 424289 | L13: =SUM(L3:L12) -> 44346.35 | ... V13: =SUM(V3:V12) -> 0 | X13: =SUM(X3:X12) -> 0 | Y13: =SUM(Y3:Y12) -> 4242.89 | Z13: =SUM(Z3:Z12) -> 33354.59 | AA13: =SUM(AA3:AA12) -> 33354.59 | AB13: =L13/K13 -> 0.10451921 | AC13: =Z13/L13 -> 0.75213834 | AD13: =Z13/K13 -> 0.078612903 | AE13: =R13/K13 -> 0.23835127
I14: % от выручки за весь период
J15: =-J13/I13 -> 0.058579068 | K15: 0 | L15: =L13/$K$13 -> 0.10451921 | M15: =M13/$K$13 -> 0.10689587 | N15: =N13/$K$13 -> 0.43 | R15: =R13/$K$13 -> 0.23835127 | Y15: =Y13/$K$13 -> 0.01 | Z15: =Z13/L13 -> 0.75213834 | AA15: Маржинальность, %

Sheet АВС 01.02
B2: ОЧКИ
C3: Прибыль | D3: % прибыль | E3: Доля | F3: ABC прибыль | G3: ABC кол-во | J3: Кол-во | K3: % кол-во | L3: Доля | M3: ABC кол-во
B4: черные с железкой классика | D4: =C4/C$26 -> #DIV/0! | E4: =D4 -> #DIV/0! | F4: =IF(AND(E4<=0),"C",IF(E4<=0.8,"A",IF(E4<=0.95,"B","C"))) -> #DIV/0! | G4: =VLOOKUP(B$4:B$25,I$4:M$25,5,0) -> #DIV/0! | I4: черные с железкой классика | K4: =J4/J$26 -> #DIV/0! | L4: =K4 -> #DIV/0! | M4: =_xlfn.IFS(L4<80%,"A",L4<=95%,"B",L4>95%,"C") -> #DIV/0!
B5: qs черные | D5: =C5/C$26 -> #DIV/0! | E5: =D5+E4 -> #DIV/0! | F5: =IF(AND(E5<=0),"C",IF(E5<=0.8,"A",IF(E5<=0.95,"B","C"))) -> #DIV/0! | G5: =VLOOKUP(B$4:B$25,I$4:M$25,5,0) -> #DIV/0! | I5: qs черные | K5: =J5/J$26 -> #DIV/0! | L5: =K5+L4 -> #DIV/0! | M5: =_xlfn.IFS(L5<80%,"A",L5<=95%,"B",L5>95%,"C") -> #DIV/0!
B6: qs синие | D6: =C6/C$26 -> #DIV/0! | E6: =D6+E5 -> #DIV/0! | F6: =IF(AND(E6<=0),"C",IF(E6<=0.8,"A",IF(E6<=0.95,"B","C"))) -> #DIV/0! | G6: =VLOOKUP(B$4:B$25,I$4:M$25,5,0) -> #DIV/0! | I6: qs синие | K6: =J6/J$26 -> #DIV/0! | L6: =K6+L5 -> #DIV/0! | M6: =_xlfn.IFS(L6<80%,"A",L6<=95%,"B",L6>95%,"C") -> #DIV/0!
B7: qs желтые | D7: =C7/C$26 -> #DIV/0! | E7: =D7+E6 -> #DIV/0! | F7: =IF(AND(E7<=0),"C",IF(E7<=0.8,"A",IF(E7<=0.95,"B","C"))) -> #DIV/0! | G7: =VLOOKUP(B$4:B$25,I$4:M$25,5,0) -> #DIV/0! | I7: qs желтые | K7: =J7/J$26 -> #DIV/0! | L7: =K7+L6 -> #DIV/0! | M7: =_xlfn.IFS(L7<80%,"A",L7<=95%,"B",L7>95%,"C") -> #DIV/0!
B8: qs коричневые | D8: =C8/C$26 -> #DIV/0! | E8: =D8+E7 -> #DIV/0! | F8: =IF(AND(E8<=0),"C",IF(E8<=0.8,"A",IF(E8<=0.95,"B","C"))) -> #DIV/0! | G8: =VLOOKUP(B$4:B$25,I$4:M$25,5,0) -> #DIV/0! | I8: qs коричневые | K8: =J8/J$26 -> #DIV/0! | L8: =K8+L7 -> #DIV/0! | M8: =_xlfn.IFS(L8<80%,"A",L8<=95%,"B",L8>95%,"C") -> #DIV/0!
B9: th желтый Сул | D9: =C9/C$26 -> #DIV/0! | E9: =D9+E8 -> #DIV/0! | F9: =IF(AND(E9<=0),"C",IF(E9<=0.8,"A",IF(E9<=0.95,"B","C"))) -> #DIV/0! | G9: =VLOOKUP(B$4:B$25,I$4:M$25,5,0) -> #DIV/0! | I9: th желтый Сул | K9: =J9/J$26 -> #DIV/0! | L9: =K9+L8 -> #DIV/0! | M9: =_xlfn.IFS(L9<80%,"A",L9<=95%,"B",L9>95%,"C") -> #DIV/0!
B10: flip желтые Сул | D10: =C10/C$26 -> #DIV/0! | E10: =D10+E9 -> #DIV/0! | F10: =IF(AND(E10<=0),"C",IF(E10<=0.8,"A",IF(E10<=0.95,"B","C"))) -> #DIV/0! | G10: =VLOOKUP(B$4:B$25,I$4:M$25,5,0) -> #DIV/0! | I10: flip желтые Сул | K10: =J10/J$26 -> #DIV/0! | L10: =K10+L9 -> #DIV/0! | M10: =_xlfn.IFS(L10<80%,"A",L10<=95%,"B",L10>95%,"C") -> #DIV/0!
B11: MR8854 C2 | D11: =C11/C$26 -> #DIV/0! | E11: =D11+E8 -> #DIV/0! | F11: =IF(AND(E11<=0),"C",IF(E11<=0.8,"A",IF(E11<=0.95,"B","C"))) -> #DIV/0! | G11: =VLOOKUP(B$4:B$25,I$4:M$25,5,0) -> #DIV/0! | I11: MR8854 C2 | K11: =J11/J$26 -> #DIV/0! | L11: =K11+L8 -> #DIV/0! | M11: =_xlfn.IFS(L11<80%,"A",L11<=95%,"B",L11>95%,"C") -> #DIV/0!
B12: MR 1819 черн | D12: =C12/C$26 -> #DIV/0! | E12: =D12+E11 -> #DIV/0! | F12: =IF(AND(E12<=0),"C",IF(E12<=0.8,"A",IF(E12<=0.95,"B","C"))) -> #DIV/0! | G12: =VLOOKUP(B$4:B$25,I$4:M$25,5,0) -> #DIV/0! | I12: MR 1819 черн | K12: =J12/J$26 -> #DIV/0! | L12: =K12+L11 -> #DIV/0! | M12: =_xlfn.IFS(L12<80%,"A",L12<=95%,"B",L12>95%,"C") -> #DIV/0!
B13: MR 1819 корич | D13: =C13/C$26 -> #DIV/0! | E13: =D13+E12 -> #DIV/0! | F13: =IF(AND(E13<=0),"C",IF(E13<=0.8,"A",IF(E13<=0.95,"B","C"))) -> #DIV/0! | G13: =VLOOKUP(B$4:B$25,I$4:M$25,5,0) -> #DIV/0! | I13: MR 1819 корич | K13: =J13/J$26 -> #DIV/0! | L13: =K13+L12 -> #DIV/0! | M13: =_xlfn.IFS(L13<80%,"A",L13<=95%,"B",L13>95%,"C") -> #DIV/0! | P13: A | Q13: 0.8
B14: MR Р1874 черн | D14: =C14/C$26 -> #DIV/0! | E14: =D14+E13 -> #DIV/0! | F14: =IF(AND(E14<=0),"C",IF(E14<=0.8,"A",IF(E14<=0.95,"B","C"))) -> #DIV/0! | G14: =VLOOKUP(B$4:B$25,I$4:M$25,5,0) -> #DIV/0! | I14: MR Р1874 черн | K14: =J14/J$26 -> #DIV/0! | L14: =K14+L13 -> #DIV/0! | M14: =_xlfn.IFS(L14<80%,"A",L14<=95%,"B",L14>95%,"C") -> #DIV/0! | P14: B | Q14: 0.15
B15: MR Р1874 корич | D15: =C15/C$26 -> #DIV/0! | E15: =D15+E14 -> #DIV/0! | F15: =IF(AND(E15<=0),"C",IF(E15<=0.8,"A",IF(E15<=0.95,"B","C"))) -> #DIV/0! | G15: =VLOOKUP(B$4:B$25,I$4:M$25,5,0) -> #DIV/0! | I15: MR Р1874 корич | K15: =J15/J$26 -> #DIV/0! | L15: =K15+L14 -> #DIV/0! | M15: =_xlfn.IFS(L15<80%,"A",L15<=95%,"B",L15>95%,"C") -> #DIV/0! | P15: C | Q15: 0.05
B16: MR Р1886 черн глянец | D16: =C16/C$26 -> #DIV/0! | E16: =D16+E15 -> #DIV/0! | F16: =IF(AND(E16<=0),"C",IF(E16<=0.8,"A",IF(E16<=0.95,"B","C"))) -> #DIV/0! | G16: =VLOOKUP(B$4:B$25,I$4:M$25,5,0) -> #DIV/0! | I16: MR Р1886 черн глянец | K16: =J16/J$26 -> #DIV/0! | L16: =K16+L15 -> #DIV/0! | M16: =_xlfn.IFS(L16<80%,"A",L16<=95%,"B",L16>95%,"C") -> #DIV/0!
B17: MR Р1886 корич | D17: =C17/C$26 -> #DIV/0! | E17: =D17+E16 -> #DIV/0! | F17: =IF(AND(E17<=0),"C",IF(E17<=0.8,"A",IF(E17<=0.95,"B","C"))) -> #DIV/0! | G17: =VLOOKUP(B$4:B$25,I$4:M$25,5,0) -> #DIV/0! | I17: MR Р1886 корич | K17: =J17/J$26 -> #DIV/0! | L17: =K17+L16 -> #DIV/0! | M17: =_xlfn.IFS(L17<80%,"A",L17<=95%,"B",L17>95%,"C") -> #DIV/0!
B18: lux1 | D18: =C18/C$26 -> #DIV/0! | E18: =D18+E17 -> #DIV/0! | F18: =IF(AND(E18<=0),"C",IF(E18<=0.8,"A",IF(E18<=0.95,"B","C"))) -> #DIV/0! | G18: =VLOOKUP(B$4:B$25,I$4:M$25,5,0) -> #DIV/0! | I18: lux1 | K18: =J18/J$26 -> #DIV/0! | L18: =K18+L17 -> #DIV/0! | M18: =_xlfn.IFS(L18<80%,"A",L18<=95%,"B",L18>95%,"C") -> #DIV/0!
B19: lux2 | D19: =C19/C$26 -> #DIV/0! | E19: =D19+E18 -> #DIV/0! | F19: =IF(AND(E19<=0),"C",IF(E19<=0.8,"A",IF(E19<=0.95,"B","C"))) -> #DIV/0! | G19: =VLOOKUP(B$4:B$25,I$4:M$25,5,0) -> #DIV/0! | I19: lux2 | K19: =J19/J$26 -> #DIV/0! | L19: =K19+L18 -> #DIV/0! | M19: =_xlfn.IFS(L19<80%,"A",L19<=95%,"B",L19>95%,"C") -> #DIV/0!
B20: lux3 | D20: =C20/C$26 -> #DIV/0! | E20: =D20+E19 -> #DIV/0! | F20: =IF(AND(E20<=0),"C",IF(E20<=0.8,"A",IF(E20<=0.95,"B","C"))) -> #DIV/0! | G20: =VLOOKUP(B$4:B$25,I$4:M$25,5,0) -> #DIV/0! | I20: lux3 | K20: =J20/J$26 -> #DIV/0! | L20: =K20+L19 -> #DIV/0! | M20: =_xlfn.IFS(L20<80%,"A",L20<=95%,"B",L20>95%,"C") -> #DIV/0!
B21: lux4 | D21: =C21/C$26 -> #DIV/0! | E21: =D21+E20 -> #DIV/0! | F21: =IF(AND(E21<=0),"C",IF(E21<=0.8,"A",IF(E21<=0.95,"B","C"))) -> #DIV/0! | G21: =VLOOKUP(B$4:B$25,I$4:M$25,5,0) -> #DIV/0! | I21: lux4 | K21: =J21/J$26 -> #DIV/0! | L21: =K21+L20 -> #DIV/0! | M21: =_xlfn.IFS(L21<80%,"A",L21<=95%,"B",L21>95%,"C") -> #DIV/0!
B22: lux5 | D22: =C22/C$26 -> #DIV/0! | E22: =D22+E21 -> #DIV/0! | F22: =IF(AND(E22<=0),"C",IF(E22<=0.8,"A",IF(E22<=0.95,"B","C"))) -> #DIV/0! | G22: =VLOOKUP(B$4:B$25,I$4:M$25,5,0) -> #DIV/0! | I22: lux5 | K22: =J22/J$26 -> #DIV/0! | L22: =K22+L21 -> #DIV/0! | M22: =_xlfn.IFS(L22<80%,"A",L22<=95%,"B",L22>95%,"C") -> #DIV/0!
B23: lux6 | D23: =C23/C$26 -> #DIV/0! | E23: =D23+E22 -> #DIV/0! | F23: =IF(AND(E23<=0),"C",IF(E23<=0.8,"A",IF(E23<=0.95,"B","C"))) -> #DIV/0! | G23: =VLOOKUP(B$4:B$25,I$4:M$25,5,0) -> #DIV/0! | I23: lux6 | K23: =J23/J$26 -> #DIV/0! | L23: =K23+L22 -> #DIV/0! | M23: =_xlfn.IFS(L23<80%,"A",L23<=95%,"B",L23>95%,"C") -> #DIV/0!
B24: lux7 | D24: =C24/C$26 -> #DIV/0! | E24: =D24+E23 -> #DIV/0! | F24: =IF(AND(E24<=0),"C",IF(E24<=0.8,"A",IF(E24<=0.95,"B","C"))) -> #DIV/0! | G24: =VLOOKUP(B$4:B$25,I$4:M$25,5,0) -> #DIV/0! | I24: lux7 | K24: =J24/J$26 -> #DIV/0! | L24: =K24+L23 -> #DIV/0! | M24: =_xlfn.IFS(L24<80%,"A",L24<=95%,"B",L24>95%,"C") -> #DIV/0!
B25: lux8 | D25: =C25/C$26 -> #DIV/0! | E25: =D25+E24 -> #DIV/0! | F25: =IF(AND(E25<=0),"C",IF(E25<=0.8,"A",IF(E25<=0.95,"B","C"))) -> #DIV/0! | G25: =VLOOKUP(B$4:B$25,I$4:M$25,5,0) -> #DIV/0! | I25: lux8 | K25: =J25/J$26 -> #DIV/0! | L25: =K25+L24 -> #DIV/0! | M25: =_xlfn.IFS(L25<80%,"A",L25<=95%,"B",L25>95%,"C") -> #DIV/0!
C26: =SUM(C4:C25) -> 0 | D26: =SUM(D4:D25) -> #DIV/0! | J26: =SUM(J4:J25) -> 0 | K26: =SUM(K4:K25) -> #DIV/0!
B28: ТУНИКИ
C29: Прибыль | D29: % прибыль | E29: Доля | F29: ABC прибыль | G29: ABC кол-во | J29: Кол-во | K29: % кол-во | L29: Доля | M29: ABC кол-во
B30: tunika02 оливковая с руч вышивкой | D30: =C30/C$50 -> #DIV/0! | E30: =D30 -> #DIV/0! | F30: =IF(AND(E30<=0),"C",IF(E30<=0.8,"A",IF(E30<=0.95,"B","C"))) -> #DIV/0! | G30: =VLOOKUP(B$30:B$50,I$30:M$50,5,0) -> #DIV/0! | I30: tunika02 оливковая с руч вышивкой | K30: =J30/J$50 -> #DIV/0! | L30: =K30 -> #DIV/0! | M30: =_xlfn.IFS(L30<80%,"A",L30<=95%,"B",L30>95%,"C") -> #DIV/0!
B31: tunika03 черная распашная | D31: =C31/C$50 -> #DIV/0! | E31: =D31+E30 -> #DIV/0! | F31: =IF(AND(E31<=0),"C",IF(E31<=0.8,"A",IF(E31<=0.95,"B","C"))) -> #DIV/0! | G31: =VLOOKUP(B$30:B$50,I$30:M$50,5,0) -> #DIV/0! | I31: tunika03 черная распашная | K31: =J31/J$50 -> #DIV/0! | L31: =K31+L30 -> #DIV/0! | M31: =_xlfn.IFS(L31<80%,"A",L31<=95%,"B",L31>95%,"C") -> #DIV/0!
B32: tunika05 белая распашная | D32: =C32/C$50 -> #DIV/0! | E32: =D32+E31 -> #DIV/0! | F32: =IF(AND(E32<=0),"C",IF(E32<=0.8,"A",IF(E32<=0.95,"B","C"))) -> #DIV/0! | G32: =VLOOKUP(B$30:B$50,I$30:M$50,5,0) -> #DIV/0! | I32: tunika05 белая распашная | K32: =J32/J$50 -> #DIV/0! | L32: =K32+L31 -> #DIV/0! | M32: =_xlfn.IFS(L32<80%,"A",L32<=95%,"B",L32>95%,"C") -> #DIV/0!
B33: tunika06 белая | D33: =C33/C$50 -> #DIV/0! | E33: =D33+E32 -> #DIV/0! | F33: =IF(AND(E33<=0),"C",IF(E33<=0.8,"A",IF(E33<=0.95,"B","C"))) -> #DIV/0! | G33: =VLOOKUP(B$30:B$50,I$30:M$50,5,0) -> #DIV/0! | I33: tunika06 белая | K33: =J33/J$50 -> #DIV/0! | L33: =K33+L32 -> #DIV/0! | M33: =_xlfn.IFS(L33<80%,"A",L33<=95%,"B",L33>95%,"C") -> #DIV/0!
B34: tunika06 черная | D34: =C34/C$50 -> #DIV/0! | E34: =D34+E33 -> #DIV/0! | F34: =IF(AND(E34<=0),"C",IF(E34<=0.8,"A",IF(E34<=0.95,"B","C"))) -> #DIV/0! | G34: =VLOOKUP(B$30:B$50,I$30:M$50,5,0) -> #DIV/0! | I34: tunika06 черная | K34: =J34/J$50 -> #DIV/0! | L34: =K34+L33 -> #DIV/0! | M34: =_xlfn.IFS(L34<80%,"A",L34<=95%,"B",L34>95%,"C") -> #DIV/0!
B35: tunika07 кружево | D35: =C35/C$50 -> #DIV/0! | E35: =D35+E34 -> #DIV/0! | F35: =IF(AND(E35<=0),"C",IF(E35<=0.8,"A",IF(E35<=0.95,"B","C"))) -> #DIV/0! | G35: =VLOOKUP(B$30:B$50,I$30:M$50,5,0) -> #DIV/0! | I35: tunika07 кружево | K35: =J35/J$50 -> #DIV/0! | L35: =K35+L34 -> #DIV/0! | M35: =_xlfn.IFS(L35<80%,"A",L35<=95%,"B",L35>95%,"C") -> #DIV/0!
B36: tunika08 белая | D36: =C36/C$50 -> #DIV/0! | E36: =D36+E35 -> #DIV/0! | F36: =IF(AND(E36<=0),"C",IF(E36<=0.8,"A",IF(E36<=0.95,"B","C"))) -> #DIV/0! | G36: =VLOOKUP(B$30:B$50,I$30:M$50,5,0) -> #DIV/0! | I36: tunika08 белая | K36: =J36/J$50 -> #DIV/0! | L36: =K36+L35 -> #DIV/0! | M36: =_xlfn.IFS(L36<80%,"A",L36<=95%,"B",L36>95%,"C") -> #DIV/0!
B37: tunika08 черная | D37: =C37/C$50 -> #DIV/0! | E37: =D37+E36 -> #DIV/0! | F37: =IF(AND(E37<=0),"C",IF(E37<=0.8,"A",IF(E37<=0.95,"B","C"))) -> #DIV/0! | G37: =VLOOKUP(B$30:B$50,I$30:M$50,5,0) -> #DIV/0! | I37: tunika08 черная | K37: =J37/J$50 -> #DIV/0! | L37: =K37+L36 -> #DIV/0! | M37: =_xlfn.IFS(L37<80%,"A",L37<=95%,"B",L37>95%,"C") -> #DIV/0!
B38: tunika08 зеленая | D38: =C38/C$50 -> #DIV/0! | E38: =D38+E37 -> #DIV/0! | F38: =IF(AND(E38<=0),"C",IF(E38<=0.8,"A",IF(E38<=0.95,"B","C"))) -> #DIV/0! | G38: =VLOOKUP(B$30:B$50,I$30:M$50,5,0) -> #DIV/0! | I38: tunika08 зеленая | K38: =J38/J$50 -> #DIV/0! | L38: =K38+L37 -> #DIV/0! | M38: =_xlfn.IFS(L38<80%,"A",L38<=95%,"B",L38>95%,"C") -> #DIV/0!
B39: tunika09 кимоно | D39: =C39/C$50 -> #DIV/0! | E39: =D39+E38 -> #DIV/0! | F39: =IF(AND(E39<=0),"C",IF(E39<=0.8,"A",IF(E39<=0.95,"B","C"))) -> #DIV/0! | G39: =VLOOKUP(B$30:B$50,I$30:M$50,5,0) -> #DIV/0! | I39: tunika09 кимоно | K39: =J39/J$50 -> #DIV/0! | L39: =K39+L38 -> #DIV/0! | M39: =_xlfn.IFS(L39<80%,"A",L39<=95%,"B",L39>95%,"C") -> #DIV/0!
B40: tunika10 кимоно ч/б | D40: =C40/C$50 -> #DIV/0! | E40: =D40+E39 -> #DIV/0! | F40: =IF(AND(E40<=0),"C",IF(E40<=0.8,"A",IF(E40<=0.95,"B","C"))) -> #DIV/0! | G40: =VLOOKUP(B$30:B$50,I$30:M$50,5,0) -> #DIV/0! | I40: tunika10 кимоно ч/б | K40: =J40/J$50 -> #DIV/0! | L40: =K40+L39 -> #DIV/0! | M40: =_xlfn.IFS(L40<80%,"A",L40<=95%,"B",L40>95%,"C") -> #DIV/0!
B41: tunika11 халат зеленая | D41: =C41/C$50 -> #DIV/0! | E41: =D41+E40 -> #DIV/0! | F41: =IF(AND(E41<=0),"C",IF(E41<=0.8,"A",IF(E41<=0.95,"B","C"))) -> #DIV/0! | G41: =VLOOKUP(B$30:B$50,I$30:M$50,5,0) -> #DIV/0! | I41: tunika11 халат зеленая | K41: =J41/J$50 -> #DIV/0! | L41: =K41+L40 -> #DIV/0! | M41: =_xlfn.IFS(L41<80%,"A",L41<=95%,"B",L41>95%,"C") -> #DIV/0!
B42: tunika12 халат белая | D42: =C42/C$50 -> #DIV/0! | E42: =D42+E41 -> #DIV/0! | F42: =IF(AND(E42<=0),"C",IF(E42<=0.8,"A",IF(E42<=0.95,"B","C"))) -> #DIV/0! | G42: =VLOOKUP(B$30:B$50,I$30:M$50,5,0) -> #DIV/0! | I42: tunika12 халат белая | K42: =J42/J$50 -> #DIV/0! | L42: =K42+L41 -> #DIV/0! | M42: =_xlfn.IFS(L42<80%,"A",L42<=95%,"B",L42>95%,"C") -> #DIV/0!
...

Sheet АВС ЯНВАРЬ
B2: ОЧКИ
C3: Прибыль | D3: % прибыль | E3: Доля | F3: ABC прибыль | G3: ABC кол-во | J3: Кол-во | K3: % кол-во | L3: Доля | M3: ABC кол-во
B4: черные с железкой классика | D4: =C4/C$26 -> #DIV/0! | E4: =D4 -> #DIV/0! | F4: =IF(AND(E4<=0),"C",IF(E4<=0.8,"A",IF(E4<=0.95,"B","C"))) -> #DIV/0! | G4: =VLOOKUP(B$4:B$25,I$4:M$25,5,0) -> #DIV/0! | I4: черные с железкой классика | K4: =J4/J$26 -> #DIV/0! | L4: =K4 -> #DIV/0! | M4: =_xlfn.IFS(L4<80%,"A",L4<=95%,"B",L4>95%,"C") -> #DIV/0!
B5: qs черные | D5: =C5/C$26 -> #DIV/0! | E5: =D5+E4 -> #DIV/0! | F5: =IF(AND(E5<=0),"C",IF(E5<=0.8,"A",IF(E5<=0.95,"B","C"))) -> #DIV/0! | G5: =VLOOKUP(B$4:B$25,I$4:M$25,5,0) -> #DIV/0! | I5: qs черные | K5: =J5/J$26 -> #DIV/0! | L5: =K5+L4 -> #DIV/0! | M5: =_xlfn.IFS(L5<80%,"A",L5<=95%,"B",L5>95%,"C") -> #DIV/0!
B6: qs синие | D6: =C6/C$26 -> #DIV/0! | E6: =D6+E5 -> #DIV/0! | F6: =IF(AND(E6<=0),"C",IF(E6<=0.8,"A",IF(E6<=0.95,"B","C"))) -> #DIV/0! | G6: =VLOOKUP(B$4:B$25,I$4:M$25,5,0) -> #DIV/0! | I6: qs синие | K6: =J6/J$26 -> #DIV/0! | L6: =K6+L5 -> #DIV/0! | M6: =_xlfn.IFS(L6<80%,"A",L6<=95%,"B",L6>95%,"C") -> #DIV/0!
B7: qs желтые | D7: =C7/C$26 -> #DIV/0! | E7: =D7+E6 -> #DIV/0! | F7: =IF(AND(E7<=0),"C",IF(E7<=0.8,"A",IF(E7<=0.95,"B","C"))) -> #DIV/0! | G7: =VLOOKUP(B$4:B$25,I$4:M$25,5,0) -> #DIV/0! | I7: qs желтые | K7: =J7/J$26 -> #DIV/0! | L7: =K7+L6 -> #DIV/0! | M7: =_xlfn.IFS(L7<80%,"A",L7<=95%,"B",L7>95%,"C") -> #DIV/0!
B8: qs коричневые | D8: =C8/C$26 -> #DIV/0! | E8: =D8+E7 -> #DIV/0! | F8: =IF(AND(E8<=0),"C",IF(E8<=0.8,"A",IF(E8<=0.95,"B","C"))) -> #DIV/0! | G8: =VLOOKUP(B$4:B$25,I$4:M$25,5,0) -> #DIV/0! | I8: qs коричневые | K8: =J8/J$26 -> #DIV/0! | L8: =K8+L7 -> #DIV/0! | M8: =_xlfn.IFS(L8<80%,"A",L8<=95%,"B",L8>95%,"C") -> #DIV/0!
B9: th желтый Сул | D9: =C9/C$26 -> #DIV/0! | E9: =D9+E8 -> #DIV/0! | F9: =IF(AND(E9<=0),"C",IF(E9<=0.8,"A",IF(E9<=0.95,"B","C"))) -> #DIV/0! | G9: =VLOOKUP(B$4:B$25,I$4:M$25,5,0) -> #DIV/0! | I9: th желтый Сул | K9: =J9/J$26 -> #DIV/0! | L9: =K9+L8 -> #DIV/0! | M9: =_xlfn.IFS(L9<80%,"A",L9<=95%,"B",L9>95%,"C") -> #DIV/0!
B10: flip желтые Сул | D10: =C10/C$26 -> #DIV/0! | E10: =D10+E9 -> #DIV/0! | F10: =IF(AND(E10<=0),"C",IF(E10<=0.8,"A",IF(E10<=0.95,"B","C"))) -> #DIV/0! | G10: =VLOOKUP(B$4:B$25,I$4:M$25,5,0) -> #DIV/0! | I10: flip желтые Сул | K10: =J10/J$26 -> #DIV/0! | L10: =K10+L9 -> #DIV/0! | M10: =_xlfn.IFS(L10<80%,"A",L10<=95%,"B",L10>95%,"C") -> #DIV/0!
B11: MR8854 C2 | D11: =C11/C$26 -> #DIV/0! | E11: =D11+E8 -> #DIV/0! | F11: =IF(AND(E11<=0),"C",IF(E11<=0.8,"A",IF(E11<=0.95,"B","C"))) -> #DIV/0! | G11: =VLOOKUP(B$4:B$25,I$4:M$25,5,0) -> #DIV/0! | I11: MR8854 C2 | K11: =J11/J$26 -> #DIV/0! | L11: =K11+L8 -> #DIV/0! | M11: =_xlfn.IFS(L11<80%,"A",L11<=95%,"B",L11>95%,"C") -> #DIV/0!
B12: MR 1819 черн | D12: =C12/C$26 -> #DIV/0! | E12: =D12+E11 -> #DIV/0! | F12: =IF(AND(E12<=0),"C",IF(E12<=0.8,"A",IF(E12<=0.95,"B","C"))) -> #DIV/0! | G12: =VLOOKUP(B$4:B$25,I$4:M$25,5,0) -> #DIV/0! | I12: MR 1819 черн | K12: =J12/J$26 -> #DIV/0! | L12: =K12+L11 -> #DIV/0! | M12: =_xlfn.IFS(L12<80%,"A",L12<=95%,"B",L12>95%,"C") -> #DIV/0!
B13: MR 1819 корич | D13: =C13/C$26 -> #DIV/0! | E13: =D13+E12 -> #DIV/0! | F13: =IF(AND(E13<=0),"C",IF(E13<=0.8,"A",IF(E13<=0.95,"B","C"))) -> #DIV/0! | G13: =VLOOKUP(B$4:B$25,I$4:M$25,5,0) -> #DIV/0! | I13: MR 1819 корич | K13: =J13/J$26 -> #DIV/0! | L13: =K13+L12 -> #DIV/0! | M13: =_xlfn.IFS(L13<80%,"A",L13<=95%,"B",L13>95%,"C") -> #DIV/0! | P13: A | Q13: 0.8
B14: MR Р1874 черн | D14: =C14/C$26 -> #DIV/0! | E14: =D14+E13 -> #DIV/0! | F14: =IF(AND(E14<=0),"C",IF(E14<=0.8,"A",IF(E14<=0.95,"B","C"))) -> #DIV/0! | G14: =VLOOKUP(B$4:B$25,I$4:M$25,5,0) -> #DIV/0! | I14: MR Р1874 черн | K14: =J14/J$26 -> #DIV/0! | L14: =K14+L13 -> #DIV/0! | M14: =_xlfn.IFS(L14<80%,"A",L14<=95%,"B",L14>95%,"C") -> #DIV/0! | P14: B | Q14: 0.15
B15: MR Р1874 корич | D15: =C15/C$26 -> #DIV/0! | E15: =D15+E14 -> #DIV/0! | F15: =IF(AND(E15<=0),"C",IF(E15<=0.8,"A",IF(E15<=0.95,"B","C"))) -> #DIV/0! | G15: =VLOOKUP(B$4:B$25,I$4:M$25,5,0) -> #DIV/0! | I15: MR Р1874 корич | K15: =J15/J$26 -> #DIV/0! | L15: =K15+L14 -> #DIV/0! | M15: =_xlfn.IFS(L15<80%,"A",L15<=95%,"B",L15>95%,"C") -> #DIV/0! | P15: C | Q15: 0.05
B16: MR Р1886 черн глянец | D16: =C16/C$26 -> #DIV/0! | E16: =D16+E15 -> #DIV/0! | F16: =IF(AND(E16<=0),"C",IF(E16<=0.8,"A",IF(E16<=0.95,"B","C"))) -> #DIV/0! | G16: =VLOOKUP(B$4:B$25,I$4:M$25,5,0) -> #DIV/0! | I16: MR Р1886 черн глянец | K16: =J16/J$26 -> #DIV/0! | L16: =K16+L15 -> #DIV/0! | M16: =_xlfn.IFS(L16<80%,"A",L16<=95%,"B",L16>95%,"C") -> #DIV/0!
B17: MR Р1886 корич | D17: =C17/C$26 -> #DIV/0! | E17: =D17+E16 -> #DIV/0! | F17: =IF(AND(E17<=0),"C",IF(E17<=0.8,"A",IF(E17<=0.95,"B","C"))) -> #DIV/0! | G17: =VLOOKUP(B$4:B$25,I$4:M$25,5,0) -> #DIV/0! | I17: MR Р1886 корич | K17: =J17/J$26 -> #DIV/0! | L17: =K17+L16 -> #DIV/0! | M17: =_xlfn.IFS(L17<80%,"A",L17<=95%,"B",L17>95%,"C") -> #DIV/0!
B18: lux1 | D18: =C18/C$26 -> #DIV/0! | E18: =D18+E17 -> #DIV/0! | F18: =IF(AND(E18<=0),"C",IF(E18<=0.8,"A",IF(E18<=0.95,"B","C"))) -> #DIV/0! | G18: =VLOOKUP(B$4:B$25,I$4:M$25,5,0) -> #DIV/0! | I18: lux1 | K18: =J18/J$26 -> #DIV/0! | L18: =K18+L17 -> #DIV/0! | M18: =_xlfn.IFS(L18<80%,"A",L18<=95%,"B",L18>95%,"C") -> #DIV/0!
B19: lux2 | D19: =C19/C$26 -> #DIV/0! | E19: =D19+E18 -> #DIV/0! | F19: =IF(AND(E19<=0),"C",IF(E19<=0.8,"A",IF(E19<=0.95,"B","C"))) -> #DIV/0! | G19: =VLOOKUP(B$4:B$25,I$4:M$25,5,0) -> #DIV/0! | I19: lux2 | K19: =J19/J$26 -> #DIV/0! | L19: =K19+L18 -> #DIV/0! | M19: =_xlfn.IFS(L19<80%,"A",L19<=95%,"B",L19>95%,"C") -> #DIV/0!
B20: lux3 | D20: =C20/C$26 -> #DIV/0! | E20: =D20+E19 -> #DIV/0! | F20: =IF(AND(E20<=0),"C",IF(E20<=0.8,"A",IF(E20<=0.95,"B","C"))) -> #DIV/0! | G20: =VLOOKUP(B$4:B$25,I$4:M$25,5,0) -> #DIV/0! | I20: lux3 | K20: =J20/J$26 -> #DIV/0! | L20: =K20+L19 -> #DIV/0! | M20: =_xlfn.IFS(L20<80%,"A",L20<=95%,"B",L20>95%,"C") -> #DIV/0!
B21: lux4 | D21: =C21/C$26 -> #DIV/0! | E21: =D21+E20 -> #DIV/0! | F21: =IF(AND(E21<=0),"C",IF(E21<=0.8,"A",IF(E21<=0.95,"B","C"))) -> #DIV/0! | G21: =VLOOKUP(B$4:B$25,I$4:M$25,5,0) -> #DIV/0! | I21: lux4 | K21: =J21/J$26 -> #DIV/0! | L21: =K21+L20 -> #DIV/0! | M21: =_xlfn.IFS(L21<80%,"A",L21<=95%,"B",L21>95%,"C") -> #DIV/0!
B22: lux5 | D22: =C22/C$26 -> #DIV/0! | E22: =D22+E21 -> #DIV/0! | F22: =IF(AND(E22<=0),"C",IF(E22<=0.8,"A",IF(E22<=0.95,"B","C"))) -> #DIV/0! | G22: =VLOOKUP(B$4:B$25,I$4:M$25,5,0) -> #DIV/0! | I22: lux5 | K22: =J22/J$26 -> #DIV/0! | L22: =K22+L21 -> #DIV/0! | M22: =_xlfn.IFS(L22<80%,"A",L22<=95%,"B",L22>95%,"C") -> #DIV/0!
B23: lux6 | D23: =C23/C$26 -> #DIV/0! | E23: =D23+E22 -> #DIV/0! | F23: =IF(AND(E23<=0),"C",IF(E23<=0.8,"A",IF(E23<=0.95,"B","C"))) -> #DIV/0! | G23: =VLOOKUP(B$4:B$25,I$4:M$25,5,0) -> #DIV/0! | I23: lux6 | K23: =J23/J$26 -> #DIV/0! | L23: =K23+L22 -> #DIV/0! | M23: =_xlfn.IFS(L23<80%,"A",L23<=95%,"B",L23>95%,"C") -> #DIV/0!
B24: lux7 | D24: =C24/C$26 -> #DIV/0! | E24: =D24+E23 -> #DIV/0! | F24: =IF(AND(E24<=0),"C",IF(E24<=0.8,"A",IF(E24<=0.95,"B","C"))) -> #DIV/0! | G24: =VLOOKUP(B$4:B$25,I$4:M$25,5,0) -> #DIV/0! | I24: lux7 | K24: =J24/J$26 -> #DIV/0! | L24: =K24+L23 -> #DIV/0! | M24: =_xlfn.IFS(L24<80%,"A",L24<=95%,"B",L24>95%,"C") -> #DIV/0!
B25: lux8 | D25: =C25/C$26 -> #DIV/0! | E25: =D25+E24 -> #DIV/0! | F25: =IF(AND(E25<=0),"C",IF(E25<=0.8,"A",IF(E25<=0.95,"B","C"))) -> #DIV/0! | G25: =VLOOKUP(B$4:B$25,I$4:M$25,5,0) -> #DIV/0! | I25: lux8 | K25: =J25/J$26 -> #DIV/0! | L25: =K25+L24 -> #DIV/0! | M25: =_xlfn.IFS(L25<80%,"A",L25<=95%,"B",L25>95%,"C") -> #DIV/0!
C26: =SUM(C4:C25) -> 0 | D26: =SUM(D4:D25) -> #DIV/0! | J26: =SUM(J4:J25) -> 0 | K26: =SUM(K4:K25) -> #DIV/0!
B28: ТУНИКИ
C29: Прибыль | D29: % прибыль | E29: Доля | F29: ABC прибыль | G29: ABC кол-во | J29: Кол-во | K29: % кол-во | L29: Доля | M29: ABC кол-во
B30: tunika02 оливковая с руч вышивкой | D30: =C30/C$50 -> #DIV/0! | E30: =D30 -> #DIV/0! | F30: =IF(AND(E30<=0),"C",IF(E30<=0.8,"A",IF(E30<=0.95,"B","C"))) -> #DIV/0! | G30: =VLOOKUP(B$30:B$50,I$30:M$50,5,0) -> #DIV/0! | I30: tunika02 оливковая с руч вышивкой | K30: =J30/J$50 -> #DIV/0! | L30: =K30 -> #DIV/0! | M30: =_xlfn.IFS(L30<80%,"A",L30<=95%,"B",L30>95%,"C") -> #DIV/0!
B31: tunika03 черная распашная | D31: =C31/C$50 -> #DIV/0! | E31: =D31+E30 -> #DIV/0! | F31: =IF(AND(E31<=0),"C",IF(E31<=0.8,"A",IF(E31<=0.95,"B","C"))) -> #DIV/0! | G31: =VLOOKUP(B$30:B$50,I$30:M$50,5,0) -> #DIV/0! | I31: tunika03 черная распашная | K31: =J31/J$50 -> #DIV/0! | L31: =K31+L30 -> #DIV/0! | M31: =_xlfn.IFS(L31<80%,"A",L31<=95%,"B",L31>95%,"C") -> #DIV/0!
B32: tunika05 белая распашная | D32: =C32/C$50 -> #DIV/0! | E32: =D32+E31 -> #DIV/0! | F32: =IF(AND(E32<=0),"C",IF(E32<=0.8,"A",IF(E32<=0.95,"B","C"))) -> #DIV/0! | G32: =VLOOKUP(B$30:B$50,I$30:M$50,5,0) -> #DIV/0! | I32: tunika05 белая распашная | K32: =J32/J$50 -> #DIV/0! | L32: =K32+L31 -> #DIV/0! | M32: =_xlfn.IFS(L32<80%,"A",L32<=95%,"B",L32>95%,"C") -> #DIV/0!
B33: tunika06 белая | D33: =C33/C$50 -> #DIV/0! | E33: =D33+E32 -> #DIV/0! | F33: =IF(AND(E33<=0),"C",IF(E33<=0.8,"A",IF(E33<=0.95,"B","C"))) -> #DIV/0! | G33: =VLOOKUP(B$30:B$50,I$30:M$50,5,0) -> #DIV/0! | I33: tunika06 белая | K33: =J33/J$50 -> #DIV/0! | L33: =K33+L32 -> #DIV/0! | M33: =_xlfn.IFS(L33<80%,"A",L33<=95%,"B",L33>95%,"C") -> #DIV/0!
B34: tunika06 черная | D34: =C34/C$50 -> #DIV/0! | E34: =D34+E33 -> #DIV/0! | F34: =IF(AND(E34<=0),"C",IF(E34<=0.8,"A",IF(E34<=0.95,"B","C"))) -> #DIV/0! | G34: =VLOOKUP(B$30:B$50,I$30:M$50,5,0) -> #DIV/0! | I34: tunika06 черная | K34: =J34/J$50 -> #DIV/0! | L34: =K34+L33 -> #DIV/0! | M34: =_xlfn.IFS(L34<80%,"A",L34<=95%,"B",L34>95%,"C") -> #DIV/0!
B35: tunika07 кружево | D35: =C35/C$50 -> #DIV/0! | E35: =D35+E34 -> #DIV/0! | F35: =IF(AND(E35<=0),"C",IF(E35<=0.8,"A",IF(E35<=0.95,"B","C"))) -> #DIV/0! | G35: =VLOOKUP(B$30:B$50,I$30:M$50,5,0) -> #DIV/0! | I35: tunika07 кружево | K35: =J35/J$50 -> #DIV/0! | L35: =K35+L34 -> #DIV/0! | M35: =_xlfn.IFS(L35<80%,"A",L35<=95%,"B",L35>95%,"C") -> #DIV/0!
B36: tunika08 белая | D36: =C36/C$50 -> #DIV/0! | E36: =D36+E35 -> #DIV/0! | F36: =IF(AND(E36<=0),"C",IF(E36<=0.8,"A",IF(E36<=0.95,"B","C"))) -> #DIV/0! | G36: =VLOOKUP(B$30:B$50,I$30:M$50,5,0) -> #DIV/0! | I36: tunika08 белая | K36: =J36/J$50 -> #DIV/0! | L36: =K36+L35 -> #DIV/0! | M36: =_xlfn.IFS(L36<80%,"A",L36<=95%,"B",L36>95%,"C") -> #DIV/0!
B37: tunika08 черная | D37: =C37/C$50 -> #DIV/0! | E37: =D37+E36 -> #DIV/0! | F37: =IF(AND(E37<=0),"C",IF(E37<=0.8,"A",IF(E37<=0.95,"B","C"))) -> #DIV/0! | G37: =VLOOKUP(B$30:B$50,I$30:M$50,5,0) -> #DIV/0! | I37: tunika08 черная | K37: =J37/J$50 -> #DIV/0! | L37: =K37+L36 -> #DIV/0! | M37: =_xlfn.IFS(L37<80%,"A",L37<=95%,"B",L37>95%,"C") -> #DIV/0!
B38: tunika08 зеленая | D38: =C38/C$50 -> #DIV/0! | E38: =D38+E37 -> #DIV/0! | F38: =IF(AND(E38<=0),"C",IF(E38<=0.8,"A",IF(E38<=0.95,"B","C"))) -> #DIV/0! | G38: =VLOOKUP(B$30:B$50,I$30:M$50,5,0) -> #DIV/0! | I38: tunika08 зеленая | K38: =J38/J$50 -> #DIV/0! | L38: =K38+L37 -> #DIV/0! | M38: =_xlfn.IFS(L38<80%,"A",L38<=95%,"B",L38>95%,"C") -> #DIV/0!
B39: tunika09 кимоно | D39: =C39/C$50 -> #DIV/0! | E39: =D39+E38 -> #DIV/0! | F39: =IF(AND(E39<=0),"C",IF(E39<=0.8,"A",IF(E39<=0.95,"B","C"))) -> #DIV/0! | G39: =VLOOKUP(B$30:B$50,I$30:M$50,5,0) -> #DIV/0! | I39: tunika09 кимоно | K39: =J39/J$50 -> #DIV/0! | L39: =K39+L38 -> #DIV/0! | M39: =_xlfn.IFS(L39<80%,"A",L39<=95%,"B",L39>95%,"C") -> #DIV/0!
B40: tunika10 кимоно ч/б | D40: =C40/C$50 -> #DIV/0! | E40: =D40+E39 -> #DIV/0! | F40: =IF(AND(E40<=0),"C",IF(E40<=0.8,"A",IF(E40<=0.95,"B","C"))) -> #DIV/0! | G40: =VLOOKUP(B$30:B$50,I$30:M$50,5,0) -> #DIV/0! | I40: tunika10 кимоно ч/б | K40: =J40/J$50 -> #DIV/0! | L40: =K40+L39 -> #DIV/0! | M40: =_xlfn.IFS(L40<80%,"A",L40<=95%,"B",L40>95%,"C") -> #DIV/0!
B41: tunika11 халат зеленая | D41: =C41/C$50 -> #DIV/0! | E41: =D41+E40 -> #DIV/0! | F41: =IF(AND(E41<=0),"C",IF(E41<=0.8,"A",IF(E41<=0.95,"B","C"))) -> #DIV/0! | G41: =VLOOKUP(B$30:B$50,I$30:M$50,5,0) -> #DIV/0! | I41: tunika11 халат зеленая | K41: =J41/J$50 -> #DIV/0! | L41: =K41+L40 -> #DIV/0! | M41: =_xlfn.IFS(L41<80%,"A",L41<=95%,"B",L41>95%,"C") -> #DIV/0!
B42: tunika12 халат белая | D42: =C42/C$50 -> #DIV/0! | E42: =D42+E41 -> #DIV/0! | F42: =IF(AND(E42<=0),"C",IF(E42<=0.8,"A",IF(E42<=0.95,"B","C"))) -> #DIV/0! | G42: =VLOOKUP(B$30:B$50,I$30:M$50,5,0) -> #DIV/0! | I42: tunika12 халат белая | K42: =J42/J$50 -> #DIV/0! | L42: =K42+L41 -> #DIV/0! | M42: =_xlfn.IFS(L42<80%,"A",L42<=95%,"B",L42>95%,"C") -> #DIV/0!
...

Sheet АВС 26-31.01
B2: ОЧКИ
C3: Прибыль | D3: % прибыль | E3: Доля | F3: ABC прибыль | G3: ABC кол-во | J3: Кол-во | K3: % кол-во | L3: Доля | M3: ABC кол-во
B4: черные с железкой классика | D4: =C4/C$26 -> #DIV/0! | E4: =D4 -> #DIV/0! | F4: =IF(AND(E4<=0),"C",IF(E4<=0.8,"A",IF(E4<=0.95,"B","C"))) -> #DIV/0! | G4: =VLOOKUP(B$4:B$25,I$4:M$25,5,0) -> #DIV/0! | I4: черные с железкой классика | K4: =J4/J$26 -> #DIV/0! | L4: =K4 -> #DIV/0! | M4: =_xlfn.IFS(L4<80%,"A",L4<=95%,"B",L4>95%,"C") -> #DIV/0!
B5: qs черные | D5: =C5/C$26 -> #DIV/0! | E5: =D5+E4 -> #DIV/0! | F5: =IF(AND(E5<=0),"C",IF(E5<=0.8,"A",IF(E5<=0.95,"B","C"))) -> #DIV/0! | G5: =VLOOKUP(B$4:B$25,I$4:M$25,5,0) -> #DIV/0! | I5: qs черные | K5: =J5/J$26 -> #DIV/0! | L5: =K5+L4 -> #DIV/0! | M5: =_xlfn.IFS(L5<80%,"A",L5<=95%,"B",L5>95%,"C") -> #DIV/0!
B6: qs синие | D6: =C6/C$26 -> #DIV/0! | E6: =D6+E5 -> #DIV/0! | F6: =IF(AND(E6<=0),"C",IF(E6<=0.8,"A",IF(E6<=0.95,"B","C"))) -> #DIV/0! | G6: =VLOOKUP(B$4:B$25,I$4:M$25,5,0) -> #DIV/0! | I6: qs синие | K6: =J6/J$26 -> #DIV/0! | L6: =K6+L5 -> #DIV/0! | M6: =_xlfn.IFS(L6<80%,"A",L6<=95%,"B",L6>95%,"C") -> #DIV/0!
B7: qs желтые | D7: =C7/C$26 -> #DIV/0! | E7: =D7+E6 -> #DIV/0! | F7: =IF(AND(E7<=0),"C",IF(E7<=0.8,"A",IF(E7<=0.95,"B","C"))) -> #DIV/0! | G7: =VLOOKUP(B$4:B$25,I$4:M$25,5,0) -> #DIV/0! | I7: qs желтые | K7: =J7/J$26 -> #DIV/0! | L7: =K7+L6 -> #DIV/0! | M7: =_xlfn.IFS(L7<80%,"A",L7<=95%,"B",L7>95%,"C") -> #DIV/0!
B8: qs коричневые | D8: =C8/C$26 -> #DIV/0! | E8: =D8+E7 -> #DIV/0! | F8: =IF(AND(E8<=0),"C",IF(E8<=0.8,"A",IF(E8<=0.95,"B","C"))) -> #DIV/0! | G8: =VLOOKUP(B$4:B$25,I$4:M$25,5,0) -> #DIV/0! | I8: qs коричневые | K8: =J8/J$26 -> #DIV/0! | L8: =K8+L7 -> #DIV/0! | M8: =_xlfn.IFS(L8<80%,"A",L8<=95%,"B",L8>95%,"C") -> #DIV/0!
B9: th желтый Сул | D9: =C9/C$26 -> #DIV/0! | E9: =D9+E8 -> #DIV/0! | F9: =IF(AND(E9<=0),"C",IF(E9<=0.8,"A",IF(E9<=0.95,"B","C"))) -> #DIV/0! | G9: =VLOOKUP(B$4:B$25,I$4:M$25,5,0) -> #DIV/0! | I9: th желтый Сул | K9: =J9/J$26 -> #DIV/0! | L9: =K9+L8 -> #DIV/0! | M9: =_xlfn.IFS(L9<80%,"A",L9<=95%,"B",L9>95%,"C") -> #DIV/0!
B10: flip желтые Сул | D10: =C10/C$26 -> #DIV/0! | E10: =D10+E9 -> #DIV/0! | F10: =IF(AND(E10<=0),"C",IF(E10<=0.8,"A",IF(E10<=0.95,"B","C"))) -> #DIV/0! | G10: =VLOOKUP(B$4:B$25,I$4:M$25,5,0) -> #DIV/0! | I10: flip желтые Сул | K10: =J10/J$26 -> #DIV/0! | L10: =K10+L9 -> #DIV/0! | M10: =_xlfn.IFS(L10<80%,"A",L10<=95%,"B",L10>95%,"C") -> #DIV/0!
B11: MR8854 C2 | D11: =C11/C$26 -> #DIV/0! | E11: =D11+E8 -> #DIV/0! | F11: =IF(AND(E11<=0),"C",IF(E11<=0.8,"A",IF(E11<=0.95,"B","C"))) -> #DIV/0! | G11: =VLOOKUP(B$4:B$25,I$4:M$25,5,0) -> #DIV/0! | I11: MR8854 C2 | K11: =J11/J$26 -> #DIV/0! | L11: =K11+L8 -> #DIV/0! | M11: =_xlfn.IFS(L11<80%,"A",L11<=95%,"B",L11>95%,"C") -> #DIV/0!
B12: MR 1819 черн | D12: =C12/C$26 -> #DIV/0! | E12: =D12+E11 -> #DIV/0! | F12: =IF(AND(E12<=0),"C",IF(E12<=0.8,"A",IF(E12<=0.95,"B","C"))) -> #DIV/0! | G12: =VLOOKUP(B$4:B$25,I$4:M$25,5,0) -> #DIV/0! | I12: MR 1819 черн | K12: =J12/J$26 -> #DIV/0! | L12: =K12+L11 -> #DIV/0! | M12: =_xlfn.IFS(L12<80%,"A",L12<=95%,"B",L12>95%,"C") -> #DIV/0!
B13: MR 1819 корич | D13: =C13/C$26 -> #DIV/0! | E13: =D13+E12 -> #DIV/0! | F13: =IF(AND(E13<=0),"C",IF(E13<=0.8,"A",IF(E13<=0.95,"B","C"))) -> #DIV/0! | G13: =VLOOKUP(B$4:B$25,I$4:M$25,5,0) -> #DIV/0! | I13: MR 1819 корич | K13: =J13/J$26 -> #DIV/0! | L13: =K13+L12 -> #DIV/0! | M13: =_xlfn.IFS(L13<80%,"A",L13<=95%,"B",L13>95%,"C") -> #DIV/0! | P13: A | Q13: 0.8
B14: MR Р1874 черн | D14: =C14/C$26 -> #DIV/0! | E14: =D14+E13 -> #DIV/0! | F14: =IF(AND(E14<=0),"C",IF(E14<=0.8,"A",IF(E14<=0.95,"B","C"))) -> #DIV/0! | G14: =VLOOKUP(B$4:B$25,I$4:M$25,5,0) -> #DIV/0! | I14: MR Р1874 черн | K14: =J14/J$26 -> #DIV/0! | L14: =K14+L13 -> #DIV/0! | M14: =_xlfn.IFS(L14<80%,"A",L14<=95%,"B",L14>95%,"C") -> #DIV/0! | P14: B | Q14: 0.15
B15: MR Р1874 корич | D15: =C15/C$26 -> #DIV/0! | E15: =D15+E14 -> #DIV/0! | F15: =IF(AND(E15<=0),"C",IF(E15<=0.8,"A",IF(E15<=0.95,"B","C"))) -> #DIV/0! | G15: =VLOOKUP(B$4:B$25,I$4:M$25,5,0) -> #DIV/0! | I15: MR Р1874 корич | K15: =J15/J$26 -> #DIV/0! | L15: =K15+L14 -> #DIV/0! | M15: =_xlfn.IFS(L15<80%,"A",L15<=95%,"B",L15>95%,"C") -> #DIV/0! | P15: C | Q15: 0.05
B16: MR Р1886 черн глянец | D16: =C16/C$26 -> #DIV/0! | E16: =D16+E15 -> #DIV/0! | F16: =IF(AND(E16<=0),"C",IF(E16<=0.8,"A",IF(E16<=0.95,"B","C"))) -> #DIV/0! | G16: =VLOOKUP(B$4:B$25,I$4:M$25,5,0) -> #DIV/0! | I16: MR Р1886 черн глянец | K16: =J16/J$26 -> #DIV/0! | L16: =K16+L15 -> #DIV/0! | M16: =_xlfn.IFS(L16<80%,"A",L16<=95%,"B",L16>95%,"C") -> #DIV/0!
B17: MR Р1886 корич | D17: =C17/C$26 -> #DIV/0! | E17: =D17+E16 -> #DIV/0! | F17: =IF(AND(E17<=0),"C",IF(E17<=0.8,"A",IF(E17<=0.95,"B","C"))) -> #DIV/0! | G17: =VLOOKUP(B$4:B$25,I$4:M$25,5,0) -> #DIV/0! | I17: MR Р1886 корич | K17: =J17/J$26 -> #DIV/0! | L17: =K17+L16 -> #DIV/0! | M17: =_xlfn.IFS(L17<80%,"A",L17<=95%,"B",L17>95%,"C") -> #DIV/0!
B18: lux1 | D18: =C18/C$26 -> #DIV/0! | E18: =D18+E17 -> #DIV/0! | F18: =IF(AND(E18<=0),"C",IF(E18<=0.8,"A",IF(E18<=0.95,"B","C"))) -> #DIV/0! | G18: =VLOOKUP(B$4:B$25,I$4:M$25,5,0) -> #DIV/0! | I18: lux1 | K18: =J18/J$26 -> #DIV/0! | L18: =K18+L17 -> #DIV/0! | M18: =_xlfn.IFS(L18<80%,"A",L18<=95%,"B",L18>95%,"C") -> #DIV/0!
B19: lux2 | D19: =C19/C$26 -> #DIV/0! | E19: =D19+E18 -> #DIV/0! | F19: =IF(AND(E19<=0),"C",IF(E19<=0.8,"A",IF(E19<=0.95,"B","C"))) -> #DIV/0! | G19: =VLOOKUP(B$4:B$25,I$4:M$25,5,0) -> #DIV/0! | I19: lux2 | K19: =J19/J$26 -> #DIV/0! | L19: =K19+L18 -> #DIV/0! | M19: =_xlfn.IFS(L19<80%,"A",L19<=95%,"B",L19>95%,"C") -> #DIV/0!
B20: lux3 | D20: =C20/C$26 -> #DIV/0! | E20: =D20+E19 -> #DIV/0! | F20: =IF(AND(E20<=0),"C",IF(E20<=0.8,"A",IF(E20<=0.95,"B","C"))) -> #DIV/0! | G20: =VLOOKUP(B$4:B$25,I$4:M$25,5,0) -> #DIV/0! | I20: lux3 | K20: =J20/J$26 -> #DIV/0! | L20: =K20+L19 -> #DIV/0! | M20: =_xlfn.IFS(L20<80%,"A",L20<=95%,"B",L20>95%,"C") -> #DIV/0!
B21: lux4 | D21: =C21/C$26 -> #DIV/0! | E21: =D21+E20 -> #DIV/0! | F21: =IF(AND(E21<=0),"C",IF(E21<=0.8,"A",IF(E21<=0.95,"B","C"))) -> #DIV/0! | G21: =VLOOKUP(B$4:B$25,I$4:M$25,5,0) -> #DIV/0! | I21: lux4 | K21: =J21/J$26 -> #DIV/0! | L21: =K21+L20 -> #DIV/0! | M21: =_xlfn.IFS(L21<80%,"A",L21<=95%,"B",L21>95%,"C") -> #DIV/0!
B22: lux5 | D22: =C22/C$26 -> #DIV/0! | E22: =D22+E21 -> #DIV/0! | F22: =IF(AND(E22<=0),"C",IF(E22<=0.8,"A",IF(E22<=0.95,"B","C"))) -> #DIV/0! | G22: =VLOOKUP(B$4:B$25,I$4:M$25,5,0) -> #DIV/0! | I22: lux5 | K22: =J22/J$26 -> #DIV/0! | L22: =K22+L21 -> #DIV/0! | M22: =_xlfn.IFS(L22<80%,"A",L22<=95%,"B",L22>95%,"C") -> #DIV/0!
B23: lux6 | D23: =C23/C$26 -> #DIV/0! | E23: =D23+E22 -> #DIV/0! | F23: =IF(AND(E23<=0),"C",IF(E23<=0.8,"A",IF(E23<=0.95,"B","C"))) -> #DIV/0! | G23: =VLOOKUP(B$4:B$25,I$4:M$25,5,0) -> #DIV/0! | I23: lux6 | K23: =J23/J$26 -> #DIV/0! | L23: =K23+L22 -> #DIV/0! | M23: =_xlfn.IFS(L23<80%,"A",L23<=95%,"B",L23>95%,"C") -> #DIV/0!
B24: lux7 | D24: =C24/C$26 -> #DIV/0! | E24: =D24+E23 -> #DIV/0! | F24: =IF(AND(E24<=0),"C",IF(E24<=0.8,"A",IF(E24<=0.95,"B","C"))) -> #DIV/0! | G24: =VLOOKUP(B$4:B$25,I$4:M$25,5,0) -> #DIV/0! | I24: lux7 | K24: =J24/J$26 -> #DIV/0! | L24: =K24+L23 -> #DIV/0! | M24: =_xlfn.IFS(L24<80%,"A",L24<=95%,"B",L24>95%,"C") -> #DIV/0!
B25: lux8 | D25: =C25/C$26 -> #DIV/0! | E25: =D25+E24 -> #DIV/0! | F25: =IF(AND(E25<=0),"C",IF(E25<=0.8,"A",IF(E25<=0.95,"B","C"))) -> #DIV/0! | G25: =VLOOKUP(B$4:B$25,I$4:M$25,5,0) -> #DIV/0! | I25: lux8 | K25: =J25/J$26 -> #DIV/0! | L25: =K25+L24 -> #DIV/0! | M25: =_xlfn.IFS(L25<80%,"A",L25<=95%,"B",L25>95%,"C") -> #DIV/0!
C26: =SUM(C4:C25) -> 0 | D26: =SUM(D4:D25) -> #DIV/0! | J26: =SUM(J4:J25) -> 0 | K26: =SUM(K4:K25) -> #DIV/0!
B28: ТУНИКИ
C29: Прибыль | D29: % прибыль | E29: Доля | F29: ABC прибыль | G29: ABC кол-во | J29: Кол-во | K29: % кол-во | L29: Доля | M29: ABC кол-во
B30: tunika02 оливковая с руч вышивкой | D30: =C30/C$50 -> #DIV/0! | E30: =D30 -> #DIV/0! | F30: =IF(AND(E30<=0),"C",IF(E30<=0.8,"A",IF(E30<=0.95,"B","C"))) -> #DIV/0! | G30: =VLOOKUP(B$30:B$50,I$30:M$50,5,0) -> #DIV/0! | I30: tunika02 оливковая с руч вышивкой | K30: =J30/J$50 -> #DIV/0! | L30: =K30 -> #DIV/0! | M30: =_xlfn.IFS(L30<80%,"A",L30<=95%,"B",L30>95%,"C") -> #DIV/0!
B31: tunika03 черная распашная | D31: =C31/C$50 -> #DIV/0! | E31: =D31+E30 -> #DIV/0! | F31: =IF(AND(E31<=0),"C",IF(E31<=0.8,"A",IF(E31<=0.95,"B","C"))) -> #DIV/0! | G31: =VLOOKUP(B$30:B$50,I$30:M$50,5,0) -> #DIV/0! | I31: tunika03 черная распашная | K31: =J31/J$50 -> #DIV/0! | L31: =K31+L30 -> #DIV/0! | M31: =_xlfn.IFS(L31<80%,"A",L31<=95%,"B",L31>95%,"C") -> #DIV/0!
B32: tunika05 белая распашная | D32: =C32/C$50 -> #DIV/0! | E32: =D32+E31 -> #DIV/0! | F32: =IF(AND(E32<=0),"C",IF(E32<=0.8,"A",IF(E32<=0.95,"B","C"))) -> #DIV/0! | G32: =VLOOKUP(B$30:B$50,I$30:M$50,5,0) -> #DIV/0! | I32: tunika05 белая распашная | K32: =J32/J$50 -> #DIV/0! | L32: =K32+L31 -> #DIV/0! | M32: =_xlfn.IFS(L32<80%,"A",L32<=95%,"B",L32>95%,"C") -> #DIV/0!
B33: tunika06 белая | D33: =C33/C$50 -> #DIV/0! | E33: =D33+E32 -> #DIV/0! | F33: =IF(AND(E33<=0),"C",IF(E33<=0.8,"A",IF(E33<=0.95,"B","C"))) -> #DIV/0! | G33: =VLOOKUP(B$30:B$50,I$30:M$50,5,0) -> #DIV/0! | I33: tunika06 белая | K33: =J33/J$50 -> #DIV/0! | L33: =K33+L32 -> #DIV/0! | M33: =_xlfn.IFS(L33<80%,"A",L33<=95%,"B",L33>95%,"C") -> #DIV/0!
B34: tunika06 черная | D34: =C34/C$50 -> #DIV/0! | E34: =D34+E33 -> #DIV/0! | F34: =IF(AND(E34<=0),"C",IF(E34<=0.8,"A",IF(E34<=0.95,"B","C"))) -> #DIV/0! | G34: =VLOOKUP(B$30:B$50,I$30:M$50,5,0) -> #DIV/0! | I34: tunika06 черная | K34: =J34/J$50 -> #DIV/0! | L34: =K34+L33 -> #DIV/0! | M34: =_xlfn.IFS(L34<80%,"A",L34<=95%,"B",L34>95%,"C") -> #DIV/0!
B35: tunika07 кружево | D35: =C35/C$50 -> #DIV/0! | E35: =D35+E34 -> #DIV/0! | F35: =IF(AND(E35<=0),"C",IF(E35<=0.8,"A",IF(E35<=0.95,"B","C"))) -> #DIV/0! | G35: =VLOOKUP(B$30:B$50,I$30:M$50,5,0) -> #DIV/0! | I35: tunika07 кружево | K35: =J35/J$50 -> #DIV/0! | L35: =K35+L34 -> #DIV/0! | M35: =_xlfn.IFS(L35<80%,"A",L35<=95%,"B",L35>95%,"C") -> #DIV/0!
B36: tunika08 белая | D36: =C36/C$50 -> #DIV/0! | E36: =D36+E35 -> #DIV/0! | F36: =IF(AND(E36<=0),"C",IF(E36<=0.8,"A",IF(E36<=0.95,"B","C"))) -> #DIV/0! | G36: =VLOOKUP(B$30:B$50,I$30:M$50,5,0) -> #DIV/0! | I36: tunika08 белая | K36: =J36/J$50 -> #DIV/0! | L36: =K36+L35 -> #DIV/0! | M36: =_xlfn.IFS(L36<80%,"A",L36<=95%,"B",L36>95%,"C") -> #DIV/0!
B37: tunika08 черная | D37: =C37/C$50 -> #DIV/0! | E37: =D37+E36 -> #DIV/0! | F37: =IF(AND(E37<=0),"C",IF(E37<=0.8,"A",IF(E37<=0.95,"B","C"))) -> #DIV/0! | G37: =VLOOKUP(B$30:B$50,I$30:M$50,5,0) -> #DIV/0! | I37: tunika08 черная | K37: =J37/J$50 -> #DIV/0! | L37: =K37+L36 -> #DIV/0! | M37: =_xlfn.IFS(L37<80%,"A",L37<=95%,"B",L37>95%,"C") -> #DIV/0!
B38: tunika08 зеленая | D38: =C38/C$50 -> #DIV/0! | E38: =D38+E37 -> #DIV/0! | F38: =IF(AND(E38<=0),"C",IF(E38<=0.8,"A",IF(E38<=0.95,"B","C"))) -> #DIV/0! | G38: =VLOOKUP(B$30:B$50,I$30:M$50,5,0) -> #DIV/0! | I38: tunika08 зеленая | K38: =J38/J$50 -> #DIV/0! | L38: =K38+L37 -> #DIV/0! | M38: =_xlfn.IFS(L38<80%,"A",L38<=95%,"B",L38>95%,"C") -> #DIV/0!
B39: tunika09 кимоно | D39: =C39/C$50 -> #DIV/0! | E39: =D39+E38 -> #DIV/0! | F39: =IF(AND(E39<=0),"C",IF(E39<=0.8,"A",IF(E39<=0.95,"B","C"))) -> #DIV/0! | G39: =VLOOKUP(B$30:B$50,I$30:M$50,5,0) -> #DIV/0! | I39: tunika09 кимоно | K39: =J39/J$50 -> #DIV/0! | L39: =K39+L38 -> #DIV/0! | M39: =_xlfn.IFS(L39<80%,"A",L39<=95%,"B",L39>95%,"C") -> #DIV/0!
B40: tunika10 кимоно ч/б | D40: =C40/C$50 -> #DIV/0! | E40: =D40+E39 -> #DIV/0! | F40: =IF(AND(E40<=0),"C",IF(E40<=0.8,"A",IF(E40<=0.95,"B","C"))) -> #DIV/0! | G40: =VLOOKUP(B$30:B$50,I$30:M$50,5,0) -> #DIV/0! | I40: tunika10 кимоно ч/б | K40: =J40/J$50 -> #DIV/0! | L40: =K40+L39 -> #DIV/0! | M40: =_xlfn.IFS(L40<80%,"A",L40<=95%,"B",L40>95%,"C") -> #DIV/0!
B41: tunika11 халат зеленая | D41: =C41/C$50 -> #DIV/0! | E41: =D41+E40 -> #DIV/0! | F41: =IF(AND(E41<=0),"C",IF(E41<=0.8,"A",IF(E41<=0.95,"B","C"))) -> #DIV/0! | G41: =VLOOKUP(B$30:B$50,I$30:M$50,5,0) -> #DIV/0! | I41: tunika11 халат зеленая | K41: =J41/J$50 -> #DIV/0! | L41: =K41+L40 -> #DIV/0! | M41: =_xlfn.IFS(L41<80%,"A",L41<=95%,"B",L41>95%,"C") -> #DIV/0!
B42: tunika12 халат белая | D42: =C42/C$50 -> #DIV/0! | E42: =D42+E41 -> #DIV/0! | F42: =IF(AND(E42<=0),"C",IF(E42<=0.8,"A",IF(E42<=0.95,"B","C"))) -> #DIV/0! | G42: =VLOOKUP(B$30:B$50,I$30:M$50,5,0) -> #DIV/0! | I42: tunika12 халат белая | K42: =J42/J$50 -> #DIV/0! | L42: =K42+L41 -> #DIV/0! | M42: =_xlfn.IFS(L42<80%,"A",L42<=95%,"B",L42>95%,"C") -> #DIV/0!
...

Sheet АВС 19-25.01
B2: ОЧКИ
C3: Прибыль | D3: % прибыль | E3: Доля | F3: ABC прибыль | G3: ABC кол-во | J3: Кол-во | K3: % кол-во | L3: Доля | M3: ABC кол-во
B4: черные с железкой классика | C4: ='Юнит 19-25.01'!AE3 -> 5864.4518 | D4: =C4/C$26 -> 0.58621262 | E4: =D4 -> 0.58621262 | F4: =IF(AND(E4<=0),"C",IF(E4<=0.8,"A",IF(E4<=0.95,"B","C"))) -> A | G4: =VLOOKUP(B$4:B$25,I$4:M$25,5,0) -> A | I4: черные с железкой классика | J4: ='Юнит 19-25.01'!R3 -> 38 | K4: =J4/J$26 -> 0.6031746 | L4: =K4 -> 0.6031746 | M4: =_xlfn.IFS(L4<80%,"A",L4<=95%,"B",L4>95%,"C") -> A
B5: qs коричневые | C5: ='Юнит 19-25.01'!AE7 -> 2637.98 | D5: =C5/C$26 -> 0.26369339 | E5: =D5+E4 -> 0.84990601 | F5: =IF(AND(E5<=0),"C",IF(E5<=0.8,"A",IF(E5<=0.95,"B","C"))) -> B | G5: =VLOOKUP(B$4:B$25,I$4:M$25,5,0) -> A | I5: qs коричневые | J5: ='Юнит 19-25.01'!R7 -> 6 | K5: =J5/J$26 -> 0.095238095 | L5: =K5+L4 -> 0.6984127 | M5: =_xlfn.IFS(L5<80%,"A",L5<=95%,"B",L5>95%,"C") -> A
B6: lux3 | C6: ='Юнит 19-25.01'!AE19 -> 914.65 | D6: =C6/C$26 -> 0.091428728 | E6: =D6+E5 -> 0.94133474 | F6: =IF(AND(E6<=0),"C",IF(E6<=0.8,"A",IF(E6<=0.95,"B","C"))) -> B | G6: =VLOOKUP(B$4:B$25,I$4:M$25,5,0) -> C | I6: qs черные | J6: ='Юнит 19-25.01'!R4 -> 5 | K6: =J6/J$26 -> 0.079365079 | L6: =K6+L5 -> 0.77777778 | M6: =_xlfn.IFS(L6<80%,"A",L6<=95%,"B",L6>95%,"C") -> A
B7: th желтый Сул | C7: ='Юнит 19-25.01'!AE8 -> 606.7 | D7: =C7/C$26 -> 0.060645941 | E7: =D7+E6 -> 1.0019807 | F7: =IF(AND(E7<=0),"C",IF(E7<=0.8,"A",IF(E7<=0.95,"B","C"))) -> C | G7: =VLOOKUP(B$4:B$25,I$4:M$25,5,0) -> C | I7: flip желтые Сул | J7: ='Юнит 19-25.01'!R9 -> 5 | K7: =J7/J$26 -> 0.079365079 | L7: =K7+L6 -> 0.85714286 | M7: =_xlfn.IFS(L7<80%,"A",L7<=95%,"B",L7>95%,"C") -> B
B8: MR Р1874 корич | C8: ='Юнит 19-25.01'!AE14 -> 490.89 | D8: =C8/C$26 -> 0.049069533 | E8: =D8+E7 -> 1.0510502 | F8: =IF(AND(E8<=0),"C",IF(E8<=0.8,"A",IF(E8<=0.95,"B","C"))) -> C | G8: =VLOOKUP(B$4:B$25,I$4:M$25,5,0) -> B | I8: MR Р1874 черн | J8: ='Юнит 19-25.01'!R13 -> 3 | K8: =J8/J$26 -> 0.047619048 | L8: =K8+L7 -> 0.9047619 | M8: =_xlfn.IFS(L8<80%,"A",L8<=95%,"B",L8>95%,"C") -> B
B9: MR 1819 корич | C9: ='Юнит 19-25.01'!AE12 -> 322.02 | D9: =C9/C$26 -> 0.03218923 | E9: =D9+E8 -> 1.0832394 | F9: =IF(AND(E9<=0),"C",IF(E9<=0.8,"A",IF(E9<=0.95,"B","C"))) -> C | G9: =VLOOKUP(B$4:B$25,I$4:M$25,5,0) -> B | I9: qs желтые | J9: ='Юнит 19-25.01'!R6 -> 2 | K9: =J9/J$26 -> 0.031746032 | L9: =K9+L8 -> 0.93650794 | M9: =_xlfn.IFS(L9<80%,"A",L9<=95%,"B",L9>95%,"C") -> B
B10: MR Р1874 черн | C10: ='Юнит 19-25.01'!AE13 -> 420.19 | D10: =C10/C$26 -> 0.042002337 | E10: =D10+E9 -> 1.1252418 | F10: =IF(AND(E10<=0),"C",IF(E10<=0.8,"A",IF(E10<=0.95,"B","C"))) -> C | G10: =VLOOKUP(B$4:B$25,I$4:M$25,5,0) -> B | I10: th желтый Сул | J10: ='Юнит 19-25.01'!R8 -> 1 | K10: =J10/J$26 -> 0.015873016 | L10: =K10+L9 -> 0.95238095 | M10: =_xlfn.IFS(L10<80%,"A",L10<=95%,"B",L10>95%,"C") -> C
B11: qs черные | C11: ='Юнит 19-25.01'!AE4 -> 591.94117 | D11: =C11/C$26 -> 0.059170643 | E11: =D11+E8 -> 1.1102209 | F11: =IF(AND(E11<=0),"C",IF(E11<=0.8,"A",IF(E11<=0.95,"B","C"))) -> C | G11: =VLOOKUP(B$4:B$25,I$4:M$25,5,0) -> A | I11: MR 1819 корич | J11: ='Юнит 19-25.01'!R12 -> 1 | K11: =J11/J$26 -> 0.015873016 | L11: =K11+L8 -> 0.92063492 | M11: =_xlfn.IFS(L11<80%,"A",L11<=95%,"B",L11>95%,"C") -> B
B12: qs синие | C12: ='Юнит 19-25.01'!AE5 -> 0 | D12: =C12/C$26 -> 0 | E12: =D12+E11 -> 1.1102209 | F12: =IF(AND(E12<=0),"C",IF(E12<=0.8,"A",IF(E12<=0.95,"B","C"))) -> C | G12: =VLOOKUP(B$4:B$25,I$4:M$25,5,0) -> C | I12: MR Р1874 корич | J12: ='Юнит 19-25.01'!R14 -> 1 | K12: =J12/J$26 -> 0.015873016 | L12: =K12+L11 -> 0.93650794 | M12: =_xlfn.IFS(L12<80%,"A",L12<=95%,"B",L12>95%,"C") -> B
B13: lux1 | C13: ='Юнит 19-25.01'!AE17 -> 0 | D13: =C13/C$26 -> 0 | E13: =D13+E12 -> 1.1102209 | F13: =IF(AND(E13<=0),"C",IF(E13<=0.8,"A",IF(E13<=0.95,"B","C"))) -> C | G13: =VLOOKUP(B$4:B$25,I$4:M$25,5,0) -> C | I13: lux3 | J13: ='Юнит 19-25.01'!R19 -> 1 | K13: =J13/J$26 -> 0.015873016 | L13: =K13+L12 -> 0.95238095 | M13: =_xlfn.IFS(L13<80%,"A",L13<=95%,"B",L13>95%,"C") -> C | P13: A | Q13: 0.8
B14: lux2 | C14: ='Юнит 19-25.01'!AE18 -> 0 | D14: =C14/C$26 -> 0 | E14: =D14+E13 -> 1.1102209 | F14: =IF(AND(E14<=0),"C",IF(E14<=0.8,"A",IF(E14<=0.95,"B","C"))) -> C | G14: =VLOOKUP(B$4:B$25,I$4:M$25,5,0) -> C | I14: qs синие | J14: ='Юнит 19-25.01'!R5 -> 0 | K14: =J14/J$26 -> 0 | L14: =K14+L13 -> 0.95238095 | M14: =_xlfn.IFS(L14<80%,"A",L14<=95%,"B",L14>95%,"C") -> C | P14: B | Q14: 0.15
B15: lux4 | C15: ='Юнит 19-25.01'!AE20 -> 0 | D15: =C15/C$26 -> 0 | E15: =D15+E14 -> 1.1102209 | F15: =IF(AND(E15<=0),"C",IF(E15<=0.8,"A",IF(E15<=0.95,"B","C"))) -> C | G15: =VLOOKUP(B$4:B$25,I$4:M$25,5,0) -> C | I15: MR8854 C2 | J15: ='Юнит 19-25.01'!R10 -> 0 | K15: =J15/J$26 -> 0 | L15: =K15+L14 -> 0.95238095 | M15: =_xlfn.IFS(L15<80%,"A",L15<=95%,"B",L15>95%,"C") -> C | P15: C | Q15: 0.05
B16: lux5 | C16: ='Юнит 19-25.01'!AE21 -> 0 | D16: =C16/C$26 -> 0 | E16: =D16+E15 -> 1.1102209 | F16: =IF(AND(E16<=0),"C",IF(E16<=0.8,"A",IF(E16<=0.95,"B","C"))) -> C | G16: =VLOOKUP(B$4:B$25,I$4:M$25,5,0) -> C | I16: MR 1819 черн | J16: ='Юнит 19-25.01'!R11 -> 0 | K16: =J16/J$26 -> 0 | L16: =K16+L15 -> 0.95238095 | M16: =_xlfn.IFS(L16<80%,"A",L16<=95%,"B",L16>95%,"C") -> C
B17: lux6 | C17: ='Юнит 19-25.01'!AE22 -> 0 | D17: =C17/C$26 -> 0 | E17: =D17+E16 -> 1.1102209 | F17: =IF(AND(E17<=0),"C",IF(E17<=0.8,"A",IF(E17<=0.95,"B","C"))) -> C | G17: =VLOOKUP(B$4:B$25,I$4:M$25,5,0) -> C | I17: MR Р1886 черн глянец | J17: ='Юнит 19-25.01'!R15 -> 0 | K17: =J17/J$26 -> 0 | L17: =K17+L16 -> 0.95238095 | M17: =_xlfn.IFS(L17<80%,"A",L17<=95%,"B",L17>95%,"C") -> C
B18: lux7 | C18: ='Юнит 19-25.01'!AE23 -> 0 | D18: =C18/C$26 -> 0 | E18: =D18+E17 -> 1.1102209 | F18: =IF(AND(E18<=0),"C",IF(E18<=0.8,"A",IF(E18<=0.95,"B","C"))) -> C | G18: =VLOOKUP(B$4:B$25,I$4:M$25,5,0) -> C | I18: MR Р1886 корич | J18: ='Юнит 19-25.01'!R16 -> 0 | K18: =J18/J$26 -> 0 | L18: =K18+L17 -> 0.95238095 | M18: =_xlfn.IFS(L18<80%,"A",L18<=95%,"B",L18>95%,"C") -> C
B19: lux8 | C19: ='Юнит 19-25.01'!AE24 -> 0 | D19: =C19/C$26 -> 0 | E19: =D19+E18 -> 1.1102209 | F19: =IF(AND(E19<=0),"C",IF(E19<=0.8,"A",IF(E19<=0.95,"B","C"))) -> C | G19: =VLOOKUP(B$4:B$25,I$4:M$25,5,0) -> C | I19: lux1 | J19: ='Юнит 19-25.01'!R17 -> 0 | K19: =J19/J$26 -> 0 | L19: =K19+L18 -> 0.95238095 | M19: =_xlfn.IFS(L19<80%,"A",L19<=95%,"B",L19>95%,"C") -> C
B20: MR8854 C2 | C20: ='Юнит 19-25.01'!AE10 -> -93.54 | D20: =C20/C$26 -> -0.0093502906 | E20: =D20+E19 -> 1.1008706 | F20: =IF(AND(E20<=0),"C",IF(E20<=0.8,"A",IF(E20<=0.95,"B","C"))) -> C | G20: =VLOOKUP(B$4:B$25,I$4:M$25,5,0) -> C | I20: lux2 | J20: ='Юнит 19-25.01'!R18 -> 0 | K20: =J20/J$26 -> 0 | L20: =K20+L19 -> 0.95238095 | M20: =_xlfn.IFS(L20<80%,"A",L20<=95%,"B",L20>95%,"C") -> C
B21: MR 1819 черн | C21: ='Юнит 19-25.01'!AE11 -> -93.54 | D21: =C21/C$26 -> -0.0093502906 | E21: =D21+E20 -> 1.0915203 | F21: =IF(AND(E21<=0),"C",IF(E21<=0.8,"A",IF(E21<=0.95,"B","C"))) -> C | G21: =VLOOKUP(B$4:B$25,I$4:M$25,5,0) -> C | I21: lux4 | J21: ='Юнит 19-25.01'!R20 -> 0 | K21: =J21/J$26 -> 0 | L21: =K21+L20 -> 0.95238095 | M21: =_xlfn.IFS(L21<80%,"A",L21<=95%,"B",L21>95%,"C") -> C
B22: MR Р1886 черн глянец | C22: ='Юнит 19-25.01'!AE15 -> -93.54 | D22: =C22/C$26 -> -0.0093502906 | E22: =D22+E21 -> 1.08217 | F22: =IF(AND(E22<=0),"C",IF(E22<=0.8,"A",IF(E22<=0.95,"B","C"))) -> C | G22: =VLOOKUP(B$4:B$25,I$4:M$25,5,0) -> C | I22: lux5 | J22: ='Юнит 19-25.01'!R21 -> 0 | K22: =J22/J$26 -> 0 | L22: =K22+L21 -> 0.95238095 | M22: =_xlfn.IFS(L22<80%,"A",L22<=95%,"B",L22>95%,"C") -> C
B23: MR Р1886 корич | C23: ='Юнит 19-25.01'!AE16 -> -328.67 | D23: =C23/C$26 -> -0.032853966 | E23: =D23+E22 -> 1.049316 | F23: =IF(AND(E23<=0),"C",IF(E23<=0.8,"A",IF(E23<=0.95,"B","C"))) -> C | G23: =VLOOKUP(B$4:B$25,I$4:M$25,5,0) -> C | I23: lux6 | J23: ='Юнит 19-25.01'!R22 -> 0 | K23: =J23/J$26 -> 0 | L23: =K23+L22 -> 0.95238095 | M23: =_xlfn.IFS(L23<80%,"A",L23<=95%,"B",L23>95%,"C") -> C
B24: flip желтые Сул | C24: ='Юнит 19-25.01'!AE9 -> 72.94261 | D24: =C24/C$26 -> 0.0072913684 | E24: =D24+E23 -> 1.0566074 | F24: =IF(AND(E24<=0),"C",IF(E24<=0.8,"A",IF(E24<=0.95,"B","C"))) -> C | G24: =VLOOKUP(B$4:B$25,I$4:M$25,5,0) -> B | I24: lux7 | J24: ='Юнит 19-25.01'!R23 -> 0 | K24: =J24/J$26 -> 0 | L24: =K24+L23 -> 0.95238095 | M24: =_xlfn.IFS(L24<80%,"A",L24<=95%,"B",L24>95%,"C") -> C
B25: qs желтые | C25: ='Юнит 19-25.01'!AE6 -> -1308.5084 | D25: =C25/C$26 -> -0.13079895 | E25: =D25+E24 -> 0.92580843 | F25: =IF(AND(E25<=0),"C",IF(E25<=0.8,"A",IF(E25<=0.95,"B","C"))) -> B | G25: =VLOOKUP(B$4:B$25,I$4:M$25,5,0) -> B | I25: lux8 | J25: ='Юнит 19-25.01'!R24 -> 0 | K25: =J25/J$26 -> 0 | L25: =K25+L24 -> 0.95238095 | M25: =_xlfn.IFS(L25<80%,"A",L25<=95%,"B",L25>95%,"C") -> C
C26: =SUM(C4:C25) -> 10003.967 | D26: =SUM(D4:D25) -> 1 | J26: =SUM(J4:J25) -> 63 | K26: =SUM(K4:K25) -> 1
B28: ТУНИКИ
C29: Прибыль | D29: % прибыль | E29: Доля | F29: ABC прибыль | G29: ABC кол-во | J29: Кол-во | K29: % кол-во | L29: Доля | M29: ABC кол-во
B30: tunika15 кимоно песочная | C30: ='Юнит 19-25.01'!AE45 -> 6439.7034 | D30: =C30/C$50 -> 1.6022372 | E30: =D30 -> 1.6022372 | F30: =IF(AND(E30<=0),"C",IF(E30<=0.8,"A",IF(E30<=0.95,"B","C"))) -> C | G30: =VLOOKUP(B$30:B$50,I$30:M$50,5,0) -> A | I30: tunika15 кимоно песочная | J30: ='Юнит 19-25.01'!R45 -> 8 | K30: =J30/J$50 -> 0.57142857 | L30: =K30 -> 0.57142857 | M30: =_xlfn.IFS(L30<80%,"A",L30<=95%,"B",L30>95%,"C") -> A
B31: tunika09 кимоно | C31: ='Юнит 19-25.01'!AE37 -> 2688.14 | D31: =C31/C$50 -> 0.6688255 | E31: =D31+E30 -> 2.2710627 | F31: =IF(AND(E31<=0),"C",IF(E31<=0.8,"A",IF(E31<=0.95,"B","C"))) -> C | G31: =VLOOKUP(B$30:B$50,I$30:M$50,5,0) -> B | I31: tunika15 кимоно бирюза | J31: ='Юнит 19-25.01'!R44 -> 3 | K31: =J31/J$50 -> 0.21428571 | L31: =K31+L30 -> 0.78571429 | M31: =_xlfn.IFS(L31<80%,"A",L31<=95%,"B",L31>95%,"C") -> A
B32: tunika06 белая | C32: ='Юнит 19-25.01'!AE31 -> 1234.21 | D32: =C32/C$50 -> 0.30707892 | E32: =D32+E31 -> 2.5781416 | F32: =IF(AND(E32<=0),"C",IF(E32<=0.8,"A",IF(E32<=0.95,"B","C"))) -> C | G32: =VLOOKUP(B$30:B$50,I$30:M$50,5,0) -> C | I32: tunika09 кимоно | J32: ='Юнит 19-25.01'!R37 -> 2 | K32: =J32/J$50 -> 0.14285714 | L32: =K32+L31 -> 0.92857143 | M32: =_xlfn.IFS(L32<80%,"A",L32<=95%,"B",L32>95%,"C") -> B
B33: tunika07 кружево | C33: ='Юнит 19-25.01'!AE33 -> 848.44 | D33: =C33/C$50 -> 0.21109701 | E33: =D33+E32 -> 2.7892386 | F33: =IF(AND(E33<=0),"C",IF(E33<=0.8,"A",IF(E33<=0.95,"B","C"))) -> C | G33: =VLOOKUP(B$30:B$50,I$30:M$50,5,0) -> C | I33: tunika06 белая | J33: ='Юнит 19-25.01'!R31 -> 1 | K33: =J33/J$50 -> 0.071428571 | L33: =K33+L32 -> 1 | M33: =_xlfn.IFS(L33<80%,"A",L33<=95%,"B",L33>95%,"C") -> C
B34: tunika03 черная распашная | C34: ='Юнит 19-25.01'!AE29 -> 0 | D34: =C34/C$50 -> 0 | E34: =D34+E33 -> 2.7892386 | F34: =IF(AND(E34<=0),"C",IF(E34<=0.8,"A",IF(E34<=0.95,"B","C"))) -> C | G34: =VLOOKUP(B$30:B$50,I$30:M$50,5,0) -> C | I34: tunika07 кружево | J34: ='Юнит 19-25.01'!R33 -> 1 | K34: =J34/J$50 -> 0.071428571 | L34: =K34+L33 -> 1.0714286 | M34: =_xlfn.IFS(L34<80%,"A",L34<=95%,"B",L34>95%,"C") -> C
B35: tunika05 белая распашная | C35: ='Юнит 19-25.01'!AE30 -> 0 | D35: =C35/C$50 -> 0 | E35: =D35+E34 -> 2.7892386 | F35: =IF(AND(E35<=0),"C",IF(E35<=0.8,"A",IF(E35<=0.95,"B","C"))) -> C | G35: =VLOOKUP(B$30:B$50,I$30:M$50,5,0) -> C | I35: tunika02 оливковая с руч вышивкой | J35: ='Юнит 19-25.01'!R28 -> 0 | K35: =J35/J$50 -> 0 | L35: =K35+L34 -> 1.0714286 | M35: =_xlfn.IFS(L35<80%,"A",L35<=95%,"B",L35>95%,"C") -> C
B36: tunika06 черная | C36: ='Юнит 19-25.01'!AE32 -> 0 | D36: =C36/C$50 -> 0 | E36: =D36+E35 -> 2.7892386 | F36: =IF(AND(E36<=0),"C",IF(E36<=0.8,"A",IF(E36<=0.95,"B","C"))) -> C | G36: =VLOOKUP(B$30:B$50,I$30:M$50,5,0) -> C | I36: tunika03 черная распашная | J36: ='Юнит 19-25.01'!R29 -> 0 | K36: =J36/J$50 -> 0 | L36: =K36+L35 -> 1.0714286 | M36: =_xlfn.IFS(L36<80%,"A",L36<=95%,"B",L36>95%,"C") -> C
B37: tunika08 белая | C37: ='Юнит 19-25.01'!AE34 -> 0 | D37: =C37/C$50 -> 0 | E37: =D37+E36 -> 2.7892386 | F37: =IF(AND(E37<=0),"C",IF(E37<=0.8,"A",IF(E37<=0.95,"B","C"))) -> C | G37: =VLOOKUP(B$30:B$50,I$30:M$50,5,0) -> C | I37: tunika05 белая распашная | J37: ='Юнит 19-25.01'!R30 -> 0 | K37: =J37/J$50 -> 0 | L37: =K37+L36 -> 1.0714286 | M37: =_xlfn.IFS(L37<80%,"A",L37<=95%,"B",L37>95%,"C") -> C
B38: tunika08 черная | C38: ='Юнит 19-25.01'!AE35 -> 0 | D38: =C38/C$50 -> 0 | E38: =D38+E37 -> 2.7892386 | F38: =IF(AND(E38<=0),"C",IF(E38<=0.8,"A",IF(E38<=0.95,"B","C"))) -> C | G38: =VLOOKUP(B$30:B$50,I$30:M$50,5,0) -> C | I38: tunika06 черная | J38: ='Юнит 19-25.01'!R32 -> 0 | K38: =J38/J$50 -> 0 | L38: =K38+L37 -> 1.0714286 | M38: =_xlfn.IFS(L38<80%,"A",L38<=95%,"B",L38>95%,"C") -> C
B39: tunika11 халат зеленая | C39: ='Юнит 19-25.01'!AE39 -> 0 | D39: =C39/C$50 -> 0 | E39: =D39+E38 -> 2.7892386 | F39: =IF(AND(E39<=0),"C",IF(E39<=0.8,"A",IF(E39<=0.95,"B","C"))) -> C | G39: =VLOOKUP(B$30:B$50,I$30:M$50,5,0) -> C | I39: tunika08 белая | J39: ='Юнит 19-25.01'!R34 -> 0 | K39: =J39/J$50 -> 0 | L39: =K39+L38 -> 1.0714286 | M39: =_xlfn.IFS(L39<80%,"A",L39<=95%,"B",L39>95%,"C") -> C
B40: tunika12 халат белая | C40: ='Юнит 19-25.01'!AE40 -> 0 | D40: =C40/C$50 -> 0 | E40: =D40+E39 -> 2.7892386 | F40: =IF(AND(E40<=0),"C",IF(E40<=0.8,"A",IF(E40<=0.95,"B","C"))) -> C | G40: =VLOOKUP(B$30:B$50,I$30:M$50,5,0) -> C | I40: tunika08 черная | J40: ='Юнит 19-25.01'!R35 -> 0 | K40: =J40/J$50 -> 0 | L40: =K40+L39 -> 1.0714286 | M40: =_xlfn.IFS(L40<80%,"A",L40<=95%,"B",L40>95%,"C") -> C
B41: tunika13 халат черная | C41: ='Юнит 19-25.01'!AE41 -> 0 | D41: =C41/C$50 -> 0 | E41: =D41+E40 -> 2.7892386 | F41: =IF(AND(E41<=0),"C",IF(E41<=0.8,"A",IF(E41<=0.95,"B","C"))) -> C | G41: =VLOOKUP(B$30:B$50,I$30:M$50,5,0) -> C | I41: tunika08 зеленая | J41: ='Юнит 19-25.01'!R36 -> 0 | K41: =J41/J$50 -> 0 | L41: =K41+L40 -> 1.0714286 | M41: =_xlfn.IFS(L41<80%,"A",L41<=95%,"B",L41>95%,"C") -> C
B42: tunika14 халат с разрезами белая | C42: ='Юнит 19-25.01'!AE42 -> 0 | D42: =C42/C$50 -> 0 | E42: =D42+E41 -> 2.7892386 | F42: =IF(AND(E42<=0),"C",IF(E42<=0.8,"A",IF(E42<=0.95,"B","C"))) -> C | G42: =VLOOKUP(B$30:B$50,I$30:M$50,5,0) -> C | I42: tunika11 халат зеленая | J42: ='Юнит 19-25.01'!R39 -> 0 | K42: =J42/J$50 -> 0 | L42: =K42+L41 -> 1.0714286 | M42: =_xlfn.IFS(L42<80%,"A",L42<=95%,"B",L42>95%,"C") -> C
...

Sheet АВС 12-18.01
B2: ОЧКИ
C3: Прибыль | D3: % прибыль | E3: Доля | F3: ABC прибыль | G3: ABC кол-во | J3: Кол-во | K3: % кол-во | L3: Доля | M3: ABC кол-во
