Workbook

Sheet Реклама
B2: ПЕРИОД | C2: БАЛАНС | F2: СЧЕТ | I2: Неделя
C3: Номер документа | D3: Сумма | E3: Даты | F3: Номер документа | G3: Сумма | H3: Даты
B4: 01-04.01 | F4: 277607349 | G4: 4738 | H4: 01-04.01 | I4: 1
B5: 04-11.01 | F5: 279228154 | G5: 6535 | H5: 04-11.01 | I5: 2
B6: 11-18.01 | C6: 280305485 | D6: 2922 | E6: 14-18.01 | F6: 280297200 | G6: 3464 | H6: 11-17.01 | I6: 3
B7: 18-25.01 | C7: 281290485 | D7: 5916 | E7: 18-23.01 | F7: 281290488 | G7: 2033 | H7: 18-25.01 | I7: 4
B8: 25.01-01.02 | C8: 282283796 | D8: 12613 | E8: 27-31.01 | F8: 282343451 | G8: 9553 | H8: 25-31.01 | I8: 5
C9: 282375547 | D9: 1000 | E9: 01.02 | F9: 282385566 | G9: 79 | H9: 01.02
B10: 01-08.02 | C10: 283356234 | D10: 9526 | E10: 01-04.02 | F10: 283392061 | G10: 17308 | H10: 01-08.02 | I10: 6
B11: 08-15.02 | C11: 284419876 | D11: 16968 | E11: 09-12.02 | F11: 284354982 | G11: 25029 | H11: 08-15.02 | I11: 7
B12: 15-22.02 | C12: 285375130 | D12: 19000 | E12: 16-21.02 | F12: 285375131 | G12: 43359 | H12: 16-22.02 | I12: 8
B13: 22.02-01.03 | C13: 286365345 | D13: 20188 | E13: 23-28.02 | F13: 286438626 | G13: 41519 | H13: 22-28.02 | I13: 9
F14: 286502032 | G14: 8252 | H14: 01.03
B15: 01-08.03 | C15: 287719816 | D15: 55356 | E15: 01.03-08.03 | F15: 287759820 | G15: 14284 | H15: 01.03-05.03 | I15: 10
B16: 08-15.03 | C16: 288712526 | D16: 117662 | E16: 08-15.03 | I16: 11
B17: 15-22.03 | C17: 289759802 | D17: 121051 | E17: 15-22.03 | I17: 12
B18: 22-29.03 | I18: 13
H33: .

Sheet Сводная
B2: Период | E2: Дата поступления дс | F2: Итого к перечислению на счет, руб | G2: шт. | J2: ВБ реализовал товар (выручка с СПП) | M2: Выручка до вычета комиссии ВБ | P2: Себестоимость продаж | Q2: Логистика WB | R2: Комиссия WB | S2: Хранение WB | T2: Платная приемка WB | U2: Штрафы WB | V2: Прочие удержания WB | W2: Реклама БАЛАНС | X2: Реклама СЧЕТ | Y2: Блогеры | Z2: Налог | AA2: Прочие поступления WB | AB2: Прибыль до вычета налогов | AC2: Прибыль после вычета налогов | AD2: Итог месяц | AE2: % Cебестоимости | AF2: Маржинальность, % | AG2: Рентабельность, % | AH2: Доля рекламы, %
B3: Месяц | C3: Даты | D3: Нед | G3: Заказы | H3: Продажи | I3: Возвраты | J3: Продажи | K3: Возвраты | L3: Общая | M3: Продажи | N3: Возвраты | O3: Общая
B4: Январь 1 | C4: 29.12-04.01 | D4: 1 | F4: =IFERROR(O4-SUM(Q4:W4)+AA4,0) -> 29279.64 | G4: ='Юнит 1'!L$17 -> 66 | H4: ='Юнит 1'!Q$17 -> 45 | I4: ='Юнит 1'!R$17 -> 0 | J4: ='Юнит 1'!T$74 -> 46145.63 | K4: ='Юнит 1'!U$74 -> 0 | L4: =IFERROR(J4+K4,0) -> 46145.63 | M4: ='Юнит 1'!W$74 -> 54988.62 | N4: ='Юнит 1'!X$74 -> 0 | O4: =IFERROR(M4+N4,0) -> 54988.62 | P4: ='Юнит 1'!AB$74 -> 5712.21 | Q4: ='Юнит 1'!AE$74 -> 4543.05 | R4: ='Юнит 1'!AC$74 -> 19854.22 | S4: ='Юнит 1'!AI$74 -> 1049.63 | U4: ='Юнит 1'!AJ$74 -> 0 | V4: 262.08 | W4: ='Юнит 1'!AF$74 -> 0 | X4: ='Юнит 1'!AG$74 -> 4738 | Y4: ='Юнит 1'!AH84 -> 0 | Z4: 457.89 | AB4: =O4-SUM(P4:Y4)+AA4 -> 18829.43 | AC4: =O4-SUM(P4:Z4)+AA4 -> 18371.54 | AD4: =SUM(AC4:AC8) -> 67154.08 | AE4: =P4/O4 -> 0.10387986 | AF4: =AC4/P4 -> 3.2161878 | AG4: =AC4/O4 -> 0.33409713 | AH4: =(W4+X4+Y4)/O4 -> 0.086163283
B5: Январь 2 | C5: 05-11.01 | D5: 2 | F5: =IFERROR(O5-SUM(Q5:W5)+AA5,0) -> 25524.23 | G5: ='Юнит 2'!L$17 -> 86 | H5: ='Юнит 2'!Q$17 -> 43 | I5: ='Юнит 2'!R$17 -> -1 | J5: ='Юнит 2'!T$74 -> 43245.32 | K5: ='Юнит 2'!U$74 -> -931 | L5: =IFERROR(J5+K5,0) -> 42314.32 | M5: ='Юнит 2'!W$74 -> 52197.86 | N5: ='Юнит 2'!X$74 -> -1199 | O5: =IFERROR(M5+N5,0) -> 50998.86 | P5: ='Юнит 2'!AB$74 -> 5562.9 | Q5: ='Юнит 2'!AE$74 -> 5752.8 | R5: ='Юнит 2'!AC$74 -> 18463.04 | S5: ='Юнит 2'!AI$74 -> 1083.11 | U5: ='Юнит 2'!AJ$74 -> 0 | V5: 175.68 | W5: ='Юнит 2'!AF$74 -> 0 | X5: ='Юнит 2'!AG$74 -> 6535 | Y5: ='Юнит 2'!AH85 -> 0 | Z5: 416.28 | AB5: =O5-SUM(P5:Y5)+AA5 -> 13426.33 | AC5: =O5-SUM(P5:Z5)+AA5 -> 13010.05 | AE5: =P5/O5 -> 0.10907891 | AF5: =AC5/P5 -> 2.3387172 | AG5: =AC5/O5 -> 0.25510472 | AH5: =(W5+X5+Y5)/O5 -> 0.12814012
B6: Январь 3 | C6: 12-18.01 | D6: 3 | F6: =IFERROR(O6-SUM(Q6:W6)+AA6,0) -> 25982.83 | G6: ='Юнит 3'!L$17 -> 62 | H6: ='Юнит 3'!Q$17 -> 49 | I6: ='Юнит 3'!R$17 -> -1 | J6: ='Юнит 3'!T$74 -> 45785.47 | K6: ='Юнит 3'!U$74 -> -948 | L6: =IFERROR(J6+K6,0) -> 44837.47 | M6: ='Юнит 3'!W$74 -> 56919.74 | N6: ='Юнит 3'!X$74 -> -1174 | O6: =IFERROR(M6+N6,0) -> 55745.74 | P6: ='Юнит 3'!AB$74 -> 6528.42 | Q6: ='Юнит 3'!AE$74 -> 6055.25 | R6: ='Юнит 3'!AC$74 -> 19306.86 | S6: ='Юнит 3'!AI$74 -> 1361.68 | U6: ='Юнит 3'!AJ$74 -> 0 | V6: 117.12 | W6: ='Юнит 3'!AF$74 -> 2922 | X6: ='Юнит 3'!AG$74 -> 3464 | Y6: ='Юнит 3'!AH86 -> 0 | Z6: 467.24 | AB6: =O6-SUM(P6:Y6)+AA6 -> 15990.41 | AC6: =O6-SUM(P6:Z6)+AA6 -> 15523.17 | AE6: =P6/O6 -> 0.11711065 | AF6: =AC6/P6 -> 2.3777836 | AG6: =AC6/O6 -> 0.27846379 | AH6: =(W6+X6+Y6)/O6 -> 0.11455584
B7: Январь 4 | C7: 19-25.01 | D7: 4 | F7: =IFERROR(O7-SUM(Q7:W7)+AA7,0) -> 22836.85 | G7: ='Юнит 4'!L$17 -> 86 | H7: ='Юнит 4'!Q$17 -> 49 | I7: ='Юнит 4'!R$17 -> -2 | J7: ='Юнит 4'!T$74 -> 44338.88 | K7: ='Юнит 4'!U$74 -> -1888 | L7: =IFERROR(J7+K7,0) -> 42450.88 | M7: ='Юнит 4'!W$74 -> 59321.67 | N7: ='Юнит 4'!X$74 -> -2412 | O7: =IFERROR(M7+N7,0) -> 56909.67 | P7: ='Юнит 4'!AB$74 -> 6764.52 | Q7: ='Юнит 4'!AE$74 -> 6115.35 | R7: ='Юнит 4'!AC$74 -> 20543.92 | S7: ='Юнит 4'!AI$74 -> 1438.99 | U7: ='Юнит 4'!AJ$74 -> 0 | V7: 58.56 | W7: ='Юнит 4'!AF$74 -> 5916 | X7: ='Юнит 4'!AG$74 -> 2033 | Y7: ='Юнит 4'!AH87 -> 0 | Z7: 456.13 | AB7: =O7-SUM(P7:Y7)+AA7 -> 14039.33 | AC7: =O7-SUM(P7:Z7)+AA7 -> 13583.2 | AE7: =P7/O7 -> 0.11886416 | AF7: =AC7/P7 -> 2.0080065 | AG7: =AC7/O7 -> 0.23868 | AH7: =(W7+X7+Y7)/O7 -> 0.13967749
B8: Январь 5 | C8: 26.01-01.02 | D8: 5 | F8: =IFERROR(O8-SUM(Q8:W8)+AA8,0) -> 26541.81 | G8: ='Юнит 5'!L$17 -> 157 | H8: ='Юнит 5'!Q$17 -> 70 | I8: ='Юнит 5'!R$17 -> -1 | J8: ='Юнит 5'!T$74 -> 53707.42 | K8: ='Юнит 5'!U$74 -> -813 | L8: =IFERROR(J8+K8,0) -> 52894.42 | M8: ='Юнит 5'!W$74 -> 80352 | N8: ='Юнит 5'!X$74 -> -1238 | O8: =IFERROR(M8+N8,0) -> 79114 | P8: ='Юнит 5'!AB$74 -> 9760.32 | Q8: ='Юнит 5'!AE$74 -> 8509.6 | R8: ='Юнит 5'!AC$74 -> 28720.66 | S8: ='Юнит 5'!AI$74 -> 1377.57 | U8: ='Юнит 5'!AJ$74 -> 0 | V8: 351.36 | W8: ='Юнит 5'!AF$74 -> 13613 | X8: ='Юнит 5'!AG$74 -> 9632 | Y8: ='Юнит 5'!AH88 -> 0 | Z8: 483.37 | AB8: =O8-SUM(P8:Y8)+AA8 -> 7149.49 | AC8: =O8-SUM(P8:Z8)+AA8 -> 6666.12 | AE8: =P8/O8 -> 0.12337033 | AF8: =AC8/P8 -> 0.68298171 | AG8: =AC8/O8 -> 0.084259676 | AH8: =(W8+X8+Y8)/O8 -> 0.29381652
B9: Февраль 1 | C9: 02-08.02 | D9: 6 | F9: =IFERROR(O9-SUM(Q9:W9)+AA9,0) -> 59865 | G9: ='Юнит 6'!L$45 -> 286 | H9: ='Юнит 6'!Q$45 -> 118 | I9: ='Юнит 6'!R$45 -> -1 | J9: ='Юнит 6'!T$102 -> 85982.96 | K9: ='Юнит 6'!U$102 -> -777 | L9: =IFERROR(J9+K9,0) -> 85205.96 | M9: ='Юнит 6'!W$102 -> 132376.93 | N9: ='Юнит 6'!X$102 -> -1238 | O9: =IFERROR(M9+N9,0) -> 131138.93 | P9: ='Юнит 6'!AB$102 -> 15974.01 | Q9: ='Юнит 6'!AE$102 -> 12544.65 | R9: ='Юнит 6'!AC$102 -> 47795.47 | S9: ='Юнит 6'!AI$102 -> 1261.41 | U9: ='Юнит 6'!AJ$102 -> 0 | V9: 146.4 | W9: ='Юнит 6'!AF$102 -> 9526 | X9: ='Юнит 6'!AG$102 -> 17308 | Y9: ='Юнит 6'!AH117 -> 0 | Z9: 922.79 | AB9: =O9-SUM(P9:Y9)+AA9 -> 26582.99 | AC9: =O9-SUM(P9:Z9)+AA9 -> 25660.2 | AD9: =SUM(AC9:AC12) -> 265557.06 | AE9: =P9/O9 -> 0.12180982 | AF9: =AC9/P9 -> 1.6063719 | AG9: =AC9/O9 -> 0.19567187 | AH9: =(W9+X9+Y9)/O9 -> 0.20462269
B10: Февраль 2 | C10: 09-15.02 | D10: 7 | F10: =IFERROR(O10-SUM(Q10:W10)+AA10,0) -> 105982.04 | G10: ='Юнит 7'!L$45 -> 388 | H10: ='Юнит 7'!Q$45 -> 212 | I10: ='Юнит 7'!R$45 -> -2 | J10: ='Юнит 7'!T$102 -> 149383.2 | K10: ='Юнит 7'!U$102 -> -1458 | L10: =IFERROR(J10+K10,0) -> 147925.2 | M10: ='Юнит 7'!W$102 -> 234275.74 | N10: ='Юнит 7'!X$102 -> -2388 | O10: =IFERROR(M10+N10,0) -> 231887.74 | P10: ='Юнит 7'!AB$102 -> 27919.8 | Q10: ='Юнит 7'!AE$102 -> 22767.8 | R10: ='Юнит 7'!AC$102 -> 84374.68 | S10: ='Юнит 7'!AI$102 -> 1132.46 | T10: 165 | U10: ='Юнит 7'!AJ$102 -> 0 | V10: 497.76 | W10: ='Юнит 7'!AF$102 -> 16968 | X10: ='Юнит 7'!AG$102 -> 25029 | Y10: ='Юнит 7'!AH118 -> 0 | Z10: 1478.16 | AB10: =O10-SUM(P10:Y10)+AA10 -> 53033.24 | AC10: =O10-SUM(P10:Z10)+AA10 -> 51555.08 | AE10: =P10/O10 -> 0.12040223 | AF10: =AC10/P10 -> 1.8465419 | AG10: =AC10/O10 -> 0.22232775 | AH10: =(W10+X10+Y10)/O10 -> 0.18110919
B11: Февраль 3 | C11: 16-22.02 | D11: 8 | F11: =IFERROR(O11-SUM(Q11:W11)+AA11,0) -> 168699.24 | G11: ='Юнит 8'!L$45 -> 640 | H11: ='Юнит 8'!Q$45 -> 332 | I11: ='Юнит 8'!R$45 -> -3 | J11: ='Юнит 8'!T$102 -> 231517.83 | K11: ='Юнит 8'!U$102 -> -2178 | L11: =IFERROR(J11+K11,0) -> 229339.83 | M11: ='Юнит 8'!W$102 -> 360665.46 | N11: ='Юнит 8'!X$102 -> -3466 | O11: =IFERROR(M11+N11,0) -> 357199.46 | P11: ='Юнит 8'!AB$102 -> 44360.03 | Q11: ='Юнит 8'!AE$102 -> 32716.08 | R11: ='Юнит 8'!AC$102 -> 132861.28 | S11: ='Юнит 8'!AI$102 -> 1284.66 | T11: 1905 | U11: ='Юнит 8'!AJ$102 -> 294 | V11: 439.2 | W11: ='Юнит 8'!AF$102 -> 19000 | X11: ='Юнит 8'!AG$102 -> 43359 | Y11: ='Юнит 8'!AH119 -> 0 | Z11: 2261.26 | AB11: =O11-SUM(P11:Y11)+AA11 -> 80980.21 | AC11: =O11-SUM(P11:Z11)+AA11 -> 78718.95 | AE11: =P11/O11 -> 0.1241884 | AF11: =AC11/P11 -> 1.7745468 | AG11: =AC11/O11 -> 0.22037813 | AH11: =(W11+X11+Y11)/O11 -> 0.17457753
B12: Февраль 4 | C12: 23.02-01.03 | D12: 9 | F12: =IFERROR(O12-SUM(Q12:W12)+AA12,0) -> 214108.03 | G12: ='Юнит 9'!L$45 -> 632 | H12: ='Юнит 9'!Q$45 -> 399 | I12: ='Юнит 9'!R$45 -> -9 | J12: ='Юнит 9'!T$102 -> 296481.4 | K12: ='Юнит 9'!U$102 -> -6522 | L12: =IFERROR(J12+K12,0) -> 289959.4 | M12: ='Юнит 9'!W$102 -> 464446.44 | N12: ='Юнит 9'!X$102 -> -10316 | O12: =IFERROR(M12+N12,0) -> 454130.44 | P12: ='Юнит 9'!AB$102 -> 51789.51 | Q12: ='Юнит 9'!AE$102 -> 45998.58 | R12: ='Юнит 9'!AC$102 -> 171766.49 | S12: ='Юнит 9'!AI$102 -> 1545.78 | T12: 465 | U12: ='Юнит 9'!AJ$102 -> 0 | V12: 58.56 | W12: ='Юнит 9'!AF$102 -> 20188 | X12: ='Юнит 9'!AG$102 -> 49771 | Y12: ='Юнит 9'!AH120 -> 0 | Z12: 2924.69 | AB12: =O12-SUM(P12:Y12)+AA12 -> 112547.52 | AC12: =O12-SUM(P12:Z12)+AA12 -> 109622.83 | AE12: =P12/O12 -> 0.11404105 | AF12: =AC12/P12 -> 2.1166995 | AG12: =AC12/O12 -> 0.24139062 | AH12: =(W12+X12+Y12)/O12 -> 0.15405045
B13: Март 1 очки | C13: 02-08.03 | D13: 10 | F13: =IFERROR(O13-SUM(Q13:W13)+AA13,0) -> 183388.28 | G13: ='Юнит 10'!L$58 -> 833 | H13: ='Юнит 10'!Q$58 -> 382 | I13: ='Юнит 10'!R$58 -> -8 | J13: ='Юнит 10'!T$58 -> 300005.62 | K13: ='Юнит 10'!U$58 -> -6272.41 | L13: =IFERROR(J13+K13,0) -> 293733.21 | M13: ='Юнит 10'!W$58 -> 466843.39 | N13: ='Юнит 10'!X$58 -> -9947.95 | O13: =IFERROR(M13+N13,0) -> 456895.44 | P13: ='Юнит 10'!AB$58 -> 49184.92 | Q13: ='Юнит 10'!AE$58 -> 46676.69 | R13: ='Юнит 10'!AC$58 -> 172521.44 | S13: ='Юнит 10'!AI$58 -> 2108.03 | T13: 735 | U13: ='Юнит 10'!AJ$58 -> 30 | W13: ='Юнит 10'!AF$58 -> 51436 | X13: ='Юнит 10'!AG$58 -> 14284 | Y13: ='Юнит 10'!AH134 -> 0 | Z13: =IFERROR((L13)*0.01,0) -> 2937.3321 | AB13: =O13-SUM(P13:Y13)+AA13 -> 119919.36 | AC13: =O13-SUM(P13:Z13)+AA13 -> 116982.03 | AD13: =SUM(AC13:AC20) -> 688145.05 | AE13: =P13/O13 -> 0.10765028 | AF13: =AC13/P13 -> 2.3784125 | AG13: =AC13/O13 -> 0.25603676 | AH13: =(W13+X13+Y13)/O13 -> 0.14384035
B14: Март 1 шапки | C14: 02-08.03 | D14: 10 | F14: =IFERROR(O14-SUM(Q14:W14)+AA14,0) -> -3920 | G14: ='Юнит 10'!L$68 -> 2 | H14: ='Юнит 10'!Q$68 -> 0 | I14: ='Юнит 10'!R$68 -> 0 | J14: ='Юнит 10'!T$68 -> 0 | K14: ='Юнит 10'!U$68 -> 0 | L14: =IFERROR(J14+K14,0) -> 0 | M14: ='Юнит 10'!W$68 -> 0 | N14: ='Юнит 10'!X$68 -> 0 | O14: =IFERROR(M14+N14,0) -> 0 | P14: ='Юнит 10'!AB$68 -> 0 | Q14: ='Юнит 10'!AE$68 -> 0 | R14: ='Юнит 10'!AC$68 -> 0 | S14: ='Юнит 10'!AI$68 -> 0 | U14: ='Юнит 10'!AJ$68 -> 0 | W14: ='Юнит 10'!AF$68 -> 3920 | X14: ='Юнит 10'!AG$68 -> 0 | Y14: ='Юнит 10'!AH135 -> 0 | Z14: =IFERROR((L14)*0.01,0) -> 0 | AB14: =O14-SUM(P14:Y14)+AA14 -> -3920 | AC14: =O14-SUM(P14:Z14)+AA14 -> -3920 | AE14: =P14/O14 -> #DIV/0! | AF14: =AC14/P14 -> #DIV/0! | AG14: =AC14/O14 -> #DIV/0! | AH14: =(W14+X14+Y14)/O14 -> #DIV/0!
B15: Март 2 очки | C15: 09-15.03 | D15: 11 | F15: =IFERROR(O15-SUM(Q15:W15)+AA15,0) -> 370668.61 | G15: ='Юнит 11'!L$58 -> 1503 | H15: ='Юнит 11'!Q$58 -> 797 | I15: ='Юнит 11'!R$58 -> -13 | J15: ='Юнит 11'!T$58 -> 612594.65 | K15: ='Юнит 11'!U$58 -> -10314 | L15: =IFERROR(J15+K15,0) -> 602280.65 | M15: ='Юнит 11'!W$58 -> 943118.99 | N15: ='Юнит 11'!X$58 -> -15997 | O15: =IFERROR(M15+N15,0) -> 927121.99 | P15: ='Юнит 11'!AB$58 -> 103751.9 | Q15: ='Юнит 11'!AE$58 -> 97317.48 | R15: ='Юнит 11'!AC$58 -> 349180.58 | S15: ='Юнит 11'!AI$58 -> 1851.28 | T15: 165 | U15: ='Юнит 11'!AJ$58 -> 0 | V15: 2357.04 | W15: ='Юнит 11'!AF$58 -> 105582 | X15: ='Юнит 11'!AG$58 -> 0 | Y15: ='Юнит 11'!AH136 -> 0 | Z15: =IFERROR((L15)*0.01,0) -> 6022.8065 | AB15: =O15-SUM(P15:Y15)+AA15 -> 266916.71 | AC15: =O15-SUM(P15:Z15)+AA15 -> 260893.9 | AE15: =P15/O15 -> 0.1119075 | AF15: =AC15/P15 -> 2.514594 | AG15: =AC15/O15 -> 0.28140192 | AH15: =(W15+X15+Y15)/O15 -> 0.11388145
B16: Март 2 шапки | C16: 09-15.03 | D16: 11 | F16: =IFERROR(O16-SUM(Q16:W16)+AA16,0) -> -12473.82 | G16: ='Юнит 11'!L$68 -> 16 | H16: ='Юнит 11'!Q$68 -> 0 | I16: ='Юнит 11'!R$68 -> 0 | J16: ='Юнит 11'!T$68 -> 0 | K16: ='Юнит 11'!U$68 -> 0 | L16: =IFERROR(J16+K16,0) -> 0 | M16: ='Юнит 11'!W$68 -> 0 | N16: ='Юнит 11'!X$68 -> 0 | O16: =IFERROR(M16+N16,0) -> 0 | P16: ='Юнит 11'!AB$68 -> 0 | Q16: ='Юнит 11'!AE$68 -> 198.82 | R16: ='Юнит 11'!AC$68 -> 0 | S16: ='Юнит 11'!AI$68 -> 0 | T16: 195 | U16: ='Юнит 11'!AJ$68 -> 0 | W16: ='Юнит 11'!AF$68 -> 12080 | X16: ='Юнит 11'!AG$68 -> 0 | Y16: ='Юнит 11'!AH137 -> 0 | Z16: =IFERROR((L16)*0.01,0) -> 0 | AB16: =O16-SUM(P16:Y16)+AA16 -> -12473.82 | AC16: =O16-SUM(P16:Z16)+AA16 -> -12473.82 | AE16: =P16/O16 -> #DIV/0! | AF16: =AC16/P16 -> #DIV/0! | AG16: =AC16/O16 -> #DIV/0! | AH16: =(W16+X16+Y16)/O16 -> #DIV/0!
B17: Март 3 очки | C17: 16-22.03 | D17: 12 | F17: =IFERROR(O17-SUM(Q17:W17)+AA17,0) -> 460743.49 | G17: ='Юнит 12'!L$58 -> 1912 | H17: ='Юнит 12'!Q$58 -> 947 | I17: ='Юнит 12'!R$58 -> -22 | J17: ='Юнит 12'!T$58 -> 770335.74 | K17: ='Юнит 12'!U$58 -> -17585.11 | L17: =IFERROR(J17+K17,0) -> 752750.63 | M17: ='Юнит 12'!W$58 -> 1160661.8 | N17: ='Юнит 12'!X$58 -> -26564.08 | O17: =IFERROR(M17+N17,0) -> 1134097.7 | P17: ='Юнит 12'!AB$58 -> 122764.06 | Q17: ='Юнит 12'!AE$58 -> 116519.87 | R17: ='Юнит 12'!AC$58 -> 428981.74 | S17: ='Юнит 12'!AI$58 -> 2973.3315 | T17: 300 | U17: ='Юнит 12'!AJ$58 -> 0 | V17: 3528.24 | W17: ='Юнит 12'!AF$58 -> 121051 | X17: ='Юнит 12'!AG$58 -> 0 | Y17: ='Юнит 12'!AH138 -> 0 | Z17: =IFERROR((L17)*0.01,0) -> 7527.5063 | AB17: =O17-SUM(P17:Y17)+AA17 -> 337979.43 | AC17: =O17-SUM(P17:Z17)+AA17 -> 330451.92 | AE17: =P17/O17 -> 0.10824823 | AF17: =AC17/P17 -> 2.6917644 | AG17: =AC17/O17 -> 0.29137872 | AH17: =(W17+X17+Y17)/O17 -> 0.10673772
B18: Март 3 шапки | C18: 16-22.03 | D18: 12 | F18: =IFERROR(O18-SUM(Q18:W18)+AA18,0) -> -2556.9685 | G18: ='Юнит 12'!L$68 -> 4 | H18: ='Юнит 12'!Q$68 -> 3 | I18: ='Юнит 12'!R$68 -> 0 | J18: ='Юнит 12'!T$68 -> 4468 | K18: ='Юнит 12'!U$68 -> 0 | L18: =IFERROR(J18+K18,0) -> 4468 | M18: ='Юнит 12'!W$68 -> 6680 | N18: ='Юнит 12'!X$68 -> 0 | O18: =IFERROR(M18+N18,0) -> 6680 | P18: ='Юнит 12'!AB$68 -> 1187.34 | Q18: ='Юнит 12'!AE$68 -> 2459.75 | R18: ='Юнит 12'!AC$68 -> 2953.15 | S18: ='Юнит 12'!AI$68 -> 3.7884878 | T18: 75 | U18: ='Юнит 12'!AJ$68 -> 3745.28 | W18: ='Юнит 12'!AF$68 -> 0 | X18: ='Юнит 12'!AG$68 -> 0 | Y18: ='Юнит 12'!AH139 -> 0 | Z18: =IFERROR((L18)*0.01,0) -> 44.68 | AB18: =O18-SUM(P18:Y18)+AA18 -> -3744.3085 | AC18: =O18-SUM(P18:Z18)+AA18 -> -3788.9885 | AE18: =P18/O18 -> 0.17774551 | AF18: =AC18/P18 -> -3.1911571 | AG18: =AC18/O18 -> -0.56721385 | AH18: =(W18+X18+Y18)/O18 -> 0
B19: Март 4 очки | C19: 23-29.03 | D19: 13 | F19: =IFERROR(O19-SUM(Q19:W19)+AA19,0) -> 0 | G19: ='Юнит 13'!L$58 -> 0 | H19: ='Юнит 13'!Q$58 -> 0 | I19: ='Юнит 13'!R$58 -> 0 | J19: ='Юнит 13'!T$58 -> 0 | K19: ='Юнит 13'!U$58 -> 0 | L19: =IFERROR(J19+K19,0) -> 0 | M19: ='Юнит 13'!W$58 -> 0 | N19: ='Юнит 13'!X$58 -> 0 | O19: =IFERROR(M19+N19,0) -> 0 | P19: ='Юнит 13'!AB$58 -> 0 | Q19: ='Юнит 13'!AE$58 -> 0 | R19: ='Юнит 13'!AC$58 -> 0 | S19: ='Юнит 13'!AI$58 -> 0 | U19: ='Юнит 13'!AJ$58 -> 0 | W19: ='Юнит 13'!AF$58 -> 0 | X19: ='Юнит 13'!AG$58 -> 0 | Y19: ='Юнит 13'!AH140 -> 0 | Z19: =IFERROR((L19)*0.01,0) -> 0 | AB19: =O19-SUM(P19:Y19)+AA19 -> 0 | AC19: =O19-SUM(P19:Z19)+AA19 -> 0 | AE19: =P19/O19 -> #DIV/0! | AF19: =AC19/P19 -> #DIV/0! | AG19: =AC19/O19 -> #DIV/0! | AH19: =(W19+X19+Y19)/O19 -> #DIV/0!
B20: Март 4 шапки | C20: 23-29.03 | D20: 13 | F20: =IFERROR(O20-SUM(Q20:W20)+AA20,0) -> 0 | G20: ='Юнит 13'!L$68 -> 0 | H20: ='Юнит 13'!Q$68 -> 0 | I20: ='Юнит 13'!R$68 -> 0 | J20: ='Юнит 13'!T$68 -> 0 | K20: ='Юнит 13'!U$68 -> 0 | L20: =IFERROR(J20+K20,0) -> 0 | M20: ='Юнит 13'!W$68 -> 0 | N20: ='Юнит 13'!X$68 -> 0 | O20: =IFERROR(M20+N20,0) -> 0 | P20: ='Юнит 13'!AB$68 -> 0 | Q20: ='Юнит 13'!AE$68 -> 0 | R20: ='Юнит 13'!AC$68 -> 0 | S20: ='Юнит 13'!AI$68 -> 0 | U20: ='Юнит 13'!AJ$68 -> 0 | W20: ='Юнит 13'!AF$68 -> 0 | X20: ='Юнит 13'!AG$68 -> 0 | Y20: ='Юнит 13'!AH141 -> 0 | Z20: =IFERROR((L20)*0.01,0) -> 0 | AB20: =O20-SUM(P20:Y20)+AA20 -> 0 | AC20: =O20-SUM(P20:Z20)+AA20 -> 0 | AE20: =P20/O20 -> #DIV/0! | AF20: =AC20/P20 -> #DIV/0! | AG20: =AC20/O20 -> #DIV/0! | AH20: =(W20+X20+Y20)/O20 -> #DIV/0!
AB22: =O22-SUM(P22:Y22)+AA22 -> 0 | AC22: =O22-SUM(P22:Z22)+AA22 -> 0 | AE22: =P22/O22 -> #DIV/0! | AF22: =AC22/P22 -> #DIV/0! | AG22: =AC22/O22 -> #DIV/0! | AH22: =(W22+X22+Y22)/O22 -> #DIV/0!
B23: Итого | F23: =SUM(F4:F22) -> 1674669.3 | G23: =SUM(G4:G22) -> 6673 | H23: =SUM(H4:H22) -> 3446 | I23: =SUM(I4:I22) -> -63 | J23: =SUM(J4:J22) -> 2683992.1 | K23: =SUM(K4:K22) -> -49686.52 | L23: =SUM(L4:L22) -> 2634305.6 | M23: =SUM(M4:M22) -> 4072848.6 | ... AD23: =SUM(AD4:AD22) -> 1020856.2 | AE23: =P23/O23 -> 0.11290224 | AF23: =AC23/P23 -> 2.2622353 | AG23: =AC23/O23 -> 0.25541144 | AH23: =(W23+X23+Y23)/O23 -> 0.13969672
M24: % от выручки за весь период
N25: =-N23/M23 -> 0.018645434 | P25: =P23/$O$23 -> 0.11290224 | Q25: =Q23/$O$23 -> 0.10212287 | R25: =R23/$O$23 -> 0.37462041 | S25: =S23/$O$23 -> 0.0046215018 | T25: =T23/$O$23 -> 0.0010020244 | U25: =U23/$O$23 -> 0.0010181069 | V25: =V23/$O$23 -> 0.0019995454 | W25: =W23/$O$23 -> 0.095624404 | ... Z25: =Z23/$O$23 -> 0.0066051386 | AD25: =AC23/P23 -> 2.2622353 | AE25: Маржинальность, %
W26: =(W23+X23)/O23 -> 0.13969672 | AD26: =AC23/O23 -> 0.25541144 | AE26: Рентабельность, %
B28: ЯНВАРЬ | G28: =SUM(G4:G8) -> 457 | H28: =SUM(H4:H8) -> 256 | I28: =SUM(I4:I8) -> -5 | J28: =SUM(J4:J8) -> 233222.72 | K28: =SUM(K4:K8) -> -4580 | L28: =SUM(L4:L8) -> 228642.72 | M28: =SUM(M4:M8) -> 303779.89 | N28: =SUM(N4:N8) -> -6023 | ... AA28: =SUM(AA4:AA8) -> 0 | AC28: =SUM(AC4:AC8) -> 67154.08 | AD28: =AC28/P28 -> 1.9562269
N29: =-N28/M28 -> 0.019826856 | P29: =P28/$O$28 -> 0.11528993 | Q29: =Q28/$O$28 -> 0.10403135 | R29: =R28/$O$28 -> 0.35897977 | S29: =S28/$O$28 -> 0.021195076 | T29: =T28/$O$28 -> 0 | U29: =U28/$O$28 -> 0 | V29: =V28/$O$28 -> 0.0032402273 | W29: =W28/$O$28 -> 0.075400438 | ... AA29: =AA28/$O$28 -> 0 | AC29: =AC28/O28 -> 0.22553325 | AD29: =AC28/O28 -> 0.22553325
B31: ФЕВРАЛЬ | G31: =SUM(G9:G12) -> 1946 | H31: =SUM(H9:H12) -> 1061 | I31: =SUM(I9:I12) -> -15 | J31: =SUM(J9:J12) -> 763365.39 | K31: =SUM(K9:K12) -> -10935 | L31: =SUM(L9:L12) -> 752430.39 | M31: =SUM(M9:M12) -> 1191764.6 | N31: =SUM(N9:N12) -> -17408 | ... AC31: =SUM(AC9:AC12) -> 265557.06 | AD31: =AC31/P31 -> 1.896249
N32: =-N31/M31 -> 0.014606912 | P32: =P31/$O$31 -> 0.11925113 | Q32: =Q31/$O$31 -> 0.09709752 | R32: =R31/$O$31 -> 0.37194659 | S32: =S31/$O$31 -> 0.0044486574 | T32: =T31/$O$31 -> 0.0021586289 | U32: =U31/$O$31 -> 0.00025034986 | V32: =V31/$O$31 -> 0.00097237928 | W32: =W31/$O$31 -> 0.055930202 | ... AA32: =AA31/$O$31 -> 0 | AC32: =AC31/O31 -> 0.22612984 | AD32: =AC31/O31 -> 0.22612984
B34: 11 нед очки | G34: =G15 -> 1503 | H34: =H15 -> 797 | I34: =I15 -> -13 | J34: =J15 -> 612594.65 | K34: =K15 -> -10314 | L34: =L15 -> 602280.65 | M34: =M15 -> 943118.99 | N34: =N15 -> -15997 | ... AC34: =AC15 -> 260893.9 | AD34: =AC15/P15 -> 2.514594
N35: =-N34/$M$34 -> 0.016961805 | P35: =P34/$O$34 -> 0.1119075 | Q35: =Q34/$O$34 -> 0.10496729 | R35: =R34/$O$34 -> 0.37662852 | S35: =S34/$O$34 -> 0.001996803 | T35: =T34/$O$34 -> 0.00017797011 | U35: =U34/$O$34 -> 0 | V35: =V34/$O$34 -> 0.0025423192 | W35: =W34/$O$34 -> 0.11388145 | ... AC35: =AC34/$O$34 -> 0.28140192 | AD35: =AC15/O15 -> 0.28140192
B37: 12 нед очки | G37: =G17 -> 1912 | H37: =H17 -> 947 | I37: =I17 -> -22 | J37: =J17 -> 770335.74 | K37: =K17 -> -17585.11 | L37: =L17 -> 752750.63 | M37: =M17 -> 1160661.8 | N37: =N17 -> -26564.08 | ... AC37: =AC17 -> 330451.92 | AD37: =AC17/P17 -> 2.6917644
N38: =-N37/$M$37 -> 0.022887013 | P38: =P37/$O$37 -> 0.10824823 | Q38: =Q37/$O$37 -> 0.10274236 | R38: =R37/$O$37 -> 0.3782582 | S38: =S37/$O$37 -> 0.0026217597 | T38: =T37/$O$37 -> 0.00026452748 | U38: =U37/$O$37 -> 0 | V38: =V37/$O$37 -> 0.0031110548 | W38: =W37/$O$37 -> 0.10673772 | ... AC38: =AC37/$O$37 -> 0.29137872 | AD38: =AC17/O17 -> 0.29137872
B43: МАРТ | G43: =SUM(G13:G22) -> 4270 | H43: =SUM(H13:H22) -> 2129 | I43: =SUM(I13:I22) -> -43 | J43: =SUM(J13:J22) -> 1687404 | K43: =SUM(K13:K22) -> -34171.52 | L43: =SUM(L13:L22) -> 1653232.5 | M43: =SUM(M13:M22) -> 2577304.1 | N43: =SUM(N13:N22) -> -52509.03 | ... AC43: =SUM(AC13:AC22) -> 688145.05 | AD43: =AC43/P43 -> 2.485281
AD44: =AC43/O43 -> 0.27255481

Sheet АВС 13
B2: ОЧКИ
C3: Прибыль | D3: % прибыль | E3: Доля | F3: ABC прибыль | G3: ABC кол-во | J3: Кол-во | K3: % кол-во | L3: Доля | M3: ABC кол-во
B4: Черные с железкой Сул | D4: =C4/C$58 -> #DIV/0! | E4: =D4 -> #DIV/0! | F4: =IF(AND(E4<=0),"C",IF(E4<=0.8,"A",IF(E4<=0.95,"B","C"))) -> #DIV/0! | G4: =VLOOKUP(B$4:B$57,I$4:M$57,5,0) -> #DIV/0! | I4: Черные с железкой Сул | K4: =J4/J$58 -> #DIV/0! | L4: =K4 -> #DIV/0! | M4: =_xlfn.IFS(L4<80%,"A",L4<=95%,"B",L4>95%,"C") -> #DIV/0! | P4: A | Q4: 0.8
B5: Qs черн Сул | D5: =C5/C$58 -> #DIV/0! | E5: =E4+D5 -> #DIV/0! | F5: =IF(AND(E5<=0),"C",IF(E5<=0.8,"A",IF(E5<=0.95,"B","C"))) -> #DIV/0! | G5: =VLOOKUP(B$4:B$57,I$4:M$57,5,0) -> #DIV/0! | I5: Qs черн Сул | K5: =J5/J$58 -> #DIV/0! | L5: =L4+K5 -> #DIV/0! | M5: =_xlfn.IFS(L5<80%,"A",L5<=95%,"B",L5>95%,"C") -> #DIV/0! | P5: B | Q5: 0.15
B6: Qs син Сул | D6: =C6/C$58 -> #DIV/0! | E6: =E5+D6 -> #DIV/0! | F6: =IF(AND(E6<=0),"C",IF(E6<=0.8,"A",IF(E6<=0.95,"B","C"))) -> #DIV/0! | G6: =VLOOKUP(B$4:B$57,I$4:M$57,5,0) -> #DIV/0! | I6: Qs син Сул | K6: =J6/J$58 -> #DIV/0! | L6: =L5+K6 -> #DIV/0! | M6: =_xlfn.IFS(L6<80%,"A",L6<=95%,"B",L6>95%,"C") -> #DIV/0! | P6: C | Q6: 0.05
B7: Qs желт Сул | D7: =C7/C$58 -> #DIV/0! | E7: =E6+D7 -> #DIV/0! | F7: =IF(AND(E7<=0),"C",IF(E7<=0.8,"A",IF(E7<=0.95,"B","C"))) -> #DIV/0! | G7: =VLOOKUP(B$4:B$57,I$4:M$57,5,0) -> #DIV/0! | I7: Qs желт Сул | K7: =J7/J$58 -> #DIV/0! | L7: =L6+K7 -> #DIV/0! | M7: =_xlfn.IFS(L7<80%,"A",L7<=95%,"B",L7>95%,"C") -> #DIV/0!
B8: flip черные Сул | D8: =C8/C$58 -> #DIV/0! | E8: =E7+D8 -> #DIV/0! | F8: =IF(AND(E8<=0),"C",IF(E8<=0.8,"A",IF(E8<=0.95,"B","C"))) -> #DIV/0! | G8: =VLOOKUP(B$4:B$57,I$4:M$57,5,0) -> #DIV/0! | I8: flip черные Сул | K8: =J8/J$58 -> #DIV/0! | L8: =L7+K8 -> #DIV/0! | M8: =_xlfn.IFS(L8<80%,"A",L8<=95%,"B",L8>95%,"C") -> #DIV/0!
B9: flip желтые Сул | D9: =C9/C$58 -> #DIV/0! | E9: =E8+D9 -> #DIV/0! | F9: =IF(AND(E9<=0),"C",IF(E9<=0.8,"A",IF(E9<=0.95,"B","C"))) -> #DIV/0! | G9: =VLOOKUP(B$4:B$57,I$4:M$57,5,0) -> #DIV/0! | I9: flip желтые Сул | K9: =J9/J$58 -> #DIV/0! | L9: =L8+K9 -> #DIV/0! | M9: =_xlfn.IFS(L9<80%,"A",L9<=95%,"B",L9>95%,"C") -> #DIV/0!
B10: MR8854 C2 Сул | D10: =C10/C$58 -> #DIV/0! | E10: =E9+D10 -> #DIV/0! | F10: =IF(AND(E10<=0),"C",IF(E10<=0.8,"A",IF(E10<=0.95,"B","C"))) -> #DIV/0! | G10: =VLOOKUP(B$4:B$57,I$4:M$57,5,0) -> #DIV/0! | I10: MR8854 C2 Сул | K10: =J10/J$58 -> #DIV/0! | L10: =L9+K10 -> #DIV/0! | M10: =_xlfn.IFS(L10<80%,"A",L10<=95%,"B",L10>95%,"C") -> #DIV/0!
B11: MR 1819 черн | D11: =C11/C$58 -> #DIV/0! | E11: =E10+D11 -> #DIV/0! | F11: =IF(AND(E11<=0),"C",IF(E11<=0.8,"A",IF(E11<=0.95,"B","C"))) -> #DIV/0! | G11: =VLOOKUP(B$4:B$57,I$4:M$57,5,0) -> #DIV/0! | I11: MR 1819 черн | K11: =J11/J$58 -> #DIV/0! | L11: =L10+K11 -> #DIV/0! | M11: =_xlfn.IFS(L11<80%,"A",L11<=95%,"B",L11>95%,"C") -> #DIV/0!
B12: MR 1819 корич | D12: =C12/C$58 -> #DIV/0! | E12: =E11+D12 -> #DIV/0! | F12: =IF(AND(E12<=0),"C",IF(E12<=0.8,"A",IF(E12<=0.95,"B","C"))) -> #DIV/0! | G12: =VLOOKUP(B$4:B$57,I$4:M$57,5,0) -> #DIV/0! | I12: MR 1819 корич | K12: =J12/J$58 -> #DIV/0! | L12: =L11+K12 -> #DIV/0! | M12: =_xlfn.IFS(L12<80%,"A",L12<=95%,"B",L12>95%,"C") -> #DIV/0!
B13: MR Р1874 черн | D13: =C13/C$58 -> #DIV/0! | E13: =E12+D13 -> #DIV/0! | F13: =IF(AND(E13<=0),"C",IF(E13<=0.8,"A",IF(E13<=0.95,"B","C"))) -> #DIV/0! | G13: =VLOOKUP(B$4:B$57,I$4:M$57,5,0) -> #DIV/0! | I13: MR Р1874 черн | K13: =J13/J$58 -> #DIV/0! | L13: =L12+K13 -> #DIV/0! | M13: =_xlfn.IFS(L13<80%,"A",L13<=95%,"B",L13>95%,"C") -> #DIV/0!
B14: MR Р1874 корич | D14: =C14/C$58 -> #DIV/0! | E14: =E13+D14 -> #DIV/0! | F14: =IF(AND(E14<=0),"C",IF(E14<=0.8,"A",IF(E14<=0.95,"B","C"))) -> #DIV/0! | G14: =VLOOKUP(B$4:B$57,I$4:M$57,5,0) -> #DIV/0! | I14: MR Р1874 корич | K14: =J14/J$58 -> #DIV/0! | L14: =L13+K14 -> #DIV/0! | M14: =_xlfn.IFS(L14<80%,"A",L14<=95%,"B",L14>95%,"C") -> #DIV/0!
B15: MR Р1886 черн | D15: =C15/C$58 -> #DIV/0! | E15: =E14+D15 -> #DIV/0! | F15: =IF(AND(E15<=0),"C",IF(E15<=0.8,"A",IF(E15<=0.95,"B","C"))) -> #DIV/0! | G15: =VLOOKUP(B$4:B$57,I$4:M$57,5,0) -> #DIV/0! | I15: MR Р1886 черн | K15: =J15/J$58 -> #DIV/0! | L15: =L14+K15 -> #DIV/0! | M15: =_xlfn.IFS(L15<80%,"A",L15<=95%,"B",L15>95%,"C") -> #DIV/0!
B16: MR Р1886 корич | D16: =C16/C$58 -> #DIV/0! | E16: =E15+D16 -> #DIV/0! | F16: =IF(AND(E16<=0),"C",IF(E16<=0.8,"A",IF(E16<=0.95,"B","C"))) -> #DIV/0! | G16: =VLOOKUP(B$4:B$57,I$4:M$57,5,0) -> #DIV/0! | I16: MR Р1886 корич | K16: =J16/J$58 -> #DIV/0! | L16: =L15+K16 -> #DIV/0! | M16: =_xlfn.IFS(L16<80%,"A",L16<=95%,"B",L16>95%,"C") -> #DIV/0!
B17: MR 1890 черн | D17: =C17/C$58 -> #DIV/0! | E17: =E16+D17 -> #DIV/0! | F17: =IF(AND(E17<=0),"C",IF(E17<=0.8,"A",IF(E17<=0.95,"B","C"))) -> #DIV/0! | G17: =VLOOKUP(B$4:B$57,I$4:M$57,5,0) -> #DIV/0! | I17: MR 1890 черн | K17: =J17/J$58 -> #DIV/0! | L17: =L16+K17 -> #DIV/0! | M17: =_xlfn.IFS(L17<80%,"A",L17<=95%,"B",L17>95%,"C") -> #DIV/0!
B18: MR 1890 желт | D18: =C18/C$58 -> #DIV/0! | E18: =E17+D18 -> #DIV/0! | F18: =IF(AND(E18<=0),"C",IF(E18<=0.8,"A",IF(E18<=0.95,"B","C"))) -> #DIV/0! | G18: =VLOOKUP(B$4:B$57,I$4:M$57,5,0) -> #DIV/0! | I18: MR 1890 желт | K18: =J18/J$58 -> #DIV/0! | L18: =L17+K18 -> #DIV/0! | M18: =_xlfn.IFS(L18<80%,"A",L18<=95%,"B",L18>95%,"C") -> #DIV/0!
... B27: qs009 | D27: =C27/C$58 -> #DIV/0! | E27: =E26+D27 -> #DIV/0! | F27: =IF(AND(E27<=0),"C",IF(E27<=0.8,"A",IF(E27<=0.95,"B","C"))) -> #DIV/0! | G27: =VLOOKUP(B$4:B$57,I$4:M$57,5,0) -> #DIV/0! | I27: qs009 | K27: =J27/J$58 -> #DIV/0! | L27: =L26+K27 -> #DIV/0! | M27: =_xlfn.IFS(L27<80%,"A",L27<=95%,"B",L27>95%,"C") -> #DIV/0!
B28: qs010 | D28: =C28/C$58 -> #DIV/0! | E28: =E24+D28 -> #DIV/0! | F28: =IF(AND(E28<=0),"C",IF(E28<=0.8,"A",IF(E28<=0.95,"B","C"))) -> #DIV/0! | G28: =VLOOKUP(B$4:B$57,I$4:M$57,5,0) -> #DIV/0! | I28: qs010 | K28: =J28/J$58 -> #DIV/0! | L28: =L24+K28 -> #DIV/0! | M28: =_xlfn.IFS(L28<80%,"A",L28<=95%,"B",L28>95%,"C") -> #DIV/0!
B29: qs011 | D29: =C29/C$58 -> #DIV/0! | E29: =E28+D29 -> #DIV/0! | F29: =IF(AND(E29<=0),"C",IF(E29<=0.8,"A",IF(E29<=0.95,"B","C"))) -> #DIV/0! | G29: =VLOOKUP(B$4:B$57,I$4:M$57,5,0) -> #DIV/0! | I29: qs011 | K29: =J29/J$58 -> #DIV/0! | L29: =L28+K29 -> #DIV/0! | M29: =_xlfn.IFS(L29<80%,"A",L29<=95%,"B",L29>95%,"C") -> #DIV/0!
B30: qs012 | D30: =C30/C$58 -> #DIV/0! | E30: =E29+D30 -> #DIV/0! | F30: =IF(AND(E30<=0),"C",IF(E30<=0.8,"A",IF(E30<=0.95,"B","C"))) -> #DIV/0! | G30: =VLOOKUP(B$4:B$57,I$4:M$57,5,0) -> #DIV/0! | I30: qs012 | K30: =J30/J$58 -> #DIV/0! | L30: =L29+K30 -> #DIV/0! | M30: =_xlfn.IFS(L30<80%,"A",L30<=95%,"B",L30>95%,"C") -> #DIV/0!
B31: qs013 | D31: =C31/C$58 -> #DIV/0! | E31: =E30+D31 -> #DIV/0! | F31: =IF(AND(E31<=0),"C",IF(E31<=0.8,"A",IF(E31<=0.95,"B","C"))) -> #DIV/0! | G31: =VLOOKUP(B$4:B$57,I$4:M$57,5,0) -> #DIV/0! | I31: qs013 | K31: =J31/J$58 -> #DIV/0! | L31: =L30+K31 -> #DIV/0! | M31: =_xlfn.IFS(L31<80%,"A",L31<=95%,"B",L31>95%,"C") -> #DIV/0!
B32: qs014 | D32: =C32/C$58 -> #DIV/0! | E32: =E31+D32 -> #DIV/0! | F32: =IF(AND(E32<=0),"C",IF(E32<=0.8,"A",IF(E32<=0.95,"B","C"))) -> #DIV/0! | G32: =VLOOKUP(B$4:B$57,I$4:M$57,5,0) -> #DIV/0! | I32: qs014 | K32: =J32/J$58 -> #DIV/0! | L32: =L31+K32 -> #DIV/0! | M32: =_xlfn.IFS(L32<80%,"A",L32<=95%,"B",L32>95%,"C") -> #DIV/0!
B33: qs015 | D33: =C33/C$58 -> #DIV/0! | E33: =E32+D33 -> #DIV/0! | F33: =IF(AND(E33<=0),"C",IF(E33<=0.8,"A",IF(E33<=0.95,"B","C"))) -> #DIV/0! | G33: =VLOOKUP(B$4:B$57,I$4:M$57,5,0) -> #DIV/0! | I33: qs015 | K33: =J33/J$58 -> #DIV/0! | L33: =L32+K33 -> #DIV/0! | M33: =_xlfn.IFS(L33<80%,"A",L33<=95%,"B",L33>95%,"C") -> #DIV/0!
B34: qs001 Ж | D34: =C34/C$58 -> #DIV/0! | E34: =E33+D34 -> #DIV/0! | F34: =IF(AND(E34<=0),"C",IF(E34<=0.8,"A",IF(E34<=0.95,"B","C"))) -> #DIV/0! | G34: =VLOOKUP(B$4:B$57,I$4:M$57,5,0) -> #DIV/0! | I34: qs001 Ж | K34: =J34/J$58 -> #DIV/0! | L34: =L33+K34 -> #DIV/0! | M34: =_xlfn.IFS(L34<80%,"A",L34<=95%,"B",L34>95%,"C") -> #DIV/0!
B35: qs010ж | D35: =C35/C$58 -> #DIV/0! | E35: =E34+D35 -> #DIV/0! | F35: =IF(AND(E35<=0),"C",IF(E35<=0.8,"A",IF(E35<=0.95,"B","C"))) -> #DIV/0! | G35: =VLOOKUP(B$4:B$57,I$4:M$57,5,0) -> #DIV/0! | I35: qs010ж | K35: =J35/J$58 -> #DIV/0! | L35: =L34+K35 -> #DIV/0! | M35: =_xlfn.IFS(L35<80%,"A",L35<=95%,"B",L35>95%,"C") -> #DIV/0!
B36: qs011ж | D36: =C36/C$58 -> #DIV/0! | E36: =E35+D36 -> #DIV/0! | F36: =IF(AND(E36<=0),"C",IF(E36<=0.8,"A",IF(E36<=0.95,"B","C"))) -> #DIV/0! | G36: =VLOOKUP(B$4:B$57,I$4:M$57,5,0) -> #DIV/0! | I36: qs011ж | K36: =J36/J$58 -> #DIV/0! | L36: =L35+K36 -> #DIV/0! | M36: =_xlfn.IFS(L36<80%,"A",L36<=95%,"B",L36>95%,"C") -> #DIV/0!
B37: qs012ж | D37: =C37/C$58 -> #DIV/0! | E37: =E36+D37 -> #DIV/0! | F37: =IF(AND(E37<=0),"C",IF(E37<=0.8,"A",IF(E37<=0.95,"B","C"))) -> #DIV/0! | G37: =VLOOKUP(B$4:B$57,I$4:M$57,5,0) -> #DIV/0! | I37: qs012ж | K37: =J37/J$58 -> #DIV/0! | L37: =L36+K37 -> #DIV/0! | M37: =_xlfn.IFS(L37<80%,"A",L37<=95%,"B",L37>95%,"C") -> #DIV/0!
B38: 2038ч/б | D38: =C38/C$58 -> #DIV/0! | E38: =E37+D38 -> #DIV/0! | F38: =IF(AND(E38<=0),"C",IF(E38<=0.8,"A",IF(E38<=0.95,"B","C"))) -> #DIV/0! | G38: =VLOOKUP(B$4:B$57,I$4:M$57,5,0) -> #DIV/0! | I38: 2038ч/б | K38: =J38/J$58 -> #DIV/0! | L38: =L37+K38 -> #DIV/0! | M38: =_xlfn.IFS(L38<80%,"A",L38<=95%,"B",L38>95%,"C") -> #DIV/0!
B39: 2038красный | D39: =C39/C$58 -> #DIV/0! | E39: =E38+D39 -> #DIV/0! | F39: =IF(AND(E39<=0),"C",IF(E39<=0.8,"A",IF(E39<=0.95,"B","C"))) -> #DIV/0! | G39: =VLOOKUP(B$4:B$57,I$4:M$57,5,0) -> #DIV/0! | I39: 2038красный | K39: =J39/J$58 -> #DIV/0! | L39: =L38+K39 -> #DIV/0! | M39: =_xlfn.IFS(L39<80%,"A",L39<=95%,"B",L39>95%,"C") -> #DIV/0!
B40: 2100черный | D40: =C40/C$58 -> #DIV/0! | E40: =E39+D40 -> #DIV/0! | F40: =IF(AND(E40<=0),"C",IF(E40<=0.8,"A",IF(E40<=0.95,"B","C"))) -> #DIV/0! | G40: =VLOOKUP(B$4:B$57,I$4:M$57,5,0) -> #DIV/0! | I40: 2100черный | K40: =J40/J$58 -> #DIV/0! | L40: =L39+K40 -> #DIV/0! | M40: =_xlfn.IFS(L40<80%,"A",L40<=95%,"B",L40>95%,"C") -> #DIV/0!
... B57: 8852 | D57: =C57/C$58 -> #DIV/0! | E57: =E56+D57 -> #DIV/0! | F57: =IF(AND(E57<=0),"C",IF(E57<=0.8,"A",IF(E57<=0.95,"B","C"))) -> #DIV/0! | G57: =VLOOKUP(B$4:B$57,I$4:M$57,5,0) -> #DIV/0! | I57: 8852 | K57: =J57/J$58 -> #DIV/0! | L57: =L56+K57 -> #DIV/0! | M57: =_xlfn.IFS(L57<80%,"A",L57<=95%,"B",L57>95%,"C") -> #DIV/0!
C58: =SUM(C4:C44) -> 0 | D58: =SUM(D4:D44) -> #DIV/0! | J58: =SUM(J4:J44) -> 0 | K58: =SUM(K4:K44) -> #DIV/0!
C61: Прибыль | D61: % прибыль | E61: Доля | F61: ABC прибыль | G61: ABC кол-во | J61: Кол-во | K61: % кол-во | L61: Доля | M61: ABC кол-во
D62: =C62/C$114 -> #DIV/0! | E62: =D62 -> #DIV/0! | F62: =IF(AND(E62<=0),"C",IF(E62<=0.8,"A",IF(E62<=0.95,"B","C"))) -> #DIV/0! | G62: =VLOOKUP(B62:B113,I$62:M$113,5,0) -> #N/A | K62: =J62/J$114 -> #DIV/0! | L62: =K62 -> #DIV/0! | M62: =_xlfn.IFS(L62<80%,"A",L62<=95%,"B",L62>95%,"C") -> #DIV/0!
D63: =C63/C$114 -> #DIV/0! | E63: =D63+E62 -> #DIV/0! | F63: =IF(AND(E63<=0),"C",IF(E63<=0.8,"A",IF(E63<=0.95,"B","C"))) -> #DIV/0! | G63: =VLOOKUP(B63:B114,I$62:M$113,5,0) -> #N/A | K63: =J63/J$114 -> #DIV/0! | L63: =K63+L62 -> #DIV/0! | M63: =_xlfn.IFS(L63<80%,"A",L63<=95%,"B",L63>95%,"C") -> #DIV/0!
D64: =C64/C$114 -> #DIV/0! | E64: =D64+E63 -> #DIV/0! | F64: =IF(AND(E64<=0),"C",IF(E64<=0.8,"A",IF(E64<=0.95,"B","C"))) -> #DIV/0! | G64: =VLOOKUP(B64:B115,I$62:M$113,5,0) -> #N/A | K64: =J64/J$114 -> #DIV/0! | L64: =K64+L63 -> #DIV/0! | M64: =_xlfn.IFS(L64<80%,"A",L64<=95%,"B",L64>95%,"C") -> #DIV/0!
D65: =C65/C$114 -> #DIV/0! | E65: =D65+E64 -> #DIV/0! | F65: =IF(AND(E65<=0),"C",IF(E65<=0.8,"A",IF(E65<=0.95,"B","C"))) -> #DIV/0! | G65: =VLOOKUP(B65:B116,I$62:M$113,5,0) -> #N/A | K65: =J65/J$114 -> #DIV/0! | L65: =K65+L64 -> #DIV/0! | M65: =_xlfn.IFS(L65<80%,"A",L65<=95%,"B",L65>95%,"C") -> #DIV/0!
D66: =C66/C$114 -> #DIV/0! | E66: =D66+E65 -> #DIV/0! | F66: =IF(AND(E66<=0),"C",IF(E66<=0.8,"A",IF(E66<=0.95,"B","C"))) -> #DIV/0! | G66: =VLOOKUP(B66:B117,I$62:M$113,5,0) -> #N/A | K66: =J66/J$114 -> #DIV/0! | L66: =K66+L65 -> #DIV/0! | M66: =_xlfn.IFS(L66<80%,"A",L66<=95%,"B",L66>95%,"C") -> #DIV/0!
D67: =C67/C$114 -> #DIV/0! | E67: =D67+E66 -> #DIV/0! | F67: =IF(AND(E67<=0),"C",IF(E67<=0.8,"A",IF(E67<=0.95,"B","C"))) -> #DIV/0! | G67: =VLOOKUP(B67:B118,I$62:M$113,5,0) -> #N/A | K67: =J67/J$114 -> #DIV/0! | L67: =K67+L66 -> #DIV/0! | M67: =_xlfn.IFS(L67<80%,"A",L67<=95%,"B",L67>95%,"C") -> #DIV/0!
...

Sheet АВС 12
B2: ОЧКИ
C3: Прибыль | D3: % прибыль | E3: Доля | F3: ABC прибыль | G3: ABC кол-во | J3: Кол-во | K3: % кол-во | L3: Доля | M3: ABC кол-во
B4: Qs черн Сул | C4: ='Юнит 12'!AL4 -> 127787.88 | D4: =C4/C$58 -> 0.36810085 | E4: =D4 -> 0.36810085 | F4: =IF(AND(E4<=0),"C",IF(E4<=0.8,"A",IF(E4<=0.95,"B","C"))) -> A | G4: =VLOOKUP(B$4:B$57,I$4:M$57,5,0) -> A | I4: Qs черн Сул | J4: ='Юнит 12'!S4 -> 331 | K4: =J4/J$58 -> 0.35783784 | L4: =K4 -> 0.35783784 | M4: =_xlfn.IFS(L4<80%,"A",L4<=95%,"B",L4>95%,"C") -> A | P4: A | Q4: 0.8
B5: Черные с железкой Сул | C5: ='Юнит 12'!AL3 -> 38176.831 | D5: =C5/C$58 -> 0.10997071 | E5: =E4+D5 -> 0.47807157 | F5: =IF(AND(E5<=0),"C",IF(E5<=0.8,"A",IF(E5<=0.95,"B","C"))) -> A | G5: =VLOOKUP(B$4:B$57,I$4:M$57,5,0) -> A | I5: Черные с железкой Сул | J5: ='Юнит 12'!S3 -> 119 | K5: =J5/J$58 -> 0.12864865 | L5: =L4+K5 -> 0.48648649 | M5: =_xlfn.IFS(L5<80%,"A",L5<=95%,"B",L5>95%,"C") -> A | P5: B | Q5: 0.15
B6: flip желтые Сул | C6: ='Юнит 12'!AL8 -> 32615.135 | D6: =C6/C$58 -> 0.093949908 | E6: =E5+D6 -> 0.57202147 | F6: =IF(AND(E6<=0),"C",IF(E6<=0.8,"A",IF(E6<=0.95,"B","C"))) -> A | G6: =VLOOKUP(B$4:B$57,I$4:M$57,5,0) -> A | I6: flip желтые Сул | J6: ='Юнит 12'!S8 -> 74 | K6: =J6/J$58 -> 0.08 | L6: =L5+K6 -> 0.56648649 | M6: =_xlfn.IFS(L6<80%,"A",L6<=95%,"B",L6>95%,"C") -> A | P6: C | Q6: 0.05
B7: qs002 | C7: ='Юнит 12'!AL20 -> 23606.43 | D7: =C7/C$58 -> 0.067999777 | E7: =E6+D7 -> 0.64002125 | F7: =IF(AND(E7<=0),"C",IF(E7<=0.8,"A",IF(E7<=0.95,"B","C"))) -> A | G7: =VLOOKUP(B$4:B$57,I$4:M$57,5,0) -> A | I7: Qs син Сул | J7: ='Юнит 12'!S5 -> 58 | K7: =J7/J$58 -> 0.062702703 | L7: =L6+K7 -> 0.62918919 | M7: =_xlfn.IFS(L7<80%,"A",L7<=95%,"B",L7>95%,"C") -> A
B8: MR8854 C2 Сул | C8: ='Юнит 12'!AL9 -> 20677.466 | D8: =C8/C$58 -> 0.059562714 | E8: =E7+D8 -> 0.69958397 | F8: =IF(AND(E8<=0),"C",IF(E8<=0.8,"A",IF(E8<=0.95,"B","C"))) -> A | G8: =VLOOKUP(B$4:B$57,I$4:M$57,5,0) -> A | I8: qs002 | J8: ='Юнит 12'!S20 -> 41 | K8: =J8/J$58 -> 0.044324324 | L8: =L7+K8 -> 0.67351351 | M8: =_xlfn.IFS(L8<80%,"A",L8<=95%,"B",L8>95%,"C") -> A
B9: Qs син Сул | C9: ='Юнит 12'!AL5 -> 19385.896 | D9: =C9/C$58 -> 0.05584227 | E9: =E8+D9 -> 0.75542624 | F9: =IF(AND(E9<=0),"C",IF(E9<=0.8,"A",IF(E9<=0.95,"B","C"))) -> A | G9: =VLOOKUP(B$4:B$57,I$4:M$57,5,0) -> A | I9: MR8854 C2 Сул | J9: ='Юнит 12'!S9 -> 40 | K9: =J9/J$58 -> 0.043243243 | L9: =L8+K9 -> 0.71675676 | M9: =_xlfn.IFS(L9<80%,"A",L9<=95%,"B",L9>95%,"C") -> A
B10: Qs желт Сул | C10: ='Юнит 12'!AL6 -> 15746.161 | D10: =C10/C$58 -> 0.045357788 | E10: =E9+D10 -> 0.80078402 | F10: =IF(AND(E10<=0),"C",IF(E10<=0.8,"A",IF(E10<=0.95,"B","C"))) -> B | G10: =VLOOKUP(B$4:B$57,I$4:M$57,5,0) -> A | I10: Qs желт Сул | J10: ='Юнит 12'!S6 -> 38 | K10: =J10/J$58 -> 0.041081081 | L10: =L9+K10 -> 0.75783784 | M10: =_xlfn.IFS(L10<80%,"A",L10<=95%,"B",L10>95%,"C") -> A
B11: qs001 | C11: ='Юнит 12'!AL19 -> 9290.4056 | D11: =C11/C$58 -> 0.026761586 | E11: =E10+D11 -> 0.82754561 | F11: =IF(AND(E11<=0),"C",IF(E11<=0.8,"A",IF(E11<=0.95,"B","C"))) -> B | G11: =VLOOKUP(B$4:B$57,I$4:M$57,5,0) -> A | I11: MR 1890 желт | J11: ='Юнит 12'!S17 -> 18 | K11: =J11/J$58 -> 0.019459459 | L11: =L10+K11 -> 0.7772973 | M11: =_xlfn.IFS(L11<80%,"A",L11<=95%,"B",L11>95%,"C") -> A
B12: qs014 | C12: ='Юнит 12'!AL31 -> 7940.4738 | D12: =C12/C$58 -> 0.022873024 | E12: =E11+D12 -> 0.85041863 | F12: =IF(AND(E12<=0),"C",IF(E12<=0.8,"A",IF(E12<=0.95,"B","C"))) -> B | G12: =VLOOKUP(B$4:B$57,I$4:M$57,5,0) -> B | I12: qs001 | J12: ='Юнит 12'!S19 -> 18 | K12: =J12/J$58 -> 0.019459459 | L12: =L11+K12 -> 0.79675676 | M12: =_xlfn.IFS(L12<80%,"A",L12<=95%,"B",L12>95%,"C") -> A
B13: qs006 | C13: ='Юнит 12'!AL23 -> 7629.0002 | D13: =C13/C$58 -> 0.021975805 | E13: =E12+D13 -> 0.87239444 | F13: =IF(AND(E13<=0),"C",IF(E13<=0.8,"A",IF(E13<=0.95,"B","C"))) -> B | G13: =VLOOKUP(B$4:B$57,I$4:M$57,5,0) -> B | I13: qs006 | J13: ='Юнит 12'!S23 -> 16 | K13: =J13/J$58 -> 0.017297297 | L13: =L12+K13 -> 0.81405405 | M13: =_xlfn.IFS(L13<80%,"A",L13<=95%,"B",L13>95%,"C") -> B
B14: qs010ж | C14: ='Юнит 12'!AL34 -> 7130.7921 | D14: =C14/C$58 -> 0.020540686 | E14: =E13+D14 -> 0.89293513 | F14: =IF(AND(E14<=0),"C",IF(E14<=0.8,"A",IF(E14<=0.95,"B","C"))) -> B | G14: =VLOOKUP(B$4:B$57,I$4:M$57,5,0) -> B | I14: qs014 | J14: ='Юнит 12'!S31 -> 16 | K14: =J14/J$58 -> 0.017297297 | L14: =L13+K14 -> 0.83135135 | M14: =_xlfn.IFS(L14<80%,"A",L14<=95%,"B",L14>95%,"C") -> B
B15: qs013 | C15: ='Юнит 12'!AL30 -> 4296.4329 | D15: =C15/C$58 -> 0.01237614 | E15: =E14+D15 -> 0.90531127 | F15: =IF(AND(E15<=0),"C",IF(E15<=0.8,"A",IF(E15<=0.95,"B","C"))) -> B | G15: =VLOOKUP(B$4:B$57,I$4:M$57,5,0) -> B | I15: MR 1890 черн | J15: ='Юнит 12'!S16 -> 15 | K15: =J15/J$58 -> 0.016216216 | L15: =L14+K15 -> 0.84756757 | M15: =_xlfn.IFS(L15<80%,"A",L15<=95%,"B",L15>95%,"C") -> B
B16: MR 1890 корич | C16: ='Юнит 12'!AL18 -> 4291.8395 | D16: =C16/C$58 -> 0.012362908 | E16: =E15+D16 -> 0.91767417 | F16: =IF(AND(E16<=0),"C",IF(E16<=0.8,"A",IF(E16<=0.95,"B","C"))) -> B | G16: =VLOOKUP(B$4:B$57,I$4:M$57,5,0) -> B | I16: flip черные Сул | J16: ='Юнит 12'!S7 -> 14 | K16: =J16/J$58 -> 0.015135135 | L16: =L15+K16 -> 0.8627027 | M16: =_xlfn.IFS(L16<80%,"A",L16<=95%,"B",L16>95%,"C") -> B
B17: MR 1819 корич | C17: ='Юнит 12'!AL11 -> 3590.8944 | D17: =C17/C$58 -> 0.010343793 | E17: =E16+D17 -> 0.92801797 | F17: =IF(AND(E17<=0),"C",IF(E17<=0.8,"A",IF(E17<=0.95,"B","C"))) -> B | G17: =VLOOKUP(B$4:B$57,I$4:M$57,5,0) -> B | I17: qs010ж | J17: ='Юнит 12'!S34 -> 14 | K17: =J17/J$58 -> 0.015135135 | L17: =L16+K17 -> 0.87783784 | M17: =_xlfn.IFS(L17<80%,"A",L17<=95%,"B",L17>95%,"C") -> B
B18: qs003 | C18: ='Юнит 12'!AL21 -> 3250.7054 | D18: =C18/C$58 -> 0.0093638573 | E18: =E17+D18 -> 0.93738182 | F18: =IF(AND(E18<=0),"C",IF(E18<=0.8,"A",IF(E18<=0.95,"B","C"))) -> B | G18: =VLOOKUP(B$4:B$57,I$4:M$57,5,0) -> C | I18: qs007 | J18: ='Юнит 12'!S24 -> 12 | K18: =J18/J$58 -> 0.012972973 | L18: =L17+K18 -> 0.89081081 | M18: =_xlfn.IFS(L18<80%,"A",L18<=95%,"B",L18>95%,"C") -> B
B19: MR Р1874 черн | C19: ='Юнит 12'!AL12 -> 3097.0137 | D19: =C19/C$58 -> 0.0089211389 | E19: =E18+D19 -> 0.94630296 | F19: =IF(AND(E19<=0),"C",IF(E19<=0.8,"A",IF(E19<=0.95,"B","C"))) -> B | G19: =VLOOKUP(B$4:B$57,I$4:M$57,5,0) -> B | I19: MR 1819 корич | J19: ='Юнит 12'!S11 -> 10 | K19: =J19/J$58 -> 0.010810811 | L19: =L18+K19 -> 0.90162162 | M19: =_xlfn.IFS(L19<80%,"A",L19<=95%,"B",L19>95%,"C") -> B
B20: MR Р1886 черн | C20: ='Юнит 12'!AL14 -> 2583.3919 | D20: =C20/C$58 -> 0.0074416197 | E20: =E19+D20 -> 0.95374458 | F20: =IF(AND(E20<=0),"C",IF(E20<=0.8,"A",IF(E20<=0.95,"B","C"))) -> C | G20: =VLOOKUP(B$4:B$57,I$4:M$57,5,0) -> B | I20: qs013 | J20: ='Юнит 12'!S30 -> 10 | K20: =J20/J$58 -> 0.010810811 | L20: =L19+K20 -> 0.91243243 | M20: =_xlfn.IFS(L20<80%,"A",L20<=95%,"B",L20>95%,"C") -> B
B21: MR Р1886 корич | C21: ='Юнит 12'!AL15 -> 2569.23 | D21: =C21/C$58 -> 0.0074008254 | E21: =E20+D21 -> 0.96114541 | F21: =IF(AND(E21<=0),"C",IF(E21<=0.8,"A",IF(E21<=0.95,"B","C"))) -> C | G21: =VLOOKUP(B$4:B$57,I$4:M$57,5,0) -> B | I21: MR Р1874 черн | J21: ='Юнит 12'!S12 -> 8 | K21: =J21/J$58 -> 0.0086486486 | L21: =L20+K21 -> 0.92108108 | M21: =_xlfn.IFS(L21<80%,"A",L21<=95%,"B",L21>95%,"C") -> B
B22: qs010 | C22: ='Юнит 12'!AL27 -> 2198.3772 | D22: =C22/C$58 -> 0.006332561 | E22: =E21+D22 -> 0.96747797 | F22: =IF(AND(E22<=0),"C",IF(E22<=0.8,"A",IF(E22<=0.95,"B","C"))) -> C | G22: =VLOOKUP(B$4:B$57,I$4:M$57,5,0) -> C | I22: MR Р1886 корич | J22: ='Юнит 12'!S15 -> 8 | K22: =J22/J$58 -> 0.0086486486 | L22: =L21+K22 -> 0.92972973 | M22: =_xlfn.IFS(L22<80%,"A",L22<=95%,"B",L22>95%,"C") -> B
B23: qs008 | C23: ='Юнит 12'!AL25 -> 2015.4121 | D23: =C23/C$58 -> 0.0058055188 | E23: =E22+D23 -> 0.97328349 | F23: =IF(AND(E23<=0),"C",IF(E23<=0.8,"A",IF(E23<=0.95,"B","C"))) -> C | G23: =VLOOKUP(B$4:B$57,I$4:M$57,5,0) -> C | I23: MR 1890 корич | J23: ='Юнит 12'!S18 -> 8 | K23: =J23/J$58 -> 0.0086486486 | L23: =L22+K23 -> 0.93837838 | M23: =_xlfn.IFS(L23<80%,"A",L23<=95%,"B",L23>95%,"C") -> B
B24: qs009 | C24: ='Юнит 12'!AL26 -> 1987.8121 | D24: =C24/C$58 -> 0.0057260153 | E24: =E23+D24 -> 0.9790095 | F24: =IF(AND(E24<=0),"C",IF(E24<=0.8,"A",IF(E24<=0.95,"B","C"))) -> C | G24: =VLOOKUP(B$4:B$57,I$4:M$57,5,0) -> C | I24: MR Р1886 черн | J24: ='Юнит 12'!S14 -> 7 | K24: =J24/J$58 -> 0.0075675676 | L24: =L23+K24 -> 0.94594595 | M24: =_xlfn.IFS(L24<80%,"A",L24<=95%,"B",L24>95%,"C") -> B
B25: 2100черный | C25: ='Юнит 12'!AL39 -> 1415.8346 | D25: =C25/C$58 -> 0.0040783989 | E25: =E24+D25 -> 0.9830879 | F25: =IF(AND(E25<=0),"C",IF(E25<=0.8,"A",IF(E25<=0.95,"B","C"))) -> C | G25: =VLOOKUP(B$4:B$57,I$4:M$57,5,0) -> C | I25: qs003 | J25: ='Юнит 12'!S21 -> 6 | K25: =J25/J$58 -> 0.0064864865 | L25: =L24+K25 -> 0.95243243 | M25: =_xlfn.IFS(L25<80%,"A",L25<=95%,"B",L25>95%,"C") -> C
B26: 2100красный | C26: ='Юнит 12'!AL40 -> 996.27585 | D26: =C26/C$58 -> 0.002869834 | E26: =E25+D26 -> 0.98595774 | F26: =IF(AND(E26<=0),"C",IF(E26<=0.8,"A",IF(E26<=0.95,"B","C"))) -> C | G26: =VLOOKUP(B$4:B$57,I$4:M$57,5,0) -> C | I26: qs010 | J26: ='Юнит 12'!S27 -> 5 | K26: =J26/J$58 -> 0.0054054054 | L26: =L25+K26 -> 0.95783784 | M26: =_xlfn.IFS(L26<80%,"A",L26<=95%,"B",L26>95%,"C") -> C
B27: qs011 | C27: ='Юнит 12'!AL28 -> 839.6 | D27: =C27/C$58 -> 0.0024185196 | E27: =E26+D27 -> 0.98837626 | F27: =IF(AND(E27<=0),"C",IF(E27<=0.8,"A",IF(E27<=0.95,"B","C"))) -> C | G27: =VLOOKUP(B$4:B$57,I$4:M$57,5,0) -> C | I27: qs008 | J27: ='Юнит 12'!S25 -> 4 | K27: =J27/J$58 -> 0.0043243243 | L27: =L26+K27 -> 0.96216216 | M27: =_xlfn.IFS(L27<80%,"A",L27<=95%,"B",L27>95%,"C") -> C
B28: qs012ж | C28: ='Юнит 12'!AL36 -> 821.24859 | D28: =C28/C$58 -> 0.0023656572 | E28: =E24+D28 -> 0.98137516 | F28: =IF(AND(E28<=0),"C",IF(E28<=0.8,"A",IF(E28<=0.95,"B","C"))) -> C | G28: =VLOOKUP(B$4:B$57,I$4:M$57,5,0) -> C | I28: qs009 | J28: ='Юнит 12'!S26 -> 4 | K28: =J28/J$58 -> 0.0043243243 | L28: =L24+K28 -> 0.95027027 | M28: =_xlfn.IFS(L28<80%,"A",L28<=95%,"B",L28>95%,"C") -> C
B29: qs005 | C29: ='Юнит 12'!AL22 -> 694.26068 | D29: =C29/C$58 -> 0.0019998607 | E29: =E28+D29 -> 0.98337502 | F29: =IF(AND(E29<=0),"C",IF(E29<=0.8,"A",IF(E29<=0.95,"B","C"))) -> C | G29: =VLOOKUP(B$4:B$57,I$4:M$57,5,0) -> C | I29: qs015 | J29: ='Юнит 12'!S32 -> 4 | K29: =J29/J$58 -> 0.0043243243 | L29: =L28+K29 -> 0.95459459 | M29: =_xlfn.IFS(L29<80%,"A",L29<=95%,"B",L29>95%,"C") -> C
B30: qs011ж | C30: ='Юнит 12'!AL35 -> 588.62859 | D30: =C30/C$58 -> 0.0016955809 | E30: =E29+D30 -> 0.9850706 | F30: =IF(AND(E30<=0),"C",IF(E30<=0.8,"A",IF(E30<=0.95,"B","C"))) -> C | G30: =VLOOKUP(B$4:B$57,I$4:M$57,5,0) -> C | I30: 2100черный | J30: ='Юнит 12'!S39 -> 4 | K30: =J30/J$58 -> 0.0043243243 | L30: =L29+K30 -> 0.95891892 | M30: =_xlfn.IFS(L30<80%,"A",L30<=95%,"B",L30>95%,"C") -> C
B31: qs012 | C31: ='Юнит 12'!AL29 -> 495.7 | D31: =C31/C$58 -> 0.0014278944 | E31: =E30+D31 -> 0.9864985 | F31: =IF(AND(E31<=0),"C",IF(E31<=0.8,"A",IF(E31<=0.95,"B","C"))) -> C | G31: =VLOOKUP(B$4:B$57,I$4:M$57,5,0) -> C | I31: 6008 | J31: ='Юнит 12'!S43 -> 4 | K31: =J31/J$58 -> 0.0043243243 | L31: =L30+K31 -> 0.96324324 | M31: =_xlfn.IFS(L31<80%,"A",L31<=95%,"B",L31>95%,"C") -> C
B32: MR Р1874 корич | C32: ='Юнит 12'!AL13 -> 486.15 | D32: =C32/C$58 -> 0.001400385 | E32: =E31+D32 -> 0.98789888 | F32: =IF(AND(E32<=0),"C",IF(E32<=0.8,"A",IF(E32<=0.95,"B","C"))) -> C | G32: =VLOOKUP(B$4:B$57,I$4:M$57,5,0) -> C | I32: qs011 | J32: ='Юнит 12'!S28 -> 3 | K32: =J32/J$58 -> 0.0032432432 | L32: =L31+K32 -> 0.96648649 | M32: =_xlfn.IFS(L32<80%,"A",L32<=95%,"B",L32>95%,"C") -> C
B33: 2104 | C33: ='Юнит 12'!AL42 -> 388.23727 | D33: =C33/C$58 -> 0.0011183414 | E33: =E32+D33 -> 0.98901722 | F33: =IF(AND(E33<=0),"C",IF(E33<=0.8,"A",IF(E33<=0.95,"B","C"))) -> C | G33: =VLOOKUP(B$4:B$57,I$4:M$57,5,0) -> C | I33: 2100красный | J33: ='Юнит 12'!S40 -> 3 | K33: =J33/J$58 -> 0.0032432432 | L33: =L32+K33 -> 0.96972973 | M33: =_xlfn.IFS(L33<80%,"A",L33<=95%,"B",L33>95%,"C") -> C
B34: qs007 | C34: ='Юнит 12'!AL24 -> 302.6523 | D34: =C34/C$58 -> 0.0008718086 | E34: =E33+D34 -> 0.98988903 | F34: =IF(AND(E34<=0),"C",IF(E34<=0.8,"A",IF(E34<=0.95,"B","C"))) -> C | G34: =VLOOKUP(B$4:B$57,I$4:M$57,5,0) -> B | I34: MR 1819 черн | J34: ='Юнит 12'!S10 -> 2 | K34: =J34/J$58 -> 0.0021621622 | L34: =L33+K34 -> 0.97189189 | M34: =_xlfn.IFS(L34<80%,"A",L34<=95%,"B",L34>95%,"C") -> C
B35: qs015 | C35: ='Юнит 12'!AL32 -> 258.35811 | D35: =C35/C$58 -> 0.00074421645 | E35: =E34+D35 -> 0.99063325 | F35: =IF(AND(E35<=0),"C",IF(E35<=0.8,"A",IF(E35<=0.95,"B","C"))) -> C | G35: =VLOOKUP(B$4:B$57,I$4:M$57,5,0) -> C | I35: qs005 | J35: ='Юнит 12'!S22 -> 2 | K35: =J35/J$58 -> 0.0021621622 | L35: =L34+K35 -> 0.97405405 | M35: =_xlfn.IFS(L35<80%,"A",L35<=95%,"B",L35>95%,"C") -> C
B36: qs001 Ж | C36: ='Юнит 12'!AL33 -> 0 | D36: =C36/C$58 -> 0 | E36: =E35+D36 -> 0.99063325 | F36: =IF(AND(E36<=0),"C",IF(E36<=0.8,"A",IF(E36<=0.95,"B","C"))) -> C | G36: =VLOOKUP(B$4:B$57,I$4:M$57,5,0) -> C | I36: qs011ж | J36: ='Юнит 12'!S35 -> 2 | K36: =J36/J$58 -> 0.0021621622 | L36: =L35+K36 -> 0.97621622 | M36: =_xlfn.IFS(L36<80%,"A",L36<=95%,"B",L36>95%,"C") -> C
B37: 123черный | C37: ='Юнит 12'!AL44 -> 0 | D37: =C37/C$58 -> 0 | E37: =E36+D37 -> 0.99063325 | F37: =IF(AND(E37<=0),"C",IF(E37<=0.8,"A",IF(E37<=0.95,"B","C"))) -> C | G37: =VLOOKUP(B$4:B$57,I$4:M$57,5,0) -> C | I37: qs012ж | J37: ='Юнит 12'!S36 -> 2 | K37: =J37/J$58 -> 0.0021621622 | L37: =L36+K37 -> 0.97837838 | M37: =_xlfn.IFS(L37<80%,"A",L37<=95%,"B",L37>95%,"C") -> C
B38: 123метал | C38: ='Юнит 12'!AL45 -> 0 | D38: =C38/C$58 -> 0 | E38: =E37+D38 -> 0.99063325 | F38: =IF(AND(E38<=0),"C",IF(E38<=0.8,"A",IF(E38<=0.95,"B","C"))) -> C | G38: =VLOOKUP(B$4:B$57,I$4:M$57,5,0) -> C | I38: 2100фиолетовый | J38: ='Юнит 12'!S41 -> 2 | K38: =J38/J$58 -> 0.0021621622 | L38: =L37+K38 -> 0.98054054 | M38: =_xlfn.IFS(L38<80%,"A",L38<=95%,"B",L38>95%,"C") -> C
B39: 180ч/б | C39: ='Юнит 12'!AL46 -> 0 | D39: =C39/C$58 -> 0 | E39: =E38+D39 -> 0.99063325 | F39: =IF(AND(E39<=0),"C",IF(E39<=0.8,"A",IF(E39<=0.95,"B","C"))) -> C | G39: =VLOOKUP(B$4:B$57,I$4:M$57,5,0) -> C | I39: MR Р1874 корич | J39: ='Юнит 12'!S13 -> 1 | K39: =J39/J$58 -> 0.0010810811 | L39: =L38+K39 -> 0.98162162 | M39: =_xlfn.IFS(L39<80%,"A",L39<=95%,"B",L39>95%,"C") -> C
B40: 180узор | C40: ='Юнит 12'!AL47 -> 0 | D40: =C40/C$58 -> 0 | E40: =E39+D40 -> 0.99063325 | F40: =IF(AND(E40<=0),"C",IF(E40<=0.8,"A",IF(E40<=0.95,"B","C"))) -> C | G40: =VLOOKUP(B$4:B$57,I$4:M$57,5,0) -> C | I40: qs012 | J40: ='Юнит 12'!S29 -> 1 | K40: =J40/J$58 -> 0.0010810811 | L40: =L39+K40 -> 0.9827027 | M40: =_xlfn.IFS(L40<80%,"A",L40<=95%,"B",L40>95%,"C") -> C
B41: 580черный | C41: ='Юнит 12'!AL48 -> 0 | D41: =C41/C$58 -> 0 | E41: =E40+D41 -> 0.99063325 | F41: =IF(AND(E41<=0),"C",IF(E41<=0.8,"A",IF(E41<=0.95,"B","C"))) -> C | G41: =VLOOKUP(B$4:B$57,I$4:M$57,5,0) -> C | I41: 2104 | J41: ='Юнит 12'!S42 -> 1 | K41: =J41/J$58 -> 0.0010810811 | L41: =L40+K41 -> 0.98378378 | M41: =_xlfn.IFS(L41<80%,"A",L41<=95%,"B",L41>95%,"C") -> C
...

Sheet АВС 11
B2: ОЧКИ
C3: Прибыль | D3: % прибыль | E3: Доля | F3: ABC прибыль | G3: ABC кол-во | J3: Кол-во | K3: % кол-во | L3: Доля | M3: ABC кол-во
B4: Qs черн Сул | C4: ='Юнит 11'!AL4 -> 90111.226 | D4: =C4/C$45 -> 0.34208721 | E4: =D4 -> 0.34208721 | F4: =IF(AND(E4<=0),"C",IF(E4<=0.8,"A",IF(E4<=0.95,"B","C"))) -> A | G4: =VLOOKUP(B$4:B$44,I$4:M$44,5,0) -> A | I4: Qs черн Сул | J4: ='Юнит 11'!S4 -> 252 | K4: =J4/J$45 -> 0.32142857 | L4: =K4 -> 0.32142857 | M4: =_xlfn.IFS(L4<80%,"A",L4<=95%,"B",L4>95%,"C") -> A | P4: A | Q4: 0.8
B5: Черные с железкой Сул | C5: ='Юнит 11'!AL3 -> 40807.465 | D5: =C5/C$45 -> 0.15491646 | E5: =E4+D5 -> 0.49700367 | F5: =IF(AND(E5<=0),"C",IF(E5<=0.8,"A",IF(E5<=0.95,"B","C"))) -> A | G5: =VLOOKUP(B$4:B$44,I$4:M$44,5,0) -> A | I5: Черные с железкой Сул | J5: ='Юнит 11'!S3 -> 112 | K5: =J5/J$45 -> 0.14285714 | L5: =L4+K5 -> 0.46428571 | M5: =_xlfn.IFS(L5<80%,"A",L5<=95%,"B",L5>95%,"C") -> A | P5: B | Q5: 0.15
B6: flip желтые Сул | C6: ='Юнит 11'!AL8 -> 20439.649 | D6: =C6/C$45 -> 0.077594577 | E6: =E5+D6 -> 0.57459825 | F6: =IF(AND(E6<=0),"C",IF(E6<=0.8,"A",IF(E6<=0.95,"B","C"))) -> A | G6: =VLOOKUP(B$4:B$44,I$4:M$44,5,0) -> A | I6: flip желтые Сул | J6: ='Юнит 11'!S8 -> 63 | K6: =J6/J$45 -> 0.080357143 | L6: =L5+K6 -> 0.54464286 | M6: =_xlfn.IFS(L6<80%,"A",L6<=95%,"B",L6>95%,"C") -> A | P6: C | Q6: 0.05
B7: Qs син Сул | C7: ='Юнит 11'!AL5 -> 17033.043 | D7: =C7/C$45 -> 0.064662156 | E7: =E6+D7 -> 0.63926041 | F7: =IF(AND(E7<=0),"C",IF(E7<=0.8,"A",IF(E7<=0.95,"B","C"))) -> A | G7: =VLOOKUP(B$4:B$44,I$4:M$44,5,0) -> A | I7: Qs син Сул | J7: ='Юнит 11'!S5 -> 58 | K7: =J7/J$45 -> 0.073979592 | L7: =L6+K7 -> 0.61862245 | M7: =_xlfn.IFS(L7<80%,"A",L7<=95%,"B",L7>95%,"C") -> A
B8: Qs желт Сул | C8: ='Юнит 11'!AL6 -> 16026.328 | D8: =C8/C$45 -> 0.060840387 | E8: =E7+D8 -> 0.70010079 | F8: =IF(AND(E8<=0),"C",IF(E8<=0.8,"A",IF(E8<=0.95,"B","C"))) -> A | G8: =VLOOKUP(B$4:B$44,I$4:M$44,5,0) -> A | I8: Qs желт Сул | J8: ='Юнит 11'!S6 -> 47 | K8: =J8/J$45 -> 0.05994898 | L8: =L7+K8 -> 0.67857143 | M8: =_xlfn.IFS(L8<80%,"A",L8<=95%,"B",L8>95%,"C") -> A
B9: MR8854 C2 Сул | C9: ='Юнит 11'!AL9 -> 15602.722 | D9: =C9/C$45 -> 0.059232262 | E9: =E8+D9 -> 0.75933305 | F9: =IF(AND(E9<=0),"C",IF(E9<=0.8,"A",IF(E9<=0.95,"B","C"))) -> A | G9: =VLOOKUP(B$4:B$44,I$4:M$44,5,0) -> A | I9: MR8854 C2 Сул | J9: ='Юнит 11'!S9 -> 31 | K9: =J9/J$45 -> 0.039540816 | L9: =L8+K9 -> 0.71811224 | M9: =_xlfn.IFS(L9<80%,"A",L9<=95%,"B",L9>95%,"C") -> A
B10: qs001 | C10: ='Юнит 11'!AL19 -> 11683.631 | D10: =C10/C$45 -> 0.044354304 | E10: =E9+D10 -> 0.80368736 | F10: =IF(AND(E10<=0),"C",IF(E10<=0.8,"A",IF(E10<=0.95,"B","C"))) -> B | G10: =VLOOKUP(B$4:B$44,I$4:M$44,5,0) -> A | I10: qs002 | J10: ='Юнит 11'!S20 -> 28 | K10: =J10/J$45 -> 0.035714286 | L10: =L9+K10 -> 0.75382653 | M10: =_xlfn.IFS(L10<80%,"A",L10<=95%,"B",L10>95%,"C") -> A
B11: qs014 | C11: ='Юнит 11'!AL31 -> 10852.688 | D11: =C11/C$45 -> 0.041199813 | E11: =E10+D11 -> 0.84488717 | F11: =IF(AND(E11<=0),"C",IF(E11<=0.8,"A",IF(E11<=0.95,"B","C"))) -> B | G11: =VLOOKUP(B$4:B$44,I$4:M$44,5,0) -> B | I11: qs001 | J11: ='Юнит 11'!S19 -> 24 | K11: =J11/J$45 -> 0.030612245 | L11: =L10+K11 -> 0.78443878 | M11: =_xlfn.IFS(L11<80%,"A",L11<=95%,"B",L11>95%,"C") -> A
B12: qs002 | C12: ='Юнит 11'!AL20 -> 7502.0826 | D12: =C12/C$45 -> 0.028479987 | E12: =E11+D12 -> 0.87336716 | F12: =IF(AND(E12<=0),"C",IF(E12<=0.8,"A",IF(E12<=0.95,"B","C"))) -> B | G12: =VLOOKUP(B$4:B$44,I$4:M$44,5,0) -> A | I12: flip черные Сул | J12: ='Юнит 11'!S7 -> 22 | K12: =J12/J$45 -> 0.028061224 | L12: =L11+K12 -> 0.8125 | M12: =_xlfn.IFS(L12<80%,"A",L12<=95%,"B",L12>95%,"C") -> B
B13: flip черные Сул | C13: ='Юнит 11'!AL7 -> 6672.868 | D13: =C13/C$45 -> 0.025332058 | E13: =E12+D13 -> 0.89869922 | F13: =IF(AND(E13<=0),"C",IF(E13<=0.8,"A",IF(E13<=0.95,"B","C"))) -> B | G13: =VLOOKUP(B$4:B$44,I$4:M$44,5,0) -> B | I13: qs014 | J13: ='Юнит 11'!S31 -> 20 | K13: =J13/J$45 -> 0.025510204 | L13: =L12+K13 -> 0.8380102 | M13: =_xlfn.IFS(L13<80%,"A",L13<=95%,"B",L13>95%,"C") -> B
B14: qs006 | C14: ='Юнит 11'!AL23 -> 6364.3185 | D14: =C14/C$45 -> 0.024160719 | E14: =E13+D14 -> 0.92285993 | F14: =IF(AND(E14<=0),"C",IF(E14<=0.8,"A",IF(E14<=0.95,"B","C"))) -> B | G14: =VLOOKUP(B$4:B$44,I$4:M$44,5,0) -> B | I14: MR 1890 черн | J14: ='Юнит 11'!S16 -> 14 | K14: =J14/J$45 -> 0.017857143 | L14: =L13+K14 -> 0.85586735 | M14: =_xlfn.IFS(L14<80%,"A",L14<=95%,"B",L14>95%,"C") -> B
B15: qs010ж | C15: ='Юнит 11'!AL34 -> 4784.8192 | D15: =C15/C$45 -> 0.018164501 | E15: =E14+D15 -> 0.94102444 | F15: =IF(AND(E15<=0),"C",IF(E15<=0.8,"A",IF(E15<=0.95,"B","C"))) -> B | G15: =VLOOKUP(B$4:B$44,I$4:M$44,5,0) -> B | I15: qs010ж | J15: ='Юнит 11'!S34 -> 14 | K15: =J15/J$45 -> 0.017857143 | L15: =L14+K15 -> 0.87372449 | M15: =_xlfn.IFS(L15<80%,"A",L15<=95%,"B",L15>95%,"C") -> B
B16: MR 1890 корич | C16: ='Юнит 11'!AL18 -> 4709.866 | D16: =C16/C$45 -> 0.017879958 | E16: =E15+D16 -> 0.95890439 | F16: =IF(AND(E16<=0),"C",IF(E16<=0.8,"A",IF(E16<=0.95,"B","C"))) -> C | G16: =VLOOKUP(B$4:B$44,I$4:M$44,5,0) -> B | I16: qs006 | J16: ='Юнит 11'!S23 -> 13 | K16: =J16/J$45 -> 0.016581633 | L16: =L15+K16 -> 0.89030612 | M16: =_xlfn.IFS(L16<80%,"A",L16<=95%,"B",L16>95%,"C") -> B
B17: MR Р1874 черн | C17: ='Юнит 11'!AL12 -> 3566.34 | D17: =C17/C$45 -> 0.013538816 | E17: =E16+D17 -> 0.97244321 | F17: =IF(AND(E17<=0),"C",IF(E17<=0.8,"A",IF(E17<=0.95,"B","C"))) -> C | G17: =VLOOKUP(B$4:B$44,I$4:M$44,5,0) -> B | I17: qs013 | J17: ='Юнит 11'!S30 -> 13 | K17: =J17/J$45 -> 0.016581633 | L17: =L16+K17 -> 0.90688776 | M17: =_xlfn.IFS(L17<80%,"A",L17<=95%,"B",L17>95%,"C") -> B
B18: MR 1890 черн | C18: ='Юнит 11'!AL16 -> 3108.5182 | D18: =C18/C$45 -> 0.011800797 | E18: =E17+D18 -> 0.98424401 | F18: =IF(AND(E18<=0),"C",IF(E18<=0.8,"A",IF(E18<=0.95,"B","C"))) -> C | G18: =VLOOKUP(B$4:B$44,I$4:M$44,5,0) -> B | I18: MR Р1874 черн | J18: ='Юнит 11'!S12 -> 9 | K18: =J18/J$45 -> 0.011479592 | L18: =L17+K18 -> 0.91836735 | M18: =_xlfn.IFS(L18<80%,"A",L18<=95%,"B",L18>95%,"C") -> B
B19: 2100фиолетовый | C19: ='Юнит 11'!AL41 -> 2715.922 | D19: =C19/C$45 -> 0.010310393 | E19: =E18+D19 -> 0.9945544 | F19: =IF(AND(E19<=0),"C",IF(E19<=0.8,"A",IF(E19<=0.95,"B","C"))) -> C | G19: =VLOOKUP(B$4:B$44,I$4:M$44,5,0) -> B | I19: MR 1890 корич | J19: ='Юнит 11'!S18 -> 8 | K19: =J19/J$45 -> 0.010204082 | L19: =L18+K19 -> 0.92857143 | M19: =_xlfn.IFS(L19<80%,"A",L19<=95%,"B",L19>95%,"C") -> B
B20: qs003 | C20: ='Юнит 11'!AL21 -> 2070.5644 | D20: =C20/C$45 -> 0.0078604371 | E20: =E19+D20 -> 1.0024148 | F20: =IF(AND(E20<=0),"C",IF(E20<=0.8,"A",IF(E20<=0.95,"B","C"))) -> C | G20: =VLOOKUP(B$4:B$44,I$4:M$44,5,0) -> C | I20: qs015 | J20: ='Юнит 11'!S32 -> 8 | K20: =J20/J$45 -> 0.010204082 | L20: =L19+K20 -> 0.93877551 | M20: =_xlfn.IFS(L20<80%,"A",L20<=95%,"B",L20>95%,"C") -> B
B21: MR Р1886 корич | C21: ='Юнит 11'!AL15 -> 2026.8344 | D21: =C21/C$45 -> 0.0076944256 | E21: =E20+D21 -> 1.0101093 | F21: =IF(AND(E21<=0),"C",IF(E21<=0.8,"A",IF(E21<=0.95,"B","C"))) -> C | G21: =VLOOKUP(B$4:B$44,I$4:M$44,5,0) -> C | I21: 2100фиолетовый | J21: ='Юнит 11'!S41 -> 8 | K21: =J21/J$45 -> 0.010204082 | L21: =L20+K21 -> 0.94897959 | M21: =_xlfn.IFS(L21<80%,"A",L21<=95%,"B",L21>95%,"C") -> B
B22: qs008 | C22: ='Юнит 11'!AL25 -> 1842.012 | D22: =C22/C$45 -> 0.0069927884 | E22: =E21+D22 -> 1.0171021 | F22: =IF(AND(E22<=0),"C",IF(E22<=0.8,"A",IF(E22<=0.95,"B","C"))) -> C | G22: =VLOOKUP(B$4:B$44,I$4:M$44,5,0) -> C | I22: MR Р1886 корич | J22: ='Юнит 11'!S15 -> 5 | K22: =J22/J$45 -> 0.006377551 | L22: =L21+K22 -> 0.95535714 | M22: =_xlfn.IFS(L22<80%,"A",L22<=95%,"B",L22>95%,"C") -> C
B23: MR 1819 корич | C23: ='Юнит 11'!AL11 -> 1792.6192 | D23: =C23/C$45 -> 0.0068052797 | E23: =E22+D23 -> 1.0239073 | F23: =IF(AND(E23<=0),"C",IF(E23<=0.8,"A",IF(E23<=0.95,"B","C"))) -> C | G23: =VLOOKUP(B$4:B$44,I$4:M$44,5,0) -> C | I23: qs003 | J23: ='Юнит 11'!S21 -> 5 | K23: =J23/J$45 -> 0.006377551 | L23: =L22+K23 -> 0.96173469 | M23: =_xlfn.IFS(L23<80%,"A",L23<=95%,"B",L23>95%,"C") -> C
B24: MR Р1886 черн | C24: ='Юнит 11'!AL14 -> 1370.5175 | D24: =C24/C$45 -> 0.0052028648 | E24: =E23+D24 -> 1.0291102 | F24: =IF(AND(E24<=0),"C",IF(E24<=0.8,"A",IF(E24<=0.95,"B","C"))) -> C | G24: =VLOOKUP(B$4:B$44,I$4:M$44,5,0) -> C | I24: qs007 | J24: ='Юнит 11'!S24 -> 5 | K24: =J24/J$45 -> 0.006377551 | L24: =L23+K24 -> 0.96811224 | M24: =_xlfn.IFS(L24<80%,"A",L24<=95%,"B",L24>95%,"C") -> C
B25: qs011ж | C25: ='Юнит 11'!AL35 -> 1356.95 | D25: =C25/C$45 -> 0.0051513587 | E25: =E24+D25 -> 1.0342616 | F25: =IF(AND(E25<=0),"C",IF(E25<=0.8,"A",IF(E25<=0.95,"B","C"))) -> C | G25: =VLOOKUP(B$4:B$44,I$4:M$44,5,0) -> C | I25: MR 1819 корич | J25: ='Юнит 11'!S11 -> 4 | K25: =J25/J$45 -> 0.0051020408 | L25: =L24+K25 -> 0.97321429 | M25: =_xlfn.IFS(L25<80%,"A",L25<=95%,"B",L25>95%,"C") -> C
B26: qs013 | C26: ='Юнит 11'!AL30 -> 1025.0034 | D26: =C26/C$45 -> 0.0038911972 | E26: =E25+D26 -> 1.0381528 | F26: =IF(AND(E26<=0),"C",IF(E26<=0.8,"A",IF(E26<=0.95,"B","C"))) -> C | G26: =VLOOKUP(B$4:B$44,I$4:M$44,5,0) -> B | I26: MR Р1886 черн | J26: ='Юнит 11'!S14 -> 3 | K26: =J26/J$45 -> 0.0038265306 | L26: =L25+K26 -> 0.97704082 | M26: =_xlfn.IFS(L26<80%,"A",L26<=95%,"B",L26>95%,"C") -> C
B27: MR Р1874 корич | C27: ='Юнит 11'!AL13 -> 935.07 | D27: =C27/C$45 -> 0.0035497851 | E27: =E26+D27 -> 1.0417025 | F27: =IF(AND(E27<=0),"C",IF(E27<=0.8,"A",IF(E27<=0.95,"B","C"))) -> C | G27: =VLOOKUP(B$4:B$44,I$4:M$44,5,0) -> C | I27: qs008 | J27: ='Юнит 11'!S25 -> 3 | K27: =J27/J$45 -> 0.0038265306 | L27: =L26+K27 -> 0.98086735 | M27: =_xlfn.IFS(L27<80%,"A",L27<=95%,"B",L27>95%,"C") -> C
B28: 2038ч/б | C28: ='Юнит 11'!AL37 -> 806.39718 | D28: =C28/C$45 -> 0.0030613074 | E28: =E24+D28 -> 1.0321715 | F28: =IF(AND(E28<=0),"C",IF(E28<=0.8,"A",IF(E28<=0.95,"B","C"))) -> C | G28: =VLOOKUP(B$4:B$44,I$4:M$44,5,0) -> C | I28: qs011ж | J28: ='Юнит 11'!S35 -> 3 | K28: =J28/J$45 -> 0.0038265306 | L28: =L24+K28 -> 0.97193878 | M28: =_xlfn.IFS(L28<80%,"A",L28<=95%,"B",L28>95%,"C") -> C
B29: MR 1890 желт | C29: ='Юнит 11'!AL17 -> 646.30596 | D29: =C29/C$45 -> 0.0024535567 | E29: =E28+D29 -> 1.0346251 | F29: =IF(AND(E29<=0),"C",IF(E29<=0.8,"A",IF(E29<=0.95,"B","C"))) -> C | G29: =VLOOKUP(B$4:B$44,I$4:M$44,5,0) -> C | I29: MR 1819 черн | J29: ='Юнит 11'!S10 -> 2 | K29: =J29/J$45 -> 0.0025510204 | L29: =L28+K29 -> 0.9744898 | M29: =_xlfn.IFS(L29<80%,"A",L29<=95%,"B",L29>95%,"C") -> C
B30: 2104 | C30: ='Юнит 11'!AL42 -> 457.77199 | D30: =C30/C$45 -> 0.0017378295 | E30: =E29+D30 -> 1.0363629 | F30: =IF(AND(E30<=0),"C",IF(E30<=0.8,"A",IF(E30<=0.95,"B","C"))) -> C | G30: =VLOOKUP(B$4:B$44,I$4:M$44,5,0) -> C | I30: MR Р1874 корич | J30: ='Юнит 11'!S13 -> 2 | K30: =J30/J$45 -> 0.0025510204 | L30: =L29+K30 -> 0.97704082 | M30: =_xlfn.IFS(L30<80%,"A",L30<=95%,"B",L30>95%,"C") -> C
B31: MR 1819 черн | C31: ='Юнит 11'!AL10 -> 283.86477 | D31: =C31/C$45 -> 0.0010776294 | E31: =E30+D31 -> 1.0374405 | F31: =IF(AND(E31<=0),"C",IF(E31<=0.8,"A",IF(E31<=0.95,"B","C"))) -> C | G31: =VLOOKUP(B$4:B$44,I$4:M$44,5,0) -> C | I31: MR 1890 желт | J31: ='Юнит 11'!S17 -> 2 | K31: =J31/J$45 -> 0.0025510204 | L31: =L30+K31 -> 0.97959184 | M31: =_xlfn.IFS(L31<80%,"A",L31<=95%,"B",L31>95%,"C") -> C
