Workbook

Sheet Сводная
A1: Период | D1: Итого к перечислению на счет, руб | E1: шт. | H1: Выручка | K1: Себестоимость продаж | L1: Логистика | M1: Комиссия | N1: Хранение | O1: Платная приемка | P1: Штрафы | Q1: Реклама Ozon | R1: Другие услуги и штрафы | S1: Услуги агентов | T1: Услуги FBO | U1: Компенсировано | V1: Пополнение рекламного кабинета | W1: ЕАЭС | X1: Налог | Y1: Прибыль до вычета налогов | Z1: Прибыль после вычета налогов | AA1: Итог месяц | AB1: % Cебестоимости | AC1: Маржинальность, % | AD1: Рентабельность, % | AE1: Доля рекламы, % | AG1: Данные для построения диаграмм
A2: Месяц | B2: Даты | C2: Нед | E2: Заказы | F2: Продажи | G2: Возвраты | H2: Продажи | I2: Возвраты | J2: Общая | AG2: Нед | AH2: По магазину | AI2: По очкам | AJ2: По туникам
A3: Январь | B3: 01-04.01 очки | D3: =J3-SUM(L3:T3)+U3+V3 -> 8693.5829 | E3: ='Юнит 01-04.01'!K$26 -> 44 | F3: ='Юнит 01-04.01'!P$26 -> 28 | G3: ='Юнит 01-04.01'!Q$26 -> 0 | H3: ='Юнит 01-04.01'!S$26 -> 45978 | I3: ='Юнит 01-04.01'!T$26 -> 0 | J3: =H3+I3 -> 45978 | K3: ='Юнит 01-04.01'!W$26 -> 4528.66 | L3: ='Юнит 01-04.01'!Z$26 -> 3709.34 | M3: ='Юнит 01-04.01'!X$26 -> 19770.54 | Q3: ='Юнит 01-04.01'!AA$26 -> 12383.647 | S3: 808.39 | T3: 612.5 | W3: 2545 | X3: =2656.15*J3/SUM($J$3:$J$12) -> 193.86959 | Y3: =J3-SUM(L3:T3)-K3-V3+U3+W3 -> 6709.9229 | Z3: =Y3-X3 -> 6516.0533 | AA3: =SUM(Z3:Z12) -> 53230.01 | AB3: =K3/J3 -> 0.098496237 | AC3: =Z3/K3 -> 1.438848 | AD3: =Z3/J3 -> 0.14172111 | AE3: =Q3/J3 -> 0.26933853
B4: 01-04.01 туники | D4: =J4-SUM(L4:T4)+U4+V4+W4 -> -283.08293 | E4: ='Юнит 01-04.01'!K$49 -> 5 | F4: ='Юнит 01-04.01'!P$49 -> 1 | G4: ='Юнит 01-04.01'!Q$49 -> 0 | H4: ='Юнит 01-04.01'!S$49 -> 4247 | I4: ='Юнит 01-04.01'!T$49 -> 0 | J4: =H4+I4 -> 4247 | K4: ='Юнит 01-04.01'!W$49 -> 597 | L4: ='Юнит 01-04.01'!Z$49 -> 186.2 | M4: ='Юнит 01-04.01'!X$49 -> 1826.21 | Q4: ='Юнит 01-04.01'!AA$49 -> 2517.6729 | X4: =2656.15*J4/SUM($J$3:$J$12) -> 17.907785 | Y4: =J4-SUM(L4:T4)-K4-V4+U4+W4 -> -880.08293 | Z4: =Y4-X4 -> -897.99072 | AB4: =K4/J4 -> 0.14056981 | AC4: =Z4/K4 -> -1.5041721 | AD4: =Z4/J4 -> -0.21144119 | AE4: =Q4/J4 -> 0.59281209
B5: 05-11.01 очки | D5: =J5-SUM(L5:T5)+U5+V5+W5 -> 15399.171 | E5: ='Юнит 05-11.01'!K$26 -> 74 | F5: ='Юнит 05-11.01'!P$26 -> 58 | G5: ='Юнит 05-11.01'!Q$26 -> 4 | H5: ='Юнит 05-11.01'!S$26 -> 92160 | I5: ='Юнит 05-11.01'!T$26 -> -6799 | J5: =H5+I5 -> 85361 | K5: ='Юнит 05-11.01'!W$26 -> 7651.8 | L5: ='Юнит 05-11.01'!Z$26 -> 9950.27 | M5: ='Юнит 05-11.01'!X$26 -> 36705.23 | Q5: ='Юнит 05-11.01'!AA$26 -> 20067.069 | R5: 5 | S5: 1918.46 | T5: 1315.8 | X5: =2656.15*J5/SUM($J$3:$J$12) -> 359.93088 | Y5: =J5-SUM(L5:T5)-K5-V5+U5+W5 -> 7747.3709 | Z5: =Y5-X5 -> 7387.44 | AB5: =K5/J5 -> 0.089640468 | AC5: =Z5/K5 -> 0.96545127 | AD5: =Z5/J5 -> 0.086543504 | AE5: =Q5/J5 -> 0.23508475
B6: 05-11.01 туники | D6: =J6-SUM(L6:T6)+U6+V6+W6 -> 4110.6391 | E6: ='Юнит 05-11.01'!K$49 -> 4 | F6: ='Юнит 05-11.01'!P$49 -> 2 | G6: ='Юнит 05-11.01'!Q$49 -> 0 | H6: ='Юнит 05-11.01'!S$49 -> 10524 | I6: ='Юнит 05-11.01'!T$49 -> 0 | J6: =H6+I6 -> 10524 | K6: ='Юнит 05-11.01'!W$49 -> 1329 | L6: ='Юнит 05-11.01'!Z$49 -> 907.3 | M6: ='Юнит 05-11.01'!X$49 -> 4525.32 | Q6: ='Юнит 05-11.01'!AA$49 -> 980.7409 | X6: =2656.15*J6/SUM($J$3:$J$12) -> 44.375213 | Y6: =J6-SUM(L6:T6)-K6-V6+U6+W6 -> 2781.6391 | Z6: =Y6-X6 -> 2737.2639 | AB6: =K6/J6 -> 0.12628278 | AC6: =Z6/K6 -> 2.0596417 | AD6: =Z6/J6 -> 0.26009729 | AE6: =Q6/J6 -> 0.093190888
B7: 12-18.01 очки | D7: =J7-SUM(L7:T7)+U7+V7+W7 -> 29545.798 | E7: ='Юнит 12-18.01'!K$26 -> 96 | F7: ='Юнит 12-18.01'!P$26 -> 56 | G7: ='Юнит 12-18.01'!Q$26 -> 0 | H7: ='Юнит 12-18.01'!S$26 -> 91762 | I7: ='Юнит 12-18.01'!T$26 -> 0 | J7: =H7+I7 -> 91762 | K7: ='Юнит 12-18.01'!W$26 -> 7841.91 | L7: ='Юнит 12-18.01'!Z$26 -> 9811.64 | M7: ='Юнит 12-18.01'!X$26 -> 39457.66 | Q7: ='Юнит 12-18.01'!AA$26 -> 18818.032 | S7: 2168.87 | T7: 800 | V7: 7000 | W7: 1840 | X7: =2656.15*J7/SUM($J$3:$J$12) -> 386.92116 | Y7: =J7-SUM(L7:T7)-K7-V7+U7+W7 -> 7703.8881 | Z7: =Y7-X7 -> 7316.967 | AB7: =K7/J7 -> 0.085459231 | AC7: =Z7/K7 -> 0.93305929 | AD7: =Z7/J7 -> 0.07973853 | AE7: =Q7/J7 -> 0.20507434
B8: 12-18.01 туники | D8: =J8-SUM(L8:T8)+U8+V8+W8 -> 4732.6119 | E8: ='Юнит 12-18.01'!K$49 -> 30 | F8: ='Юнит 12-18.01'!P$49 -> 5 | G8: ='Юнит 12-18.01'!Q$49 -> 0 | H8: ='Юнит 12-18.01'!S$49 -> 21020 | I8: ='Юнит 12-18.01'!T$49 -> 0 | J8: =H8+I8 -> 21020 | K8: ='Юнит 12-18.01'!W$49 -> 3435 | L8: ='Юнит 12-18.01'!Z$49 -> 1528.99 | M8: ='Юнит 12-18.01'!X$49 -> 9038.6 | Q8: ='Юнит 12-18.01'!AA$49 -> 5719.7981 | X8: =2656.15*J8/SUM($J$3:$J$12) -> 88.632363 | Y8: =J8-SUM(L8:T8)-K8-V8+U8+W8 -> 1297.6119 | Z8: =Y8-X8 -> 1208.9795 | AB8: =K8/J8 -> 0.16341579 | AC8: =Z8/K8 -> 0.3519591 | AD8: =Z8/J8 -> 0.057515676 | AE8: =Q8/J8 -> 0.27211219
B9: 19-25.01 очки | D9: =J9-SUM(L9:T9)+U9+V9+W9 -> 21740.787 | E9: ='Юнит 19-25.01'!K$26 -> 119 | F9: ='Юнит 19-25.01'!P$26 -> 64 | G9: ='Юнит 19-25.01'!Q$26 -> 1 | H9: ='Юнит 19-25.01'!S$26 -> 104586 | I9: ='Юнит 19-25.01'!T$26 -> -1670 | J9: =H9+I9 -> 102916 | K9: ='Юнит 19-25.01'!W$26 -> 9494.98 | L9: ='Юнит 19-25.01'!Z$26 -> 12870.13 | M9: ='Юнит 19-25.01'!X$26 -> 44253.88 | Q9: ='Юнит 19-25.01'!AA$26 -> 25263.883 | R9: 15 | S9: 3536.42 | T9: 2235.9 | V9: 7000 | X9: =2656.15*J9/SUM($J$3:$J$12) -> 433.95282 | Y9: =J9-SUM(L9:T9)-K9-V9+U9+W9 -> -1754.1928 | Z9: =Y9-X9 -> -2188.1456 | AB9: =K9/J9 -> 0.092259513 | AC9: =Z9/K9 -> -0.23045289 | AD9: =Z9/J9 -> -0.021261472 | AE9: =Q9/J9 -> 0.24548061
B10: 19-25.01 туники | D10: =J10-SUM(L10:T10)+U10+V10+W10 -> 13844.323 | E10: ='Юнит 19-25.01'!K$49 -> 66 | F10: ='Юнит 19-25.01'!P$49 -> 18 | G10: ='Юнит 19-25.01'!Q$49 -> 4 | H10: ='Юнит 19-25.01'!S$49 -> 80413 | I10: ='Юнит 19-25.01'!T$49 -> -17932 | J10: =H10+I10 -> 62481 | K10: ='Юнит 19-25.01'!W$49 -> 9468 | L10: ='Юнит 19-25.01'!Z$49 -> 6390.87 | M10: ='Юнит 19-25.01'!X$49 -> 26866.83 | Q10: ='Юнит 19-25.01'!AA$49 -> 15378.977 | X10: =2656.15*J10/SUM($J$3:$J$12) -> 263.45569 | Y10: =J10-SUM(L10:T10)-K10-V10+U10+W10 -> 4376.3228 | Z10: =Y10-X10 -> 4112.8671 | AB10: =K10/J10 -> 0.15153407 | AC10: =Z10/K10 -> 0.43439661 | AD10: =Z10/J10 -> 0.065825885 | AE10: =Q10/J10 -> 0.24613846
B11: 26-31.01 очки | D11: =J11-SUM(L11:T11)+U11+V11+W11 -> 23967.429 | E11: ='Юнит 26-31.01'!K$26 -> 100 | F11: ='Юнит 26-31.01'!P$26 -> 72 | G11: ='Юнит 26-31.01'!Q$26 -> 3 | H11: ='Юнит 26-31.01'!S$26 -> 120331 | I11: ='Юнит 26-31.01'!T$26 -> -4419 | J11: =H11+I11 -> 115912 | K11: ='Юнит 26-31.01'!W$26 -> 10470.94 | L11: ='Юнит 26-31.01'!Z$26 -> 13196.61 | M11: ='Юнит 26-31.01'!X$26 -> 49842.16 | Q11: ='Юнит 26-31.01'!AA$26 -> 19493.871 | R11: 25 | S11: 2141.43 | T11: 7245.5 | X11: =2656.15*J11/SUM($J$3:$J$12) -> 488.7514 | Y11: =J11-SUM(L11:T11)-K11-V11+U11+W11 -> 13496.489 | Z11: =Y11-X11 -> 13007.738 | AB11: =K11/J11 -> 0.090335254 | AC11: =Z11/K11 -> 1.2422703 | AD11: =Z11/J11 -> 0.1122208 | AE11: =Q11/J11 -> 0.16817819
B12: 26-31.01 туники | D12: =J12-SUM(L12:T12)+U12+V12+W12 -> 27742.191 | E12: ='Юнит 26-31.01'!K$49 -> 60 | F12: ='Юнит 26-31.01'!P$49 -> 20 | G12: ='Юнит 26-31.01'!Q$49 -> 0 | H12: ='Юнит 26-31.01'!S$49 -> 89730 | I12: ='Юнит 26-31.01'!T$49 -> 0 | J12: =H12+I12 -> 89730 | K12: ='Юнит 26-31.01'!W$49 -> 13335 | L12: ='Юнит 26-31.01'!Z$49 -> 8653.99 | M12: ='Юнит 26-31.01'!X$49 -> 38583.9 | Q12: ='Юнит 26-31.01'!AA$49 -> 13258.459 | S12: 1491.46 | X12: =2656.15*J12/SUM($J$3:$J$12) -> 378.35309 | Y12: =J12-SUM(L12:T12)-K12-V12+U12+W12 -> 14407.191 | Z12: =Y12-X12 -> 14028.838 | AB12: =K12/J12 -> 0.1486125 | AC12: =Z12/K12 -> 1.0520313 | AD12: =Z12/J12 -> 0.15634501 | AE12: =Q12/J12 -> 0.14775949
A13: Февраль | B13: 01.02 очки | D13: =J13-SUM(L13:T13)+U13+V13 -> 1221.3769 | E13: ='Юнит 01.02'!K$26 -> 19 | F13: ='Юнит 01.02'!P$26 -> 8 | G13: ='Юнит 01.02'!Q$26 -> 1 | H13: ='Юнит 01.02'!S$26 -> 13169 | I13: ='Юнит 01.02'!T$26 -> -1655 | J13: =H13+I13 -> 11514 | K13: ='Юнит 01.02'!W$26 -> 1054.68 | L13: ='Юнит 01.02'!Z$26 -> 1614.84 | M13: ='Юнит 01.02'!X$26 -> 4951.02 | Q13: ='Юнит 01.02'!AA$26 -> 3338.9931 | S13: 387.77 | W13: 902 | X13: ='Юнит 01.02'!AD26 -> 52.608637 | Y13: =J13-SUM(L13:T13)-K13-V13+U13+W13 -> 1068.6969 | Z13: =J13-SUM(L13:T13)-K13-X13+U13+W13-V13 -> 1016.0883 | AA13: =SUM(Z13:Z22) -> 147232.47 | AB13: =K13/J13 -> 0.091599792 | AC13: =Z13/K13 -> 0.96340905 | AD13: =Z13/J13 -> 0.088248068 | AE13: =Q13/J13 -> 0.28999419
B14: 01.02 туники | D14: =J14-SUM(L14:T14)+U14+V14+W14 -> -3647.3769 | E14: ='Юнит 01.02'!K$49 -> 7 | F14: ='Юнит 01.02'!P$49 -> 1 | G14: ='Юнит 01.02'!Q$49 -> 0 | H14: ='Юнит 01.02'!S$49 -> 4940 | I14: ='Юнит 01.02'!T$49 -> 0 | J14: =H14+I14 -> 4940 | K14: ='Юнит 01.02'!W$49 -> 687 | L14: ='Юнит 01.02'!Z$49 -> 1483.67 | M14: ='Юнит 01.02'!X$49 -> 2124.2 | Q14: ='Юнит 01.02'!AA$49 -> 4567.9469 | R14: 5 | S14: 406.56 | X14: ='Юнит 01.02'!AD49 -> 22.571363 | Y14: =J14-SUM(L14:T14)-K14-V14+U14+W14 -> -4334.3769 | Z14: =J14-SUM(L14:T14)-K14-X14+U14+W14-V14 -> -4356.9483 | AB14: =K14/J14 -> 0.13906883 | AC14: =Z14/K14 -> -6.3419916 | AD14: =Z14/J14 -> -0.88197333 | AE14: =Q14/J14 -> 0.92468561
B15: 02-08.02 очки | D15: =J15-SUM(L15:T15)+U15+V15 -> 19261.798 | E15: ='Юнит 02-08.02'!K$26 -> 131 | F15: ='Юнит 02-08.02'!P$26 -> 65 | G15: ='Юнит 02-08.02'!Q$26 -> 5 | H15: ='Юнит 02-08.02'!S$26 -> 119818 | I15: ='Юнит 02-08.02'!T$26 -> -9187 | J15: =H15+I15 -> 110631 | K15: ='Юнит 02-08.02'!W$26 -> 9043.72 | L15: ='Юнит 02-08.02'!Z$26 -> 13862.81 | M15: ='Юнит 02-08.02'!X$26 -> 47571.33 | Q15: ='Юнит 02-08.02'!AA$26 -> 26854.642 | S15: 3080.42 | X15: ='Юнит 02-08.02'!AD26 -> 495.41892 | Y15: =J15-SUM(L15:T15)-K15-V15+U15+W15 -> 10218.078 | Z15: =J15-SUM(L15:T15)-K15-X15+U15+W15-V15 -> 9722.659 | AB15: =K15/J15 -> 0.081746708 | AC15: =Z15/K15 -> 1.075073 | AD15: =Z15/J15 -> 0.087883676 | AE15: =Q15/J15 -> 0.24274066
B16: 02-08.02 туники | D16: =J16-SUM(L16:T16)+U16+V16+W16 -> 28854.102 | E16: ='Юнит 02-08.02'!K$49 -> 68 | F16: ='Юнит 02-08.02'!P$49 -> 24 | G16: ='Юнит 02-08.02'!Q$49 -> 1 | H16: ='Юнит 02-08.02'!S$49 -> 114048 | I16: ='Юнит 02-08.02'!T$49 -> -4178 | J16: =H16+I16 -> 109870 | K16: ='Юнит 02-08.02'!W$49 -> 14496 | L16: ='Юнит 02-08.02'!Z$49 -> 11481.36 | M16: ='Юнит 02-08.02'!X$49 -> 47244.1 | Q16: ='Юнит 02-08.02'!AA$49 -> 20002.458 | R16: 20 | S16: 2267.98 | X16: ='Юнит 02-08.02'!AD49 -> 492.01108 | Y16: =J16-SUM(L16:T16)-K16-V16+U16+W16 -> 14358.102 | Z16: =J16-SUM(L16:T16)-K16-X16+U16+W16-V16 -> 13866.091 | AB16: =K16/J16 -> 0.13193774 | AC16: =Z16/K16 -> 0.95654601 | AD16: =Z16/J16 -> 0.12620452 | AE16: =Q16/J16 -> 0.18205568
B17: 09-15.02 очки | D17: =J17-SUM(L17:T17)+U17+V17 -> 22441.752 | E17: ='Юнит 09-15.02'!K$26 -> 121 | F17: ='Юнит 09-15.02'!P$26 -> 60 | G17: ='Юнит 09-15.02'!Q$26 -> 2 | H17: ='Юнит 09-15.02'!S$26 -> 125456 | I17: ='Юнит 09-15.02'!T$26 -> -4877 | J17: =H17+I17 -> 120579 | K17: ='Юнит 09-15.02'!W$26 -> 7423.19 | L17: ='Юнит 09-15.02'!Z$26 -> 13659.9 | M17: ='Юнит 09-15.02'!X$26 -> 51848.97 | Q17: ='Юнит 09-15.02'!AA$26 -> 26940.334 | S17: 3309.41 | T17: =3250.8*F17/(F17+F18) -> 2378.6341 | X17: ='Юнит 09-15.02'!AD26 -> 529.24794 | Y17: =J17-SUM(L17:T17)-K17-V17+U17+W17 -> 15018.562 | Z17: =J17-SUM(L17:T17)-K17-X17+U17+W17-V17 -> 14489.314 | AB17: =K17/J17 -> 0.061562876 | AC17: =Z17/K17 -> 1.9518986 | AD17: =Z17/J17 -> 0.12016449 | AE17: =Q17/J17 -> 0.22342476
B18: 09-15.02 туники | D18: =J18-SUM(L18:T18)+U18+V18+W18 -> 28836.778 | E18: ='Юнит 09-15.02'!K$49 -> 54 | F18: ='Юнит 09-15.02'!P$49 -> 22 | G18: ='Юнит 09-15.02'!Q$49 -> 2 | H18: ='Юнит 09-15.02'!S$49 -> 110799 | I18: ='Юнит 09-15.02'!T$49 -> -9047 | J18: =H18+I18 -> 101752 | K18: ='Юнит 09-15.02'!W$49 -> 13275 | L18: ='Юнит 09-15.02'!Z$49 -> 8720.99 | M18: ='Юнит 09-15.02'!X$49 -> 43753.36 | Q18: ='Юнит 09-15.02'!AA$49 -> 17681.836 | R18: 25 | S18: 1861.87 | T18: =3250.8*F18/(F17+F18) -> 872.16585 | X18: ='Юнит 09-15.02'!AD49 -> 446.61206 | Y18: =J18-SUM(L18:T18)-K18-V18+U18+W18 -> 15561.778 | Z18: =J18-SUM(L18:T18)-K18-X18+U18+W18-V18 -> 15115.166 | AB18: =K18/J18 -> 0.13046427 | AC18: =Z18/K18 -> 1.1386189 | AD18: =Z18/J18 -> 0.14854908 | AE18: =Q18/J18 -> 0.17377385
B19: 16-22.02 очки | D19: =J19-SUM(L19:T19)+U19+V19 -> 37691.629 | E19: ='Юнит 16-22.02'!K$26 -> 172 | F19: ='Юнит 16-22.02'!P$26 -> 79 | G19: ='Юнит 16-22.02'!Q$26 -> 2 | H19: ='Юнит 16-22.02'!S$26 -> 173410 | I19: ='Юнит 16-22.02'!T$26 -> -4800 | J19: =H19+I19 -> 168610 | K19: ='Юнит 16-22.02'!W$26 -> 11163.54 | L19: ='Юнит 16-22.02'!Z$26 -> 17063.86 | M19: ='Юнит 16-22.02'!X$26 -> 72502.3 | Q19: ='Юнит 16-22.02'!AA$26 -> 37347.301 | S19: 4004.91 | W19: 972 | X19: ='Юнит 16-22.02'!AD$26 -> 745.37032 | Y19: =J19-SUM(L19:T19)-K19-V19+U19+W19 -> 27500.089 | Z19: =J19-SUM(L19:T19)-K19-X19+U19+W19-V19 -> 26754.719 | AB19: =K19/J19 -> 0.06620924 | AC19: =Z19/K19 -> 2.396616 | AD19: =Z19/J19 -> 0.15867813 | AE19: =Q19/J19 -> 0.2215011
B20: 16-22.02 туники | D20: =J20-SUM(L20:T20)+U20+V20+W20 -> 43858.251 | E20: ='Юнит 16-22.02'!K$49 -> 78 | F20: ='Юнит 16-22.02'!P$49 -> 27 | G20: ='Юнит 16-22.02'!Q$49 -> 2 | H20: ='Юнит 16-22.02'!S$49 -> 141378 | I20: ='Юнит 16-22.02'!T$49 -> -10000 | J20: =H20+I20 -> 131378 | K20: ='Юнит 16-22.02'!W$49 -> 15420 | L20: ='Юнит 16-22.02'!Z$49 -> 10936.38 | M20: ='Юнит 16-22.02'!X$49 -> 56492.54 | Q20: ='Юнит 16-22.02'!AA$49 -> 21117.479 | R20: 20 | S20: 2139.35 | W20: 3186 | X20: ='Юнит 16-22.02'!AD$49 -> 580.77968 | Y20: =J20-SUM(L20:T20)-K20-V20+U20+W20 -> 28438.251 | Z20: =J20-SUM(L20:T20)-K20-X20+U20+W20-V20 -> 27857.471 | AB20: =K20/J20 -> 0.11737125 | AC20: =Z20/K20 -> 1.8065805 | AD20: =Z20/J20 -> 0.21204061 | AE20: =Q20/J20 -> 0.16073832
B21: 23-28.02 очки | D21: =J21-SUM(L21:T21)+U21+V21 -> 51268.243 | E21: ='Юнит 23-28.02'!K$26 -> 200 | F21: ='Юнит 23-28.02'!P$26 -> 104 | G21: ='Юнит 23-28.02'!Q$26 -> 6 | H21: ='Юнит 23-28.02'!S$26 -> 230456 | I21: ='Юнит 23-28.02'!T$26 -> -14068 | J21: =H21+I21 -> 216388 | K21: ='Юнит 23-28.02'!W$26 -> 14285.64 | L21: ='Юнит 23-28.02'!Z$26 -> 18630.99 | M21: ='Юнит 23-28.02'!X$26 -> 93046.84 | Q21: ='Юнит 23-28.02'!AA$26 -> 49038.397 | S21: 4403.53 | X21: ='Юнит 23-28.02'!AD$26 -> 980.47315 | Y21: =J21-SUM(L21:T21)-K21-V21+U21+W21 -> 36982.603 | Z21: =J21-SUM(L21:T21)-K21-X21+U21+W21-V21 -> 36002.13 | AB21: =K21/J21 -> 0.066018633 | AC21: =Z21/K21 -> 2.5201622 | AD21: =Z21/J21 -> 0.16637766 | AE21: =Q21/J21 -> 0.22662253
B22: 23-28.02 туники | D22: =J22-SUM(L22:T22)+U22+V22+W22 -> 20741.567 | E22: ='Юнит 23-28.02'!K$49 -> 73 | F22: ='Юнит 23-28.02'!P$49 -> 22 | G22: ='Юнит 23-28.02'!Q$49 -> 1 | H22: ='Юнит 23-28.02'!S$49 -> 118788 | I22: ='Юнит 23-28.02'!T$49 -> -6500 | J22: =H22+I22 -> 112288 | K22: ='Юнит 23-28.02'!W$49 -> 13467 | L22: ='Юнит 23-28.02'!Z$49 -> 9725.32 | M22: ='Юнит 23-28.02'!X$49 -> 48283.84 | Q22: ='Юнит 23-28.02'!AA$49 -> 30882.493 | R22: 10 | S22: 2644.78 | X22: ='Юнит 23-28.02'!AD$49 -> 508.78685 | Y22: =J22-SUM(L22:T22)-K22-V22+U22+W22 -> 7274.5671 | Z22: =J22-SUM(L22:T22)-K22-X22+U22+W22-V22 -> 6765.7802 | AB22: =K22/J22 -> 0.11993267 | AC22: =Z22/K22 -> 0.50239699 | AD22: =Z22/J22 -> 0.060253814 | AE22: =Q22/J22 -> 0.27502933
A23: Март | B23: 01.03 очки | D23: =J23-SUM(L23:T23)+U23+V23 -> 9573.6928 | E23: ='Юнит 01.03'!K$26 -> 33 | F23: ='Юнит 01.03'!P$26 -> 19 | G23: ='Юнит 01.03'!Q$26 -> 0 | H23: ='Юнит 01.03'!S$26 -> 40846 | I23: ='Юнит 01.03'!T$26 -> 0 | J23: =H23+I23 -> 40846 | K23: ='Юнит 01.03'!W$26 -> 2795.01 | L23: ='Юнит 01.03'!Z$26 -> 4137.97 | M23: ='Юнит 01.03'!X$26 -> 17563.78 | Q23: ='Юнит 01.03'!AA$26 -> 8589.2572 | S23: 981.3 | W23: 2592 | X23: ='Юнит 01.03'!AD$26 -> 174.8667 | Y23: =J23-SUM(L23:T23)-K23-V23+U23+W23 -> 9370.6828 | Z23: =J23-SUM(L23:T23)-K23-X23+U23+W23-V23 -> 9195.8161 | AB23: =K23/J23 -> 0.068427998 | AC23: =Z23/K23 -> 3.2900834 | AD23: =Z23/J23 -> 0.22513382 | AE23: =Q23/J23 -> 0.21028393
B24: 01.03 туники | D24: =J24-SUM(L24:T24)+U24+V24+W24 -> 11464.637 | E24: ='Юнит 01.03'!K$49 -> 10 | F24: ='Юнит 01.03'!P$49 -> 5 | G24: ='Юнит 01.03'!Q$49 -> 0 | H24: ='Юнит 01.03'!S$49 -> 27900 | I24: ='Юнит 01.03'!T$49 -> 0 | J24: =H24+I24 -> 27900 | K24: ='Юнит 01.03'!W$49 -> 3240 | L24: ='Юнит 01.03'!Z$49 -> 1772.61 | M24: ='Юнит 01.03'!X$49 -> 11997 | Q24: ='Юнит 01.03'!AA$49 -> 2452.0328 | S24: 213.72 | X24: ='Юнит 01.03'!AD$49 -> 119.4433 | Y24: =J24-SUM(L24:T24)-K24-V24+U24+W24 -> 8224.6372 | Z24: =J24-SUM(L24:T24)-K24-X24+U24+W24-V24 -> 8105.1939 | AB24: =K24/J24 -> 0.11612903 | AC24: =Z24/K24 -> 2.5016031 | AD24: =Z24/J24 -> 0.29050874 | AE24: =Q24/J24 -> 0.08788648
A27: Итого | D27: =SUM(D3:D22) -> 400021.57 | E27: =SUM(E3:E22) -> 1521 | F27: =SUM(F3:F22) -> 736 | G27: =SUM(G3:G22) -> 34 | H27: =SUM(H3:H22) -> 1813013 | I27: =SUM(I3:I22) -> -95132 | J27: =SUM(J3:J22) -> 1717881 | K27: =SUM(K3:K22) -> 168468.06 | ... S27: =SUM(S3:S22) -> 36571.61 | T27: =SUM(T3:T24) -> 15460.5 | U27: =SUM(U3:U22) -> 0 | V27: =SUM(V3:V22) -> 14000 | W27: =SUM(W3:W22) -> 9445 | X27: =SUM(X3:X22) -> 7510.03 | Y27: =SUM(Y3:Y22) -> 207972.51 | Z27: =SUM(Z3:Z22) -> 200462.48 | AA27: =SUM(AA3:AA22) -> 200462.48 | AB27: =K27/J27 -> 0.098067363 | AC27: =Z27/K27 -> 1.1899139 | AD27: =Z27/J27 -> 0.11669171 | AE27: =Q27/J27 -> 0.21634446
H28: % от выручки за весь период | Z28: Маржинальность, % | AA28: Рентабельность, %
I29: =-I27/H27 -> 0.052471769 | J29: 0 | K29: =K27/$J$27 -> 0.098067363 | L29: =L27/$J$27 -> 0.10151196 | M29: =M27/$J$27 -> 0.43 | Q29: =Q27/$J$27 -> 0.21634446 | R29: =R27/$J$27 -> 7.2764062e-05 | S29: =S27/$J$27 -> 0.021288791 | T29: =T27/$J$27 -> 0.0089997503 | U29: =U27/$J$27 -> 0 | V29: =V27/$J$27 -> 0.008149575 | X29: =X27/$J$27 -> 0.0043716823 | Z29: =Z27/K27 -> 1.1899139
A31: январь очки | D31: =D3+D5+D7+D9+D11 -> 99346.768 | E31: =E3+E5+E7+E9+E11 -> 433 | F31: =F3+F5+F7+F9+F11 -> 278 | G31: =G3+G5+G7+G9+G11 -> 8 | H31: =H3+H5+H7+H9+H11 -> 454817 | I31: =I3+I5+I7+I9+I11 -> -12888 | J31: =J3+J5+J7+J9+J11 -> 441929 | K31: =K3+K5+K7+K9+K11 -> 39988.29 | ... Z31: =Z3+Z5+Z7+Z9+Z11 -> 32040.052
A32: январь туники | D32: =D4+D6+D8+D10+D12 -> 50146.682 | E32: =E4+E6+E8+E10+E12 -> 165 | F32: =F4+F6+F8+F10+F12 -> 46 | G32: =G4+G6+G8+G10+G12 -> 4 | H32: =H4+H6+H8+H10+H12 -> 205934 | I32: =I4+I6+I8+I10+I12 -> -17932 | J32: =J4+J6+J8+J10+J12 -> 188002 | K32: =K4+K6+K8+K10+K12 -> 28164 | ... Z32: =Z4+Z6+Z8+Z10+Z12 -> 21189.958
A33: январь итого | D33: =D31+D32 -> 149493.45 | E33: =E31+E32 -> 598 | F33: =F31+F32 -> 324 | G33: =G31+G32 -> 12 | H33: =H31+H32 -> 660751 | I33: =I31+I32 -> -30820 | J33: =J31+J32 -> 629931 | K33: =K31+K32 -> 68152.29 | ... Z33: =Z31+Z32 -> 53230.01
A35: февраль очки | D35: =D13+D15+D17+D19+D21 -> 131884.8 | E35: =E13+E15+E17+E19+E21 -> 643 | F35: =F13+F15+F17+F19+F21 -> 316 | G35: =G13+G15+G17+G19+G21 -> 16 | H35: =H13+H15+H17+H19+H21 -> 662309 | I35: =I13+I15+I17+I19+I21 -> -34587 | J35: =J13+J15+J17+J19+J21 -> 627722 | K35: =K13+K15+K17+K19+K21 -> 42970.77 | ... Z35: =Z13+Z15+Z17+Z19+Z21 -> 87984.91
A36: февраль туники | D36: =D14+D16+D18+D20+D22 -> 118643.32 | E36: =E14+E16+E18+E20+E22 -> 280 | F36: =F14+F16+F18+F20+F22 -> 96 | G36: =G14+G16+G18+G20+G22 -> 6 | H36: =H14+H16+H18+H20+H22 -> 489953 | I36: =I14+I16+I18+I20+I22 -> -29725 | J36: =J14+J16+J18+J20+J22 -> 460228 | K36: =K14+K16+K18+K20+K22 -> 57345 | ... Z36: =Z14+Z16+Z18+Z20+Z22 -> 59247.56
A37: февраль итого | D37: =D35+D36 -> 250528.12 | E37: =E35+E36 -> 923 | F37: =F35+F36 -> 412 | G37: =G35+G36 -> 22 | H37: =H35+H36 -> 1152262 | I37: =I35+I36 -> -64312 | J37: =J35+J36 -> 1087950 | K37: =K35+K36 -> 100315.77 | ... Z37: =Z35+Z36 -> 147232.47
A39: 5 неделя очки | K39: =(K11+K13)/($J$11+$J$13) -> 0.090449516 | L39: =(L11+L13)/($J$11+$J$13) -> 0.1162357 | M39: =(M11+M13)/($J$11+$J$13) -> 0.43 | N39: =(N11+N13)/($J$11+$J$13) -> 0 | O39: =(O11+O13)/($J$11+$J$13) -> 0 | P39: =(P11+P13)/($J$11+$J$13) -> 0 | Q39: =(Q11+Q13)/($J$11+$J$13) -> 0.17918528 | R39: =(R11+S11+T11+R13+S13+T13)/($J$11+$J$13) -> 0.076905027 | U39: =(U11+U13)/($J$11+$J$13) -> 0 | V39: =(V11+V13)/($J$11+$J$13) -> 0 | W39: =(W11+W13)/($J$11+$J$13) -> 0.0070786182 | X39: =(X11+X13)/($J$11+$J$13) -> 0.0042484268 | Y39: =(Y11+Y13)/($J$11+$J$13) -> 0.11430309 | Z39: =(Z11+Z13)/($J$11+$J$13) -> 0.11005467
A40: 6 неделя очки | K40: =K15/$J$15 -> 0.081746708 | L40: =L15/$J$15 -> 0.12530674 | M40: =M15/$J$15 -> 0.43 | Q40: =Q15/$J$15 -> 0.24274066 | R40: =(R15+S15+T15)/$J$15 -> 0.027844094 | U40: =U15/$J$15 -> 0 | V40: =V15/$J$15 -> 0 | X40: =X15/$J$15 -> 0.0044781203 | Z40: =Z15/K15 -> 1.075073
A41: 7 неделя очки | K41: =K17/$J$17 -> 0.061562876 | L41: =L17/$J$17 -> 0.1132859 | M41: =M17/$J$17 -> 0.43 | Q41: =Q17/$J$17 -> 0.22342476 | R41: =(R17+S17+T17)/$J$17 -> 0.047172759 | U41: =U17/$J$17 -> 0 | V41: =V17/$J$17 -> 0 | X41: =X17/$J$17 -> 0.0043892215 | Z41: =Z17/K17 -> 1.9518986
A42: 8 неделя очки | K42: =K19/$J$19 -> 0.06620924 | L42: =L19/$J$19 -> 0.10120313 | M42: =M19/$J$19 -> 0.43 | Q42: =Q19/$J$19 -> 0.2215011 | R42: =(R19+S19+T19)/$J$19 -> 0.023752506 | U42: =U19/$J$19 -> 0 | V42: =V19/$J$19 -> 0 | X42: =X19/$J$19 -> 0.0044206768 | Z42: =Z19/K19 -> 2.396616
A43: 9 неделя очки | K43: =(K21+K23)/($J$21+$J$23) -> 0.066401214 | L43: =(L21+L23)/($J$21+$J$23) -> 0.088514582 | M43: =(M21+M23)/($J$21+$J$23) -> 0.43 | N43: =(N21+N23)/($J$21+$J$23) -> 0 | O43: =(O21+O23)/($J$21+$J$23) -> 0 | P43: =(P21+P23)/($J$21+$J$23) -> 0 | Q43: =(Q21+Q23)/($J$21+$J$23) -> 0.22402814 | R43: =(R21+S21+T21+R23+S23+T23)/($J$21+$J$23) -> 0.020933586 | U43: =(U21+U23)/($J$21+$J$23) -> 0 | V43: =(V21+V23)/($J$21+$J$23) -> 0 | X43: =(X21+X23)/($J$21+$J$23) -> 0.0044913964 | Z43: =(Z21+Z23)/(K21+K23) -> 2.6461491 | AA43: =(Z21+Z23)/(J21+J23) -> 0.17570751

Sheet АВС 02-08.03
B2: ОЧКИ
C3: Прибыль | D3: % прибыль | E3: Доля | F3: ABC прибыль | G3: ABC кол-во | J3: Кол-во | K3: % кол-во | L3: Доля | M3: ABC кол-во
B4: черные с железкой классика | D4: =C4/C$26 -> #DIV/0! | E4: =D4 -> #DIV/0! | F4: =IF(AND(E4<=0),"C",IF(E4<=0.8,"A",IF(E4<=0.95,"B","C"))) -> #DIV/0! | G4: =VLOOKUP(B$4:B$25,I$4:M$25,5,0) -> #DIV/0! | I4: черные с железкой классика | K4: =J4/J$26 -> #DIV/0! | L4: =K4 -> #DIV/0! | M4: =_xlfn.IFS(L4<80%,"A",L4<=95%,"B",L4>95%,"C") -> #DIV/0!
B5: qs черные | D5: =C5/C$26 -> #DIV/0! | E5: =D5+E4 -> #DIV/0! | F5: =IF(AND(E5<=0),"C",IF(E5<=0.8,"A",IF(E5<=0.95,"B","C"))) -> #DIV/0! | G5: =VLOOKUP(B$4:B$25,I$4:M$25,5,0) -> #DIV/0! | I5: qs черные | K5: =J5/J$26 -> #DIV/0! | L5: =K5+L4 -> #DIV/0! | M5: =_xlfn.IFS(L5<80%,"A",L5<=95%,"B",L5>95%,"C") -> #DIV/0!
B6: qs синие | D6: =C6/C$26 -> #DIV/0! | E6: =D6+E5 -> #DIV/0! | F6: =IF(AND(E6<=0),"C",IF(E6<=0.8,"A",IF(E6<=0.95,"B","C"))) -> #DIV/0! | G6: =VLOOKUP(B$4:B$25,I$4:M$25,5,0) -> #DIV/0! | I6: qs синие | K6: =J6/J$26 -> #DIV/0! | L6: =K6+L5 -> #DIV/0! | M6: =_xlfn.IFS(L6<80%,"A",L6<=95%,"B",L6>95%,"C") -> #DIV/0!
B7: qs желтые | D7: =C7/C$26 -> #DIV/0! | E7: =D7+E6 -> #DIV/0! | F7: =IF(AND(E7<=0),"C",IF(E7<=0.8,"A",IF(E7<=0.95,"B","C"))) -> #DIV/0! | G7: =VLOOKUP(B$4:B$25,I$4:M$25,5,0) -> #DIV/0! | I7: qs желтые | K7: =J7/J$26 -> #DIV/0! | L7: =K7+L6 -> #DIV/0! | M7: =_xlfn.IFS(L7<80%,"A",L7<=95%,"B",L7>95%,"C") -> #DIV/0!
B8: qs коричневые | D8: =C8/C$26 -> #DIV/0! | E8: =D8+E7 -> #DIV/0! | F8: =IF(AND(E8<=0),"C",IF(E8<=0.8,"A",IF(E8<=0.95,"B","C"))) -> #DIV/0! | G8: =VLOOKUP(B$4:B$25,I$4:M$25,5,0) -> #DIV/0! | I8: qs коричневые | K8: =J8/J$26 -> #DIV/0! | L8: =K8+L7 -> #DIV/0! | M8: =_xlfn.IFS(L8<80%,"A",L8<=95%,"B",L8>95%,"C") -> #DIV/0!
B9: th желтый Сул | D9: =C9/C$26 -> #DIV/0! | E9: =D9+E8 -> #DIV/0! | F9: =IF(AND(E9<=0),"C",IF(E9<=0.8,"A",IF(E9<=0.95,"B","C"))) -> #DIV/0! | G9: =VLOOKUP(B$4:B$25,I$4:M$25,5,0) -> #DIV/0! | I9: th желтый Сул | K9: =J9/J$26 -> #DIV/0! | L9: =K9+L8 -> #DIV/0! | M9: =_xlfn.IFS(L9<80%,"A",L9<=95%,"B",L9>95%,"C") -> #DIV/0!
B10: flip желтые Сул | D10: =C10/C$26 -> #DIV/0! | E10: =D10+E9 -> #DIV/0! | F10: =IF(AND(E10<=0),"C",IF(E10<=0.8,"A",IF(E10<=0.95,"B","C"))) -> #DIV/0! | G10: =VLOOKUP(B$4:B$25,I$4:M$25,5,0) -> #DIV/0! | I10: flip желтые Сул | K10: =J10/J$26 -> #DIV/0! | L10: =K10+L9 -> #DIV/0! | M10: =_xlfn.IFS(L10<80%,"A",L10<=95%,"B",L10>95%,"C") -> #DIV/0!
B11: MR8854 C2 | D11: =C11/C$26 -> #DIV/0! | E11: =D11+E8 -> #DIV/0! | F11: =IF(AND(E11<=0),"C",IF(E11<=0.8,"A",IF(E11<=0.95,"B","C"))) -> #DIV/0! | G11: =VLOOKUP(B$4:B$25,I$4:M$25,5,0) -> #DIV/0! | I11: MR8854 C2 | K11: =J11/J$26 -> #DIV/0! | L11: =K11+L8 -> #DIV/0! | M11: =_xlfn.IFS(L11<80%,"A",L11<=95%,"B",L11>95%,"C") -> #DIV/0!
B12: MR 1819 черн | D12: =C12/C$26 -> #DIV/0! | E12: =D12+E11 -> #DIV/0! | F12: =IF(AND(E12<=0),"C",IF(E12<=0.8,"A",IF(E12<=0.95,"B","C"))) -> #DIV/0! | G12: =VLOOKUP(B$4:B$25,I$4:M$25,5,0) -> #DIV/0! | I12: MR 1819 черн | K12: =J12/J$26 -> #DIV/0! | L12: =K12+L11 -> #DIV/0! | M12: =_xlfn.IFS(L12<80%,"A",L12<=95%,"B",L12>95%,"C") -> #DIV/0!
B13: MR 1819 корич | D13: =C13/C$26 -> #DIV/0! | E13: =D13+E12 -> #DIV/0! | F13: =IF(AND(E13<=0),"C",IF(E13<=0.8,"A",IF(E13<=0.95,"B","C"))) -> #DIV/0! | G13: =VLOOKUP(B$4:B$25,I$4:M$25,5,0) -> #DIV/0! | I13: MR 1819 корич | K13: =J13/J$26 -> #DIV/0! | L13: =K13+L12 -> #DIV/0! | M13: =_xlfn.IFS(L13<80%,"A",L13<=95%,"B",L13>95%,"C") -> #DIV/0! | P13: A | Q13: 0.8
B14: MR Р1874 черн | D14: =C14/C$26 -> #DIV/0! | E14: =D14+E13 -> #DIV/0! | F14: =IF(AND(E14<=0),"C",IF(E14<=0.8,"A",IF(E14<=0.95,"B","C"))) -> #DIV/0! | G14: =VLOOKUP(B$4:B$25,I$4:M$25,5,0) -> #DIV/0! | I14: MR Р1874 черн | K14: =J14/J$26 -> #DIV/0! | L14: =K14+L13 -> #DIV/0! | M14: =_xlfn.IFS(L14<80%,"A",L14<=95%,"B",L14>95%,"C") -> #DIV/0! | P14: B | Q14: 0.15
B15: MR Р1874 корич | D15: =C15/C$26 -> #DIV/0! | E15: =D15+E14 -> #DIV/0! | F15: =IF(AND(E15<=0),"C",IF(E15<=0.8,"A",IF(E15<=0.95,"B","C"))) -> #DIV/0! | G15: =VLOOKUP(B$4:B$25,I$4:M$25,5,0) -> #DIV/0! | I15: MR Р1874 корич | K15: =J15/J$26 -> #DIV/0! | L15: =K15+L14 -> #DIV/0! | M15: =_xlfn.IFS(L15<80%,"A",L15<=95%,"B",L15>95%,"C") -> #DIV/0! | P15: C | Q15: 0.05
B16: MR Р1886 черн глянец | D16: =C16/C$26 -> #DIV/0! | E16: =D16+E15 -> #DIV/0! | F16: =IF(AND(E16<=0),"C",IF(E16<=0.8,"A",IF(E16<=0.95,"B","C"))) -> #DIV/0! | G16: =VLOOKUP(B$4:B$25,I$4:M$25,5,0) -> #DIV/0! | I16: MR Р1886 черн глянец | K16: =J16/J$26 -> #DIV/0! | L16: =K16+L15 -> #DIV/0! | M16: =_xlfn.IFS(L16<80%,"A",L16<=95%,"B",L16>95%,"C") -> #DIV/0!
B17: MR Р1886 корич | D17: =C17/C$26 -> #DIV/0! | E17: =D17+E16 -> #DIV/0! | F17: =IF(AND(E17<=0),"C",IF(E17<=0.8,"A",IF(E17<=0.95,"B","C"))) -> #DIV/0! | G17: =VLOOKUP(B$4:B$25,I$4:M$25,5,0) -> #DIV/0! | I17: MR Р1886 корич | K17: =J17/J$26 -> #DIV/0! | L17: =K17+L16 -> #DIV/0! | M17: =_xlfn.IFS(L17<80%,"A",L17<=95%,"B",L17>95%,"C") -> #DIV/0!
B18: lux1 | D18: =C18/C$26 -> #DIV/0! | E18: =D18+E17 -> #DIV/0! | F18: =IF(AND(E18<=0),"C",IF(E18<=0.8,"A",IF(E18<=0.95,"B","C"))) -> #DIV/0! | G18: =VLOOKUP(B$4:B$25,I$4:M$25,5,0) -> #DIV/0! | I18: lux1 | K18: =J18/J$26 -> #DIV/0! | L18: =K18+L17 -> #DIV/0! | M18: =_xlfn.IFS(L18<80%,"A",L18<=95%,"B",L18>95%,"C") -> #DIV/0!
B19: lux2 | D19: =C19/C$26 -> #DIV/0! | E19: =D19+E18 -> #DIV/0! | F19: =IF(AND(E19<=0),"C",IF(E19<=0.8,"A",IF(E19<=0.95,"B","C"))) -> #DIV/0! | G19: =VLOOKUP(B$4:B$25,I$4:M$25,5,0) -> #DIV/0! | I19: lux2 | K19: =J19/J$26 -> #DIV/0! | L19: =K19+L18 -> #DIV/0! | M19: =_xlfn.IFS(L19<80%,"A",L19<=95%,"B",L19>95%,"C") -> #DIV/0!
B20: lux3 | D20: =C20/C$26 -> #DIV/0! | E20: =D20+E19 -> #DIV/0! | F20: =IF(AND(E20<=0),"C",IF(E20<=0.8,"A",IF(E20<=0.95,"B","C"))) -> #DIV/0! | G20: =VLOOKUP(B$4:B$25,I$4:M$25,5,0) -> #DIV/0! | I20: lux3 | K20: =J20/J$26 -> #DIV/0! | L20: =K20+L19 -> #DIV/0! | M20: =_xlfn.IFS(L20<80%,"A",L20<=95%,"B",L20>95%,"C") -> #DIV/0!
B21: lux4 | D21: =C21/C$26 -> #DIV/0! | E21: =D21+E20 -> #DIV/0! | F21: =IF(AND(E21<=0),"C",IF(E21<=0.8,"A",IF(E21<=0.95,"B","C"))) -> #DIV/0! | G21: =VLOOKUP(B$4:B$25,I$4:M$25,5,0) -> #DIV/0! | I21: lux4 | K21: =J21/J$26 -> #DIV/0! | L21: =K21+L20 -> #DIV/0! | M21: =_xlfn.IFS(L21<80%,"A",L21<=95%,"B",L21>95%,"C") -> #DIV/0!
B22: lux5 | D22: =C22/C$26 -> #DIV/0! | E22: =D22+E21 -> #DIV/0! | F22: =IF(AND(E22<=0),"C",IF(E22<=0.8,"A",IF(E22<=0.95,"B","C"))) -> #DIV/0! | G22: =VLOOKUP(B$4:B$25,I$4:M$25,5,0) -> #DIV/0! | I22: lux5 | K22: =J22/J$26 -> #DIV/0! | L22: =K22+L21 -> #DIV/0! | M22: =_xlfn.IFS(L22<80%,"A",L22<=95%,"B",L22>95%,"C") -> #DIV/0!
B23: lux6 | D23: =C23/C$26 -> #DIV/0! | E23: =D23+E22 -> #DIV/0! | F23: =IF(AND(E23<=0),"C",IF(E23<=0.8,"A",IF(E23<=0.95,"B","C"))) -> #DIV/0! | G23: =VLOOKUP(B$4:B$25,I$4:M$25,5,0) -> #DIV/0! | I23: lux6 | K23: =J23/J$26 -> #DIV/0! | L23: =K23+L22 -> #DIV/0! | M23: =_xlfn.IFS(L23<80%,"A",L23<=95%,"B",L23>95%,"C") -> #DIV/0!
B24: lux7 | D24: =C24/C$26 -> #DIV/0! | E24: =D24+E23 -> #DIV/0! | F24: =IF(AND(E24<=0),"C",IF(E24<=0.8,"A",IF(E24<=0.95,"B","C"))) -> #DIV/0! | G24: =VLOOKUP(B$4:B$25,I$4:M$25,5,0) -> #DIV/0! | I24: lux7 | K24: =J24/J$26 -> #DIV/0! | L24: =K24+L23 -> #DIV/0! | M24: =_xlfn.IFS(L24<80%,"A",L24<=95%,"B",L24>95%,"C") -> #DIV/0!
B25: lux8 | D25: =C25/C$26 -> #DIV/0! | E25: =D25+E24 -> #DIV/0! | F25: =IF(AND(E25<=0),"C",IF(E25<=0.8,"A",IF(E25<=0.95,"B","C"))) -> #DIV/0! | G25: =VLOOKUP(B$4:B$25,I$4:M$25,5,0) -> #DIV/0! | I25: lux8 | K25: =J25/J$26 -> #DIV/0! | L25: =K25+L24 -> #DIV/0! | M25: =_xlfn.IFS(L25<80%,"A",L25<=95%,"B",L25>95%,"C") -> #DIV/0!
C26: =SUM(C4:C25) -> 0 | D26: =SUM(D4:D25) -> #DIV/0! | J26: =SUM(J4:J25) -> 0 | K26: =SUM(K4:K25) -> #DIV/0!
B28: ТУНИКИ
C29: Прибыль | D29: % прибыль | E29: Доля | F29: ABC прибыль | G29: ABC кол-во | J29: Кол-во | K29: % кол-во | L29: Доля | M29: ABC кол-во
B30: tunika02 оливковая с руч вышивкой | D30: =C30/C$50 -> #DIV/0! | E30: =D30 -> #DIV/0! | F30: =IF(AND(E30<=0),"C",IF(E30<=0.8,"A",IF(E30<=0.95,"B","C"))) -> #DIV/0! | G30: =VLOOKUP(B$30:B$50,I$30:M$50,5,0) -> #DIV/0! | I30: tunika02 оливковая с руч вышивкой | K30: =J30/J$50 -> #DIV/0! | L30: =K30 -> #DIV/0! | M30: =_xlfn.IFS(L30<80%,"A",L30<=95%,"B",L30>95%,"C") -> #DIV/0!
B31: tunika03 черная распашная | D31: =C31/C$50 -> #DIV/0! | E31: =D31+E30 -> #DIV/0! | F31: =IF(AND(E31<=0),"C",IF(E31<=0.8,"A",IF(E31<=0.95,"B","C"))) -> #DIV/0! | G31: =VLOOKUP(B$30:B$50,I$30:M$50,5,0) -> #DIV/0! | I31: tunika03 черная распашная | K31: =J31/J$50 -> #DIV/0! | L31: =K31+L30 -> #DIV/0! | M31: =_xlfn.IFS(L31<80%,"A",L31<=95%,"B",L31>95%,"C") -> #DIV/0!
B32: tunika05 белая распашная | D32: =C32/C$50 -> #DIV/0! | E32: =D32+E31 -> #DIV/0! | F32: =IF(AND(E32<=0),"C",IF(E32<=0.8,"A",IF(E32<=0.95,"B","C"))) -> #DIV/0! | G32: =VLOOKUP(B$30:B$50,I$30:M$50,5,0) -> #DIV/0! | I32: tunika05 белая распашная | K32: =J32/J$50 -> #DIV/0! | L32: =K32+L31 -> #DIV/0! | M32: =_xlfn.IFS(L32<80%,"A",L32<=95%,"B",L32>95%,"C") -> #DIV/0!
B33: tunika06 белая | D33: =C33/C$50 -> #DIV/0! | E33: =D33+E32 -> #DIV/0! | F33: =IF(AND(E33<=0),"C",IF(E33<=0.8,"A",IF(E33<=0.95,"B","C"))) -> #DIV/0! | G33: =VLOOKUP(B$30:B$50,I$30:M$50,5,0) -> #DIV/0! | I33: tunika06 белая | K33: =J33/J$50 -> #DIV/0! | L33: =K33+L32 -> #DIV/0! | M33: =_xlfn.IFS(L33<80%,"A",L33<=95%,"B",L33>95%,"C") -> #DIV/0!
B34: tunika06 черная | D34: =C34/C$50 -> #DIV/0! | E34: =D34+E33 -> #DIV/0! | F34: =IF(AND(E34<=0),"C",IF(E34<=0.8,"A",IF(E34<=0.95,"B","C"))) -> #DIV/0! | G34: =VLOOKUP(B$30:B$50,I$30:M$50,5,0) -> #DIV/0! | I34: tunika06 черная | K34: =J34/J$50 -> #DIV/0! | L34: =K34+L33 -> #DIV/0! | M34: =_xlfn.IFS(L34<80%,"A",L34<=95%,"B",L34>95%,"C") -> #DIV/0!
B35: tunika07 кружево | D35: =C35/C$50 -> #DIV/0! | E35: =D35+E34 -> #DIV/0! | F35: =IF(AND(E35<=0),"C",IF(E35<=0.8,"A",IF(E35<=0.95,"B","C"))) -> #DIV/0! | G35: =VLOOKUP(B$30:B$50,I$30:M$50,5,0) -> #DIV/0! | I35: tunika07 кружево | K35: =J35/J$50 -> #DIV/0! | L35: =K35+L34 -> #DIV/0! | M35: =_xlfn.IFS(L35<80%,"A",L35<=95%,"B",L35>95%,"C") -> #DIV/0!
B36: tunika08 белая | D36: =C36/C$50 -> #DIV/0! | E36: =D36+E35 -> #DIV/0! | F36: =IF(AND(E36<=0),"C",IF(E36<=0.8,"A",IF(E36<=0.95,"B","C"))) -> #DIV/0! | G36: =VLOOKUP(B$30:B$50,I$30:M$50,5,0) -> #DIV/0! | I36: tunika08 белая | K36: =J36/J$50 -> #DIV/0! | L36: =K36+L35 -> #DIV/0! | M36: =_xlfn.IFS(L36<80%,"A",L36<=95%,"B",L36>95%,"C") -> #DIV/0!
B37: tunika08 черная | D37: =C37/C$50 -> #DIV/0! | E37: =D37+E36 -> #DIV/0! | F37: =IF(AND(E37<=0),"C",IF(E37<=0.8,"A",IF(E37<=0.95,"B","C"))) -> #DIV/0! | G37: =VLOOKUP(B$30:B$50,I$30:M$50,5,0) -> #DIV/0! | I37: tunika08 черная | K37: =J37/J$50 -> #DIV/0! | L37: =K37+L36 -> #DIV/0! | M37: =_xlfn.IFS(L37<80%,"A",L37<=95%,"B",L37>95%,"C") -> #DIV/0!
B38: tunika08 зеленая | D38: =C38/C$50 -> #DIV/0! | E38: =D38+E37 -> #DIV/0! | F38: =IF(AND(E38<=0),"C",IF(E38<=0.8,"A",IF(E38<=0.95,"B","C"))) -> #DIV/0! | G38: =VLOOKUP(B$30:B$50,I$30:M$50,5,0) -> #DIV/0! | I38: tunika08 зеленая | K38: =J38/J$50 -> #DIV/0! | L38: =K38+L37 -> #DIV/0! | M38: =_xlfn.IFS(L38<80%,"A",L38<=95%,"B",L38>95%,"C") -> #DIV/0!
B39: tunika09 кимоно | D39: =C39/C$50 -> #DIV/0! | E39: =D39+E38 -> #DIV/0! | F39: =IF(AND(E39<=0),"C",IF(E39<=0.8,"A",IF(E39<=0.95,"B","C"))) -> #DIV/0! | G39: =VLOOKUP(B$30:B$50,I$30:M$50,5,0) -> #DIV/0! | I39: tunika09 кимоно | K39: =J39/J$50 -> #DIV/0! | L39: =K39+L38 -> #DIV/0! | M39: =_xlfn.IFS(L39<80%,"A",L39<=95%,"B",L39>95%,"C") -> #DIV/0!
B40: tunika10 кимоно ч/б | D40: =C40/C$50 -> #DIV/0! | E40: =D40+E39 -> #DIV/0! | F40: =IF(AND(E40<=0),"C",IF(E40<=0.8,"A",IF(E40<=0.95,"B","C"))) -> #DIV/0! | G40: =VLOOKUP(B$30:B$50,I$30:M$50,5,0) -> #DIV/0! | I40: tunika10 кимоно ч/б | K40: =J40/J$50 -> #DIV/0! | L40: =K40+L39 -> #DIV/0! | M40: =_xlfn.IFS(L40<80%,"A",L40<=95%,"B",L40>95%,"C") -> #DIV/0!
B41: tunika11 халат зеленая | D41: =C41/C$50 -> #DIV/0! | E41: =D41+E40 -> #DIV/0! | F41: =IF(AND(E41<=0),"C",IF(E41<=0.8,"A",IF(E41<=0.95,"B","C"))) -> #DIV/0! | G41: =VLOOKUP(B$30:B$50,I$30:M$50,5,0) -> #DIV/0! | I41: tunika11 халат зеленая | K41: =J41/J$50 -> #DIV/0! | L41: =K41+L40 -> #DIV/0! | M41: =_xlfn.IFS(L41<80%,"A",L41<=95%,"B",L41>95%,"C") -> #DIV/0!
B42: tunika12 халат белая | D42: =C42/C$50 -> #DIV/0! | E42: =D42+E41 -> #DIV/0! | F42: =IF(AND(E42<=0),"C",IF(E42<=0.8,"A",IF(E42<=0.95,"B","C"))) -> #DIV/0! | G42: =VLOOKUP(B$30:B$50,I$30:M$50,5,0) -> #DIV/0! | I42: tunika12 халат белая | K42: =J42/J$50 -> #DIV/0! | L42: =K42+L41 -> #DIV/0! | M42: =_xlfn.IFS(L42<80%,"A",L42<=95%,"B",L42>95%,"C") -> #DIV/0!
...

Sheet АВС ФЕВРАЛЬ
B2: ОЧКИ
C3: Прибыль | D3: % прибыль | E3: Доля | F3: ABC прибыль | G3: ABC кол-во | J3: Кол-во | K3: % кол-во | L3: Доля | M3: ABC кол-во
B4: черные с железкой классика | C4: =ФЕВРАЛЬ!AE3 -> 77132.294 | D4: =C4/C$26 -> 0.74395918 | E4: =D4 -> 0.74395918 | F4: =IF(AND(E4<=0),"C",IF(E4<=0.8,"A",IF(E4<=0.95,"B","C"))) -> A | G4: =VLOOKUP(B$4:B$25,I$4:M$25,5,0) -> A | I4: черные с железкой классика | J4: =ФЕВРАЛЬ!R3 -> 166 | K4: =J4/J$26 -> 0.55333333 | L4: =K4 -> 0.55333333 | M4: =_xlfn.IFS(L4<80%,"A",L4<=95%,"B",L4>95%,"C") -> A
B5: qs желтые | C5: =ФЕВРАЛЬ!AE6 -> 6378.7419 | D5: =C5/C$26 -> 0.061524471 | E5: =D5+E4 -> 0.80548365 | F5: =IF(AND(E5<=0),"C",IF(E5<=0.8,"A",IF(E5<=0.95,"B","C"))) -> B | G5: =VLOOKUP(B$4:B$25,I$4:M$25,5,0) -> A | I5: qs коричневые | J5: =ФЕВРАЛЬ!R7 -> 27 | K5: =J5/J$26 -> 0.09 | L5: =K5+L4 -> 0.64333333 | M5: =_xlfn.IFS(L5<80%,"A",L5<=95%,"B",L5>95%,"C") -> A
B6: MR8854 C2 | C6: =ФЕВРАЛЬ!AE10 -> 5822.0094 | D6: =C6/C$26 -> 0.056154655 | E6: =D6+E5 -> 0.86163831 | F6: =IF(AND(E6<=0),"C",IF(E6<=0.8,"A",IF(E6<=0.95,"B","C"))) -> B | G6: =VLOOKUP(B$4:B$25,I$4:M$25,5,0) -> B | I6: qs желтые | J6: =ФЕВРАЛЬ!R6 -> 19 | K6: =J6/J$26 -> 0.063333333 | L6: =K6+L5 -> 0.70666667 | M6: =_xlfn.IFS(L6<80%,"A",L6<=95%,"B",L6>95%,"C") -> A
B7: MR Р1874 черн | C7: =ФЕВРАЛЬ!AE13 -> 5494.0231 | D7: =C7/C$26 -> 0.05299115 | E7: =D7+E6 -> 0.91462946 | F7: =IF(AND(E7<=0),"C",IF(E7<=0.8,"A",IF(E7<=0.95,"B","C"))) -> B | G7: =VLOOKUP(B$4:B$25,I$4:M$25,5,0) -> A | I7: MR Р1874 черн | J7: =ФЕВРАЛЬ!R13 -> 19 | K7: =J7/J$26 -> 0.063333333 | L7: =K7+L6 -> 0.77 | M7: =_xlfn.IFS(L7<80%,"A",L7<=95%,"B",L7>95%,"C") -> A
B8: qs коричневые | C8: =ФЕВРАЛЬ!AE7 -> 3289.8918 | D8: =C8/C$26 -> 0.031731783 | E8: =D8+E7 -> 0.94636124 | F8: =IF(AND(E8<=0),"C",IF(E8<=0.8,"A",IF(E8<=0.95,"B","C"))) -> B | G8: =VLOOKUP(B$4:B$25,I$4:M$25,5,0) -> A | I8: MR8854 C2 | J8: =ФЕВРАЛЬ!R10 -> 18 | K8: =J8/J$26 -> 0.06 | L8: =K8+L7 -> 0.83 | M8: =_xlfn.IFS(L8<80%,"A",L8<=95%,"B",L8>95%,"C") -> B
B9: flip желтые Сул | C9: =ФЕВРАЛЬ!AE9 -> 2485.3387 | D9: =C9/C$26 -> 0.023971679 | E9: =D9+E8 -> 0.97033292 | F9: =IF(AND(E9<=0),"C",IF(E9<=0.8,"A",IF(E9<=0.95,"B","C"))) -> C | G9: =VLOOKUP(B$4:B$25,I$4:M$25,5,0) -> B | I9: MR Р1886 черн глянец | J9: =ФЕВРАЛЬ!R15 -> 16 | K9: =J9/J$26 -> 0.053333333 | L9: =K9+L8 -> 0.88333333 | M9: =_xlfn.IFS(L9<80%,"A",L9<=95%,"B",L9>95%,"C") -> B
B10: MR 1819 корич | C10: =ФЕВРАЛЬ!AE12 -> 1757.9816 | D10: =C10/C$26 -> 0.016956148 | E10: =D10+E9 -> 0.98728907 | F10: =IF(AND(E10<=0),"C",IF(E10<=0.8,"A",IF(E10<=0.95,"B","C"))) -> C | G10: =VLOOKUP(B$4:B$25,I$4:M$25,5,0) -> B | I10: flip желтые Сул | J10: =ФЕВРАЛЬ!R9 -> 12 | K10: =J10/J$26 -> 0.04 | L10: =K10+L9 -> 0.92333333 | M10: =_xlfn.IFS(L10<80%,"A",L10<=95%,"B",L10>95%,"C") -> B
B11: th желтый Сул | C11: =ФЕВРАЛЬ!AE8 -> 1380.6419 | D11: =C11/C$26 -> 0.013316617 | E11: =D11+E8 -> 0.95967786 | F11: =IF(AND(E11<=0),"C",IF(E11<=0.8,"A",IF(E11<=0.95,"B","C"))) -> C | G11: =VLOOKUP(B$4:B$25,I$4:M$25,5,0) -> B | I11: th желтый Сул | J11: =ФЕВРАЛЬ!R8 -> 6 | K11: =J11/J$26 -> 0.02 | L11: =K11+L8 -> 0.85 | M11: =_xlfn.IFS(L11<80%,"A",L11<=95%,"B",L11>95%,"C") -> B
B12: qs черные | C12: =ФЕВРАЛЬ!AE4 -> 441.06216 | D12: =C12/C$26 -> 0.0042541487 | E12: =D12+E11 -> 0.96393201 | F12: =IF(AND(E12<=0),"C",IF(E12<=0.8,"A",IF(E12<=0.95,"B","C"))) -> C | G12: =VLOOKUP(B$4:B$25,I$4:M$25,5,0) -> B | I12: qs черные | J12: =ФЕВРАЛЬ!R4 -> 5 | K12: =J12/J$26 -> 0.016666667 | L12: =K12+L11 -> 0.86666667 | M12: =_xlfn.IFS(L12<80%,"A",L12<=95%,"B",L12>95%,"C") -> B
B13: MR Р1886 корич | C13: =ФЕВРАЛЬ!AE16 -> 243.47954 | D13: =C13/C$26 -> 0.0023484176 | E13: =D13+E12 -> 0.96628042 | F13: =IF(AND(E13<=0),"C",IF(E13<=0.8,"A",IF(E13<=0.95,"B","C"))) -> C | G13: =VLOOKUP(B$4:B$25,I$4:M$25,5,0) -> B | I13: MR 1819 корич | J13: =ФЕВРАЛЬ!R12 -> 4 | K13: =J13/J$26 -> 0.013333333 | L13: =K13+L12 -> 0.88 | M13: =_xlfn.IFS(L13<80%,"A",L13<=95%,"B",L13>95%,"C") -> B | P13: A | Q13: 0.8
B14: MR Р1886 черн глянец | C14: =ФЕВРАЛЬ!AE15 -> 19.779702 | D14: =C14/C$26 -> 0.00019077989 | E14: =D14+E13 -> 0.9664712 | F14: =IF(AND(E14<=0),"C",IF(E14<=0.8,"A",IF(E14<=0.95,"B","C"))) -> C | G14: =VLOOKUP(B$4:B$25,I$4:M$25,5,0) -> B | I14: qs синие | J14: =ФЕВРАЛЬ!R5 -> 3 | K14: =J14/J$26 -> 0.01 | L14: =K14+L13 -> 0.89 | M14: =_xlfn.IFS(L14<80%,"A",L14<=95%,"B",L14>95%,"C") -> B | P14: B | Q14: 0.15
B15: MR 1819 черн | C15: =ФЕВРАЛЬ!AE11 -> 9.6613093 | D15: =C15/C$26 -> 9.3185608e-05 | E15: =D15+E14 -> 0.96656439 | F15: =IF(AND(E15<=0),"C",IF(E15<=0.8,"A",IF(E15<=0.95,"B","C"))) -> C | G15: =VLOOKUP(B$4:B$25,I$4:M$25,5,0) -> B | I15: MR Р1874 корич | J15: =ФЕВРАЛЬ!R14 -> 2 | K15: =J15/J$26 -> 0.0066666667 | L15: =K15+L14 -> 0.89666667 | M15: =_xlfn.IFS(L15<80%,"A",L15<=95%,"B",L15>95%,"C") -> B | P15: C | Q15: 0.05
B16: lux1 | C16: =ФЕВРАЛЬ!AE17 -> 0 | D16: =C16/C$26 -> 0 | E16: =D16+E15 -> 0.96656439 | F16: =IF(AND(E16<=0),"C",IF(E16<=0.8,"A",IF(E16<=0.95,"B","C"))) -> C | G16: =VLOOKUP(B$4:B$25,I$4:M$25,5,0) -> B | I16: MR Р1886 корич | J16: =ФЕВРАЛЬ!R16 -> 2 | K16: =J16/J$26 -> 0.0066666667 | L16: =K16+L15 -> 0.90333333 | M16: =_xlfn.IFS(L16<80%,"A",L16<=95%,"B",L16>95%,"C") -> B
B17: lux2 | C17: =ФЕВРАЛЬ!AE18 -> 0 | D17: =C17/C$26 -> 0 | E17: =D17+E16 -> 0.96656439 | F17: =IF(AND(E17<=0),"C",IF(E17<=0.8,"A",IF(E17<=0.95,"B","C"))) -> C | G17: =VLOOKUP(B$4:B$25,I$4:M$25,5,0) -> B | I17: MR 1819 черн | J17: =ФЕВРАЛЬ!R11 -> 1 | K17: =J17/J$26 -> 0.0033333333 | L17: =K17+L16 -> 0.90666667 | M17: =_xlfn.IFS(L17<80%,"A",L17<=95%,"B",L17>95%,"C") -> B
B18: lux5 | C18: =ФЕВРАЛЬ!AE21 -> 0 | D18: =C18/C$26 -> 0 | E18: =D18+E17 -> 0.96656439 | F18: =IF(AND(E18<=0),"C",IF(E18<=0.8,"A",IF(E18<=0.95,"B","C"))) -> C | G18: =VLOOKUP(B$4:B$25,I$4:M$25,5,0) -> B | I18: lux1 | J18: =ФЕВРАЛЬ!R17 -> 0 | K18: =J18/J$26 -> 0 | L18: =K18+L17 -> 0.90666667 | M18: =_xlfn.IFS(L18<80%,"A",L18<=95%,"B",L18>95%,"C") -> B
B19: lux6 | C19: =ФЕВРАЛЬ!AE22 -> 0 | D19: =C19/C$26 -> 0 | E19: =D19+E18 -> 0.96656439 | F19: =IF(AND(E19<=0),"C",IF(E19<=0.8,"A",IF(E19<=0.95,"B","C"))) -> C | G19: =VLOOKUP(B$4:B$25,I$4:M$25,5,0) -> B | I19: lux2 | J19: =ФЕВРАЛЬ!R18 -> 0 | K19: =J19/J$26 -> 0 | L19: =K19+L18 -> 0.90666667 | M19: =_xlfn.IFS(L19<80%,"A",L19<=95%,"B",L19>95%,"C") -> B
B20: lux7 | C20: =ФЕВРАЛЬ!AE23 -> 0 | D20: =C20/C$26 -> 0 | E20: =D20+E19 -> 0.96656439 | F20: =IF(AND(E20<=0),"C",IF(E20<=0.8,"A",IF(E20<=0.95,"B","C"))) -> C | G20: =VLOOKUP(B$4:B$25,I$4:M$25,5,0) -> B | I20: lux3 | J20: =ФЕВРАЛЬ!R19 -> 0 | K20: =J20/J$26 -> 0 | L20: =K20+L19 -> 0.90666667 | M20: =_xlfn.IFS(L20<80%,"A",L20<=95%,"B",L20>95%,"C") -> B
B21: lux8 | C21: =ФЕВРАЛЬ!AE24 -> 0 | D21: =C21/C$26 -> 0 | E21: =D21+E20 -> 0.96656439 | F21: =IF(AND(E21<=0),"C",IF(E21<=0.8,"A",IF(E21<=0.95,"B","C"))) -> C | G21: =VLOOKUP(B$4:B$25,I$4:M$25,5,0) -> B | I21: lux4 | J21: =ФЕВРАЛЬ!R20 -> 0 | K21: =J21/J$26 -> 0 | L21: =K21+L20 -> 0.90666667 | M21: =_xlfn.IFS(L21<80%,"A",L21<=95%,"B",L21>95%,"C") -> B
B22: qs синие | C22: =ФЕВРАЛЬ!AE5 -> -35.117451 | D22: =C22/C$26 -> -0.00033871611 | E22: =D22+E21 -> 0.96622567 | F22: =IF(AND(E22<=0),"C",IF(E22<=0.8,"A",IF(E22<=0.95,"B","C"))) -> C | G22: =VLOOKUP(B$4:B$25,I$4:M$25,5,0) -> B | I22: lux5 | J22: =ФЕВРАЛЬ!R21 -> 0 | K22: =J22/J$26 -> 0 | L22: =K22+L21 -> 0.90666667 | M22: =_xlfn.IFS(L22<80%,"A",L22<=95%,"B",L22>95%,"C") -> B
B23: lux3 | C23: =ФЕВРАЛЬ!AE19 -> -227.76 | D23: =C23/C$26 -> -0.002196799 | E23: =D23+E22 -> 0.96402887 | F23: =IF(AND(E23<=0),"C",IF(E23<=0.8,"A",IF(E23<=0.95,"B","C"))) -> C | G23: =VLOOKUP(B$4:B$25,I$4:M$25,5,0) -> B | I23: lux6 | J23: =ФЕВРАЛЬ!R22 -> 0 | K23: =J23/J$26 -> 0 | L23: =K23+L22 -> 0.90666667 | M23: =_xlfn.IFS(L23<80%,"A",L23<=95%,"B",L23>95%,"C") -> B
B24: MR Р1874 корич | C24: =ФЕВРАЛЬ!AE14 -> -235.72137 | D24: =C24/C$26 -> -0.0022735882 | E24: =D24+E23 -> 0.96175529 | F24: =IF(AND(E24<=0),"C",IF(E24<=0.8,"A",IF(E24<=0.95,"B","C"))) -> C | G24: =VLOOKUP(B$4:B$25,I$4:M$25,5,0) -> B | I24: lux7 | J24: =ФЕВРАЛЬ!R23 -> 0 | K24: =J24/J$26 -> 0 | L24: =K24+L23 -> 0.90666667 | M24: =_xlfn.IFS(L24<80%,"A",L24<=95%,"B",L24>95%,"C") -> B
B25: lux4 | C25: =ФЕВРАЛЬ!AE20 -> -278.18 | D25: =C25/C$26 -> -0.0026831117 | E25: =D25+E24 -> 0.95907217 | F25: =IF(AND(E25<=0),"C",IF(E25<=0.8,"A",IF(E25<=0.95,"B","C"))) -> C | G25: =VLOOKUP(B$4:B$25,I$4:M$25,5,0) -> B | I25: lux8 | J25: =ФЕВРАЛЬ!R24 -> 0 | K25: =J25/J$26 -> 0 | L25: =K25+L24 -> 0.90666667 | M25: =_xlfn.IFS(L25<80%,"A",L25<=95%,"B",L25>95%,"C") -> B
C26: =SUM(C4:C25) -> 103678.13 | D26: =SUM(D4:D25) -> 1 | J26: =SUM(J4:J25) -> 300 | K26: =SUM(K4:K25) -> 1
B28: ТУНИКИ
C29: Прибыль | D29: % прибыль | E29: Доля | F29: ABC прибыль | G29: ABC кол-во | J29: Кол-во | K29: % кол-во | L29: Доля | M29: ABC кол-во
B30: tunika15 кимоно бирюза | C30: =ФЕВРАЛЬ!AE44 -> 16181.565 | D30: =C30/C$50 -> 0.244031 | E30: =D30 -> 0.244031 | F30: =IF(AND(E30<=0),"C",IF(E30<=0.8,"A",IF(E30<=0.95,"B","C"))) -> A | G30: =VLOOKUP(B$30:B$50,I$30:M$50,5,0) -> A | I30: tunika16 сетка белая | J30: =ФЕВРАЛЬ!R46 -> 22 | K30: =J30/J$50 -> 0.24444444 | L30: =K30 -> 0.24444444 | M30: =_xlfn.IFS(L30<80%,"A",L30<=95%,"B",L30>95%,"C") -> A
B31: tunika09 кимоно | C31: =ФЕВРАЛЬ!AE37 -> 14759.606 | D31: =C31/C$50 -> 0.22258673 | E31: =D31+E30 -> 0.46661773 | F31: =IF(AND(E31<=0),"C",IF(E31<=0.8,"A",IF(E31<=0.95,"B","C"))) -> A | G31: =VLOOKUP(B$30:B$50,I$30:M$50,5,0) -> A | I31: tunika15 кимоно песочная | J31: =ФЕВРАЛЬ!R45 -> 20 | K31: =J31/J$50 -> 0.22222222 | L31: =K31+L30 -> 0.46666667 | M31: =_xlfn.IFS(L31<80%,"A",L31<=95%,"B",L31>95%,"C") -> A
B32: tunika15 кимоно песочная | C32: =ФЕВРАЛЬ!AE45 -> 8336.1811 | D32: =C32/C$50 -> 0.12571631 | E32: =D32+E31 -> 0.59233404 | F32: =IF(AND(E32<=0),"C",IF(E32<=0.8,"A",IF(E32<=0.95,"B","C"))) -> A | G32: =VLOOKUP(B$30:B$50,I$30:M$50,5,0) -> A | I32: tunika15 кимоно бирюза | J32: =ФЕВРАЛЬ!R44 -> 18 | K32: =J32/J$50 -> 0.2 | L32: =K32+L31 -> 0.66666667 | M32: =_xlfn.IFS(L32<80%,"A",L32<=95%,"B",L32>95%,"C") -> A
B33: tunika16 сетка белая | C33: =ФЕВРАЛЬ!AE46 -> 7633.3938 | D33: =C33/C$50 -> 0.11511771 | E33: =D33+E32 -> 0.70745175 | F33: =IF(AND(E33<=0),"C",IF(E33<=0.8,"A",IF(E33<=0.95,"B","C"))) -> A | G33: =VLOOKUP(B$30:B$50,I$30:M$50,5,0) -> A | I33: tunika09 кимоно | J33: =ФЕВРАЛЬ!R37 -> 8 | K33: =J33/J$50 -> 0.088888889 | L33: =K33+L32 -> 0.75555556 | M33: =_xlfn.IFS(L33<80%,"A",L33<=95%,"B",L33>95%,"C") -> A
B34: tunika14 халат с разрезами черный | C34: =ФЕВРАЛЬ!AE43 -> 3896.0955 | D34: =C34/C$50 -> 0.058756251 | E34: =D34+E33 -> 0.766208 | F34: =IF(AND(E34<=0),"C",IF(E34<=0.8,"A",IF(E34<=0.95,"B","C"))) -> A | G34: =VLOOKUP(B$30:B$50,I$30:M$50,5,0) -> B | I34: tunika14 халат с разрезами белая | J34: =ФЕВРАЛЬ!R42 -> 4 | K34: =J34/J$50 -> 0.044444444 | L34: =K34+L33 -> 0.8 | M34: =_xlfn.IFS(L34<80%,"A",L34<=95%,"B",L34>95%,"C") -> B
B35: tunika08 белая | C35: =ФЕВРАЛЬ!AE34 -> 3166.1898 | D35: =C35/C$50 -> 0.047748687 | E35: =D35+E34 -> 0.81395669 | F35: =IF(AND(E35<=0),"C",IF(E35<=0.8,"A",IF(E35<=0.95,"B","C"))) -> B | G35: =VLOOKUP(B$30:B$50,I$30:M$50,5,0) -> B | I35: tunika07 кружево | J35: =ФЕВРАЛЬ!R33 -> 3 | K35: =J35/J$50 -> 0.033333333 | L35: =K35+L34 -> 0.83333333 | M35: =_xlfn.IFS(L35<80%,"A",L35<=95%,"B",L35>95%,"C") -> B
B36: tunika12 халат белая | C36: =ФЕВРАЛЬ!AE40 -> 3105.9178 | D36: =C36/C$50 -> 0.046839736 | E36: =D36+E35 -> 0.86079643 | F36: =IF(AND(E36<=0),"C",IF(E36<=0.8,"A",IF(E36<=0.95,"B","C"))) -> B | G36: =VLOOKUP(B$30:B$50,I$30:M$50,5,0) -> B | I36: tunika14 халат с разрезами черный | J36: =ФЕВРАЛЬ!R43 -> 3 | K36: =J36/J$50 -> 0.033333333 | L36: =K36+L35 -> 0.86666667 | M36: =_xlfn.IFS(L36<80%,"A",L36<=95%,"B",L36>95%,"C") -> B
B37: tunika07 кружево | C37: =ФЕВРАЛЬ!AE33 -> 2753.8648 | D37: =C37/C$50 -> 0.041530494 | E37: =D37+E36 -> 0.90232692 | F37: =IF(AND(E37<=0),"C",IF(E37<=0.8,"A",IF(E37<=0.95,"B","C"))) -> B | G37: =VLOOKUP(B$30:B$50,I$30:M$50,5,0) -> B | I37: tunika05 белая распашная | J37: =ФЕВРАЛЬ!R30 -> 2 | K37: =J37/J$50 -> 0.022222222 | L37: =K37+L36 -> 0.88888889 | M37: =_xlfn.IFS(L37<80%,"A",L37<=95%,"B",L37>95%,"C") -> B
B38: tunika08 черная | C38: =ФЕВРАЛЬ!AE35 -> 2633.0503 | D38: =C38/C$50 -> 0.039708515 | E38: =D38+E37 -> 0.94203544 | F38: =IF(AND(E38<=0),"C",IF(E38<=0.8,"A",IF(E38<=0.95,"B","C"))) -> B | G38: =VLOOKUP(B$30:B$50,I$30:M$50,5,0) -> C | I38: tunika08 белая | J38: =ФЕВРАЛЬ!R34 -> 2 | K38: =J38/J$50 -> 0.022222222 | L38: =K38+L37 -> 0.91111111 | M38: =_xlfn.IFS(L38<80%,"A",L38<=95%,"B",L38>95%,"C") -> B
B39: tunika05 белая распашная | C39: =ФЕВРАЛЬ!AE30 -> 2145.1551 | D39: =C39/C$50 -> 0.032350663 | E39: =D39+E38 -> 0.9743861 | F39: =IF(AND(E39<=0),"C",IF(E39<=0.8,"A",IF(E39<=0.95,"B","C"))) -> C | G39: =VLOOKUP(B$30:B$50,I$30:M$50,5,0) -> B | I39: tunika12 халат белая | J39: =ФЕВРАЛЬ!R40 -> 2 | K39: =J39/J$50 -> 0.022222222 | L39: =K39+L38 -> 0.93333333 | M39: =_xlfn.IFS(L39<80%,"A",L39<=95%,"B",L39>95%,"C") -> B
B40: tunika06 белая | C40: =ФЕВРАЛЬ!AE31 -> 1514.5156 | D40: =C40/C$50 -> 0.022840112 | E40: =D40+E39 -> 0.99722621 | F40: =IF(AND(E40<=0),"C",IF(E40<=0.8,"A",IF(E40<=0.95,"B","C"))) -> C | G40: =VLOOKUP(B$30:B$50,I$30:M$50,5,0) -> C | I40: tunika16 сетка черная | J40: =ФЕВРАЛЬ!R47 -> 2 | K40: =J40/J$50 -> 0.022222222 | L40: =K40+L39 -> 0.95555556 | M40: =_xlfn.IFS(L40<80%,"A",L40<=95%,"B",L40>95%,"C") -> C
B41: tunika16 сетка черная | C41: =ФЕВРАЛЬ!AE47 -> 1147.9337 | D41: =C41/C$50 -> 0.017311762 | E41: =D41+E40 -> 1.014538 | F41: =IF(AND(E41<=0),"C",IF(E41<=0.8,"A",IF(E41<=0.95,"B","C"))) -> C | G41: =VLOOKUP(B$30:B$50,I$30:M$50,5,0) -> C | I41: tunika02 оливковая с руч вышивкой | J41: =ФЕВРАЛЬ!R28 -> 1 | K41: =J41/J$50 -> 0.011111111 | L41: =K41+L40 -> 0.96666667 | M41: =_xlfn.IFS(L41<80%,"A",L41<=95%,"B",L41>95%,"C") -> C
B42: tunika11 халат зеленая | C42: =ФЕВРАЛЬ!AE39 -> 917.63924 | D42: =C42/C$50 -> 0.013838737 | E42: =D42+E41 -> 1.0283767 | F42: =IF(AND(E42<=0),"C",IF(E42<=0.8,"A",IF(E42<=0.95,"B","C"))) -> C | G42: =VLOOKUP(B$30:B$50,I$30:M$50,5,0) -> C | I42: tunika06 белая | J42: =ФЕВРАЛЬ!R31 -> 1 | K42: =J42/J$50 -> 0.011111111 | L42: =K42+L41 -> 0.97777778 | M42: =_xlfn.IFS(L42<80%,"A",L42<=95%,"B",L42>95%,"C") -> C
...

Sheet АВС 23.02-01.03
B2: ОЧКИ
C3: Прибыль | D3: % прибыль | E3: Доля | F3: ABC прибыль | G3: ABC кол-во | J3: Кол-во | K3: % кол-во | L3: Доля | M3: ABC кол-во
B4: черные с железкой классика | C4: ='Юнит 23.02-01.03'!AE3 -> 33017.893 | D4: =C4/C$26 -> 0.6879919 | E4: =D4 -> 0.6879919 | F4: =IF(AND(E4<=0),"C",IF(E4<=0.8,"A",IF(E4<=0.95,"B","C"))) -> A | G4: =VLOOKUP(B$4:B$25,I$4:M$25,5,0) -> A | I4: черные с железкой классика | J4: ='Юнит 23.02-01.03'!R3 -> 55 | K4: =J4/J$26 -> 0.47008547 | L4: =K4 -> 0.47008547 | M4: =_xlfn.IFS(L4<80%,"A",L4<=95%,"B",L4>95%,"C") -> A
B5: qs желтые | C5: ='Юнит 23.02-01.03'!AE6 -> 5714.258 | D5: =C5/C$26 -> 0.11906766 | E5: =D5+E4 -> 0.80705956 | F5: =IF(AND(E5<=0),"C",IF(E5<=0.8,"A",IF(E5<=0.95,"B","C"))) -> B | G5: =VLOOKUP(B$4:B$25,I$4:M$25,5,0) -> A | I5: qs желтые | J5: ='Юнит 23.02-01.03'!R6 -> 12 | K5: =J5/J$26 -> 0.1025641 | L5: =K5+L4 -> 0.57264957 | M5: =_xlfn.IFS(L5<80%,"A",L5<=95%,"B",L5>95%,"C") -> A
B6: MR8854 C2 | C6: ='Юнит 23.02-01.03'!AE10 -> 4422.0429 | D6: =C6/C$26 -> 0.09214185 | E6: =D6+E5 -> 0.89920141 | F6: =IF(AND(E6<=0),"C",IF(E6<=0.8,"A",IF(E6<=0.95,"B","C"))) -> B | G6: =VLOOKUP(B$4:B$25,I$4:M$25,5,0) -> A | I6: MR8854 C2 | J6: ='Юнит 23.02-01.03'!R10 -> 11 | K6: =J6/J$26 -> 0.094017094 | L6: =K6+L5 -> 0.66666667 | M6: =_xlfn.IFS(L6<80%,"A",L6<=95%,"B",L6>95%,"C") -> A
B7: MR Р1874 черн | C7: ='Юнит 23.02-01.03'!AE13 -> 2403.0929 | D7: =C7/C$26 -> 0.050073107 | E7: =D7+E6 -> 0.94927452 | F7: =IF(AND(E7<=0),"C",IF(E7<=0.8,"A",IF(E7<=0.95,"B","C"))) -> B | G7: =VLOOKUP(B$4:B$25,I$4:M$25,5,0) -> B | I7: MR Р1886 черн глянец | J7: ='Юнит 23.02-01.03'!R15 -> 11 | K7: =J7/J$26 -> 0.094017094 | L7: =K7+L6 -> 0.76068376 | M7: =_xlfn.IFS(L7<80%,"A",L7<=95%,"B",L7>95%,"C") -> A
B8: qs коричневые | C8: ='Юнит 23.02-01.03'!AE7 -> 1638.1117 | D8: =C8/C$26 -> 0.034133238 | E8: =D8+E7 -> 0.98340776 | F8: =IF(AND(E8<=0),"C",IF(E8<=0.8,"A",IF(E8<=0.95,"B","C"))) -> C | G8: =VLOOKUP(B$4:B$25,I$4:M$25,5,0) -> B | I8: qs коричневые | J8: ='Юнит 23.02-01.03'!R7 -> 9 | K8: =J8/J$26 -> 0.076923077 | L8: =K8+L7 -> 0.83760684 | M8: =_xlfn.IFS(L8<80%,"A",L8<=95%,"B",L8>95%,"C") -> B
B9: qs черные | C9: ='Юнит 23.02-01.03'!AE4 -> 1601.8791 | D9: =C9/C$26 -> 0.033378261 | E9: =D9+E8 -> 1.016786 | F9: =IF(AND(E9<=0),"C",IF(E9<=0.8,"A",IF(E9<=0.95,"B","C"))) -> C | G9: =VLOOKUP(B$4:B$25,I$4:M$25,5,0) -> B | I9: MR Р1874 черн | J9: ='Юнит 23.02-01.03'!R13 -> 9 | K9: =J9/J$26 -> 0.076923077 | L9: =K9+L8 -> 0.91452991 | M9: =_xlfn.IFS(L9<80%,"A",L9<=95%,"B",L9>95%,"C") -> B
B10: MR 1819 корич | C10: ='Юнит 23.02-01.03'!AE12 -> 1428.7372 | D10: =C10/C$26 -> 0.029770513 | E10: =D10+E9 -> 1.0465565 | F10: =IF(AND(E10<=0),"C",IF(E10<=0.8,"A",IF(E10<=0.95,"B","C"))) -> C | G10: =VLOOKUP(B$4:B$25,I$4:M$25,5,0) -> B | I10: qs черные | J10: ='Юнит 23.02-01.03'!R4 -> 4 | K10: =J10/J$26 -> 0.034188034 | L10: =K10+L9 -> 0.94871795 | M10: =_xlfn.IFS(L10<80%,"A",L10<=95%,"B",L10>95%,"C") -> B
B11: th желтый Сул | C11: ='Юнит 23.02-01.03'!AE8 -> 375.86234 | D11: =C11/C$26 -> 0.0078318216 | E11: =D11+E8 -> 0.99123958 | F11: =IF(AND(E11<=0),"C",IF(E11<=0.8,"A",IF(E11<=0.95,"B","C"))) -> C | G11: =VLOOKUP(B$4:B$25,I$4:M$25,5,0) -> B | I11: MR 1819 корич | J11: ='Юнит 23.02-01.03'!R12 -> 3 | K11: =J11/J$26 -> 0.025641026 | L11: =K11+L8 -> 0.86324786 | M11: =_xlfn.IFS(L11<80%,"A",L11<=95%,"B",L11>95%,"C") -> B
B12: MR Р1874 корич | C12: ='Юнит 23.02-01.03'!AE14 -> 0 | D12: =C12/C$26 -> 0 | E12: =D12+E11 -> 0.99123958 | F12: =IF(AND(E12<=0),"C",IF(E12<=0.8,"A",IF(E12<=0.95,"B","C"))) -> C | G12: =VLOOKUP(B$4:B$25,I$4:M$25,5,0) -> B | I12: th желтый Сул | J12: ='Юнит 23.02-01.03'!R8 -> 1 | K12: =J12/J$26 -> 0.0085470085 | L12: =K12+L11 -> 0.87179487 | M12: =_xlfn.IFS(L12<80%,"A",L12<=95%,"B",L12>95%,"C") -> B
B13: lux1 | C13: ='Юнит 23.02-01.03'!AE17 -> 0 | D13: =C13/C$26 -> 0 | E13: =D13+E12 -> 0.99123958 | F13: =IF(AND(E13<=0),"C",IF(E13<=0.8,"A",IF(E13<=0.95,"B","C"))) -> C | G13: =VLOOKUP(B$4:B$25,I$4:M$25,5,0) -> B | I13: flip желтые Сул | J13: ='Юнит 23.02-01.03'!R9 -> 1 | K13: =J13/J$26 -> 0.0085470085 | L13: =K13+L12 -> 0.88034188 | M13: =_xlfn.IFS(L13<80%,"A",L13<=95%,"B",L13>95%,"C") -> B | P13: A | Q13: 0.8
B14: lux2 | C14: ='Юнит 23.02-01.03'!AE18 -> 0 | D14: =C14/C$26 -> 0 | E14: =D14+E13 -> 0.99123958 | F14: =IF(AND(E14<=0),"C",IF(E14<=0.8,"A",IF(E14<=0.95,"B","C"))) -> C | G14: =VLOOKUP(B$4:B$25,I$4:M$25,5,0) -> B | I14: MR Р1886 корич | J14: ='Юнит 23.02-01.03'!R16 -> 1 | K14: =J14/J$26 -> 0.0085470085 | L14: =K14+L13 -> 0.88888889 | M14: =_xlfn.IFS(L14<80%,"A",L14<=95%,"B",L14>95%,"C") -> B | P14: B | Q14: 0.15
B15: lux4 | C15: ='Юнит 23.02-01.03'!AE20 -> 0 | D15: =C15/C$26 -> 0 | E15: =D15+E14 -> 0.99123958 | F15: =IF(AND(E15<=0),"C",IF(E15<=0.8,"A",IF(E15<=0.95,"B","C"))) -> C | G15: =VLOOKUP(B$4:B$25,I$4:M$25,5,0) -> B | I15: qs синие | J15: ='Юнит 23.02-01.03'!R5 -> 0 | K15: =J15/J$26 -> 0 | L15: =K15+L14 -> 0.88888889 | M15: =_xlfn.IFS(L15<80%,"A",L15<=95%,"B",L15>95%,"C") -> B | P15: C | Q15: 0.05
B16: lux5 | C16: ='Юнит 23.02-01.03'!AE21 -> 0 | D16: =C16/C$26 -> 0 | E16: =D16+E15 -> 0.99123958 | F16: =IF(AND(E16<=0),"C",IF(E16<=0.8,"A",IF(E16<=0.95,"B","C"))) -> C | G16: =VLOOKUP(B$4:B$25,I$4:M$25,5,0) -> B | I16: MR 1819 черн | J16: ='Юнит 23.02-01.03'!R11 -> 0 | K16: =J16/J$26 -> 0 | L16: =K16+L15 -> 0.88888889 | M16: =_xlfn.IFS(L16<80%,"A",L16<=95%,"B",L16>95%,"C") -> B
B17: lux6 | C17: ='Юнит 23.02-01.03'!AE22 -> 0 | D17: =C17/C$26 -> 0 | E17: =D17+E16 -> 0.99123958 | F17: =IF(AND(E17<=0),"C",IF(E17<=0.8,"A",IF(E17<=0.95,"B","C"))) -> C | G17: =VLOOKUP(B$4:B$25,I$4:M$25,5,0) -> B | I17: MR Р1874 корич | J17: ='Юнит 23.02-01.03'!R14 -> 0 | K17: =J17/J$26 -> 0 | L17: =K17+L16 -> 0.88888889 | M17: =_xlfn.IFS(L17<80%,"A",L17<=95%,"B",L17>95%,"C") -> B
B18: lux7 | C18: ='Юнит 23.02-01.03'!AE23 -> 0 | D18: =C18/C$26 -> 0 | E18: =D18+E17 -> 0.99123958 | F18: =IF(AND(E18<=0),"C",IF(E18<=0.8,"A",IF(E18<=0.95,"B","C"))) -> C | G18: =VLOOKUP(B$4:B$25,I$4:M$25,5,0) -> B | I18: lux1 | J18: ='Юнит 23.02-01.03'!R17 -> 0 | K18: =J18/J$26 -> 0 | L18: =K18+L17 -> 0.88888889 | M18: =_xlfn.IFS(L18<80%,"A",L18<=95%,"B",L18>95%,"C") -> B
B19: lux8 | C19: ='Юнит 23.02-01.03'!AE24 -> 0 | D19: =C19/C$26 -> 0 | E19: =D19+E18 -> 0.99123958 | F19: =IF(AND(E19<=0),"C",IF(E19<=0.8,"A",IF(E19<=0.95,"B","C"))) -> C | G19: =VLOOKUP(B$4:B$25,I$4:M$25,5,0) -> B | I19: lux2 | J19: ='Юнит 23.02-01.03'!R18 -> 0 | K19: =J19/J$26 -> 0 | L19: =K19+L18 -> 0.88888889 | M19: =_xlfn.IFS(L19<80%,"A",L19<=95%,"B",L19>95%,"C") -> B
B20: flip желтые Сул | C20: ='Юнит 23.02-01.03'!AE9 -> -22.464127 | D20: =C20/C$26 -> -0.00046808369 | E20: =D20+E19 -> 0.99077149 | F20: =IF(AND(E20<=0),"C",IF(E20<=0.8,"A",IF(E20<=0.95,"B","C"))) -> C | G20: =VLOOKUP(B$4:B$25,I$4:M$25,5,0) -> B | I20: lux3 | J20: ='Юнит 23.02-01.03'!R19 -> 0 | K20: =J20/J$26 -> 0 | L20: =K20+L19 -> 0.88888889 | M20: =_xlfn.IFS(L20<80%,"A",L20<=95%,"B",L20>95%,"C") -> B
B21: lux3 | C21: ='Юнит 23.02-01.03'!AE19 -> -113.88 | D21: =C21/C$26 -> -0.0023729109 | E21: =D21+E20 -> 0.98839858 | F21: =IF(AND(E21<=0),"C",IF(E21<=0.8,"A",IF(E21<=0.95,"B","C"))) -> C | G21: =VLOOKUP(B$4:B$25,I$4:M$25,5,0) -> B | I21: lux4 | J21: ='Юнит 23.02-01.03'!R20 -> 0 | K21: =J21/J$26 -> 0 | L21: =K21+L20 -> 0.88888889 | M21: =_xlfn.IFS(L21<80%,"A",L21<=95%,"B",L21>95%,"C") -> B
B22: MR Р1886 корич | C22: ='Юнит 23.02-01.03'!AE16 -> -142.52354 | D22: =C22/C$26 -> -0.0029697546 | E22: =D22+E21 -> 0.98542883 | F22: =IF(AND(E22<=0),"C",IF(E22<=0.8,"A",IF(E22<=0.95,"B","C"))) -> C | G22: =VLOOKUP(B$4:B$25,I$4:M$25,5,0) -> B | I22: lux5 | J22: ='Юнит 23.02-01.03'!R21 -> 0 | K22: =J22/J$26 -> 0 | L22: =K22+L21 -> 0.88888889 | M22: =_xlfn.IFS(L22<80%,"A",L22<=95%,"B",L22>95%,"C") -> B
B23: MR 1819 черн | C23: ='Юнит 23.02-01.03'!AE11 -> -187.08 | D23: =C23/C$26 -> -0.003898175 | E23: =D23+E22 -> 0.98153065 | F23: =IF(AND(E23<=0),"C",IF(E23<=0.8,"A",IF(E23<=0.95,"B","C"))) -> C | G23: =VLOOKUP(B$4:B$25,I$4:M$25,5,0) -> B | I23: lux6 | J23: ='Юнит 23.02-01.03'!R22 -> 0 | K23: =J23/J$26 -> 0 | L23: =K23+L22 -> 0.88888889 | M23: =_xlfn.IFS(L23<80%,"A",L23<=95%,"B",L23>95%,"C") -> B
B24: qs синие | C24: ='Юнит 23.02-01.03'!AE5 -> -935.41696 | D24: =C24/C$26 -> -0.019491228 | E24: =D24+E23 -> 0.96203942 | F24: =IF(AND(E24<=0),"C",IF(E24<=0.8,"A",IF(E24<=0.95,"B","C"))) -> C | G24: =VLOOKUP(B$4:B$25,I$4:M$25,5,0) -> B | I24: lux7 | J24: ='Юнит 23.02-01.03'!R23 -> 0 | K24: =J24/J$26 -> 0 | L24: =K24+L23 -> 0.88888889 | M24: =_xlfn.IFS(L24<80%,"A",L24<=95%,"B",L24>95%,"C") -> B
B25: MR Р1886 черн глянец | C25: ='Юнит 23.02-01.03'!AE15 -> -1208.8242 | D25: =C25/C$26 -> -0.025188198 | E25: =D25+E24 -> 0.93685123 | F25: =IF(AND(E25<=0),"C",IF(E25<=0.8,"A",IF(E25<=0.95,"B","C"))) -> B | G25: =VLOOKUP(B$4:B$25,I$4:M$25,5,0) -> A | I25: lux8 | J25: ='Юнит 23.02-01.03'!R24 -> 0 | K25: =J25/J$26 -> 0 | L25: =K25+L24 -> 0.88888889 | M25: =_xlfn.IFS(L25<80%,"A",L25<=95%,"B",L25>95%,"C") -> B
C26: =SUM(C4:C25) -> 47991.688 | D26: =SUM(D4:D25) -> 1 | J26: =SUM(J4:J25) -> 117 | K26: =SUM(K4:K25) -> 1
B28: ТУНИКИ
C29: Прибыль | D29: % прибыль | E29: Доля | F29: ABC прибыль | G29: ABC кол-во | J29: Кол-во | K29: % кол-во | L29: Доля | M29: ABC кол-во
B30: tunika15 кимоно бирюза | C30: ='Юнит 23.02-01.03'!AE44 -> 4779.458 | D30: =C30/C$50 -> 0.26977565 | E30: =D30 -> 0.26977565 | F30: =IF(AND(E30<=0),"C",IF(E30<=0.8,"A",IF(E30<=0.95,"B","C"))) -> A | G30: =VLOOKUP(B$30:B$50,I$30:M$50,5,0) -> B | I30: tunika15 кимоно песочная | J30: ='Юнит 23.02-01.03'!R45 -> 9 | K30: =J30/J$50 -> 0.34615385 | L30: =K30 -> 0.34615385 | M30: =_xlfn.IFS(L30<80%,"A",L30<=95%,"B",L30>95%,"C") -> A
B31: tunika05 белая распашная | C31: ='Юнит 23.02-01.03'!AE30 -> 3307.6535 | D31: =C31/C$50 -> 0.18669991 | E31: =D31+E30 -> 0.45647555 | F31: =IF(AND(E31<=0),"C",IF(E31<=0.8,"A",IF(E31<=0.95,"B","C"))) -> A | G31: =VLOOKUP(B$30:B$50,I$30:M$50,5,0) -> A | I31: tunika16 сетка белая | J31: ='Юнит 23.02-01.03'!R46 -> 5 | K31: =J31/J$50 -> 0.19230769 | L31: =K31+L30 -> 0.53846154 | M31: =_xlfn.IFS(L31<80%,"A",L31<=95%,"B",L31>95%,"C") -> A
B32: tunika12 халат белая | C32: ='Юнит 23.02-01.03'!AE40 -> 3219.5676 | D32: =C32/C$50 -> 0.18172792 | E32: =D32+E31 -> 0.63820347 | F32: =IF(AND(E32<=0),"C",IF(E32<=0.8,"A",IF(E32<=0.95,"B","C"))) -> A | G32: =VLOOKUP(B$30:B$50,I$30:M$50,5,0) -> A | I32: tunika05 белая распашная | J32: ='Юнит 23.02-01.03'!R30 -> 2 | K32: =J32/J$50 -> 0.076923077 | L32: =K32+L31 -> 0.61538462 | M32: =_xlfn.IFS(L32<80%,"A",L32<=95%,"B",L32>95%,"C") -> A
B33: tunika09 кимоно | C33: ='Юнит 23.02-01.03'!AE37 -> 2623.219 | D33: =C33/C$50 -> 0.14806712 | E33: =D33+E32 -> 0.78627059 | F33: =IF(AND(E33<=0),"C",IF(E33<=0.8,"A",IF(E33<=0.95,"B","C"))) -> A | G33: =VLOOKUP(B$30:B$50,I$30:M$50,5,0) -> C | I33: tunika12 халат белая | J33: ='Юнит 23.02-01.03'!R40 -> 2 | K33: =J33/J$50 -> 0.076923077 | L33: =K33+L32 -> 0.69230769 | M33: =_xlfn.IFS(L33<80%,"A",L33<=95%,"B",L33>95%,"C") -> A
B34: tunika14 халат с разрезами черный | C34: ='Юнит 23.02-01.03'!AE43 -> 2553.9268 | D34: =C34/C$50 -> 0.14415594 | E34: =D34+E33 -> 0.93042653 | F34: =IF(AND(E34<=0),"C",IF(E34<=0.8,"A",IF(E34<=0.95,"B","C"))) -> B | G34: =VLOOKUP(B$30:B$50,I$30:M$50,5,0) -> A | I34: tunika14 халат с разрезами черный | J34: ='Юнит 23.02-01.03'!R43 -> 2 | K34: =J34/J$50 -> 0.076923077 | L34: =K34+L33 -> 0.76923077 | M34: =_xlfn.IFS(L34<80%,"A",L34<=95%,"B",L34>95%,"C") -> A
