Workbook

Sheet Динамика показатели
B1: Неделя | C1: 52 | D1: 51 | E1: 50 | F1: 49 | G1: 48 | H1: 47 | I1: 46 | J1: 45 | K1: 44 | L1: 43 | M1: 42 | N1: 41 | O1: 40
B2: ОЧКИ
B3: Логистика | C3: ='Дашборд 22-31.12'!$G$19 -> 0.099636126 | D3: ='Дашборд 15-21.12'!$G$19 -> 0.12768273 | E3: ='Дашборд 08-14.12'!$G$19 -> 0.11649218 | F3: ='Дашборд 01-07.12'!$G$19 -> 0.10242165 | G3: ='Дашборд 24-30.11'!$G$19 -> 0.11386342 | H3: ='Дашборд 17-23.11'!$G$19 -> 0.11274964 | I3: ='Дашборд 10-16.11'!$G$19 -> 0.073365321 | J3: ='Дашборд 03-09.11'!$G$19 -> 0.084928063 | K3: ='Дашборд 27.10-02.11'!$G$19 -> 0.064888889 | L3: ='Дашборд 20-26.10'!$G$17 -> 0.12556256 | M3: ='Дашборд 13-19.10'!$G$17 -> 0.15547938 | N3: ='Дашборд 06-12.10'!G17 -> 0.089603283 | O3: ='Дашборд 01-05.10'!G17 -> 0.086414947
B4: Реклама | C4: ='Дашборд 22-31.12'!$G$20 -> 0.32953964 | D4: ='Дашборд 15-21.12'!$G$20 -> 0.34210081 | E4: ='Дашборд 08-14.12'!$G$20 -> 0.18201157 | F4: ='Дашборд 01-07.12'!$G$20 -> 0.15322395 | G4: ='Дашборд 24-30.11'!$G$20 -> 0.4273338 | H4: ='Дашборд 17-23.11'!$G$20 -> 0.56864193 | I4: ='Дашборд 10-16.11'!$G$20 -> 0.63833041 | J4: ='Дашборд 03-09.11'!$G$20 -> 0.74072085 | K4: ='Дашборд 27.10-02.11'!$G$20 -> 0.69204075 | L4: ='Дашборд 20-26.10'!$G$18 -> 0.69204481 | M4: ='Дашборд 13-19.10'!$G$18 -> 0.55619483 | N4: ='Дашборд 06-12.10'!G18 -> 1.0468865 | O4: ='Дашборд 01-05.10'!G18 -> 0.64043644
B5: Возвраты | C5: ='Дашборд 22-31.12'!$G$22 -> 0.039055874 | D5: ='Дашборд 15-21.12'!$G$22 -> 0.055486468 | E5: ='Дашборд 08-14.12'!$G$22 -> 0.067593769 | F5: ='Дашборд 01-07.12'!$G$22 -> 0 | G5: ='Дашборд 24-30.11'!$G$22 -> 0.10751985 | H5: ='Дашборд 17-23.11'!$G$22 -> 0.058502071 | I5: ='Дашборд 10-16.11'!$G$22 -> 0.033727313 | J5: ='Дашборд 03-09.11'!$G$22 -> 0 | K5: ='Дашборд 27.10-02.11'!$G$22 -> 0 | L5: ='Дашборд 20-26.10'!$G$20 -> 0 | M5: ='Дашборд 13-19.10'!$G$20 -> 0 | N5: ='Дашборд 06-12.10'!G20 -> 0.048796357 | O5: ='Дашборд 01-05.10'!G20 -> 0.13485795
B6: Комиссия | C6: ='Дашборд 22-31.12'!$G$23 -> 0.43 | D6: ='Дашборд 15-21.12'!$G$23 -> 0.43 | E6: ='Дашборд 08-14.12'!$G$23 -> 0.43 | F6: ='Дашборд 01-07.12'!$G$23 -> 0.43 | G6: ='Дашборд 24-30.11'!$G$23 -> 0.43 | H6: ='Дашборд 17-23.11'!$G$23 -> 0.42795259 | I6: ='Дашборд 10-16.11'!$G$23 -> 0.41578228 | J6: ='Дашборд 03-09.11'!$G$23 -> 0.38 | K6: ='Дашборд 27.10-02.11'!$G$23 -> 0.35771457 | L6: ='Дашборд 20-26.10'!$G$21 -> 0.33486049 | M6: ='Дашборд 13-19.10'!$G$21 -> 0.29973018 | N6: ='Дашборд 06-12.10'!G21 -> 0.26126582 | O6: ='Дашборд 01-05.10'!G21 -> 0.25220142
B7: Маржинальность | C7: ='Дашборд 22-31.12'!$G$25 -> -0.11642303 | D7: ='Дашборд 15-21.12'!$G$25 -> -1.0579162 | E7: ='Дашборд 08-14.12'!$G$25 -> 0.24679927 | F7: ='Дашборд 01-07.12'!$G$25 -> 2.0890589 | G7: ='Дашборд 24-30.11'!$G$25 -> -1.0637454 | H7: ='Дашборд 17-23.11'!$G$25 -> -2.7480703 | I7: ='Дашборд 10-16.11'!$G$25 -> -3.8926561 | J7: ='Дашборд 03-09.11'!$G$25 -> -5.0291455 | K7: ='Дашборд 27.10-02.11'!$G$25 -> -0.65630134 | L7: ='Дашборд 20-26.10'!$G$23 -> -2.5798194 | M7: ='Дашборд 13-19.10'!$G$23 -> 4.0584498 | N7: ='Дашборд 06-12.10'!G23 -> 0.29139814 | O7: ='Дашборд 01-05.10'!G23 -> -1.1880959
B8: Рентабельность | C8: ='Дашборд 22-31.12'!$G$26 -> -0.011163575 | D8: ='Дашборд 15-21.12'!$G$26 -> -0.10426806 | E8: ='Дашборд 08-14.12'!$G$26 -> 0.022814908 | F8: ='Дашборд 01-07.12'!$G$26 -> 0.1855935 | G8: ='Дашборд 24-30.11'!$G$26 -> -0.090846166 | H8: ='Дашборд 17-23.11'!$G$26 -> -0.23673668 | I8: ='Дашборд 10-16.11'!$G$26 -> -0.35667142 | J8: ='Дашборд 03-09.11'!$G$26 -> -0.49810247 | K8: ='Дашборд 27.10-02.11'!$G$26 -> -0.13668589 | L8: ='Дашборд 20-26.10'!$G$24 -> -0.38894231 | M8: ='Дашборд 13-19.10'!$G$24 -> 0.61004204 | N8: ='Дашборд 06-12.10'!G24 -> 0.044814921 | O8: ='Дашборд 01-05.10'!G24 -> -0.23230452
B9: Прибыль | C9: ='Дашборд 22-31.12'!$E$16 -> -1492.57 | D9: ='Дашборд 15-21.12'!$E$16 -> -6018.6652 | E9: ='Дашборд 08-14.12'!$E$16 -> 1272.7068 | F9: ='Дашборд 01-07.12'!$E$16 -> 16113.413 | G9: ='Дашборд 24-30.11'!$E$16 -> -4585.5511 | H9: ='Дашборд 17-23.11'!$E$16 -> -11624.008 | I9: ='Дашборд 10-16.11'!$E$16 -> -13938.006 | J9: ='Дашборд 03-09.11'!$E$16 -> -7131.8312 | K9: ='Дашборд 27.10-02.11'!$E$16 -> -7332.4751 | L9: ='Дашборд 20-26.10'!$E$14 -> -6913.8386 | M9: ='Дашборд 13-19.10'!$E$14 -> 11033.22 | N9: ='Дашборд 06-12.10'!E14 -> 1048.3106 | O9: ='Дашборд 01-05.10'!E14 -> -6564.6933
B10: ТУНИКИ
B11: Логистика | C11: ='Дашборд 22-31.12'!$M$19 -> #DIV/0! | D11: ='Дашборд 15-21.12'!$M$19 -> 0.093010769 | E11: ='Дашборд 08-14.12'!$M$19 -> 0.094414944 | F11: ='Дашборд 01-07.12'!$M$19 -> -0.17600545 | G11: ='Дашборд 24-30.11'!$M$19 -> 0.15342 | H11: ='Дашборд 17-23.11'!$M$19 -> 0.19407336 | I11: ='Дашборд 10-16.11'!$M$19 -> 0.085996663 | J11: ='Дашборд 03-09.11'!$M$19 -> 0.091958599 | K11: ='Дашборд 27.10-02.11'!$M$19 -> 0.047370828 | L11: ='Дашборд 20-26.10'!$M$17 -> 0.069799063 | M11: ='Дашборд 13-19.10'!$M$17 -> 0.062033314 | N11: ='Дашборд 06-12.10'!M17 -> 0.076712329 | O11: ='Дашборд 01-05.10'!M17 -> 0.034773969
B12: Реклама | C12: ='Дашборд 22-31.12'!$M$20 -> #DIV/0! | D12: ='Дашборд 15-21.12'!$M$20 -> 0.13809151 | E12: ='Дашборд 08-14.12'!$M$20 -> 0.087279936 | F12: ='Дашборд 01-07.12'!$M$20 -> -0.041702373 | G12: ='Дашборд 24-30.11'!$M$20 -> 0.19972316 | H12: ='Дашборд 17-23.11'!$M$20 -> 0.32442005 | I12: ='Дашборд 10-16.11'!$M$20 -> 0.23358537 | J12: ='Дашборд 03-09.11'!$M$20 -> 0.3694242 | K12: ='Дашборд 27.10-02.11'!$M$20 -> 0.24762288 | L12: ='Дашборд 20-26.10'!$M$18 -> 0.28593184 | M12: ='Дашборд 13-19.10'!$M$18 -> 0.23810065 | N12: ='Дашборд 06-12.10'!M18 -> 0.42773008 | O12: ='Дашборд 01-05.10'!M18 -> 0.22476519
B13: Возвраты | C13: ='Дашборд 22-31.12'!$M$22 -> #DIV/0! | D13: ='Дашборд 15-21.12'!$M$22 -> 0.32150313 | E13: ='Дашборд 08-14.12'!$M$22 -> 0 | F13: ='Дашборд 01-07.12'!$M$22 -> 1.8461538 | G13: ='Дашборд 24-30.11'!$M$22 -> 0.5 | H13: ='Дашборд 17-23.11'!$M$22 -> 0.41278895 | I13: ='Дашборд 10-16.11'!$M$22 -> 0.21759772 | J13: ='Дашборд 03-09.11'!$M$22 -> 0.43621826 | K13: ='Дашборд 27.10-02.11'!$M$22 -> 0.10258515 | L13: ='Дашборд 20-26.10'!$M$20 -> 0.26504553 | M13: ='Дашборд 13-19.10'!$M$20 -> 0.16951174 | N13: ='Дашборд 06-12.10'!M20 -> 0.076524264 | O13: ='Дашборд 01-05.10'!M20 -> 0.083959044
B14: Комиссия | C14: ='Дашборд 22-31.12'!$M$23 -> #DIV/0! | D14: ='Дашборд 15-21.12'!$M$23 -> 0.43 | E14: ='Дашборд 08-14.12'!$M$23 -> 0.43 | F14: ='Дашборд 01-07.12'!$M$23 -> 0.43 | G14: ='Дашборд 24-30.11'!$M$23 -> 0.43 | H14: ='Дашборд 17-23.11'!$M$23 -> 0.46514826 | I14: ='Дашборд 10-16.11'!$M$23 -> 0.43 | J14: ='Дашборд 03-09.11'!$M$23 -> 0.38 | K14: ='Дашборд 27.10-02.11'!$M$23 -> 0.36710928 | L14: ='Дашборд 20-26.10'!$M$21 -> 0.3121257 | M14: ='Дашборд 13-19.10'!$M$21 -> 0.26984328 | N14: ='Дашборд 06-12.10'!M21 -> 0.24 | O14: ='Дашборд 01-05.10'!M21 -> 0.24
B15: Маржинальность | C15: ='Дашборд 22-31.12'!$M$25 -> #DIV/0! | D15: ='Дашборд 15-21.12'!$M$25 -> 2.1118417 | E15: ='Дашборд 08-14.12'!$M$25 -> 0.68505138 | F15: ='Дашборд 01-07.12'!$M$25 -> 6.1648125 | G15: ='Дашборд 24-30.11'!$M$25 -> 0.97949131 | H15: ='Дашборд 17-23.11'!$M$25 -> -0.95935662 | I15: ='Дашборд 10-16.11'!$M$25 -> 0.87332767 | J15: ='Дашборд 03-09.11'!$M$25 -> 0.08683085 | K15: ='Дашборд 27.10-02.11'!$M$25 -> 1.2618752 | L15: ='Дашборд 20-26.10'!$M$23 -> 0.37676652 | M15: ='Дашборд 13-19.10'!$M$23 -> 0.78107774 | N15: ='Дашборд 06-12.10'!M23 -> 0.151625 | O15: ='Дашборд 01-05.10'!M23 -> 1.1157134
B16: Рентабельность | C16: ='Дашборд 22-31.12'!$M$26 -> #DIV/0! | D16: ='Дашборд 15-21.12'!$M$26 -> 0.22320542 | E16: ='Дашборд 08-14.12'!$M$26 -> 0.15379854 | F16: ='Дашборд 01-07.12'!$M$26 -> 0.66916237 | G16: ='Дашборд 24-30.11'!$M$26 -> 0.10235684 | H16: ='Дашборд 17-23.11'!$M$26 -> -0.1500834 | I16: ='Дашборд 10-16.11'!$M$26 -> 0.11208058 | J16: ='Дашборд 03-09.11'!$M$26 -> 0.011873566 | K16: ='Дашборд 27.10-02.11'!$M$26 -> 0.17365982 | L16: ='Дашборд 20-26.10'!$M$24 -> 0.0881579 | M16: ='Дашборд 13-19.10'!$M$24 -> 0.1841977 | N16: ='Дашборд 06-12.10'!M24 -> 0.03233055 | O16: ='Дашборд 01-05.10'!M24 -> 0.25864266
B17: Прибыль | C17: ='Дашборд 22-31.12'!$K$16 -> -284.7 | D17: ='Дашборд 15-21.12'!$K$16 -> 1450.8352 | E17: ='Дашборд 08-14.12'!$K$16 -> 1309.1332 | F17: ='Дашборд 01-07.12'!$K$16 -> -3680.3931 | G17: ='Дашборд 24-30.11'!$K$16 -> 614.14105 | H17: ='Дашборд 17-23.11'!$K$16 -> -1174.2525 | I17: ='Дашборд 10-16.11'!$K$16 -> 2216.5056 | J17: ='Дашборд 03-09.11'!$K$16 -> 238.61118 | K17: ='Дашборд 27.10-02.11'!$K$16 -> 7220.2151 | L17: ='Дашборд 20-26.10'!$K$14 -> 2334.0686 | M17: ='Дашборд 13-19.10'!$K$14 -> 8979.2696 | N17: ='Дашборд 06-12.10'!K14 -> 1439.6794 | O17: ='Дашборд 01-05.10'!K14 -> 10412.953

Sheet Динамика финансы
A1: Период | D1: Дата поступления дс | E1: Итого к перечислению на счет, руб | F1: шт. | I1: Выручка | L1: Себестоимость продаж | M1: Логистика | N1: Комиссия | O1: Хранение | P1: Платная приемка | Q1: Штрафы | R1: Реклама Ozon | S1: Прочее | T1: Доп. услуги | U1: Услуги FBO | V1: Компенсировано | W1: Прочие начисления | X1: Налог | Y1: Итого | Z1: Итог месяц | AA1: % Cебестоимости | AB1: Маржинальность, % | AC1: Рентабельность, % | AD1: Доля рекламы, % | AF1: Данные для построения диаграмм
A2: Месяц | B2: Даты | C2: Нед | F2: Заказы | G2: Продажи | H2: Возвраты | I2: Продажи | J2: Возвраты | K2: Общая | AF2: Нед | AG2: По магазину | AH2: По очкам | AI2: По туникам
A3: Август | B3: 01-31.08 очки | E3: =K3-SUM(M3:U3)+V3+W3 -> 1314.45 | F3: =АВГУСТ!K$24 -> 19 | G3: =АВГУСТ!P$24 -> 5 | H3: =АВГУСТ!Q$24 -> 0 | I3: =АВГУСТ!S$24 -> 8513 | J3: =АВГУСТ!T$24 -> 0 | K3: =I3+J3 -> 8513 | L3: =АВГУСТ!W$24 -> 649.38 | M3: =АВГУСТ!Z$24 -> 506 | N3: =АВГУСТ!X$24 -> 1702.6 | R3: =АВГУСТ!AA$24 -> 15668.72 | S3: 0 | T3: 284.73 | U3: 15426.5 | W3: 26390 | X3: =(K3)*0.01 -> 85.13 | Y3: =K3-SUM(M3:U3)-L3-X3+V3+W3 -> 579.94 | Z3: =SUM(Y3:Y4) -> 579.94 | AA3: =L3/K3 -> 0.076280982 | AB3: =Y3/L3 -> 0.89306723 | AC3: =Y3/K3 -> 0.068124046 | AD3: =R3/K3 -> 1.8405638 | AF3: август | AG3: =(K3+K4)/1000 -> 8.513 | AH3: =K3/1000 -> 8.513 | AI3: =K4/1000 -> 0
B4: 01-31.08 туники | E4: =K4-SUM(M4:U4)+V4+W4 -> 0 | F4: =АВГУСТ!K$47 -> 0 | G4: =АВГУСТ!P$47 -> 0 | H4: =АВГУСТ!Q$47 -> 0 | I4: =АВГУСТ!S$47 -> 0 | J4: =АВГУСТ!T$47 -> 0 | K4: =I4+J4 -> 0 | L4: =АВГУСТ!W$47 -> 0 | M4: =АВГУСТ!Z$47 -> 0 | N4: =АВГУСТ!X$47 -> 0 | R4: =АВГУСТ!AA$47 -> 0 | X4: =(K4)*0.01 -> 0 | Y4: =K4-SUM(M4:U4)-L4-X4+V4+W4 -> 0 | AA4: =L4/K4 -> #DIV/0! | AB4: =Y4/L4 -> #DIV/0! | AC4: =Y4/K4 -> #DIV/0! | AD4: =R4/K4 -> #DIV/0! | AF4: сентябрь | AG4: =(K5+K6)/1000 -> 164.682 | AH4: =K5/1000 -> 133.332 | AI4: =K6/1000 -> 31.35
A5: Сентябрь | B5: 01-30.09 очки | E5: =K5-SUM(M5:U5)+V5+W5 -> 59471.661 | F5: =СЕНТЯБРЬ!K$24 -> 197 | G5: =СЕНТЯБРЬ!P$24 -> 108 | H5: =СЕНТЯБРЬ!Q$24 -> 5 | I5: =СЕНТЯБРЬ!S$24 -> 140000 | J5: =СЕНТЯБРЬ!T$24 -> -6668 | K5: =I5+J5 -> 133332 | L5: =СЕНТЯБРЬ!W$24 -> 17238.88 | M5: =СЕНТЯБРЬ!Z$24 -> 10852 | N5: =СЕНТЯБРЬ!X$24 -> 28418.52 | R5: =СЕНТЯБРЬ!AA$24 -> 94178.709 | S5: 10 | T5: 3767.91 | U5: 14633.2 | W5: 78000 | X5: =(K5)*0.01 -> 1333.32 | Y5: =K5-SUM(M5:U5)-L5-X5+V5+W5 -> 40899.461 | Z5: =SUM(Y5:Y6) -> 47356.31 | AA5: =L5/K5 -> 0.12929289 | AB5: =Y5/L5 -> 2.3725126 | AC5: =Y5/K5 -> 0.30674902 | AD5: =R5/K5 -> 0.70634738 | AF5: 40 | AG5: =(K7+K8)/1000 -> 68.519 | AH5: =K7/1000 -> 28.259 | AI5: =K8/1000 -> 40.26
B6: 01-30.09 туники | E6: =K6-SUM(M6:U6)+V6+W6 -> 13757.349 | F6: =СЕНТЯБРЬ!K$47 -> 42 | G6: =СЕНТЯБРЬ!P$47 -> 10 | H6: =СЕНТЯБРЬ!Q$47 -> 1 | I6: =СЕНТЯБРЬ!S$47 -> 35040 | J6: =СЕНТЯБРЬ!T$47 -> -3690 | K6: =I6+J6 -> 31350 | L6: =СЕНТЯБРЬ!W$47 -> 6987 | M6: =СЕНТЯБРЬ!Z$47 -> 2408 | N6: =СЕНТЯБРЬ!X$47 -> 6464.4 | R6: =СЕНТЯБРЬ!AA$47 -> 8720.2508 | X6: =(K6)*0.01 -> 313.5 | Y6: =K6-SUM(M6:U6)-L6-X6+V6+W6 -> 6456.8492 | AA6: =L6/K6 -> 0.22287081 | AB6: =Y6/L6 -> 0.92412325 | AC6: =Y6/K6 -> 0.2059601 | AD6: =R6/K6 -> 0.27815792 | AF6: 41 | AG6: =(K9+K10)/1000 -> 67.922 | AH6: =K9/1000 -> 23.392 | AI6: =K10/1000 -> 44.53
A7: Октябрь | B7: 01-05.10 очки | E7: =K7-SUM(M7:U7)+V7+W7 -> -756.71333 | F7: ='Юнит 01-05.10'!K$24 -> 25 | G7: ='Юнит 01-05.10'!P$24 -> 26 | H7: ='Юнит 01-05.10'!Q$24 -> 2 | I7: ='Юнит 01-05.10'!S$24 -> 32664 | J7: ='Юнит 01-05.10'!T$24 -> -4405 | K7: =I7+J7 -> 28259 | L7: ='Юнит 01-05.10'!W$24 -> 5525.39 | M7: ='Юнит 01-05.10'!Z$24 -> 2442 | N7: ='Юнит 01-05.10'!X$24 -> 7126.96 | R7: ='Юнит 01-05.10'!AA$24 -> 18098.093 | S7: 10 | T7: 1338.66 | U7: 0 | X7: =(K7)*0.01 -> 282.59 | Y7: =K7-SUM(M7:U7)-L7-X7+V7+W7 -> -6564.6933 | Z7: =SUM(Y7:Y16) -> 20856.72 | AA7: =L7/K7 -> 0.19552673 | AB7: =Y7/L7 -> -1.1880959 | AC7: =Y7/K7 -> -0.23230452 | AD7: =R7/K7 -> 0.64043644 | AF7: 42 | AG7: =(K11+K12)/1000 -> 66.834 | AH7: =K11/1000 -> 18.086 | AI7: =K12/1000 -> 48.748
B8: 01-05.10 туники | E8: =K8-SUM(M8:U8)+V8+W8 -> 20148.553 | F8: ='Юнит 01-05.10'!K$47 -> 44 | G8: ='Юнит 01-05.10'!P$47 -> 13 | H8: ='Юнит 01-05.10'!Q$47 -> 1 | I8: ='Юнит 01-05.10'!S$47 -> 43950 | J8: ='Юнит 01-05.10'!T$47 -> -3690 | K8: =I8+J8 -> 40260 | L8: ='Юнит 01-05.10'!W$47 -> 9333 | M8: ='Юнит 01-05.10'!Z$47 -> 1400 | N8: ='Юнит 01-05.10'!X$47 -> 9662.4 | R8: ='Юнит 01-05.10'!AA$47 -> 9049.0467 | X8: =(K8)*0.01 -> 402.6 | Y8: =K8-SUM(M8:U8)-L8-X8+V8+W8 -> 10412.953 | AA8: =L8/K8 -> 0.23181818 | AB8: =Y8/L8 -> 1.1157134 | AC8: =Y8/K8 -> 0.25864266 | AD8: =R8/K8 -> 0.22476519 | AF8: 43 | AG8: =(K13+K14)/1000 -> 44.252 | AH8: =K13/1000 -> 17.776 | AI8: =K14/1000 -> 26.476
B9: 06-12.10 очки | E9: =K9-SUM(M9:U9)+V9+W9 -> 4879.7506 | F9: ='Юнит 06-12.10'!K$24 -> 41 | G9: ='Юнит 06-12.10'!P$24 -> 18 | H9: ='Юнит 06-12.10'!Q$24 -> 1 | I9: ='Юнит 06-12.10'!S$24 -> 24592 | J9: ='Юнит 06-12.10'!T$24 -> -1200 | K9: =I9+J9 -> 23392 | L9: ='Юнит 06-12.10'!W$24 -> 3597.52 | M9: ='Юнит 06-12.10'!Z$24 -> 2096 | N9: ='Юнит 06-12.10'!X$24 -> 6111.53 | R9: ='Юнит 06-12.10'!AA$24 -> 24488.769 | S9: 10 | T9: 1805.95 | U9: 0 | W9: 16000 | X9: =(K9)*0.01 -> 233.92 | Y9: =K9-SUM(M9:U9)-L9-X9+V9+W9 -> 1048.3106 | AA9: =L9/K9 -> 0.15379275 | AB9: =Y9/L9 -> 0.29139814 | AC9: =Y9/K9 -> 0.044814921 | AD9: =R9/K9 -> 1.0468865 | AF9: 44 | AG9: =(K15+K16+K17+K18)/1000 -> 63.99 | AH9: =(K15+K17)/1000 -> 20.25 | AI9: =(K16+K18)/1000 -> 43.74
B10: 06-12.10 туники | E10: =K10-SUM(M10:U10)+V10+W10 -> 11379.979 | F10: ='Юнит 06-12.10'!K$47 -> 32 | G10: ='Юнит 06-12.10'!P$47 -> 14 | H10: ='Юнит 06-12.10'!Q$47 -> 1 | I10: ='Юнит 06-12.10'!S$47 -> 48220 | J10: ='Юнит 06-12.10'!T$47 -> -3690 | K10: =I10+J10 -> 44530 | L10: ='Юнит 06-12.10'!W$47 -> 9495 | M10: ='Юнит 06-12.10'!Z$47 -> 3416 | N10: ='Юнит 06-12.10'!X$47 -> 10687.2 | R10: ='Юнит 06-12.10'!AA$47 -> 19046.821 | X10: =(K10)*0.01 -> 445.3 | Y10: =K10-SUM(M10:U10)-L10-X10+V10+W10 -> 1439.6794 | AA10: =L10/K10 -> 0.21322704 | AB10: =Y10/L10 -> 0.151625 | AC10: =Y10/K10 -> 0.03233055 | AD10: =R10/K10 -> 0.42773008 | AF10: 45 | AG10: =(K19+K20)/1000 -> 34.414 | AH10: =(K19)/1000 -> 14.318 | AI10: =(K20)/1000 -> 20.096
B11: 13-19.10 очки | E11: =K11-SUM(M11:U11)+V11+W11 -> 13932.66 | F11: ='Юнит 13-19.10'!K$24 -> 26 | G11: ='Юнит 13-19.10'!P$24 -> 13 | H11: ='Юнит 13-19.10'!Q$24 -> 0 | I11: ='Юнит 13-19.10'!S$24 -> 18086 | J11: ='Юнит 13-19.10'!T$24 -> 0 | K11: =I11+J11 -> 18086 | L11: ='Юнит 13-19.10'!W$24 -> 2718.58 | M11: ='Юнит 13-19.10'!Z$24 -> 2812 | N11: ='Юнит 13-19.10'!X$24 -> 5420.92 | R11: ='Юнит 13-19.10'!AA$24 -> 10059.34 | S11: 174 | T11: 1687.08 | U11: 0 | W11: 16000 | X11: =(K11)*0.01 -> 180.86 | Y11: =K11-SUM(M11:U11)-L11-X11+V11+W11 -> 11033.22 | AA11: =L11/K11 -> 0.15031406 | AB11: =Y11/L11 -> 4.0584498 | AC11: =Y11/K11 -> 0.61004204 | AD11: =R11/K11 -> 0.55619483 | AF11: 46 | AG11: =(K21+K22)/1000 -> 58.854 | AH11: =(K21)/1000 -> 39.078 | AI11: =(K22)/1000 -> 19.776
B12: 13-19.10 туники | E12: =K12-SUM(M12:U12)+V12+W12 -> 20962.75 | F12: ='Юнит 13-19.10'!K$47 -> 17 | G12: ='Юнит 13-19.10'!P$47 -> 15 | H12: ='Юнит 13-19.10'!Q$47 -> 3 | I12: ='Юнит 13-19.10'!S$47 -> 58698 | J12: ='Юнит 13-19.10'!T$47 -> -9950 | K12: =I12+J12 -> 48748 | L12: ='Юнит 13-19.10'!W$47 -> 11496 | M12: ='Юнит 13-19.10'!Z$47 -> 3024 | N12: ='Юнит 13-19.10'!X$47 -> 13154.32 | R12: ='Юнит 13-19.10'!AA$47 -> 11606.93 | X12: =(K12)*0.01 -> 487.48 | Y12: =K12-SUM(M12:U12)-L12-X12+V12+W12 -> 8979.2696 | AA12: =L12/K12 -> 0.23582506 | AB12: =Y12/L12 -> 0.78107774 | AC12: =Y12/K12 -> 0.1841977 | AD12: =R12/K12 -> 0.23810065 | AF12: 47 | AG12: =(K23+K24)/1000 -> 56.925 | AH12: =(K23)/1000 -> 49.101 | AI12: =(K24)/1000 -> 7.824
B13: 20-26.10 очки | E13: =K13-SUM(M13:U13)+V13+W13 -> -4056.1086 | F13: ='Юнит 20-26.10'!K$24 -> 20 | G13: ='Юнит 20-26.10'!P$24 -> 13 | H13: ='Юнит 20-26.10'!Q$24 -> 0 | I13: ='Юнит 20-26.10'!S$24 -> 17776 | J13: ='Юнит 20-26.10'!T$24 -> 0 | K13: =I13+J13 -> 17776 | L13: ='Юнит 20-26.10'!W$24 -> 2679.97 | M13: ='Юнит 20-26.10'!Z$24 -> 2232 | N13: ='Юнит 20-26.10'!X$24 -> 5952.48 | R13: ='Юнит 20-26.10'!AA$24 -> 12301.789 | S13: 20 | T13: 1325.84 | U13: 0 | X13: =(K13)*0.01 -> 177.76 | Y13: =K13-SUM(M13:U13)-L13-X13+V13+W13 -> -6913.8386 | AA13: =L13/K13 -> 0.15076339 | AB13: =Y13/L13 -> -2.5798194 | AC13: =Y13/K13 -> -0.38894231 | AD13: =R13/K13 -> 0.69204481 | AF13: 48 | AG13: =(K25+K26)/1000 -> 56.476 | AH13: =(K25)/1000 -> 50.476 | AI13: =(K26)/1000 -> 6
B14: 20-26.10 туники | E14: =K14-SUM(M14:U14)+V14+W14 -> 8793.8286 | F14: ='Юнит 20-26.10'!K$47 -> 0 | G14: ='Юнит 20-26.10'!P$47 -> 8 | H14: ='Юнит 20-26.10'!Q$47 -> 2 | I14: ='Юнит 20-26.10'!S$47 -> 36024 | J14: ='Юнит 20-26.10'!T$47 -> -9548 | K14: =I14+J14 -> 26476 | L14: ='Юнит 20-26.10'!W$47 -> 6195 | M14: ='Юнит 20-26.10'!Z$47 -> 1848 | N14: ='Юнит 20-26.10'!X$47 -> 8263.84 | R14: ='Юнит 20-26.10'!AA$47 -> 7570.3314 | X14: =(K14)*0.01 -> 264.76 | Y14: =K14-SUM(M14:U14)-L14-X14+V14+W14 -> 2334.0686 | AA14: =L14/K14 -> 0.2339855 | AB14: =Y14/L14 -> 0.37676652 | AC14: =Y14/K14 -> 0.0881579 | AD14: =R14/K14 -> 0.28593184 | AF14: 49 | AG14: =(K27+K28)/1000 -> 81.321 | AH14: =(K27)/1000 -> 86.821 | AI14: =(K28)/1000 -> -5.5
B15: 27-31.10 очки | E15: =K15-SUM(M15:U15)+V15+W15 -> -4016.9211 | F15: ='Юнит 27-31.10'!K$24 -> 13 | G15: ='Юнит 27-31.10'!P$24 -> 10 | H15: ='Юнит 27-31.10'!Q$24 -> 0 | I15: ='Юнит 27-31.10'!S$24 -> 13972 | J15: ='Юнит 27-31.10'!T$24 -> 0 | K15: =I15+J15 -> 13972 | L15: ='Юнит 27-31.10'!W$24 -> 2317.72 | M15: ='Юнит 27-31.10'!Z$24 -> 1074 | N15: ='Юнит 27-31.10'!X$24 -> 4858.08 | R15: ='Юнит 27-31.10'!AA$24 -> 11163.561 | S15: 5 | T15: 888.28 | U15: 0 | X15: =(K15)*0.01 -> 139.72 | Y15: =K15-SUM(M15:U15)-L15-X15+V15+W15 -> -6474.3611 | AA15: =L15/K15 -> 0.16588319 | AB15: =Y15/L15 -> -2.7934181 | AC15: =Y15/K15 -> -0.46338113 | AD15: =R15/K15 -> 0.79899521 | AF15: 50 | AG15: =(K29+K30)/1000 -> 64.296 | AH15: =(K29)/1000 -> 55.784 | AI15: =(K30)/1000 -> 8.512
B16: 27-31.10 туники | E16: =K16-SUM(M16:U16)+V16+W16 -> 11712.031 | F16: ='Юнит 27-31.10'!K$47 -> 24 | G16: ='Юнит 27-31.10'!P$47 -> 8 | H16: ='Юнит 27-31.10'!Q$47 -> 1 | I16: ='Юнит 27-31.10'!S$47 -> 39192 | J16: ='Юнит 27-31.10'!T$47 -> -5000 | K16: =I16+J16 -> 34192 | L16: ='Юнит 27-31.10'!W$47 -> 5808 | M16: ='Юнит 27-31.10'!Z$47 -> 1120 | N16: ='Юнит 27-31.10'!X$47 -> 12429.12 | R16: ='Юнит 27-31.10'!AA$47 -> 8930.8489 | X16: =(K16)*0.01 -> 341.92 | Y16: =K16-SUM(M16:U16)-L16-X16+V16+W16 -> 5562.1111 | AA16: =L16/K16 -> 0.1698643 | AB16: =Y16/L16 -> 0.95766376 | AC16: =Y16/K16 -> 0.16267288 | AD16: =R16/K16 -> 0.26119703 | AF16: 51 | AG16: =(K31+K32)/1000 -> 64.223 | AH16: =(K31)/1000 -> 57.723 | AI16: =(K32)/1000 -> 6.5
A17: Ноябрь | B17: 01-02.11 очки | E17: =K17-SUM(M17:U17)+V17+W17 -> 512.166 | F17: ='Юнит 01-02.11'!K$24 -> 4 | G17: ='Юнит 01-02.11'!P$24 -> 3 | H17: ='Юнит 01-02.11'!Q$24 -> 0 | I17: ='Юнит 01-02.11'!S$24 -> 6278 | J17: ='Юнит 01-02.11'!T$24 -> 0 | K17: =I17+J17 -> 6278 | L17: ='Юнит 01-02.11'!W$24 -> 1307.5 | M17: ='Юнит 01-02.11'!Z$24 -> 240 | N17: ='Юнит 01-02.11'!X$24 -> 2385.64 | R17: ='Юнит 01-02.11'!AA$24 -> 2850.264 | S17: 0 | T17: 289.93 | U17: 0 | X17: =(K17)*0.01 -> 62.78 | Y17: =K17-SUM(M17:U17)-L17-X17+V17+W17 -> -858.114 | Z17: =SUM(Y17:Y26) -> -34584.4 | AA17: =L17/K17 -> 0.20826696 | AB17: =Y17/L17 -> -0.65630134 | AC17: =Y17/K17 -> -0.13668589 | AD17: =R17/K17 -> 0.45400828 | AF17: 52 | AG17: =(K33+K34)/1000 -> 133.7 | AH17: =(K33)/1000 -> 133.7 | AI17: =(K34)/1000 -> 0
B18: 01-02.11 туники | E18: =K18-SUM(M18:U18)+V18+W18 -> 3067.584 | F18: ='Юнит 01-02.11'!K$47 -> 3 | G18: ='Юнит 01-02.11'!P$47 -> 2 | H18: ='Юнит 01-02.11'!Q$47 -> 0 | I18: ='Юнит 01-02.11'!S$47 -> 9548 | J18: ='Юнит 01-02.11'!T$47 -> 0 | K18: =I18+J18 -> 9548 | L18: ='Юнит 01-02.11'!W$47 -> 1314 | M18: ='Юнит 01-02.11'!Z$47 -> 952 | N18: ='Юнит 01-02.11'!X$47 -> 3628.24 | R18: ='Юнит 01-02.11'!AA$47 -> 1900.176 | X18: =(K18)*0.01 -> 95.48 | Y18: =K18-SUM(M18:U18)-L18-X18+V18+W18 -> 1658.104 | AA18: =L18/K18 -> 0.13762044 | AB18: =Y18/L18 -> 1.2618752 | AC18: =Y18/K18 -> 0.17365982 | AD18: =R18/K18 -> 0.19901299
B19: 03-09.11 очки | E19: =K19-SUM(M19:U19)+V19+W19 -> -5570.5512 | F19: ='Юнит 03-09.11'!K$26 -> 20 | G19: ='Юнит 03-09.11'!P$26 -> 10 | H19: ='Юнит 03-09.11'!Q$26 -> 0 | I19: ='Юнит 03-09.11'!S$26 -> 14318 | J19: ='Юнит 03-09.11'!T$26 -> 0 | K19: =I19+J19 -> 14318 | L19: ='Юнит 03-09.11'!W$26 -> 1418.1 | M19: ='Юнит 03-09.11'!Z$26 -> 1216 | N19: ='Юнит 03-09.11'!X$26 -> 5440.84 | R19: ='Юнит 03-09.11'!AA$26 -> 10605.641 | S19: 5 | T19: 924.97 | U19: 1696.1 | X19: =(K19)*0.01 -> 143.18 | Y19: =K19-SUM(M19:U19)-L19-X19+V19+W19 -> -7131.8312 | AA19: =L19/K19 -> 0.099043162 | AB19: =Y19/L19 -> -5.0291455 | AC19: =Y19/K19 -> -0.49810247 | AD19: =R19/K19 -> 0.74072085
B20: 03-09.11 туники | E20: =K20-SUM(M20:U20)+V20+W20 -> 3187.5712 | F20: ='Юнит 03-09.11'!K$49 -> 16 | G20: ='Юнит 03-09.11'!P$49 -> 7 | H20: ='Юнит 03-09.11'!Q$49 -> 3 | I20: ='Юнит 03-09.11'!S$49 -> 35645 | J20: ='Юнит 03-09.11'!T$49 -> -15549 | K20: =I20+J20 -> 20096 | L20: ='Юнит 03-09.11'!W$49 -> 2748 | M20: ='Юнит 03-09.11'!Z$49 -> 1848 | N20: ='Юнит 03-09.11'!X$49 -> 7636.48 | R20: ='Юнит 03-09.11'!AA$49 -> 7423.9488 | X20: =(K20)*0.01 -> 200.96 | Y20: =K20-SUM(M20:U20)-L20-X20+V20+W20 -> 238.61118 | AA20: =L20/K20 -> 0.13674363 | AB20: =Y20/L20 -> 0.08683085 | AC20: =Y20/K20 -> 0.011873566 | AD20: =R20/K20 -> 0.3694242
B21: 10-16.11 очки | E21: =K21-SUM(M21:U21)+V21+W21 -> -9966.6356 | F21: ='Юнит 10-16.11'!K$26 -> 53 | G21: ='Юнит 10-16.11'!P$26 -> 27 | H21: ='Юнит 10-16.11'!Q$26 -> 1 | I21: ='Юнит 10-16.11'!S$26 -> 40442 | J21: ='Юнит 10-16.11'!T$26 -> -1364 | K21: =I21+J21 -> 39078 | L21: ='Юнит 10-16.11'!W$26 -> 3580.59 | M21: ='Юнит 10-16.11'!Z$26 -> 2866.97 | N21: ='Юнит 10-16.11'!X$26 -> 16247.94 | R21: ='Юнит 10-16.11'!AA$26 -> 24944.676 | S21: 5 | T21: 1416.75 | U21: 3563.3 | X21: =(K21)*0.01 -> 390.78 | Y21: =K21-SUM(M21:U21)-L21-X21+V21+W21 -> -13938.006 | AA21: =L21/K21 -> 0.091626747 | AB21: =Y21/L21 -> -3.8926561 | AC21: =Y21/K21 -> -0.35667142 | AD21: =R21/K21 -> 0.63833041
B22: 10-16.11 туники | E22: =K22-SUM(M22:U22)+V22+W22 -> 4952.2656 | F22: ='Юнит 10-16.11'!K$49 -> 18 | G22: ='Юнит 10-16.11'!P$49 -> 5 | H22: ='Юнит 10-16.11'!Q$49 -> 1 | I22: ='Юнит 10-16.11'!S$49 -> 25276 | J22: ='Юнит 10-16.11'!T$49 -> -5500 | K22: =I22+J22 -> 19776 | L22: ='Юнит 10-16.11'!W$49 -> 2538 | M22: ='Юнит 10-16.11'!Z$49 -> 1700.67 | N22: ='Юнит 10-16.11'!X$49 -> 8503.68 | R22: ='Юнит 10-16.11'!AA$49 -> 4619.3844 | X22: =(K22)*0.01 -> 197.76 | Y22: =K22-SUM(M22:U22)-L22-X22+V22+W22 -> 2216.5056 | AA22: =L22/K22 -> 0.12833738 | AB22: =Y22/L22 -> 0.87332767 | AC22: =Y22/K22 -> 0.11208058 | AD22: =R22/K22 -> 0.23358537
B23: 17-23.11 очки | E23: =K23-SUM(M23:U23)+V23+W23 -> -6903.1175 | F23: ='Юнит 17-23.11'!K$26 -> 68 | G23: ='Юнит 17-23.11'!P$26 -> 33 | H23: ='Юнит 17-23.11'!Q$26 -> 2 | I23: ='Юнит 17-23.11'!S$26 -> 52152 | J23: ='Юнит 17-23.11'!T$26 -> -3051 | K23: =I23+J23 -> 49101 | L23: ='Юнит 17-23.11'!W$26 -> 4229.88 | M23: ='Юнит 17-23.11'!Z$26 -> 5536.12 | N23: ='Юнит 17-23.11'!X$26 -> 21012.9 | R23: ='Юнит 17-23.11'!AA$26 -> 27920.888 | S23: 5 | T23: 1529.21 | U23: 0 | X23: =(K23)*0.01 -> 491.01 | Y23: =K23-SUM(M23:U23)-L23-X23+V23+W23 -> -11624.008 | AA23: =L23/K23 -> 0.086146514 | AB23: =Y23/L23 -> -2.7480703 | AC23: =Y23/K23 -> -0.23673668 | AD23: =R23/K23 -> 0.56864193
B24: 17-23.11 туники | E24: =K24-SUM(M24:U24)+V24+W24 -> 127.9875 | F24: ='Юнит 17-23.11'!K$49 -> 5 | G24: ='Юнит 17-23.11'!P$49 -> 3 | H24: ='Юнит 17-23.11'!Q$49 -> 1 | I24: ='Юнит 17-23.11'!S$49 -> 13324 | J24: ='Юнит 17-23.11'!T$49 -> -5500 | K24: =I24+J24 -> 7824 | L24: ='Юнит 17-23.11'!W$49 -> 1224 | M24: ='Юнит 17-23.11'!Z$49 -> 1518.43 | N24: ='Юнит 17-23.11'!X$49 -> 3639.32 | R24: ='Юнит 17-23.11'!AA$49 -> 2538.2625 | X24: =(K24)*0.01 -> 78.24 | Y24: =K24-SUM(M24:U24)-L24-X24+V24+W24 -> -1174.2525 | AA24: =L24/K24 -> 0.15644172 | AB24: =Y24/L24 -> -0.95935662 | AC24: =Y24/K24 -> -0.1500834 | AD24: =R24/K24 -> 0.32442005
B25: 24-30.11 очки | E25: =K25-SUM(M25:U25)+V25+W25 -> 229.96895 | F25: ='Юнит 24-30.11'!K$26 -> 69 | G25: ='Юнит 24-30.11'!P$26 -> 36 | H25: ='Юнит 24-30.11'!Q$26 -> 4 | I25: ='Юнит 24-30.11'!S$26 -> 56557 | J25: ='Юнит 24-30.11'!T$26 -> -6081 | K25: =I25+J25 -> 50476 | L25: ='Юнит 24-30.11'!W$26 -> 4310.76 | M25: ='Юнит 24-30.11'!Z$26 -> 5747.37 | N25: ='Юнит 24-30.11'!X$26 -> 21704.68 | R25: ='Юнит 24-30.11'!AA$26 -> 21570.101 | S25: 5 | T25: 1218.88 | U25: 0 | X25: =(K25)*0.01 -> 504.76 | Y25: =K25-SUM(M25:U25)-L25-X25+V25+W25 -> -4585.5511 | AA25: =L25/K25 -> 0.085402171 | AB25: =Y25/L25 -> -1.0637454 | AC25: =Y25/K25 -> -0.090846166 | AD25: =R25/K25 -> 0.4273338
B26: 24-30.11 туники | E26: =K26-SUM(M26:U26)+V26+W26 -> 1301.1411 | F26: ='Юнит 24-30.11'!K$49 -> 7 | G26: ='Юнит 24-30.11'!P$49 -> 2 | H26: ='Юнит 24-30.11'!Q$49 -> 1 | I26: ='Юнит 24-30.11'!S$49 -> 12000 | J26: ='Юнит 24-30.11'!T$49 -> -6000 | K26: =I26+J26 -> 6000 | L26: ='Юнит 24-30.11'!W$49 -> 627 | M26: ='Юнит 24-30.11'!Z$49 -> 920.52 | N26: ='Юнит 24-30.11'!X$49 -> 2580 | R26: ='Юнит 24-30.11'!AA$49 -> 1198.3389 | X26: =(K26)*0.01 -> 60 | Y26: =K26-SUM(M26:U26)-L26-X26+V26+W26 -> 614.14105 | AA26: =L26/K26 -> 0.1045 | AB26: =Y26/L26 -> 0.97949131 | AC26: =Y26/K26 -> 0.10235684 | AD26: =R26/K26 -> 0.19972316
A27: Декабрь | B27: 01-07.12 очки | E27: =K27-SUM(M27:U27)+V27+W27 -> 24694.863 | F27: ='Юнит 01-07.12'!K$26 -> 79 | G27: ='Юнит 01-07.12'!P$26 -> 58 | H27: ='Юнит 01-07.12'!Q$26 -> 0 | I27: ='Юнит 01-07.12'!S$26 -> 86821 | J27: ='Юнит 01-07.12'!T$26 -> 0 | K27: =I27+J27 -> 86821 | L27: ='Юнит 01-07.12'!W$26 -> 7713.24 | M27: ='Юнит 01-07.12'!Z$26 -> 8892.35 | N27: ='Юнит 01-07.12'!X$26 -> 37333.03 | R27: ='Юнит 01-07.12'!AA$26 -> 13303.057 | S27: 10 | T27: 1682.9 | U27: 904.8 | X27: =(K27)*0.01 -> 868.21 | Y27: =K27-SUM(M27:U27)-L27-X27+V27+W27 -> 16113.413 | Z27: =SUM(Y27:Y34) -> 8669.76 | AA27: =L27/K27 -> 0.088840718 | AB27: =Y27/L27 -> 2.0890589 | AC27: =Y27/K27 -> 0.1855935 | AD27: =R27/K27 -> 0.15322395
B28: 01-07.12 туники | E28: =K28-SUM(M28:U28)+V28+W28 -> -4332.3931 | F28: ='Юнит 01-07.12'!K$49 -> 1 | G28: ='Юнит 01-07.12'!P$49 -> 1 | H28: ='Юнит 01-07.12'!Q$49 -> 2 | I28: ='Юнит 01-07.12'!S$49 -> 6500 | J28: ='Юнит 01-07.12'!T$49 -> -12000 | K28: =I28+J28 -> -5500 | L28: ='Юнит 01-07.12'!W$49 -> -597 | M28: ='Юнит 01-07.12'!Z$49 -> 968.03 | N28: ='Юнит 01-07.12'!X$49 -> -2365 | R28: ='Юнит 01-07.12'!AA$49 -> 229.36305 | X28: =(K28)*0.01 -> -55 | Y28: =K28-SUM(M28:U28)-L28-X28+V28+W28 -> -3680.3931 | AA28: =L28/K28 -> 0.10854545 | AB28: =Y28/L28 -> 6.1648125 | AC28: =Y28/K28 -> 0.66916237 | AD28: =R28/K28 -> -0.041702373
B29: 08-14.12 очки | E29: =K29-SUM(M29:U29)+V29+W29 -> 6987.3968 | F29: ='Юнит 08-14.12'!K$26 -> 58 | G29: ='Юнит 08-14.12'!P$26 -> 41 | H29: ='Юнит 08-14.12'!Q$26 -> 3 | I29: ='Юнит 08-14.12'!S$26 -> 59828 | J29: ='Юнит 08-14.12'!T$26 -> -4044 | K29: =I29+J29 -> 55784 | L29: ='Юнит 08-14.12'!W$26 -> 5156.85 | M29: ='Юнит 08-14.12'!Z$26 -> 6498.4 | N29: ='Юнит 08-14.12'!X$26 -> 23987.12 | R29: ='Юнит 08-14.12'!AA$26 -> 10153.333 | S29: 0 | T29: 1409.05 | U29: 6748.7 | X29: =(K29)*0.01 -> 557.84 | Y29: =K29-SUM(M29:U29)-L29-X29+V29+W29 -> 1272.7068 | AA29: =L29/K29 -> 0.092443174 | AB29: =Y29/L29 -> 0.24679927 | AC29: =Y29/K29 -> 0.022814908 | AD29: =R29/K29 -> 0.18201157
B30: 08-14.12 туники | E30: =K30-SUM(M30:U30)+V30+W30 -> 3305.2532 | F30: ='Юнит 08-14.12'!K$49 -> 6 | G30: ='Юнит 08-14.12'!P$49 -> 3 | H30: ='Юнит 08-14.12'!Q$49 -> 0 | I30: ='Юнит 08-14.12'!S$49 -> 8512 | J30: ='Юнит 08-14.12'!T$49 -> 0 | K30: =I30+J30 -> 8512 | L30: ='Юнит 08-14.12'!W$49 -> 1911 | M30: ='Юнит 08-14.12'!Z$49 -> 803.66 | N30: ='Юнит 08-14.12'!X$49 -> 3660.16 | R30: ='Юнит 08-14.12'!AA$49 -> 742.92682 | X30: =(K30)*0.01 -> 85.12 | Y30: =K30-SUM(M30:U30)-L30-X30+V30+W30 -> 1309.1332 | AA30: =L30/K30 -> 0.22450658 | AB30: =Y30/L30 -> 0.68505138 | AC30: =Y30/K30 -> 0.15379854 | AD30: =R30/K30 -> 0.087279936
B31: 15-21.12 очки | E31: =K31-SUM(M31:U31)+V31+W31 -> 247.73478 | F31: ='Юнит 15-21.12'!K$26 -> 95 | G31: ='Юнит 15-21.12'!P$26 -> 44 | H31: ='Юнит 15-21.12'!Q$26 -> 2 | I31: ='Юнит 15-21.12'!S$26 -> 61114 | J31: ='Юнит 15-21.12'!T$26 -> -3391 | K31: =I31+J31 -> 57723 | L31: ='Юнит 15-21.12'!W$26 -> 5689.17 | M31: ='Юнит 15-21.12'!Z$26 -> 7370.23 | N31: ='Юнит 15-21.12'!X$26 -> 24820.89 | R31: ='Юнит 15-21.12'!AA$26 -> 19747.085 | S31: 0 | T31: 1553.66 | U31: 3983.4 | X31: =(K31)*0.01 -> 577.23 | Y31: =K31-SUM(M31:U31)-L31-X31+V31+W31 -> -6018.6652 | AA31: =L31/K31 -> 0.098559846 | AB31: =Y31/L31 -> -1.0579162 | AC31: =Y31/K31 -> -0.10426806 | AD31: =R31/K31 -> 0.34210081
B32: 15-21.12 туники | E32: =K32-SUM(M32:U32)+V32+W32 -> 2202.8352 | F32: ='Юнит 15-21.12'!K$49 -> 2 | G32: ='Юнит 15-21.12'!P$49 -> 2 | H32: ='Юнит 15-21.12'!Q$49 -> 1 | I32: ='Юнит 15-21.12'!S$49 -> 9580 | J32: ='Юнит 15-21.12'!T$49 -> -3080 | K32: =I32+J32 -> 6500 | L32: ='Юнит 15-21.12'!W$49 -> 687 | M32: ='Юнит 15-21.12'!Z$49 -> 604.57 | N32: ='Юнит 15-21.12'!X$49 -> 2795 | R32: ='Юнит 15-21.12'!AA$49 -> 897.59478 | X32: =(K32)*0.01 -> 65 | Y32: =K32-SUM(M32:U32)-L32-X32+V32+W32 -> 1450.8352 | AA32: =L32/K32 -> 0.10569231 | AB32: =Y32/L32 -> 2.1118417 | AC32: =Y32/K32 -> 0.22320542 | AD32: =R32/K32 -> 0.13809151
B33: 22-31.12 очки | E33: =K33-SUM(M33:U33)+V33+W33 -> 12664.66 | F33: ='Юнит 22-31.12'!K$26 -> 152 | G33: ='Юнит 22-31.12'!P$26 -> 94 | H33: ='Юнит 22-31.12'!Q$26 -> 4 | I33: ='Юнит 22-31.12'!S$26 -> 139134 | J33: ='Юнит 22-31.12'!T$26 -> -5434 | K33: =I33+J33 -> 133700 | L33: ='Юнит 22-31.12'!W$26 -> 12820.23 | M33: ='Юнит 22-31.12'!Z$26 -> 13321.35 | N33: ='Юнит 22-31.12'!X$26 -> 57491 | R33: ='Юнит 22-31.12'!AA$26 -> 44059.45 | S33: 25 | T33: 2416.34 | U33: 3722.2 | X33: =(K33)*0.01 -> 1337 | Y33: =K33-SUM(M33:U33)-L33-X33+V33+W33 -> -1492.57 | AA33: =L33/K33 -> 0.095888033 | AB33: =Y33/L33 -> -0.11642303 | AC33: =Y33/K33 -> -0.011163575 | AD33: =R33/K33 -> 0.32953964
B34: 22-31.12 туники | E34: =K34-SUM(M34:U34)+V34+W34 -> -284.7 | F34: ='Юнит 22-31.12'!K$49 -> 3 | G34: ='Юнит 22-31.12'!P$49 -> 0 | H34: ='Юнит 22-31.12'!Q$49 -> 0 | I34: ='Юнит 22-31.12'!S$49 -> 0 | J34: ='Юнит 22-31.12'!T$49 -> 0 | K34: =I34+J34 -> 0 | L34: ='Юнит 22-31.12'!W$49 -> 0 | M34: ='Юнит 22-31.12'!Z$49 -> 284.7 | N34: ='Юнит 22-31.12'!X$49 -> 0 | R34: ='Юнит 22-31.12'!AA$49 -> 0 | X34: =(K34)*0.01 -> 0 | Y34: =K34-SUM(M34:U34)-L34-X34+V34+W34 -> -284.7 | AA34: =L34/K34 -> #DIV/0! | AB34: =Y34/L34 -> #DIV/0! | AC34: =Y34/K34 -> #DIV/0! | AD34: =R34/K34 -> #DIV/0!
A35: Итого | E35: =SUM(E3:E34) -> 193947.3 | F35: =SUM(F3:F34) -> 1159 | G35: =SUM(G3:G34) -> 632 | H35: =SUM(H3:H34) -> 42 | I35: =SUM(I3:I34) -> 1153756 | J35: =SUM(J3:J34) -> -118835 | K35: =SUM(K3:K34) -> 1034921 | L35: =SUM(L3:L34) -> 140719.76 | ... Z35: =SUM(Z3:Z34) -> 42878.33 | AA35: =L35/K35 -> 0.1359715 | AB35: =Y35/L35 -> 0.30470724 | AC35: =Y35/K35 -> 0.041431501 | AD35: =R35/K35 -> 0.43055238
I36: % от выручки за весь период
J37: =-J35/I35 -> 0.10299838 | K37: 0 | L37: =L35/$K$35 -> 0.1359715 | M37: =M35/$K$35 -> 0.093262549 | N37: =N35/$K$35 -> 0.34858148 | R37: =R35/$K$35 -> 0.43055238 | X37: =X35/$K$35 -> 0.01 | Y37: =Y35/L35 -> 0.30470724 | Z37: Маржинальность, %
Y38: =Y35/$K$35 -> 0.041431501 | Z38: Рентабельность, %
I39: 22-31.12
I40: % от выручки за последнюю неделю
...

Sheet Дашборд 22-31.12
B2: Период | E2: Дата поступления дс | F2: Итого к перечислению на счет, руб | G2: Выручка | J2: Себестоимость продаж | K2: Логистика | L2: Комиссия | M2: Хранение | N2: Платная приемка | O2: Штрафы | P2: Реклама Ozon | Q2: Прочее | R2: Доп. услуги | S2: Услуги FBO | T2: Компенсировано | U2: Прочие начисления | V2: Налог | W2: Итого | Y2: % Cебестоимости | Z2: Маржинальность, % | AA2: Рентабельность, % | AB2: Доля рекламы, %
B3: Месяц | C3: Даты | D3: Нед | G3: Продажи | H3: Возвраты | I3: Общая
C4: ='Динамика финансы'!B33 -> 22-31.12 очки | D4: ='Динамика финансы'!C33 -> 0 | E4: ='Динамика финансы'!D33 -> 0 | F4: ='Динамика финансы'!E33 -> 12664.66 | G4: ='Динамика финансы'!I33 -> 139134 | H4: ='Динамика финансы'!J33 -> -5434 | I4: ='Динамика финансы'!K33 -> 133700 | J4: ='Динамика финансы'!L33 -> 12820.23 | K4: ='Динамика финансы'!M33 -> 13321.35 | L4: ='Динамика финансы'!N33 -> 57491 | M4: ='Динамика финансы'!O33 -> 0 | N4: ='Динамика финансы'!P33 -> 0 | ... W4: ='Динамика финансы'!Y33 -> -1492.57 | Y4: ='Динамика финансы'!AA33 -> 0.095888033 | Z4: ='Динамика финансы'!AB33 -> -0.11642303 | AA4: ='Динамика финансы'!AC33 -> -0.011163575 | AB4: ='Динамика финансы'!AD33 -> 0.32953964
C5: ='Динамика финансы'!B34 -> 22-31.12 туники | D5: ='Динамика финансы'!C34 -> 0 | E5: ='Динамика финансы'!D34 -> 0 | F5: ='Динамика финансы'!E34 -> -284.7 | G5: ='Динамика финансы'!I34 -> 0 | H5: ='Динамика финансы'!J34 -> 0 | I5: ='Динамика финансы'!K34 -> 0 | J5: ='Динамика финансы'!L34 -> 0 | K5: ='Динамика финансы'!M34 -> 284.7 | L5: ='Динамика финансы'!N34 -> 0 | M5: ='Динамика финансы'!O34 -> 0 | N5: ='Динамика финансы'!P34 -> 0 | ... W5: ='Динамика финансы'!Y34 -> -284.7 | Y5: ='Динамика финансы'!AA34 -> #DIV/0! | Z5: ='Динамика финансы'!AB34 -> #DIV/0! | AA5: ='Динамика финансы'!AC34 -> #DIV/0! | AB5: ='Динамика финансы'!AD34 -> #DIV/0!
F8: =F4+F5+F6+F7 -> 12379.96 | G8: =G4+G5+G6+G7 -> 139134 | H8: =H4+H5+H6+H7 -> -5434 | I8: =I4+I5+I6+I7 -> 133700 | J8: =J4+J5+J6+J7 -> 12820.23 | K8: =K4+K5+K6+K7 -> 13606.05 | L8: =L4+L5+L6+L7 -> 57491 | M8: =M4+M5+M6+M7 -> 0 | ... W8: =W4+W5+W6+W7 -> -1777.27
C11: АНАЛИЗ ФИНАНСОВЫХ ПОКАЗАТЕЛЕЙ ЗА | G11: 22-31.12
C13: ОЧКИ | I13: ТУНИКИ
C15: Выручка | E15: =I4 -> 133700 | F15: руб. | G15: ='Динамика финансы'!K44 -> 1.3162344 | I15: Выручка | K15: =I5 -> 0 | L15: руб. | M15: ='Динамика финансы'!K45 -> -1
C16: Прибыль | E16: =W4 -> -1492.57 | F16: руб. | G16: ='Динамика финансы'!Y44 -> 0.7520098 | I16: Прибыль | K16: =W5 -> -284.7 | L16: руб. | M16: ='Динамика финансы'!Y45 -> -1.1962318
C17: Себестоимость продаж | E17: =J4 -> 12820.23 | F17: руб. | G17: ='Динамика финансы'!L44 -> 1.2534447 | I17: Себестоимость продаж | K17: =J5 -> 0 | L17: руб. | M17: ='Динамика финансы'!L45 -> -1
G18: % от выручки | M18: % от выручки
C19: Логистика | E19: =K4 -> 13321.35 | F19: руб. | G19: ='Динамика финансы'!M41 -> 0.099636126 | I19: Логистика | K19: =K5 -> 284.7 | L19: руб. | M19: ='Динамика финансы'!M42 -> #DIV/0!
C20: Реклама | E20: =P4 -> 44059.45 | F20: руб. | G20: ='Динамика финансы'!R41 -> 0.32953964 | I20: Реклама | K20: =P5 -> 0 | L20: руб. | M20: ='Динамика финансы'!R42 -> #DIV/0!
C22: Возвраты | E22: =H4 -> -5434 | F22: руб. | G22: ='Динамика финансы'!J41 -> 0.039055874 | I22: Возвраты | K22: =H5 -> 0 | L22: руб. | M22: ='Динамика финансы'!J42 -> #DIV/0!
C23: Комиссия | E23: =L4 -> 57491 | F23: руб. | G23: ='Динамика финансы'!N41 -> 0.43 | I23: Комиссия | K23: =L5 -> 0 | L23: руб. | M23: ='Динамика финансы'!N42 -> #DIV/0!
E25: Маржинальность | G25: =Z4 -> -0.11642303 | K25: Маржинальность | M25: =Z5 -> #DIV/0!
E26: Рентабельность | G26: =AA4 -> -0.011163575 | K26: Рентабельность | M26: =AA5 -> #DIV/0!
E27: % себестоимости | G27: =Y4 -> 0.095888033 | K27: % себестоимости | M27: =Y5 -> #DIV/0!
F29: На остатках товара на | I29: руб.

Sheet Дашборд 15-21.12
B2: Период | E2: Дата поступления дс | F2: Итого к перечислению на счет, руб | G2: Выручка | J2: Себестоимость продаж | K2: Логистика | L2: Комиссия | M2: Хранение | N2: Платная приемка | O2: Штрафы | P2: Реклама Ozon | Q2: Прочее | R2: Доп. услуги | S2: Услуги FBO | T2: Компенсировано | U2: Прочие начисления | V2: Налог | W2: Итого | Y2: % Cебестоимости | Z2: Маржинальность, % | AA2: Рентабельность, % | AB2: Доля рекламы, %
B3: Месяц | C3: Даты | D3: Нед | G3: Продажи | H3: Возвраты | I3: Общая
C4: ='Динамика финансы'!B31 -> 15-21.12 очки | D4: ='Динамика финансы'!C31 -> 0 | E4: ='Динамика финансы'!D31 -> 0 | F4: ='Динамика финансы'!E31 -> 247.73478 | G4: ='Динамика финансы'!I31 -> 61114 | H4: ='Динамика финансы'!J31 -> -3391 | I4: ='Динамика финансы'!K31 -> 57723 | J4: ='Динамика финансы'!L31 -> 5689.17 | K4: ='Динамика финансы'!M31 -> 7370.23 | L4: ='Динамика финансы'!N31 -> 24820.89 | M4: ='Динамика финансы'!O31 -> 0 | N4: ='Динамика финансы'!P31 -> 0 | ... W4: ='Динамика финансы'!Y31 -> -6018.6652 | Y4: ='Динамика финансы'!AA31 -> 0.098559846 | Z4: ='Динамика финансы'!AB31 -> -1.0579162 | AA4: ='Динамика финансы'!AC31 -> -0.10426806 | AB4: ='Динамика финансы'!AD31 -> 0.34210081
C5: ='Динамика финансы'!B32 -> 15-21.12 туники | D5: ='Динамика финансы'!C32 -> 0 | E5: ='Динамика финансы'!D32 -> 0 | F5: ='Динамика финансы'!E32 -> 2202.8352 | G5: ='Динамика финансы'!I32 -> 9580 | H5: ='Динамика финансы'!J32 -> -3080 | I5: ='Динамика финансы'!K32 -> 6500 | J5: ='Динамика финансы'!L32 -> 687 | K5: ='Динамика финансы'!M32 -> 604.57 | L5: ='Динамика финансы'!N32 -> 2795 | M5: ='Динамика финансы'!O32 -> 0 | N5: ='Динамика финансы'!P32 -> 0 | ... W5: ='Динамика финансы'!Y32 -> 1450.8352 | Y5: ='Динамика финансы'!AA32 -> 0.10569231 | Z5: ='Динамика финансы'!AB32 -> 2.1118417 | AA5: ='Динамика финансы'!AC32 -> 0.22320542 | AB5: ='Динамика финансы'!AD32 -> 0.13809151
F8: =F4+F5+F6+F7 -> 2450.57 | G8: =G4+G5+G6+G7 -> 70694 | H8: =H4+H5+H6+H7 -> -6471 | I8: =I4+I5+I6+I7 -> 64223 | J8: =J4+J5+J6+J7 -> 6376.17 | K8: =K4+K5+K6+K7 -> 7974.8 | L8: =L4+L5+L6+L7 -> 27615.89 | M8: =M4+M5+M6+M7 -> 0 | ... W8: =W4+W5+W6+W7 -> -4567.83
C11: АНАЛИЗ ФИНАНСОВЫХ ПОКАЗАТЕЛЕЙ ЗА | G11: 15-21.12
C13: ОЧКИ | I13: ТУНИКИ
C15: Выручка | E15: =I4 -> 57723 | F15: руб. | G15: ='Динамика финансы'!K51 -> 0.034759071 | I15: Выручка | K15: =I5 -> 6500 | L15: руб. | M15: ='Динамика финансы'!K52 -> -0.23637218
C16: Прибыль | E16: =W4 -> -6018.6652 | F16: руб. | G16: ='Динамика финансы'!Y51 -> -5.7290272 | I16: Прибыль | K16: =W5 -> 1450.8352 | L16: руб. | M16: ='Динамика финансы'!Y52 -> 0.10824112
C17: Себестоимость продаж | E17: =J4 -> 5689.17 | F17: руб. | G17: ='Динамика финансы'!L51 -> 0.10322581 | I17: Себестоимость продаж | K17: =J5 -> 687 | L17: руб. | M17: ='Динамика финансы'!L52 -> -0.64050235
G18: % от выручки | M18: % от выручки
C19: Логистика | E19: =K4 -> 7370.23 | F19: руб. | G19: ='Динамика финансы'!M48 -> 0.12768273 | I19: Логистика | K19: =K5 -> 604.57 | L19: руб. | M19: ='Динамика финансы'!M49 -> 0.093010769
C20: Реклама | E20: =P4 -> 19747.085 | F20: руб. | G20: ='Динамика финансы'!R48 -> 0.34210081 | I20: Реклама | K20: =P5 -> 897.59478 | L20: руб. | M20: ='Динамика финансы'!R49 -> 0.13809151
C22: Возвраты | E22: =H4 -> -3391 | F22: руб. | G22: ='Динамика финансы'!J48 -> 0.055486468 | I22: Возвраты | K22: =H5 -> -3080 | L22: руб. | M22: ='Динамика финансы'!J49 -> 0.32150313
C23: Комиссия | E23: =L4 -> 24820.89 | F23: руб. | G23: ='Динамика финансы'!N48 -> 0.43 | I23: Комиссия | K23: =L5 -> 2795 | L23: руб. | M23: ='Динамика финансы'!N49 -> 0.43
E25: Маржинальность | G25: =Z4 -> -1.0579162 | K25: Маржинальность | M25: =Z5 -> 2.1118417
E26: Рентабельность | G26: =AA4 -> -0.10426806 | K26: Рентабельность | M26: =AA5 -> 0.22320542
E27: % себестоимости | G27: =Y4 -> 0.098559846 | K27: % себестоимости | M27: =Y5 -> 0.10569231
F29: На остатках товара на | H29: ='Юнит 15-21.12'!I51 -> 808739.01 | I29: руб.

Sheet Дашборд 08-14.12
B2: Период | E2: Дата поступления дс | F2: Итого к перечислению на счет, руб | G2: Выручка | J2: Себестоимость продаж | K2: Логистика | L2: Комиссия | M2: Хранение | N2: Платная приемка | O2: Штрафы | P2: Реклама Ozon | Q2: Прочее | R2: Доп. услуги | S2: Услуги FBO | T2: Компенсировано | U2: Прочие начисления | V2: Налог | W2: Итого | Y2: % Cебестоимости | Z2: Маржинальность, % | AA2: Рентабельность, % | AB2: Доля рекламы, %
B3: Месяц | C3: Даты | D3: Нед | G3: Продажи | H3: Возвраты | I3: Общая
C4: ='Динамика финансы'!B29 -> 08-14.12 очки | D4: ='Динамика финансы'!C29 -> 0 | E4: ='Динамика финансы'!D29 -> 0 | F4: ='Динамика финансы'!E29 -> 6987.3968 | G4: ='Динамика финансы'!I29 -> 59828 | H4: ='Динамика финансы'!J29 -> -4044 | I4: ='Динамика финансы'!K29 -> 55784 | J4: ='Динамика финансы'!L29 -> 5156.85 | K4: ='Динамика финансы'!M29 -> 6498.4 | L4: ='Динамика финансы'!N29 -> 23987.12 | M4: ='Динамика финансы'!O29 -> 0 | N4: ='Динамика финансы'!P29 -> 0 | ... W4: ='Динамика финансы'!Y29 -> 1272.7068 | Y4: ='Динамика финансы'!AA29 -> 0.092443174 | Z4: ='Динамика финансы'!AB29 -> 0.24679927 | AA4: ='Динамика финансы'!AC29 -> 0.022814908 | AB4: ='Динамика финансы'!AD29 -> 0.18201157
C5: ='Динамика финансы'!B30 -> 08-14.12 туники | D5: ='Динамика финансы'!C30 -> 0 | E5: ='Динамика финансы'!D30 -> 0 | F5: ='Динамика финансы'!E30 -> 3305.2532 | G5: ='Динамика финансы'!I30 -> 8512 | H5: ='Динамика финансы'!J30 -> 0 | I5: ='Динамика финансы'!K30 -> 8512 | J5: ='Динамика финансы'!L30 -> 1911 | K5: ='Динамика финансы'!M30 -> 803.66 | L5: ='Динамика финансы'!N30 -> 3660.16 | M5: ='Динамика финансы'!O30 -> 0 | N5: ='Динамика финансы'!P30 -> 0 | ... W5: ='Динамика финансы'!Y30 -> 1309.1332 | Y5: ='Динамика финансы'!AA30 -> 0.22450658 | Z5: ='Динамика финансы'!AB30 -> 0.68505138 | AA5: ='Динамика финансы'!AC30 -> 0.15379854 | AB5: ='Динамика финансы'!AD30 -> 0.087279936
F8: =F4+F5+F6+F7 -> 10292.65 | G8: =G4+G5+G6+G7 -> 68340 | H8: =H4+H5+H6+H7 -> -4044 | I8: =I4+I5+I6+I7 -> 64296 | J8: =J4+J5+J6+J7 -> 7067.85 | K8: =K4+K5+K6+K7 -> 7302.06 | L8: =L4+L5+L6+L7 -> 27647.28 | M8: =M4+M5+M6+M7 -> 0 | ... W8: =W4+W5+W6+W7 -> 2581.84
C11: АНАЛИЗ ФИНАНСОВЫХ ПОКАЗАТЕЛЕЙ ЗА | G11: 08-14.12
C13: ОЧКИ | I13: ТУНИКИ
C15: Выручка | E15: =I4 -> 55784 | F15: руб. | G15: ='Динамика финансы'!K58 -> -0.35748264 | I15: Выручка | K15: =I5 -> 8512 | L15: руб. | M15: ='Динамика финансы'!K59 -> -2.5476364
C16: Прибыль | E16: =W4 -> 1272.7068 | F16: руб. | G16: ='Динамика финансы'!Y58 -> -0.92101569 | I16: Прибыль | K16: =W5 -> 1309.1332 | L16: руб. | M16: ='Динамика финансы'!Y59 -> 1.3557047
C17: Себестоимость продаж | E17: =J4 -> 5156.85 | F17: руб. | G17: ='Динамика финансы'!L58 -> -0.33142882 | I17: Себестоимость продаж | K17: =J5 -> 1911 | L17: руб. | M17: ='Динамика финансы'!L59 -> -4.201005
G18: % от выручки | M18: % от выручки
C19: Логистика | E19: =K4 -> 6498.4 | F19: руб. | G19: ='Динамика финансы'!M55 -> 0.11649218 | I19: Логистика | K19: =K5 -> 803.66 | L19: руб. | M19: ='Динамика финансы'!M56 -> 0.094414944
C20: Реклама | E20: =P4 -> 10153.333 | F20: руб. | G20: ='Динамика финансы'!R55 -> 0.18201157 | I20: Реклама | K20: =P5 -> 742.92682 | L20: руб. | M20: ='Динамика финансы'!R56 -> 0.087279936
C22: Возвраты | E22: =H4 -> -4044 | F22: руб. | G22: ='Динамика финансы'!J55 -> 0.067593769 | I22: Возвраты | K22: =H5 -> 0 | L22: руб. | M22: ='Динамика финансы'!J56 -> 0
C23: Комиссия | E23: =L4 -> 23987.12 | F23: руб. | G23: ='Динамика финансы'!N55 -> 0.43 | I23: Комиссия | K23: =L5 -> 3660.16 | L23: руб. | M23: ='Динамика финансы'!N56 -> 0.43
E25: Маржинальность | G25: =Z4 -> 0.24679927 | K25: Маржинальность | M25: =Z5 -> 0.68505138
E26: Рентабельность | G26: =AA4 -> 0.022814908 | K26: Рентабельность | M26: =AA5 -> 0.15379854
E27: % себестоимости | G27: =Y4 -> 0.092443174 | K27: % себестоимости | M27: =Y5 -> 0.22450658
F29: На остатках товара на | H29: ='Юнит 24-30.11'!I51 -> 728189.41 | I29: руб.

Sheet Дашборд 01-07.12
B2: Период | E2: Дата поступления дс | F2: Итого к перечислению на счет, руб | G2: Выручка | J2: Себестоимость продаж | K2: Логистика | L2: Комиссия | M2: Хранение | N2: Платная приемка | O2: Штрафы | P2: Реклама Ozon | Q2: Прочее | R2: Доп. услуги | S2: Услуги FBO | T2: Компенсировано | U2: Прочие начисления | V2: Налог | W2: Итого | Y2: % Cебестоимости | Z2: Маржинальность, % | AA2: Рентабельность, % | AB2: Доля рекламы, %
B3: Месяц | C3: Даты | D3: Нед | G3: Продажи | H3: Возвраты | I3: Общая
C4: ='Динамика финансы'!B27 -> 01-07.12 очки | D4: ='Динамика финансы'!C27 -> 0 | E4: ='Динамика финансы'!D27 -> 0 | F4: ='Динамика финансы'!E27 -> 24694.863 | G4: ='Динамика финансы'!I27 -> 86821 | H4: ='Динамика финансы'!J27 -> 0 | I4: ='Динамика финансы'!K27 -> 86821 | J4: ='Динамика финансы'!L27 -> 7713.24 | K4: ='Динамика финансы'!M27 -> 8892.35 | L4: ='Динамика финансы'!N27 -> 37333.03 | M4: ='Динамика финансы'!O27 -> 0 | N4: ='Динамика финансы'!P27 -> 0 | ... W4: ='Динамика финансы'!Y27 -> 16113.413 | Y4: ='Динамика финансы'!AA27 -> 0.088840718 | Z4: ='Динамика финансы'!AB27 -> 2.0890589 | AA4: ='Динамика финансы'!AC27 -> 0.1855935 | AB4: ='Динамика финансы'!AD27 -> 0.15322395
C5: ='Динамика финансы'!B28 -> 01-07.12 туники | D5: ='Динамика финансы'!C28 -> 0 | E5: ='Динамика финансы'!D28 -> 0 | F5: ='Динамика финансы'!E28 -> -4332.3931 | G5: ='Динамика финансы'!I28 -> 6500 | H5: ='Динамика финансы'!J28 -> -12000 | I5: ='Динамика финансы'!K28 -> -5500 | J5: ='Динамика финансы'!L28 -> -597 | K5: ='Динамика финансы'!M28 -> 968.03 | L5: ='Динамика финансы'!N28 -> -2365 | M5: ='Динамика финансы'!O28 -> 0 | N5: ='Динамика финансы'!P28 -> 0 | ... W5: ='Динамика финансы'!Y28 -> -3680.3931 | Y5: ='Динамика финансы'!AA28 -> 0.10854545 | Z5: ='Динамика финансы'!AB28 -> 6.1648125 | AA5: ='Динамика финансы'!AC28 -> 0.66916237 | AB5: ='Динамика финансы'!AD28 -> -0.041702373
F8: =F4+F5+F6+F7 -> 20362.47 | G8: =G4+G5+G6+G7 -> 93321 | H8: =H4+H5+H6+H7 -> -12000 | I8: =I4+I5+I6+I7 -> 81321 | J8: =J4+J5+J6+J7 -> 7116.24 | K8: =K4+K5+K6+K7 -> 9860.38 | L8: =L4+L5+L6+L7 -> 34968.03 | M8: =M4+M5+M6+M7 -> 0 | ... W8: =W4+W5+W6+W7 -> 12433.02
C11: АНАЛИЗ ФИНАНСОВЫХ ПОКАЗАТЕЛЕЙ ЗА | G11: 01-07.12
C13: ОЧКИ | I13: ТУНИКИ
C15: Выручка | E15: =I4 -> 86821 | F15: руб. | G15: ='Динамика финансы'!K65 -> 0.72004517 | I15: Выручка | K15: =I5 -> -5500 | L15: руб. | M15: ='Динамика финансы'!K66 -> -1.9166667
C16: Прибыль | E16: =W4 -> 16113.413 | F16: руб. | G16: ='Динамика финансы'!Y65 -> 4.5139535 | I16: Прибыль | K16: =W5 -> -3680.3931 | L16: руб. | M16: ='Динамика финансы'!Y66 -> -6.9927488
C17: Себестоимость продаж | E17: =J4 -> 7713.24 | F17: руб. | G17: ='Динамика финансы'!L65 -> 0.78929933 | I17: Себестоимость продаж | K17: =J5 -> -597 | L17: руб. | M17: ='Динамика финансы'!L66 -> -1.9521531
G18: % от выручки | M18: % от выручки
C19: Логистика | E19: =K4 -> 8892.35 | F19: руб. | G19: ='Динамика финансы'!M62 -> 0.10242165 | I19: Логистика | K19: =K5 -> 968.03 | L19: руб. | M19: ='Динамика финансы'!M63 -> -0.17600545
C20: Реклама | E20: =P4 -> 13303.057 | F20: руб. | G20: ='Динамика финансы'!R62 -> 0.15322395 | I20: Реклама | K20: =P5 -> 229.36305 | L20: руб. | M20: ='Динамика финансы'!R63 -> -0.041702373
C22: Возвраты | E22: =H4 -> 0 | F22: руб. | G22: ='Динамика финансы'!J62 -> 0 | I22: Возвраты | K22: =H5 -> -12000 | L22: руб. | M22: ='Динамика финансы'!J63 -> 1.8461538
C23: Комиссия | E23: =L4 -> 37333.03 | F23: руб. | G23: ='Динамика финансы'!N62 -> 0.43 | I23: Комиссия | K23: =L5 -> -2365 | L23: руб. | M23: ='Динамика финансы'!N63 -> 0.43
E25: Маржинальность | G25: =Z4 -> 2.0890589 | K25: Маржинальность | M25: =Z5 -> 6.1648125
E26: Рентабельность | G26: =AA4 -> 0.1855935 | K26: Рентабельность | M26: =AA5 -> 0.66916237
E27: % себестоимости | G27: =Y4 -> 0.088840718 | K27: % себестоимости | M27: =Y5 -> 0.10854545
F29: На остатках товара на | H29: ='Юнит 24-30.11'!I51 -> 728189.41 | I29: руб.

Sheet Дашборд 24-30.11
B2: Период | E2: Дата поступления дс | F2: Итого к перечислению на счет, руб | G2: Выручка | J2: Себестоимость продаж | K2: Логистика | L2: Комиссия | M2: Хранение | N2: Платная приемка | O2: Штрафы | P2: Реклама Ozon | Q2: Прочее | R2: Доп. услуги | S2: Услуги FBO | T2: Компенсировано | U2: Прочие начисления | V2: Налог | W2: Итого | Y2: % Cебестоимости | Z2: Маржинальность, % | AA2: Рентабельность, % | AB2: Доля рекламы, %
B3: Месяц | C3: Даты | D3: Нед | G3: Продажи | H3: Возвраты | I3: Общая
C4: ='Динамика финансы'!B25 -> 24-30.11 очки | D4: ='Динамика финансы'!C25 -> 0 | E4: ='Динамика финансы'!D25 -> 0 | F4: ='Динамика финансы'!E25 -> 229.96895 | G4: ='Динамика финансы'!I25 -> 56557 | H4: ='Динамика финансы'!J25 -> -6081 | I4: ='Динамика финансы'!K25 -> 50476 | J4: ='Динамика финансы'!L25 -> 4310.76 | K4: ='Динамика финансы'!M25 -> 5747.37 | L4: ='Динамика финансы'!N25 -> 21704.68 | M4: ='Динамика финансы'!O25 -> 0 | N4: ='Динамика финансы'!P25 -> 0 | ... W4: ='Динамика финансы'!Y25 -> -4585.5511 | Y4: ='Динамика финансы'!AA25 -> 0.085402171 | Z4: ='Динамика финансы'!AB25 -> -1.0637454 | AA4: ='Динамика финансы'!AC25 -> -0.090846166 | AB4: ='Динамика финансы'!AD25 -> 0.4273338
C5: ='Динамика финансы'!B26 -> 24-30.11 туники | D5: ='Динамика финансы'!C26 -> 0 | E5: ='Динамика финансы'!D26 -> 0 | F5: ='Динамика финансы'!E26 -> 1301.1411 | G5: ='Динамика финансы'!I26 -> 12000 | H5: ='Динамика финансы'!J26 -> -6000 | I5: ='Динамика финансы'!K26 -> 6000 | J5: ='Динамика финансы'!L26 -> 627 | K5: ='Динамика финансы'!M26 -> 920.52 | L5: ='Динамика финансы'!N26 -> 2580 | M5: ='Динамика финансы'!O26 -> 0 | N5: ='Динамика финансы'!P26 -> 0 | ... W5: ='Динамика финансы'!Y26 -> 614.14105 | Y5: ='Динамика финансы'!AA26 -> 0.1045 | Z5: ='Динамика финансы'!AB26 -> 0.97949131 | AA5: ='Динамика финансы'!AC26 -> 0.10235684 | AB5: ='Динамика финансы'!AD26 -> 0.19972316
F8: =F4+F5+F6+F7 -> 1531.11 | G8: =G4+G5+G6+G7 -> 68557 | H8: =H4+H5+H6+H7 -> -12081 | I8: =I4+I5+I6+I7 -> 56476 | J8: =J4+J5+J6+J7 -> 4937.76 | K8: =K4+K5+K6+K7 -> 6667.89 | L8: =L4+L5+L6+L7 -> 24284.68 | M8: =M4+M5+M6+M7 -> 0 | ... W8: =W4+W5+W6+W7 -> -3971.41
C11: АНАЛИЗ ФИНАНСОВЫХ ПОКАЗАТЕЛЕЙ ЗА | G11: 24-30.11
C13: ОЧКИ | I13: ТУНИКИ
C15: Выручка | E15: =I4 -> 50476 | F15: руб. | G15: ='Динамика финансы'!K72 -> 0.028003503 | I15: Выручка | K15: =I5 -> 6000 | L15: руб. | M15: ='Динамика финансы'!K73 -> -0.23312883
C16: Прибыль | E16: =W4 -> -4585.5511 | F16: руб. | G16: ='Динамика финансы'!Y72 -> 0.60551032 | I16: Прибыль | K16: =W5 -> 614.14105 | L16: руб. | M16: ='Динамика финансы'!Y73 -> 1.523006
C17: Себестоимость продаж | E17: =J4 -> 4310.76 | F17: руб. | G17: ='Динамика финансы'!L72 -> 0.01912111 | I17: Себестоимость продаж | K17: =J5 -> 627 | L17: руб. | M17: ='Динамика финансы'!L73 -> -0.4877451
G18: % от выручки | M18: % от выручки
C19: Логистика | E19: =K4 -> 5747.37 | F19: руб. | G19: ='Динамика финансы'!M69 -> 0.11386342 | I19: Логистика | K19: =K5 -> 920.52 | L19: руб. | M19: ='Динамика финансы'!M70 -> 0.15342
C20: Реклама | E20: =P4 -> 21570.101 | F20: руб. | G20: ='Динамика финансы'!R69 -> 0.4273338 | I20: Реклама | K20: =P5 -> 1198.3389 | L20: руб. | M20: ='Динамика финансы'!R70 -> 0.19972316
C22: Возвраты | E22: =H4 -> -6081 | F22: руб. | G22: ='Динамика финансы'!J69 -> 0.10751985 | I22: Возвраты | K22: =H5 -> -6000 | L22: руб. | M22: ='Динамика финансы'!J70 -> 0.5
C23: Комиссия | E23: =L4 -> 21704.68 | F23: руб. | G23: ='Динамика финансы'!N69 -> 0.43 | I23: Комиссия | K23: =L5 -> 2580 | L23: руб. | M23: ='Динамика финансы'!N70 -> 0.43
E25: Маржинальность | G25: =Z4 -> -1.0637454 | K25: Маржинальность | M25: =Z5 -> 0.97949131
E26: Рентабельность | G26: =AA4 -> -0.090846166 | K26: Рентабельность | M26: =AA5 -> 0.10235684
E27: % себестоимости | G27: =Y4 -> 0.085402171 | K27: % себестоимости | M27: =Y5 -> 0.1045
F29: На остатках товара на | H29: ='Юнит 24-30.11'!I51 -> 728189.41 | I29: руб.

Sheet Дашборд 17-23.11
B2: Период | E2: Дата поступления дс | F2: Итого к перечислению на счет, руб | G2: Выручка | J2: Себестоимость продаж | K2: Логистика | L2: Комиссия | M2: Хранение | N2: Платная приемка | O2: Штрафы | P2: Реклама Ozon | Q2: Прочее | R2: Доп. услуги | S2: Услуги FBO | T2: Компенсировано | U2: Прочие начисления | V2: Налог | W2: Итого | Y2: % Cебестоимости | Z2: Маржинальность, % | AA2: Рентабельность, % | AB2: Доля рекламы, %
B3: Месяц | C3: Даты | D3: Нед | G3: Продажи | H3: Возвраты | I3: Общая
C4: ='Динамика финансы'!B23 -> 17-23.11 очки | D4: ='Динамика финансы'!C23 -> 0 | E4: ='Динамика финансы'!D23 -> 0 | F4: ='Динамика финансы'!E23 -> -6903.1175 | G4: ='Динамика финансы'!I23 -> 52152 | H4: ='Динамика финансы'!J23 -> -3051 | I4: ='Динамика финансы'!K23 -> 49101 | J4: ='Динамика финансы'!L23 -> 4229.88 | K4: ='Динамика финансы'!M23 -> 5536.12 | L4: ='Динамика финансы'!N23 -> 21012.9 | M4: ='Динамика финансы'!O23 -> 0 | N4: ='Динамика финансы'!P23 -> 0 | ... W4: ='Динамика финансы'!Y23 -> -11624.008 | Y4: ='Динамика финансы'!AA23 -> 0.086146514 | Z4: ='Динамика финансы'!AB23 -> -2.7480703 | AA4: ='Динамика финансы'!AC23 -> -0.23673668 | AB4: ='Динамика финансы'!AD23 -> 0.56864193
C5: ='Динамика финансы'!B24 -> 17-23.11 туники | D5: ='Динамика финансы'!C24 -> 0 | E5: ='Динамика финансы'!D24 -> 0 | F5: ='Динамика финансы'!E24 -> 127.9875 | G5: ='Динамика финансы'!I24 -> 13324 | H5: ='Динамика финансы'!J24 -> -5500 | I5: ='Динамика финансы'!K24 -> 7824 | J5: ='Динамика финансы'!L24 -> 1224 | K5: ='Динамика финансы'!M24 -> 1518.43 | L5: ='Динамика финансы'!N24 -> 3639.32 | M5: ='Динамика финансы'!O24 -> 0 | N5: ='Динамика финансы'!P24 -> 0 | ... W5: ='Динамика финансы'!Y24 -> -1174.2525 | Y5: ='Динамика финансы'!AA24 -> 0.15644172 | Z5: ='Динамика финансы'!AB24 -> -0.95935662 | AA5: ='Динамика финансы'!AC24 -> -0.1500834 | AB5: ='Динамика финансы'!AD24 -> 0.32442005
F8: =F4+F5+F6+F7 -> -6775.13 | G8: =G4+G5+G6+G7 -> 65476 | H8: =H4+H5+H6+H7 -> -8551 | I8: =I4+I5+I6+I7 -> 56925 | J8: =J4+J5+J6+J7 -> 5453.88 | K8: =K4+K5+K6+K7 -> 7054.55 | L8: =L4+L5+L6+L7 -> 24652.22 | M8: =M4+M5+M6+M7 -> 0 | ... W8: =W4+W5+W6+W7 -> -12798.26
C11: АНАЛИЗ ФИНАНСОВЫХ ПОКАЗАТЕЛЕЙ ЗА | G11: 10-16.11
C13: ОЧКИ | I13: ТУНИКИ
C15: Выручка | E15: =I4 -> 49101 | F15: руб. | G15: ='Динамика финансы'!K79 -> 0.25648703 | I15: Выручка | K15: =I5 -> 7824 | L15: руб. | M15: ='Динамика финансы'!K80 -> -0.60436893
C16: Прибыль | E16: =W4 -> -11624.008 | F16: руб. | G16: ='Динамика финансы'!Y79 -> 0.16602075 | I16: Прибыль | K16: =W5 -> -1174.2525 | L16: руб. | M16: ='Динамика финансы'!Y80 -> 1.5297765
C17: Себестоимость продаж | E17: =J4 -> 4229.88 | F17: руб. | G17: ='Динамика финансы'!L79 -> 0.18133604 | I17: Себестоимость продаж | K17: =J5 -> 1224 | L17: руб. | M17: ='Динамика финансы'!L80 -> -0.5177305
G18: % от выручки | M18: % от выручки
C19: Логистика | E19: =K4 -> 5536.12 | F19: руб. | G19: ='Динамика финансы'!M76 -> 0.11274964 | I19: Логистика | K19: =K5 -> 1518.43 | L19: руб. | M19: ='Динамика финансы'!M77 -> 0.19407336
C20: Реклама | E20: =P4 -> 27920.888 | F20: руб. | G20: ='Динамика финансы'!R76 -> 0.56864193 | I20: Реклама | K20: =P5 -> 2538.2625 | L20: руб. | M20: ='Динамика финансы'!R77 -> 0.32442005
C22: Возвраты | E22: =H4 -> -3051 | F22: руб. | G22: ='Динамика финансы'!J76 -> 0.058502071 | I22: Возвраты | K22: =H5 -> -5500 | L22: руб. | M22: ='Динамика финансы'!J77 -> 0.41278895
C23: Комиссия | E23: =L4 -> 21012.9 | F23: руб. | G23: ='Динамика финансы'!N76 -> 0.42795259 | I23: Комиссия | K23: =L5 -> 3639.32 | L23: руб. | M23: ='Динамика финансы'!N77 -> 0.46514826
E25: Маржинальность | G25: =Z4 -> -2.7480703 | K25: Маржинальность | M25: =Z5 -> -0.95935662
E26: Рентабельность | G26: =AA4 -> -0.23673668 | K26: Рентабельность | M26: =AA5 -> -0.1500834
E27: % себестоимости | G27: =Y4 -> 0.086146514 | K27: % себестоимости | M27: =Y5 -> 0.15644172
F29: На остатках товара на | H29: ='Юнит 17-23.11'!I51 -> 736264.3 | I29: руб.

Sheet Дашборд 10-16.11
B2: Период | E2: Дата поступления дс | F2: Итого к перечислению на счет, руб | G2: Выручка | J2: Себестоимость продаж | K2: Логистика | L2: Комиссия | M2: Хранение | N2: Платная приемка | O2: Штрафы | P2: Реклама Ozon | Q2: Прочее | R2: Доп. услуги | S2: Услуги FBO | T2: Компенсировано | U2: Прочие начисления | V2: Налог | W2: Итого | Y2: % Cебестоимости | Z2: Маржинальность, % | AA2: Рентабельность, % | AB2: Доля рекламы, %
B3: Месяц | C3: Даты | D3: Нед | G3: Продажи | H3: Возвраты | I3: Общая
C4: ='Динамика финансы'!B21 -> 10-16.11 очки | D4: ='Динамика финансы'!C21 -> 0 | E4: ='Динамика финансы'!D21 -> 0 | F4: ='Динамика финансы'!E21 -> -9966.6356 | G4: ='Динамика финансы'!I21 -> 40442 | H4: ='Динамика финансы'!J21 -> -1364 | I4: ='Динамика финансы'!K21 -> 39078 | J4: ='Динамика финансы'!L21 -> 3580.59 | K4: ='Динамика финансы'!M21 -> 2866.97 | L4: ='Динамика финансы'!N21 -> 16247.94 | M4: ='Динамика финансы'!O21 -> 0 | N4: ='Динамика финансы'!P21 -> 0 | ... W4: ='Динамика финансы'!Y21 -> -13938.006 | Y4: ='Динамика финансы'!AA21 -> 0.091626747 | Z4: ='Динамика финансы'!AB21 -> -3.8926561 | AA4: ='Динамика финансы'!AC21 -> -0.35667142 | AB4: ='Динамика финансы'!AD21 -> 0.63833041
C5: ='Динамика финансы'!B22 -> 10-16.11 туники | D5: ='Динамика финансы'!C22 -> 0 | E5: ='Динамика финансы'!D22 -> 0 | F5: ='Динамика финансы'!E22 -> 4952.2656 | G5: ='Динамика финансы'!I22 -> 25276 | H5: ='Динамика финансы'!J22 -> -5500 | I5: ='Динамика финансы'!K22 -> 19776 | J5: ='Динамика финансы'!L22 -> 2538 | K5: ='Динамика финансы'!M22 -> 1700.67 | L5: ='Динамика финансы'!N22 -> 8503.68 | M5: ='Динамика финансы'!O22 -> 0 | N5: ='Динамика финансы'!P22 -> 0 | ... W5: ='Динамика финансы'!Y22 -> 2216.5056 | Y5: ='Динамика финансы'!AA22 -> 0.12833738 | Z5: ='Динамика финансы'!AB22 -> 0.87332767 | AA5: ='Динамика финансы'!AC22 -> 0.11208058 | AB5: ='Динамика финансы'!AD22 -> 0.23358537
F8: =F4+F5+F6+F7 -> -5014.37 | G8: =G4+G5+G6+G7 -> 65718 | H8: =H4+H5+H6+H7 -> -6864 | I8: =I4+I5+I6+I7 -> 58854 | J8: =J4+J5+J6+J7 -> 6118.59 | K8: =K4+K5+K6+K7 -> 4567.64 | L8: =L4+L5+L6+L7 -> 24751.62 | M8: =M4+M5+M6+M7 -> 0 | ... W8: =W4+W5+W6+W7 -> -11721.5
C11: АНАЛИЗ ФИНАНСОВЫХ ПОКАЗАТЕЛЕЙ ЗА | G11: 10-16.11
C13: ОЧКИ | I13: ТУНИКИ
C15: Выручка | E15: =I4 -> 39078 | F15: руб. | G15: ='Динамика финансы'!K86 -> 1.7292918 | I15: Выручка | K15: =I5 -> 19776 | L15: руб. | M15: ='Динамика финансы'!K87 -> -0.015923567
C16: Прибыль | E16: =W4 -> -13938.006 | F16: руб. | G16: ='Динамика финансы'!Y86 -> -0.95433757 | I16: Прибыль | K16: =W5 -> 2216.5056 | L16: руб. | M16: ='Динамика финансы'!Y87 -> -8.2891945
C17: Себестоимость продаж | E17: =J4 -> 3580.59 | F17: руб. | G17: ='Динамика финансы'!L86 -> 1.5249207 | I17: Себестоимость продаж | K17: =J5 -> 2538 | L17: руб. | M17: ='Динамика финансы'!L87 -> -0.076419214
G18: % от выручки | M18: % от выручки
C19: Логистика | E19: =K4 -> 2866.97 | F19: руб. | G19: ='Динамика финансы'!M83 -> 0.073365321 | I19: Логистика | K19: =K5 -> 1700.67 | L19: руб. | M19: ='Динамика финансы'!M84 -> 0.085996663
C20: Реклама | E20: =P4 -> 24944.676 | F20: руб. | G20: ='Динамика финансы'!R83 -> 0.63833041 | I20: Реклама | K20: =P5 -> 4619.3844 | L20: руб. | M20: ='Динамика финансы'!R84 -> 0.23358537
C22: Возвраты | E22: =H4 -> -1364 | F22: руб. | G22: ='Динамика финансы'!J83 -> 0.033727313 | I22: Возвраты | K22: =H5 -> -5500 | L22: руб. | M22: ='Динамика финансы'!J84 -> 0.21759772
C23: Комиссия | E23: =L4 -> 16247.94 | F23: руб. | G23: ='Динамика финансы'!N83 -> 0.41578228 | I23: Комиссия | K23: =L5 -> 8503.68 | L23: руб. | M23: ='Динамика финансы'!N84 -> 0.43
E25: Маржинальность | G25: =Z4 -> -3.8926561 | K25: Маржинальность | M25: =Z5 -> 0.87332767
E26: Рентабельность | G26: =AA4 -> -0.35667142 | K26: Рентабельность | M26: =AA5 -> 0.11208058
E27: % себестоимости | G27: =Y4 -> 0.091626747 | K27: % себестоимости | M27: =Y5 -> 0.12833738
F29: На остатках товара на | H29: ='Юнит 10-16.11'!I51 -> 740327.11 | I29: руб.

Sheet Дашборд 03-09.11
