Workbook

Sheet Сводная
A1: Период | D1: Итого к перечислению на счет, руб | E1: шт. | H1: Выручка | K1: Себестоимость продаж | L1: Логистика | M1: Комиссия | N1: Хранение | O1: Платная приемка | P1: Штрафы | Q1: Реклама Ozon | R1: Другие услуги и штрафы | S1: Услуги агентов | T1: Услуги FBO | U1: Компенсировано | V1: Пополнение рекламного кабинета | W1: ЕАЭС | X1: Налог | Y1: Прибыль до вычета налогов | Z1: Прибыль после вычета налогов | AA1: Итог месяц | AB1: % Cебестоимости | AC1: Маржинальность, % | AD1: Рентабельность, % | AE1: Доля рекламы, % | AG1: Данные для построения диаграмм
A2: Месяц | B2: Даты | C2: Нед | E2: Заказы | F2: Продажи | G2: Возвраты | H2: Продажи | I2: Возвраты | J2: Общая | AG2: Нед | AH2: По магазину | AI2: По очкам | AJ2: По туникам
A3: Январь | B3: 01-04.01 очки | D3: =J3-SUM(L3:T3)+U3+V3 -> 6689.7486 | E3: ='Юнит 01-04.01'!K$26 -> 44 | F3: ='Юнит 01-04.01'!P$26 -> 28 | G3: ='Юнит 01-04.01'!Q$26 -> 0 | H3: ='Юнит 01-04.01'!S$26 -> 45978 | I3: ='Юнит 01-04.01'!T$26 -> 0 | J3: =H3+I3 -> 45978 | K3: ='Юнит 01-04.01'!W$26 -> 4528.66 | L3: ='Юнит 01-04.01'!Z$26 -> 3709.34 | M3: ='Юнит 01-04.01'!X$26 -> 19770.54 | Q3: ='Юнит 01-04.01'!AA$26 -> 14387.481 | S3: 808.39 | T3: 612.5 | W3: 2545 | X3: =2656.15*J3/SUM($J$3:$J$12) -> 193.86959 | Y3: =J3-SUM(L3:T3)-K3-V3+U3+W3 -> 4706.0886 | Z3: =Y3-X3 -> 4512.219 | AA3: =SUM(Z3:Z12) -> 53230.01 | AB3: =K3/J3 -> 0.098496237 | AC3: =Z3/K3 -> 0.99636957 | AD3: =Z3/J3 -> 0.098138654 | AE3: =Q3/J3 -> 0.31292099
B4: 01-04.01 туники | D4: =J4-SUM(L4:T4)+U4+V4+W4 -> 1720.7514 | E4: ='Юнит 01-04.01'!K$49 -> 5 | F4: ='Юнит 01-04.01'!P$49 -> 1 | G4: ='Юнит 01-04.01'!Q$49 -> 0 | H4: ='Юнит 01-04.01'!S$49 -> 4247 | I4: ='Юнит 01-04.01'!T$49 -> 0 | J4: =H4+I4 -> 4247 | K4: ='Юнит 01-04.01'!W$49 -> 597 | L4: ='Юнит 01-04.01'!Z$49 -> 186.2 | M4: ='Юнит 01-04.01'!X$49 -> 1826.21 | Q4: ='Юнит 01-04.01'!AA$49 -> 513.83862 | X4: =2656.15*J4/SUM($J$3:$J$12) -> 17.907785 | Y4: =J4-SUM(L4:T4)-K4-V4+U4+W4 -> 1123.7514 | Z4: =Y4-X4 -> 1105.8436 | AB4: =K4/J4 -> 0.14056981 | AC4: =Z4/K4 -> 1.8523343 | AD4: =Z4/J4 -> 0.26038229 | AE4: =Q4/J4 -> 0.12098861
B5: 05-11.01 очки | D5: =J5-SUM(L5:T5)+U5+V5+W5 -> 15120.024 | E5: ='Юнит 05-11.01'!K$26 -> 74 | F5: ='Юнит 05-11.01'!P$26 -> 58 | G5: ='Юнит 05-11.01'!Q$26 -> 4 | H5: ='Юнит 05-11.01'!S$26 -> 92160 | I5: ='Юнит 05-11.01'!T$26 -> -6799 | J5: =H5+I5 -> 85361 | K5: ='Юнит 05-11.01'!W$26 -> 7651.8 | L5: ='Юнит 05-11.01'!Z$26 -> 9950.27 | M5: ='Юнит 05-11.01'!X$26 -> 36705.23 | Q5: ='Юнит 05-11.01'!AA$26 -> 20346.216 | R5: 5 | S5: 1918.46 | T5: 1315.8 | X5: =2656.15*J5/SUM($J$3:$J$12) -> 359.93088 | Y5: =J5-SUM(L5:T5)-K5-V5+U5+W5 -> 7468.2237 | Z5: =Y5-X5 -> 7108.2928 | AB5: =K5/J5 -> 0.089640468 | AC5: =Z5/K5 -> 0.92897002 | AD5: =Z5/J5 -> 0.083273307 | AE5: =Q5/J5 -> 0.23835494
B6: 05-11.01 туники | D6: =J6-SUM(L6:T6)+U6+V6+W6 -> 4389.7863 | E6: ='Юнит 05-11.01'!K$49 -> 4 | F6: ='Юнит 05-11.01'!P$49 -> 2 | G6: ='Юнит 05-11.01'!Q$49 -> 0 | H6: ='Юнит 05-11.01'!S$49 -> 10524 | I6: ='Юнит 05-11.01'!T$49 -> 0 | J6: =H6+I6 -> 10524 | K6: ='Юнит 05-11.01'!W$49 -> 1329 | L6: ='Юнит 05-11.01'!Z$49 -> 907.3 | M6: ='Юнит 05-11.01'!X$49 -> 4525.32 | Q6: ='Юнит 05-11.01'!AA$49 -> 701.59367 | X6: =2656.15*J6/SUM($J$3:$J$12) -> 44.375213 | Y6: =J6-SUM(L6:T6)-K6-V6+U6+W6 -> 3060.7863 | Z6: =Y6-X6 -> 3016.4111 | AB6: =K6/J6 -> 0.12628278 | AC6: =Z6/K6 -> 2.2696848 | AD6: =Z6/J6 -> 0.28662211 | AE6: =Q6/J6 -> 0.066666065
B7: 12-18.01 очки | D7: =J7-SUM(L7:T7)+U7+V7+W7 -> 25837.298 | E7: ='Юнит 12-18.01'!K$26 -> 96 | F7: ='Юнит 12-18.01'!P$26 -> 56 | G7: ='Юнит 12-18.01'!Q$26 -> 0 | H7: ='Юнит 12-18.01'!S$26 -> 91762 | I7: ='Юнит 12-18.01'!T$26 -> 0 | J7: =H7+I7 -> 91762 | K7: ='Юнит 12-18.01'!W$26 -> 7841.91 | L7: ='Юнит 12-18.01'!Z$26 -> 9811.64 | M7: ='Юнит 12-18.01'!X$26 -> 39457.66 | Q7: ='Юнит 12-18.01'!AA$26 -> 22526.532 | S7: 2168.87 | T7: 800 | V7: 7000 | W7: 1840 | X7: =2656.15*J7/SUM($J$3:$J$12) -> 386.92116 | Y7: =J7-SUM(L7:T7)-K7-V7+U7+W7 -> 3995.3875 | Z7: =Y7-X7 -> 3608.4664 | AB7: =K7/J7 -> 0.085459231 | AC7: =Z7/K7 -> 0.46015147 | AD7: =Z7/J7 -> 0.039324191 | AE7: =Q7/J7 -> 0.24548868
B8: 12-18.01 туники | D8: =J8-SUM(L8:T8)+U8+V8+W8 -> 8441.1125 | E8: ='Юнит 12-18.01'!K$49 -> 30 | F8: ='Юнит 12-18.01'!P$49 -> 5 | G8: ='Юнит 12-18.01'!Q$49 -> 0 | H8: ='Юнит 12-18.01'!S$49 -> 21020 | I8: ='Юнит 12-18.01'!T$49 -> 0 | J8: =H8+I8 -> 21020 | K8: ='Юнит 12-18.01'!W$49 -> 3435 | L8: ='Юнит 12-18.01'!Z$49 -> 1528.99 | M8: ='Юнит 12-18.01'!X$49 -> 9038.6 | Q8: ='Юнит 12-18.01'!AA$49 -> 2011.2975 | X8: =2656.15*J8/SUM($J$3:$J$12) -> 88.632363 | Y8: =J8-SUM(L8:T8)-K8-V8+U8+W8 -> 5006.1125 | Z8: =Y8-X8 -> 4917.4801 | AB8: =K8/J8 -> 0.16341579 | AC8: =Z8/K8 -> 1.4315808 | AD8: =Z8/J8 -> 0.23394292 | AE8: =Q8/J8 -> 0.095684945
B9: 19-25.01 очки | D9: =J9-SUM(L9:T9)+U9+V9+W9 -> 15283.413 | E9: ='Юнит 19-25.01'!K$26 -> 119 | F9: ='Юнит 19-25.01'!P$26 -> 64 | G9: ='Юнит 19-25.01'!Q$26 -> 1 | H9: ='Юнит 19-25.01'!S$26 -> 104586 | I9: ='Юнит 19-25.01'!T$26 -> -1670 | J9: =H9+I9 -> 102916 | K9: ='Юнит 19-25.01'!W$26 -> 9494.98 | L9: ='Юнит 19-25.01'!Z$26 -> 12870.13 | M9: ='Юнит 19-25.01'!X$26 -> 44253.88 | Q9: ='Юнит 19-25.01'!AA$26 -> 31721.257 | R9: 15 | S9: 3536.42 | T9: 2235.9 | V9: 7000 | X9: =2656.15*J9/SUM($J$3:$J$12) -> 433.95282 | Y9: =J9-SUM(L9:T9)-K9-V9+U9+W9 -> -8211.5666 | Z9: =Y9-X9 -> -8645.5194 | AB9: =K9/J9 -> 0.092259513 | AC9: =Z9/K9 -> -0.91053582 | AD9: =Z9/J9 -> -0.084005591 | AE9: =Q9/J9 -> 0.30822473
B10: 19-25.01 туники | D10: =J10-SUM(L10:T10)+U10+V10+W10 -> 20301.697 | E10: ='Юнит 19-25.01'!K$49 -> 66 | F10: ='Юнит 19-25.01'!P$49 -> 18 | G10: ='Юнит 19-25.01'!Q$49 -> 4 | H10: ='Юнит 19-25.01'!S$49 -> 80413 | I10: ='Юнит 19-25.01'!T$49 -> -17932 | J10: =H10+I10 -> 62481 | K10: ='Юнит 19-25.01'!W$49 -> 9468 | L10: ='Юнит 19-25.01'!Z$49 -> 6390.87 | M10: ='Юнит 19-25.01'!X$49 -> 26866.83 | Q10: ='Юнит 19-25.01'!AA$49 -> 8921.6034 | X10: =2656.15*J10/SUM($J$3:$J$12) -> 263.45569 | Y10: =J10-SUM(L10:T10)-K10-V10+U10+W10 -> 10833.697 | Z10: =Y10-X10 -> 10570.241 | AB10: =K10/J10 -> 0.15153407 | AC10: =Z10/K10 -> 1.1164175 | AD10: =Z10/J10 -> 0.16917528 | AE10: =Q10/J10 -> 0.14278906
B11: 26-31.01 очки | D11: =J11-SUM(L11:T11)+U11+V11+W11 -> 17829.042 | E11: ='Юнит 26-31.01'!K$26 -> 100 | F11: ='Юнит 26-31.01'!P$26 -> 72 | G11: ='Юнит 26-31.01'!Q$26 -> 3 | H11: ='Юнит 26-31.01'!S$26 -> 120331 | I11: ='Юнит 26-31.01'!T$26 -> -4419 | J11: =H11+I11 -> 115912 | K11: ='Юнит 26-31.01'!W$26 -> 10470.94 | L11: ='Юнит 26-31.01'!Z$26 -> 13196.61 | M11: ='Юнит 26-31.01'!X$26 -> 49842.16 | Q11: ='Юнит 26-31.01'!AA$26 -> 25632.258 | R11: 25 | S11: 2141.43 | T11: 7245.5 | X11: =2656.15*J11/SUM($J$3:$J$12) -> 488.7514 | Y11: =J11-SUM(L11:T11)-K11-V11+U11+W11 -> 7358.1017 | Z11: =Y11-X11 -> 6869.3503 | AB11: =K11/J11 -> 0.090335254 | AC11: =Z11/K11 -> 0.65603951 | AD11: =Z11/J11 -> 0.059263496 | AE11: =Q11/J11 -> 0.2211355
B12: 26-31.01 туники | D12: =J12-SUM(L12:T12)+U12+V12+W12 -> 33880.578 | E12: ='Юнит 26-31.01'!K$49 -> 60 | F12: ='Юнит 26-31.01'!P$49 -> 20 | G12: ='Юнит 26-31.01'!Q$49 -> 0 | H12: ='Юнит 26-31.01'!S$49 -> 89730 | I12: ='Юнит 26-31.01'!T$49 -> 0 | J12: =H12+I12 -> 89730 | K12: ='Юнит 26-31.01'!W$49 -> 13335 | L12: ='Юнит 26-31.01'!Z$49 -> 8653.99 | M12: ='Юнит 26-31.01'!X$49 -> 38583.9 | Q12: ='Юнит 26-31.01'!AA$49 -> 7120.0717 | S12: 1491.46 | X12: =2656.15*J12/SUM($J$3:$J$12) -> 378.35309 | Y12: =J12-SUM(L12:T12)-K12-V12+U12+W12 -> 20545.578 | Z12: =Y12-X12 -> 20167.225 | AB12: =K12/J12 -> 0.1486125 | AC12: =Z12/K12 -> 1.5123528 | AD12: =Z12/J12 -> 0.22475454 | AE12: =Q12/J12 -> 0.079349958
A13: Февраль | B13: 01.02 очки | D13: =J13-SUM(L13:T13)+U13+V13 -> -2468.0211 | E13: ='Юнит 01.02'!K$26 -> 19 | F13: ='Юнит 01.02'!P$26 -> 8 | G13: ='Юнит 01.02'!Q$26 -> 1 | H13: ='Юнит 01.02'!S$26 -> 13169 | I13: ='Юнит 01.02'!T$26 -> -1655 | J13: =H13+I13 -> 11514 | K13: ='Юнит 01.02'!W$26 -> 1054.68 | L13: ='Юнит 01.02'!Z$26 -> 1614.84 | M13: ='Юнит 01.02'!X$26 -> 4951.02 | Q13: ='Юнит 01.02'!AA$26 -> 7028.3911 | S13: 387.77 | T13: 0 | W13: 902 | X13: ='Юнит 01.02'!AD26 -> 52.608637 | Y13: =J13-SUM(L13:T13)-K13-V13+U13+W13 -> -2620.7011 | Z13: =J13-SUM(L13:T13)-K13-X13+U13+W13-V13 -> -2673.3097 | AA13: =SUM(Z13:Z22) -> 104464.56 | AB13: =K13/J13 -> 0.091599792 | AC13: =Z13/K13 -> -2.5347117 | AD13: =Z13/J13 -> -0.23217906 | AE13: =Q13/J13 -> 0.61042132
B14: 01.02 туники | D14: =J14-SUM(L14:T14)+U14+V14+W14 -> 42.021111 | E14: ='Юнит 01.02'!K$49 -> 7 | F14: ='Юнит 01.02'!P$49 -> 1 | G14: ='Юнит 01.02'!Q$49 -> 0 | H14: ='Юнит 01.02'!S$49 -> 4940 | I14: ='Юнит 01.02'!T$49 -> 0 | J14: =H14+I14 -> 4940 | K14: ='Юнит 01.02'!W$49 -> 687 | L14: ='Юнит 01.02'!Z$49 -> 1483.67 | M14: ='Юнит 01.02'!X$49 -> 2124.2 | Q14: ='Юнит 01.02'!AA$49 -> 878.54889 | R14: 5 | S14: 406.56 | X14: ='Юнит 01.02'!AD49 -> 22.571363 | Y14: =J14-SUM(L14:T14)-K14-V14+U14+W14 -> -644.97889 | Z14: =J14-SUM(L14:T14)-K14-X14+U14+W14-V14 -> -667.55025 | AB14: =K14/J14 -> 0.13906883 | AC14: =Z14/K14 -> -0.97168887 | AD14: =Z14/J14 -> -0.13513163 | AE14: =Q14/J14 -> 0.1778439
B15: 02-08.02 очки | D15: =J15-SUM(L15:T15)+U15+V15 -> 11894.962 | E15: ='Юнит 02-08.02'!K$26 -> 131 | F15: ='Юнит 02-08.02'!P$26 -> 65 | G15: ='Юнит 02-08.02'!Q$26 -> 5 | H15: ='Юнит 02-08.02'!S$26 -> 119818 | I15: ='Юнит 02-08.02'!T$26 -> -9187 | J15: =H15+I15 -> 110631 | K15: ='Юнит 02-08.02'!W$26 -> 9043.72 | L15: ='Юнит 02-08.02'!Z$26 -> 13862.81 | M15: ='Юнит 02-08.02'!X$26 -> 47571.33 | Q15: ='Юнит 02-08.02'!AA$26 -> 34221.478 | S15: 3080.42 | T15: 0 | X15: ='Юнит 02-08.02'!AD26 -> 495.41892 | Y15: =J15-SUM(L15:T15)-K15-V15+U15+W15 -> 2851.2425 | Z15: =J15-SUM(L15:T15)-K15-X15+U15+W15-V15 -> 2355.8235 | AB15: =K15/J15 -> 0.081746708 | AC15: =Z15/K15 -> 0.26049276 | AD15: =Z15/J15 -> 0.021294425 | AE15: =Q15/J15 -> 0.30932991
B16: 02-08.02 туники | D16: =J16-SUM(L16:T16)+U16+V16+W16 -> 36220.938 | E16: ='Юнит 02-08.02'!K$49 -> 68 | F16: ='Юнит 02-08.02'!P$49 -> 24 | G16: ='Юнит 02-08.02'!Q$49 -> 1 | H16: ='Юнит 02-08.02'!S$49 -> 114048 | I16: ='Юнит 02-08.02'!T$49 -> -4178 | J16: =H16+I16 -> 109870 | K16: ='Юнит 02-08.02'!W$49 -> 14496 | L16: ='Юнит 02-08.02'!Z$49 -> 11481.36 | M16: ='Юнит 02-08.02'!X$49 -> 47244.1 | Q16: ='Юнит 02-08.02'!AA$49 -> 12635.622 | R16: 20 | S16: 2267.98 | T16: 0 | X16: ='Юнит 02-08.02'!AD49 -> 492.01108 | Y16: =J16-SUM(L16:T16)-K16-V16+U16+W16 -> 21724.938 | Z16: =J16-SUM(L16:T16)-K16-X16+U16+W16-V16 -> 21232.926 | AB16: =K16/J16 -> 0.13193774 | AC16: =Z16/K16 -> 1.4647438 | AD16: =Z16/J16 -> 0.193255 | AE16: =Q16/J16 -> 0.11500521
B17: 09-15.02 очки | D17: =J17-SUM(L17:T17)+U17+V17 -> 16731.718 | E17: ='Юнит 09-15.02'!K$26 -> 121 | F17: ='Юнит 09-15.02'!P$26 -> 60 | G17: ='Юнит 09-15.02'!Q$26 -> 2 | H17: ='Юнит 09-15.02'!S$26 -> 125456 | I17: ='Юнит 09-15.02'!T$26 -> -4877 | J17: =H17+I17 -> 120579 | K17: ='Юнит 09-15.02'!W$26 -> 7423.19 | L17: ='Юнит 09-15.02'!Z$26 -> 13659.9 | M17: ='Юнит 09-15.02'!X$26 -> 51848.97 | Q17: ='Юнит 09-15.02'!AA$26 -> 32650.368 | S17: 3309.41 | T17: =3250.8*F17/(F17+F18) -> 2378.6341 | X17: ='Юнит 09-15.02'!AD26 -> 529.24794 | Y17: =J17-SUM(L17:T17)-K17-V17+U17+W17 -> 9308.5276 | Z17: =J17-SUM(L17:T17)-K17-X17+U17+W17-V17 -> 8779.2796 | AB17: =K17/J17 -> 0.061562876 | AC17: =Z17/K17 -> 1.1826829 | AD17: =Z17/J17 -> 0.072809358 | AE17: =Q17/J17 -> 0.27077989
B18: 09-15.02 туники | D18: =J18-SUM(L18:T18)+U18+V18+W18 -> 34546.812 | E18: ='Юнит 09-15.02'!K$49 -> 54 | F18: ='Юнит 09-15.02'!P$49 -> 22 | G18: ='Юнит 09-15.02'!Q$49 -> 2 | H18: ='Юнит 09-15.02'!S$49 -> 110799 | I18: ='Юнит 09-15.02'!T$49 -> -9047 | J18: =H18+I18 -> 101752 | K18: ='Юнит 09-15.02'!W$49 -> 13275 | L18: ='Юнит 09-15.02'!Z$49 -> 8720.99 | M18: ='Юнит 09-15.02'!X$49 -> 43753.36 | Q18: ='Юнит 09-15.02'!AA$49 -> 11971.802 | R18: 25 | S18: 1861.87 | T18: =3250.8*F18/(F17+F18) -> 872.16585 | X18: ='Юнит 09-15.02'!AD49 -> 446.61206 | Y18: =J18-SUM(L18:T18)-K18-V18+U18+W18 -> 21271.812 | Z18: =J18-SUM(L18:T18)-K18-X18+U18+W18-V18 -> 20825.2 | AB18: =K18/J18 -> 0.13046427 | AC18: =Z18/K18 -> 1.5687533 | AD18: =Z18/J18 -> 0.20466625 | AE18: =Q18/J18 -> 0.11765667
B19: 16-22.02 очки | D19: =J19-SUM(L19:T19)+U19+V19 -> 31466.122 | E19: ='Юнит 16-22.02'!K$26 -> 172 | F19: ='Юнит 16-22.02'!P$26 -> 79 | G19: ='Юнит 16-22.02'!Q$26 -> 2 | H19: ='Юнит 16-22.02'!S$26 -> 173410 | I19: ='Юнит 16-22.02'!T$26 -> -4800 | J19: =H19+I19 -> 168610 | K19: ='Юнит 16-22.02'!W$26 -> 11163.54 | L19: ='Юнит 16-22.02'!Z$26 -> 17063.86 | M19: ='Юнит 16-22.02'!X$26 -> 72502.3 | Q19: ='Юнит 16-22.02'!AA$26 -> 43572.808 | S19: 4004.91 | T19: 0 | W19: 4158 | X19: ='Юнит 16-22.02'!AD$26 -> 745.37032 | Y19: =J19-SUM(L19:T19)-K19-V19+U19+W19 -> 24460.582 | Z19: =J19-SUM(L19:T19)-K19-X19+U19+W19-V19 -> 23715.212 | AB19: =K19/J19 -> 0.06620924 | AC19: =Z19/K19 -> 2.1243451 | AD19: =Z19/J19 -> 0.14065128 | AE19: =Q19/J19 -> 0.25842363
B20: 16-22.02 туники | D20: =J20-SUM(L20:T20)+U20+V20+W20 -> 46897.758 | E20: ='Юнит 16-22.02'!K$49 -> 78 | F20: ='Юнит 16-22.02'!P$49 -> 27 | G20: ='Юнит 16-22.02'!Q$49 -> 2 | H20: ='Юнит 16-22.02'!S$49 -> 141378 | I20: ='Юнит 16-22.02'!T$49 -> -10000 | J20: =H20+I20 -> 131378 | K20: ='Юнит 16-22.02'!W$49 -> 15420 | L20: ='Юнит 16-22.02'!Z$49 -> 10936.38 | M20: ='Юнит 16-22.02'!X$49 -> 56492.54 | Q20: ='Юнит 16-22.02'!AA$49 -> 14891.972 | R20: 20 | S20: 2139.35 | T20: 0 | X20: ='Юнит 16-22.02'!AD$49 -> 580.77968 | Y20: =J20-SUM(L20:T20)-K20-V20+U20+W20 -> 31477.758 | Z20: =J20-SUM(L20:T20)-K20-X20+U20+W20-V20 -> 30896.978 | AB20: =K20/J20 -> 0.11737125 | AC20: =Z20/K20 -> 2.0036951 | AD20: =Z20/J20 -> 0.23517619 | AE20: =Q20/J20 -> 0.1133521
B21: 23-28.02 очки | X21: ='Юнит 23-28.02'!AD26 -> #DIV/0!
B22: 23-28.02 туники | X22: ='Юнит 23-28.02'!AD49 -> #DIV/0!
A23: Итого | D23: =SUM(D3:D22) -> 324825.76 | E23: =SUM(E3:E22) -> 1248 | F23: =SUM(F3:F22) -> 610 | G23: =SUM(G3:G22) -> 27 | H23: =SUM(H3:H22) -> 1463769 | I23: =SUM(I3:I22) -> -74564 | J23: =SUM(J3:J22) -> 1389205 | K23: =SUM(K3:K22) -> 140715.42 | ... AA23: =SUM(AA3:AA22) -> 157694.57 | AB23: =K23/J23 -> 0.10129205 | AC23: =Z23/K23 -> 1.120663 | AD23: =Z23/J23 -> 0.11351425 | AE23: =Q23/J23 -> 0.21000006
H24: % от выручки за весь период
I25: =-I23/H23 -> 0.050939732 | J25: 0 | K25: =K23/$J$23 -> 0.10129205 | L25: =L23/$J$23 -> 0.10511706 | M25: =M23/$J$23 -> 0.43 | Q25: =Q23/$J$23 -> 0.21000006 | R25: =R23/$J$23 -> 8.2781159e-05 | S25: =S23/$J$23 -> 0.021251939 | T25: =T23/$J$23 -> 0.011129027 | U25: =U23/$J$23 -> 0 | V25: =V23/$J$23 -> 0.010077706 | X25: =X23/$J$23 -> #DIV/0! | Z25: =Z23/K23 -> 1.120663 | AA25: Маржинальность, %
A27: январь очки | D27: =D3+D5+D7+D9+D11 -> 80759.525 | E27: =E3+E5+E7+E9+E11 -> 433 | F27: =F3+F5+F7+F9+F11 -> 278 | G27: =G3+G5+G7+G9+G11 -> 8 | H27: =H3+H5+H7+H9+H11 -> 454817 | I27: =I3+I5+I7+I9+I11 -> -12888 | J27: =J3+J5+J7+J9+J11 -> 441929 | K27: =K3+K5+K7+K9+K11 -> 39988.29 | ... Z27: =Z3+Z5+Z7+Z9+Z11 -> 13452.809 | AA27: =Z23/J23 -> 0.11351425
A28: январь туники | D28: =D4+D6+D8+D10+D12 -> 68733.925 | E28: =E4+E6+E8+E10+E12 -> 165 | F28: =F4+F6+F8+F10+F12 -> 46 | G28: =G4+G6+G8+G10+G12 -> 4 | H28: =H4+H6+H8+H10+H12 -> 205934 | I28: =I4+I6+I8+I10+I12 -> -17932 | J28: =J4+J6+J8+J10+J12 -> 188002 | K28: =K4+K6+K8+K10+K12 -> 28164 | ... Z28: =Z4+Z6+Z8+Z10+Z12 -> 39777.201
A29: январь итого | D29: =D27+D28 -> 149493.45 | E29: =E27+E28 -> 598 | F29: =F27+F28 -> 324 | G29: =G27+G28 -> 12 | H29: =H27+H28 -> 660751 | I29: =I27+I28 -> -30820 | J29: =J27+J28 -> 629931 | K29: =K27+K28 -> 68152.29 | ... Z29: =Z27+Z28 -> 53230.01
A31: 5 неделя очки | K31: =(K11+K13)/($J$11+$J$13) -> 0.090449516 | L31: =(L11+L13)/($J$11+$J$13) -> 0.1162357 | M31: =(M11+M13)/($J$11+$J$13) -> 0.43 | N31: =(N11+N13)/($J$11+$J$13) -> 0 | O31: =(O11+O13)/($J$11+$J$13) -> 0 | P31: =(P11+P13)/($J$11+$J$13) -> 0 | Q31: =(Q11+Q13)/($J$11+$J$13) -> 0.25631072 | R31: =(R11+S11+T11+R13+S13+T13)/($J$11+$J$13) -> 0.076905027 | U31: =(U11+U13)/($J$11+$J$13) -> 0 | V31: =(V11+V13)/($J$11+$J$13) -> 0 | W31: =(W11+W13)/($J$11+$J$13) -> 0.0070786182 | X31: =(X11+X13)/($J$11+$J$13) -> 0.0042484268 | Y31: =(Y11+Y13)/($J$11+$J$13) -> 0.037177661 | Z31: =(Z11+Z13)/($J$11+$J$13) -> 0.032929234
A32: 6 неделя очки | K32: =K15/$J$15 -> 0.081746708 | L32: =L15/$J$15 -> 0.12530674 | M32: =M15/$J$15 -> 0.43 | Q32: =Q15/$J$15 -> 0.30932991 | R32: =(R15+S15+T15)/$J$15 -> 0.027844094 | U32: =U15/$J$15 -> 0 | V32: =V15/$J$15 -> 0 | X32: =X15/$J$15 -> 0.0044781203 | Z32: =Z15/K15 -> 0.26049276
A33: 7 неделя очки | K33: =K17/$J$17 -> 0.061562876 | L33: =L17/$J$17 -> 0.1132859 | M33: =M17/$J$17 -> 0.43 | Q33: =Q17/$J$17 -> 0.27077989 | R33: =(R17+S17+T17)/$J$17 -> 0.047172759 | U33: =U17/$J$17 -> 0 | V33: =V17/$J$17 -> 0 | X33: =X17/$J$17 -> 0.0043892215 | Z33: =Z17/K17 -> 1.1826829
A34: 8 неделя очки | K34: =K19/$J$19 -> 0.06620924 | L34: =L19/$J$19 -> 0.10120313 | M34: =M19/$J$19 -> 0.43 | Q34: =Q19/$J$19 -> 0.25842363 | R34: =(R19+S19+T19)/$J$19 -> 0.023752506 | U34: =U19/$J$19 -> 0 | V34: =V19/$J$19 -> 0 | X34: =X19/$J$19 -> 0.0044206768 | Z34: =Z19/K19 -> 2.1243451

Sheet АВС 16-22.02
B2: ОЧКИ
C3: Прибыль | D3: % прибыль | E3: Доля | F3: ABC прибыль | G3: ABC кол-во | J3: Кол-во | K3: % кол-во | L3: Доля | M3: ABC кол-во
B4: черные с железкой классика | D4: =C4/C$26 -> #DIV/0! | E4: =D4 -> #DIV/0! | F4: =IF(AND(E4<=0),"C",IF(E4<=0.8,"A",IF(E4<=0.95,"B","C"))) -> #DIV/0! | G4: =VLOOKUP(B$4:B$25,I$4:M$25,5,0) -> #DIV/0! | I4: черные с железкой классика | K4: =J4/J$26 -> #DIV/0! | L4: =K4 -> #DIV/0! | M4: =_xlfn.IFS(L4<80%,"A",L4<=95%,"B",L4>95%,"C") -> #DIV/0!
B5: qs черные | D5: =C5/C$26 -> #DIV/0! | E5: =D5+E4 -> #DIV/0! | F5: =IF(AND(E5<=0),"C",IF(E5<=0.8,"A",IF(E5<=0.95,"B","C"))) -> #DIV/0! | G5: =VLOOKUP(B$4:B$25,I$4:M$25,5,0) -> #DIV/0! | I5: qs черные | K5: =J5/J$26 -> #DIV/0! | L5: =K5+L4 -> #DIV/0! | M5: =_xlfn.IFS(L5<80%,"A",L5<=95%,"B",L5>95%,"C") -> #DIV/0!
B6: qs синие | D6: =C6/C$26 -> #DIV/0! | E6: =D6+E5 -> #DIV/0! | F6: =IF(AND(E6<=0),"C",IF(E6<=0.8,"A",IF(E6<=0.95,"B","C"))) -> #DIV/0! | G6: =VLOOKUP(B$4:B$25,I$4:M$25,5,0) -> #DIV/0! | I6: qs синие | K6: =J6/J$26 -> #DIV/0! | L6: =K6+L5 -> #DIV/0! | M6: =_xlfn.IFS(L6<80%,"A",L6<=95%,"B",L6>95%,"C") -> #DIV/0!
B7: qs желтые | D7: =C7/C$26 -> #DIV/0! | E7: =D7+E6 -> #DIV/0! | F7: =IF(AND(E7<=0),"C",IF(E7<=0.8,"A",IF(E7<=0.95,"B","C"))) -> #DIV/0! | G7: =VLOOKUP(B$4:B$25,I$4:M$25,5,0) -> #DIV/0! | I7: qs желтые | K7: =J7/J$26 -> #DIV/0! | L7: =K7+L6 -> #DIV/0! | M7: =_xlfn.IFS(L7<80%,"A",L7<=95%,"B",L7>95%,"C") -> #DIV/0!
B8: qs коричневые | D8: =C8/C$26 -> #DIV/0! | E8: =D8+E7 -> #DIV/0! | F8: =IF(AND(E8<=0),"C",IF(E8<=0.8,"A",IF(E8<=0.95,"B","C"))) -> #DIV/0! | G8: =VLOOKUP(B$4:B$25,I$4:M$25,5,0) -> #DIV/0! | I8: qs коричневые | K8: =J8/J$26 -> #DIV/0! | L8: =K8+L7 -> #DIV/0! | M8: =_xlfn.IFS(L8<80%,"A",L8<=95%,"B",L8>95%,"C") -> #DIV/0!
B9: th желтый Сул | D9: =C9/C$26 -> #DIV/0! | E9: =D9+E8 -> #DIV/0! | F9: =IF(AND(E9<=0),"C",IF(E9<=0.8,"A",IF(E9<=0.95,"B","C"))) -> #DIV/0! | G9: =VLOOKUP(B$4:B$25,I$4:M$25,5,0) -> #DIV/0! | I9: th желтый Сул | K9: =J9/J$26 -> #DIV/0! | L9: =K9+L8 -> #DIV/0! | M9: =_xlfn.IFS(L9<80%,"A",L9<=95%,"B",L9>95%,"C") -> #DIV/0!
B10: flip желтые Сул | D10: =C10/C$26 -> #DIV/0! | E10: =D10+E9 -> #DIV/0! | F10: =IF(AND(E10<=0),"C",IF(E10<=0.8,"A",IF(E10<=0.95,"B","C"))) -> #DIV/0! | G10: =VLOOKUP(B$4:B$25,I$4:M$25,5,0) -> #DIV/0! | I10: flip желтые Сул | K10: =J10/J$26 -> #DIV/0! | L10: =K10+L9 -> #DIV/0! | M10: =_xlfn.IFS(L10<80%,"A",L10<=95%,"B",L10>95%,"C") -> #DIV/0!
B11: MR8854 C2 | D11: =C11/C$26 -> #DIV/0! | E11: =D11+E8 -> #DIV/0! | F11: =IF(AND(E11<=0),"C",IF(E11<=0.8,"A",IF(E11<=0.95,"B","C"))) -> #DIV/0! | G11: =VLOOKUP(B$4:B$25,I$4:M$25,5,0) -> #DIV/0! | I11: MR8854 C2 | K11: =J11/J$26 -> #DIV/0! | L11: =K11+L8 -> #DIV/0! | M11: =_xlfn.IFS(L11<80%,"A",L11<=95%,"B",L11>95%,"C") -> #DIV/0!
B12: MR 1819 черн | D12: =C12/C$26 -> #DIV/0! | E12: =D12+E11 -> #DIV/0! | F12: =IF(AND(E12<=0),"C",IF(E12<=0.8,"A",IF(E12<=0.95,"B","C"))) -> #DIV/0! | G12: =VLOOKUP(B$4:B$25,I$4:M$25,5,0) -> #DIV/0! | I12: MR 1819 черн | K12: =J12/J$26 -> #DIV/0! | L12: =K12+L11 -> #DIV/0! | M12: =_xlfn.IFS(L12<80%,"A",L12<=95%,"B",L12>95%,"C") -> #DIV/0!
B13: MR 1819 корич | D13: =C13/C$26 -> #DIV/0! | E13: =D13+E12 -> #DIV/0! | F13: =IF(AND(E13<=0),"C",IF(E13<=0.8,"A",IF(E13<=0.95,"B","C"))) -> #DIV/0! | G13: =VLOOKUP(B$4:B$25,I$4:M$25,5,0) -> #DIV/0! | I13: MR 1819 корич | K13: =J13/J$26 -> #DIV/0! | L13: =K13+L12 -> #DIV/0! | M13: =_xlfn.IFS(L13<80%,"A",L13<=95%,"B",L13>95%,"C") -> #DIV/0! | P13: A | Q13: 0.8
B14: MR Р1874 черн | D14: =C14/C$26 -> #DIV/0! | E14: =D14+E13 -> #DIV/0! | F14: =IF(AND(E14<=0),"C",IF(E14<=0.8,"A",IF(E14<=0.95,"B","C"))) -> #DIV/0! | G14: =VLOOKUP(B$4:B$25,I$4:M$25,5,0) -> #DIV/0! | I14: MR Р1874 черн | K14: =J14/J$26 -> #DIV/0! | L14: =K14+L13 -> #DIV/0! | M14: =_xlfn.IFS(L14<80%,"A",L14<=95%,"B",L14>95%,"C") -> #DIV/0! | P14: B | Q14: 0.15
B15: MR Р1874 корич | D15: =C15/C$26 -> #DIV/0! | E15: =D15+E14 -> #DIV/0! | F15: =IF(AND(E15<=0),"C",IF(E15<=0.8,"A",IF(E15<=0.95,"B","C"))) -> #DIV/0! | G15: =VLOOKUP(B$4:B$25,I$4:M$25,5,0) -> #DIV/0! | I15: MR Р1874 корич | K15: =J15/J$26 -> #DIV/0! | L15: =K15+L14 -> #DIV/0! | M15: =_xlfn.IFS(L15<80%,"A",L15<=95%,"B",L15>95%,"C") -> #DIV/0! | P15: C | Q15: 0.05
B16: MR Р1886 черн глянец | D16: =C16/C$26 -> #DIV/0! | E16: =D16+E15 -> #DIV/0! | F16: =IF(AND(E16<=0),"C",IF(E16<=0.8,"A",IF(E16<=0.95,"B","C"))) -> #DIV/0! | G16: =VLOOKUP(B$4:B$25,I$4:M$25,5,0) -> #DIV/0! | I16: MR Р1886 черн глянец | K16: =J16/J$26 -> #DIV/0! | L16: =K16+L15 -> #DIV/0! | M16: =_xlfn.IFS(L16<80%,"A",L16<=95%,"B",L16>95%,"C") -> #DIV/0!
B17: MR Р1886 корич | D17: =C17/C$26 -> #DIV/0! | E17: =D17+E16 -> #DIV/0! | F17: =IF(AND(E17<=0),"C",IF(E17<=0.8,"A",IF(E17<=0.95,"B","C"))) -> #DIV/0! | G17: =VLOOKUP(B$4:B$25,I$4:M$25,5,0) -> #DIV/0! | I17: MR Р1886 корич | K17: =J17/J$26 -> #DIV/0! | L17: =K17+L16 -> #DIV/0! | M17: =_xlfn.IFS(L17<80%,"A",L17<=95%,"B",L17>95%,"C") -> #DIV/0!
B18: lux1 | D18: =C18/C$26 -> #DIV/0! | E18: =D18+E17 -> #DIV/0! | F18: =IF(AND(E18<=0),"C",IF(E18<=0.8,"A",IF(E18<=0.95,"B","C"))) -> #DIV/0! | G18: =VLOOKUP(B$4:B$25,I$4:M$25,5,0) -> #DIV/0! | I18: lux1 | K18: =J18/J$26 -> #DIV/0! | L18: =K18+L17 -> #DIV/0! | M18: =_xlfn.IFS(L18<80%,"A",L18<=95%,"B",L18>95%,"C") -> #DIV/0!
B19: lux2 | D19: =C19/C$26 -> #DIV/0! | E19: =D19+E18 -> #DIV/0! | F19: =IF(AND(E19<=0),"C",IF(E19<=0.8,"A",IF(E19<=0.95,"B","C"))) -> #DIV/0! | G19: =VLOOKUP(B$4:B$25,I$4:M$25,5,0) -> #DIV/0! | I19: lux2 | K19: =J19/J$26 -> #DIV/0! | L19: =K19+L18 -> #DIV/0! | M19: =_xlfn.IFS(L19<80%,"A",L19<=95%,"B",L19>95%,"C") -> #DIV/0!
B20: lux3 | D20: =C20/C$26 -> #DIV/0! | E20: =D20+E19 -> #DIV/0! | F20: =IF(AND(E20<=0),"C",IF(E20<=0.8,"A",IF(E20<=0.95,"B","C"))) -> #DIV/0! | G20: =VLOOKUP(B$4:B$25,I$4:M$25,5,0) -> #DIV/0! | I20: lux3 | K20: =J20/J$26 -> #DIV/0! | L20: =K20+L19 -> #DIV/0! | M20: =_xlfn.IFS(L20<80%,"A",L20<=95%,"B",L20>95%,"C") -> #DIV/0!
B21: lux4 | D21: =C21/C$26 -> #DIV/0! | E21: =D21+E20 -> #DIV/0! | F21: =IF(AND(E21<=0),"C",IF(E21<=0.8,"A",IF(E21<=0.95,"B","C"))) -> #DIV/0! | G21: =VLOOKUP(B$4:B$25,I$4:M$25,5,0) -> #DIV/0! | I21: lux4 | K21: =J21/J$26 -> #DIV/0! | L21: =K21+L20 -> #DIV/0! | M21: =_xlfn.IFS(L21<80%,"A",L21<=95%,"B",L21>95%,"C") -> #DIV/0!
B22: lux5 | D22: =C22/C$26 -> #DIV/0! | E22: =D22+E21 -> #DIV/0! | F22: =IF(AND(E22<=0),"C",IF(E22<=0.8,"A",IF(E22<=0.95,"B","C"))) -> #DIV/0! | G22: =VLOOKUP(B$4:B$25,I$4:M$25,5,0) -> #DIV/0! | I22: lux5 | K22: =J22/J$26 -> #DIV/0! | L22: =K22+L21 -> #DIV/0! | M22: =_xlfn.IFS(L22<80%,"A",L22<=95%,"B",L22>95%,"C") -> #DIV/0!
B23: lux6 | D23: =C23/C$26 -> #DIV/0! | E23: =D23+E22 -> #DIV/0! | F23: =IF(AND(E23<=0),"C",IF(E23<=0.8,"A",IF(E23<=0.95,"B","C"))) -> #DIV/0! | G23: =VLOOKUP(B$4:B$25,I$4:M$25,5,0) -> #DIV/0! | I23: lux6 | K23: =J23/J$26 -> #DIV/0! | L23: =K23+L22 -> #DIV/0! | M23: =_xlfn.IFS(L23<80%,"A",L23<=95%,"B",L23>95%,"C") -> #DIV/0!
B24: lux7 | D24: =C24/C$26 -> #DIV/0! | E24: =D24+E23 -> #DIV/0! | F24: =IF(AND(E24<=0),"C",IF(E24<=0.8,"A",IF(E24<=0.95,"B","C"))) -> #DIV/0! | G24: =VLOOKUP(B$4:B$25,I$4:M$25,5,0) -> #DIV/0! | I24: lux7 | K24: =J24/J$26 -> #DIV/0! | L24: =K24+L23 -> #DIV/0! | M24: =_xlfn.IFS(L24<80%,"A",L24<=95%,"B",L24>95%,"C") -> #DIV/0!
B25: lux8 | D25: =C25/C$26 -> #DIV/0! | E25: =D25+E24 -> #DIV/0! | F25: =IF(AND(E25<=0),"C",IF(E25<=0.8,"A",IF(E25<=0.95,"B","C"))) -> #DIV/0! | G25: =VLOOKUP(B$4:B$25,I$4:M$25,5,0) -> #DIV/0! | I25: lux8 | K25: =J25/J$26 -> #DIV/0! | L25: =K25+L24 -> #DIV/0! | M25: =_xlfn.IFS(L25<80%,"A",L25<=95%,"B",L25>95%,"C") -> #DIV/0!
C26: =SUM(C4:C25) -> 0 | D26: =SUM(D4:D25) -> #DIV/0! | J26: =SUM(J4:J25) -> 0 | K26: =SUM(K4:K25) -> #DIV/0!
B28: ТУНИКИ
C29: Прибыль | D29: % прибыль | E29: Доля | F29: ABC прибыль | G29: ABC кол-во | J29: Кол-во | K29: % кол-во | L29: Доля | M29: ABC кол-во
B30: tunika02 оливковая с руч вышивкой | D30: =C30/C$50 -> #DIV/0! | E30: =D30 -> #DIV/0! | F30: =IF(AND(E30<=0),"C",IF(E30<=0.8,"A",IF(E30<=0.95,"B","C"))) -> #DIV/0! | G30: =VLOOKUP(B$30:B$50,I$30:M$50,5,0) -> #DIV/0! | I30: tunika02 оливковая с руч вышивкой | K30: =J30/J$50 -> #DIV/0! | L30: =K30 -> #DIV/0! | M30: =_xlfn.IFS(L30<80%,"A",L30<=95%,"B",L30>95%,"C") -> #DIV/0!
B31: tunika03 черная распашная | D31: =C31/C$50 -> #DIV/0! | E31: =D31+E30 -> #DIV/0! | F31: =IF(AND(E31<=0),"C",IF(E31<=0.8,"A",IF(E31<=0.95,"B","C"))) -> #DIV/0! | G31: =VLOOKUP(B$30:B$50,I$30:M$50,5,0) -> #DIV/0! | I31: tunika03 черная распашная | K31: =J31/J$50 -> #DIV/0! | L31: =K31+L30 -> #DIV/0! | M31: =_xlfn.IFS(L31<80%,"A",L31<=95%,"B",L31>95%,"C") -> #DIV/0!
B32: tunika05 белая распашная | D32: =C32/C$50 -> #DIV/0! | E32: =D32+E31 -> #DIV/0! | F32: =IF(AND(E32<=0),"C",IF(E32<=0.8,"A",IF(E32<=0.95,"B","C"))) -> #DIV/0! | G32: =VLOOKUP(B$30:B$50,I$30:M$50,5,0) -> #DIV/0! | I32: tunika05 белая распашная | K32: =J32/J$50 -> #DIV/0! | L32: =K32+L31 -> #DIV/0! | M32: =_xlfn.IFS(L32<80%,"A",L32<=95%,"B",L32>95%,"C") -> #DIV/0!
B33: tunika06 белая | D33: =C33/C$50 -> #DIV/0! | E33: =D33+E32 -> #DIV/0! | F33: =IF(AND(E33<=0),"C",IF(E33<=0.8,"A",IF(E33<=0.95,"B","C"))) -> #DIV/0! | G33: =VLOOKUP(B$30:B$50,I$30:M$50,5,0) -> #DIV/0! | I33: tunika06 белая | K33: =J33/J$50 -> #DIV/0! | L33: =K33+L32 -> #DIV/0! | M33: =_xlfn.IFS(L33<80%,"A",L33<=95%,"B",L33>95%,"C") -> #DIV/0!
B34: tunika06 черная | D34: =C34/C$50 -> #DIV/0! | E34: =D34+E33 -> #DIV/0! | F34: =IF(AND(E34<=0),"C",IF(E34<=0.8,"A",IF(E34<=0.95,"B","C"))) -> #DIV/0! | G34: =VLOOKUP(B$30:B$50,I$30:M$50,5,0) -> #DIV/0! | I34: tunika06 черная | K34: =J34/J$50 -> #DIV/0! | L34: =K34+L33 -> #DIV/0! | M34: =_xlfn.IFS(L34<80%,"A",L34<=95%,"B",L34>95%,"C") -> #DIV/0!
B35: tunika07 кружево | D35: =C35/C$50 -> #DIV/0! | E35: =D35+E34 -> #DIV/0! | F35: =IF(AND(E35<=0),"C",IF(E35<=0.8,"A",IF(E35<=0.95,"B","C"))) -> #DIV/0! | G35: =VLOOKUP(B$30:B$50,I$30:M$50,5,0) -> #DIV/0! | I35: tunika07 кружево | K35: =J35/J$50 -> #DIV/0! | L35: =K35+L34 -> #DIV/0! | M35: =_xlfn.IFS(L35<80%,"A",L35<=95%,"B",L35>95%,"C") -> #DIV/0!
B36: tunika08 белая | D36: =C36/C$50 -> #DIV/0! | E36: =D36+E35 -> #DIV/0! | F36: =IF(AND(E36<=0),"C",IF(E36<=0.8,"A",IF(E36<=0.95,"B","C"))) -> #DIV/0! | G36: =VLOOKUP(B$30:B$50,I$30:M$50,5,0) -> #DIV/0! | I36: tunika08 белая | K36: =J36/J$50 -> #DIV/0! | L36: =K36+L35 -> #DIV/0! | M36: =_xlfn.IFS(L36<80%,"A",L36<=95%,"B",L36>95%,"C") -> #DIV/0!
B37: tunika08 черная | D37: =C37/C$50 -> #DIV/0! | E37: =D37+E36 -> #DIV/0! | F37: =IF(AND(E37<=0),"C",IF(E37<=0.8,"A",IF(E37<=0.95,"B","C"))) -> #DIV/0! | G37: =VLOOKUP(B$30:B$50,I$30:M$50,5,0) -> #DIV/0! | I37: tunika08 черная | K37: =J37/J$50 -> #DIV/0! | L37: =K37+L36 -> #DIV/0! | M37: =_xlfn.IFS(L37<80%,"A",L37<=95%,"B",L37>95%,"C") -> #DIV/0!
B38: tunika08 зеленая | D38: =C38/C$50 -> #DIV/0! | E38: =D38+E37 -> #DIV/0! | F38: =IF(AND(E38<=0),"C",IF(E38<=0.8,"A",IF(E38<=0.95,"B","C"))) -> #DIV/0! | G38: =VLOOKUP(B$30:B$50,I$30:M$50,5,0) -> #DIV/0! | I38: tunika08 зеленая | K38: =J38/J$50 -> #DIV/0! | L38: =K38+L37 -> #DIV/0! | M38: =_xlfn.IFS(L38<80%,"A",L38<=95%,"B",L38>95%,"C") -> #DIV/0!
B39: tunika09 кимоно | D39: =C39/C$50 -> #DIV/0! | E39: =D39+E38 -> #DIV/0! | F39: =IF(AND(E39<=0),"C",IF(E39<=0.8,"A",IF(E39<=0.95,"B","C"))) -> #DIV/0! | G39: =VLOOKUP(B$30:B$50,I$30:M$50,5,0) -> #DIV/0! | I39: tunika09 кимоно | K39: =J39/J$50 -> #DIV/0! | L39: =K39+L38 -> #DIV/0! | M39: =_xlfn.IFS(L39<80%,"A",L39<=95%,"B",L39>95%,"C") -> #DIV/0!
B40: tunika10 кимоно ч/б | D40: =C40/C$50 -> #DIV/0! | E40: =D40+E39 -> #DIV/0! | F40: =IF(AND(E40<=0),"C",IF(E40<=0.8,"A",IF(E40<=0.95,"B","C"))) -> #DIV/0! | G40: =VLOOKUP(B$30:B$50,I$30:M$50,5,0) -> #DIV/0! | I40: tunika10 кимоно ч/б | K40: =J40/J$50 -> #DIV/0! | L40: =K40+L39 -> #DIV/0! | M40: =_xlfn.IFS(L40<80%,"A",L40<=95%,"B",L40>95%,"C") -> #DIV/0!
B41: tunika11 халат зеленая | D41: =C41/C$50 -> #DIV/0! | E41: =D41+E40 -> #DIV/0! | F41: =IF(AND(E41<=0),"C",IF(E41<=0.8,"A",IF(E41<=0.95,"B","C"))) -> #DIV/0! | G41: =VLOOKUP(B$30:B$50,I$30:M$50,5,0) -> #DIV/0! | I41: tunika11 халат зеленая | K41: =J41/J$50 -> #DIV/0! | L41: =K41+L40 -> #DIV/0! | M41: =_xlfn.IFS(L41<80%,"A",L41<=95%,"B",L41>95%,"C") -> #DIV/0!
B42: tunika12 халат белая | D42: =C42/C$50 -> #DIV/0! | E42: =D42+E41 -> #DIV/0! | F42: =IF(AND(E42<=0),"C",IF(E42<=0.8,"A",IF(E42<=0.95,"B","C"))) -> #DIV/0! | G42: =VLOOKUP(B$30:B$50,I$30:M$50,5,0) -> #DIV/0! | I42: tunika12 халат белая | K42: =J42/J$50 -> #DIV/0! | L42: =K42+L41 -> #DIV/0! | M42: =_xlfn.IFS(L42<80%,"A",L42<=95%,"B",L42>95%,"C") -> #DIV/0!
...

Sheet АВС 09-15.02
B2: ОЧКИ
C3: Прибыль | D3: % прибыль | E3: Доля | F3: ABC прибыль | G3: ABC кол-во | J3: Кол-во | K3: % кол-во | L3: Доля | M3: ABC кол-во
B4: черные с железкой классика | C4: ='Юнит 09-15.02'!AE3 -> 18261.877 | D4: =C4/C$26 -> 0.9050678 | E4: =D4 -> 0.9050678 | F4: =IF(AND(E4<=0),"C",IF(E4<=0.8,"A",IF(E4<=0.95,"B","C"))) -> B | G4: =VLOOKUP(B$4:B$25,I$4:M$25,5,0) -> A | I4: черные с железкой классика | J4: ='Юнит 09-15.02'!R3 -> 40 | K4: =J4/J$26 -> 0.68965517 | L4: =K4 -> 0.68965517 | M4: =_xlfn.IFS(L4<80%,"A",L4<=95%,"B",L4>95%,"C") -> A
B5: qs коричневые | C5: ='Юнит 09-15.02'!AE7 -> 2261.0319 | D5: =C5/C$26 -> 0.11205787 | E5: =D5+E4 -> 1.0171257 | F5: =IF(AND(E5<=0),"C",IF(E5<=0.8,"A",IF(E5<=0.95,"B","C"))) -> C | G5: =VLOOKUP(B$4:B$25,I$4:M$25,5,0) -> A | I5: qs коричневые | J5: ='Юнит 09-15.02'!R7 -> 5 | K5: =J5/J$26 -> 0.086206897 | L5: =K5+L4 -> 0.77586207 | M5: =_xlfn.IFS(L5<80%,"A",L5<=95%,"B",L5>95%,"C") -> A
B6: flip желтые Сул | C6: ='Юнит 09-15.02'!AE9 -> 1236.572 | D6: =C6/C$26 -> 0.061285126 | E6: =D6+E5 -> 1.0784108 | F6: =IF(AND(E6<=0),"C",IF(E6<=0.8,"A",IF(E6<=0.95,"B","C"))) -> C | G6: =VLOOKUP(B$4:B$25,I$4:M$25,5,0) -> B | I6: flip желтые Сул | J6: ='Юнит 09-15.02'!R9 -> 5 | K6: =J6/J$26 -> 0.086206897 | L6: =K6+L5 -> 0.86206897 | M6: =_xlfn.IFS(L6<80%,"A",L6<=95%,"B",L6>95%,"C") -> B
B7: qs черные | C7: ='Юнит 09-15.02'!AE4 -> 873.30156 | D7: =C7/C$26 -> 0.043281263 | E7: =D7+E6 -> 1.1216921 | F7: =IF(AND(E7<=0),"C",IF(E7<=0.8,"A",IF(E7<=0.95,"B","C"))) -> C | G7: =VLOOKUP(B$4:B$25,I$4:M$25,5,0) -> B | I7: MR8854 C2 | J7: ='Юнит 09-15.02'!R10 -> 4 | K7: =J7/J$26 -> 0.068965517 | L7: =K7+L6 -> 0.93103448 | M7: =_xlfn.IFS(L7<80%,"A",L7<=95%,"B",L7>95%,"C") -> B
B8: MR8854 C2 | C8: ='Юнит 09-15.02'!AE10 -> 827.0756 | D8: =C8/C$26 -> 0.040990281 | E8: =D8+E7 -> 1.1626823 | F8: =IF(AND(E8<=0),"C",IF(E8<=0.8,"A",IF(E8<=0.95,"B","C"))) -> C | G8: =VLOOKUP(B$4:B$25,I$4:M$25,5,0) -> B | I8: qs черные | J8: ='Юнит 09-15.02'!R4 -> 1 | K8: =J8/J$26 -> 0.017241379 | L8: =K8+L7 -> 0.94827586 | M8: =_xlfn.IFS(L8<80%,"A",L8<=95%,"B",L8>95%,"C") -> B
B9: MR 1819 корич | C9: ='Юнит 09-15.02'!AE12 -> 329.21308 | D9: =C9/C$26 -> 0.016315965 | E9: =D9+E8 -> 1.1789983 | F9: =IF(AND(E9<=0),"C",IF(E9<=0.8,"A",IF(E9<=0.95,"B","C"))) -> C | G9: =VLOOKUP(B$4:B$25,I$4:M$25,5,0) -> C | I9: qs синие | J9: ='Юнит 09-15.02'!R5 -> 1 | K9: =J9/J$26 -> 0.017241379 | L9: =K9+L8 -> 0.96551724 | M9: =_xlfn.IFS(L9<80%,"A",L9<=95%,"B",L9>95%,"C") -> C
B10: qs синие | C10: ='Юнит 09-15.02'!AE5 -> 310.95156 | D10: =C10/C$26 -> 0.015410915 | E10: =D10+E9 -> 1.1944092 | F10: =IF(AND(E10<=0),"C",IF(E10<=0.8,"A",IF(E10<=0.95,"B","C"))) -> C | G10: =VLOOKUP(B$4:B$25,I$4:M$25,5,0) -> C | I10: MR 1819 корич | J10: ='Юнит 09-15.02'!R12 -> 1 | K10: =J10/J$26 -> 0.017241379 | L10: =K10+L9 -> 0.98275862 | M10: =_xlfn.IFS(L10<80%,"A",L10<=95%,"B",L10>95%,"C") -> C
B11: MR Р1874 черн | C11: ='Юнит 09-15.02'!AE13 -> 142.4794 | D11: =C11/C$26 -> 0.0070613505 | E11: =D11+E8 -> 1.1697437 | F11: =IF(AND(E11<=0),"C",IF(E11<=0.8,"A",IF(E11<=0.95,"B","C"))) -> C | G11: =VLOOKUP(B$4:B$25,I$4:M$25,5,0) -> C | I11: MR Р1874 черн | J11: ='Юнит 09-15.02'!R13 -> 1 | K11: =J11/J$26 -> 0.017241379 | L11: =K11+L8 -> 0.96551724 | M11: =_xlfn.IFS(L11<80%,"A",L11<=95%,"B",L11>95%,"C") -> C
B12: lux1 | C12: ='Юнит 09-15.02'!AE17 -> 0 | D12: =C12/C$26 -> 0 | E12: =D12+E11 -> 1.1697437 | F12: =IF(AND(E12<=0),"C",IF(E12<=0.8,"A",IF(E12<=0.95,"B","C"))) -> C | G12: =VLOOKUP(B$4:B$25,I$4:M$25,5,0) -> C | I12: MR Р1886 черн глянец | J12: ='Юнит 09-15.02'!R15 -> 1 | K12: =J12/J$26 -> 0.017241379 | L12: =K12+L11 -> 0.98275862 | M12: =_xlfn.IFS(L12<80%,"A",L12<=95%,"B",L12>95%,"C") -> C
B13: lux2 | C13: ='Юнит 09-15.02'!AE18 -> 0 | D13: =C13/C$26 -> 0 | E13: =D13+E12 -> 1.1697437 | F13: =IF(AND(E13<=0),"C",IF(E13<=0.8,"A",IF(E13<=0.95,"B","C"))) -> C | G13: =VLOOKUP(B$4:B$25,I$4:M$25,5,0) -> C | I13: qs желтые | J13: ='Юнит 09-15.02'!R6 -> 0 | K13: =J13/J$26 -> 0 | L13: =K13+L12 -> 0.98275862 | M13: =_xlfn.IFS(L13<80%,"A",L13<=95%,"B",L13>95%,"C") -> C | P13: A | Q13: 0.8
B14: lux3 | C14: ='Юнит 09-15.02'!AE19 -> 0 | D14: =C14/C$26 -> 0 | E14: =D14+E13 -> 1.1697437 | F14: =IF(AND(E14<=0),"C",IF(E14<=0.8,"A",IF(E14<=0.95,"B","C"))) -> C | G14: =VLOOKUP(B$4:B$25,I$4:M$25,5,0) -> C | I14: th желтый Сул | J14: ='Юнит 09-15.02'!R8 -> 0 | K14: =J14/J$26 -> 0 | L14: =K14+L13 -> 0.98275862 | M14: =_xlfn.IFS(L14<80%,"A",L14<=95%,"B",L14>95%,"C") -> C | P14: B | Q14: 0.15
B15: lux5 | C15: ='Юнит 09-15.02'!AE21 -> 0 | D15: =C15/C$26 -> 0 | E15: =D15+E14 -> 1.1697437 | F15: =IF(AND(E15<=0),"C",IF(E15<=0.8,"A",IF(E15<=0.95,"B","C"))) -> C | G15: =VLOOKUP(B$4:B$25,I$4:M$25,5,0) -> C | I15: MR 1819 черн | J15: ='Юнит 09-15.02'!R11 -> 0 | K15: =J15/J$26 -> 0 | L15: =K15+L14 -> 0.98275862 | M15: =_xlfn.IFS(L15<80%,"A",L15<=95%,"B",L15>95%,"C") -> C | P15: C | Q15: 0.05
B16: lux6 | C16: ='Юнит 09-15.02'!AE22 -> 0 | D16: =C16/C$26 -> 0 | E16: =D16+E15 -> 1.1697437 | F16: =IF(AND(E16<=0),"C",IF(E16<=0.8,"A",IF(E16<=0.95,"B","C"))) -> C | G16: =VLOOKUP(B$4:B$25,I$4:M$25,5,0) -> C | I16: MR Р1874 корич | J16: ='Юнит 09-15.02'!R14 -> 0 | K16: =J16/J$26 -> 0 | L16: =K16+L15 -> 0.98275862 | M16: =_xlfn.IFS(L16<80%,"A",L16<=95%,"B",L16>95%,"C") -> C
B17: lux7 | C17: ='Юнит 09-15.02'!AE23 -> 0 | D17: =C17/C$26 -> 0 | E17: =D17+E16 -> 1.1697437 | F17: =IF(AND(E17<=0),"C",IF(E17<=0.8,"A",IF(E17<=0.95,"B","C"))) -> C | G17: =VLOOKUP(B$4:B$25,I$4:M$25,5,0) -> C | I17: MR Р1886 корич | J17: ='Юнит 09-15.02'!R16 -> 0 | K17: =J17/J$26 -> 0 | L17: =K17+L16 -> 0.98275862 | M17: =_xlfn.IFS(L17<80%,"A",L17<=95%,"B",L17>95%,"C") -> C
B18: lux8 | C18: ='Юнит 09-15.02'!AE24 -> 0 | D18: =C18/C$26 -> 0 | E18: =D18+E17 -> 1.1697437 | F18: =IF(AND(E18<=0),"C",IF(E18<=0.8,"A",IF(E18<=0.95,"B","C"))) -> C | G18: =VLOOKUP(B$4:B$25,I$4:M$25,5,0) -> C | I18: lux1 | J18: ='Юнит 09-15.02'!R17 -> 0 | K18: =J18/J$26 -> 0 | L18: =K18+L17 -> 0.98275862 | M18: =_xlfn.IFS(L18<80%,"A",L18<=95%,"B",L18>95%,"C") -> C
B19: MR Р1886 черн глянец | C19: ='Юнит 09-15.02'!AE15 -> -119.58737 | D19: =C19/C$26 -> -0.0059268098 | E19: =D19+E18 -> 1.1638169 | F19: =IF(AND(E19<=0),"C",IF(E19<=0.8,"A",IF(E19<=0.95,"B","C"))) -> C | G19: =VLOOKUP(B$4:B$25,I$4:M$25,5,0) -> C | I19: lux2 | J19: ='Юнит 09-15.02'!R18 -> 0 | K19: =J19/J$26 -> 0 | L19: =K19+L18 -> 0.98275862 | M19: =_xlfn.IFS(L19<80%,"A",L19<=95%,"B",L19>95%,"C") -> C
B20: MR 1819 черн | C20: ='Юнит 09-15.02'!AE11 -> -187.08 | D20: =C20/C$26 -> -0.0092717786 | E20: =D20+E19 -> 1.1545451 | F20: =IF(AND(E20<=0),"C",IF(E20<=0.8,"A",IF(E20<=0.95,"B","C"))) -> C | G20: =VLOOKUP(B$4:B$25,I$4:M$25,5,0) -> C | I20: lux3 | J20: ='Юнит 09-15.02'!R19 -> 0 | K20: =J20/J$26 -> 0 | L20: =K20+L19 -> 0.98275862 | M20: =_xlfn.IFS(L20<80%,"A",L20<=95%,"B",L20>95%,"C") -> C
B21: MR Р1874 корич | C21: ='Юнит 09-15.02'!AE14 -> -387.09 | D21: =C21/C$26 -> -0.019184374 | E21: =D21+E20 -> 1.1353607 | F21: =IF(AND(E21<=0),"C",IF(E21<=0.8,"A",IF(E21<=0.95,"B","C"))) -> C | G21: =VLOOKUP(B$4:B$25,I$4:M$25,5,0) -> C | I21: lux5 | J21: ='Юнит 09-15.02'!R21 -> 0 | K21: =J21/J$26 -> 0 | L21: =K21+L20 -> 0.98275862 | M21: =_xlfn.IFS(L21<80%,"A",L21<=95%,"B",L21>95%,"C") -> C
B22: th желтый Сул | C22: ='Юнит 09-15.02'!AE8 -> -425.04 | D22: =C22/C$26 -> -0.021065195 | E22: =D22+E21 -> 1.1142955 | F22: =IF(AND(E22<=0),"C",IF(E22<=0.8,"A",IF(E22<=0.95,"B","C"))) -> C | G22: =VLOOKUP(B$4:B$25,I$4:M$25,5,0) -> C | I22: lux6 | J22: ='Юнит 09-15.02'!R22 -> 0 | K22: =J22/J$26 -> 0 | L22: =K22+L21 -> 0.98275862 | M22: =_xlfn.IFS(L22<80%,"A",L22<=95%,"B",L22>95%,"C") -> C
B23: MR Р1886 корич | C23: ='Юнит 09-15.02'!AE16 -> -569.18 | D23: =C23/C$26 -> -0.028208846 | E23: =D23+E22 -> 1.0860867 | F23: =IF(AND(E23<=0),"C",IF(E23<=0.8,"A",IF(E23<=0.95,"B","C"))) -> C | G23: =VLOOKUP(B$4:B$25,I$4:M$25,5,0) -> C | I23: lux7 | J23: ='Юнит 09-15.02'!R23 -> 0 | K23: =J23/J$26 -> 0 | L23: =K23+L22 -> 0.98275862 | M23: =_xlfn.IFS(L23<80%,"A",L23<=95%,"B",L23>95%,"C") -> C
B24: lux4 | C24: ='Юнит 09-15.02'!AE20 -> -925.79033 | D24: =C24/C$26 -> -0.045882633 | E24: =D24+E23 -> 1.0402041 | F24: =IF(AND(E24<=0),"C",IF(E24<=0.8,"A",IF(E24<=0.95,"B","C"))) -> C | G24: =VLOOKUP(B$4:B$25,I$4:M$25,5,0) -> C | I24: lux8 | J24: ='Юнит 09-15.02'!R24 -> 0 | K24: =J24/J$26 -> 0 | L24: =K24+L23 -> 0.98275862 | M24: =_xlfn.IFS(L24<80%,"A",L24<=95%,"B",L24>95%,"C") -> C
B25: qs желтые | C25: ='Юнит 09-15.02'!AE6 -> -1451.3763 | D25: =C25/C$26 -> -0.071930937 | E25: =D25+E24 -> 0.96827312 | F25: =IF(AND(E25<=0),"C",IF(E25<=0.8,"A",IF(E25<=0.95,"B","C"))) -> C | G25: =VLOOKUP(B$4:B$25,I$4:M$25,5,0) -> C | I25: lux4 | J25: ='Юнит 09-15.02'!R20 -> -1 | K25: =J25/J$26 -> -0.017241379 | L25: =K25+L24 -> 0.96551724 | M25: =_xlfn.IFS(L25<80%,"A",L25<=95%,"B",L25>95%,"C") -> C
C26: =SUM(C4:C25) -> 20177.358 | D26: =SUM(D4:D25) -> 1 | J26: =SUM(J4:J25) -> 58 | K26: =SUM(K4:K25) -> 1
B28: ТУНИКИ
C29: Прибыль | D29: % прибыль | E29: Доля | F29: ABC прибыль | G29: ABC кол-во | J29: Кол-во | K29: % кол-во | L29: Доля | M29: ABC кол-во
B30: tunika15 кимоно бирюза | C30: ='Юнит 09-15.02'!AE44 -> 7055.3882 | D30: =C30/C$50 -> 0.39472445 | E30: =D30 -> 0.39472445 | F30: =IF(AND(E30<=0),"C",IF(E30<=0.8,"A",IF(E30<=0.95,"B","C"))) -> A | G30: =VLOOKUP(B$30:B$50,I$30:M$50,5,0) -> A | I30: tunika15 кимоно бирюза | J30: ='Юнит 09-15.02'!R44 -> 7 | K30: =J30/J$50 -> 0.35 | L30: =K30 -> 0.35 | M30: =_xlfn.IFS(L30<80%,"A",L30<=95%,"B",L30>95%,"C") -> A
B31: tunika09 кимоно | C31: ='Юнит 09-15.02'!AE37 -> 5645.122 | D31: =C31/C$50 -> 0.31582495 | E31: =D31+E30 -> 0.7105494 | F31: =IF(AND(E31<=0),"C",IF(E31<=0.8,"A",IF(E31<=0.95,"B","C"))) -> A | G31: =VLOOKUP(B$30:B$50,I$30:M$50,5,0) -> A | I31: tunika15 кимоно песочная | J31: ='Юнит 09-15.02'!R45 -> 4 | K31: =J31/J$50 -> 0.2 | L31: =K31+L30 -> 0.55 | M31: =_xlfn.IFS(L31<80%,"A",L31<=95%,"B",L31>95%,"C") -> A
B32: tunika15 кимоно песочная | C32: ='Юнит 09-15.02'!AE45 -> 4691.1462 | D32: =C32/C$50 -> 0.26245332 | E32: =D32+E31 -> 0.97300272 | F32: =IF(AND(E32<=0),"C",IF(E32<=0.8,"A",IF(E32<=0.95,"B","C"))) -> C | G32: =VLOOKUP(B$30:B$50,I$30:M$50,5,0) -> A | I32: tunika09 кимоно | J32: ='Юнит 09-15.02'!R37 -> 3 | K32: =J32/J$50 -> 0.15 | L32: =K32+L31 -> 0.7 | M32: =_xlfn.IFS(L32<80%,"A",L32<=95%,"B",L32>95%,"C") -> A
B33: tunika03 черная распашная | C33: ='Юнит 09-15.02'!AE29 -> 1950.7439 | D33: =C33/C$50 -> 0.10913734 | E33: =D33+E32 -> 1.0821401 | F33: =IF(AND(E33<=0),"C",IF(E33<=0.8,"A",IF(E33<=0.95,"B","C"))) -> C | G33: =VLOOKUP(B$30:B$50,I$30:M$50,5,0) -> B | I33: tunika07 кружево | J33: ='Юнит 09-15.02'!R33 -> 2 | K33: =J33/J$50 -> 0.1 | L33: =K33+L32 -> 0.8 | M33: =_xlfn.IFS(L33<80%,"A",L33<=95%,"B",L33>95%,"C") -> B
B34: tunika07 кружево | C34: ='Юнит 09-15.02'!AE33 -> 1741.132 | D34: =C34/C$50 -> 0.097410283 | E34: =D34+E33 -> 1.1795503 | F34: =IF(AND(E34<=0),"C",IF(E34<=0.8,"A",IF(E34<=0.95,"B","C"))) -> C | G34: =VLOOKUP(B$30:B$50,I$30:M$50,5,0) -> B | I34: tunika14 халат с разрезами белая | J34: ='Юнит 09-15.02'!R42 -> 2 | K34: =J34/J$50 -> 0.1 | L34: =K34+L33 -> 0.9 | M34: =_xlfn.IFS(L34<80%,"A",L34<=95%,"B",L34>95%,"C") -> B
B35: tunika06 белая | C35: ='Юнит 09-15.02'!AE31 -> 1628.7063 | D35: =C35/C$50 -> 0.091120459 | E35: =D35+E34 -> 1.2706708 | F35: =IF(AND(E35<=0),"C",IF(E35<=0.8,"A",IF(E35<=0.95,"B","C"))) -> C | G35: =VLOOKUP(B$30:B$50,I$30:M$50,5,0) -> C | I35: tunika03 черная распашная | J35: ='Юнит 09-15.02'!R29 -> 1 | K35: =J35/J$50 -> 0.05 | L35: =K35+L34 -> 0.95 | M35: =_xlfn.IFS(L35<80%,"A",L35<=95%,"B",L35>95%,"C") -> B
B36: tunika14 халат с разрезами белая | C36: ='Юнит 09-15.02'!AE42 -> 1576.2627 | D36: =C36/C$50 -> 0.088186419 | E36: =D36+E35 -> 1.3588572 | F36: =IF(AND(E36<=0),"C",IF(E36<=0.8,"A",IF(E36<=0.95,"B","C"))) -> C | G36: =VLOOKUP(B$30:B$50,I$30:M$50,5,0) -> B | I36: tunika06 белая | J36: ='Юнит 09-15.02'!R31 -> 1 | K36: =J36/J$50 -> 0.05 | L36: =K36+L35 -> 1 | M36: =_xlfn.IFS(L36<80%,"A",L36<=95%,"B",L36>95%,"C") -> C
B37: tunika02 оливковая с руч вышивкой | C37: ='Юнит 09-15.02'!AE28 -> 0 | D37: =C37/C$50 -> 0 | E37: =D37+E36 -> 1.3588572 | F37: =IF(AND(E37<=0),"C",IF(E37<=0.8,"A",IF(E37<=0.95,"B","C"))) -> C | G37: =VLOOKUP(B$30:B$50,I$30:M$50,5,0) -> C | I37: tunika16 сетка белая | J37: ='Юнит 09-15.02'!R46 -> 1 | K37: =J37/J$50 -> 0.05 | L37: =K37+L36 -> 1.05 | M37: =_xlfn.IFS(L37<80%,"A",L37<=95%,"B",L37>95%,"C") -> C
B38: tunika06 черная | C38: ='Юнит 09-15.02'!AE32 -> 0 | D38: =C38/C$50 -> 0 | E38: =D38+E37 -> 1.3588572 | F38: =IF(AND(E38<=0),"C",IF(E38<=0.8,"A",IF(E38<=0.95,"B","C"))) -> C | G38: =VLOOKUP(B$30:B$50,I$30:M$50,5,0) -> C | I38: tunika02 оливковая с руч вышивкой | J38: ='Юнит 09-15.02'!R28 -> 0 | K38: =J38/J$50 -> 0 | L38: =K38+L37 -> 1.05 | M38: =_xlfn.IFS(L38<80%,"A",L38<=95%,"B",L38>95%,"C") -> C
B39: tunika08 белая | C39: ='Юнит 09-15.02'!AE34 -> 0 | D39: =C39/C$50 -> 0 | E39: =D39+E38 -> 1.3588572 | F39: =IF(AND(E39<=0),"C",IF(E39<=0.8,"A",IF(E39<=0.95,"B","C"))) -> C | G39: =VLOOKUP(B$30:B$50,I$30:M$50,5,0) -> C | I39: tunika05 белая распашная | J39: ='Юнит 09-15.02'!R30 -> 0 | K39: =J39/J$50 -> 0 | L39: =K39+L38 -> 1.05 | M39: =_xlfn.IFS(L39<80%,"A",L39<=95%,"B",L39>95%,"C") -> C
B40: tunika08 черная | C40: ='Юнит 09-15.02'!AE35 -> 0 | D40: =C40/C$50 -> 0 | E40: =D40+E39 -> 1.3588572 | F40: =IF(AND(E40<=0),"C",IF(E40<=0.8,"A",IF(E40<=0.95,"B","C"))) -> C | G40: =VLOOKUP(B$30:B$50,I$30:M$50,5,0) -> C | I40: tunika06 черная | J40: ='Юнит 09-15.02'!R32 -> 0 | K40: =J40/J$50 -> 0 | L40: =K40+L39 -> 1.05 | M40: =_xlfn.IFS(L40<80%,"A",L40<=95%,"B",L40>95%,"C") -> C
B41: tunika11 халат зеленая | C41: ='Юнит 09-15.02'!AE39 -> 0 | D41: =C41/C$50 -> 0 | E41: =D41+E40 -> 1.3588572 | F41: =IF(AND(E41<=0),"C",IF(E41<=0.8,"A",IF(E41<=0.95,"B","C"))) -> C | G41: =VLOOKUP(B$30:B$50,I$30:M$50,5,0) -> C | I41: tunika08 белая | J41: ='Юнит 09-15.02'!R34 -> 0 | K41: =J41/J$50 -> 0 | L41: =K41+L40 -> 1.05 | M41: =_xlfn.IFS(L41<80%,"A",L41<=95%,"B",L41>95%,"C") -> C
B42: tunika12 халат белая | C42: ='Юнит 09-15.02'!AE40 -> 0 | D42: =C42/C$50 -> 0 | E42: =D42+E41 -> 1.3588572 | F42: =IF(AND(E42<=0),"C",IF(E42<=0.8,"A",IF(E42<=0.95,"B","C"))) -> C | G42: =VLOOKUP(B$30:B$50,I$30:M$50,5,0) -> C | I42: tunika08 черная | J42: ='Юнит 09-15.02'!R35 -> 0 | K42: =J42/J$50 -> 0 | L42: =K42+L41 -> 1.05 | M42: =_xlfn.IFS(L42<80%,"A",L42<=95%,"B",L42>95%,"C") -> C
...

Sheet АВС 02-08.02
B2: ОЧКИ
C3: Прибыль | D3: % прибыль | E3: Доля | F3: ABC прибыль | G3: ABC кол-во | J3: Кол-во | K3: % кол-во | L3: Доля | M3: ABC кол-во
B4: черные с железкой классика | C4: ='Юнит 02-08.02'!AE3 -> 10282.202 | D4: =C4/C$26 -> 0.80310383 | E4: =D4 -> 0.80310383 | F4: =IF(AND(E4<=0),"C",IF(E4<=0.8,"A",IF(E4<=0.95,"B","C"))) -> B | G4: =VLOOKUP(B$4:B$25,I$4:M$25,5,0) -> A | I4: черные с железкой классика | J4: ='Юнит 02-08.02'!R3 -> 38 | K4: =J4/J$26 -> 0.63333333 | L4: =K4 -> 0.63333333 | M4: =_xlfn.IFS(L4<80%,"A",L4<=95%,"B",L4>95%,"C") -> A
B5: flip желтые Сул | C5: ='Юнит 02-08.02'!AE9 -> 2101.7612 | D5: =C5/C$26 -> 0.16416061 | E5: =D5+E4 -> 0.96726444 | F5: =IF(AND(E5<=0),"C",IF(E5<=0.8,"A",IF(E5<=0.95,"B","C"))) -> C | G5: =VLOOKUP(B$4:B$25,I$4:M$25,5,0) -> B | I5: qs коричневые | J5: ='Юнит 02-08.02'!R7 -> 8 | K5: =J5/J$26 -> 0.13333333 | L5: =K5+L4 -> 0.76666667 | M5: =_xlfn.IFS(L5<80%,"A",L5<=95%,"B",L5>95%,"C") -> A
B6: lux4 | C6: ='Юнит 02-08.02'!AE20 -> 647.32719 | D6: =C6/C$26 -> 0.050560274 | E6: =D6+E5 -> 1.0178247 | F6: =IF(AND(E6<=0),"C",IF(E6<=0.8,"A",IF(E6<=0.95,"B","C"))) -> C | G6: =VLOOKUP(B$4:B$25,I$4:M$25,5,0) -> B | I6: flip желтые Сул | J6: ='Юнит 02-08.02'!R9 -> 5 | K6: =J6/J$26 -> 0.083333333 | L6: =K6+L5 -> 0.85 | M6: =_xlfn.IFS(L6<80%,"A",L6<=95%,"B",L6>95%,"C") -> B
B7: qs черные | C7: ='Юнит 02-08.02'!AE4 -> 601.7972 | D7: =C7/C$26 -> 0.047004099 | E7: =D7+E6 -> 1.0648288 | F7: =IF(AND(E7<=0),"C",IF(E7<=0.8,"A",IF(E7<=0.95,"B","C"))) -> C | G7: =VLOOKUP(B$4:B$25,I$4:M$25,5,0) -> C | I7: MR Р1874 черн | J7: ='Юнит 02-08.02'!R13 -> 3 | K7: =J7/J$26 -> 0.05 | L7: =K7+L6 -> 0.9 | M7: =_xlfn.IFS(L7<80%,"A",L7<=95%,"B",L7>95%,"C") -> B
B8: qs синие | C8: ='Юнит 02-08.02'!AE5 -> 549.23742 | D8: =C8/C$26 -> 0.042898854 | E8: =D8+E7 -> 1.1077277 | F8: =IF(AND(E8<=0),"C",IF(E8<=0.8,"A",IF(E8<=0.95,"B","C"))) -> C | G8: =VLOOKUP(B$4:B$25,I$4:M$25,5,0) -> B | I8: qs синие | J8: ='Юнит 02-08.02'!R5 -> 2 | K8: =J8/J$26 -> 0.033333333 | L8: =K8+L7 -> 0.93333333 | M8: =_xlfn.IFS(L8<80%,"A",L8<=95%,"B",L8>95%,"C") -> B
B9: th желтый Сул | C9: ='Юнит 02-08.02'!AE8 -> 119.68725 | D9: =C9/C$26 -> 0.009348318 | E9: =D9+E8 -> 1.117076 | F9: =IF(AND(E9<=0),"C",IF(E9<=0.8,"A",IF(E9<=0.95,"B","C"))) -> C | G9: =VLOOKUP(B$4:B$25,I$4:M$25,5,0) -> C | I9: th желтый Сул | J9: ='Юнит 02-08.02'!R8 -> 2 | K9: =J9/J$26 -> 0.033333333 | L9: =K9+L8 -> 0.96666667 | M9: =_xlfn.IFS(L9<80%,"A",L9<=95%,"B",L9>95%,"C") -> C
B10: MR Р1886 корич | C10: ='Юнит 02-08.02'!AE16 -> 0 | D10: =C10/C$26 -> 0 | E10: =D10+E9 -> 1.117076 | F10: =IF(AND(E10<=0),"C",IF(E10<=0.8,"A",IF(E10<=0.95,"B","C"))) -> C | G10: =VLOOKUP(B$4:B$25,I$4:M$25,5,0) -> B | I10: qs черные | J10: ='Юнит 02-08.02'!R4 -> 1 | K10: =J10/J$26 -> 0.016666667 | L10: =K10+L9 -> 0.98333333 | M10: =_xlfn.IFS(L10<80%,"A",L10<=95%,"B",L10>95%,"C") -> C
B11: lux1 | C11: ='Юнит 02-08.02'!AE17 -> 0 | D11: =C11/C$26 -> 0 | E11: =D11+E8 -> 1.1077277 | F11: =IF(AND(E11<=0),"C",IF(E11<=0.8,"A",IF(E11<=0.95,"B","C"))) -> C | G11: =VLOOKUP(B$4:B$25,I$4:M$25,5,0) -> B | I11: lux4 | J11: ='Юнит 02-08.02'!R20 -> 1 | K11: =J11/J$26 -> 0.016666667 | L11: =K11+L8 -> 0.95 | M11: =_xlfn.IFS(L11<80%,"A",L11<=95%,"B",L11>95%,"C") -> B
B12: lux2 | C12: ='Юнит 02-08.02'!AE18 -> 0 | D12: =C12/C$26 -> 0 | E12: =D12+E11 -> 1.1077277 | F12: =IF(AND(E12<=0),"C",IF(E12<=0.8,"A",IF(E12<=0.95,"B","C"))) -> C | G12: =VLOOKUP(B$4:B$25,I$4:M$25,5,0) -> B | I12: qs желтые | J12: ='Юнит 02-08.02'!R6 -> 0 | K12: =J12/J$26 -> 0 | L12: =K12+L11 -> 0.95 | M12: =_xlfn.IFS(L12<80%,"A",L12<=95%,"B",L12>95%,"C") -> B
B13: lux5 | C13: ='Юнит 02-08.02'!AE21 -> 0 | D13: =C13/C$26 -> 0 | E13: =D13+E12 -> 1.1077277 | F13: =IF(AND(E13<=0),"C",IF(E13<=0.8,"A",IF(E13<=0.95,"B","C"))) -> C | G13: =VLOOKUP(B$4:B$25,I$4:M$25,5,0) -> B | I13: MR8854 C2 | J13: ='Юнит 02-08.02'!R10 -> 0 | K13: =J13/J$26 -> 0 | L13: =K13+L12 -> 0.95 | M13: =_xlfn.IFS(L13<80%,"A",L13<=95%,"B",L13>95%,"C") -> B | P13: A | Q13: 0.8
B14: lux6 | C14: ='Юнит 02-08.02'!AE22 -> 0 | D14: =C14/C$26 -> 0 | E14: =D14+E13 -> 1.1077277 | F14: =IF(AND(E14<=0),"C",IF(E14<=0.8,"A",IF(E14<=0.95,"B","C"))) -> C | G14: =VLOOKUP(B$4:B$25,I$4:M$25,5,0) -> B | I14: MR 1819 черн | J14: ='Юнит 02-08.02'!R11 -> 0 | K14: =J14/J$26 -> 0 | L14: =K14+L13 -> 0.95 | M14: =_xlfn.IFS(L14<80%,"A",L14<=95%,"B",L14>95%,"C") -> B | P14: B | Q14: 0.15
B15: lux7 | C15: ='Юнит 02-08.02'!AE23 -> 0 | D15: =C15/C$26 -> 0 | E15: =D15+E14 -> 1.1077277 | F15: =IF(AND(E15<=0),"C",IF(E15<=0.8,"A",IF(E15<=0.95,"B","C"))) -> C | G15: =VLOOKUP(B$4:B$25,I$4:M$25,5,0) -> B | I15: MR 1819 корич | J15: ='Юнит 02-08.02'!R12 -> 0 | K15: =J15/J$26 -> 0 | L15: =K15+L14 -> 0.95 | M15: =_xlfn.IFS(L15<80%,"A",L15<=95%,"B",L15>95%,"C") -> B | P15: C | Q15: 0.05
B16: lux8 | C16: ='Юнит 02-08.02'!AE24 -> 0 | D16: =C16/C$26 -> 0 | E16: =D16+E15 -> 1.1077277 | F16: =IF(AND(E16<=0),"C",IF(E16<=0.8,"A",IF(E16<=0.95,"B","C"))) -> C | G16: =VLOOKUP(B$4:B$25,I$4:M$25,5,0) -> B | I16: MR Р1874 корич | J16: ='Юнит 02-08.02'!R14 -> 0 | K16: =J16/J$26 -> 0 | L16: =K16+L15 -> 0.95 | M16: =_xlfn.IFS(L16<80%,"A",L16<=95%,"B",L16>95%,"C") -> B
B17: MR 1819 черн | C17: ='Юнит 02-08.02'!AE11 -> -93.54 | D17: =C17/C$26 -> -0.0073060551 | E17: =D17+E16 -> 1.1004216 | F17: =IF(AND(E17<=0),"C",IF(E17<=0.8,"A",IF(E17<=0.95,"B","C"))) -> C | G17: =VLOOKUP(B$4:B$25,I$4:M$25,5,0) -> B | I17: MR Р1886 черн глянец | J17: ='Юнит 02-08.02'!R15 -> 0 | K17: =J17/J$26 -> 0 | L17: =K17+L16 -> 0.95 | M17: =_xlfn.IFS(L17<80%,"A",L17<=95%,"B",L17>95%,"C") -> B
B18: MR 1819 корич | C18: ='Юнит 02-08.02'!AE12 -> -93.54 | D18: =C18/C$26 -> -0.0073060551 | E18: =D18+E17 -> 1.0931156 | F18: =IF(AND(E18<=0),"C",IF(E18<=0.8,"A",IF(E18<=0.95,"B","C"))) -> C | G18: =VLOOKUP(B$4:B$25,I$4:M$25,5,0) -> B | I18: MR Р1886 корич | J18: ='Юнит 02-08.02'!R16 -> 0 | K18: =J18/J$26 -> 0 | L18: =K18+L17 -> 0.95 | M18: =_xlfn.IFS(L18<80%,"A",L18<=95%,"B",L18>95%,"C") -> B
B19: MR Р1874 корич | C19: ='Юнит 02-08.02'!AE14 -> -93.54 | D19: =C19/C$26 -> -0.0073060551 | E19: =D19+E18 -> 1.0858095 | F19: =IF(AND(E19<=0),"C",IF(E19<=0.8,"A",IF(E19<=0.95,"B","C"))) -> C | G19: =VLOOKUP(B$4:B$25,I$4:M$25,5,0) -> B | I19: lux1 | J19: ='Юнит 02-08.02'!R17 -> 0 | K19: =J19/J$26 -> 0 | L19: =K19+L18 -> 0.95 | M19: =_xlfn.IFS(L19<80%,"A",L19<=95%,"B",L19>95%,"C") -> B
B20: MR Р1886 черн глянец | C20: ='Юнит 02-08.02'!AE15 -> -93.54 | D20: =C20/C$26 -> -0.0073060551 | E20: =D20+E19 -> 1.0785034 | F20: =IF(AND(E20<=0),"C",IF(E20<=0.8,"A",IF(E20<=0.95,"B","C"))) -> C | G20: =VLOOKUP(B$4:B$25,I$4:M$25,5,0) -> B | I20: lux2 | J20: ='Юнит 02-08.02'!R18 -> 0 | K20: =J20/J$26 -> 0 | L20: =K20+L19 -> 0.95 | M20: =_xlfn.IFS(L20<80%,"A",L20<=95%,"B",L20>95%,"C") -> B
B21: qs коричневые | C21: ='Юнит 02-08.02'!AE7 -> -28.274503 | D21: =C21/C$26 -> -0.0022084143 | E21: =D21+E20 -> 1.076295 | F21: =IF(AND(E21<=0),"C",IF(E21<=0.8,"A",IF(E21<=0.95,"B","C"))) -> C | G21: =VLOOKUP(B$4:B$25,I$4:M$25,5,0) -> A | I21: lux3 | J21: ='Юнит 02-08.02'!R19 -> 0 | K21: =J21/J$26 -> 0 | L21: =K21+L20 -> 0.95 | M21: =_xlfn.IFS(L21<80%,"A",L21<=95%,"B",L21>95%,"C") -> B
B22: lux3 | C22: ='Юнит 02-08.02'!AE19 -> -113.88 | D22: =C22/C$26 -> -0.0088947354 | E22: =D22+E21 -> 1.0674003 | F22: =IF(AND(E22<=0),"C",IF(E22<=0.8,"A",IF(E22<=0.95,"B","C"))) -> C | G22: =VLOOKUP(B$4:B$25,I$4:M$25,5,0) -> B | I22: lux5 | J22: ='Юнит 02-08.02'!R21 -> 0 | K22: =J22/J$26 -> 0 | L22: =K22+L21 -> 0.95 | M22: =_xlfn.IFS(L22<80%,"A",L22<=95%,"B",L22>95%,"C") -> B
B23: qs желтые | C23: ='Юнит 02-08.02'!AE6 -> -263.94 | D23: =C23/C$26 -> -0.020615354 | E23: =D23+E22 -> 1.0467849 | F23: =IF(AND(E23<=0),"C",IF(E23<=0.8,"A",IF(E23<=0.95,"B","C"))) -> C | G23: =VLOOKUP(B$4:B$25,I$4:M$25,5,0) -> B | I23: lux6 | J23: ='Юнит 02-08.02'!R22 -> 0 | K23: =J23/J$26 -> 0 | L23: =K23+L22 -> 0.95 | M23: =_xlfn.IFS(L23<80%,"A",L23<=95%,"B",L23>95%,"C") -> B
B24: MR Р1874 черн | C24: ='Юнит 02-08.02'!AE13 -> -258.67858 | D24: =C24/C$26 -> -0.020204404 | E24: =D24+E23 -> 1.0265805 | F24: =IF(AND(E24<=0),"C",IF(E24<=0.8,"A",IF(E24<=0.95,"B","C"))) -> C | G24: =VLOOKUP(B$4:B$25,I$4:M$25,5,0) -> B | I24: lux7 | J24: ='Юнит 02-08.02'!R23 -> 0 | K24: =J24/J$26 -> 0 | L24: =K24+L23 -> 0.95 | M24: =_xlfn.IFS(L24<80%,"A",L24<=95%,"B",L24>95%,"C") -> B
B25: MR8854 C2 | C25: ='Юнит 02-08.02'!AE10 -> -460 | D25: =C25/C$26 -> -0.035928857 | E25: =D25+E24 -> 0.99065168 | F25: =IF(AND(E25<=0),"C",IF(E25<=0.8,"A",IF(E25<=0.95,"B","C"))) -> C | G25: =VLOOKUP(B$4:B$25,I$4:M$25,5,0) -> B | I25: lux8 | J25: ='Юнит 02-08.02'!R24 -> 0 | K25: =J25/J$26 -> 0 | L25: =K25+L24 -> 0.95 | M25: =_xlfn.IFS(L25<80%,"A",L25<=95%,"B",L25>95%,"C") -> B
C26: =SUM(C4:C25) -> 12803.079 | D26: =SUM(D4:D25) -> 1 | J26: =SUM(J4:J25) -> 60 | K26: =SUM(K4:K25) -> 1
B28: ТУНИКИ
C29: Прибыль | D29: % прибыль | E29: Доля | F29: ABC прибыль | G29: ABC кол-во | J29: Кол-во | K29: % кол-во | L29: Доля | M29: ABC кол-во
B30: tunika16 сетка белая | C30: ='Юнит 02-08.02'!AE46 -> 7804.8634 | D30: =C30/C$50 -> 0.48315587 | E30: =D30 -> 0.48315587 | F30: =IF(AND(E30<=0),"C",IF(E30<=0.8,"A",IF(E30<=0.95,"B","C"))) -> A | G30: =VLOOKUP(B$30:B$50,I$30:M$50,5,0) -> A | I30: tunika16 сетка белая | J30: ='Юнит 02-08.02'!R46 -> 7 | K30: =J30/J$50 -> 0.30434783 | L30: =K30 -> 0.30434783 | M30: =_xlfn.IFS(L30<80%,"A",L30<=95%,"B",L30>95%,"C") -> A
B31: tunika08 белая | C31: ='Юнит 02-08.02'!AE34 -> 3279.9222 | D31: =C31/C$50 -> 0.20304182 | E31: =D31+E30 -> 0.68619769 | F31: =IF(AND(E31<=0),"C",IF(E31<=0.8,"A",IF(E31<=0.95,"B","C"))) -> A | G31: =VLOOKUP(B$30:B$50,I$30:M$50,5,0) -> A | I31: tunika15 кимоно бирюза | J31: ='Юнит 02-08.02'!R44 -> 6 | K31: =J31/J$50 -> 0.26086957 | L31: =K31+L30 -> 0.56521739 | M31: =_xlfn.IFS(L31<80%,"A",L31<=95%,"B",L31>95%,"C") -> A
B32: tunika09 кимоно | C32: ='Юнит 02-08.02'!AE37 -> 3060.0832 | D32: =C32/C$50 -> 0.1894328 | E32: =D32+E31 -> 0.87563049 | F32: =IF(AND(E32<=0),"C",IF(E32<=0.8,"A",IF(E32<=0.95,"B","C"))) -> B | G32: =VLOOKUP(B$30:B$50,I$30:M$50,5,0) -> A | I32: tunika08 белая | J32: ='Юнит 02-08.02'!R34 -> 2 | K32: =J32/J$50 -> 0.086956522 | L32: =K32+L31 -> 0.65217391 | M32: =_xlfn.IFS(L32<80%,"A",L32<=95%,"B",L32>95%,"C") -> A
B33: tunika14 халат с разрезами черный | C33: ='Юнит 02-08.02'!AE43 -> 1455.7641 | D33: =C33/C$50 -> 0.090118292 | E33: =D33+E32 -> 0.96574878 | F33: =IF(AND(E33<=0),"C",IF(E33<=0.8,"A",IF(E33<=0.95,"B","C"))) -> C | G33: =VLOOKUP(B$30:B$50,I$30:M$50,5,0) -> C | I33: tunika09 кимоно | J33: ='Юнит 02-08.02'!R37 -> 2 | K33: =J33/J$50 -> 0.086956522 | L33: =K33+L32 -> 0.73913043 | M33: =_xlfn.IFS(L33<80%,"A",L33<=95%,"B",L33>95%,"C") -> A
B34: tunika15 кимоно бирюза | C34: ='Юнит 02-08.02'!AE44 -> 1463.1582 | D34: =C34/C$50 -> 0.09057602 | E34: =D34+E33 -> 1.0563248 | F34: =IF(AND(E34<=0),"C",IF(E34<=0.8,"A",IF(E34<=0.95,"B","C"))) -> C | G34: =VLOOKUP(B$30:B$50,I$30:M$50,5,0) -> A | I34: tunika15 кимоно песочная | J34: ='Юнит 02-08.02'!R45 -> 2 | K34: =J34/J$50 -> 0.086956522 | L34: =K34+L33 -> 0.82608696 | M34: =_xlfn.IFS(L34<80%,"A",L34<=95%,"B",L34>95%,"C") -> B
B35: tunika11 халат зеленая | C35: ='Юнит 02-08.02'!AE39 -> 1145.3411 | D35: =C35/C$50 -> 0.070901722 | E35: =D35+E34 -> 1.1272265 | F35: =IF(AND(E35<=0),"C",IF(E35<=0.8,"A",IF(E35<=0.95,"B","C"))) -> C | G35: =VLOOKUP(B$30:B$50,I$30:M$50,5,0) -> B | I35: tunika10 кимоно ч/б | J35: ='Юнит 02-08.02'!R38 -> 1 | K35: =J35/J$50 -> 0.043478261 | L35: =K35+L34 -> 0.86956522 | M35: =_xlfn.IFS(L35<80%,"A",L35<=95%,"B",L35>95%,"C") -> B
B36: tunika15 кимоно песочная | C36: ='Юнит 02-08.02'!AE45 -> 1169.3962 | D36: =C36/C$50 -> 0.072390845 | E36: =D36+E35 -> 1.1996174 | F36: =IF(AND(E36<=0),"C",IF(E36<=0.8,"A",IF(E36<=0.95,"B","C"))) -> C | G36: =VLOOKUP(B$30:B$50,I$30:M$50,5,0) -> B | I36: tunika11 халат зеленая | J36: ='Юнит 02-08.02'!R39 -> 1 | K36: =J36/J$50 -> 0.043478261 | L36: =K36+L35 -> 0.91304348 | M36: =_xlfn.IFS(L36<80%,"A",L36<=95%,"B",L36>95%,"C") -> B
B37: tunika10 кимоно ч/б | C37: ='Юнит 02-08.02'!AE38 -> 947.91203 | D37: =C37/C$50 -> 0.058679984 | E37: =D37+E36 -> 1.2582974 | F37: =IF(AND(E37<=0),"C",IF(E37<=0.8,"A",IF(E37<=0.95,"B","C"))) -> C | G37: =VLOOKUP(B$30:B$50,I$30:M$50,5,0) -> B | I37: tunika14 халат с разрезами белая | J37: ='Юнит 02-08.02'!R42 -> 1 | K37: =J37/J$50 -> 0.043478261 | L37: =K37+L36 -> 0.95652174 | M37: =_xlfn.IFS(L37<80%,"A",L37<=95%,"B",L37>95%,"C") -> C
B38: tunika05 белая распашная | C38: ='Юнит 02-08.02'!AE30 -> 0 | D38: =C38/C$50 -> 0 | E38: =D38+E37 -> 1.2582974 | F38: =IF(AND(E38<=0),"C",IF(E38<=0.8,"A",IF(E38<=0.95,"B","C"))) -> C | G38: =VLOOKUP(B$30:B$50,I$30:M$50,5,0) -> C | I38: tunika14 халат с разрезами черный | J38: ='Юнит 02-08.02'!R43 -> 1 | K38: =J38/J$50 -> 0.043478261 | L38: =K38+L37 -> 1 | M38: =_xlfn.IFS(L38<80%,"A",L38<=95%,"B",L38>95%,"C") -> C
B39: tunika06 белая | C39: ='Юнит 02-08.02'!AE31 -> 0 | D39: =C39/C$50 -> 0 | E39: =D39+E38 -> 1.2582974 | F39: =IF(AND(E39<=0),"C",IF(E39<=0.8,"A",IF(E39<=0.95,"B","C"))) -> C | G39: =VLOOKUP(B$30:B$50,I$30:M$50,5,0) -> C | I39: tunika02 оливковая с руч вышивкой | J39: ='Юнит 02-08.02'!R28 -> 0 | K39: =J39/J$50 -> 0 | L39: =K39+L38 -> 1 | M39: =_xlfn.IFS(L39<80%,"A",L39<=95%,"B",L39>95%,"C") -> C
B40: tunika06 черная | C40: ='Юнит 02-08.02'!AE32 -> 0 | D40: =C40/C$50 -> 0 | E40: =D40+E39 -> 1.2582974 | F40: =IF(AND(E40<=0),"C",IF(E40<=0.8,"A",IF(E40<=0.95,"B","C"))) -> C | G40: =VLOOKUP(B$30:B$50,I$30:M$50,5,0) -> C | I40: tunika03 черная распашная | J40: ='Юнит 02-08.02'!R29 -> 0 | K40: =J40/J$50 -> 0 | L40: =K40+L39 -> 1 | M40: =_xlfn.IFS(L40<80%,"A",L40<=95%,"B",L40>95%,"C") -> C
B41: tunika08 черная | C41: ='Юнит 02-08.02'!AE35 -> 0 | D41: =C41/C$50 -> 0 | E41: =D41+E40 -> 1.2582974 | F41: =IF(AND(E41<=0),"C",IF(E41<=0.8,"A",IF(E41<=0.95,"B","C"))) -> C | G41: =VLOOKUP(B$30:B$50,I$30:M$50,5,0) -> C | I41: tunika05 белая распашная | J41: ='Юнит 02-08.02'!R30 -> 0 | K41: =J41/J$50 -> 0 | L41: =K41+L40 -> 1 | M41: =_xlfn.IFS(L41<80%,"A",L41<=95%,"B",L41>95%,"C") -> C
B42: tunika12 халат белая | C42: ='Юнит 02-08.02'!AE40 -> 0 | D42: =C42/C$50 -> 0 | E42: =D42+E41 -> 1.2582974 | F42: =IF(AND(E42<=0),"C",IF(E42<=0.8,"A",IF(E42<=0.95,"B","C"))) -> C | G42: =VLOOKUP(B$30:B$50,I$30:M$50,5,0) -> C | I42: tunika06 белая | J42: ='Юнит 02-08.02'!R31 -> 0 | K42: =J42/J$50 -> 0 | L42: =K42+L41 -> 1 | M42: =_xlfn.IFS(L42<80%,"A",L42<=95%,"B",L42>95%,"C") -> C
...

Sheet АВС ЯНВАРЬ
B2: ОЧКИ
C3: Прибыль | D3: % прибыль | E3: Доля | F3: ABC прибыль | G3: ABC кол-во | J3: Кол-во | K3: % кол-во | L3: Доля | M3: ABC кол-во
B4: черные с железкой классика | C4: =ЯНВАРЬ!AE3 -> 40731.919 | D4: =C4/C$26 -> 0.63166595 | E4: =D4 -> 0.63166595 | F4: =IF(AND(E4<=0),"C",IF(E4<=0.8,"A",IF(E4<=0.95,"B","C"))) -> A | G4: =VLOOKUP(B$4:B$25,I$4:M$25,5,0) -> A | I4: черные с железкой классика | J4: =ЯНВАРЬ!R3 -> 174 | K4: =J4/J$26 -> 0.64444444 | L4: =K4 -> 0.64444444 | M4: =_xlfn.IFS(L4<80%,"A",L4<=95%,"B",L4>95%,"C") -> A
B5: qs желтые | C5: =ЯНВАРЬ!AE6 -> 7328.9101 | D5: =C5/C$26 -> 0.1136559 | E5: =D5+E4 -> 0.74532185 | F5: =IF(AND(E5<=0),"C",IF(E5<=0.8,"A",IF(E5<=0.95,"B","C"))) -> A | G5: =VLOOKUP(B$4:B$25,I$4:M$25,5,0) -> A | I5: qs желтые | J5: =ЯНВАРЬ!R6 -> 33 | K5: =J5/J$26 -> 0.12222222 | L5: =K5+L4 -> 0.76666667 | M5: =_xlfn.IFS(L5<80%,"A",L5<=95%,"B",L5>95%,"C") -> A
B6: qs коричневые | C6: =ЯНВАРЬ!AE7 -> 5299.7732 | D6: =C6/C$26 -> 0.082188278 | E6: =D6+E5 -> 0.82751013 | F6: =IF(AND(E6<=0),"C",IF(E6<=0.8,"A",IF(E6<=0.95,"B","C"))) -> B | G6: =VLOOKUP(B$4:B$25,I$4:M$25,5,0) -> B | I6: qs коричневые | J6: =ЯНВАРЬ!R7 -> 12 | K6: =J6/J$26 -> 0.044444444 | L6: =K6+L5 -> 0.81111111 | M6: =_xlfn.IFS(L6<80%,"A",L6<=95%,"B",L6>95%,"C") -> B
B7: th желтый Сул | C7: =ЯНВАРЬ!AE8 -> 1731.7421 | D7: =C7/C$26 -> 0.026855658 | E7: =D7+E6 -> 0.85436579 | F7: =IF(AND(E7<=0),"C",IF(E7<=0.8,"A",IF(E7<=0.95,"B","C"))) -> B | G7: =VLOOKUP(B$4:B$25,I$4:M$25,5,0) -> B | I7: flip желтые Сул | J7: =ЯНВАРЬ!R9 -> 11 | K7: =J7/J$26 -> 0.040740741 | L7: =K7+L6 -> 0.85185185 | M7: =_xlfn.IFS(L7<80%,"A",L7<=95%,"B",L7>95%,"C") -> B
