Workbook

Sheet Сводная
A1: Период | D1: Итого к перечислению на счет, руб | E1: шт. | H1: Выручка | K1: Себестоимость продаж | L1: Логистика | M1: Комиссия | N1: Хранение | O1: Платная приемка | P1: Штрафы | Q1: Реклама Ozon | R1: Другие услуги и штрафы | S1: Услуги партнёров | T1: Услуги FBO | U1: Компенсировано | V1: Пополнение рекламного кабинета | W1: ЕАЭС | X1: Налог | Y1: Прибыль до вычета налогов | Z1: Прибыль после вычета налогов | AA1: Итог месяц | AB1: % Cебестоимости | AC1: Маржинальность, % | AD1: Рентабельность, % | AE1: Доля рекламы, % | AG1: Данные для построения диаграмм
A2: Месяц | B2: Даты | C2: Нед | E2: Заказы | F2: Продажи | G2: Возвраты | H2: Продажи | I2: Возвраты | J2: Общая | AG2: Нед | AH2: По магазину | AI2: По очкам | AJ2: По туникам
A3: Январь | B3: 01-04.01 очки | D3: =J3-SUM(L3:T3)+U3+V3 -> 8693.5829 | E3: ='Юнит 01-04.01'!K$26 -> 44 | F3: ='Юнит 01-04.01'!P$26 -> 28 | G3: ='Юнит 01-04.01'!Q$26 -> 0 | H3: ='Юнит 01-04.01'!S$26 -> 45978 | I3: ='Юнит 01-04.01'!T$26 -> 0 | J3: =H3+I3 -> 45978 | K3: ='Юнит 01-04.01'!W$26 -> 4528.66 | L3: ='Юнит 01-04.01'!Z$26 -> 3709.34 | M3: ='Юнит 01-04.01'!X$26 -> 19770.54 | Q3: ='Юнит 01-04.01'!AA$26 -> 12383.647 | S3: 808.39 | T3: 612.5 | W3: 2545 | X3: =2656.15*J3/SUM($J$3:$J$12) -> 193.86959 | Y3: =J3-SUM(L3:T3)-K3-V3+U3+W3 -> 6709.9229 | Z3: =Y3-X3 -> 6516.0533 | AA3: =SUM(Z3:Z12) -> 53230.01 | AB3: =K3/J3 -> 0.098496237 | AC3: =Z3/K3 -> 1.438848 | AD3: =Z3/J3 -> 0.14172111 | AE3: =Q3/J3 -> 0.26933853
B4: 01-04.01 туники | D4: =J4-SUM(L4:T4)+U4+V4+W4 -> -283.08293 | E4: ='Юнит 01-04.01'!K$49 -> 5 | F4: ='Юнит 01-04.01'!P$49 -> 1 | G4: ='Юнит 01-04.01'!Q$49 -> 0 | H4: ='Юнит 01-04.01'!S$49 -> 4247 | I4: ='Юнит 01-04.01'!T$49 -> 0 | J4: =H4+I4 -> 4247 | K4: ='Юнит 01-04.01'!W$49 -> 597 | L4: ='Юнит 01-04.01'!Z$49 -> 186.2 | M4: ='Юнит 01-04.01'!X$49 -> 1826.21 | Q4: ='Юнит 01-04.01'!AA$49 -> 2517.6729 | X4: =2656.15*J4/SUM($J$3:$J$12) -> 17.907785 | Y4: =J4-SUM(L4:T4)-K4-V4+U4+W4 -> -880.08293 | Z4: =Y4-X4 -> -897.99072 | AB4: =K4/J4 -> 0.14056981 | AC4: =Z4/K4 -> -1.5041721 | AD4: =Z4/J4 -> -0.21144119 | AE4: =Q4/J4 -> 0.59281209
B5: 05-11.01 очки | D5: =J5-SUM(L5:T5)+U5+V5+W5 -> 15399.171 | E5: ='Юнит 05-11.01'!K$26 -> 74 | F5: ='Юнит 05-11.01'!P$26 -> 58 | G5: ='Юнит 05-11.01'!Q$26 -> 4 | H5: ='Юнит 05-11.01'!S$26 -> 92160 | I5: ='Юнит 05-11.01'!T$26 -> -6799 | J5: =H5+I5 -> 85361 | K5: ='Юнит 05-11.01'!W$26 -> 7651.8 | L5: ='Юнит 05-11.01'!Z$26 -> 9950.27 | M5: ='Юнит 05-11.01'!X$26 -> 36705.23 | Q5: ='Юнит 05-11.01'!AA$26 -> 20067.069 | R5: 5 | S5: 1918.46 | T5: 1315.8 | X5: =2656.15*J5/SUM($J$3:$J$12) -> 359.93088 | Y5: =J5-SUM(L5:T5)-K5-V5+U5+W5 -> 7747.3709 | Z5: =Y5-X5 -> 7387.44 | AB5: =K5/J5 -> 0.089640468 | AC5: =Z5/K5 -> 0.96545127 | AD5: =Z5/J5 -> 0.086543504 | AE5: =Q5/J5 -> 0.23508475
B6: 05-11.01 туники | D6: =J6-SUM(L6:T6)+U6+V6+W6 -> 4110.6391 | E6: ='Юнит 05-11.01'!K$49 -> 4 | F6: ='Юнит 05-11.01'!P$49 -> 2 | G6: ='Юнит 05-11.01'!Q$49 -> 0 | H6: ='Юнит 05-11.01'!S$49 -> 10524 | I6: ='Юнит 05-11.01'!T$49 -> 0 | J6: =H6+I6 -> 10524 | K6: ='Юнит 05-11.01'!W$49 -> 1329 | L6: ='Юнит 05-11.01'!Z$49 -> 907.3 | M6: ='Юнит 05-11.01'!X$49 -> 4525.32 | Q6: ='Юнит 05-11.01'!AA$49 -> 980.7409 | X6: =2656.15*J6/SUM($J$3:$J$12) -> 44.375213 | Y6: =J6-SUM(L6:T6)-K6-V6+U6+W6 -> 2781.6391 | Z6: =Y6-X6 -> 2737.2639 | AB6: =K6/J6 -> 0.12628278 | AC6: =Z6/K6 -> 2.0596417 | AD6: =Z6/J6 -> 0.26009729 | AE6: =Q6/J6 -> 0.093190888
B7: 12-18.01 очки | D7: =J7-SUM(L7:T7)+U7+V7+W7 -> 29545.798 | E7: ='Юнит 12-18.01'!K$26 -> 96 | F7: ='Юнит 12-18.01'!P$26 -> 56 | G7: ='Юнит 12-18.01'!Q$26 -> 0 | H7: ='Юнит 12-18.01'!S$26 -> 91762 | I7: ='Юнит 12-18.01'!T$26 -> 0 | J7: =H7+I7 -> 91762 | K7: ='Юнит 12-18.01'!W$26 -> 7841.91 | L7: ='Юнит 12-18.01'!Z$26 -> 9811.64 | M7: ='Юнит 12-18.01'!X$26 -> 39457.66 | Q7: ='Юнит 12-18.01'!AA$26 -> 18818.032 | S7: 2168.87 | T7: 800 | V7: 7000 | W7: 1840 | X7: =2656.15*J7/SUM($J$3:$J$12) -> 386.92116 | Y7: =J7-SUM(L7:T7)-K7-V7+U7+W7 -> 7703.8881 | Z7: =Y7-X7 -> 7316.967 | AB7: =K7/J7 -> 0.085459231 | AC7: =Z7/K7 -> 0.93305929 | AD7: =Z7/J7 -> 0.07973853 | AE7: =Q7/J7 -> 0.20507434
B8: 12-18.01 туники | D8: =J8-SUM(L8:T8)+U8+V8+W8 -> 4732.6119 | E8: ='Юнит 12-18.01'!K$49 -> 30 | F8: ='Юнит 12-18.01'!P$49 -> 5 | G8: ='Юнит 12-18.01'!Q$49 -> 0 | H8: ='Юнит 12-18.01'!S$49 -> 21020 | I8: ='Юнит 12-18.01'!T$49 -> 0 | J8: =H8+I8 -> 21020 | K8: ='Юнит 12-18.01'!W$49 -> 3435 | L8: ='Юнит 12-18.01'!Z$49 -> 1528.99 | M8: ='Юнит 12-18.01'!X$49 -> 9038.6 | Q8: ='Юнит 12-18.01'!AA$49 -> 5719.7981 | X8: =2656.15*J8/SUM($J$3:$J$12) -> 88.632363 | Y8: =J8-SUM(L8:T8)-K8-V8+U8+W8 -> 1297.6119 | Z8: =Y8-X8 -> 1208.9795 | AB8: =K8/J8 -> 0.16341579 | AC8: =Z8/K8 -> 0.3519591 | AD8: =Z8/J8 -> 0.057515676 | AE8: =Q8/J8 -> 0.27211219
B9: 19-25.01 очки | D9: =J9-SUM(L9:T9)+U9+V9+W9 -> 21740.787 | E9: ='Юнит 19-25.01'!K$26 -> 119 | F9: ='Юнит 19-25.01'!P$26 -> 64 | G9: ='Юнит 19-25.01'!Q$26 -> 1 | H9: ='Юнит 19-25.01'!S$26 -> 104586 | I9: ='Юнит 19-25.01'!T$26 -> -1670 | J9: =H9+I9 -> 102916 | K9: ='Юнит 19-25.01'!W$26 -> 9494.98 | L9: ='Юнит 19-25.01'!Z$26 -> 12870.13 | M9: ='Юнит 19-25.01'!X$26 -> 44253.88 | Q9: ='Юнит 19-25.01'!AA$26 -> 25263.883 | R9: 15 | S9: 3536.42 | T9: 2235.9 | V9: 7000 | X9: =2656.15*J9/SUM($J$3:$J$12) -> 433.95282 | Y9: =J9-SUM(L9:T9)-K9-V9+U9+W9 -> -1754.1928 | Z9: =Y9-X9 -> -2188.1456 | AB9: =K9/J9 -> 0.092259513 | AC9: =Z9/K9 -> -0.23045289 | AD9: =Z9/J9 -> -0.021261472 | AE9: =Q9/J9 -> 0.24548061
B10: 19-25.01 туники | D10: =J10-SUM(L10:T10)+U10+V10+W10 -> 13844.323 | E10: ='Юнит 19-25.01'!K$49 -> 66 | F10: ='Юнит 19-25.01'!P$49 -> 18 | G10: ='Юнит 19-25.01'!Q$49 -> 4 | H10: ='Юнит 19-25.01'!S$49 -> 80413 | I10: ='Юнит 19-25.01'!T$49 -> -17932 | J10: =H10+I10 -> 62481 | K10: ='Юнит 19-25.01'!W$49 -> 9468 | L10: ='Юнит 19-25.01'!Z$49 -> 6390.87 | M10: ='Юнит 19-25.01'!X$49 -> 26866.83 | Q10: ='Юнит 19-25.01'!AA$49 -> 15378.977 | X10: =2656.15*J10/SUM($J$3:$J$12) -> 263.45569 | Y10: =J10-SUM(L10:T10)-K10-V10+U10+W10 -> 4376.3228 | Z10: =Y10-X10 -> 4112.8671 | AB10: =K10/J10 -> 0.15153407 | AC10: =Z10/K10 -> 0.43439661 | AD10: =Z10/J10 -> 0.065825885 | AE10: =Q10/J10 -> 0.24613846
B11: 26-31.01 очки | D11: =J11-SUM(L11:T11)+U11+V11+W11 -> 23967.429 | E11: ='Юнит 26-31.01'!K$26 -> 100 | F11: ='Юнит 26-31.01'!P$26 -> 72 | G11: ='Юнит 26-31.01'!Q$26 -> 3 | H11: ='Юнит 26-31.01'!S$26 -> 120331 | I11: ='Юнит 26-31.01'!T$26 -> -4419 | J11: =H11+I11 -> 115912 | K11: ='Юнит 26-31.01'!W$26 -> 10470.94 | L11: ='Юнит 26-31.01'!Z$26 -> 13196.61 | M11: ='Юнит 26-31.01'!X$26 -> 49842.16 | Q11: ='Юнит 26-31.01'!AA$26 -> 19493.871 | R11: 25 | S11: 2141.43 | T11: 7245.5 | X11: =2656.15*J11/SUM($J$3:$J$12) -> 488.7514 | Y11: =J11-SUM(L11:T11)-K11-V11+U11+W11 -> 13496.489 | Z11: =Y11-X11 -> 13007.738 | AB11: =K11/J11 -> 0.090335254 | AC11: =Z11/K11 -> 1.2422703 | AD11: =Z11/J11 -> 0.1122208 | AE11: =Q11/J11 -> 0.16817819
B12: 26-31.01 туники | D12: =J12-SUM(L12:T12)+U12+V12+W12 -> 27742.191 | E12: ='Юнит 26-31.01'!K$49 -> 60 | F12: ='Юнит 26-31.01'!P$49 -> 20 | G12: ='Юнит 26-31.01'!Q$49 -> 0 | H12: ='Юнит 26-31.01'!S$49 -> 89730 | I12: ='Юнит 26-31.01'!T$49 -> 0 | J12: =H12+I12 -> 89730 | K12: ='Юнит 26-31.01'!W$49 -> 13335 | L12: ='Юнит 26-31.01'!Z$49 -> 8653.99 | M12: ='Юнит 26-31.01'!X$49 -> 38583.9 | Q12: ='Юнит 26-31.01'!AA$49 -> 13258.459 | S12: 1491.46 | X12: =2656.15*J12/SUM($J$3:$J$12) -> 378.35309 | Y12: =J12-SUM(L12:T12)-K12-V12+U12+W12 -> 14407.191 | Z12: =Y12-X12 -> 14028.838 | AB12: =K12/J12 -> 0.1486125 | AC12: =Z12/K12 -> 1.0520313 | AD12: =Z12/J12 -> 0.15634501 | AE12: =Q12/J12 -> 0.14775949
A13: Февраль | B13: 01.02 очки | D13: =J13-SUM(L13:T13)+U13+V13 -> 1221.3769 | E13: ='Юнит 01.02'!K$26 -> 19 | F13: ='Юнит 01.02'!P$26 -> 8 | G13: ='Юнит 01.02'!Q$26 -> 1 | H13: ='Юнит 01.02'!S$26 -> 13169 | I13: ='Юнит 01.02'!T$26 -> -1655 | J13: =H13+I13 -> 11514 | K13: ='Юнит 01.02'!W$26 -> 1054.68 | L13: ='Юнит 01.02'!Z$26 -> 1614.84 | M13: ='Юнит 01.02'!X$26 -> 4951.02 | Q13: ='Юнит 01.02'!AA$26 -> 3338.9931 | S13: 387.77 | W13: 902 | X13: =4921.38*J13/SUM($J$13:$J$22) -> 52.083983 | Y13: =J13-SUM(L13:T13)-K13-V13+U13+W13 -> 1068.6969 | Z13: =J13-SUM(L13:T13)-K13-X13+U13+W13-V13 -> 1016.6129 | AA13: =SUM(Z13:Z22) -> 147164.97 | AB13: =K13/J13 -> 0.091599792 | AC13: =Z13/K13 -> 0.9639065 | AD13: =Z13/J13 -> 0.088293634 | AE13: =Q13/J13 -> 0.28999419
B14: 01.02 туники | D14: =J14-SUM(L14:T14)+U14+V14+W14 -> -3647.3769 | E14: ='Юнит 01.02'!K$49 -> 7 | F14: ='Юнит 01.02'!P$49 -> 1 | G14: ='Юнит 01.02'!Q$49 -> 0 | H14: ='Юнит 01.02'!S$49 -> 4940 | I14: ='Юнит 01.02'!T$49 -> 0 | J14: =H14+I14 -> 4940 | K14: ='Юнит 01.02'!W$49 -> 687 | L14: ='Юнит 01.02'!Z$49 -> 1483.67 | M14: ='Юнит 01.02'!X$49 -> 2124.2 | Q14: ='Юнит 01.02'!AA$49 -> 4567.9469 | R14: 5 | S14: 406.56 | X14: =4921.38*J14/SUM($J$13:$J$22) -> 22.346263 | Y14: =J14-SUM(L14:T14)-K14-V14+U14+W14 -> -4334.3769 | Z14: =J14-SUM(L14:T14)-K14-X14+U14+W14-V14 -> -4356.7232 | AB14: =K14/J14 -> 0.13906883 | AC14: =Z14/K14 -> -6.341664 | AD14: =Z14/J14 -> -0.88192776 | AE14: =Q14/J14 -> 0.92468561
B15: 02-08.02 очки | D15: =J15-SUM(L15:T15)+U15+V15 -> 19261.798 | E15: ='Юнит 02-08.02'!K$26 -> 131 | F15: ='Юнит 02-08.02'!P$26 -> 65 | G15: ='Юнит 02-08.02'!Q$26 -> 5 | H15: ='Юнит 02-08.02'!S$26 -> 119818 | I15: ='Юнит 02-08.02'!T$26 -> -9187 | J15: =H15+I15 -> 110631 | K15: ='Юнит 02-08.02'!W$26 -> 9043.72 | L15: ='Юнит 02-08.02'!Z$26 -> 13862.81 | M15: ='Юнит 02-08.02'!X$26 -> 47571.33 | Q15: ='Юнит 02-08.02'!AA$26 -> 26854.642 | S15: 3080.42 | X15: =4921.38*J15/SUM($J$13:$J$22) -> 500.44321 | Y15: =J15-SUM(L15:T15)-K15-V15+U15+W15 -> 10218.078 | Z15: =J15-SUM(L15:T15)-K15-X15+U15+W15-V15 -> 9717.6347 | AB15: =K15/J15 -> 0.081746708 | AC15: =Z15/K15 -> 1.0745174 | AD15: =Z15/J15 -> 0.087838262 | AE15: =Q15/J15 -> 0.24274066
B16: 02-08.02 туники | D16: =J16-SUM(L16:T16)+U16+V16+W16 -> 28854.102 | E16: ='Юнит 02-08.02'!K$49 -> 68 | F16: ='Юнит 02-08.02'!P$49 -> 24 | G16: ='Юнит 02-08.02'!Q$49 -> 1 | H16: ='Юнит 02-08.02'!S$49 -> 114048 | I16: ='Юнит 02-08.02'!T$49 -> -4178 | J16: =H16+I16 -> 109870 | K16: ='Юнит 02-08.02'!W$49 -> 14496 | L16: ='Юнит 02-08.02'!Z$49 -> 11481.36 | M16: ='Юнит 02-08.02'!X$49 -> 47244.1 | Q16: ='Юнит 02-08.02'!AA$49 -> 20002.458 | R16: 20 | S16: 2267.98 | X16: =4921.38*J16/SUM($J$13:$J$22) -> 497.0008 | Y16: =J16-SUM(L16:T16)-K16-V16+U16+W16 -> 14358.102 | Z16: =J16-SUM(L16:T16)-K16-X16+U16+W16-V16 -> 13861.101 | AB16: =K16/J16 -> 0.13193774 | AC16: =Z16/K16 -> 0.9562018 | AD16: =Z16/J16 -> 0.12615911 | AE16: =Q16/J16 -> 0.18205568
B17: 09-15.02 очки | D17: =J17-SUM(L17:T17)+U17+V17 -> 22441.752 | E17: ='Юнит 09-15.02'!K$26 -> 121 | F17: ='Юнит 09-15.02'!P$26 -> 60 | G17: ='Юнит 09-15.02'!Q$26 -> 2 | H17: ='Юнит 09-15.02'!S$26 -> 125456 | I17: ='Юнит 09-15.02'!T$26 -> -4877 | J17: =H17+I17 -> 120579 | K17: ='Юнит 09-15.02'!W$26 -> 7423.19 | L17: ='Юнит 09-15.02'!Z$26 -> 13659.9 | M17: ='Юнит 09-15.02'!X$26 -> 51848.97 | Q17: ='Юнит 09-15.02'!AA$26 -> 26940.334 | S17: 3309.41 | T17: =3250.8*F17/(F17+F18) -> 2378.6341 | X17: =4921.38*J17/SUM($J$13:$J$22) -> 545.44334 | Y17: =J17-SUM(L17:T17)-K17-V17+U17+W17 -> 15018.562 | Z17: =J17-SUM(L17:T17)-K17-X17+U17+W17-V17 -> 14473.119 | AB17: =K17/J17 -> 0.061562876 | AC17: =Z17/K17 -> 1.9497169 | AD17: =Z17/J17 -> 0.12003018 | AE17: =Q17/J17 -> 0.22342476
B18: 09-15.02 туники | D18: =J18-SUM(L18:T18)+U18+V18+W18 -> 28836.778 | E18: ='Юнит 09-15.02'!K$49 -> 54 | F18: ='Юнит 09-15.02'!P$49 -> 22 | G18: ='Юнит 09-15.02'!Q$49 -> 2 | H18: ='Юнит 09-15.02'!S$49 -> 110799 | I18: ='Юнит 09-15.02'!T$49 -> -9047 | J18: =H18+I18 -> 101752 | K18: ='Юнит 09-15.02'!W$49 -> 13275 | L18: ='Юнит 09-15.02'!Z$49 -> 8720.99 | M18: ='Юнит 09-15.02'!X$49 -> 43753.36 | Q18: ='Юнит 09-15.02'!AA$49 -> 17681.836 | R18: 25 | S18: 1861.87 | T18: =3250.8*F18/(F17+F18) -> 872.16585 | X18: =4921.38*J18/SUM($J$13:$J$22) -> 460.27874 | Y18: =J18-SUM(L18:T18)-K18-V18+U18+W18 -> 15561.778 | Z18: =J18-SUM(L18:T18)-K18-X18+U18+W18-V18 -> 15101.499 | AB18: =K18/J18 -> 0.13046427 | AC18: =Z18/K18 -> 1.1375894 | AD18: =Z18/J18 -> 0.14841476 | AE18: =Q18/J18 -> 0.17377385
B19: 16-22.02 очки | D19: =J19-SUM(L19:T19)+U19+V19 -> 37691.629 | E19: ='Юнит 16-22.02'!K$26 -> 172 | F19: ='Юнит 16-22.02'!P$26 -> 79 | G19: ='Юнит 16-22.02'!Q$26 -> 2 | H19: ='Юнит 16-22.02'!S$26 -> 173410 | I19: ='Юнит 16-22.02'!T$26 -> -4800 | J19: =H19+I19 -> 168610 | K19: ='Юнит 16-22.02'!W$26 -> 11163.54 | L19: ='Юнит 16-22.02'!Z$26 -> 17063.86 | M19: ='Юнит 16-22.02'!X$26 -> 72502.3 | Q19: ='Юнит 16-22.02'!AA$26 -> 37347.301 | S19: 4004.91 | W19: 972 | X19: =4921.38*J19/SUM($J$13:$J$22) -> 762.71325 | Y19: =J19-SUM(L19:T19)-K19-V19+U19+W19 -> 27500.089 | Z19: =J19-SUM(L19:T19)-K19-X19+U19+W19-V19 -> 26737.376 | AB19: =K19/J19 -> 0.06620924 | AC19: =Z19/K19 -> 2.3950625 | AD19: =Z19/J19 -> 0.15857527 | AE19: =Q19/J19 -> 0.2215011
B20: 16-22.02 туники | D20: =J20-SUM(L20:T20)+U20+V20+W20 -> 43858.251 | E20: ='Юнит 16-22.02'!K$49 -> 78 | F20: ='Юнит 16-22.02'!P$49 -> 27 | G20: ='Юнит 16-22.02'!Q$49 -> 2 | H20: ='Юнит 16-22.02'!S$49 -> 141378 | I20: ='Юнит 16-22.02'!T$49 -> -10000 | J20: =H20+I20 -> 131378 | K20: ='Юнит 16-22.02'!W$49 -> 15420 | L20: ='Юнит 16-22.02'!Z$49 -> 10936.38 | M20: ='Юнит 16-22.02'!X$49 -> 56492.54 | Q20: ='Юнит 16-22.02'!AA$49 -> 21117.479 | R20: 20 | S20: 2139.35 | W20: 3186 | X20: =4921.38*J20/SUM($J$13:$J$22) -> 594.29299 | Y20: =J20-SUM(L20:T20)-K20-V20+U20+W20 -> 28438.251 | Z20: =J20-SUM(L20:T20)-K20-X20+U20+W20-V20 -> 27843.958 | AB20: =K20/J20 -> 0.11737125 | AC20: =Z20/K20 -> 1.8057041 | AD20: =Z20/J20 -> 0.21193775 | AE20: =Q20/J20 -> 0.16073832
B21: 23-28.02 очки | D21: =J21-SUM(L21:T21)+U21+V21 -> 51268.243 | E21: ='Юнит 23-28.02'!K$26 -> 200 | F21: ='Юнит 23-28.02'!P$26 -> 104 | G21: ='Юнит 23-28.02'!Q$26 -> 6 | H21: ='Юнит 23-28.02'!S$26 -> 230456 | I21: ='Юнит 23-28.02'!T$26 -> -14068 | J21: =H21+I21 -> 216388 | K21: ='Юнит 23-28.02'!W$26 -> 14285.64 | L21: ='Юнит 23-28.02'!Z$26 -> 18630.99 | M21: ='Юнит 23-28.02'!X$26 -> 93046.84 | Q21: ='Юнит 23-28.02'!AA$26 -> 49038.397 | S21: 4403.53 | X21: =4921.38*J21/SUM($J$13:$J$22) -> 978.83871 | Y21: =J21-SUM(L21:T21)-K21-V21+U21+W21 -> 36982.603 | Z21: =J21-SUM(L21:T21)-K21-X21+U21+W21-V21 -> 36003.764 | AB21: =K21/J21 -> 0.066018633 | AC21: =Z21/K21 -> 2.5202766 | AD21: =Z21/J21 -> 0.16638522 | AE21: =Q21/J21 -> 0.22662253
B22: 23-28.02 туники | D22: =J22-SUM(L22:T22)+U22+V22+W22 -> 20741.567 | E22: ='Юнит 23-28.02'!K$49 -> 73 | F22: ='Юнит 23-28.02'!P$49 -> 22 | G22: ='Юнит 23-28.02'!Q$49 -> 1 | H22: ='Юнит 23-28.02'!S$49 -> 118788 | I22: ='Юнит 23-28.02'!T$49 -> -6500 | J22: =H22+I22 -> 112288 | K22: ='Юнит 23-28.02'!W$49 -> 13467 | L22: ='Юнит 23-28.02'!Z$49 -> 9725.32 | M22: ='Юнит 23-28.02'!X$49 -> 48283.84 | Q22: ='Юнит 23-28.02'!AA$49 -> 30882.493 | R22: 10 | S22: 2644.78 | X22: =4921.38*J22/SUM($J$13:$J$22) -> 507.93871 | Y22: =J22-SUM(L22:T22)-K22-V22+U22+W22 -> 7274.5671 | Z22: =J22-SUM(L22:T22)-K22-X22+U22+W22-V22 -> 6766.6284 | AB22: =K22/J22 -> 0.11993267 | AC22: =Z22/K22 -> 0.50245997 | AD22: =Z22/J22 -> 0.060261367 | AE22: =Q22/J22 -> 0.27502933
A23: Март | B23: 01.03 очки | C23: 9 | D23: =J23-SUM(L23:T23)+U23+V23 -> 9573.6928 | E23: ='Юнит 01.03'!K$26 -> 33 | F23: ='Юнит 01.03'!P$26 -> 19 | G23: ='Юнит 01.03'!Q$26 -> 0 | H23: ='Юнит 01.03'!S$26 -> 40846 | I23: ='Юнит 01.03'!T$26 -> 0 | J23: =H23+I23 -> 40846 | K23: ='Юнит 01.03'!W$26 -> 2795.01 | L23: ='Юнит 01.03'!Z$26 -> 4137.97 | M23: ='Юнит 01.03'!X$26 -> 17563.78 | Q23: ='Юнит 01.03'!AA$26 -> 8589.2572 | S23: 981.3 | W23: 2592 | X23: ='Юнит 01.03'!AD$26 -> 174.8667 | Y23: =J23-SUM(L23:T23)-K23-V23+U23+W23 -> 9370.6828 | Z23: =J23-SUM(L23:T23)-K23-X23+U23+W23-V23 -> 9195.8161 | AA23: =SUM(Z23:Z38) -> 330669.81 | AB23: =K23/J23 -> 0.068427998 | AC23: =Z23/K23 -> 3.2900834 | AD23: =Z23/J23 -> 0.22513382 | AE23: =Q23/J23 -> 0.21028393
B24: 01.03 туники | C24: 9 | D24: =J24-SUM(L24:T24)+U24+V24+W24 -> 11464.637 | E24: ='Юнит 01.03'!K$49 -> 10 | F24: ='Юнит 01.03'!P$49 -> 5 | G24: ='Юнит 01.03'!Q$49 -> 0 | H24: ='Юнит 01.03'!S$49 -> 27900 | I24: ='Юнит 01.03'!T$49 -> 0 | J24: =H24+I24 -> 27900 | K24: ='Юнит 01.03'!W$49 -> 3240 | L24: ='Юнит 01.03'!Z$49 -> 1772.61 | M24: ='Юнит 01.03'!X$49 -> 11997 | Q24: ='Юнит 01.03'!AA$49 -> 2452.0328 | S24: 213.72 | X24: ='Юнит 01.03'!AD$49 -> 119.4433 | Y24: =J24-SUM(L24:T24)-K24-V24+U24+W24 -> 8224.6372 | Z24: =J24-SUM(L24:T24)-K24-X24+U24+W24-V24 -> 8105.1939 | AB24: =K24/J24 -> 0.11612903 | AC24: =Z24/K24 -> 2.5016031 | AD24: =Z24/J24 -> 0.29050874 | AE24: =Q24/J24 -> 0.08788648
B25: 02-08.03 очки | C25: 10 | D25: =J25-SUM(L25:T25)+U25+V25 -> 43006.268 | E25: ='Юнит 02-08.03'!K$26 -> 197 | F25: ='Юнит 02-08.03'!P$26 -> 103 | G25: ='Юнит 02-08.03'!Q$26 -> 9 | H25: ='Юнит 02-08.03'!S$26 -> 247424 | I25: ='Юнит 02-08.03'!T$26 -> -18379 | J25: =H25+I25 -> 229045 | K25: ='Юнит 02-08.03'!W$26 -> 13689.96 | L25: ='Юнит 02-08.03'!Z$26 -> 23987.37 | M25: ='Юнит 02-08.03'!X$26 -> 98489.35 | Q25: ='Юнит 02-08.03'!AA$26 -> 55823.055 | R25: 40 | S25: 5595.07 | T25: =2818.8*F25/(F25+F26) -> 2103.887 | X25: ='Юнит 02-08.03'!AD$26 -> 946.88488 | Y25: =J25-SUM(L25:T25)-K25-V25+U25+W25 -> 29316.308 | Z25: =J25-SUM(L25:T25)-K25-X25+U25+W25-V25 -> 28369.423 | AB25: =K25/J25 -> 0.05976974 | AC25: =Z25/K25 -> 2.0722795 | AD25: =Z25/J25 -> 0.12385961 | AE25: =Q25/J25 -> 0.24372091
B26: 02-08.03 туники | C26: 10 | D26: =J26-SUM(L26:T26)+U26+V26+W26 -> 11946.392 | E26: ='Юнит 02-08.03'!K$49 -> 64 | F26: ='Юнит 02-08.03'!P$49 -> 35 | G26: ='Юнит 02-08.03'!Q$49 -> 11 | H26: ='Юнит 02-08.03'!S$49 -> 173194 | I26: ='Юнит 02-08.03'!T$49 -> -55802 | J26: =H26+I26 -> 117392 | K26: ='Юнит 02-08.03'!W$49 -> 14478 | L26: ='Юнит 02-08.03'!Z$49 -> 12952.31 | M26: ='Юнит 02-08.03'!X$49 -> 50478.56 | Q26: ='Юнит 02-08.03'!AA$49 -> 39094.165 | R26: 45 | S26: 2160.66 | T26: =2818.8*F26/(F25+F26) -> 714.91304 | X26: ='Юнит 02-08.03'!AD$49 -> 485.30512 | Y26: =J26-SUM(L26:T26)-K26-V26+U26+W26 -> -2531.6083 | Z26: =J26-SUM(L26:T26)-K26-X26+U26+W26-V26 -> -3016.9135 | AB26: =K26/J26 -> 0.12333038 | AC26: =Z26/K26 -> -0.20837916 | AD26: =Z26/J26 -> -0.025699481 | AE26: =Q26/J26 -> 0.3330224
B27: 09-15.03 очки | C27: 11 | D27: =J27-SUM(L27:T27)+U27+V27 -> 105076.48 | E27: ='Юнит 09-15.03'!K$26 -> 349 | F27: ='Юнит 09-15.03'!P$26 -> 151 | G27: ='Юнит 09-15.03'!Q$26 -> 7 | H27: ='Юнит 09-15.03'!S$26 -> 390195 | I27: ='Юнит 09-15.03'!T$26 -> -18400 | J27: =H27+I27 -> 371795 | K27: ='Юнит 09-15.03'!W$26 -> 20433.06 | L27: ='Юнит 09-15.03'!Z$26 -> 31144.36 | M27: ='Юнит 09-15.03'!X$26 -> 159871.85 | Q27: ='Юнит 09-15.03'!AA$26 -> 66464.463 | R27: 55 | S27: 7274.73 | T27: =2350.4*F27/(F27+F28) -> 1908.1204 | X27: ='Юнит 09-15.03'!AD$26 -> 1429.6569 | Y27: =J27-SUM(L27:T27)-K27-V27+U27+W27 -> 84643.417 | Z27: =J27-SUM(L27:T27)-K27-X27+U27+W27-V27 -> 83213.76 | AB27: =K27/J27 -> 0.054957867 | AC27: =Z27/K27 -> 4.072506 | AD27: =Z27/J27 -> 0.22381624 | AE27: =Q27/J27 -> 0.17876642
B28: 09-15.03 туники | C28: 11 | D28: =J28-SUM(L28:T28)+U28+V28+W28 -> 30545.503 | E28: ='Юнит 09-15.03'!K$49 -> 81 | F28: ='Юнит 09-15.03'!P$49 -> 35 | G28: ='Юнит 09-15.03'!Q$49 -> 3 | H28: ='Юнит 09-15.03'!S$49 -> 165276 | I28: ='Юнит 09-15.03'!T$49 -> -15138 | J28: =H28+I28 -> 150138 | K28: ='Юнит 09-15.03'!W$49 -> 20184 | L28: ='Юнит 09-15.03'!Z$49 -> 13386.34 | M28: ='Юнит 09-15.03'!X$49 -> 64559.34 | Q28: ='Юнит 09-15.03'!AA$49 -> 38590.547 | R28: 25 | S28: 2588.99 | T28: =2350.4*F28/(F27+F28) -> 442.27957 | X28: ='Юнит 09-15.03'!AD$49 -> 577.32307 | Y28: =J28-SUM(L28:T28)-K28-V28+U28+W28 -> 10361.503 | Z28: =J28-SUM(L28:T28)-K28-X28+U28+W28-V28 -> 9784.1801 | AB28: =K28/J28 -> 0.13443632 | AC28: =Z28/K28 -> 0.48474931 | AD28: =Z28/J28 -> 0.065167913 | AE28: =Q28/J28 -> 0.25703384
B29: 16-22.03 очки | C29: 12 | D29: =J29-SUM(L29:T29)+U29+V29 -> 140853.44 | E29: ='Юнит 16-22.03'!K$26 -> 335 | F29: ='Юнит 16-22.03'!P$26 -> 174 | G29: ='Юнит 16-22.03'!Q$26 -> 3 | H29: ='Юнит 16-22.03'!S$26 -> 466726 | I29: ='Юнит 16-22.03'!T$26 -> -8150 | J29: =H29+I29 -> 458576 | K29: ='Юнит 16-22.03'!W$26 -> 24482.7 | L29: ='Юнит 16-22.03'!Z$26 -> 38820.12 | M29: ='Юнит 16-22.03'!X$26 -> 197187.68 | Q29: ='Юнит 16-22.03'!AA$26 -> 72779.225 | R29: 230 | S29: 8705.53 | W29: 1431 | X29: ='Юнит 16-22.03'!AD$26 -> 1891.4078 | Y29: =J29-SUM(L29:T29)-K29-V29+U29+W29 -> 117801.74 | Z29: =J29-SUM(L29:T29)-K29-X29+U29+W29-V29 -> 115910.34 | AB29: =K29/J29 -> 0.053388533 | AC29: =Z29/K29 -> 4.7343772 | AD29: =Z29/J29 -> 0.25276145 | AE29: =Q29/J29 -> 0.15870701
B30: 16-22.03 туники | C30: 12 | D30: =J30-SUM(L30:T30)+U30+V30+W30 -> 19370.855 | E30: ='Юнит 16-22.03'!K$49 -> 46 | F30: ='Юнит 16-22.03'!P$49 -> 27 | G30: ='Юнит 16-22.03'!Q$49 -> 6 | H30: ='Юнит 16-22.03'!S$49 -> 109484 | I30: ='Юнит 16-22.03'!T$49 -> -29016 | J30: =H30+I30 -> 80468 | K30: ='Юнит 16-22.03'!W$49 -> 12897 | L30: ='Юнит 16-22.03'!Z$49 -> 9001.49 | M30: ='Юнит 16-22.03'!X$49 -> 34601.24 | Q30: ='Юнит 16-22.03'!AA$49 -> 16067.285 | R30: 30 | S30: 1397.13 | X30: ='Юнит 16-22.03'!AD$49 -> 331.89221 | Y30: =J30-SUM(L30:T30)-K30-V30+U30+W30 -> 6473.8555 | Z30: =J30-SUM(L30:T30)-K30-X30+U30+W30-V30 -> 6141.9633 | AB30: =K30/J30 -> 0.16027489 | AC30: =Z30/K30 -> 0.47623193 | AD30: =Z30/J30 -> 0.076328022 | AE30: =Q30/J30 -> 0.19967297
B31: 23-29.03 очки | C31: 13 | D31: =J31-SUM(L31:T31)+U31+V31 -> 96137.006 | E31: ='Юнит 23-29.03'!K$26 -> 301 | F31: ='Юнит 23-29.03'!P$26 -> 135 | G31: ='Юнит 23-29.03'!Q$26 -> 4 | H31: ='Юнит 23-29.03'!S$26 -> 367961 | I31: ='Юнит 23-29.03'!T$26 -> -10800 | J31: =H31+I31 -> 357161 | K31: ='Юнит 23-29.03'!W$26 -> 18526.35 | L31: ='Юнит 23-29.03'!Z$26 -> 34591.78 | M31: ='Юнит 23-29.03'!X$26 -> 153579.23 | Q31: ='Юнит 23-29.03'!AA$26 -> 64198.067 | R31: 65 | S31: 7549.42 | T31: =1148.4*F31/(F31+F32) -> 1040.4966 | X31: ='Юнит 23-29.03'!AD$26 -> 1665.1657 | Y31: =J31-SUM(L31:T31)-K31-V31+U31+W31 -> 77610.656 | Z31: =J31-SUM(L31:T31)-K31-X31+U31+W31-V31 -> 75945.491 | AB31: =K31/J31 -> 0.051871145 | AC31: =Z31/K31 -> 4.0993229 | AD31: =Z31/J31 -> 0.21263657 | AE31: =Q31/J31 -> 0.17974546
B32: 23-29.03 туники | C32: 13 | D32: =J32-SUM(L32:T32)+U32+V32+W32 -> 5243.0235 | E32: ='Юнит 23-29.03'!K$49 -> 37 | F32: ='Юнит 23-29.03'!P$49 -> 14 | G32: ='Юнит 23-29.03'!Q$49 -> 2 | H32: ='Юнит 23-29.03'!S$49 -> 54641 | I32: ='Юнит 23-29.03'!T$49 -> -11000 | J32: =H32+I32 -> 43641 | K32: ='Юнит 23-29.03'!W$49 -> 8019 | L32: ='Юнит 23-29.03'!Z$49 -> 6060.65 | M32: ='Юнит 23-29.03'!X$49 -> 18765.63 | Q32: ='Юнит 23-29.03'!AA$49 -> 12301.373 | R32: 25 | S32: 1137.42 | T32: =1148.4*F32/(F31+F32) -> 107.90336 | X32: ='Юнит 23-29.03'!AD$49 -> 203.46426 | Y32: =J32-SUM(L32:T32)-K32-V32+U32+W32 -> -2775.9765 | Z32: =J32-SUM(L32:T32)-K32-X32+U32+W32-V32 -> -2979.4407 | AB32: =K32/J32 -> 0.18374923 | AC32: =Z32/K32 -> -0.37154767 | AD32: =Z32/J32 -> -0.068271596 | AE32: =Q32/J32 -> 0.28187652
B33: 30-31.03 очки | C33: 14 | D33: =J33-SUM(L33:T33)+U33+V33 -> 0 | E33: ='Юнит 30-31.03'!K$26 -> 0 | F33: ='Юнит 30-31.03'!P$26 -> 0 | G33: ='Юнит 30-31.03'!Q$26 -> 0 | H33: ='Юнит 30-31.03'!S$26 -> 0 | I33: ='Юнит 30-31.03'!T$26 -> 0 | J33: =H33+I33 -> 0 | K33: ='Юнит 30-31.03'!W$26 -> 0 | L33: ='Юнит 30-31.03'!Z$26 -> 0 | M33: ='Юнит 30-31.03'!X$26 -> 0 | Q33: ='Юнит 30-31.03'!AA$26 -> 0 | X33: ='Юнит 30-31.03'!AD$26 -> 0 | Y33: =J33-SUM(L33:T33)-K33-V33+U33+W33 -> 0 | Z33: =J33-SUM(L33:T33)-K33-X33+U33+W33-V33 -> 0 | AB33: =K33/J33 -> #DIV/0! | AC33: =Z33/K33 -> #DIV/0! | AD33: =Z33/J33 -> #DIV/0! | AE33: =Q33/J33 -> #DIV/0!
B34: 30-31.03 туники | C34: 14 | D34: =J34-SUM(L34:T34)+U34+V34+W34 -> 0 | E34: ='Юнит 30-31.03'!K$49 -> 0 | F34: ='Юнит 30-31.03'!P$49 -> 0 | G34: ='Юнит 30-31.03'!Q$49 -> 0 | H34: ='Юнит 30-31.03'!S$49 -> 0 | I34: ='Юнит 30-31.03'!T$49 -> 0 | J34: =H34+I34 -> 0 | K34: ='Юнит 30-31.03'!W$49 -> 0 | L34: ='Юнит 30-31.03'!Z$49 -> 0 | M34: ='Юнит 30-31.03'!X$49 -> 0 | Q34: ='Юнит 30-31.03'!AA$49 -> 0 | X34: ='Юнит 30-31.03'!AD$49 -> 0 | Y34: =J34-SUM(L34:T34)-K34-V34+U34+W34 -> 0 | Z34: =J34-SUM(L34:T34)-K34-X34+U34+W34-V34 -> 0 | AB34: =K34/J34 -> #DIV/0! | AC34: =Z34/K34 -> #DIV/0! | AD34: =Z34/J34 -> #DIV/0! | AE34: =Q34/J34 -> #DIV/0!
B35: 01-05.04 очки | C35: 15 | D35: =J35-SUM(L35:T35)+U35+V35 -> 0 | E35: ='Юнит 01-05.04'!K$26 -> 0 | F35: ='Юнит 01-05.04'!P$26 -> 0 | G35: ='Юнит 01-05.04'!Q$26 -> 0 | H35: ='Юнит 01-05.04'!S$26 -> 0 | I35: ='Юнит 01-05.04'!T$26 -> 0 | J35: =H35+I35 -> 0 | K35: ='Юнит 01-05.04'!W$26 -> 0 | L35: ='Юнит 01-05.04'!Z$26 -> 0 | M35: ='Юнит 01-05.04'!X$26 -> 0 | Q35: ='Юнит 01-05.04'!AA$26 -> 0 | X35: ='Юнит 01-05.04'!AD$26 -> 0 | Y35: =J35-SUM(L35:T35)-K35-V35+U35+W35 -> 0 | Z35: =J35-SUM(L35:T35)-K35-X35+U35+W35-V35 -> 0
B36: 01-05.04 туники | C36: 15 | D36: =J36-SUM(L36:T36)+U36+V36+W36 -> 0 | E36: ='Юнит 01-05.04'!K$49 -> 0 | F36: ='Юнит 01-05.04'!P$49 -> 0 | G36: ='Юнит 01-05.04'!Q$49 -> 0 | H36: ='Юнит 01-05.04'!S$49 -> 0 | I36: ='Юнит 01-05.04'!T$49 -> 0 | J36: =H36+I36 -> 0 | K36: ='Юнит 01-05.04'!W$49 -> 0 | L36: ='Юнит 01-05.04'!Z$49 -> 0 | M36: ='Юнит 01-05.04'!X$49 -> 0 | Q36: ='Юнит 01-05.04'!AA$49 -> 0 | X36: ='Юнит 01-05.04'!AD$49 -> 0 | Y36: =J36-SUM(L36:T36)-K36-V36+U36+W36 -> 0 | Z36: =J36-SUM(L36:T36)-K36-X36+U36+W36-V36 -> 0
A39: Итого | D39: =SUM(D3:D38) -> 873238.87 | E39: =SUM(E3:E38) -> 2974 | F39: =SUM(F3:F38) -> 1434 | G39: =SUM(G3:G38) -> 79 | H39: =SUM(H3:H38) -> 3856660 | I39: =SUM(I3:I38) -> -261817 | J39: =SUM(J3:J38) -> 3594843 | K39: =SUM(K3:K38) -> 307213.14 | ... AA39: =SUM(AA3:AA38) -> 531064.79 | AB39: =K39/J39 -> 0.085459404 | AC39: =Z39/K39 -> 1.7286526 | AD39: =Z39/J39 -> 0.14772962 | AE39: =Q39/J39 -> 0.2080796
H40: % от выручки за весь период | AA40: Маржинальность, % | AB40: Рентабельность, %
I41: =-I39/H39 -> 0.06788698 | J41: 0 | K41: =K39/$J$39 -> 0.085459404 | L41: =L39/$J$39 -> 0.097428583 | M41: =M39/$J$39 -> 0.43 | Q41: =Q39/$J$39 -> 0.2080796 | R41: =R39/$J$39 -> 0.00017803281 | S41: =S39/$J$39 -> 0.020633886 | T41: =T39/$J$39 -> 0.0060581505 | U41: =U39/$J$39 -> 0 | V41: =V39/$J$39 -> 0.0038944677 | X41: =X39/$J$39 -> 0.0042847323 | AA41: =Z39/K39 -> 1.7286526 | AB41: =Z39/J39 -> 0.14772962
A43: январь очки | D43: =D3+D5+D7+D9+D11 -> 99346.768 | E43: =E3+E5+E7+E9+E11 -> 433 | F43: =F3+F5+F7+F9+F11 -> 278 | G43: =G3+G5+G7+G9+G11 -> 8 | H43: =H3+H5+H7+H9+H11 -> 454817 | I43: =I3+I5+I7+I9+I11 -> -12888 | J43: =J3+J5+J7+J9+J11 -> 441929 | K43: =K3+K5+K7+K9+K11 -> 39988.29 | ... Z43: =Z3+Z5+Z7+Z9+Z11 -> 32040.052 | AA43: =Z43/K43 -> 0.80123587 | AB43: =Z43/J43 -> 0.072500452
...

Sheet АВС МАРТ
B2: ОЧКИ
C3: Прибыль | D3: % прибыль | E3: Доля | F3: ABC прибыль | G3: ABC кол-во | J3: Кол-во | K3: % кол-во | L3: Доля | M3: ABC кол-во
B4: черные с железкой классика | D4: =C4/C$26 -> #DIV/0! | E4: =D4 -> #DIV/0! | F4: =IF(AND(E4<=0),"C",IF(E4<=0.8,"A",IF(E4<=0.95,"B","C"))) -> #DIV/0! | G4: =VLOOKUP(B$4:B$25,I$4:M$25,5,0) -> #DIV/0! | I4: черные с железкой классика | K4: =J4/J$26 -> #DIV/0! | L4: =K4 -> #DIV/0! | M4: =_xlfn.IFS(L4<80%,"A",L4<=95%,"B",L4>95%,"C") -> #DIV/0!
B5: qs черные | D5: =C5/C$26 -> #DIV/0! | E5: =D5+E4 -> #DIV/0! | F5: =IF(AND(E5<=0),"C",IF(E5<=0.8,"A",IF(E5<=0.95,"B","C"))) -> #DIV/0! | G5: =VLOOKUP(B$4:B$25,I$4:M$25,5,0) -> #DIV/0! | I5: qs черные | K5: =J5/J$26 -> #DIV/0! | L5: =K5+L4 -> #DIV/0! | M5: =_xlfn.IFS(L5<80%,"A",L5<=95%,"B",L5>95%,"C") -> #DIV/0!
B6: qs синие | D6: =C6/C$26 -> #DIV/0! | E6: =D6+E5 -> #DIV/0! | F6: =IF(AND(E6<=0),"C",IF(E6<=0.8,"A",IF(E6<=0.95,"B","C"))) -> #DIV/0! | G6: =VLOOKUP(B$4:B$25,I$4:M$25,5,0) -> #DIV/0! | I6: qs синие | K6: =J6/J$26 -> #DIV/0! | L6: =K6+L5 -> #DIV/0! | M6: =_xlfn.IFS(L6<80%,"A",L6<=95%,"B",L6>95%,"C") -> #DIV/0!
B7: qs желтые | D7: =C7/C$26 -> #DIV/0! | E7: =D7+E6 -> #DIV/0! | F7: =IF(AND(E7<=0),"C",IF(E7<=0.8,"A",IF(E7<=0.95,"B","C"))) -> #DIV/0! | G7: =VLOOKUP(B$4:B$25,I$4:M$25,5,0) -> #DIV/0! | I7: qs желтые | K7: =J7/J$26 -> #DIV/0! | L7: =K7+L6 -> #DIV/0! | M7: =_xlfn.IFS(L7<80%,"A",L7<=95%,"B",L7>95%,"C") -> #DIV/0!
B8: qs коричневые | D8: =C8/C$26 -> #DIV/0! | E8: =D8+E7 -> #DIV/0! | F8: =IF(AND(E8<=0),"C",IF(E8<=0.8,"A",IF(E8<=0.95,"B","C"))) -> #DIV/0! | G8: =VLOOKUP(B$4:B$25,I$4:M$25,5,0) -> #DIV/0! | I8: qs коричневые | K8: =J8/J$26 -> #DIV/0! | L8: =K8+L7 -> #DIV/0! | M8: =_xlfn.IFS(L8<80%,"A",L8<=95%,"B",L8>95%,"C") -> #DIV/0!
B9: th желтый Сул | D9: =C9/C$26 -> #DIV/0! | E9: =D9+E8 -> #DIV/0! | F9: =IF(AND(E9<=0),"C",IF(E9<=0.8,"A",IF(E9<=0.95,"B","C"))) -> #DIV/0! | G9: =VLOOKUP(B$4:B$25,I$4:M$25,5,0) -> #DIV/0! | I9: th желтый Сул | K9: =J9/J$26 -> #DIV/0! | L9: =K9+L8 -> #DIV/0! | M9: =_xlfn.IFS(L9<80%,"A",L9<=95%,"B",L9>95%,"C") -> #DIV/0!
B10: flip желтые Сул | D10: =C10/C$26 -> #DIV/0! | E10: =D10+E9 -> #DIV/0! | F10: =IF(AND(E10<=0),"C",IF(E10<=0.8,"A",IF(E10<=0.95,"B","C"))) -> #DIV/0! | G10: =VLOOKUP(B$4:B$25,I$4:M$25,5,0) -> #DIV/0! | I10: flip желтые Сул | K10: =J10/J$26 -> #DIV/0! | L10: =K10+L9 -> #DIV/0! | M10: =_xlfn.IFS(L10<80%,"A",L10<=95%,"B",L10>95%,"C") -> #DIV/0!
B11: MR8854 C2 | D11: =C11/C$26 -> #DIV/0! | E11: =D11+E8 -> #DIV/0! | F11: =IF(AND(E11<=0),"C",IF(E11<=0.8,"A",IF(E11<=0.95,"B","C"))) -> #DIV/0! | G11: =VLOOKUP(B$4:B$25,I$4:M$25,5,0) -> #DIV/0! | I11: MR8854 C2 | K11: =J11/J$26 -> #DIV/0! | L11: =K11+L8 -> #DIV/0! | M11: =_xlfn.IFS(L11<80%,"A",L11<=95%,"B",L11>95%,"C") -> #DIV/0!
B12: MR 1819 черн | D12: =C12/C$26 -> #DIV/0! | E12: =D12+E11 -> #DIV/0! | F12: =IF(AND(E12<=0),"C",IF(E12<=0.8,"A",IF(E12<=0.95,"B","C"))) -> #DIV/0! | G12: =VLOOKUP(B$4:B$25,I$4:M$25,5,0) -> #DIV/0! | I12: MR 1819 черн | K12: =J12/J$26 -> #DIV/0! | L12: =K12+L11 -> #DIV/0! | M12: =_xlfn.IFS(L12<80%,"A",L12<=95%,"B",L12>95%,"C") -> #DIV/0!
B13: MR 1819 корич | D13: =C13/C$26 -> #DIV/0! | E13: =D13+E12 -> #DIV/0! | F13: =IF(AND(E13<=0),"C",IF(E13<=0.8,"A",IF(E13<=0.95,"B","C"))) -> #DIV/0! | G13: =VLOOKUP(B$4:B$25,I$4:M$25,5,0) -> #DIV/0! | I13: MR 1819 корич | K13: =J13/J$26 -> #DIV/0! | L13: =K13+L12 -> #DIV/0! | M13: =_xlfn.IFS(L13<80%,"A",L13<=95%,"B",L13>95%,"C") -> #DIV/0! | P13: A | Q13: 0.8
B14: MR Р1874 черн | D14: =C14/C$26 -> #DIV/0! | E14: =D14+E13 -> #DIV/0! | F14: =IF(AND(E14<=0),"C",IF(E14<=0.8,"A",IF(E14<=0.95,"B","C"))) -> #DIV/0! | G14: =VLOOKUP(B$4:B$25,I$4:M$25,5,0) -> #DIV/0! | I14: MR Р1874 черн | K14: =J14/J$26 -> #DIV/0! | L14: =K14+L13 -> #DIV/0! | M14: =_xlfn.IFS(L14<80%,"A",L14<=95%,"B",L14>95%,"C") -> #DIV/0! | P14: B | Q14: 0.15
B15: MR Р1874 корич | D15: =C15/C$26 -> #DIV/0! | E15: =D15+E14 -> #DIV/0! | F15: =IF(AND(E15<=0),"C",IF(E15<=0.8,"A",IF(E15<=0.95,"B","C"))) -> #DIV/0! | G15: =VLOOKUP(B$4:B$25,I$4:M$25,5,0) -> #DIV/0! | I15: MR Р1874 корич | K15: =J15/J$26 -> #DIV/0! | L15: =K15+L14 -> #DIV/0! | M15: =_xlfn.IFS(L15<80%,"A",L15<=95%,"B",L15>95%,"C") -> #DIV/0! | P15: C | Q15: 0.05
B16: MR Р1886 черн глянец | D16: =C16/C$26 -> #DIV/0! | E16: =D16+E15 -> #DIV/0! | F16: =IF(AND(E16<=0),"C",IF(E16<=0.8,"A",IF(E16<=0.95,"B","C"))) -> #DIV/0! | G16: =VLOOKUP(B$4:B$25,I$4:M$25,5,0) -> #DIV/0! | I16: MR Р1886 черн глянец | K16: =J16/J$26 -> #DIV/0! | L16: =K16+L15 -> #DIV/0! | M16: =_xlfn.IFS(L16<80%,"A",L16<=95%,"B",L16>95%,"C") -> #DIV/0!
B17: MR Р1886 корич | D17: =C17/C$26 -> #DIV/0! | E17: =D17+E16 -> #DIV/0! | F17: =IF(AND(E17<=0),"C",IF(E17<=0.8,"A",IF(E17<=0.95,"B","C"))) -> #DIV/0! | G17: =VLOOKUP(B$4:B$25,I$4:M$25,5,0) -> #DIV/0! | I17: MR Р1886 корич | K17: =J17/J$26 -> #DIV/0! | L17: =K17+L16 -> #DIV/0! | M17: =_xlfn.IFS(L17<80%,"A",L17<=95%,"B",L17>95%,"C") -> #DIV/0!
B18: lux1 | D18: =C18/C$26 -> #DIV/0! | E18: =D18+E17 -> #DIV/0! | F18: =IF(AND(E18<=0),"C",IF(E18<=0.8,"A",IF(E18<=0.95,"B","C"))) -> #DIV/0! | G18: =VLOOKUP(B$4:B$25,I$4:M$25,5,0) -> #DIV/0! | I18: lux1 | K18: =J18/J$26 -> #DIV/0! | L18: =K18+L17 -> #DIV/0! | M18: =_xlfn.IFS(L18<80%,"A",L18<=95%,"B",L18>95%,"C") -> #DIV/0!
B19: lux2 | D19: =C19/C$26 -> #DIV/0! | E19: =D19+E18 -> #DIV/0! | F19: =IF(AND(E19<=0),"C",IF(E19<=0.8,"A",IF(E19<=0.95,"B","C"))) -> #DIV/0! | G19: =VLOOKUP(B$4:B$25,I$4:M$25,5,0) -> #DIV/0! | I19: lux2 | K19: =J19/J$26 -> #DIV/0! | L19: =K19+L18 -> #DIV/0! | M19: =_xlfn.IFS(L19<80%,"A",L19<=95%,"B",L19>95%,"C") -> #DIV/0!
B20: lux3 | D20: =C20/C$26 -> #DIV/0! | E20: =D20+E19 -> #DIV/0! | F20: =IF(AND(E20<=0),"C",IF(E20<=0.8,"A",IF(E20<=0.95,"B","C"))) -> #DIV/0! | G20: =VLOOKUP(B$4:B$25,I$4:M$25,5,0) -> #DIV/0! | I20: lux3 | K20: =J20/J$26 -> #DIV/0! | L20: =K20+L19 -> #DIV/0! | M20: =_xlfn.IFS(L20<80%,"A",L20<=95%,"B",L20>95%,"C") -> #DIV/0!
B21: lux4 | D21: =C21/C$26 -> #DIV/0! | E21: =D21+E20 -> #DIV/0! | F21: =IF(AND(E21<=0),"C",IF(E21<=0.8,"A",IF(E21<=0.95,"B","C"))) -> #DIV/0! | G21: =VLOOKUP(B$4:B$25,I$4:M$25,5,0) -> #DIV/0! | I21: lux4 | K21: =J21/J$26 -> #DIV/0! | L21: =K21+L20 -> #DIV/0! | M21: =_xlfn.IFS(L21<80%,"A",L21<=95%,"B",L21>95%,"C") -> #DIV/0!
B22: lux5 | D22: =C22/C$26 -> #DIV/0! | E22: =D22+E21 -> #DIV/0! | F22: =IF(AND(E22<=0),"C",IF(E22<=0.8,"A",IF(E22<=0.95,"B","C"))) -> #DIV/0! | G22: =VLOOKUP(B$4:B$25,I$4:M$25,5,0) -> #DIV/0! | I22: lux5 | K22: =J22/J$26 -> #DIV/0! | L22: =K22+L21 -> #DIV/0! | M22: =_xlfn.IFS(L22<80%,"A",L22<=95%,"B",L22>95%,"C") -> #DIV/0!
B23: lux6 | D23: =C23/C$26 -> #DIV/0! | E23: =D23+E22 -> #DIV/0! | F23: =IF(AND(E23<=0),"C",IF(E23<=0.8,"A",IF(E23<=0.95,"B","C"))) -> #DIV/0! | G23: =VLOOKUP(B$4:B$25,I$4:M$25,5,0) -> #DIV/0! | I23: lux6 | K23: =J23/J$26 -> #DIV/0! | L23: =K23+L22 -> #DIV/0! | M23: =_xlfn.IFS(L23<80%,"A",L23<=95%,"B",L23>95%,"C") -> #DIV/0!
B24: lux7 | D24: =C24/C$26 -> #DIV/0! | E24: =D24+E23 -> #DIV/0! | F24: =IF(AND(E24<=0),"C",IF(E24<=0.8,"A",IF(E24<=0.95,"B","C"))) -> #DIV/0! | G24: =VLOOKUP(B$4:B$25,I$4:M$25,5,0) -> #DIV/0! | I24: lux7 | K24: =J24/J$26 -> #DIV/0! | L24: =K24+L23 -> #DIV/0! | M24: =_xlfn.IFS(L24<80%,"A",L24<=95%,"B",L24>95%,"C") -> #DIV/0!
B25: lux8 | D25: =C25/C$26 -> #DIV/0! | E25: =D25+E24 -> #DIV/0! | F25: =IF(AND(E25<=0),"C",IF(E25<=0.8,"A",IF(E25<=0.95,"B","C"))) -> #DIV/0! | G25: =VLOOKUP(B$4:B$25,I$4:M$25,5,0) -> #DIV/0! | I25: lux8 | K25: =J25/J$26 -> #DIV/0! | L25: =K25+L24 -> #DIV/0! | M25: =_xlfn.IFS(L25<80%,"A",L25<=95%,"B",L25>95%,"C") -> #DIV/0!
C26: =SUM(C4:C25) -> 0 | D26: =SUM(D4:D25) -> #DIV/0! | J26: =SUM(J4:J25) -> 0 | K26: =SUM(K4:K25) -> #DIV/0!
B28: ТУНИКИ
C29: Прибыль | D29: % прибыль | E29: Доля | F29: ABC прибыль | G29: ABC кол-во | J29: Кол-во | K29: % кол-во | L29: Доля | M29: ABC кол-во
B30: tunika02 оливковая с руч вышивкой | D30: =C30/C$50 -> #DIV/0! | E30: =D30 -> #DIV/0! | F30: =IF(AND(E30<=0),"C",IF(E30<=0.8,"A",IF(E30<=0.95,"B","C"))) -> #DIV/0! | G30: =VLOOKUP(B$30:B$50,I$30:M$50,5,0) -> #DIV/0! | I30: tunika02 оливковая с руч вышивкой | K30: =J30/J$50 -> #DIV/0! | L30: =K30 -> #DIV/0! | M30: =_xlfn.IFS(L30<80%,"A",L30<=95%,"B",L30>95%,"C") -> #DIV/0!
B31: tunika03 черная распашная | D31: =C31/C$50 -> #DIV/0! | E31: =D31+E30 -> #DIV/0! | F31: =IF(AND(E31<=0),"C",IF(E31<=0.8,"A",IF(E31<=0.95,"B","C"))) -> #DIV/0! | G31: =VLOOKUP(B$30:B$50,I$30:M$50,5,0) -> #DIV/0! | I31: tunika03 черная распашная | K31: =J31/J$50 -> #DIV/0! | L31: =K31+L30 -> #DIV/0! | M31: =_xlfn.IFS(L31<80%,"A",L31<=95%,"B",L31>95%,"C") -> #DIV/0!
B32: tunika05 белая распашная | D32: =C32/C$50 -> #DIV/0! | E32: =D32+E31 -> #DIV/0! | F32: =IF(AND(E32<=0),"C",IF(E32<=0.8,"A",IF(E32<=0.95,"B","C"))) -> #DIV/0! | G32: =VLOOKUP(B$30:B$50,I$30:M$50,5,0) -> #DIV/0! | I32: tunika05 белая распашная | K32: =J32/J$50 -> #DIV/0! | L32: =K32+L31 -> #DIV/0! | M32: =_xlfn.IFS(L32<80%,"A",L32<=95%,"B",L32>95%,"C") -> #DIV/0!
B33: tunika06 белая | D33: =C33/C$50 -> #DIV/0! | E33: =D33+E32 -> #DIV/0! | F33: =IF(AND(E33<=0),"C",IF(E33<=0.8,"A",IF(E33<=0.95,"B","C"))) -> #DIV/0! | G33: =VLOOKUP(B$30:B$50,I$30:M$50,5,0) -> #DIV/0! | I33: tunika06 белая | K33: =J33/J$50 -> #DIV/0! | L33: =K33+L32 -> #DIV/0! | M33: =_xlfn.IFS(L33<80%,"A",L33<=95%,"B",L33>95%,"C") -> #DIV/0!
B34: tunika06 черная | D34: =C34/C$50 -> #DIV/0! | E34: =D34+E33 -> #DIV/0! | F34: =IF(AND(E34<=0),"C",IF(E34<=0.8,"A",IF(E34<=0.95,"B","C"))) -> #DIV/0! | G34: =VLOOKUP(B$30:B$50,I$30:M$50,5,0) -> #DIV/0! | I34: tunika06 черная | K34: =J34/J$50 -> #DIV/0! | L34: =K34+L33 -> #DIV/0! | M34: =_xlfn.IFS(L34<80%,"A",L34<=95%,"B",L34>95%,"C") -> #DIV/0!
B35: tunika07 кружево | D35: =C35/C$50 -> #DIV/0! | E35: =D35+E34 -> #DIV/0! | F35: =IF(AND(E35<=0),"C",IF(E35<=0.8,"A",IF(E35<=0.95,"B","C"))) -> #DIV/0! | G35: =VLOOKUP(B$30:B$50,I$30:M$50,5,0) -> #DIV/0! | I35: tunika07 кружево | K35: =J35/J$50 -> #DIV/0! | L35: =K35+L34 -> #DIV/0! | M35: =_xlfn.IFS(L35<80%,"A",L35<=95%,"B",L35>95%,"C") -> #DIV/0!
B36: tunika08 белая | D36: =C36/C$50 -> #DIV/0! | E36: =D36+E35 -> #DIV/0! | F36: =IF(AND(E36<=0),"C",IF(E36<=0.8,"A",IF(E36<=0.95,"B","C"))) -> #DIV/0! | G36: =VLOOKUP(B$30:B$50,I$30:M$50,5,0) -> #DIV/0! | I36: tunika08 белая | K36: =J36/J$50 -> #DIV/0! | L36: =K36+L35 -> #DIV/0! | M36: =_xlfn.IFS(L36<80%,"A",L36<=95%,"B",L36>95%,"C") -> #DIV/0!
B37: tunika08 черная | D37: =C37/C$50 -> #DIV/0! | E37: =D37+E36 -> #DIV/0! | F37: =IF(AND(E37<=0),"C",IF(E37<=0.8,"A",IF(E37<=0.95,"B","C"))) -> #DIV/0! | G37: =VLOOKUP(B$30:B$50,I$30:M$50,5,0) -> #DIV/0! | I37: tunika08 черная | K37: =J37/J$50 -> #DIV/0! | L37: =K37+L36 -> #DIV/0! | M37: =_xlfn.IFS(L37<80%,"A",L37<=95%,"B",L37>95%,"C") -> #DIV/0!
B38: tunika08 зеленая | D38: =C38/C$50 -> #DIV/0! | E38: =D38+E37 -> #DIV/0! | F38: =IF(AND(E38<=0),"C",IF(E38<=0.8,"A",IF(E38<=0.95,"B","C"))) -> #DIV/0! | G38: =VLOOKUP(B$30:B$50,I$30:M$50,5,0) -> #DIV/0! | I38: tunika08 зеленая | K38: =J38/J$50 -> #DIV/0! | L38: =K38+L37 -> #DIV/0! | M38: =_xlfn.IFS(L38<80%,"A",L38<=95%,"B",L38>95%,"C") -> #DIV/0!
B39: tunika09 кимоно | D39: =C39/C$50 -> #DIV/0! | E39: =D39+E38 -> #DIV/0! | F39: =IF(AND(E39<=0),"C",IF(E39<=0.8,"A",IF(E39<=0.95,"B","C"))) -> #DIV/0! | G39: =VLOOKUP(B$30:B$50,I$30:M$50,5,0) -> #DIV/0! | I39: tunika09 кимоно | K39: =J39/J$50 -> #DIV/0! | L39: =K39+L38 -> #DIV/0! | M39: =_xlfn.IFS(L39<80%,"A",L39<=95%,"B",L39>95%,"C") -> #DIV/0!
B40: tunika10 кимоно ч/б | D40: =C40/C$50 -> #DIV/0! | E40: =D40+E39 -> #DIV/0! | F40: =IF(AND(E40<=0),"C",IF(E40<=0.8,"A",IF(E40<=0.95,"B","C"))) -> #DIV/0! | G40: =VLOOKUP(B$30:B$50,I$30:M$50,5,0) -> #DIV/0! | I40: tunika10 кимоно ч/б | K40: =J40/J$50 -> #DIV/0! | L40: =K40+L39 -> #DIV/0! | M40: =_xlfn.IFS(L40<80%,"A",L40<=95%,"B",L40>95%,"C") -> #DIV/0!
B41: tunika11 халат зеленая | D41: =C41/C$50 -> #DIV/0! | E41: =D41+E40 -> #DIV/0! | F41: =IF(AND(E41<=0),"C",IF(E41<=0.8,"A",IF(E41<=0.95,"B","C"))) -> #DIV/0! | G41: =VLOOKUP(B$30:B$50,I$30:M$50,5,0) -> #DIV/0! | I41: tunika11 халат зеленая | K41: =J41/J$50 -> #DIV/0! | L41: =K41+L40 -> #DIV/0! | M41: =_xlfn.IFS(L41<80%,"A",L41<=95%,"B",L41>95%,"C") -> #DIV/0!
B42: tunika12 халат белая | D42: =C42/C$50 -> #DIV/0! | E42: =D42+E41 -> #DIV/0! | F42: =IF(AND(E42<=0),"C",IF(E42<=0.8,"A",IF(E42<=0.95,"B","C"))) -> #DIV/0! | G42: =VLOOKUP(B$30:B$50,I$30:M$50,5,0) -> #DIV/0! | I42: tunika12 халат белая | K42: =J42/J$50 -> #DIV/0! | L42: =K42+L41 -> #DIV/0! | M42: =_xlfn.IFS(L42<80%,"A",L42<=95%,"B",L42>95%,"C") -> #DIV/0!
...

Sheet АВС 30-31.03
B2: ОЧКИ
C3: Прибыль | D3: % прибыль | E3: Доля | F3: ABC прибыль | G3: ABC кол-во | J3: Кол-во | K3: % кол-во | L3: Доля | M3: ABC кол-во
B4: черные с железкой классика | D4: =C4/C$26 -> #DIV/0! | E4: =D4 -> #DIV/0! | F4: =IF(AND(E4<=0),"C",IF(E4<=0.8,"A",IF(E4<=0.95,"B","C"))) -> #DIV/0! | G4: =VLOOKUP(B$4:B$25,I$4:M$25,5,0) -> #DIV/0! | I4: черные с железкой классика | K4: =J4/J$26 -> #DIV/0! | L4: =K4 -> #DIV/0! | M4: =_xlfn.IFS(L4<80%,"A",L4<=95%,"B",L4>95%,"C") -> #DIV/0!
B5: qs черные | D5: =C5/C$26 -> #DIV/0! | E5: =D5+E4 -> #DIV/0! | F5: =IF(AND(E5<=0),"C",IF(E5<=0.8,"A",IF(E5<=0.95,"B","C"))) -> #DIV/0! | G5: =VLOOKUP(B$4:B$25,I$4:M$25,5,0) -> #DIV/0! | I5: qs черные | K5: =J5/J$26 -> #DIV/0! | L5: =K5+L4 -> #DIV/0! | M5: =_xlfn.IFS(L5<80%,"A",L5<=95%,"B",L5>95%,"C") -> #DIV/0!
B6: qs синие | D6: =C6/C$26 -> #DIV/0! | E6: =D6+E5 -> #DIV/0! | F6: =IF(AND(E6<=0),"C",IF(E6<=0.8,"A",IF(E6<=0.95,"B","C"))) -> #DIV/0! | G6: =VLOOKUP(B$4:B$25,I$4:M$25,5,0) -> #DIV/0! | I6: qs синие | K6: =J6/J$26 -> #DIV/0! | L6: =K6+L5 -> #DIV/0! | M6: =_xlfn.IFS(L6<80%,"A",L6<=95%,"B",L6>95%,"C") -> #DIV/0!
B7: qs желтые | D7: =C7/C$26 -> #DIV/0! | E7: =D7+E6 -> #DIV/0! | F7: =IF(AND(E7<=0),"C",IF(E7<=0.8,"A",IF(E7<=0.95,"B","C"))) -> #DIV/0! | G7: =VLOOKUP(B$4:B$25,I$4:M$25,5,0) -> #DIV/0! | I7: qs желтые | K7: =J7/J$26 -> #DIV/0! | L7: =K7+L6 -> #DIV/0! | M7: =_xlfn.IFS(L7<80%,"A",L7<=95%,"B",L7>95%,"C") -> #DIV/0!
B8: qs коричневые | D8: =C8/C$26 -> #DIV/0! | E8: =D8+E7 -> #DIV/0! | F8: =IF(AND(E8<=0),"C",IF(E8<=0.8,"A",IF(E8<=0.95,"B","C"))) -> #DIV/0! | G8: =VLOOKUP(B$4:B$25,I$4:M$25,5,0) -> #DIV/0! | I8: qs коричневые | K8: =J8/J$26 -> #DIV/0! | L8: =K8+L7 -> #DIV/0! | M8: =_xlfn.IFS(L8<80%,"A",L8<=95%,"B",L8>95%,"C") -> #DIV/0!
B9: th желтый Сул | D9: =C9/C$26 -> #DIV/0! | E9: =D9+E8 -> #DIV/0! | F9: =IF(AND(E9<=0),"C",IF(E9<=0.8,"A",IF(E9<=0.95,"B","C"))) -> #DIV/0! | G9: =VLOOKUP(B$4:B$25,I$4:M$25,5,0) -> #DIV/0! | I9: th желтый Сул | K9: =J9/J$26 -> #DIV/0! | L9: =K9+L8 -> #DIV/0! | M9: =_xlfn.IFS(L9<80%,"A",L9<=95%,"B",L9>95%,"C") -> #DIV/0!
B10: flip желтые Сул | D10: =C10/C$26 -> #DIV/0! | E10: =D10+E9 -> #DIV/0! | F10: =IF(AND(E10<=0),"C",IF(E10<=0.8,"A",IF(E10<=0.95,"B","C"))) -> #DIV/0! | G10: =VLOOKUP(B$4:B$25,I$4:M$25,5,0) -> #DIV/0! | I10: flip желтые Сул | K10: =J10/J$26 -> #DIV/0! | L10: =K10+L9 -> #DIV/0! | M10: =_xlfn.IFS(L10<80%,"A",L10<=95%,"B",L10>95%,"C") -> #DIV/0!
B11: MR8854 C2 | D11: =C11/C$26 -> #DIV/0! | E11: =D11+E8 -> #DIV/0! | F11: =IF(AND(E11<=0),"C",IF(E11<=0.8,"A",IF(E11<=0.95,"B","C"))) -> #DIV/0! | G11: =VLOOKUP(B$4:B$25,I$4:M$25,5,0) -> #DIV/0! | I11: MR8854 C2 | K11: =J11/J$26 -> #DIV/0! | L11: =K11+L8 -> #DIV/0! | M11: =_xlfn.IFS(L11<80%,"A",L11<=95%,"B",L11>95%,"C") -> #DIV/0!
B12: MR 1819 черн | D12: =C12/C$26 -> #DIV/0! | E12: =D12+E11 -> #DIV/0! | F12: =IF(AND(E12<=0),"C",IF(E12<=0.8,"A",IF(E12<=0.95,"B","C"))) -> #DIV/0! | G12: =VLOOKUP(B$4:B$25,I$4:M$25,5,0) -> #DIV/0! | I12: MR 1819 черн | K12: =J12/J$26 -> #DIV/0! | L12: =K12+L11 -> #DIV/0! | M12: =_xlfn.IFS(L12<80%,"A",L12<=95%,"B",L12>95%,"C") -> #DIV/0!
B13: MR 1819 корич | D13: =C13/C$26 -> #DIV/0! | E13: =D13+E12 -> #DIV/0! | F13: =IF(AND(E13<=0),"C",IF(E13<=0.8,"A",IF(E13<=0.95,"B","C"))) -> #DIV/0! | G13: =VLOOKUP(B$4:B$25,I$4:M$25,5,0) -> #DIV/0! | I13: MR 1819 корич | K13: =J13/J$26 -> #DIV/0! | L13: =K13+L12 -> #DIV/0! | M13: =_xlfn.IFS(L13<80%,"A",L13<=95%,"B",L13>95%,"C") -> #DIV/0! | P13: A | Q13: 0.8
B14: MR Р1874 черн | D14: =C14/C$26 -> #DIV/0! | E14: =D14+E13 -> #DIV/0! | F14: =IF(AND(E14<=0),"C",IF(E14<=0.8,"A",IF(E14<=0.95,"B","C"))) -> #DIV/0! | G14: =VLOOKUP(B$4:B$25,I$4:M$25,5,0) -> #DIV/0! | I14: MR Р1874 черн | K14: =J14/J$26 -> #DIV/0! | L14: =K14+L13 -> #DIV/0! | M14: =_xlfn.IFS(L14<80%,"A",L14<=95%,"B",L14>95%,"C") -> #DIV/0! | P14: B | Q14: 0.15
B15: MR Р1874 корич | D15: =C15/C$26 -> #DIV/0! | E15: =D15+E14 -> #DIV/0! | F15: =IF(AND(E15<=0),"C",IF(E15<=0.8,"A",IF(E15<=0.95,"B","C"))) -> #DIV/0! | G15: =VLOOKUP(B$4:B$25,I$4:M$25,5,0) -> #DIV/0! | I15: MR Р1874 корич | K15: =J15/J$26 -> #DIV/0! | L15: =K15+L14 -> #DIV/0! | M15: =_xlfn.IFS(L15<80%,"A",L15<=95%,"B",L15>95%,"C") -> #DIV/0! | P15: C | Q15: 0.05
B16: MR Р1886 черн глянец | D16: =C16/C$26 -> #DIV/0! | E16: =D16+E15 -> #DIV/0! | F16: =IF(AND(E16<=0),"C",IF(E16<=0.8,"A",IF(E16<=0.95,"B","C"))) -> #DIV/0! | G16: =VLOOKUP(B$4:B$25,I$4:M$25,5,0) -> #DIV/0! | I16: MR Р1886 черн глянец | K16: =J16/J$26 -> #DIV/0! | L16: =K16+L15 -> #DIV/0! | M16: =_xlfn.IFS(L16<80%,"A",L16<=95%,"B",L16>95%,"C") -> #DIV/0!
B17: MR Р1886 корич | D17: =C17/C$26 -> #DIV/0! | E17: =D17+E16 -> #DIV/0! | F17: =IF(AND(E17<=0),"C",IF(E17<=0.8,"A",IF(E17<=0.95,"B","C"))) -> #DIV/0! | G17: =VLOOKUP(B$4:B$25,I$4:M$25,5,0) -> #DIV/0! | I17: MR Р1886 корич | K17: =J17/J$26 -> #DIV/0! | L17: =K17+L16 -> #DIV/0! | M17: =_xlfn.IFS(L17<80%,"A",L17<=95%,"B",L17>95%,"C") -> #DIV/0!
B18: lux1 | D18: =C18/C$26 -> #DIV/0! | E18: =D18+E17 -> #DIV/0! | F18: =IF(AND(E18<=0),"C",IF(E18<=0.8,"A",IF(E18<=0.95,"B","C"))) -> #DIV/0! | G18: =VLOOKUP(B$4:B$25,I$4:M$25,5,0) -> #DIV/0! | I18: lux1 | K18: =J18/J$26 -> #DIV/0! | L18: =K18+L17 -> #DIV/0! | M18: =_xlfn.IFS(L18<80%,"A",L18<=95%,"B",L18>95%,"C") -> #DIV/0!
B19: lux2 | D19: =C19/C$26 -> #DIV/0! | E19: =D19+E18 -> #DIV/0! | F19: =IF(AND(E19<=0),"C",IF(E19<=0.8,"A",IF(E19<=0.95,"B","C"))) -> #DIV/0! | G19: =VLOOKUP(B$4:B$25,I$4:M$25,5,0) -> #DIV/0! | I19: lux2 | K19: =J19/J$26 -> #DIV/0! | L19: =K19+L18 -> #DIV/0! | M19: =_xlfn.IFS(L19<80%,"A",L19<=95%,"B",L19>95%,"C") -> #DIV/0!
B20: lux3 | D20: =C20/C$26 -> #DIV/0! | E20: =D20+E19 -> #DIV/0! | F20: =IF(AND(E20<=0),"C",IF(E20<=0.8,"A",IF(E20<=0.95,"B","C"))) -> #DIV/0! | G20: =VLOOKUP(B$4:B$25,I$4:M$25,5,0) -> #DIV/0! | I20: lux3 | K20: =J20/J$26 -> #DIV/0! | L20: =K20+L19 -> #DIV/0! | M20: =_xlfn.IFS(L20<80%,"A",L20<=95%,"B",L20>95%,"C") -> #DIV/0!
B21: lux4 | D21: =C21/C$26 -> #DIV/0! | E21: =D21+E20 -> #DIV/0! | F21: =IF(AND(E21<=0),"C",IF(E21<=0.8,"A",IF(E21<=0.95,"B","C"))) -> #DIV/0! | G21: =VLOOKUP(B$4:B$25,I$4:M$25,5,0) -> #DIV/0! | I21: lux4 | K21: =J21/J$26 -> #DIV/0! | L21: =K21+L20 -> #DIV/0! | M21: =_xlfn.IFS(L21<80%,"A",L21<=95%,"B",L21>95%,"C") -> #DIV/0!
B22: lux5 | D22: =C22/C$26 -> #DIV/0! | E22: =D22+E21 -> #DIV/0! | F22: =IF(AND(E22<=0),"C",IF(E22<=0.8,"A",IF(E22<=0.95,"B","C"))) -> #DIV/0! | G22: =VLOOKUP(B$4:B$25,I$4:M$25,5,0) -> #DIV/0! | I22: lux5 | K22: =J22/J$26 -> #DIV/0! | L22: =K22+L21 -> #DIV/0! | M22: =_xlfn.IFS(L22<80%,"A",L22<=95%,"B",L22>95%,"C") -> #DIV/0!
B23: lux6 | D23: =C23/C$26 -> #DIV/0! | E23: =D23+E22 -> #DIV/0! | F23: =IF(AND(E23<=0),"C",IF(E23<=0.8,"A",IF(E23<=0.95,"B","C"))) -> #DIV/0! | G23: =VLOOKUP(B$4:B$25,I$4:M$25,5,0) -> #DIV/0! | I23: lux6 | K23: =J23/J$26 -> #DIV/0! | L23: =K23+L22 -> #DIV/0! | M23: =_xlfn.IFS(L23<80%,"A",L23<=95%,"B",L23>95%,"C") -> #DIV/0!
B24: lux7 | D24: =C24/C$26 -> #DIV/0! | E24: =D24+E23 -> #DIV/0! | F24: =IF(AND(E24<=0),"C",IF(E24<=0.8,"A",IF(E24<=0.95,"B","C"))) -> #DIV/0! | G24: =VLOOKUP(B$4:B$25,I$4:M$25,5,0) -> #DIV/0! | I24: lux7 | K24: =J24/J$26 -> #DIV/0! | L24: =K24+L23 -> #DIV/0! | M24: =_xlfn.IFS(L24<80%,"A",L24<=95%,"B",L24>95%,"C") -> #DIV/0!
B25: lux8 | D25: =C25/C$26 -> #DIV/0! | E25: =D25+E24 -> #DIV/0! | F25: =IF(AND(E25<=0),"C",IF(E25<=0.8,"A",IF(E25<=0.95,"B","C"))) -> #DIV/0! | G25: =VLOOKUP(B$4:B$25,I$4:M$25,5,0) -> #DIV/0! | I25: lux8 | K25: =J25/J$26 -> #DIV/0! | L25: =K25+L24 -> #DIV/0! | M25: =_xlfn.IFS(L25<80%,"A",L25<=95%,"B",L25>95%,"C") -> #DIV/0!
C26: =SUM(C4:C25) -> 0 | D26: =SUM(D4:D25) -> #DIV/0! | J26: =SUM(J4:J25) -> 0 | K26: =SUM(K4:K25) -> #DIV/0!
B28: ТУНИКИ
C29: Прибыль | D29: % прибыль | E29: Доля | F29: ABC прибыль | G29: ABC кол-во | J29: Кол-во | K29: % кол-во | L29: Доля | M29: ABC кол-во
B30: tunika02 оливковая с руч вышивкой | D30: =C30/C$50 -> #DIV/0! | E30: =D30 -> #DIV/0! | F30: =IF(AND(E30<=0),"C",IF(E30<=0.8,"A",IF(E30<=0.95,"B","C"))) -> #DIV/0! | G30: =VLOOKUP(B$30:B$50,I$30:M$50,5,0) -> #DIV/0! | I30: tunika02 оливковая с руч вышивкой | K30: =J30/J$50 -> #DIV/0! | L30: =K30 -> #DIV/0! | M30: =_xlfn.IFS(L30<80%,"A",L30<=95%,"B",L30>95%,"C") -> #DIV/0!
B31: tunika03 черная распашная | D31: =C31/C$50 -> #DIV/0! | E31: =D31+E30 -> #DIV/0! | F31: =IF(AND(E31<=0),"C",IF(E31<=0.8,"A",IF(E31<=0.95,"B","C"))) -> #DIV/0! | G31: =VLOOKUP(B$30:B$50,I$30:M$50,5,0) -> #DIV/0! | I31: tunika03 черная распашная | K31: =J31/J$50 -> #DIV/0! | L31: =K31+L30 -> #DIV/0! | M31: =_xlfn.IFS(L31<80%,"A",L31<=95%,"B",L31>95%,"C") -> #DIV/0!
B32: tunika05 белая распашная | D32: =C32/C$50 -> #DIV/0! | E32: =D32+E31 -> #DIV/0! | F32: =IF(AND(E32<=0),"C",IF(E32<=0.8,"A",IF(E32<=0.95,"B","C"))) -> #DIV/0! | G32: =VLOOKUP(B$30:B$50,I$30:M$50,5,0) -> #DIV/0! | I32: tunika05 белая распашная | K32: =J32/J$50 -> #DIV/0! | L32: =K32+L31 -> #DIV/0! | M32: =_xlfn.IFS(L32<80%,"A",L32<=95%,"B",L32>95%,"C") -> #DIV/0!
B33: tunika06 белая | D33: =C33/C$50 -> #DIV/0! | E33: =D33+E32 -> #DIV/0! | F33: =IF(AND(E33<=0),"C",IF(E33<=0.8,"A",IF(E33<=0.95,"B","C"))) -> #DIV/0! | G33: =VLOOKUP(B$30:B$50,I$30:M$50,5,0) -> #DIV/0! | I33: tunika06 белая | K33: =J33/J$50 -> #DIV/0! | L33: =K33+L32 -> #DIV/0! | M33: =_xlfn.IFS(L33<80%,"A",L33<=95%,"B",L33>95%,"C") -> #DIV/0!
B34: tunika06 черная | D34: =C34/C$50 -> #DIV/0! | E34: =D34+E33 -> #DIV/0! | F34: =IF(AND(E34<=0),"C",IF(E34<=0.8,"A",IF(E34<=0.95,"B","C"))) -> #DIV/0! | G34: =VLOOKUP(B$30:B$50,I$30:M$50,5,0) -> #DIV/0! | I34: tunika06 черная | K34: =J34/J$50 -> #DIV/0! | L34: =K34+L33 -> #DIV/0! | M34: =_xlfn.IFS(L34<80%,"A",L34<=95%,"B",L34>95%,"C") -> #DIV/0!
B35: tunika07 кружево | D35: =C35/C$50 -> #DIV/0! | E35: =D35+E34 -> #DIV/0! | F35: =IF(AND(E35<=0),"C",IF(E35<=0.8,"A",IF(E35<=0.95,"B","C"))) -> #DIV/0! | G35: =VLOOKUP(B$30:B$50,I$30:M$50,5,0) -> #DIV/0! | I35: tunika07 кружево | K35: =J35/J$50 -> #DIV/0! | L35: =K35+L34 -> #DIV/0! | M35: =_xlfn.IFS(L35<80%,"A",L35<=95%,"B",L35>95%,"C") -> #DIV/0!
B36: tunika08 белая | D36: =C36/C$50 -> #DIV/0! | E36: =D36+E35 -> #DIV/0! | F36: =IF(AND(E36<=0),"C",IF(E36<=0.8,"A",IF(E36<=0.95,"B","C"))) -> #DIV/0! | G36: =VLOOKUP(B$30:B$50,I$30:M$50,5,0) -> #DIV/0! | I36: tunika08 белая | K36: =J36/J$50 -> #DIV/0! | L36: =K36+L35 -> #DIV/0! | M36: =_xlfn.IFS(L36<80%,"A",L36<=95%,"B",L36>95%,"C") -> #DIV/0!
B37: tunika08 черная | D37: =C37/C$50 -> #DIV/0! | E37: =D37+E36 -> #DIV/0! | F37: =IF(AND(E37<=0),"C",IF(E37<=0.8,"A",IF(E37<=0.95,"B","C"))) -> #DIV/0! | G37: =VLOOKUP(B$30:B$50,I$30:M$50,5,0) -> #DIV/0! | I37: tunika08 черная | K37: =J37/J$50 -> #DIV/0! | L37: =K37+L36 -> #DIV/0! | M37: =_xlfn.IFS(L37<80%,"A",L37<=95%,"B",L37>95%,"C") -> #DIV/0!
B38: tunika08 зеленая | D38: =C38/C$50 -> #DIV/0! | E38: =D38+E37 -> #DIV/0! | F38: =IF(AND(E38<=0),"C",IF(E38<=0.8,"A",IF(E38<=0.95,"B","C"))) -> #DIV/0! | G38: =VLOOKUP(B$30:B$50,I$30:M$50,5,0) -> #DIV/0! | I38: tunika08 зеленая | K38: =J38/J$50 -> #DIV/0! | L38: =K38+L37 -> #DIV/0! | M38: =_xlfn.IFS(L38<80%,"A",L38<=95%,"B",L38>95%,"C") -> #DIV/0!
B39: tunika09 кимоно | D39: =C39/C$50 -> #DIV/0! | E39: =D39+E38 -> #DIV/0! | F39: =IF(AND(E39<=0),"C",IF(E39<=0.8,"A",IF(E39<=0.95,"B","C"))) -> #DIV/0! | G39: =VLOOKUP(B$30:B$50,I$30:M$50,5,0) -> #DIV/0! | I39: tunika09 кимоно | K39: =J39/J$50 -> #DIV/0! | L39: =K39+L38 -> #DIV/0! | M39: =_xlfn.IFS(L39<80%,"A",L39<=95%,"B",L39>95%,"C") -> #DIV/0!
B40: tunika10 кимоно ч/б | D40: =C40/C$50 -> #DIV/0! | E40: =D40+E39 -> #DIV/0! | F40: =IF(AND(E40<=0),"C",IF(E40<=0.8,"A",IF(E40<=0.95,"B","C"))) -> #DIV/0! | G40: =VLOOKUP(B$30:B$50,I$30:M$50,5,0) -> #DIV/0! | I40: tunika10 кимоно ч/б | K40: =J40/J$50 -> #DIV/0! | L40: =K40+L39 -> #DIV/0! | M40: =_xlfn.IFS(L40<80%,"A",L40<=95%,"B",L40>95%,"C") -> #DIV/0!
B41: tunika11 халат зеленая | D41: =C41/C$50 -> #DIV/0! | E41: =D41+E40 -> #DIV/0! | F41: =IF(AND(E41<=0),"C",IF(E41<=0.8,"A",IF(E41<=0.95,"B","C"))) -> #DIV/0! | G41: =VLOOKUP(B$30:B$50,I$30:M$50,5,0) -> #DIV/0! | I41: tunika11 халат зеленая | K41: =J41/J$50 -> #DIV/0! | L41: =K41+L40 -> #DIV/0! | M41: =_xlfn.IFS(L41<80%,"A",L41<=95%,"B",L41>95%,"C") -> #DIV/0!
B42: tunika12 халат белая | D42: =C42/C$50 -> #DIV/0! | E42: =D42+E41 -> #DIV/0! | F42: =IF(AND(E42<=0),"C",IF(E42<=0.8,"A",IF(E42<=0.95,"B","C"))) -> #DIV/0! | G42: =VLOOKUP(B$30:B$50,I$30:M$50,5,0) -> #DIV/0! | I42: tunika12 халат белая | K42: =J42/J$50 -> #DIV/0! | L42: =K42+L41 -> #DIV/0! | M42: =_xlfn.IFS(L42<80%,"A",L42<=95%,"B",L42>95%,"C") -> #DIV/0!
...

Sheet АВС 23-29.03
B2: ОЧКИ
C3: Прибыль | D3: % прибыль | E3: Доля | F3: ABC прибыль | G3: ABC кол-во | J3: Кол-во | K3: % кол-во | L3: Доля | M3: ABC кол-во
B4: черные с железкой классика | C4: ='Юнит 23-29.03'!AE3 -> 64086.083 | D4: =C4/C$26 -> 0.75751507 | E4: =D4 -> 0.75751507 | F4: =IF(AND(E4<=0),"C",IF(E4<=0.8,"A",IF(E4<=0.95,"B","C"))) -> A | G4: =VLOOKUP(B$4:B$25,I$4:M$25,5,0) -> A | I4: черные с железкой классика | J4: ='Юнит 23-29.03'!R3 -> 84 | K4: =J4/J$26 -> 0.64122137 | L4: =K4 -> 0.64122137 | M4: =_xlfn.IFS(L4<80%,"A",L4<=95%,"B",L4>95%,"C") -> A
B5: qs желтые | C5: ='Юнит 23-29.03'!AE6 -> 6828.646 | D5: =C5/C$26 -> 0.080716467 | E5: =D5+E4 -> 0.83823153 | F5: =IF(AND(E5<=0),"C",IF(E5<=0.8,"A",IF(E5<=0.95,"B","C"))) -> B | G5: =VLOOKUP(B$4:B$25,I$4:M$25,5,0) -> A | I5: qs желтые | J5: ='Юнит 23-29.03'!R6 -> 13 | K5: =J5/J$26 -> 0.099236641 | L5: =K5+L4 -> 0.74045802 | M5: =_xlfn.IFS(L5<80%,"A",L5<=95%,"B",L5>95%,"C") -> A
B6: qs черные | C6: ='Юнит 23-29.03'!AE4 -> 5334.3972 | D6: =C6/C$26 -> 0.063054037 | E6: =D6+E5 -> 0.90128557 | F6: =IF(AND(E6<=0),"C",IF(E6<=0.8,"A",IF(E6<=0.95,"B","C"))) -> B | G6: =VLOOKUP(B$4:B$25,I$4:M$25,5,0) -> B | I6: MR8854 C2 | J6: ='Юнит 23-29.03'!R10 -> 11 | K6: =J6/J$26 -> 0.083969466 | L6: =K6+L5 -> 0.82442748 | M6: =_xlfn.IFS(L6<80%,"A",L6<=95%,"B",L6>95%,"C") -> B
B7: flip желтые Сул | C7: ='Юнит 23-29.03'!AE9 -> 2559.7759 | D7: =C7/C$26 -> 0.030257252 | E7: =D7+E6 -> 0.93154282 | F7: =IF(AND(E7<=0),"C",IF(E7<=0.8,"A",IF(E7<=0.95,"B","C"))) -> B | G7: =VLOOKUP(B$4:B$25,I$4:M$25,5,0) -> B | I7: qs черные | J7: ='Юнит 23-29.03'!R4 -> 6 | K7: =J7/J$26 -> 0.045801527 | L7: =K7+L6 -> 0.87022901 | M7: =_xlfn.IFS(L7<80%,"A",L7<=95%,"B",L7>95%,"C") -> B
B8: MR8854 C2 | C8: ='Юнит 23-29.03'!AE10 -> 1936.3808 | D8: =C8/C$26 -> 0.022888552 | E8: =D8+E7 -> 0.95443137 | F8: =IF(AND(E8<=0),"C",IF(E8<=0.8,"A",IF(E8<=0.95,"B","C"))) -> C | G8: =VLOOKUP(B$4:B$25,I$4:M$25,5,0) -> B | I8: flip желтые Сул | J8: ='Юнит 23-29.03'!R9 -> 5 | K8: =J8/J$26 -> 0.038167939 | L8: =K8+L7 -> 0.90839695 | M8: =_xlfn.IFS(L8<80%,"A",L8<=95%,"B",L8>95%,"C") -> B
B9: qs синие | C9: ='Юнит 23-29.03'!AE5 -> 1688.0937 | D9: =C9/C$26 -> 0.01995373 | E9: =D9+E8 -> 0.9743851 | F9: =IF(AND(E9<=0),"C",IF(E9<=0.8,"A",IF(E9<=0.95,"B","C"))) -> C | G9: =VLOOKUP(B$4:B$25,I$4:M$25,5,0) -> B | I9: qs синие | J9: ='Юнит 23-29.03'!R5 -> 4 | K9: =J9/J$26 -> 0.030534351 | L9: =K9+L8 -> 0.9389313 | M9: =_xlfn.IFS(L9<80%,"A",L9<=95%,"B",L9>95%,"C") -> B
B10: MR 1819 черн | C10: ='Юнит 23-29.03'!AE11 -> 982.06837 | D10: =C10/C$26 -> 0.011608317 | E10: =D10+E9 -> 0.98599342 | F10: =IF(AND(E10<=0),"C",IF(E10<=0.8,"A",IF(E10<=0.95,"B","C"))) -> C | G10: =VLOOKUP(B$4:B$25,I$4:M$25,5,0) -> B | I10: qs коричневые | J10: ='Юнит 23-29.03'!R7 -> 3 | K10: =J10/J$26 -> 0.022900763 | L10: =K10+L9 -> 0.96183206 | M10: =_xlfn.IFS(L10<80%,"A",L10<=95%,"B",L10>95%,"C") -> C
B11: MR Р1874 черн | C11: ='Юнит 23-29.03'!AE13 -> 687.38177 | D11: =C11/C$26 -> 0.0081250409 | E11: =D11+E8 -> 0.96255642 | F11: =IF(AND(E11<=0),"C",IF(E11<=0.8,"A",IF(E11<=0.95,"B","C"))) -> C | G11: =VLOOKUP(B$4:B$25,I$4:M$25,5,0) -> B | I11: MR 1819 черн | J11: ='Юнит 23-29.03'!R11 -> 2 | K11: =J11/J$26 -> 0.015267176 | L11: =K11+L8 -> 0.92366412 | M11: =_xlfn.IFS(L11<80%,"A",L11<=95%,"B",L11>95%,"C") -> B
B12: MR Р1886 черн глянец | C12: ='Юнит 23-29.03'!AE15 -> 645.62876 | D12: =C12/C$26 -> 0.0076315089 | E12: =D12+E11 -> 0.97018792 | F12: =IF(AND(E12<=0),"C",IF(E12<=0.8,"A",IF(E12<=0.95,"B","C"))) -> C | G12: =VLOOKUP(B$4:B$25,I$4:M$25,5,0) -> B | I12: MR Р1874 черн | J12: ='Юнит 23-29.03'!R13 -> 1 | K12: =J12/J$26 -> 0.0076335878 | L12: =K12+L11 -> 0.93129771 | M12: =_xlfn.IFS(L12<80%,"A",L12<=95%,"B",L12>95%,"C") -> B
B13: qs коричневые | C13: ='Юнит 23-29.03'!AE7 -> 527.04446 | D13: =C13/C$26 -> 0.00622981 | E13: =D13+E12 -> 0.97641773 | F13: =IF(AND(E13<=0),"C",IF(E13<=0.8,"A",IF(E13<=0.95,"B","C"))) -> C | G13: =VLOOKUP(B$4:B$25,I$4:M$25,5,0) -> C | I13: MR Р1886 черн глянец | J13: ='Юнит 23-29.03'!R15 -> 1 | K13: =J13/J$26 -> 0.0076335878 | L13: =K13+L12 -> 0.9389313 | M13: =_xlfn.IFS(L13<80%,"A",L13<=95%,"B",L13>95%,"C") -> B | P13: A | Q13: 0.8
B14: MR Р1874 корич | C14: ='Юнит 23-29.03'!AE14 -> 0 | D14: =C14/C$26 -> 0 | E14: =D14+E13 -> 0.97641773 | F14: =IF(AND(E14<=0),"C",IF(E14<=0.8,"A",IF(E14<=0.95,"B","C"))) -> C | G14: =VLOOKUP(B$4:B$25,I$4:M$25,5,0) -> B | I14: MR Р1886 корич | J14: ='Юнит 23-29.03'!R16 -> 1 | K14: =J14/J$26 -> 0.0076335878 | L14: =K14+L13 -> 0.94656489 | M14: =_xlfn.IFS(L14<80%,"A",L14<=95%,"B",L14>95%,"C") -> B | P14: B | Q14: 0.15
B15: lux1 | C15: ='Юнит 23-29.03'!AE17 -> 0 | D15: =C15/C$26 -> 0 | E15: =D15+E14 -> 0.97641773 | F15: =IF(AND(E15<=0),"C",IF(E15<=0.8,"A",IF(E15<=0.95,"B","C"))) -> C | G15: =VLOOKUP(B$4:B$25,I$4:M$25,5,0) -> B | I15: th желтый Сул | J15: ='Юнит 23-29.03'!R8 -> 0 | K15: =J15/J$26 -> 0 | L15: =K15+L14 -> 0.94656489 | M15: =_xlfn.IFS(L15<80%,"A",L15<=95%,"B",L15>95%,"C") -> B | P15: C | Q15: 0.05
B16: lux2 | C16: ='Юнит 23-29.03'!AE18 -> 0 | D16: =C16/C$26 -> 0 | E16: =D16+E15 -> 0.97641773 | F16: =IF(AND(E16<=0),"C",IF(E16<=0.8,"A",IF(E16<=0.95,"B","C"))) -> C | G16: =VLOOKUP(B$4:B$25,I$4:M$25,5,0) -> B | I16: MR 1819 корич | J16: ='Юнит 23-29.03'!R12 -> 0 | K16: =J16/J$26 -> 0 | L16: =K16+L15 -> 0.94656489 | M16: =_xlfn.IFS(L16<80%,"A",L16<=95%,"B",L16>95%,"C") -> B
B17: lux4 | C17: ='Юнит 23-29.03'!AE20 -> 0 | D17: =C17/C$26 -> 0 | E17: =D17+E16 -> 0.97641773 | F17: =IF(AND(E17<=0),"C",IF(E17<=0.8,"A",IF(E17<=0.95,"B","C"))) -> C | G17: =VLOOKUP(B$4:B$25,I$4:M$25,5,0) -> B | I17: MR Р1874 корич | J17: ='Юнит 23-29.03'!R14 -> 0 | K17: =J17/J$26 -> 0 | L17: =K17+L16 -> 0.94656489 | M17: =_xlfn.IFS(L17<80%,"A",L17<=95%,"B",L17>95%,"C") -> B
B18: lux5 | C18: ='Юнит 23-29.03'!AE21 -> 0 | D18: =C18/C$26 -> 0 | E18: =D18+E17 -> 0.97641773 | F18: =IF(AND(E18<=0),"C",IF(E18<=0.8,"A",IF(E18<=0.95,"B","C"))) -> C | G18: =VLOOKUP(B$4:B$25,I$4:M$25,5,0) -> B | I18: lux1 | J18: ='Юнит 23-29.03'!R17 -> 0 | K18: =J18/J$26 -> 0 | L18: =K18+L17 -> 0.94656489 | M18: =_xlfn.IFS(L18<80%,"A",L18<=95%,"B",L18>95%,"C") -> B
B19: lux6 | C19: ='Юнит 23-29.03'!AE22 -> 0 | D19: =C19/C$26 -> 0 | E19: =D19+E18 -> 0.97641773 | F19: =IF(AND(E19<=0),"C",IF(E19<=0.8,"A",IF(E19<=0.95,"B","C"))) -> C | G19: =VLOOKUP(B$4:B$25,I$4:M$25,5,0) -> B | I19: lux2 | J19: ='Юнит 23-29.03'!R18 -> 0 | K19: =J19/J$26 -> 0 | L19: =K19+L18 -> 0.94656489 | M19: =_xlfn.IFS(L19<80%,"A",L19<=95%,"B",L19>95%,"C") -> B
B20: lux7 | C20: ='Юнит 23-29.03'!AE23 -> 0 | D20: =C20/C$26 -> 0 | E20: =D20+E19 -> 0.97641773 | F20: =IF(AND(E20<=0),"C",IF(E20<=0.8,"A",IF(E20<=0.95,"B","C"))) -> C | G20: =VLOOKUP(B$4:B$25,I$4:M$25,5,0) -> B | I20: lux3 | J20: ='Юнит 23-29.03'!R19 -> 0 | K20: =J20/J$26 -> 0 | L20: =K20+L19 -> 0.94656489 | M20: =_xlfn.IFS(L20<80%,"A",L20<=95%,"B",L20>95%,"C") -> B
B21: lux8 | C21: ='Юнит 23-29.03'!AE24 -> 0 | D21: =C21/C$26 -> 0 | E21: =D21+E20 -> 0.97641773 | F21: =IF(AND(E21<=0),"C",IF(E21<=0.8,"A",IF(E21<=0.95,"B","C"))) -> C | G21: =VLOOKUP(B$4:B$25,I$4:M$25,5,0) -> B | I21: lux4 | J21: ='Юнит 23-29.03'!R20 -> 0 | K21: =J21/J$26 -> 0 | L21: =K21+L20 -> 0.94656489 | M21: =_xlfn.IFS(L21<80%,"A",L21<=95%,"B",L21>95%,"C") -> B
B22: th желтый Сул | C22: ='Юнит 23-29.03'!AE8 -> -65.683221 | D22: =C22/C$26 -> -0.00077639367 | E22: =D22+E21 -> 0.97564134 | F22: =IF(AND(E22<=0),"C",IF(E22<=0.8,"A",IF(E22<=0.95,"B","C"))) -> C | G22: =VLOOKUP(B$4:B$25,I$4:M$25,5,0) -> B | I22: lux5 | J22: ='Юнит 23-29.03'!R21 -> 0 | K22: =J22/J$26 -> 0 | L22: =K22+L21 -> 0.94656489 | M22: =_xlfn.IFS(L22<80%,"A",L22<=95%,"B",L22>95%,"C") -> B
B23: lux3 | C23: ='Юнит 23-29.03'!AE19 -> -113.88 | D23: =C23/C$26 -> -0.0013460928 | E23: =D23+E22 -> 0.97429525 | F23: =IF(AND(E23<=0),"C",IF(E23<=0.8,"A",IF(E23<=0.95,"B","C"))) -> C | G23: =VLOOKUP(B$4:B$25,I$4:M$25,5,0) -> B | I23: lux6 | J23: ='Юнит 23-29.03'!R22 -> 0 | K23: =J23/J$26 -> 0 | L23: =K23+L22 -> 0.94656489 | M23: =_xlfn.IFS(L23<80%,"A",L23<=95%,"B",L23>95%,"C") -> B
B24: MR 1819 корич | C24: ='Юнит 23-29.03'!AE12 -> -187.08 | D24: =C24/C$26 -> -0.0022113369 | E24: =D24+E23 -> 0.97208391 | F24: =IF(AND(E24<=0),"C",IF(E24<=0.8,"A",IF(E24<=0.95,"B","C"))) -> C | G24: =VLOOKUP(B$4:B$25,I$4:M$25,5,0) -> B | I24: lux7 | J24: ='Юнит 23-29.03'!R23 -> 0 | K24: =J24/J$26 -> 0 | L24: =K24+L23 -> 0.94656489 | M24: =_xlfn.IFS(L24<80%,"A",L24<=95%,"B",L24>95%,"C") -> B
