Workbook

Sheet Реклама
B2: ПЕРИОД | C2: БАЛАНС | F2: СЧЕТ | I2: Неделя
C3: Номер документа | D3: Сумма | E3: Даты | F3: Номер документа | G3: Сумма | H3: Даты
B4: 01-04.01 | F4: 277607349 | G4: 4738 | H4: 01-04.01 | I4: 1
B5: 04-11.01 | F5: 279228154 | G5: 6535 | H5: 04-11.01 | I5: 2
B6: 11-18.01 | C6: 280305485 | D6: 2922 | E6: 14-18.01 | F6: 280297200 | G6: 3464 | H6: 11-17.01 | I6: 3
C7: 0 | D7: 923 | E7: 18.01 | F7: 0 | G7: 114 | H7: 18.01
B8: 18-25.01 | C8: 281290485 | D8: 5916 | E8: 18-23.01 | F8: 281290488 | G8: 2033 | H8: 18-25.01 | I8: 4
C9: 0 | D9: 1216 | E9: 25.01
B10: 25.01-01.02 | C10: 282283796 | D10: 12613 | E10: 27-31.01 | F10: 282343451 | G10: 9553 | H10: 25-31.01 | I10: 5
C11: 282375547 | D11: 1000 | E11: 01.02 | F11: 282385566 | G11: 79 | H11: 01.02
C12: 0 | D12: 1791 | E12: 01.02 | F12: 0 | G12: 539 | H12: 01.02
B13: 01-08.02 | C13: 283356234 | D13: 9526 | E13: 01-04.02 | F13: 283392061 | G13: 17308 | H13: 01-08.02 | I13: 6
F14: 0 | G14: 3305 | H14: 08.02
B15: 08-15.02 | C15: 284419876 | D15: 16968 | E15: 09-12.02 | F15: 284354982 | G15: 25029 | H15: 08-15.02 | I15: 7
F16: 0 | G16: 4431 | H16: 15,02
B17: 15-22.02 | I17: 8
H39: .

Sheet Сводная
B2: Период | E2: Дата поступления дс | F2: Итого к перечислению на счет, руб | G2: шт. | J2: ВБ реализовал товар (выручка с СПП) | M2: Выручка до вычета комиссии ВБ | P2: Себестоимость продаж | Q2: Логистика WB | R2: Комиссия WB | S2: Хранение WB | T2: Платная приемка WB | U2: Штрафы WB | V2: Прочие удержания WB | W2: Реклама БАЛАНС | X2: Реклама СЧЕТ | Y2: Блогеры | Z2: Налог | AA2: Прочие поступления WB | AB2: Прибыль до вычета налогов | AC2: Прибыль после вычета налогов | AD2: Итог месяц | AE2: % Cебестоимости | AF2: Маржинальность, % | AG2: Рентабельность, % | AH2: Доля рекламы, %
B3: Месяц | C3: Даты | D3: Нед | G3: Заказы | H3: Продажи | I3: Возвраты | J3: Продажи | K3: Возвраты | L3: Общая | M3: Продажи | N3: Возвраты | O3: Общая
B4: Январь 1 | C4: 29.12-04.01 | D4: 1 | F4: =IFERROR(O4-SUM(Q4:W4)+AA4,0) -> 29279.64 | G4: ='Юнит 1'!L$17 -> 66 | H4: ='Юнит 1'!Q$17 -> 45 | I4: ='Юнит 1'!R$17 -> 0 | J4: ='Юнит 1'!T$74 -> 46145.63 | K4: ='Юнит 1'!U$74 -> 0 | L4: =IFERROR(J4+K4,0) -> 46145.63 | M4: ='Юнит 1'!W$74 -> 54988.62 | N4: ='Юнит 1'!X$74 -> 0 | O4: =IFERROR(M4+N4,0) -> 54988.62 | P4: ='Юнит 1'!AB$74 -> 5712.21 | Q4: ='Юнит 1'!AE$74 -> 4543.05 | R4: ='Юнит 1'!AC$74 -> 19854.22 | S4: ='Юнит 1'!AI$74 -> 1049.63 | U4: ='Юнит 1'!AJ$74 -> 0 | V4: 262.08 | W4: ='Юнит 1'!AF$74 -> 0 | X4: ='Юнит 1'!AG$74 -> 4738 | Y4: ='Юнит 1'!AH84 -> 0 | Z4: 457.89 | AB4: =O4-SUM(P4:Y4)+AA4 -> 18829.43 | AC4: =O4-SUM(P4:Z4)+AA4 -> 18371.54 | AD4: =SUM(AC4:AC8) -> 67154.08 | AE4: =P4/O4 -> 0.10387986 | AF4: =AC4/P4 -> 3.2161878 | AG4: =AC4/O4 -> 0.33409713 | AH4: =(W4+X4+Y4)/O4 -> 0.086163283
B5: Январь 2 | C5: 05-11.01 | D5: 2 | F5: =IFERROR(O5-SUM(Q5:W5)+AA5,0) -> 25524.23 | G5: ='Юнит 2'!L$17 -> 86 | H5: ='Юнит 2'!Q$17 -> 43 | I5: ='Юнит 2'!R$17 -> -1 | J5: ='Юнит 2'!T$74 -> 43245.32 | K5: ='Юнит 2'!U$74 -> -931 | L5: =IFERROR(J5+K5,0) -> 42314.32 | M5: ='Юнит 2'!W$74 -> 52197.86 | N5: ='Юнит 2'!X$74 -> -1199 | O5: =IFERROR(M5+N5,0) -> 50998.86 | P5: ='Юнит 2'!AB$74 -> 5562.9 | Q5: ='Юнит 2'!AE$74 -> 5752.8 | R5: ='Юнит 2'!AC$74 -> 18463.04 | S5: ='Юнит 2'!AI$74 -> 1083.11 | U5: ='Юнит 2'!AJ$74 -> 0 | V5: 175.68 | W5: ='Юнит 2'!AF$74 -> 0 | X5: ='Юнит 2'!AG$74 -> 6535 | Y5: ='Юнит 2'!AH85 -> 0 | Z5: 416.28 | AB5: =O5-SUM(P5:Y5)+AA5 -> 13426.33 | AC5: =O5-SUM(P5:Z5)+AA5 -> 13010.05 | AE5: =P5/O5 -> 0.10907891 | AF5: =AC5/P5 -> 2.3387172 | AG5: =AC5/O5 -> 0.25510472 | AH5: =(W5+X5+Y5)/O5 -> 0.12814012
B6: Январь 3 | C6: 12-18.01 | D6: 3 | F6: =IFERROR(O6-SUM(Q6:W6)+AA6,0) -> 25982.83 | G6: ='Юнит 3'!L$17 -> 62 | H6: ='Юнит 3'!Q$17 -> 49 | I6: ='Юнит 3'!R$17 -> -1 | J6: ='Юнит 3'!T$74 -> 45785.47 | K6: ='Юнит 3'!U$74 -> -948 | L6: =IFERROR(J6+K6,0) -> 44837.47 | M6: ='Юнит 3'!W$74 -> 56919.74 | N6: ='Юнит 3'!X$74 -> -1174 | O6: =IFERROR(M6+N6,0) -> 55745.74 | P6: ='Юнит 3'!AB$74 -> 6528.42 | Q6: ='Юнит 3'!AE$74 -> 6055.25 | R6: ='Юнит 3'!AC$74 -> 19306.86 | S6: ='Юнит 3'!AI$74 -> 1361.68 | U6: ='Юнит 3'!AJ$74 -> 0 | V6: 117.12 | W6: ='Юнит 3'!AF$74 -> 2922 | X6: ='Юнит 3'!AG$74 -> 3464 | Y6: ='Юнит 3'!AH86 -> 0 | Z6: 467.24 | AB6: =O6-SUM(P6:Y6)+AA6 -> 15990.41 | AC6: =O6-SUM(P6:Z6)+AA6 -> 15523.17 | AE6: =P6/O6 -> 0.11711065 | AF6: =AC6/P6 -> 2.3777836 | AG6: =AC6/O6 -> 0.27846379 | AH6: =(W6+X6+Y6)/O6 -> 0.11455584
B7: Январь 4 | C7: 19-25.01 | D7: 4 | F7: =IFERROR(O7-SUM(Q7:W7)+AA7,0) -> 22836.85 | G7: ='Юнит 4'!L$17 -> 86 | H7: ='Юнит 4'!Q$17 -> 49 | I7: ='Юнит 4'!R$17 -> -2 | J7: ='Юнит 4'!T$74 -> 44338.88 | K7: ='Юнит 4'!U$74 -> -1888 | L7: =IFERROR(J7+K7,0) -> 42450.88 | M7: ='Юнит 4'!W$74 -> 59321.67 | N7: ='Юнит 4'!X$74 -> -2412 | O7: =IFERROR(M7+N7,0) -> 56909.67 | P7: ='Юнит 4'!AB$74 -> 6764.52 | Q7: ='Юнит 4'!AE$74 -> 6115.35 | R7: ='Юнит 4'!AC$74 -> 20543.92 | S7: ='Юнит 4'!AI$74 -> 1438.99 | U7: ='Юнит 4'!AJ$74 -> 0 | V7: 58.56 | W7: ='Юнит 4'!AF$74 -> 5916 | X7: ='Юнит 4'!AG$74 -> 2033 | Y7: ='Юнит 4'!AH87 -> 0 | Z7: 456.13 | AB7: =O7-SUM(P7:Y7)+AA7 -> 14039.33 | AC7: =O7-SUM(P7:Z7)+AA7 -> 13583.2 | AE7: =P7/O7 -> 0.11886416 | AF7: =AC7/P7 -> 2.0080065 | AG7: =AC7/O7 -> 0.23868 | AH7: =(W7+X7+Y7)/O7 -> 0.13967749
B8: Январь 5 | C8: 26.01-01.02 | D8: 5 | F8: =IFERROR(O8-SUM(Q8:W8)+AA8,0) -> 26541.81 | G8: ='Юнит 5'!L$17 -> 157 | H8: ='Юнит 5'!Q$17 -> 70 | I8: ='Юнит 5'!R$17 -> -1 | J8: ='Юнит 5'!T$74 -> 53707.42 | K8: ='Юнит 5'!U$74 -> -813 | L8: =IFERROR(J8+K8,0) -> 52894.42 | M8: ='Юнит 5'!W$74 -> 80352 | N8: ='Юнит 5'!X$74 -> -1238 | O8: =IFERROR(M8+N8,0) -> 79114 | P8: ='Юнит 5'!AB$74 -> 9760.32 | Q8: ='Юнит 5'!AE$74 -> 8509.6 | R8: ='Юнит 5'!AC$74 -> 28720.66 | S8: ='Юнит 5'!AI$74 -> 1377.57 | U8: ='Юнит 5'!AJ$74 -> 0 | V8: 351.36 | W8: ='Юнит 5'!AF$74 -> 13613 | X8: ='Юнит 5'!AG$74 -> 9632 | Y8: ='Юнит 5'!AH88 -> 0 | Z8: 483.37 | AB8: =O8-SUM(P8:Y8)+AA8 -> 7149.49 | AC8: =O8-SUM(P8:Z8)+AA8 -> 6666.12 | AE8: =P8/O8 -> 0.12337033 | AF8: =AC8/P8 -> 0.68298171 | AG8: =AC8/O8 -> 0.084259676 | AH8: =(W8+X8+Y8)/O8 -> 0.29381652
B9: Февраль 1 | C9: 02-08.02 | D9: 6 | F9: =IFERROR(O9-SUM(Q9:W9)+AA9,0) -> 59865 | G9: ='Юнит 6'!L$36 -> 286 | H9: ='Юнит 6'!Q$36 -> 118 | I9: ='Юнит 6'!R$36 -> -1 | J9: ='Юнит 6'!T$93 -> 85982.96 | K9: ='Юнит 6'!U$93 -> -777 | L9: =IFERROR(J9+K9,0) -> 85205.96 | M9: ='Юнит 6'!W$93 -> 132376.93 | N9: ='Юнит 6'!X$93 -> -1238 | O9: =IFERROR(M9+N9,0) -> 131138.93 | P9: ='Юнит 6'!AB$93 -> 15974.01 | Q9: ='Юнит 6'!AE$93 -> 12544.65 | R9: ='Юнит 6'!AC$93 -> 47795.47 | S9: ='Юнит 6'!AI$93 -> 1261.41 | U9: ='Юнит 6'!AJ$93 -> 0 | V9: 146.4 | W9: ='Юнит 6'!AF$93 -> 9526 | X9: ='Юнит 6'!AG$93 -> 17308 | Y9: ='Юнит 6'!AH108 -> 0 | Z9: =IFERROR((L9)*0.01,0) -> 852.0596 | AB9: =O9-SUM(P9:Y9)+AA9 -> 26582.99 | AC9: =O9-SUM(P9:Z9)+AA9 -> 25730.93 | AD9: =SUM(AC9:AC12) -> 77284.918 | AE9: =P9/O9 -> 0.12180982 | AF9: =AC9/P9 -> 1.6107997 | AG9: =AC9/O9 -> 0.19621123 | AH9: =(W9+X9+Y9)/O9 -> 0.20462269
B10: Февраль 2 | C10: 09-15.02 | D10: 7 | F10: =IFERROR(O10-SUM(Q10:W10)+AA10,0) -> 105982.04 | G10: ='Юнит 7'!L$36 -> 388 | H10: ='Юнит 7'!Q$36 -> 212 | I10: ='Юнит 7'!R$36 -> -2 | J10: ='Юнит 7'!T$93 -> 149383.2 | K10: ='Юнит 7'!U$93 -> -1458 | L10: =IFERROR(J10+K10,0) -> 147925.2 | M10: ='Юнит 7'!W$93 -> 234275.74 | N10: ='Юнит 7'!X$93 -> -2388 | O10: =IFERROR(M10+N10,0) -> 231887.74 | P10: ='Юнит 7'!AB$93 -> 27919.8 | Q10: ='Юнит 7'!AE$93 -> 22767.8 | R10: ='Юнит 7'!AC$93 -> 84374.68 | S10: ='Юнит 7'!AI$93 -> 1132.46 | T10: 165 | U10: ='Юнит 7'!AJ$93 -> 0 | V10: 497.76 | W10: ='Юнит 7'!AF$93 -> 16968 | X10: ='Юнит 7'!AG$93 -> 25029 | Y10: ='Юнит 7'!AH109 -> 0 | Z10: =IFERROR((L10)*0.01,0) -> 1479.252 | AB10: =O10-SUM(P10:Y10)+AA10 -> 53033.24 | AC10: =O10-SUM(P10:Z10)+AA10 -> 51553.988 | AE10: =P10/O10 -> 0.12040223 | AF10: =AC10/P10 -> 1.8465028 | AG10: =AC10/O10 -> 0.22232304 | AH10: =(W10+X10+Y10)/O10 -> 0.18110919
B11: Февраль 3 | C11: 16-22.02 | D11: 8 | AB11: =O11-SUM(P11:Y11)+AA11 -> 0 | AC11: =O11-SUM(P11:Z11)+AA11 -> 0 | AE11: =P11/O11 -> #DIV/0! | AF11: =AC11/P11 -> #DIV/0! | AG11: =AC11/O11 -> #DIV/0! | AH11: =(W11+X11+Y11)/O11 -> #DIV/0!
B12: Февраль 4 | C12: 23.02-01.03 | D12: 9 | AB12: =O12-SUM(P12:Y12)+AA12 -> 0 | AC12: =O12-SUM(P12:Z12)+AA12 -> 0 | AE12: =P12/O12 -> #DIV/0! | AF12: =AC12/P12 -> #DIV/0! | AG12: =AC12/O12 -> #DIV/0! | AH12: =(W12+X12+Y12)/O12 -> #DIV/0!
AB13: =O13-SUM(P13:Y13)+AA13 -> 0 | AC13: =O13-SUM(P13:Z13)+AA13 -> 0 | AE13: =P13/O13 -> #DIV/0! | AF13: =AC13/P13 -> #DIV/0! | AG13: =AC13/O13 -> #DIV/0! | AH13: =(W13+X13+Y13)/O13 -> #DIV/0!
B14: Итого | F14: =SUM(F4:F13) -> 296012.4 | G14: =SUM(G4:G13) -> 1131 | H14: =SUM(H4:H13) -> 586 | I14: =SUM(I4:I13) -> -8 | J14: =SUM(J4:J13) -> 468588.88 | K14: =SUM(K4:K13) -> -6815 | L14: =SUM(L4:L13) -> 461773.88 | M14: =SUM(M4:M13) -> 670432.56 | ... AD14: =SUM(AD4:AD13) -> 144439 | AE14: =P14/O14 -> 0.11837791 | AF14: =AC14/P14 -> 1.8465223 | AG14: =AC14/O14 -> 0.21858746 | AH14: =(W14+X14+Y14)/O14 -> 0.17809765
M15: % от выручки за весь период
N16: =-N14/M14 -> 0.014392201 | P16: =P14/$O$14 -> 0.11837791 | Q16: =Q14/$O$14 -> 0.10031802 | R16: =R14/$O$14 -> 0.36178087 | S16: =S14/$O$14 -> 0.013173527 | T16: =T14/$O$14 -> 0.00024970355 | U16: =U14/$O$14 -> 0 | V16: =V14/$O$14 -> 0.0024349274 | W16: =W14/$O$14 -> 0.074071153 | ... Z16: =Z14/$O$14 -> 0.0069799279 | AC16: =AC14/P14 -> 1.8465223 | AD16: Маржинальность, %
W17: =(W14+X14)/O14 -> 0.17809765 | AC17: =AC14/O14 -> 0.21858746 | AD17: Рентабельность, %
B18: ЯНВАРЬ | G18: =SUM(G4:G8) -> 457 | H18: =SUM(H4:H8) -> 256 | I18: =SUM(I4:I8) -> -5 | J18: =SUM(J4:J8) -> 233222.72 | K18: =SUM(K4:K8) -> -4580 | L18: =SUM(L4:L8) -> 228642.72 | M18: =SUM(M4:M8) -> 303779.89 | N18: =SUM(N4:N8) -> -6023 | ... AA18: =SUM(AA4:AA8) -> 0 | AC18: =SUM(AC4:AC8) -> 67154.08 | AD18: =AC14/O14 -> 0.21858746
N19: =-N18/M18 -> 0.019826856 | P19: =P18/$O$14 -> 0.051951005 | Q19: =Q18/$O$14 -> 0.046877755 | R19: =R18/$O$14 -> 0.16176053 | S19: =S18/$O$14 -> 0.0095507521 | T19: =T18/$O$14 -> 0 | U19: =U18/$O$14 -> 0 | V19: =V18/$O$14 -> 0.0014600848 | W19: =W18/$O$14 -> 0.03397633 | ... AA19: =AA18/$O$14 -> 0 | AC19: =AC18/O18 -> 0.22553325

Sheet АВС 8
B2: ОЧКИ
C3: Прибыль | D3: % прибыль | E3: Доля | F3: ABC прибыль | G3: ABC кол-во | J3: Кол-во | K3: % кол-во | L3: Доля | M3: ABC кол-во
B4: Черные с железкой Сул | D4: =C4/C$36 -> #DIV/0! | E4: =D4 -> #DIV/0! | F4: =IF(AND(E4<=0),"C",IF(E4<=0.8,"A",IF(E4<=0.95,"B","C"))) -> #DIV/0! | G4: =VLOOKUP(B$4:B$35,I$4:M$35,5,0) -> #DIV/0! | I4: Черные с железкой Сул | K4: =J4/J$36 -> #DIV/0! | L4: =K4 -> #DIV/0! | M4: =_xlfn.IFS(L4<80%,"A",L4<=95%,"B",L4>95%,"C") -> #DIV/0! | P4: A | Q4: 0.8
B5: Qs черн Сул | D5: =C5/C$36 -> #DIV/0! | E5: =E4+D5 -> #DIV/0! | F5: =IF(AND(E5<=0),"C",IF(E5<=0.8,"A",IF(E5<=0.95,"B","C"))) -> #DIV/0! | G5: =VLOOKUP(B$4:B$35,I$4:M$35,5,0) -> #DIV/0! | I5: Qs черн Сул | K5: =J5/J$36 -> #DIV/0! | L5: =L4+K5 -> #DIV/0! | M5: =_xlfn.IFS(L5<80%,"A",L5<=95%,"B",L5>95%,"C") -> #DIV/0! | P5: B | Q5: 0.15
B6: Qs син Сул | D6: =C6/C$36 -> #DIV/0! | E6: =E5+D6 -> #DIV/0! | F6: =IF(AND(E6<=0),"C",IF(E6<=0.8,"A",IF(E6<=0.95,"B","C"))) -> #DIV/0! | G6: =VLOOKUP(B$4:B$35,I$4:M$35,5,0) -> #DIV/0! | I6: Qs син Сул | K6: =J6/J$36 -> #DIV/0! | L6: =L5+K6 -> #DIV/0! | M6: =_xlfn.IFS(L6<80%,"A",L6<=95%,"B",L6>95%,"C") -> #DIV/0! | P6: C | Q6: 0.05
B7: Qs желт Сул | D7: =C7/C$36 -> #DIV/0! | E7: =E6+D7 -> #DIV/0! | F7: =IF(AND(E7<=0),"C",IF(E7<=0.8,"A",IF(E7<=0.95,"B","C"))) -> #DIV/0! | G7: =VLOOKUP(B$4:B$35,I$4:M$35,5,0) -> #DIV/0! | I7: Qs желт Сул | K7: =J7/J$36 -> #DIV/0! | L7: =L6+K7 -> #DIV/0! | M7: =_xlfn.IFS(L7<80%,"A",L7<=95%,"B",L7>95%,"C") -> #DIV/0!
B8: flip черные Сул | D8: =C8/C$36 -> #DIV/0! | E8: =E7+D8 -> #DIV/0! | F8: =IF(AND(E8<=0),"C",IF(E8<=0.8,"A",IF(E8<=0.95,"B","C"))) -> #DIV/0! | G8: =VLOOKUP(B$4:B$35,I$4:M$35,5,0) -> #DIV/0! | I8: flip черные Сул | K8: =J8/J$36 -> #DIV/0! | L8: =L7+K8 -> #DIV/0! | M8: =_xlfn.IFS(L8<80%,"A",L8<=95%,"B",L8>95%,"C") -> #DIV/0!
B9: flip желтые Сул | D9: =C9/C$36 -> #DIV/0! | E9: =E8+D9 -> #DIV/0! | F9: =IF(AND(E9<=0),"C",IF(E9<=0.8,"A",IF(E9<=0.95,"B","C"))) -> #DIV/0! | G9: =VLOOKUP(B$4:B$35,I$4:M$35,5,0) -> #DIV/0! | I9: flip желтые Сул | K9: =J9/J$36 -> #DIV/0! | L9: =L8+K9 -> #DIV/0! | M9: =_xlfn.IFS(L9<80%,"A",L9<=95%,"B",L9>95%,"C") -> #DIV/0!
B10: MR8854 C2 Сул | D10: =C10/C$36 -> #DIV/0! | E10: =E9+D10 -> #DIV/0! | F10: =IF(AND(E10<=0),"C",IF(E10<=0.8,"A",IF(E10<=0.95,"B","C"))) -> #DIV/0! | G10: =VLOOKUP(B$4:B$35,I$4:M$35,5,0) -> #DIV/0! | I10: MR8854 C2 Сул | K10: =J10/J$36 -> #DIV/0! | L10: =L9+K10 -> #DIV/0! | M10: =_xlfn.IFS(L10<80%,"A",L10<=95%,"B",L10>95%,"C") -> #DIV/0!
B11: MR 1819 черн | D11: =C11/C$36 -> #DIV/0! | E11: =E10+D11 -> #DIV/0! | F11: =IF(AND(E11<=0),"C",IF(E11<=0.8,"A",IF(E11<=0.95,"B","C"))) -> #DIV/0! | G11: =VLOOKUP(B$4:B$35,I$4:M$35,5,0) -> #DIV/0! | I11: MR 1819 черн | K11: =J11/J$36 -> #DIV/0! | L11: =L10+K11 -> #DIV/0! | M11: =_xlfn.IFS(L11<80%,"A",L11<=95%,"B",L11>95%,"C") -> #DIV/0!
B12: MR 1819 корич | D12: =C12/C$36 -> #DIV/0! | E12: =E11+D12 -> #DIV/0! | F12: =IF(AND(E12<=0),"C",IF(E12<=0.8,"A",IF(E12<=0.95,"B","C"))) -> #DIV/0! | G12: =VLOOKUP(B$4:B$35,I$4:M$35,5,0) -> #DIV/0! | I12: MR 1819 корич | K12: =J12/J$36 -> #DIV/0! | L12: =L11+K12 -> #DIV/0! | M12: =_xlfn.IFS(L12<80%,"A",L12<=95%,"B",L12>95%,"C") -> #DIV/0!
B13: MR Р1874 черн | D13: =C13/C$36 -> #DIV/0! | E13: =E12+D13 -> #DIV/0! | F13: =IF(AND(E13<=0),"C",IF(E13<=0.8,"A",IF(E13<=0.95,"B","C"))) -> #DIV/0! | G13: =VLOOKUP(B$4:B$35,I$4:M$35,5,0) -> #DIV/0! | I13: MR Р1874 черн | K13: =J13/J$36 -> #DIV/0! | L13: =L12+K13 -> #DIV/0! | M13: =_xlfn.IFS(L13<80%,"A",L13<=95%,"B",L13>95%,"C") -> #DIV/0!
B14: MR Р1874 корич | D14: =C14/C$36 -> #DIV/0! | E14: =E13+D14 -> #DIV/0! | F14: =IF(AND(E14<=0),"C",IF(E14<=0.8,"A",IF(E14<=0.95,"B","C"))) -> #DIV/0! | G14: =VLOOKUP(B$4:B$35,I$4:M$35,5,0) -> #DIV/0! | I14: MR Р1874 корич | K14: =J14/J$36 -> #DIV/0! | L14: =L13+K14 -> #DIV/0! | M14: =_xlfn.IFS(L14<80%,"A",L14<=95%,"B",L14>95%,"C") -> #DIV/0!
B15: MR Р1886 черн | D15: =C15/C$36 -> #DIV/0! | E15: =E14+D15 -> #DIV/0! | F15: =IF(AND(E15<=0),"C",IF(E15<=0.8,"A",IF(E15<=0.95,"B","C"))) -> #DIV/0! | G15: =VLOOKUP(B$4:B$35,I$4:M$35,5,0) -> #DIV/0! | I15: MR Р1886 черн | K15: =J15/J$36 -> #DIV/0! | L15: =L14+K15 -> #DIV/0! | M15: =_xlfn.IFS(L15<80%,"A",L15<=95%,"B",L15>95%,"C") -> #DIV/0!
B16: MR Р1886 корич | D16: =C16/C$36 -> #DIV/0! | E16: =E15+D16 -> #DIV/0! | F16: =IF(AND(E16<=0),"C",IF(E16<=0.8,"A",IF(E16<=0.95,"B","C"))) -> #DIV/0! | G16: =VLOOKUP(B$4:B$35,I$4:M$35,5,0) -> #DIV/0! | I16: MR Р1886 корич | K16: =J16/J$36 -> #DIV/0! | L16: =L15+K16 -> #DIV/0! | M16: =_xlfn.IFS(L16<80%,"A",L16<=95%,"B",L16>95%,"C") -> #DIV/0!
B17: qs001 | D17: =C17/C$36 -> #DIV/0! | E17: =E16+D17 -> #DIV/0! | F17: =IF(AND(E17<=0),"C",IF(E17<=0.8,"A",IF(E17<=0.95,"B","C"))) -> #DIV/0! | G17: =VLOOKUP(B$4:B$35,I$4:M$35,5,0) -> #DIV/0! | I17: qs001 | K17: =J17/J$36 -> #DIV/0! | L17: =L16+K17 -> #DIV/0! | M17: =_xlfn.IFS(L17<80%,"A",L17<=95%,"B",L17>95%,"C") -> #DIV/0!
B18: qs002 | D18: =C18/C$36 -> #DIV/0! | E18: =E17+D18 -> #DIV/0! | F18: =IF(AND(E18<=0),"C",IF(E18<=0.8,"A",IF(E18<=0.95,"B","C"))) -> #DIV/0! | G18: =VLOOKUP(B$4:B$35,I$4:M$35,5,0) -> #DIV/0! | I18: qs002 | K18: =J18/J$36 -> #DIV/0! | L18: =L17+K18 -> #DIV/0! | M18: =_xlfn.IFS(L18<80%,"A",L18<=95%,"B",L18>95%,"C") -> #DIV/0!
... B35: 6008 | D35: =C35/C$36 -> #DIV/0! | E35: =E34+D35 -> #DIV/0! | F35: =IF(AND(E35<=0),"C",IF(E35<=0.8,"A",IF(E35<=0.95,"B","C"))) -> #DIV/0! | G35: =VLOOKUP(B$4:B$35,I$4:M$35,5,0) -> #DIV/0! | I35: 6008 | K35: =J35/J$36 -> #DIV/0! | L35: =L34+K35 -> #DIV/0! | M35: =_xlfn.IFS(L35<80%,"A",L35<=95%,"B",L35>95%,"C") -> #DIV/0!
C36: =SUM(C4:C16) -> 0 | D36: =SUM(D4:D16) -> #DIV/0! | J36: =SUM(J4:J16) -> 0 | K36: =SUM(K4:K16) -> #DIV/0!

Sheet АВС 7
B2: ОЧКИ
C3: Прибыль | D3: % прибыль | E3: Доля | F3: ABC прибыль | G3: ABC кол-во | J3: Кол-во | K3: % кол-во | L3: Доля | M3: ABC кол-во
B4: Черные с железкой Сул | C4: ='Юнит 7'!AL3 -> 17228.538 | D4: =C4/C$36 -> 0.29979928 | E4: =D4 -> 0.29979928 | F4: =IF(AND(E4<=0),"C",IF(E4<=0.8,"A",IF(E4<=0.95,"B","C"))) -> A | G4: =VLOOKUP(B$4:B$35,I$4:M$35,5,0) -> A | I4: Черные с железкой Сул | J4: ='Юнит 7'!S3 -> 50 | K4: =J4/J$36 -> 0.23809524 | L4: =K4 -> 0.23809524 | M4: =_xlfn.IFS(L4<80%,"A",L4<=95%,"B",L4>95%,"C") -> A | P4: A | Q4: 0.8
B5: Qs черн Сул | C5: ='Юнит 7'!AL4 -> 20125.028 | D5: =C5/C$36 -> 0.35020203 | E5: =E4+D5 -> 0.65000131 | F5: =IF(AND(E5<=0),"C",IF(E5<=0.8,"A",IF(E5<=0.95,"B","C"))) -> A | G5: =VLOOKUP(B$4:B$35,I$4:M$35,5,0) -> A | I5: Qs черн Сул | J5: ='Юнит 7'!S4 -> 72 | K5: =J5/J$36 -> 0.34285714 | L5: =L4+K5 -> 0.58095238 | M5: =_xlfn.IFS(L5<80%,"A",L5<=95%,"B",L5>95%,"C") -> A | P5: B | Q5: 0.15
B6: Qs син Сул | C6: ='Юнит 7'!AL5 -> 428.6604 | D6: =C6/C$36 -> 0.0074592564 | E6: =E5+D6 -> 0.65746056 | F6: =IF(AND(E6<=0),"C",IF(E6<=0.8,"A",IF(E6<=0.95,"B","C"))) -> A | G6: =VLOOKUP(B$4:B$35,I$4:M$35,5,0) -> A | I6: Qs син Сул | J6: ='Юнит 7'!S5 -> 3 | K6: =J6/J$36 -> 0.014285714 | L6: =L5+K6 -> 0.5952381 | M6: =_xlfn.IFS(L6<80%,"A",L6<=95%,"B",L6>95%,"C") -> A | P6: C | Q6: 0.05
B7: Qs желт Сул | C7: ='Юнит 7'!AL6 -> 1904.0494 | D7: =C7/C$36 -> 0.033132971 | E7: =E6+D7 -> 0.69059353 | F7: =IF(AND(E7<=0),"C",IF(E7<=0.8,"A",IF(E7<=0.95,"B","C"))) -> A | G7: =VLOOKUP(B$4:B$35,I$4:M$35,5,0) -> A | I7: Qs желт Сул | J7: ='Юнит 7'!S6 -> 16 | K7: =J7/J$36 -> 0.076190476 | L7: =L6+K7 -> 0.67142857 | M7: =_xlfn.IFS(L7<80%,"A",L7<=95%,"B",L7>95%,"C") -> A
B8: flip черные Сул | C8: ='Юнит 7'!AL7 -> 5729.5206 | D8: =C8/C$36 -> 0.099701216 | E8: =E7+D8 -> 0.79029475 | F8: =IF(AND(E8<=0),"C",IF(E8<=0.8,"A",IF(E8<=0.95,"B","C"))) -> A | G8: =VLOOKUP(B$4:B$35,I$4:M$35,5,0) -> A | I8: flip черные Сул | J8: ='Юнит 7'!S7 -> 22 | K8: =J8/J$36 -> 0.1047619 | L8: =L7+K8 -> 0.77619048 | M8: =_xlfn.IFS(L8<80%,"A",L8<=95%,"B",L8>95%,"C") -> A
B9: flip желтые Сул | C9: ='Юнит 7'!AL8 -> 5902.157 | D9: =C9/C$36 -> 0.10270532 | E9: =E8+D9 -> 0.89300007 | F9: =IF(AND(E9<=0),"C",IF(E9<=0.8,"A",IF(E9<=0.95,"B","C"))) -> B | G9: =VLOOKUP(B$4:B$35,I$4:M$35,5,0) -> B | I9: flip желтые Сул | J9: ='Юнит 7'!S8 -> 24 | K9: =J9/J$36 -> 0.11428571 | L9: =L8+K9 -> 0.89047619 | M9: =_xlfn.IFS(L9<80%,"A",L9<=95%,"B",L9>95%,"C") -> B
B10: MR8854 C2 Сул | C10: ='Юнит 7'!AL9 -> 4814.9045 | D10: =C10/C$36 -> 0.083785689 | E10: =E9+D10 -> 0.97678576 | F10: =IF(AND(E10<=0),"C",IF(E10<=0.8,"A",IF(E10<=0.95,"B","C"))) -> C | G10: =VLOOKUP(B$4:B$35,I$4:M$35,5,0) -> B | I10: MR8854 C2 Сул | J10: ='Юнит 7'!S9 -> 11 | K10: =J10/J$36 -> 0.052380952 | L10: =L9+K10 -> 0.94285714 | M10: =_xlfn.IFS(L10<80%,"A",L10<=95%,"B",L10>95%,"C") -> B
B11: MR 1819 черн | C11: ='Юнит 7'!AL10 -> -2385.838 | D11: =C11/C$36 -> -0.041516728 | E11: =E10+D11 -> 0.93526903 | F11: =IF(AND(E11<=0),"C",IF(E11<=0.8,"A",IF(E11<=0.95,"B","C"))) -> B | G11: =VLOOKUP(B$4:B$35,I$4:M$35,5,0) -> C | I11: MR 1819 черн | J11: ='Юнит 7'!S10 -> 3 | K11: =J11/J$36 -> 0.014285714 | L11: =L10+K11 -> 0.95714286 | M11: =_xlfn.IFS(L11<80%,"A",L11<=95%,"B",L11>95%,"C") -> C
B12: MR 1819 корич | C12: ='Юнит 7'!AL11 -> -135.49913 | D12: =C12/C$36 -> -0.0023578636 | E12: =E11+D12 -> 0.93291116 | F12: =IF(AND(E12<=0),"C",IF(E12<=0.8,"A",IF(E12<=0.95,"B","C"))) -> B | G12: =VLOOKUP(B$4:B$35,I$4:M$35,5,0) -> C | I12: MR 1819 корич | J12: ='Юнит 7'!S11 -> 0 | K12: =J12/J$36 -> 0 | L12: =L11+K12 -> 0.95714286 | M12: =_xlfn.IFS(L12<80%,"A",L12<=95%,"B",L12>95%,"C") -> C
B13: MR Р1874 черн | C13: ='Юнит 7'!AL12 -> 1392.2638 | D13: =C13/C$36 -> 0.024227226 | E13: =E12+D13 -> 0.95713839 | F13: =IF(AND(E13<=0),"C",IF(E13<=0.8,"A",IF(E13<=0.95,"B","C"))) -> C | G13: =VLOOKUP(B$4:B$35,I$4:M$35,5,0) -> C | I13: MR Р1874 черн | J13: ='Юнит 7'!S12 -> 4 | K13: =J13/J$36 -> 0.019047619 | L13: =L12+K13 -> 0.97619048 | M13: =_xlfn.IFS(L13<80%,"A",L13<=95%,"B",L13>95%,"C") -> C
B14: MR Р1874 корич | C14: ='Юнит 7'!AL13 -> 1091.9077 | D14: =C14/C$36 -> 0.019000634 | E14: =E13+D14 -> 0.97613902 | F14: =IF(AND(E14<=0),"C",IF(E14<=0.8,"A",IF(E14<=0.95,"B","C"))) -> C | G14: =VLOOKUP(B$4:B$35,I$4:M$35,5,0) -> C | I14: MR Р1874 корич | J14: ='Юнит 7'!S13 -> 2 | K14: =J14/J$36 -> 0.0095238095 | L14: =L13+K14 -> 0.98571429 | M14: =_xlfn.IFS(L14<80%,"A",L14<=95%,"B",L14>95%,"C") -> C
B15: MR Р1886 черн | C15: ='Юнит 7'!AL14 -> 1055.2304 | D15: =C15/C$36 -> 0.018362401 | E15: =E14+D15 -> 0.99450142 | F15: =IF(AND(E15<=0),"C",IF(E15<=0.8,"A",IF(E15<=0.95,"B","C"))) -> C | G15: =VLOOKUP(B$4:B$35,I$4:M$35,5,0) -> C | I15: MR Р1886 черн | J15: ='Юнит 7'!S14 -> 2 | K15: =J15/J$36 -> 0.0095238095 | L15: =L14+K15 -> 0.9952381 | M15: =_xlfn.IFS(L15<80%,"A",L15<=95%,"B",L15>95%,"C") -> C
B16: MR Р1886 корич | C16: ='Юнит 7'!AL15 -> 315.98611 | D16: =C16/C$36 -> 0.0054985751 | E16: =E15+D16 -> 1 | F16: =IF(AND(E16<=0),"C",IF(E16<=0.8,"A",IF(E16<=0.95,"B","C"))) -> C | G16: =VLOOKUP(B$4:B$35,I$4:M$35,5,0) -> C | I16: MR Р1886 корич | J16: ='Юнит 7'!S15 -> 1 | K16: =J16/J$36 -> 0.0047619048 | L16: =L15+K16 -> 1 | M16: =_xlfn.IFS(L16<80%,"A",L16<=95%,"B",L16>95%,"C") -> C
B17: qs001 | C17: ='Юнит 7'!AL16 -> 0 | D17: =C17/C$36 -> 0 | E17: =E16+D17 -> 1 | F17: =IF(AND(E17<=0),"C",IF(E17<=0.8,"A",IF(E17<=0.95,"B","C"))) -> C | G17: =VLOOKUP(B$4:B$35,I$4:M$35,5,0) -> C | I17: qs001 | J17: ='Юнит 7'!S16 -> 0 | K17: =J17/J$36 -> 0 | L17: =L16+K17 -> 1 | M17: =_xlfn.IFS(L17<80%,"A",L17<=95%,"B",L17>95%,"C") -> C
B18: qs002 | C18: ='Юнит 7'!AL17 -> 0 | D18: =C18/C$36 -> 0 | E18: =E17+D18 -> 1 | F18: =IF(AND(E18<=0),"C",IF(E18<=0.8,"A",IF(E18<=0.95,"B","C"))) -> C | G18: =VLOOKUP(B$4:B$35,I$4:M$35,5,0) -> C | I18: qs002 | J18: ='Юнит 7'!S17 -> 0 | K18: =J18/J$36 -> 0 | L18: =L17+K18 -> 1 | M18: =_xlfn.IFS(L18<80%,"A",L18<=95%,"B",L18>95%,"C") -> C
... B22: qs013 | C22: ='Юнит 7'!AL21 -> 0 | D22: =C22/C$36 -> 0 | E22: =E21+D22 -> 1 | F22: =IF(AND(E22<=0),"C",IF(E22<=0.8,"A",IF(E22<=0.95,"B","C"))) -> C | G22: =VLOOKUP(B$4:B$35,I$4:M$35,5,0) -> C | I22: qs013 | J22: ='Юнит 7'!S21 -> 0 | K22: =J22/J$36 -> 0 | L22: =L21+K22 -> 1 | M22: =_xlfn.IFS(L22<80%,"A",L22<=95%,"B",L22>95%,"C") -> C
B23: qs015 | C23: ='Юнит 7'!AL23 -> 0 | D23: =C23/C$36 -> 0 | E23: =E22+D23 -> 1 | F23: =IF(AND(E23<=0),"C",IF(E23<=0.8,"A",IF(E23<=0.95,"B","C"))) -> C | G23: =VLOOKUP(B$4:B$35,I$4:M$35,5,0) -> C | I23: qs014 | J23: ='Юнит 7'!S22 -> 0 | K23: =J23/J$36 -> 0 | L23: =L22+K23 -> 1 | M23: =_xlfn.IFS(L23<80%,"A",L23<=95%,"B",L23>95%,"C") -> C
B24: qs010ж | C24: ='Юнит 7'!AL25 -> 0 | D24: =C24/C$36 -> 0 | E24: =E23+D24 -> 1 | F24: =IF(AND(E24<=0),"C",IF(E24<=0.8,"A",IF(E24<=0.95,"B","C"))) -> C | G24: =VLOOKUP(B$4:B$35,I$4:M$35,5,0) -> C | I24: qs015 | J24: ='Юнит 7'!S23 -> 0 | K24: =J24/J$36 -> 0 | L24: =L23+K24 -> 1 | M24: =_xlfn.IFS(L24<80%,"A",L24<=95%,"B",L24>95%,"C") -> C
B25: qs011ж | C25: ='Юнит 7'!AL26 -> 0 | D25: =C25/C$36 -> 0 | E25: =E24+D25 -> 1 | F25: =IF(AND(E25<=0),"C",IF(E25<=0.8,"A",IF(E25<=0.95,"B","C"))) -> C | G25: =VLOOKUP(B$4:B$35,I$4:M$35,5,0) -> C | I25: qs001 Ж | J25: ='Юнит 7'!S24 -> 0 | K25: =J25/J$36 -> 0 | L25: =L24+K25 -> 1 | M25: =_xlfn.IFS(L25<80%,"A",L25<=95%,"B",L25>95%,"C") -> C
B26: 2038ч/б | C26: ='Юнит 7'!AL28 -> 0 | D26: =C26/C$36 -> 0 | E26: =E25+D26 -> 1 | F26: =IF(AND(E26<=0),"C",IF(E26<=0.8,"A",IF(E26<=0.95,"B","C"))) -> C | G26: =VLOOKUP(B$4:B$35,I$4:M$35,5,0) -> C | I26: qs010ж | J26: ='Юнит 7'!S25 -> 0 | K26: =J26/J$36 -> 0 | L26: =L25+K26 -> 1 | M26: =_xlfn.IFS(L26<80%,"A",L26<=95%,"B",L26>95%,"C") -> C
B27: 2100красный | C27: ='Юнит 7'!AL31 -> 0 | D27: =C27/C$36 -> 0 | E27: =E26+D27 -> 1 | F27: =IF(AND(E27<=0),"C",IF(E27<=0.8,"A",IF(E27<=0.95,"B","C"))) -> C | G27: =VLOOKUP(B$4:B$35,I$4:M$35,5,0) -> C | I27: qs011ж | J27: ='Юнит 7'!S26 -> 0 | K27: =J27/J$36 -> 0 | L27: =L26+K27 -> 1 | M27: =_xlfn.IFS(L27<80%,"A",L27<=95%,"B",L27>95%,"C") -> C
B28: 2104 | C28: ='Юнит 7'!AL33 -> 0 | D28: =C28/C$36 -> 0 | E28: =E27+D28 -> 1 | F28: =IF(AND(E28<=0),"C",IF(E28<=0.8,"A",IF(E28<=0.95,"B","C"))) -> C | G28: =VLOOKUP(B$4:B$35,I$4:M$35,5,0) -> C | I28: qs012ж | J28: ='Юнит 7'!S27 -> 0 | K28: =J28/J$36 -> 0 | L28: =L27+K28 -> 1 | M28: =_xlfn.IFS(L28<80%,"A",L28<=95%,"B",L28>95%,"C") -> C
B29: 6008 | C29: ='Юнит 7'!AL34 -> 0 | D29: =C29/C$36 -> 0 | E29: =E28+D29 -> 1 | F29: =IF(AND(E29<=0),"C",IF(E29<=0.8,"A",IF(E29<=0.95,"B","C"))) -> C | G29: =VLOOKUP(B$4:B$35,I$4:M$35,5,0) -> C | I29: 2038ч/б | J29: ='Юнит 7'!S28 -> 0 | K29: =J29/J$36 -> 0 | L29: =L28+K29 -> 1 | M29: =_xlfn.IFS(L29<80%,"A",L29<=95%,"B",L29>95%,"C") -> C
B30: qs014 | C30: ='Юнит 7'!AL22 -> -7 | D30: =C30/C$36 -> -0.00012180923 | E30: =E29+D30 -> 0.99987819 | F30: =IF(AND(E30<=0),"C",IF(E30<=0.8,"A",IF(E30<=0.95,"B","C"))) -> C | G30: =VLOOKUP(B$4:B$35,I$4:M$35,5,0) -> C | I30: 2038красный | J30: ='Юнит 7'!S29 -> 0 | K30: =J30/J$36 -> 0 | L30: =L29+K30 -> 1 | M30: =_xlfn.IFS(L30<80%,"A",L30<=95%,"B",L30>95%,"C") -> C
B31: qs012ж | C31: ='Юнит 7'!AL27 -> -376 | D31: =C31/C$36 -> -0.006542896 | E31: =E30+D31 -> 0.99333529 | F31: =IF(AND(E31<=0),"C",IF(E31<=0.8,"A",IF(E31<=0.95,"B","C"))) -> C | G31: =VLOOKUP(B$4:B$35,I$4:M$35,5,0) -> C | I31: 2100черный | J31: ='Юнит 7'!S30 -> 0 | K31: =J31/J$36 -> 0 | L31: =L30+K31 -> 1 | M31: =_xlfn.IFS(L31<80%,"A",L31<=95%,"B",L31>95%,"C") -> C
B32: 2100фиолетовый | C32: ='Юнит 7'!AL32 -> -427 | D32: =C32/C$36 -> -0.0074303632 | E32: =E31+D32 -> 0.98590493 | F32: =IF(AND(E32<=0),"C",IF(E32<=0.8,"A",IF(E32<=0.95,"B","C"))) -> C | G32: =VLOOKUP(B$4:B$35,I$4:M$35,5,0) -> C | I32: 2100красный | J32: ='Юнит 7'!S31 -> 0 | K32: =J32/J$36 -> 0 | L32: =L31+K32 -> 1 | M32: =_xlfn.IFS(L32<80%,"A",L32<=95%,"B",L32>95%,"C") -> C
B33: 2038красный | C33: ='Юнит 7'!AL29 -> -1000 | D33: =C33/C$36 -> -0.017401319 | E33: =E32+D33 -> 0.96850361 | F33: =IF(AND(E33<=0),"C",IF(E33<=0.8,"A",IF(E33<=0.95,"B","C"))) -> C | G33: =VLOOKUP(B$4:B$35,I$4:M$35,5,0) -> C | I33: 2100фиолетовый | J33: ='Юнит 7'!S32 -> 0 | K33: =J33/J$36 -> 0 | L33: =L32+K33 -> 1 | M33: =_xlfn.IFS(L33<80%,"A",L33<=95%,"B",L33>95%,"C") -> C
B34: 2100черный | C34: ='Юнит 7'!AL30 -> -1119 | D34: =C34/C$36 -> -0.019472076 | E34: =E33+D34 -> 0.94903154 | F34: =IF(AND(E34<=0),"C",IF(E34<=0.8,"A",IF(E34<=0.95,"B","C"))) -> B | G34: =VLOOKUP(B$4:B$35,I$4:M$35,5,0) -> C | I34: 2104 | J34: ='Юнит 7'!S33 -> 0 | K34: =J34/J$36 -> 0 | L34: =L33+K34 -> 1 | M34: =_xlfn.IFS(L34<80%,"A",L34<=95%,"B",L34>95%,"C") -> C
B35: qs001 Ж | C35: ='Юнит 7'!AL24 -> -2321.16 | D35: =C35/C$36 -> -0.040391246 | E35: =E34+D35 -> 0.90864029 | F35: =IF(AND(E35<=0),"C",IF(E35<=0.8,"A",IF(E35<=0.95,"B","C"))) -> B | G35: =VLOOKUP(B$4:B$35,I$4:M$35,5,0) -> C | I35: 6008 | J35: ='Юнит 7'!S34 -> 0 | K35: =J35/J$36 -> 0 | L35: =L34+K35 -> 1 | M35: =_xlfn.IFS(L35<80%,"A",L35<=95%,"B",L35>95%,"C") -> C
C36: =SUM(C4:C16) -> 57466.908 | D36: =SUM(D4:D16) -> 1 | J36: =SUM(J4:J16) -> 210 | K36: =SUM(K4:K16) -> 1

Sheet АВС 6
B2: ОЧКИ
C3: Прибыль | D3: % прибыль | E3: Доля | F3: ABC прибыль | G3: ABC кол-во | J3: Кол-во | K3: % кол-во | L3: Доля | M3: ABC кол-во
B4: Черные с железкой Сул | C4: ='Юнит 6'!AL3 -> 9916.5357 | D4: =C4/C$17 -> 0.38321324 | E4: =D4 -> 0.38321324 | F4: =IF(AND(E4<=0),"C",IF(E4<=0.8,"A",IF(E4<=0.95,"B","C"))) -> A | G4: =VLOOKUP(B$4:B$16,I$4:M$16,5,0) -> A | I4: Черные с железкой Сул | J4: ='Юнит 6'!S3 -> 32 | K4: =J4/J$17 -> 0.27350427 | L4: =K4 -> 0.27350427 | M4: =_xlfn.IFS(L4<80%,"A",L4<=95%,"B",L4>95%,"C") -> A | P4: A | Q4: 0.8
B5: flip желтые Сул | C5: ='Юнит 6'!AL8 -> 6651.9986 | D5: =C5/C$17 -> 0.25705892 | E5: =E4+D5 -> 0.64027216 | F5: =IF(AND(E5<=0),"C",IF(E5<=0.8,"A",IF(E5<=0.95,"B","C"))) -> A | G5: =VLOOKUP(B$4:B$16,I$4:M$16,5,0) -> A | I5: Qs черн Сул | J5: ='Юнит 6'!S4 -> 29 | K5: =J5/J$17 -> 0.24786325 | L5: =L4+K5 -> 0.52136752 | M5: =_xlfn.IFS(L5<80%,"A",L5<=95%,"B",L5>95%,"C") -> A | P5: B | Q5: 0.15
B6: MR8854 C2 Сул | C6: ='Юнит 6'!AL9 -> 6205.3623 | D6: =C6/C$17 -> 0.23979917 | E6: =E5+D6 -> 0.88007133 | F6: =IF(AND(E6<=0),"C",IF(E6<=0.8,"A",IF(E6<=0.95,"B","C"))) -> B | G6: =VLOOKUP(B$4:B$16,I$4:M$16,5,0) -> B | I6: flip желтые Сул | J6: ='Юнит 6'!S8 -> 21 | K6: =J6/J$17 -> 0.17948718 | L6: =L5+K6 -> 0.7008547 | M6: =_xlfn.IFS(L6<80%,"A",L6<=95%,"B",L6>95%,"C") -> A | P6: C | Q6: 0.05
B7: Qs черн Сул | C7: ='Юнит 6'!AL4 -> 2677.6761 | D7: =C7/C$17 -> 0.10347575 | E7: =E6+D7 -> 0.98354708 | F7: =IF(AND(E7<=0),"C",IF(E7<=0.8,"A",IF(E7<=0.95,"B","C"))) -> C | G7: =VLOOKUP(B$4:B$16,I$4:M$16,5,0) -> A | I7: MR8854 C2 Сул | J7: ='Юнит 6'!S9 -> 14 | K7: =J7/J$17 -> 0.11965812 | L7: =L6+K7 -> 0.82051282 | M7: =_xlfn.IFS(L7<80%,"A",L7<=95%,"B",L7>95%,"C") -> B
B8: MR Р1886 черн | C8: ='Юнит 6'!AL14 -> 984.5023 | D8: =C8/C$17 -> 0.038044972 | E8: =E7+D8 -> 1.0215921 | F8: =IF(AND(E8<=0),"C",IF(E8<=0.8,"A",IF(E8<=0.95,"B","C"))) -> C | G8: =VLOOKUP(B$4:B$16,I$4:M$16,5,0) -> C | I8: flip черные Сул | J8: ='Юнит 6'!S7 -> 6 | K8: =J8/J$17 -> 0.051282051 | L8: =L7+K8 -> 0.87179487 | M8: =_xlfn.IFS(L8<80%,"A",L8<=95%,"B",L8>95%,"C") -> B
B9: MR 1819 корич | C9: ='Юнит 6'!AL11 -> 468.75573 | D9: =C9/C$17 -> 0.018114532 | E9: =E8+D9 -> 1.0397066 | F9: =IF(AND(E9<=0),"C",IF(E9<=0.8,"A",IF(E9<=0.95,"B","C"))) -> C | G9: =VLOOKUP(B$4:B$16,I$4:M$16,5,0) -> C | I9: Qs желт Сул | J9: ='Юнит 6'!S6 -> 5 | K9: =J9/J$17 -> 0.042735043 | L9: =L8+K9 -> 0.91452991 | M9: =_xlfn.IFS(L9<80%,"A",L9<=95%,"B",L9>95%,"C") -> B
B10: MR Р1874 корич | C10: ='Юнит 6'!AL13 -> 444.23552 | D10: =C10/C$17 -> 0.017166977 | E10: =E9+D10 -> 1.0568736 | F10: =IF(AND(E10<=0),"C",IF(E10<=0.8,"A",IF(E10<=0.95,"B","C"))) -> C | G10: =VLOOKUP(B$4:B$16,I$4:M$16,5,0) -> C | I10: Qs син Сул | J10: ='Юнит 6'!S5 -> 4 | K10: =J10/J$17 -> 0.034188034 | L10: =L9+K10 -> 0.94871795 | M10: =_xlfn.IFS(L10<80%,"A",L10<=95%,"B",L10>95%,"C") -> B
B11: flip черные Сул | C11: ='Юнит 6'!AL7 -> 342.73976 | D11: =C11/C$17 -> 0.013244788 | E11: =E10+D11 -> 1.0701183 | F11: =IF(AND(E11<=0),"C",IF(E11<=0.8,"A",IF(E11<=0.95,"B","C"))) -> C | G11: =VLOOKUP(B$4:B$16,I$4:M$16,5,0) -> B | I11: MR 1819 черн | J11: ='Юнит 6'!S10 -> 2 | K11: =J11/J$17 -> 0.017094017 | L11: =L10+K11 -> 0.96581197 | M11: =_xlfn.IFS(L11<80%,"A",L11<=95%,"B",L11>95%,"C") -> C
B12: Qs син Сул | C12: ='Юнит 6'!AL5 -> 262.77695 | D12: =C12/C$17 -> 0.010154716 | E12: =E11+D12 -> 1.0802731 | F12: =IF(AND(E12<=0),"C",IF(E12<=0.8,"A",IF(E12<=0.95,"B","C"))) -> C | G12: =VLOOKUP(B$4:B$16,I$4:M$16,5,0) -> B | I12: MR Р1886 черн | J12: ='Юнит 6'!S14 -> 2 | K12: =J12/J$17 -> 0.017094017 | L12: =L11+K12 -> 0.98290598 | M12: =_xlfn.IFS(L12<80%,"A",L12<=95%,"B",L12>95%,"C") -> C
B13: MR Р1886 корич | C13: ='Юнит 6'!AL15 -> -21.357206 | D13: =C13/C$17 -> -0.00082532495 | E13: =E12+D13 -> 1.0794477 | F13: =IF(AND(E13<=0),"C",IF(E13<=0.8,"A",IF(E13<=0.95,"B","C"))) -> C | G13: =VLOOKUP(B$4:B$16,I$4:M$16,5,0) -> C | I13: MR 1819 корич | J13: ='Юнит 6'!S11 -> 1 | K13: =J13/J$17 -> 0.0085470085 | L13: =L12+K13 -> 0.99145299 | M13: =_xlfn.IFS(L13<80%,"A",L13<=95%,"B",L13>95%,"C") -> C
B14: MR Р1874 черн | C14: ='Юнит 6'!AL12 -> -133.91392 | D14: =C14/C$17 -> -0.0051749511 | E14: =E13+D14 -> 1.0742728 | F14: =IF(AND(E14<=0),"C",IF(E14<=0.8,"A",IF(E14<=0.95,"B","C"))) -> C | G14: =VLOOKUP(B$4:B$16,I$4:M$16,5,0) -> C | I14: MR Р1874 корич | J14: ='Юнит 6'!S13 -> 1 | K14: =J14/J$17 -> 0.0085470085 | L14: =L13+K14 -> 1 | M14: =_xlfn.IFS(L14<80%,"A",L14<=95%,"B",L14>95%,"C") -> C
B15: Qs желт Сул | C15: ='Юнит 6'!AL6 -> -248.9843 | D15: =C15/C$17 -> -0.0096217151 | E15: =E14+D15 -> 1.0646511 | F15: =IF(AND(E15<=0),"C",IF(E15<=0.8,"A",IF(E15<=0.95,"B","C"))) -> C | G15: =VLOOKUP(B$4:B$16,I$4:M$16,5,0) -> B | I15: MR Р1874 черн | J15: ='Юнит 6'!S12 -> 0 | K15: =J15/J$17 -> 0 | L15: =L14+K15 -> 1 | M15: =_xlfn.IFS(L15<80%,"A",L15<=95%,"B",L15>95%,"C") -> C
B16: MR 1819 черн | C16: ='Юнит 6'!AL10 -> -1672.9972 | D16: =C16/C$17 -> -0.064651074 | E16: =E15+D16 -> 1 | F16: =IF(AND(E16<=0),"C",IF(E16<=0.8,"A",IF(E16<=0.95,"B","C"))) -> C | G16: =VLOOKUP(B$4:B$16,I$4:M$16,5,0) -> C | I16: MR Р1886 корич | J16: ='Юнит 6'!S15 -> 0 | K16: =J16/J$17 -> 0 | L16: =L15+K16 -> 1 | M16: =_xlfn.IFS(L16<80%,"A",L16<=95%,"B",L16>95%,"C") -> C
C17: =SUM(C4:C16) -> 25877.33 | D17: =SUM(D4:D16) -> 1 | J17: =SUM(J4:J16) -> 117 | K17: =SUM(K4:K16) -> 1
C20: Прибыль | D20: % прибыль | E20: Доля | F20: ABC прибыль | G20: ABC кол-во | J20: Кол-во | K20: % кол-во | L20: Доля | M20: ABC кол-во
D21: =C21/C$73 -> #DIV/0! | E21: =D21 -> #DIV/0! | F21: =IF(AND(E21<=0),"C",IF(E21<=0.8,"A",IF(E21<=0.95,"B","C"))) -> #DIV/0! | G21: =VLOOKUP(B21:B72,I$21:M$72,5,0) -> #N/A | K21: =J21/J$73 -> #DIV/0! | L21: =K21 -> #DIV/0! | M21: =_xlfn.IFS(L21<80%,"A",L21<=95%,"B",L21>95%,"C") -> #DIV/0!
D22: =C22/C$73 -> #DIV/0! | E22: =D22+E21 -> #DIV/0! | F22: =IF(AND(E22<=0),"C",IF(E22<=0.8,"A",IF(E22<=0.95,"B","C"))) -> #DIV/0! | G22: =VLOOKUP(B22:B73,I$21:M$72,5,0) -> #N/A | K22: =J22/J$73 -> #DIV/0! | L22: =K22+L21 -> #DIV/0! | M22: =_xlfn.IFS(L22<80%,"A",L22<=95%,"B",L22>95%,"C") -> #DIV/0!
D23: =C23/C$73 -> #DIV/0! | E23: =D23+E22 -> #DIV/0! | F23: =IF(AND(E23<=0),"C",IF(E23<=0.8,"A",IF(E23<=0.95,"B","C"))) -> #DIV/0! | G23: =VLOOKUP(B23:B74,I$21:M$72,5,0) -> #N/A | K23: =J23/J$73 -> #DIV/0! | L23: =K23+L22 -> #DIV/0! | M23: =_xlfn.IFS(L23<80%,"A",L23<=95%,"B",L23>95%,"C") -> #DIV/0!
D24: =C24/C$73 -> #DIV/0! | E24: =D24+E23 -> #DIV/0! | F24: =IF(AND(E24<=0),"C",IF(E24<=0.8,"A",IF(E24<=0.95,"B","C"))) -> #DIV/0! | G24: =VLOOKUP(B24:B75,I$21:M$72,5,0) -> #N/A | K24: =J24/J$73 -> #DIV/0! | L24: =K24+L23 -> #DIV/0! | M24: =_xlfn.IFS(L24<80%,"A",L24<=95%,"B",L24>95%,"C") -> #DIV/0!
D25: =C25/C$73 -> #DIV/0! | E25: =D25+E24 -> #DIV/0! | F25: =IF(AND(E25<=0),"C",IF(E25<=0.8,"A",IF(E25<=0.95,"B","C"))) -> #DIV/0! | G25: =VLOOKUP(B25:B76,I$21:M$72,5,0) -> #N/A | K25: =J25/J$73 -> #DIV/0! | L25: =K25+L24 -> #DIV/0! | M25: =_xlfn.IFS(L25<80%,"A",L25<=95%,"B",L25>95%,"C") -> #DIV/0!
D26: =C26/C$73 -> #DIV/0! | E26: =D26+E25 -> #DIV/0! | F26: =IF(AND(E26<=0),"C",IF(E26<=0.8,"A",IF(E26<=0.95,"B","C"))) -> #DIV/0! | G26: =VLOOKUP(B26:B77,I$21:M$72,5,0) -> #N/A | K26: =J26/J$73 -> #DIV/0! | L26: =K26+L25 -> #DIV/0! | M26: =_xlfn.IFS(L26<80%,"A",L26<=95%,"B",L26>95%,"C") -> #DIV/0!
D27: =C27/C$73 -> #DIV/0! | E27: =D27+E26 -> #DIV/0! | F27: =IF(AND(E27<=0),"C",IF(E27<=0.8,"A",IF(E27<=0.95,"B","C"))) -> #DIV/0! | G27: =VLOOKUP(B27:B78,I$21:M$72,5,0) -> #N/A | K27: =J27/J$73 -> #DIV/0! | L27: =K27+L26 -> #DIV/0! | M27: =_xlfn.IFS(L27<80%,"A",L27<=95%,"B",L27>95%,"C") -> #DIV/0!
D28: =C28/C$73 -> #DIV/0! | E28: =D28+E27 -> #DIV/0! | F28: =IF(AND(E28<=0),"C",IF(E28<=0.8,"A",IF(E28<=0.95,"B","C"))) -> #DIV/0! | G28: =VLOOKUP(B28:B79,I$21:M$72,5,0) -> #N/A | K28: =J28/J$73 -> #DIV/0! | L28: =K28+L27 -> #DIV/0! | M28: =_xlfn.IFS(L28<80%,"A",L28<=95%,"B",L28>95%,"C") -> #DIV/0!
D29: =C29/C$73 -> #DIV/0! | E29: =D29+E28 -> #DIV/0! | F29: =IF(AND(E29<=0),"C",IF(E29<=0.8,"A",IF(E29<=0.95,"B","C"))) -> #DIV/0! | G29: =VLOOKUP(B29:B80,I$21:M$72,5,0) -> #N/A | K29: =J29/J$73 -> #DIV/0! | L29: =K29+L28 -> #DIV/0! | M29: =_xlfn.IFS(L29<80%,"A",L29<=95%,"B",L29>95%,"C") -> #DIV/0!
D30: =C30/C$73 -> #DIV/0! | E30: =D30+E29 -> #DIV/0! | F30: =IF(AND(E30<=0),"C",IF(E30<=0.8,"A",IF(E30<=0.95,"B","C"))) -> #DIV/0! | G30: =VLOOKUP(B30:B81,I$21:M$72,5,0) -> #N/A | K30: =J30/J$73 -> #DIV/0! | L30: =K30+L29 -> #DIV/0! | M30: =_xlfn.IFS(L30<80%,"A",L30<=95%,"B",L30>95%,"C") -> #DIV/0!
D31: =C31/C$73 -> #DIV/0! | E31: =D31+E30 -> #DIV/0! | F31: =IF(AND(E31<=0),"C",IF(E31<=0.8,"A",IF(E31<=0.95,"B","C"))) -> #DIV/0! | G31: =VLOOKUP(B31:B82,I$21:M$72,5,0) -> #N/A | K31: =J31/J$73 -> #DIV/0! | L31: =K31+L30 -> #DIV/0! | M31: =_xlfn.IFS(L31<80%,"A",L31<=95%,"B",L31>95%,"C") -> #DIV/0!
D32: =C32/C$73 -> #DIV/0! | E32: =D32+E31 -> #DIV/0! | F32: =IF(AND(E32<=0),"C",IF(E32<=0.8,"A",IF(E32<=0.95,"B","C"))) -> #DIV/0! | G32: =VLOOKUP(B32:B83,I$21:M$72,5,0) -> #N/A | K32: =J32/J$73 -> #DIV/0! | L32: =K32+L31 -> #DIV/0! | M32: =_xlfn.IFS(L32<80%,"A",L32<=95%,"B",L32>95%,"C") -> #DIV/0!
D33: =C33/C$73 -> #DIV/0! | E33: =D33+E32 -> #DIV/0! | F33: =IF(AND(E33<=0),"C",IF(E33<=0.8,"A",IF(E33<=0.95,"B","C"))) -> #DIV/0! | G33: =VLOOKUP(B33:B84,I$21:M$72,5,0) -> #N/A | K33: =J33/J$73 -> #DIV/0! | L33: =K33+L32 -> #DIV/0! | M33: =_xlfn.IFS(L33<80%,"A",L33<=95%,"B",L33>95%,"C") -> #DIV/0!
... D72: =C72/C$73 -> #DIV/0! | E72: =D72+E71 -> #DIV/0! | F72: =IF(AND(E72<=0),"C",IF(E72<=0.8,"A",IF(E72<=0.95,"B","C"))) -> #DIV/0! | G72: =VLOOKUP(B72:B123,I$21:M$72,5,0) -> #N/A | K72: =J72/J$73 -> #DIV/0! | L72: =K72+L71 -> #DIV/0! | M72: =_xlfn.IFS(L72<80%,"A",L72<=95%,"B",L72>95%,"C") -> #DIV/0!
C73: =SUM(C21:C72) -> 0 | D73: =SUM(D21:D72) -> #DIV/0! | J73: =SUM(J21:J72) -> 0 | K73: =SUM(K21:K72) -> #DIV/0!

Sheet АВС ЯНВАРЬ
B2: ОЧКИ
C3: Прибыль | D3: % прибыль | E3: Доля | F3: ABC прибыль | G3: ABC кол-во | J3: Кол-во | K3: % кол-во | L3: Доля | M3: ABC кол-во
B4: flip желтые Сул | C4: ='Юнит 5'!AL8 -> 2045.1121 | D4: =C4/C$17 -> 0.29333616 | E4: =D4 -> 0.29333616 | F4: =IF(AND(E4<=0),"C",IF(E4<=0.8,"A",IF(E4<=0.95,"B","C"))) -> A | G4: =VLOOKUP(B$4:B$16,I$4:M$16,5,0) -> A | I4: flip желтые Сул | J4: =ЯНВАРЬ!S8 -> 107 | K4: =J4/J$17 -> 0.42629482 | L4: =K4 -> 0.42629482 | M4: =_xlfn.IFS(L4<80%,"A",L4<=95%,"B",L4>95%,"C") -> A | P4: A | Q4: 0.8
B5: Черные с железкой Сул | C5: ='Юнит 5'!AL3 -> 1813.3318 | D5: =C5/C$17 -> 0.26009127 | E5: =E4+D5 -> 0.55342742 | F5: =IF(AND(E5<=0),"C",IF(E5<=0.8,"A",IF(E5<=0.95,"B","C"))) -> A | G5: =VLOOKUP(B$4:B$16,I$4:M$16,5,0) -> A | I5: Черные с железкой Сул | J5: =ЯНВАРЬ!S3 -> 62 | K5: =J5/J$17 -> 0.24701195 | L5: =L4+K5 -> 0.67330677 | M5: =_xlfn.IFS(L5<80%,"A",L5<=95%,"B",L5>95%,"C") -> A | P5: B | Q5: 0.15
B6: Qs желт Сул | C6: ='Юнит 5'!AL6 -> 1154.6045 | D6: =C6/C$17 -> 0.16560816 | E6: =E5+D6 -> 0.71903559 | F6: =IF(AND(E6<=0),"C",IF(E6<=0.8,"A",IF(E6<=0.95,"B","C"))) -> A | G6: =VLOOKUP(B$4:B$16,I$4:M$16,5,0) -> B | I6: MR8854 C2 Сул | J6: =ЯНВАРЬ!S9 -> 26 | K6: =J6/J$17 -> 0.10358566 | L6: =L5+K6 -> 0.77689243 | M6: =_xlfn.IFS(L6<80%,"A",L6<=95%,"B",L6>95%,"C") -> A | P6: C | Q6: 0.05
B7: MR Р1886 черн | C7: ='Юнит 5'!AL14 -> 826.78813 | D7: =C7/C$17 -> 0.11858854 | E7: =E6+D7 -> 0.83762412 | F7: =IF(AND(E7<=0),"C",IF(E7<=0.8,"A",IF(E7<=0.95,"B","C"))) -> B | G7: =VLOOKUP(B$4:B$16,I$4:M$16,5,0) -> B | I7: Qs желт Сул | J7: =ЯНВАРЬ!S6 -> 20 | K7: =J7/J$17 -> 0.079681275 | L7: =L6+K7 -> 0.85657371 | M7: =_xlfn.IFS(L7<80%,"A",L7<=95%,"B",L7>95%,"C") -> B
B8: MR Р1874 черн | C8: ='Юнит 5'!AL12 -> 783.16961 | D8: =C8/C$17 -> 0.11233221 | E8: =E7+D8 -> 0.94995634 | F8: =IF(AND(E8<=0),"C",IF(E8<=0.8,"A",IF(E8<=0.95,"B","C"))) -> B | G8: =VLOOKUP(B$4:B$16,I$4:M$16,5,0) -> C | I8: Qs черн Сул | J8: =ЯНВАРЬ!S4 -> 10 | K8: =J8/J$17 -> 0.039840637 | L8: =L7+K8 -> 0.89641434 | M8: =_xlfn.IFS(L8<80%,"A",L8<=95%,"B",L8>95%,"C") -> B
B9: MR 1819 корич | C9: ='Юнит 5'!AL11 -> 758.76739 | D9: =C9/C$17 -> 0.10883214 | E9: =E8+D9 -> 1.0587885 | F9: =IF(AND(E9<=0),"C",IF(E9<=0.8,"A",IF(E9<=0.95,"B","C"))) -> C | G9: =VLOOKUP(B$4:B$16,I$4:M$16,5,0) -> C | I9: MR Р1886 черн | J9: =ЯНВАРЬ!S14 -> 6 | K9: =J9/J$17 -> 0.023904382 | L9: =L8+K9 -> 0.92031873 | M9: =_xlfn.IFS(L9<80%,"A",L9<=95%,"B",L9>95%,"C") -> B
B10: MR Р1874 корич | C10: ='Юнит 5'!AL13 -> 508.76629 | D10: =C10/C$17 -> 0.072973776 | E10: =E9+D10 -> 1.1317623 | F10: =IF(AND(E10<=0),"C",IF(E10<=0.8,"A",IF(E10<=0.95,"B","C"))) -> C | G10: =VLOOKUP(B$4:B$16,I$4:M$16,5,0) -> C | I10: Qs син Сул | J10: =ЯНВАРЬ!S5 -> 4 | K10: =J10/J$17 -> 0.015936255 | L10: =L9+K10 -> 0.93625498 | M10: =_xlfn.IFS(L10<80%,"A",L10<=95%,"B",L10>95%,"C") -> B
B11: MR 1819 черн | C11: ='Юнит 5'!AL10 -> 398.95943 | D11: =C11/C$17 -> 0.05722387 | E11: =E10+D11 -> 1.1889861 | F11: =IF(AND(E11<=0),"C",IF(E11<=0.8,"A",IF(E11<=0.95,"B","C"))) -> C | G11: =VLOOKUP(B$4:B$16,I$4:M$16,5,0) -> C | I11: MR Р1874 корич | J11: =ЯНВАРЬ!S13 -> 4 | K11: =J11/J$17 -> 0.015936255 | L11: =L10+K11 -> 0.95219124 | M11: =_xlfn.IFS(L11<80%,"A",L11<=95%,"B",L11>95%,"C") -> C
B12: MR8854 C2 Сул | C12: ='Юнит 5'!AL9 -> 297.0268 | D12: =C12/C$17 -> 0.042603387 | E12: =E11+D12 -> 1.2315895 | F12: =IF(AND(E12<=0),"C",IF(E12<=0.8,"A",IF(E12<=0.95,"B","C"))) -> C | G12: =VLOOKUP(B$4:B$16,I$4:M$16,5,0) -> A | I12: MR 1819 корич | J12: =ЯНВАРЬ!S11 -> 3 | K12: =J12/J$17 -> 0.011952191 | L12: =L11+K12 -> 0.96414343 | M12: =_xlfn.IFS(L12<80%,"A",L12<=95%,"B",L12>95%,"C") -> C
B13: Qs черн Сул | C13: ='Юнит 5'!AL4 -> 177.70464 | D13: =C13/C$17 -> 0.025488675 | E13: =E12+D13 -> 1.2570782 | F13: =IF(AND(E13<=0),"C",IF(E13<=0.8,"A",IF(E13<=0.95,"B","C"))) -> C | G13: =VLOOKUP(B$4:B$16,I$4:M$16,5,0) -> B | I13: MR Р1874 черн | J13: =ЯНВАРЬ!S12 -> 3 | K13: =J13/J$17 -> 0.011952191 | L13: =L12+K13 -> 0.97609562 | M13: =_xlfn.IFS(L13<80%,"A",L13<=95%,"B",L13>95%,"C") -> C
B14: MR Р1886 корич | C14: ='Юнит 5'!AL15 -> -22.030753 | D14: =C14/C$17 -> -0.0031599326 | E14: =E13+D14 -> 1.2539182 | F14: =IF(AND(E14<=0),"C",IF(E14<=0.8,"A",IF(E14<=0.95,"B","C"))) -> C | G14: =VLOOKUP(B$4:B$16,I$4:M$16,5,0) -> C | I14: MR Р1886 корич | J14: =ЯНВАРЬ!S15 -> 3 | K14: =J14/J$17 -> 0.011952191 | L14: =L13+K14 -> 0.98804781 | M14: =_xlfn.IFS(L14<80%,"A",L14<=95%,"B",L14>95%,"C") -> C
B15: flip черные Сул | C15: ='Юнит 5'!AL7 -> -852.48176 | D15: =C15/C$17 -> -0.12227385 | E15: =E14+D15 -> 1.1316444 | F15: =IF(AND(E15<=0),"C",IF(E15<=0.8,"A",IF(E15<=0.95,"B","C"))) -> C | G15: =VLOOKUP(B$4:B$16,I$4:M$16,5,0) -> C | I15: MR 1819 черн | J15: =ЯНВАРЬ!S10 -> 2 | K15: =J15/J$17 -> 0.0079681275 | L15: =L14+K15 -> 0.99601594 | M15: =_xlfn.IFS(L15<80%,"A",L15<=95%,"B",L15>95%,"C") -> C
B16: Qs син Сул | C16: ='Юнит 5'!AL5 -> -917.81235 | D16: =C16/C$17 -> -0.1316444 | E16: =E15+D16 -> 1 | F16: =IF(AND(E16<=0),"C",IF(E16<=0.8,"A",IF(E16<=0.95,"B","C"))) -> C | G16: =VLOOKUP(B$4:B$16,I$4:M$16,5,0) -> B | I16: flip черные Сул | J16: =ЯНВАРЬ!S7 -> 1 | K16: =J16/J$17 -> 0.0039840637 | L16: =L15+K16 -> 1 | M16: =_xlfn.IFS(L16<80%,"A",L16<=95%,"B",L16>95%,"C") -> C
C17: =SUM(C4:C16) -> 6971.9058 | D17: =SUM(D4:D16) -> 1 | J17: =SUM(J4:J16) -> 251 | K17: =SUM(K4:K16) -> 1
C20: Прибыль | D20: % прибыль | E20: Доля | F20: ABC прибыль | G20: ABC кол-во | J20: Кол-во | K20: % кол-во | L20: Доля | M20: ABC кол-во
D21: =C21/C$73 -> #DIV/0! | E21: =D21 -> #DIV/0! | F21: =IF(AND(E21<=0),"C",IF(E21<=0.8,"A",IF(E21<=0.95,"B","C"))) -> #DIV/0! | G21: =VLOOKUP(B21:B72,I$21:M$72,5,0) -> #N/A | K21: =J21/J$73 -> #DIV/0! | L21: =K21 -> #DIV/0! | M21: =_xlfn.IFS(L21<80%,"A",L21<=95%,"B",L21>95%,"C") -> #DIV/0!
D22: =C22/C$73 -> #DIV/0! | E22: =D22+E21 -> #DIV/0! | F22: =IF(AND(E22<=0),"C",IF(E22<=0.8,"A",IF(E22<=0.95,"B","C"))) -> #DIV/0! | G22: =VLOOKUP(B22:B73,I$21:M$72,5,0) -> #N/A | K22: =J22/J$73 -> #DIV/0! | L22: =K22+L21 -> #DIV/0! | M22: =_xlfn.IFS(L22<80%,"A",L22<=95%,"B",L22>95%,"C") -> #DIV/0!
D23: =C23/C$73 -> #DIV/0! | E23: =D23+E22 -> #DIV/0! | F23: =IF(AND(E23<=0),"C",IF(E23<=0.8,"A",IF(E23<=0.95,"B","C"))) -> #DIV/0! | G23: =VLOOKUP(B23:B74,I$21:M$72,5,0) -> #N/A | K23: =J23/J$73 -> #DIV/0! | L23: =K23+L22 -> #DIV/0! | M23: =_xlfn.IFS(L23<80%,"A",L23<=95%,"B",L23>95%,"C") -> #DIV/0!
D24: =C24/C$73 -> #DIV/0! | E24: =D24+E23 -> #DIV/0! | F24: =IF(AND(E24<=0),"C",IF(E24<=0.8,"A",IF(E24<=0.95,"B","C"))) -> #DIV/0! | G24: =VLOOKUP(B24:B75,I$21:M$72,5,0) -> #N/A | K24: =J24/J$73 -> #DIV/0! | L24: =K24+L23 -> #DIV/0! | M24: =_xlfn.IFS(L24<80%,"A",L24<=95%,"B",L24>95%,"C") -> #DIV/0!
D25: =C25/C$73 -> #DIV/0! | E25: =D25+E24 -> #DIV/0! | F25: =IF(AND(E25<=0),"C",IF(E25<=0.8,"A",IF(E25<=0.95,"B","C"))) -> #DIV/0! | G25: =VLOOKUP(B25:B76,I$21:M$72,5,0) -> #N/A | K25: =J25/J$73 -> #DIV/0! | L25: =K25+L24 -> #DIV/0! | M25: =_xlfn.IFS(L25<80%,"A",L25<=95%,"B",L25>95%,"C") -> #DIV/0!
D26: =C26/C$73 -> #DIV/0! | E26: =D26+E25 -> #DIV/0! | F26: =IF(AND(E26<=0),"C",IF(E26<=0.8,"A",IF(E26<=0.95,"B","C"))) -> #DIV/0! | G26: =VLOOKUP(B26:B77,I$21:M$72,5,0) -> #N/A | K26: =J26/J$73 -> #DIV/0! | L26: =K26+L25 -> #DIV/0! | M26: =_xlfn.IFS(L26<80%,"A",L26<=95%,"B",L26>95%,"C") -> #DIV/0!
D27: =C27/C$73 -> #DIV/0! | E27: =D27+E26 -> #DIV/0! | F27: =IF(AND(E27<=0),"C",IF(E27<=0.8,"A",IF(E27<=0.95,"B","C"))) -> #DIV/0! | G27: =VLOOKUP(B27:B78,I$21:M$72,5,0) -> #N/A | K27: =J27/J$73 -> #DIV/0! | L27: =K27+L26 -> #DIV/0! | M27: =_xlfn.IFS(L27<80%,"A",L27<=95%,"B",L27>95%,"C") -> #DIV/0!
D28: =C28/C$73 -> #DIV/0! | E28: =D28+E27 -> #DIV/0! | F28: =IF(AND(E28<=0),"C",IF(E28<=0.8,"A",IF(E28<=0.95,"B","C"))) -> #DIV/0! | G28: =VLOOKUP(B28:B79,I$21:M$72,5,0) -> #N/A | K28: =J28/J$73 -> #DIV/0! | L28: =K28+L27 -> #DIV/0! | M28: =_xlfn.IFS(L28<80%,"A",L28<=95%,"B",L28>95%,"C") -> #DIV/0!
D29: =C29/C$73 -> #DIV/0! | E29: =D29+E28 -> #DIV/0! | F29: =IF(AND(E29<=0),"C",IF(E29<=0.8,"A",IF(E29<=0.95,"B","C"))) -> #DIV/0! | G29: =VLOOKUP(B29:B80,I$21:M$72,5,0) -> #N/A | K29: =J29/J$73 -> #DIV/0! | L29: =K29+L28 -> #DIV/0! | M29: =_xlfn.IFS(L29<80%,"A",L29<=95%,"B",L29>95%,"C") -> #DIV/0!
D30: =C30/C$73 -> #DIV/0! | E30: =D30+E29 -> #DIV/0! | F30: =IF(AND(E30<=0),"C",IF(E30<=0.8,"A",IF(E30<=0.95,"B","C"))) -> #DIV/0! | G30: =VLOOKUP(B30:B81,I$21:M$72,5,0) -> #N/A | K30: =J30/J$73 -> #DIV/0! | L30: =K30+L29 -> #DIV/0! | M30: =_xlfn.IFS(L30<80%,"A",L30<=95%,"B",L30>95%,"C") -> #DIV/0!
D31: =C31/C$73 -> #DIV/0! | E31: =D31+E30 -> #DIV/0! | F31: =IF(AND(E31<=0),"C",IF(E31<=0.8,"A",IF(E31<=0.95,"B","C"))) -> #DIV/0! | G31: =VLOOKUP(B31:B82,I$21:M$72,5,0) -> #N/A | K31: =J31/J$73 -> #DIV/0! | L31: =K31+L30 -> #DIV/0! | M31: =_xlfn.IFS(L31<80%,"A",L31<=95%,"B",L31>95%,"C") -> #DIV/0!
D32: =C32/C$73 -> #DIV/0! | E32: =D32+E31 -> #DIV/0! | F32: =IF(AND(E32<=0),"C",IF(E32<=0.8,"A",IF(E32<=0.95,"B","C"))) -> #DIV/0! | G32: =VLOOKUP(B32:B83,I$21:M$72,5,0) -> #N/A | K32: =J32/J$73 -> #DIV/0! | L32: =K32+L31 -> #DIV/0! | M32: =_xlfn.IFS(L32<80%,"A",L32<=95%,"B",L32>95%,"C") -> #DIV/0!
D33: =C33/C$73 -> #DIV/0! | E33: =D33+E32 -> #DIV/0! | F33: =IF(AND(E33<=0),"C",IF(E33<=0.8,"A",IF(E33<=0.95,"B","C"))) -> #DIV/0! | G33: =VLOOKUP(B33:B84,I$21:M$72,5,0) -> #N/A | K33: =J33/J$73 -> #DIV/0! | L33: =K33+L32 -> #DIV/0! | M33: =_xlfn.IFS(L33<80%,"A",L33<=95%,"B",L33>95%,"C") -> #DIV/0!
... D72: =C72/C$73 -> #DIV/0! | E72: =D72+E71 -> #DIV/0! | F72: =IF(AND(E72<=0),"C",IF(E72<=0.8,"A",IF(E72<=0.95,"B","C"))) -> #DIV/0! | G72: =VLOOKUP(B72:B123,I$21:M$72,5,0) -> #N/A | K72: =J72/J$73 -> #DIV/0! | L72: =K72+L71 -> #DIV/0! | M72: =_xlfn.IFS(L72<80%,"A",L72<=95%,"B",L72>95%,"C") -> #DIV/0!
C73: =SUM(C21:C72) -> 0 | D73: =SUM(D21:D72) -> #DIV/0! | J73: =SUM(J21:J72) -> 0 | K73: =SUM(K21:K72) -> #DIV/0!

Sheet АВС 5
B2: ОЧКИ
C3: Прибыль | D3: % прибыль | E3: Доля | F3: ABC прибыль | G3: ABC кол-во | J3: Кол-во | K3: % кол-во | L3: Доля | M3: ABC кол-во
B4: flip желтые Сул | C4: ='Юнит 5'!AL8 -> 2045.1121 | D4: =C4/C$17 -> 0.29333616 | E4: =D4 -> 0.29333616 | F4: =IF(AND(E4<=0),"C",IF(E4<=0.8,"A",IF(E4<=0.95,"B","C"))) -> A | G4: =VLOOKUP(B$4:B$16,I$4:M$16,5,0) -> A | I4: Черные с железкой Сул | J4: ='Юнит 5'!S3 -> 19 | K4: =J4/J$17 -> 0.27536232 | L4: =K4 -> 0.27536232 | M4: =_xlfn.IFS(L4<80%,"A",L4<=95%,"B",L4>95%,"C") -> A | P4: A | Q4: 0.8
B5: Черные с железкой Сул | C5: ='Юнит 5'!AL3 -> 1813.3318 | D5: =C5/C$17 -> 0.26009127 | E5: =E4+D5 -> 0.55342742 | F5: =IF(AND(E5<=0),"C",IF(E5<=0.8,"A",IF(E5<=0.95,"B","C"))) -> A | G5: =VLOOKUP(B$4:B$16,I$4:M$16,5,0) -> A | I5: flip желтые Сул | J5: ='Юнит 5'!S8 -> 14 | K5: =J5/J$17 -> 0.20289855 | L5: =L4+K5 -> 0.47826087 | M5: =_xlfn.IFS(L5<80%,"A",L5<=95%,"B",L5>95%,"C") -> A | P5: B | Q5: 0.15
B6: Qs желт Сул | C6: ='Юнит 5'!AL6 -> 1154.6045 | D6: =C6/C$17 -> 0.16560816 | E6: =E5+D6 -> 0.71903559 | F6: =IF(AND(E6<=0),"C",IF(E6<=0.8,"A",IF(E6<=0.95,"B","C"))) -> A | G6: =VLOOKUP(B$4:B$16,I$4:M$16,5,0) -> B | I6: MR8854 C2 Сул | J6: ='Юнит 5'!S9 -> 11 | K6: =J6/J$17 -> 0.15942029 | L6: =L5+K6 -> 0.63768116 | M6: =_xlfn.IFS(L6<80%,"A",L6<=95%,"B",L6>95%,"C") -> A | P6: C | Q6: 0.05
B7: MR Р1886 черн | C7: ='Юнит 5'!AL14 -> 826.78813 | D7: =C7/C$17 -> 0.11858854 | E7: =E6+D7 -> 0.83762412 | F7: =IF(AND(E7<=0),"C",IF(E7<=0.8,"A",IF(E7<=0.95,"B","C"))) -> B | G7: =VLOOKUP(B$4:B$16,I$4:M$16,5,0) -> C | I7: Qs черн Сул | J7: ='Юнит 5'!S4 -> 10 | K7: =J7/J$17 -> 0.14492754 | L7: =L6+K7 -> 0.7826087 | M7: =_xlfn.IFS(L7<80%,"A",L7<=95%,"B",L7>95%,"C") -> A
B8: MR Р1874 черн | C8: ='Юнит 5'!AL12 -> 783.16961 | D8: =C8/C$17 -> 0.11233221 | E8: =E7+D8 -> 0.94995634 | F8: =IF(AND(E8<=0),"C",IF(E8<=0.8,"A",IF(E8<=0.95,"B","C"))) -> B | G8: =VLOOKUP(B$4:B$16,I$4:M$16,5,0) -> B | I8: Qs син Сул | J8: ='Юнит 5'!S5 -> 3 | K8: =J8/J$17 -> 0.043478261 | L8: =L7+K8 -> 0.82608696 | M8: =_xlfn.IFS(L8<80%,"A",L8<=95%,"B",L8>95%,"C") -> B
B9: MR 1819 корич | C9: ='Юнит 5'!AL11 -> 758.76739 | D9: =C9/C$17 -> 0.10883214 | E9: =E8+D9 -> 1.0587885 | F9: =IF(AND(E9<=0),"C",IF(E9<=0.8,"A",IF(E9<=0.95,"B","C"))) -> C | G9: =VLOOKUP(B$4:B$16,I$4:M$16,5,0) -> B | I9: Qs желт Сул | J9: ='Юнит 5'!S6 -> 3 | K9: =J9/J$17 -> 0.043478261 | L9: =L8+K9 -> 0.86956522 | M9: =_xlfn.IFS(L9<80%,"A",L9<=95%,"B",L9>95%,"C") -> B
B10: MR Р1874 корич | C10: ='Юнит 5'!AL13 -> 508.76629 | D10: =C10/C$17 -> 0.072973776 | E10: =E9+D10 -> 1.1317623 | F10: =IF(AND(E10<=0),"C",IF(E10<=0.8,"A",IF(E10<=0.95,"B","C"))) -> C | G10: =VLOOKUP(B$4:B$16,I$4:M$16,5,0) -> C | I10: MR 1819 корич | J10: ='Юнит 5'!S11 -> 2 | K10: =J10/J$17 -> 0.028985507 | L10: =L9+K10 -> 0.89855072 | M10: =_xlfn.IFS(L10<80%,"A",L10<=95%,"B",L10>95%,"C") -> B
B11: MR 1819 черн | C11: ='Юнит 5'!AL10 -> 398.95943 | D11: =C11/C$17 -> 0.05722387 | E11: =E10+D11 -> 1.1889861 | F11: =IF(AND(E11<=0),"C",IF(E11<=0.8,"A",IF(E11<=0.95,"B","C"))) -> C | G11: =VLOOKUP(B$4:B$16,I$4:M$16,5,0) -> C | I11: MR Р1874 черн | J11: ='Юнит 5'!S12 -> 2 | K11: =J11/J$17 -> 0.028985507 | L11: =L10+K11 -> 0.92753623 | M11: =_xlfn.IFS(L11<80%,"A",L11<=95%,"B",L11>95%,"C") -> B
B12: MR8854 C2 Сул | C12: ='Юнит 5'!AL9 -> 297.0268 | D12: =C12/C$17 -> 0.042603387 | E12: =E11+D12 -> 1.2315895 | F12: =IF(AND(E12<=0),"C",IF(E12<=0.8,"A",IF(E12<=0.95,"B","C"))) -> C | G12: =VLOOKUP(B$4:B$16,I$4:M$16,5,0) -> A | I12: MR Р1886 черн | J12: ='Юнит 5'!S14 -> 2 | K12: =J12/J$17 -> 0.028985507 | L12: =L11+K12 -> 0.95652174 | M12: =_xlfn.IFS(L12<80%,"A",L12<=95%,"B",L12>95%,"C") -> C
B13: Qs черн Сул | C13: ='Юнит 5'!AL4 -> 177.70464 | D13: =C13/C$17 -> 0.025488675 | E13: =E12+D13 -> 1.2570782 | F13: =IF(AND(E13<=0),"C",IF(E13<=0.8,"A",IF(E13<=0.95,"B","C"))) -> C | G13: =VLOOKUP(B$4:B$16,I$4:M$16,5,0) -> A | I13: flip черные Сул | J13: ='Юнит 5'!S7 -> 1 | K13: =J13/J$17 -> 0.014492754 | L13: =L12+K13 -> 0.97101449 | M13: =_xlfn.IFS(L13<80%,"A",L13<=95%,"B",L13>95%,"C") -> C
B14: MR Р1886 корич | C14: ='Юнит 5'!AL15 -> -22.030753 | D14: =C14/C$17 -> -0.0031599326 | E14: =E13+D14 -> 1.2539182 | F14: =IF(AND(E14<=0),"C",IF(E14<=0.8,"A",IF(E14<=0.95,"B","C"))) -> C | G14: =VLOOKUP(B$4:B$16,I$4:M$16,5,0) -> C | I14: MR 1819 черн | J14: ='Юнит 5'!S10 -> 1 | K14: =J14/J$17 -> 0.014492754 | L14: =L13+K14 -> 0.98550725 | M14: =_xlfn.IFS(L14<80%,"A",L14<=95%,"B",L14>95%,"C") -> C
B15: flip черные Сул | C15: ='Юнит 5'!AL7 -> -852.48176 | D15: =C15/C$17 -> -0.12227385 | E15: =E14+D15 -> 1.1316444 | F15: =IF(AND(E15<=0),"C",IF(E15<=0.8,"A",IF(E15<=0.95,"B","C"))) -> C | G15: =VLOOKUP(B$4:B$16,I$4:M$16,5,0) -> C | I15: MR Р1874 корич | J15: ='Юнит 5'!S13 -> 1 | K15: =J15/J$17 -> 0.014492754 | L15: =L14+K15 -> 1 | M15: =_xlfn.IFS(L15<80%,"A",L15<=95%,"B",L15>95%,"C") -> C
B16: Qs син Сул | C16: ='Юнит 5'!AL5 -> -917.81235 | D16: =C16/C$17 -> -0.1316444 | E16: =E15+D16 -> 1 | F16: =IF(AND(E16<=0),"C",IF(E16<=0.8,"A",IF(E16<=0.95,"B","C"))) -> C | G16: =VLOOKUP(B$4:B$16,I$4:M$16,5,0) -> B | I16: MR Р1886 корич | J16: ='Юнит 5'!S15 -> 0 | K16: =J16/J$17 -> 0 | L16: =L15+K16 -> 1 | M16: =_xlfn.IFS(L16<80%,"A",L16<=95%,"B",L16>95%,"C") -> C
C17: =SUM(C4:C16) -> 6971.9058 | D17: =SUM(D4:D16) -> 1 | J17: =SUM(J4:J16) -> 69 | K17: =SUM(K4:K16) -> 1
C20: Прибыль | D20: % прибыль | E20: Доля | F20: ABC прибыль | G20: ABC кол-во | J20: Кол-во | K20: % кол-во | L20: Доля | M20: ABC кол-во
D21: =C21/C$73 -> #DIV/0! | E21: =D21 -> #DIV/0! | F21: =IF(AND(E21<=0),"C",IF(E21<=0.8,"A",IF(E21<=0.95,"B","C"))) -> #DIV/0! | G21: =VLOOKUP(B21:B72,I$21:M$72,5,0) -> #N/A | K21: =J21/J$73 -> #DIV/0! | L21: =K21 -> #DIV/0! | M21: =_xlfn.IFS(L21<80%,"A",L21<=95%,"B",L21>95%,"C") -> #DIV/0!
D22: =C22/C$73 -> #DIV/0! | E22: =D22+E21 -> #DIV/0! | F22: =IF(AND(E22<=0),"C",IF(E22<=0.8,"A",IF(E22<=0.95,"B","C"))) -> #DIV/0! | G22: =VLOOKUP(B22:B73,I$21:M$72,5,0) -> #N/A | K22: =J22/J$73 -> #DIV/0! | L22: =K22+L21 -> #DIV/0! | M22: =_xlfn.IFS(L22<80%,"A",L22<=95%,"B",L22>95%,"C") -> #DIV/0!
D23: =C23/C$73 -> #DIV/0! | E23: =D23+E22 -> #DIV/0! | F23: =IF(AND(E23<=0),"C",IF(E23<=0.8,"A",IF(E23<=0.95,"B","C"))) -> #DIV/0! | G23: =VLOOKUP(B23:B74,I$21:M$72,5,0) -> #N/A | K23: =J23/J$73 -> #DIV/0! | L23: =K23+L22 -> #DIV/0! | M23: =_xlfn.IFS(L23<80%,"A",L23<=95%,"B",L23>95%,"C") -> #DIV/0!
D24: =C24/C$73 -> #DIV/0! | E24: =D24+E23 -> #DIV/0! | F24: =IF(AND(E24<=0),"C",IF(E24<=0.8,"A",IF(E24<=0.95,"B","C"))) -> #DIV/0! | G24: =VLOOKUP(B24:B75,I$21:M$72,5,0) -> #N/A | K24: =J24/J$73 -> #DIV/0! | L24: =K24+L23 -> #DIV/0! | M24: =_xlfn.IFS(L24<80%,"A",L24<=95%,"B",L24>95%,"C") -> #DIV/0!
D25: =C25/C$73 -> #DIV/0! | E25: =D25+E24 -> #DIV/0! | F25: =IF(AND(E25<=0),"C",IF(E25<=0.8,"A",IF(E25<=0.95,"B","C"))) -> #DIV/0! | G25: =VLOOKUP(B25:B76,I$21:M$72,5,0) -> #N/A | K25: =J25/J$73 -> #DIV/0! | L25: =K25+L24 -> #DIV/0! | M25: =_xlfn.IFS(L25<80%,"A",L25<=95%,"B",L25>95%,"C") -> #DIV/0!
D26: =C26/C$73 -> #DIV/0! | E26: =D26+E25 -> #DIV/0! | F26: =IF(AND(E26<=0),"C",IF(E26<=0.8,"A",IF(E26<=0.95,"B","C"))) -> #DIV/0! | G26: =VLOOKUP(B26:B77,I$21:M$72,5,0) -> #N/A | K26: =J26/J$73 -> #DIV/0! | L26: =K26+L25 -> #DIV/0! | M26: =_xlfn.IFS(L26<80%,"A",L26<=95%,"B",L26>95%,"C") -> #DIV/0!
D27: =C27/C$73 -> #DIV/0! | E27: =D27+E26 -> #DIV/0! | F27: =IF(AND(E27<=0),"C",IF(E27<=0.8,"A",IF(E27<=0.95,"B","C"))) -> #DIV/0! | G27: =VLOOKUP(B27:B78,I$21:M$72,5,0) -> #N/A | K27: =J27/J$73 -> #DIV/0! | L27: =K27+L26 -> #DIV/0! | M27: =_xlfn.IFS(L27<80%,"A",L27<=95%,"B",L27>95%,"C") -> #DIV/0!
D28: =C28/C$73 -> #DIV/0! | E28: =D28+E27 -> #DIV/0! | F28: =IF(AND(E28<=0),"C",IF(E28<=0.8,"A",IF(E28<=0.95,"B","C"))) -> #DIV/0! | G28: =VLOOKUP(B28:B79,I$21:M$72,5,0) -> #N/A | K28: =J28/J$73 -> #DIV/0! | L28: =K28+L27 -> #DIV/0! | M28: =_xlfn.IFS(L28<80%,"A",L28<=95%,"B",L28>95%,"C") -> #DIV/0!
D29: =C29/C$73 -> #DIV/0! | E29: =D29+E28 -> #DIV/0! | F29: =IF(AND(E29<=0),"C",IF(E29<=0.8,"A",IF(E29<=0.95,"B","C"))) -> #DIV/0! | G29: =VLOOKUP(B29:B80,I$21:M$72,5,0) -> #N/A | K29: =J29/J$73 -> #DIV/0! | L29: =K29+L28 -> #DIV/0! | M29: =_xlfn.IFS(L29<80%,"A",L29<=95%,"B",L29>95%,"C") -> #DIV/0!
D30: =C30/C$73 -> #DIV/0! | E30: =D30+E29 -> #DIV/0! | F30: =IF(AND(E30<=0),"C",IF(E30<=0.8,"A",IF(E30<=0.95,"B","C"))) -> #DIV/0! | G30: =VLOOKUP(B30:B81,I$21:M$72,5,0) -> #N/A | K30: =J30/J$73 -> #DIV/0! | L30: =K30+L29 -> #DIV/0! | M30: =_xlfn.IFS(L30<80%,"A",L30<=95%,"B",L30>95%,"C") -> #DIV/0!
D31: =C31/C$73 -> #DIV/0! | E31: =D31+E30 -> #DIV/0! | F31: =IF(AND(E31<=0),"C",IF(E31<=0.8,"A",IF(E31<=0.95,"B","C"))) -> #DIV/0! | G31: =VLOOKUP(B31:B82,I$21:M$72,5,0) -> #N/A | K31: =J31/J$73 -> #DIV/0! | L31: =K31+L30 -> #DIV/0! | M31: =_xlfn.IFS(L31<80%,"A",L31<=95%,"B",L31>95%,"C") -> #DIV/0!
D32: =C32/C$73 -> #DIV/0! | E32: =D32+E31 -> #DIV/0! | F32: =IF(AND(E32<=0),"C",IF(E32<=0.8,"A",IF(E32<=0.95,"B","C"))) -> #DIV/0! | G32: =VLOOKUP(B32:B83,I$21:M$72,5,0) -> #N/A | K32: =J32/J$73 -> #DIV/0! | L32: =K32+L31 -> #DIV/0! | M32: =_xlfn.IFS(L32<80%,"A",L32<=95%,"B",L32>95%,"C") -> #DIV/0!
D33: =C33/C$73 -> #DIV/0! | E33: =D33+E32 -> #DIV/0! | F33: =IF(AND(E33<=0),"C",IF(E33<=0.8,"A",IF(E33<=0.95,"B","C"))) -> #DIV/0! | G33: =VLOOKUP(B33:B84,I$21:M$72,5,0) -> #N/A | K33: =J33/J$73 -> #DIV/0! | L33: =K33+L32 -> #DIV/0! | M33: =_xlfn.IFS(L33<80%,"A",L33<=95%,"B",L33>95%,"C") -> #DIV/0!
... D72: =C72/C$73 -> #DIV/0! | E72: =D72+E71 -> #DIV/0! | F72: =IF(AND(E72<=0),"C",IF(E72<=0.8,"A",IF(E72<=0.95,"B","C"))) -> #DIV/0! | G72: =VLOOKUP(B72:B123,I$21:M$72,5,0) -> #N/A | K72: =J72/J$73 -> #DIV/0! | L72: =K72+L71 -> #DIV/0! | M72: =_xlfn.IFS(L72<80%,"A",L72<=95%,"B",L72>95%,"C") -> #DIV/0!
C73: =SUM(C21:C72) -> 0 | D73: =SUM(D21:D72) -> #DIV/0! | J73: =SUM(J21:J72) -> 0 | K73: =SUM(K21:K72) -> #DIV/0!

Sheet АВС 4
B2: ОЧКИ
C3: Прибыль | D3: % прибыль | E3: Доля | F3: ABC прибыль | G3: ABC кол-во | J3: Кол-во | K3: % кол-во | L3: Доля | M3: ABC кол-во
B4: Черные с железкой Сул | C4: ='Юнит 4'!AL3 -> 5677.8442 | D4: =C4/C$17 -> 0.415248 | E4: =D4 -> 0.415248 | F4: =IF(AND(E4<=0),"C",IF(E4<=0.8,"A",IF(E4<=0.95,"B","C"))) -> A | G4: =VLOOKUP(B$4:B$16,I$4:M$16,5,0) -> A | I4: Черные с железкой Сул | J4: ='Юнит 4'!S3 -> 21 | K4: =J4/J$17 -> 0.44680851 | L4: =K4 -> 0.44680851 | M4: =_xlfn.IFS(L4<80%,"A",L4<=95%,"B",L4>95%,"C") -> A | P4: A | Q4: 0.8
B5: flip желтые Сул | C5: ='Юнит 4'!AL8 -> 5497.2061 | D5: =C5/C$17 -> 0.40203707 | E5: =E4+D5 -> 0.81728507 | F5: =IF(AND(E5<=0),"C",IF(E5<=0.8,"A",IF(E5<=0.95,"B","C"))) -> B | G5: =VLOOKUP(B$4:B$16,I$4:M$16,5,0) -> A | I5: flip желтые Сул | J5: ='Юнит 4'!S8 -> 10 | K5: =J5/J$17 -> 0.21276596 | L5: =L4+K5 -> 0.65957447 | M5: =_xlfn.IFS(L5<80%,"A",L5<=95%,"B",L5>95%,"C") -> A | P5: B | Q5: 0.15
B6: Qs желт Сул | C6: ='Юнит 4'!AL6 -> 1821.9753 | D6: =C6/C$17 -> 0.1332498 | E6: =E5+D6 -> 0.95053487 | F6: =IF(AND(E6<=0),"C",IF(E6<=0.8,"A",IF(E6<=0.95,"B","C"))) -> C | G6: =VLOOKUP(B$4:B$16,I$4:M$16,5,0) -> B | I6: MR8854 C2 Сул | J6: ='Юнит 4'!S9 -> 9 | K6: =J6/J$17 -> 0.19148936 | L6: =L5+K6 -> 0.85106383 | M6: =_xlfn.IFS(L6<80%,"A",L6<=95%,"B",L6>95%,"C") -> B | P6: C | Q6: 0.05
B7: MR8854 C2 Сул | C7: ='Юнит 4'!AL9 -> 814.75132 | D7: =C7/C$17 -> 0.059586675 | E7: =E6+D7 -> 1.0101215 | F7: =IF(AND(E7<=0),"C",IF(E7<=0.8,"A",IF(E7<=0.95,"B","C"))) -> C | G7: =VLOOKUP(B$4:B$16,I$4:M$16,5,0) -> B | I7: Qs желт Сул | J7: ='Юнит 4'!S6 -> 4 | K7: =J7/J$17 -> 0.085106383 | L7: =L6+K7 -> 0.93617021 | M7: =_xlfn.IFS(L7<80%,"A",L7<=95%,"B",L7>95%,"C") -> B
B8: MR Р1886 корич | C8: ='Юнит 4'!AL15 -> 550.12526 | D8: =C8/C$17 -> 0.040233301 | E8: =E7+D8 -> 1.0503548 | F8: =IF(AND(E8<=0),"C",IF(E8<=0.8,"A",IF(E8<=0.95,"B","C"))) -> C | G8: =VLOOKUP(B$4:B$16,I$4:M$16,5,0) -> C | I8: MR Р1874 черн | J8: ='Юнит 4'!S12 -> 1 | K8: =J8/J$17 -> 0.021276596 | L8: =L7+K8 -> 0.95744681 | M8: =_xlfn.IFS(L8<80%,"A",L8<=95%,"B",L8>95%,"C") -> C
B9: MR Р1874 черн | C9: ='Юнит 4'!AL12 -> 373.65885 | D9: =C9/C$17 -> 0.027327466 | E9: =E8+D9 -> 1.0776823 | F9: =IF(AND(E9<=0),"C",IF(E9<=0.8,"A",IF(E9<=0.95,"B","C"))) -> C | G9: =VLOOKUP(B$4:B$16,I$4:M$16,5,0) -> C | I9: MR Р1874 корич | J9: ='Юнит 4'!S13 -> 1 | K9: =J9/J$17 -> 0.021276596 | L9: =L8+K9 -> 0.9787234 | M9: =_xlfn.IFS(L9<80%,"A",L9<=95%,"B",L9>95%,"C") -> C
B10: MR Р1874 корич | C10: ='Юнит 4'!AL13 -> 292.29359 | D10: =C10/C$17 -> 0.021376833 | E10: =E9+D10 -> 1.0990591 | F10: =IF(AND(E10<=0),"C",IF(E10<=0.8,"A",IF(E10<=0.95,"B","C"))) -> C | G10: =VLOOKUP(B$4:B$16,I$4:M$16,5,0) -> C | I10: MR Р1886 корич | J10: ='Юнит 4'!S15 -> 1 | K10: =J10/J$17 -> 0.021276596 | L10: =L9+K10 -> 1 | M10: =_xlfn.IFS(L10<80%,"A",L10<=95%,"B",L10>95%,"C") -> C
B11: MR 1819 корич | C11: ='Юнит 4'!AL11 -> -24.942493 | D11: =C11/C$17 -> -0.0018241643 | E11: =E10+D11 -> 1.097235 | F11: =IF(AND(E11<=0),"C",IF(E11<=0.8,"A",IF(E11<=0.95,"B","C"))) -> C | G11: =VLOOKUP(B$4:B$16,I$4:M$16,5,0) -> C | I11: Qs черн Сул | J11: ='Юнит 4'!S4 -> 0 | K11: =J11/J$17 -> 0 | L11: =L10+K11 -> 1 | M11: =_xlfn.IFS(L11<80%,"A",L11<=95%,"B",L11>95%,"C") -> C
B12: MR Р1886 черн | C12: ='Юнит 4'!AL14 -> -37.733516 | D12: =C12/C$17 -> -0.0027596331 | E12: =E11+D12 -> 1.0944753 | F12: =IF(AND(E12<=0),"C",IF(E12<=0.8,"A",IF(E12<=0.95,"B","C"))) -> C | G12: =VLOOKUP(B$4:B$16,I$4:M$16,5,0) -> C | I12: Qs син Сул | J12: ='Юнит 4'!S5 -> 0 | K12: =J12/J$17 -> 0 | L12: =L11+K12 -> 1 | M12: =_xlfn.IFS(L12<80%,"A",L12<=95%,"B",L12>95%,"C") -> C
