Workbook

Sheet Реклама
B2: ПЕРИОД | C2: БАЛАНС | F2: СЧЕТ | I2: Неделя
C3: Номер документа | D3: Сумма | E3: Даты | F3: Номер документа | G3: Сумма | H3: Даты
B4: 01-04.01 | F4: 277607349 | G4: 4738 | H4: 01-04.01 | I4: 1
B5: 04-11.01 | F5: 279228154 | G5: 6535 | H5: 04-11.01 | I5: 2
B6: 11-18.01 | C6: 280305485 | D6: 2922 | E6: 14-18.01 | F6: 280297200 | G6: 3464 | H6: 11-17.01 | I6: 3
C7: 0 | D7: 923 | E7: 18.01 | F7: 0 | G7: 114 | H7: 18.01
B8: 18-25.01 | C8: 281290485 | D8: 5916 | E8: 18-23.01 | F8: 281290488 | G8: 2033 | H8: 18-25.01 | I8: 4
C9: 0 | D9: 1216 | E9: 25.01
B10: 25.01-01.02 | C10: 282283796 | D10: 12613 | E10: 27-31.01 | F10: 282343451 | G10: 9553 | H10: 25-31.01 | I10: 5
C11: 282375547 | D11: 1000 | E11: 01.02
C12: 0 | D12: 1791 | E12: 01.02 | F12: 0 | G12: 539 | H12: 01.02
H39: .

Sheet Сводная
B2: Период | E2: Дата поступления дс | F2: Итого к перечислению на счет, руб | G2: шт. | J2: ВБ реализовал товар (выручка с СПП) | M2: Выручка до вычета комиссии ВБ | P2: Себестоимость продаж | Q2: Логистика WB | R2: Комиссия WB | S2: Хранение WB | T2: Платная приемка WB | U2: Штрафы WB | V2: Прочие удержания WB | W2: Реклама БАЛАНС | X2: Реклама СЧЕТ | Y2: Блогеры | Z2: Налог | AA2: Прочие поступления WB | AB2: Итого | AC2: Итог месяц | AD2: % Cебестоимости | AE2: Маржинальность, % | AF2: Рентабельность, % | AG2: Доля рекламы, %
B3: Месяц | C3: Даты | D3: Нед | G3: Заказы | H3: Продажи | I3: Возвраты | J3: Продажи | K3: Возвраты | L3: Общая | M3: Продажи | N3: Возвраты | O3: Общая
B4: Январь 1 | C4: 29.12-04.01 | D4: 1 | F4: =IFERROR(O4-SUM(Q4:W4)+AA4,0) -> 29279.64 | G4: ='Юнит 1'!L$17 -> 66 | H4: ='Юнит 1'!Q$17 -> 45 | I4: ='Юнит 1'!R$17 -> 0 | J4: ='Юнит 1'!T$74 -> 46145.63 | K4: ='Юнит 1'!U$74 -> 0 | L4: =IFERROR(J4+K4,0) -> 46145.63 | M4: ='Юнит 1'!W$74 -> 54988.62 | N4: ='Юнит 1'!X$74 -> 0 | O4: =IFERROR(M4+N4,0) -> 54988.62 | P4: ='Юнит 1'!AB$74 -> 5712.21 | Q4: ='Юнит 1'!AE$74 -> 4543.05 | R4: ='Юнит 1'!AC$74 -> 19854.22 | S4: ='Юнит 1'!AI$74 -> 1049.63 | U4: ='Юнит 1'!AJ$74 -> 0 | V4: 262.08 | W4: ='Юнит 1'!AF$74 -> 0 | X4: ='Юнит 1'!AG$74 -> 4738 | Y4: ='Юнит 1'!AH84 -> 0 | Z4: =IFERROR((L4)*0.01,0) -> 461.4563 | AB4: =O4-SUM(P4:Z4)+AA4-Y4 -> 18367.974 | AC4: =SUM(AB4:AB8) -> 67227.563 | AD4: =P4/O4 -> 0.10387986 | AE4: =AB4/P4 -> 3.2155635 | AF4: =AB4/O4 -> 0.33403227 | AG4: =(W4+X4+Y4)/O4 -> 0.086163283
B5: Январь 2 | C5: 05-11.01 | D5: 2 | F5: =IFERROR(O5-SUM(Q5:W5)+AA5,0) -> 25524.23 | G5: ='Юнит 2'!L$17 -> 86 | H5: ='Юнит 2'!Q$17 -> 43 | I5: ='Юнит 2'!R$17 -> -1 | J5: ='Юнит 2'!T$74 -> 43245.32 | K5: ='Юнит 2'!U$74 -> -931 | L5: =IFERROR(J5+K5,0) -> 42314.32 | M5: ='Юнит 2'!W$74 -> 52197.86 | N5: ='Юнит 2'!X$74 -> -1199 | O5: =IFERROR(M5+N5,0) -> 50998.86 | P5: ='Юнит 2'!AB$74 -> 5562.9 | Q5: ='Юнит 2'!AE$74 -> 5752.8 | R5: ='Юнит 2'!AC$74 -> 18463.04 | S5: ='Юнит 2'!AI$74 -> 1083.11 | U5: ='Юнит 2'!AJ$74 -> 0 | V5: 175.68 | W5: ='Юнит 2'!AF$74 -> 0 | X5: ='Юнит 2'!AG$74 -> 6535 | Y5: ='Юнит 2'!AH85 -> 0 | Z5: =IFERROR((L5)*0.01,0) -> 423.1432 | AB5: =O5-SUM(P5:Z5)+AA5-Y5 -> 13003.187 | AD5: =P5/O5 -> 0.10907891 | AE5: =AB5/P5 -> 2.3374835 | AF5: =AB5/O5 -> 0.25497015 | AG5: =(W5+X5+Y5)/O5 -> 0.12814012
B6: Январь 3 | C6: 12-18.01 | D6: 3 | F6: =IFERROR(O6-SUM(Q6:W6)+AA6,0) -> 25982.83 | G6: ='Юнит 3'!L$17 -> 62 | H6: ='Юнит 3'!Q$17 -> 49 | I6: ='Юнит 3'!R$17 -> -1 | J6: ='Юнит 3'!T$74 -> 45785.47 | K6: ='Юнит 3'!U$74 -> -948 | L6: =IFERROR(J6+K6,0) -> 44837.47 | M6: ='Юнит 3'!W$74 -> 56919.74 | N6: ='Юнит 3'!X$74 -> -1174 | O6: =IFERROR(M6+N6,0) -> 55745.74 | P6: ='Юнит 3'!AB$74 -> 6528.42 | Q6: ='Юнит 3'!AE$74 -> 6055.25 | R6: ='Юнит 3'!AC$74 -> 19306.86 | S6: ='Юнит 3'!AI$74 -> 1361.68 | U6: ='Юнит 3'!AJ$74 -> 0 | V6: 117.12 | W6: ='Юнит 3'!AF$74 -> 2922 | X6: ='Юнит 3'!AG$74 -> 3464 | Y6: ='Юнит 3'!AH86 -> 0 | Z6: =IFERROR((L6)*0.01,0) -> 448.3747 | AB6: =O6-SUM(P6:Z6)+AA6-Y6 -> 15542.035 | AD6: =P6/O6 -> 0.11711065 | AE6: =AB6/P6 -> 2.3806733 | AF6: =AB6/O6 -> 0.27880221 | AG6: =(W6+X6+Y6)/O6 -> 0.11455584
B7: Январь 4 | C7: 19-25.01 | D7: 4 | F7: =IFERROR(O7-SUM(Q7:W7)+AA7,0) -> 22836.85 | G7: ='Юнит 4'!L$17 -> 86 | H7: ='Юнит 4'!Q$17 -> 49 | I7: ='Юнит 4'!R$17 -> -2 | J7: ='Юнит 4'!T$74 -> 44338.88 | K7: ='Юнит 4'!U$74 -> -1888 | L7: =IFERROR(J7+K7,0) -> 42450.88 | M7: ='Юнит 4'!W$74 -> 59321.67 | N7: ='Юнит 4'!X$74 -> -2412 | O7: =IFERROR(M7+N7,0) -> 56909.67 | P7: ='Юнит 4'!AB$74 -> 6764.52 | Q7: ='Юнит 4'!AE$74 -> 6115.35 | R7: ='Юнит 4'!AC$74 -> 20543.92 | S7: ='Юнит 4'!AI$74 -> 1438.99 | U7: ='Юнит 4'!AJ$74 -> 0 | V7: 58.56 | W7: ='Юнит 4'!AF$74 -> 5916 | X7: ='Юнит 4'!AG$74 -> 2033 | Y7: ='Юнит 4'!AH87 -> 0 | Z7: =IFERROR((L7)*0.01,0) -> 424.5088 | AB7: =O7-SUM(P7:Z7)+AA7-Y7 -> 13614.821 | AD7: =P7/O7 -> 0.11886416 | AE7: =AB7/P7 -> 2.012681 | AF7: =AB7/O7 -> 0.23923564 | AG7: =(W7+X7+Y7)/O7 -> 0.13967749
B8: Январь 5 | C8: 26.01-01.02 | D8: 5 | F8: =IFERROR(O8-SUM(Q8:W8)+AA8,0) -> 26541.81 | G8: ='Юнит 5'!L$17 -> 157 | H8: ='Юнит 5'!Q$17 -> 70 | I8: ='Юнит 5'!R$17 -> -1 | J8: ='Юнит 5'!T$74 -> 53707.42 | K8: ='Юнит 5'!U$74 -> -813 | L8: =IFERROR(J8+K8,0) -> 52894.42 | M8: ='Юнит 5'!W$74 -> 80352 | N8: ='Юнит 5'!X$74 -> -1238 | O8: =IFERROR(M8+N8,0) -> 79114 | P8: ='Юнит 5'!AB$74 -> 9760.32 | Q8: ='Юнит 5'!AE$74 -> 8509.6 | R8: ='Юнит 5'!AC$74 -> 28720.66 | S8: ='Юнит 5'!AI$74 -> 1377.57 | U8: ='Юнит 5'!AJ$74 -> 0 | V8: 351.36 | W8: ='Юнит 5'!AF$74 -> 13613 | X8: ='Юнит 5'!AG$74 -> 9553 | Y8: ='Юнит 5'!AH88 -> 0 | Z8: =IFERROR((L8)*0.01,0) -> 528.9442 | AB8: =O8-SUM(P8:Z8)+AA8-Y8 -> 6699.5458 | AD8: =P8/O8 -> 0.12337033 | AE8: =AB8/P8 -> 0.68640637 | AF8: =AB8/O8 -> 0.084682178 | AG8: =(W8+X8+Y8)/O8 -> 0.29281796
B9: Итого | F9: =SUM(F4:F8) -> 130165.36 | G9: =SUM(G4:G8) -> 457 | H9: =SUM(H4:H8) -> 256 | I9: =SUM(I4:I8) -> -5 | J9: =SUM(J4:J8) -> 233222.72 | K9: =SUM(K4:K8) -> -4580 | L9: =SUM(L4:L8) -> 228642.72 | M9: =SUM(M4:M8) -> 303779.89 | ... AC9: =SUM(AC4:AC8) -> 67227.563 | AD9: =P9/O9 -> 0.11528993 | AE9: =AB9/P9 -> 1.9583675 | AF9: =AB9/O9 -> 0.22578004 | AG9: =(W9+X9+Y9)/O9 -> 0.16380477
M10: % от выручки за весь период
N11: =-N9/M9 -> 0.019826856 | P11: =P9/$O$9 -> 0.11528993 | Q11: =Q9/$O$9 -> 0.10403135 | R11: =R9/$O$9 -> 0.35897977 | S11: =S9/$O$9 -> 0.021195076 | U11: =U9/$O$9 -> 0 | V11: =V9/$O$9 -> 0.0032402273 | W11: =W9/$O$9 -> 0.075400438 | Z11: =Z9/$O$9 -> 0.0076788389 | AB11: =AB9/P9 -> 1.9583675 | AC11: Маржинальность, %
AB12: =AB9/O9 -> 0.22578004 | AC12: Рентабельность, %

Sheet АВС 6
B2: ОЧКИ
C3: Прибыль | D3: % прибыль | E3: Доля | F3: ABC прибыль | G3: ABC кол-во | J3: Кол-во | K3: % кол-во | L3: Доля | M3: ABC кол-во
B4: Черные с железкой Сул | D4: =C4/C$17 -> #DIV/0! | E4: =D4 -> #DIV/0! | F4: =IF(AND(E4<=0),"C",IF(E4<=0.8,"A",IF(E4<=0.95,"B","C"))) -> #DIV/0! | G4: =VLOOKUP(B$4:B$16,I$4:M$16,5,0) -> #DIV/0! | I4: Черные с железкой Сул | K4: =J4/J$17 -> #DIV/0! | L4: =K4 -> #DIV/0! | M4: =_xlfn.IFS(L4<80%,"A",L4<=95%,"B",L4>95%,"C") -> #DIV/0! | P4: A | Q4: 0.8
B5: Qs черн Сул | D5: =C5/C$17 -> #DIV/0! | E5: =E4+D5 -> #DIV/0! | F5: =IF(AND(E5<=0),"C",IF(E5<=0.8,"A",IF(E5<=0.95,"B","C"))) -> #DIV/0! | G5: =VLOOKUP(B$4:B$16,I$4:M$16,5,0) -> #DIV/0! | I5: Qs черн Сул | K5: =J5/J$17 -> #DIV/0! | L5: =L4+K5 -> #DIV/0! | M5: =_xlfn.IFS(L5<80%,"A",L5<=95%,"B",L5>95%,"C") -> #DIV/0! | P5: B | Q5: 0.15
B6: Qs син Сул | D6: =C6/C$17 -> #DIV/0! | E6: =E5+D6 -> #DIV/0! | F6: =IF(AND(E6<=0),"C",IF(E6<=0.8,"A",IF(E6<=0.95,"B","C"))) -> #DIV/0! | G6: =VLOOKUP(B$4:B$16,I$4:M$16,5,0) -> #DIV/0! | I6: Qs син Сул | K6: =J6/J$17 -> #DIV/0! | L6: =L5+K6 -> #DIV/0! | M6: =_xlfn.IFS(L6<80%,"A",L6<=95%,"B",L6>95%,"C") -> #DIV/0! | P6: C | Q6: 0.05
B7: Qs желт Сул | D7: =C7/C$17 -> #DIV/0! | E7: =E6+D7 -> #DIV/0! | F7: =IF(AND(E7<=0),"C",IF(E7<=0.8,"A",IF(E7<=0.95,"B","C"))) -> #DIV/0! | G7: =VLOOKUP(B$4:B$16,I$4:M$16,5,0) -> #DIV/0! | I7: Qs желт Сул | K7: =J7/J$17 -> #DIV/0! | L7: =L6+K7 -> #DIV/0! | M7: =_xlfn.IFS(L7<80%,"A",L7<=95%,"B",L7>95%,"C") -> #DIV/0!
B8: flip черные Сул | D8: =C8/C$17 -> #DIV/0! | E8: =E7+D8 -> #DIV/0! | F8: =IF(AND(E8<=0),"C",IF(E8<=0.8,"A",IF(E8<=0.95,"B","C"))) -> #DIV/0! | G8: =VLOOKUP(B$4:B$16,I$4:M$16,5,0) -> #DIV/0! | I8: flip черные Сул | K8: =J8/J$17 -> #DIV/0! | L8: =L7+K8 -> #DIV/0! | M8: =_xlfn.IFS(L8<80%,"A",L8<=95%,"B",L8>95%,"C") -> #DIV/0!
B9: flip желтые Сул | D9: =C9/C$17 -> #DIV/0! | E9: =E8+D9 -> #DIV/0! | F9: =IF(AND(E9<=0),"C",IF(E9<=0.8,"A",IF(E9<=0.95,"B","C"))) -> #DIV/0! | G9: =VLOOKUP(B$4:B$16,I$4:M$16,5,0) -> #DIV/0! | I9: flip желтые Сул | K9: =J9/J$17 -> #DIV/0! | L9: =L8+K9 -> #DIV/0! | M9: =_xlfn.IFS(L9<80%,"A",L9<=95%,"B",L9>95%,"C") -> #DIV/0!
B10: MR8854 C2 Сул | D10: =C10/C$17 -> #DIV/0! | E10: =E9+D10 -> #DIV/0! | F10: =IF(AND(E10<=0),"C",IF(E10<=0.8,"A",IF(E10<=0.95,"B","C"))) -> #DIV/0! | G10: =VLOOKUP(B$4:B$16,I$4:M$16,5,0) -> #DIV/0! | I10: MR8854 C2 Сул | K10: =J10/J$17 -> #DIV/0! | L10: =L9+K10 -> #DIV/0! | M10: =_xlfn.IFS(L10<80%,"A",L10<=95%,"B",L10>95%,"C") -> #DIV/0!
B11: MR 1819 черн | D11: =C11/C$17 -> #DIV/0! | E11: =E10+D11 -> #DIV/0! | F11: =IF(AND(E11<=0),"C",IF(E11<=0.8,"A",IF(E11<=0.95,"B","C"))) -> #DIV/0! | G11: =VLOOKUP(B$4:B$16,I$4:M$16,5,0) -> #DIV/0! | I11: MR 1819 черн | K11: =J11/J$17 -> #DIV/0! | L11: =L10+K11 -> #DIV/0! | M11: =_xlfn.IFS(L11<80%,"A",L11<=95%,"B",L11>95%,"C") -> #DIV/0!
B12: MR 1819 корич | D12: =C12/C$17 -> #DIV/0! | E12: =E11+D12 -> #DIV/0! | F12: =IF(AND(E12<=0),"C",IF(E12<=0.8,"A",IF(E12<=0.95,"B","C"))) -> #DIV/0! | G12: =VLOOKUP(B$4:B$16,I$4:M$16,5,0) -> #DIV/0! | I12: MR 1819 корич | K12: =J12/J$17 -> #DIV/0! | L12: =L11+K12 -> #DIV/0! | M12: =_xlfn.IFS(L12<80%,"A",L12<=95%,"B",L12>95%,"C") -> #DIV/0!
B13: MR Р1874 черн | D13: =C13/C$17 -> #DIV/0! | E13: =E12+D13 -> #DIV/0! | F13: =IF(AND(E13<=0),"C",IF(E13<=0.8,"A",IF(E13<=0.95,"B","C"))) -> #DIV/0! | G13: =VLOOKUP(B$4:B$16,I$4:M$16,5,0) -> #DIV/0! | I13: MR Р1874 черн | K13: =J13/J$17 -> #DIV/0! | L13: =L12+K13 -> #DIV/0! | M13: =_xlfn.IFS(L13<80%,"A",L13<=95%,"B",L13>95%,"C") -> #DIV/0!
B14: MR Р1874 корич | D14: =C14/C$17 -> #DIV/0! | E14: =E13+D14 -> #DIV/0! | F14: =IF(AND(E14<=0),"C",IF(E14<=0.8,"A",IF(E14<=0.95,"B","C"))) -> #DIV/0! | G14: =VLOOKUP(B$4:B$16,I$4:M$16,5,0) -> #DIV/0! | I14: MR Р1874 корич | K14: =J14/J$17 -> #DIV/0! | L14: =L13+K14 -> #DIV/0! | M14: =_xlfn.IFS(L14<80%,"A",L14<=95%,"B",L14>95%,"C") -> #DIV/0!
B15: MR Р1886 черн | D15: =C15/C$17 -> #DIV/0! | E15: =E14+D15 -> #DIV/0! | F15: =IF(AND(E15<=0),"C",IF(E15<=0.8,"A",IF(E15<=0.95,"B","C"))) -> #DIV/0! | G15: =VLOOKUP(B$4:B$16,I$4:M$16,5,0) -> #DIV/0! | I15: MR Р1886 черн | K15: =J15/J$17 -> #DIV/0! | L15: =L14+K15 -> #DIV/0! | M15: =_xlfn.IFS(L15<80%,"A",L15<=95%,"B",L15>95%,"C") -> #DIV/0!
B16: MR Р1886 корич | D16: =C16/C$17 -> #DIV/0! | E16: =E15+D16 -> #DIV/0! | F16: =IF(AND(E16<=0),"C",IF(E16<=0.8,"A",IF(E16<=0.95,"B","C"))) -> #DIV/0! | G16: =VLOOKUP(B$4:B$16,I$4:M$16,5,0) -> #DIV/0! | I16: MR Р1886 корич | K16: =J16/J$17 -> #DIV/0! | L16: =L15+K16 -> #DIV/0! | M16: =_xlfn.IFS(L16<80%,"A",L16<=95%,"B",L16>95%,"C") -> #DIV/0!
C17: =SUM(C4:C16) -> 0 | D17: =SUM(D4:D16) -> #DIV/0! | J17: =SUM(J4:J16) -> 0 | K17: =SUM(K4:K16) -> #DIV/0!
C20: Прибыль | D20: % прибыль | E20: Доля | F20: ABC прибыль | G20: ABC кол-во | J20: Кол-во | K20: % кол-во | L20: Доля | M20: ABC кол-во
D21: =C21/C$73 -> #DIV/0! | E21: =D21 -> #DIV/0! | F21: =IF(AND(E21<=0),"C",IF(E21<=0.8,"A",IF(E21<=0.95,"B","C"))) -> #DIV/0! | G21: =VLOOKUP(B21:B72,I$21:M$72,5,0) -> #N/A | K21: =J21/J$73 -> #DIV/0! | L21: =K21 -> #DIV/0! | M21: =_xlfn.IFS(L21<80%,"A",L21<=95%,"B",L21>95%,"C") -> #DIV/0!
D22: =C22/C$73 -> #DIV/0! | E22: =D22+E21 -> #DIV/0! | F22: =IF(AND(E22<=0),"C",IF(E22<=0.8,"A",IF(E22<=0.95,"B","C"))) -> #DIV/0! | G22: =VLOOKUP(B22:B73,I$21:M$72,5,0) -> #N/A | K22: =J22/J$73 -> #DIV/0! | L22: =K22+L21 -> #DIV/0! | M22: =_xlfn.IFS(L22<80%,"A",L22<=95%,"B",L22>95%,"C") -> #DIV/0!
D23: =C23/C$73 -> #DIV/0! | E23: =D23+E22 -> #DIV/0! | F23: =IF(AND(E23<=0),"C",IF(E23<=0.8,"A",IF(E23<=0.95,"B","C"))) -> #DIV/0! | G23: =VLOOKUP(B23:B74,I$21:M$72,5,0) -> #N/A | K23: =J23/J$73 -> #DIV/0! | L23: =K23+L22 -> #DIV/0! | M23: =_xlfn.IFS(L23<80%,"A",L23<=95%,"B",L23>95%,"C") -> #DIV/0!
D24: =C24/C$73 -> #DIV/0! | E24: =D24+E23 -> #DIV/0! | F24: =IF(AND(E24<=0),"C",IF(E24<=0.8,"A",IF(E24<=0.95,"B","C"))) -> #DIV/0! | G24: =VLOOKUP(B24:B75,I$21:M$72,5,0) -> #N/A | K24: =J24/J$73 -> #DIV/0! | L24: =K24+L23 -> #DIV/0! | M24: =_xlfn.IFS(L24<80%,"A",L24<=95%,"B",L24>95%,"C") -> #DIV/0!
D25: =C25/C$73 -> #DIV/0! | E25: =D25+E24 -> #DIV/0! | F25: =IF(AND(E25<=0),"C",IF(E25<=0.8,"A",IF(E25<=0.95,"B","C"))) -> #DIV/0! | G25: =VLOOKUP(B25:B76,I$21:M$72,5,0) -> #N/A | K25: =J25/J$73 -> #DIV/0! | L25: =K25+L24 -> #DIV/0! | M25: =_xlfn.IFS(L25<80%,"A",L25<=95%,"B",L25>95%,"C") -> #DIV/0!
D26: =C26/C$73 -> #DIV/0! | E26: =D26+E25 -> #DIV/0! | F26: =IF(AND(E26<=0),"C",IF(E26<=0.8,"A",IF(E26<=0.95,"B","C"))) -> #DIV/0! | G26: =VLOOKUP(B26:B77,I$21:M$72,5,0) -> #N/A | K26: =J26/J$73 -> #DIV/0! | L26: =K26+L25 -> #DIV/0! | M26: =_xlfn.IFS(L26<80%,"A",L26<=95%,"B",L26>95%,"C") -> #DIV/0!
D27: =C27/C$73 -> #DIV/0! | E27: =D27+E26 -> #DIV/0! | F27: =IF(AND(E27<=0),"C",IF(E27<=0.8,"A",IF(E27<=0.95,"B","C"))) -> #DIV/0! | G27: =VLOOKUP(B27:B78,I$21:M$72,5,0) -> #N/A | K27: =J27/J$73 -> #DIV/0! | L27: =K27+L26 -> #DIV/0! | M27: =_xlfn.IFS(L27<80%,"A",L27<=95%,"B",L27>95%,"C") -> #DIV/0!
D28: =C28/C$73 -> #DIV/0! | E28: =D28+E27 -> #DIV/0! | F28: =IF(AND(E28<=0),"C",IF(E28<=0.8,"A",IF(E28<=0.95,"B","C"))) -> #DIV/0! | G28: =VLOOKUP(B28:B79,I$21:M$72,5,0) -> #N/A | K28: =J28/J$73 -> #DIV/0! | L28: =K28+L27 -> #DIV/0! | M28: =_xlfn.IFS(L28<80%,"A",L28<=95%,"B",L28>95%,"C") -> #DIV/0!
D29: =C29/C$73 -> #DIV/0! | E29: =D29+E28 -> #DIV/0! | F29: =IF(AND(E29<=0),"C",IF(E29<=0.8,"A",IF(E29<=0.95,"B","C"))) -> #DIV/0! | G29: =VLOOKUP(B29:B80,I$21:M$72,5,0) -> #N/A | K29: =J29/J$73 -> #DIV/0! | L29: =K29+L28 -> #DIV/0! | M29: =_xlfn.IFS(L29<80%,"A",L29<=95%,"B",L29>95%,"C") -> #DIV/0!
D30: =C30/C$73 -> #DIV/0! | E30: =D30+E29 -> #DIV/0! | F30: =IF(AND(E30<=0),"C",IF(E30<=0.8,"A",IF(E30<=0.95,"B","C"))) -> #DIV/0! | G30: =VLOOKUP(B30:B81,I$21:M$72,5,0) -> #N/A | K30: =J30/J$73 -> #DIV/0! | L30: =K30+L29 -> #DIV/0! | M30: =_xlfn.IFS(L30<80%,"A",L30<=95%,"B",L30>95%,"C") -> #DIV/0!
D31: =C31/C$73 -> #DIV/0! | E31: =D31+E30 -> #DIV/0! | F31: =IF(AND(E31<=0),"C",IF(E31<=0.8,"A",IF(E31<=0.95,"B","C"))) -> #DIV/0! | G31: =VLOOKUP(B31:B82,I$21:M$72,5,0) -> #N/A | K31: =J31/J$73 -> #DIV/0! | L31: =K31+L30 -> #DIV/0! | M31: =_xlfn.IFS(L31<80%,"A",L31<=95%,"B",L31>95%,"C") -> #DIV/0!
D32: =C32/C$73 -> #DIV/0! | E32: =D32+E31 -> #DIV/0! | F32: =IF(AND(E32<=0),"C",IF(E32<=0.8,"A",IF(E32<=0.95,"B","C"))) -> #DIV/0! | G32: =VLOOKUP(B32:B83,I$21:M$72,5,0) -> #N/A | K32: =J32/J$73 -> #DIV/0! | L32: =K32+L31 -> #DIV/0! | M32: =_xlfn.IFS(L32<80%,"A",L32<=95%,"B",L32>95%,"C") -> #DIV/0!
D33: =C33/C$73 -> #DIV/0! | E33: =D33+E32 -> #DIV/0! | F33: =IF(AND(E33<=0),"C",IF(E33<=0.8,"A",IF(E33<=0.95,"B","C"))) -> #DIV/0! | G33: =VLOOKUP(B33:B84,I$21:M$72,5,0) -> #N/A | K33: =J33/J$73 -> #DIV/0! | L33: =K33+L32 -> #DIV/0! | M33: =_xlfn.IFS(L33<80%,"A",L33<=95%,"B",L33>95%,"C") -> #DIV/0!
... D72: =C72/C$73 -> #DIV/0! | E72: =D72+E71 -> #DIV/0! | F72: =IF(AND(E72<=0),"C",IF(E72<=0.8,"A",IF(E72<=0.95,"B","C"))) -> #DIV/0! | G72: =VLOOKUP(B72:B123,I$21:M$72,5,0) -> #N/A | K72: =J72/J$73 -> #DIV/0! | L72: =K72+L71 -> #DIV/0! | M72: =_xlfn.IFS(L72<80%,"A",L72<=95%,"B",L72>95%,"C") -> #DIV/0!
C73: =SUM(C21:C72) -> 0 | D73: =SUM(D21:D72) -> #DIV/0! | J73: =SUM(J21:J72) -> 0 | K73: =SUM(K21:K72) -> #DIV/0!

Sheet АВС ЯНВАРЬ
B2: ОЧКИ
C3: Прибыль | D3: % прибыль | E3: Доля | F3: ABC прибыль | G3: ABC кол-во | J3: Кол-во | K3: % кол-во | L3: Доля | M3: ABC кол-во
B4: flip желтые Сул | C4: ='Юнит 5'!AL8 -> 2045.1121 | D4: =C4/C$17 -> 0.29004955 | E4: =D4 -> 0.29004955 | F4: =IF(AND(E4<=0),"C",IF(E4<=0.8,"A",IF(E4<=0.95,"B","C"))) -> A | G4: =VLOOKUP(B$4:B$16,I$4:M$16,5,0) -> A | I4: flip желтые Сул | J4: =ЯНВАРЬ!S8 -> 107 | K4: =J4/J$17 -> 0.42629482 | L4: =K4 -> 0.42629482 | M4: =_xlfn.IFS(L4<80%,"A",L4<=95%,"B",L4>95%,"C") -> A | P4: A | Q4: 0.8
B5: Черные с железкой Сул | C5: ='Юнит 5'!AL3 -> 1813.3318 | D5: =C5/C$17 -> 0.25717714 | E5: =E4+D5 -> 0.54722669 | F5: =IF(AND(E5<=0),"C",IF(E5<=0.8,"A",IF(E5<=0.95,"B","C"))) -> A | G5: =VLOOKUP(B$4:B$16,I$4:M$16,5,0) -> A | I5: Черные с железкой Сул | J5: =ЯНВАРЬ!S3 -> 62 | K5: =J5/J$17 -> 0.24701195 | L5: =L4+K5 -> 0.67330677 | M5: =_xlfn.IFS(L5<80%,"A",L5<=95%,"B",L5>95%,"C") -> A | P5: B | Q5: 0.15
B6: Qs желт Сул | C6: ='Юнит 5'!AL6 -> 1154.6045 | D6: =C6/C$17 -> 0.16375265 | E6: =E5+D6 -> 0.71097934 | F6: =IF(AND(E6<=0),"C",IF(E6<=0.8,"A",IF(E6<=0.95,"B","C"))) -> A | G6: =VLOOKUP(B$4:B$16,I$4:M$16,5,0) -> B | I6: MR8854 C2 Сул | J6: =ЯНВАРЬ!S9 -> 26 | K6: =J6/J$17 -> 0.10358566 | L6: =L5+K6 -> 0.77689243 | M6: =_xlfn.IFS(L6<80%,"A",L6<=95%,"B",L6>95%,"C") -> A | P6: C | Q6: 0.05
B7: MR Р1886 черн | C7: ='Юнит 5'!AL14 -> 826.78813 | D7: =C7/C$17 -> 0.11725985 | E7: =E6+D7 -> 0.82823919 | F7: =IF(AND(E7<=0),"C",IF(E7<=0.8,"A",IF(E7<=0.95,"B","C"))) -> B | G7: =VLOOKUP(B$4:B$16,I$4:M$16,5,0) -> B | I7: Qs желт Сул | J7: =ЯНВАРЬ!S6 -> 20 | K7: =J7/J$17 -> 0.079681275 | L7: =L6+K7 -> 0.85657371 | M7: =_xlfn.IFS(L7<80%,"A",L7<=95%,"B",L7>95%,"C") -> B
B8: MR Р1874 черн | C8: ='Юнит 5'!AL12 -> 783.16961 | D8: =C8/C$17 -> 0.11107362 | E8: =E7+D8 -> 0.93931281 | F8: =IF(AND(E8<=0),"C",IF(E8<=0.8,"A",IF(E8<=0.95,"B","C"))) -> B | G8: =VLOOKUP(B$4:B$16,I$4:M$16,5,0) -> C | I8: Qs черн Сул | J8: =ЯНВАРЬ!S4 -> 10 | K8: =J8/J$17 -> 0.039840637 | L8: =L7+K8 -> 0.89641434 | M8: =_xlfn.IFS(L8<80%,"A",L8<=95%,"B",L8>95%,"C") -> B
B9: MR 1819 корич | C9: ='Юнит 5'!AL11 -> 758.76739 | D9: =C9/C$17 -> 0.10761275 | E9: =E8+D9 -> 1.0469256 | F9: =IF(AND(E9<=0),"C",IF(E9<=0.8,"A",IF(E9<=0.95,"B","C"))) -> C | G9: =VLOOKUP(B$4:B$16,I$4:M$16,5,0) -> C | I9: MR Р1886 черн | J9: =ЯНВАРЬ!S14 -> 6 | K9: =J9/J$17 -> 0.023904382 | L9: =L8+K9 -> 0.92031873 | M9: =_xlfn.IFS(L9<80%,"A",L9<=95%,"B",L9>95%,"C") -> B
B10: MR Р1874 корич | C10: ='Юнит 5'!AL13 -> 508.76629 | D10: =C10/C$17 -> 0.072156161 | E10: =E9+D10 -> 1.1190817 | F10: =IF(AND(E10<=0),"C",IF(E10<=0.8,"A",IF(E10<=0.95,"B","C"))) -> C | G10: =VLOOKUP(B$4:B$16,I$4:M$16,5,0) -> C | I10: Qs син Сул | J10: =ЯНВАРЬ!S5 -> 4 | K10: =J10/J$17 -> 0.015936255 | L10: =L9+K10 -> 0.93625498 | M10: =_xlfn.IFS(L10<80%,"A",L10<=95%,"B",L10>95%,"C") -> B
B11: MR 1819 черн | C11: ='Юнит 5'!AL10 -> 398.95943 | D11: =C11/C$17 -> 0.05658272 | E11: =E10+D11 -> 1.1756644 | F11: =IF(AND(E11<=0),"C",IF(E11<=0.8,"A",IF(E11<=0.95,"B","C"))) -> C | G11: =VLOOKUP(B$4:B$16,I$4:M$16,5,0) -> C | I11: MR Р1874 корич | J11: =ЯНВАРЬ!S13 -> 4 | K11: =J11/J$17 -> 0.015936255 | L11: =L10+K11 -> 0.95219124 | M11: =_xlfn.IFS(L11<80%,"A",L11<=95%,"B",L11>95%,"C") -> C
B12: MR8854 C2 Сул | C12: ='Юнит 5'!AL9 -> 297.0268 | D12: =C12/C$17 -> 0.042126049 | E12: =E11+D12 -> 1.2177905 | F12: =IF(AND(E12<=0),"C",IF(E12<=0.8,"A",IF(E12<=0.95,"B","C"))) -> C | G12: =VLOOKUP(B$4:B$16,I$4:M$16,5,0) -> A | I12: MR 1819 корич | J12: =ЯНВАРЬ!S11 -> 3 | K12: =J12/J$17 -> 0.011952191 | L12: =L11+K12 -> 0.96414343 | M12: =_xlfn.IFS(L12<80%,"A",L12<=95%,"B",L12>95%,"C") -> C
B13: Qs черн Сул | C13: ='Юнит 5'!AL4 -> 177.70464 | D13: =C13/C$17 -> 0.025203094 | E13: =E12+D13 -> 1.2429936 | F13: =IF(AND(E13<=0),"C",IF(E13<=0.8,"A",IF(E13<=0.95,"B","C"))) -> C | G13: =VLOOKUP(B$4:B$16,I$4:M$16,5,0) -> B | I13: MR Р1874 черн | J13: =ЯНВАРЬ!S12 -> 3 | K13: =J13/J$17 -> 0.011952191 | L13: =L12+K13 -> 0.97609562 | M13: =_xlfn.IFS(L13<80%,"A",L13<=95%,"B",L13>95%,"C") -> C
B14: MR Р1886 корич | C14: ='Юнит 5'!AL15 -> -22.030753 | D14: =C14/C$17 -> -0.003124528 | E14: =E13+D14 -> 1.2398691 | F14: =IF(AND(E14<=0),"C",IF(E14<=0.8,"A",IF(E14<=0.95,"B","C"))) -> C | G14: =VLOOKUP(B$4:B$16,I$4:M$16,5,0) -> C | I14: MR Р1886 корич | J14: =ЯНВАРЬ!S15 -> 3 | K14: =J14/J$17 -> 0.011952191 | L14: =L13+K14 -> 0.98804781 | M14: =_xlfn.IFS(L14<80%,"A",L14<=95%,"B",L14>95%,"C") -> C
B15: flip черные Сул | C15: ='Юнит 5'!AL7 -> -773.48176 | D15: =C15/C$17 -> -0.10969963 | E15: =E14+D15 -> 1.1301694 | F15: =IF(AND(E15<=0),"C",IF(E15<=0.8,"A",IF(E15<=0.95,"B","C"))) -> C | G15: =VLOOKUP(B$4:B$16,I$4:M$16,5,0) -> C | I15: MR 1819 черн | J15: =ЯНВАРЬ!S10 -> 2 | K15: =J15/J$17 -> 0.0079681275 | L15: =L14+K15 -> 0.99601594 | M15: =_xlfn.IFS(L15<80%,"A",L15<=95%,"B",L15>95%,"C") -> C
B16: Qs син Сул | C16: ='Юнит 5'!AL5 -> -917.81235 | D16: =C16/C$17 -> -0.13016942 | E16: =E15+D16 -> 1 | F16: =IF(AND(E16<=0),"C",IF(E16<=0.8,"A",IF(E16<=0.95,"B","C"))) -> C | G16: =VLOOKUP(B$4:B$16,I$4:M$16,5,0) -> B | I16: flip черные Сул | J16: =ЯНВАРЬ!S7 -> 1 | K16: =J16/J$17 -> 0.0039840637 | L16: =L15+K16 -> 1 | M16: =_xlfn.IFS(L16<80%,"A",L16<=95%,"B",L16>95%,"C") -> C
C17: =SUM(C4:C16) -> 7050.9058 | D17: =SUM(D4:D16) -> 1 | J17: =SUM(J4:J16) -> 251 | K17: =SUM(K4:K16) -> 1
C20: Прибыль | D20: % прибыль | E20: Доля | F20: ABC прибыль | G20: ABC кол-во | J20: Кол-во | K20: % кол-во | L20: Доля | M20: ABC кол-во
D21: =C21/C$73 -> #DIV/0! | E21: =D21 -> #DIV/0! | F21: =IF(AND(E21<=0),"C",IF(E21<=0.8,"A",IF(E21<=0.95,"B","C"))) -> #DIV/0! | G21: =VLOOKUP(B21:B72,I$21:M$72,5,0) -> #N/A | K21: =J21/J$73 -> #DIV/0! | L21: =K21 -> #DIV/0! | M21: =_xlfn.IFS(L21<80%,"A",L21<=95%,"B",L21>95%,"C") -> #DIV/0!
D22: =C22/C$73 -> #DIV/0! | E22: =D22+E21 -> #DIV/0! | F22: =IF(AND(E22<=0),"C",IF(E22<=0.8,"A",IF(E22<=0.95,"B","C"))) -> #DIV/0! | G22: =VLOOKUP(B22:B73,I$21:M$72,5,0) -> #N/A | K22: =J22/J$73 -> #DIV/0! | L22: =K22+L21 -> #DIV/0! | M22: =_xlfn.IFS(L22<80%,"A",L22<=95%,"B",L22>95%,"C") -> #DIV/0!
D23: =C23/C$73 -> #DIV/0! | E23: =D23+E22 -> #DIV/0! | F23: =IF(AND(E23<=0),"C",IF(E23<=0.8,"A",IF(E23<=0.95,"B","C"))) -> #DIV/0! | G23: =VLOOKUP(B23:B74,I$21:M$72,5,0) -> #N/A | K23: =J23/J$73 -> #DIV/0! | L23: =K23+L22 -> #DIV/0! | M23: =_xlfn.IFS(L23<80%,"A",L23<=95%,"B",L23>95%,"C") -> #DIV/0!
D24: =C24/C$73 -> #DIV/0! | E24: =D24+E23 -> #DIV/0! | F24: =IF(AND(E24<=0),"C",IF(E24<=0.8,"A",IF(E24<=0.95,"B","C"))) -> #DIV/0! | G24: =VLOOKUP(B24:B75,I$21:M$72,5,0) -> #N/A | K24: =J24/J$73 -> #DIV/0! | L24: =K24+L23 -> #DIV/0! | M24: =_xlfn.IFS(L24<80%,"A",L24<=95%,"B",L24>95%,"C") -> #DIV/0!
D25: =C25/C$73 -> #DIV/0! | E25: =D25+E24 -> #DIV/0! | F25: =IF(AND(E25<=0),"C",IF(E25<=0.8,"A",IF(E25<=0.95,"B","C"))) -> #DIV/0! | G25: =VLOOKUP(B25:B76,I$21:M$72,5,0) -> #N/A | K25: =J25/J$73 -> #DIV/0! | L25: =K25+L24 -> #DIV/0! | M25: =_xlfn.IFS(L25<80%,"A",L25<=95%,"B",L25>95%,"C") -> #DIV/0!
D26: =C26/C$73 -> #DIV/0! | E26: =D26+E25 -> #DIV/0! | F26: =IF(AND(E26<=0),"C",IF(E26<=0.8,"A",IF(E26<=0.95,"B","C"))) -> #DIV/0! | G26: =VLOOKUP(B26:B77,I$21:M$72,5,0) -> #N/A | K26: =J26/J$73 -> #DIV/0! | L26: =K26+L25 -> #DIV/0! | M26: =_xlfn.IFS(L26<80%,"A",L26<=95%,"B",L26>95%,"C") -> #DIV/0!
D27: =C27/C$73 -> #DIV/0! | E27: =D27+E26 -> #DIV/0! | F27: =IF(AND(E27<=0),"C",IF(E27<=0.8,"A",IF(E27<=0.95,"B","C"))) -> #DIV/0! | G27: =VLOOKUP(B27:B78,I$21:M$72,5,0) -> #N/A | K27: =J27/J$73 -> #DIV/0! | L27: =K27+L26 -> #DIV/0! | M27: =_xlfn.IFS(L27<80%,"A",L27<=95%,"B",L27>95%,"C") -> #DIV/0!
D28: =C28/C$73 -> #DIV/0! | E28: =D28+E27 -> #DIV/0! | F28: =IF(AND(E28<=0),"C",IF(E28<=0.8,"A",IF(E28<=0.95,"B","C"))) -> #DIV/0! | G28: =VLOOKUP(B28:B79,I$21:M$72,5,0) -> #N/A | K28: =J28/J$73 -> #DIV/0! | L28: =K28+L27 -> #DIV/0! | M28: =_xlfn.IFS(L28<80%,"A",L28<=95%,"B",L28>95%,"C") -> #DIV/0!
D29: =C29/C$73 -> #DIV/0! | E29: =D29+E28 -> #DIV/0! | F29: =IF(AND(E29<=0),"C",IF(E29<=0.8,"A",IF(E29<=0.95,"B","C"))) -> #DIV/0! | G29: =VLOOKUP(B29:B80,I$21:M$72,5,0) -> #N/A | K29: =J29/J$73 -> #DIV/0! | L29: =K29+L28 -> #DIV/0! | M29: =_xlfn.IFS(L29<80%,"A",L29<=95%,"B",L29>95%,"C") -> #DIV/0!
D30: =C30/C$73 -> #DIV/0! | E30: =D30+E29 -> #DIV/0! | F30: =IF(AND(E30<=0),"C",IF(E30<=0.8,"A",IF(E30<=0.95,"B","C"))) -> #DIV/0! | G30: =VLOOKUP(B30:B81,I$21:M$72,5,0) -> #N/A | K30: =J30/J$73 -> #DIV/0! | L30: =K30+L29 -> #DIV/0! | M30: =_xlfn.IFS(L30<80%,"A",L30<=95%,"B",L30>95%,"C") -> #DIV/0!
D31: =C31/C$73 -> #DIV/0! | E31: =D31+E30 -> #DIV/0! | F31: =IF(AND(E31<=0),"C",IF(E31<=0.8,"A",IF(E31<=0.95,"B","C"))) -> #DIV/0! | G31: =VLOOKUP(B31:B82,I$21:M$72,5,0) -> #N/A | K31: =J31/J$73 -> #DIV/0! | L31: =K31+L30 -> #DIV/0! | M31: =_xlfn.IFS(L31<80%,"A",L31<=95%,"B",L31>95%,"C") -> #DIV/0!
D32: =C32/C$73 -> #DIV/0! | E32: =D32+E31 -> #DIV/0! | F32: =IF(AND(E32<=0),"C",IF(E32<=0.8,"A",IF(E32<=0.95,"B","C"))) -> #DIV/0! | G32: =VLOOKUP(B32:B83,I$21:M$72,5,0) -> #N/A | K32: =J32/J$73 -> #DIV/0! | L32: =K32+L31 -> #DIV/0! | M32: =_xlfn.IFS(L32<80%,"A",L32<=95%,"B",L32>95%,"C") -> #DIV/0!
D33: =C33/C$73 -> #DIV/0! | E33: =D33+E32 -> #DIV/0! | F33: =IF(AND(E33<=0),"C",IF(E33<=0.8,"A",IF(E33<=0.95,"B","C"))) -> #DIV/0! | G33: =VLOOKUP(B33:B84,I$21:M$72,5,0) -> #N/A | K33: =J33/J$73 -> #DIV/0! | L33: =K33+L32 -> #DIV/0! | M33: =_xlfn.IFS(L33<80%,"A",L33<=95%,"B",L33>95%,"C") -> #DIV/0!
... D72: =C72/C$73 -> #DIV/0! | E72: =D72+E71 -> #DIV/0! | F72: =IF(AND(E72<=0),"C",IF(E72<=0.8,"A",IF(E72<=0.95,"B","C"))) -> #DIV/0! | G72: =VLOOKUP(B72:B123,I$21:M$72,5,0) -> #N/A | K72: =J72/J$73 -> #DIV/0! | L72: =K72+L71 -> #DIV/0! | M72: =_xlfn.IFS(L72<80%,"A",L72<=95%,"B",L72>95%,"C") -> #DIV/0!
C73: =SUM(C21:C72) -> 0 | D73: =SUM(D21:D72) -> #DIV/0! | J73: =SUM(J21:J72) -> 0 | K73: =SUM(K21:K72) -> #DIV/0!

Sheet АВС 5
B2: ОЧКИ
C3: Прибыль | D3: % прибыль | E3: Доля | F3: ABC прибыль | G3: ABC кол-во | J3: Кол-во | K3: % кол-во | L3: Доля | M3: ABC кол-во
B4: flip желтые Сул | C4: ='Юнит 5'!AL8 -> 2045.1121 | D4: =C4/C$17 -> 0.29004955 | E4: =D4 -> 0.29004955 | F4: =IF(AND(E4<=0),"C",IF(E4<=0.8,"A",IF(E4<=0.95,"B","C"))) -> A | G4: =VLOOKUP(B$4:B$16,I$4:M$16,5,0) -> A | I4: Черные с железкой Сул | J4: ='Юнит 5'!S3 -> 19 | K4: =J4/J$17 -> 0.27536232 | L4: =K4 -> 0.27536232 | M4: =_xlfn.IFS(L4<80%,"A",L4<=95%,"B",L4>95%,"C") -> A | P4: A | Q4: 0.8
B5: Черные с железкой Сул | C5: ='Юнит 5'!AL3 -> 1813.3318 | D5: =C5/C$17 -> 0.25717714 | E5: =E4+D5 -> 0.54722669 | F5: =IF(AND(E5<=0),"C",IF(E5<=0.8,"A",IF(E5<=0.95,"B","C"))) -> A | G5: =VLOOKUP(B$4:B$16,I$4:M$16,5,0) -> A | I5: flip желтые Сул | J5: ='Юнит 5'!S8 -> 14 | K5: =J5/J$17 -> 0.20289855 | L5: =L4+K5 -> 0.47826087 | M5: =_xlfn.IFS(L5<80%,"A",L5<=95%,"B",L5>95%,"C") -> A | P5: B | Q5: 0.15
B6: Qs желт Сул | C6: ='Юнит 5'!AL6 -> 1154.6045 | D6: =C6/C$17 -> 0.16375265 | E6: =E5+D6 -> 0.71097934 | F6: =IF(AND(E6<=0),"C",IF(E6<=0.8,"A",IF(E6<=0.95,"B","C"))) -> A | G6: =VLOOKUP(B$4:B$16,I$4:M$16,5,0) -> B | I6: MR8854 C2 Сул | J6: ='Юнит 5'!S9 -> 11 | K6: =J6/J$17 -> 0.15942029 | L6: =L5+K6 -> 0.63768116 | M6: =_xlfn.IFS(L6<80%,"A",L6<=95%,"B",L6>95%,"C") -> A | P6: C | Q6: 0.05
B7: MR Р1886 черн | C7: ='Юнит 5'!AL14 -> 826.78813 | D7: =C7/C$17 -> 0.11725985 | E7: =E6+D7 -> 0.82823919 | F7: =IF(AND(E7<=0),"C",IF(E7<=0.8,"A",IF(E7<=0.95,"B","C"))) -> B | G7: =VLOOKUP(B$4:B$16,I$4:M$16,5,0) -> C | I7: Qs черн Сул | J7: ='Юнит 5'!S4 -> 10 | K7: =J7/J$17 -> 0.14492754 | L7: =L6+K7 -> 0.7826087 | M7: =_xlfn.IFS(L7<80%,"A",L7<=95%,"B",L7>95%,"C") -> A
B8: MR Р1874 черн | C8: ='Юнит 5'!AL12 -> 783.16961 | D8: =C8/C$17 -> 0.11107362 | E8: =E7+D8 -> 0.93931281 | F8: =IF(AND(E8<=0),"C",IF(E8<=0.8,"A",IF(E8<=0.95,"B","C"))) -> B | G8: =VLOOKUP(B$4:B$16,I$4:M$16,5,0) -> B | I8: Qs син Сул | J8: ='Юнит 5'!S5 -> 3 | K8: =J8/J$17 -> 0.043478261 | L8: =L7+K8 -> 0.82608696 | M8: =_xlfn.IFS(L8<80%,"A",L8<=95%,"B",L8>95%,"C") -> B
B9: MR 1819 корич | C9: ='Юнит 5'!AL11 -> 758.76739 | D9: =C9/C$17 -> 0.10761275 | E9: =E8+D9 -> 1.0469256 | F9: =IF(AND(E9<=0),"C",IF(E9<=0.8,"A",IF(E9<=0.95,"B","C"))) -> C | G9: =VLOOKUP(B$4:B$16,I$4:M$16,5,0) -> B | I9: Qs желт Сул | J9: ='Юнит 5'!S6 -> 3 | K9: =J9/J$17 -> 0.043478261 | L9: =L8+K9 -> 0.86956522 | M9: =_xlfn.IFS(L9<80%,"A",L9<=95%,"B",L9>95%,"C") -> B
B10: MR Р1874 корич | C10: ='Юнит 5'!AL13 -> 508.76629 | D10: =C10/C$17 -> 0.072156161 | E10: =E9+D10 -> 1.1190817 | F10: =IF(AND(E10<=0),"C",IF(E10<=0.8,"A",IF(E10<=0.95,"B","C"))) -> C | G10: =VLOOKUP(B$4:B$16,I$4:M$16,5,0) -> C | I10: MR 1819 корич | J10: ='Юнит 5'!S11 -> 2 | K10: =J10/J$17 -> 0.028985507 | L10: =L9+K10 -> 0.89855072 | M10: =_xlfn.IFS(L10<80%,"A",L10<=95%,"B",L10>95%,"C") -> B
B11: MR 1819 черн | C11: ='Юнит 5'!AL10 -> 398.95943 | D11: =C11/C$17 -> 0.05658272 | E11: =E10+D11 -> 1.1756644 | F11: =IF(AND(E11<=0),"C",IF(E11<=0.8,"A",IF(E11<=0.95,"B","C"))) -> C | G11: =VLOOKUP(B$4:B$16,I$4:M$16,5,0) -> C | I11: MR Р1874 черн | J11: ='Юнит 5'!S12 -> 2 | K11: =J11/J$17 -> 0.028985507 | L11: =L10+K11 -> 0.92753623 | M11: =_xlfn.IFS(L11<80%,"A",L11<=95%,"B",L11>95%,"C") -> B
B12: MR8854 C2 Сул | C12: ='Юнит 5'!AL9 -> 297.0268 | D12: =C12/C$17 -> 0.042126049 | E12: =E11+D12 -> 1.2177905 | F12: =IF(AND(E12<=0),"C",IF(E12<=0.8,"A",IF(E12<=0.95,"B","C"))) -> C | G12: =VLOOKUP(B$4:B$16,I$4:M$16,5,0) -> A | I12: MR Р1886 черн | J12: ='Юнит 5'!S14 -> 2 | K12: =J12/J$17 -> 0.028985507 | L12: =L11+K12 -> 0.95652174 | M12: =_xlfn.IFS(L12<80%,"A",L12<=95%,"B",L12>95%,"C") -> C
B13: Qs черн Сул | C13: ='Юнит 5'!AL4 -> 177.70464 | D13: =C13/C$17 -> 0.025203094 | E13: =E12+D13 -> 1.2429936 | F13: =IF(AND(E13<=0),"C",IF(E13<=0.8,"A",IF(E13<=0.95,"B","C"))) -> C | G13: =VLOOKUP(B$4:B$16,I$4:M$16,5,0) -> A | I13: flip черные Сул | J13: ='Юнит 5'!S7 -> 1 | K13: =J13/J$17 -> 0.014492754 | L13: =L12+K13 -> 0.97101449 | M13: =_xlfn.IFS(L13<80%,"A",L13<=95%,"B",L13>95%,"C") -> C
B14: MR Р1886 корич | C14: ='Юнит 5'!AL15 -> -22.030753 | D14: =C14/C$17 -> -0.003124528 | E14: =E13+D14 -> 1.2398691 | F14: =IF(AND(E14<=0),"C",IF(E14<=0.8,"A",IF(E14<=0.95,"B","C"))) -> C | G14: =VLOOKUP(B$4:B$16,I$4:M$16,5,0) -> C | I14: MR 1819 черн | J14: ='Юнит 5'!S10 -> 1 | K14: =J14/J$17 -> 0.014492754 | L14: =L13+K14 -> 0.98550725 | M14: =_xlfn.IFS(L14<80%,"A",L14<=95%,"B",L14>95%,"C") -> C
B15: flip черные Сул | C15: ='Юнит 5'!AL7 -> -773.48176 | D15: =C15/C$17 -> -0.10969963 | E15: =E14+D15 -> 1.1301694 | F15: =IF(AND(E15<=0),"C",IF(E15<=0.8,"A",IF(E15<=0.95,"B","C"))) -> C | G15: =VLOOKUP(B$4:B$16,I$4:M$16,5,0) -> C | I15: MR Р1874 корич | J15: ='Юнит 5'!S13 -> 1 | K15: =J15/J$17 -> 0.014492754 | L15: =L14+K15 -> 1 | M15: =_xlfn.IFS(L15<80%,"A",L15<=95%,"B",L15>95%,"C") -> C
B16: Qs син Сул | C16: ='Юнит 5'!AL5 -> -917.81235 | D16: =C16/C$17 -> -0.13016942 | E16: =E15+D16 -> 1 | F16: =IF(AND(E16<=0),"C",IF(E16<=0.8,"A",IF(E16<=0.95,"B","C"))) -> C | G16: =VLOOKUP(B$4:B$16,I$4:M$16,5,0) -> B | I16: MR Р1886 корич | J16: ='Юнит 5'!S15 -> 0 | K16: =J16/J$17 -> 0 | L16: =L15+K16 -> 1 | M16: =_xlfn.IFS(L16<80%,"A",L16<=95%,"B",L16>95%,"C") -> C
C17: =SUM(C4:C16) -> 7050.9058 | D17: =SUM(D4:D16) -> 1 | J17: =SUM(J4:J16) -> 69 | K17: =SUM(K4:K16) -> 1
C20: Прибыль | D20: % прибыль | E20: Доля | F20: ABC прибыль | G20: ABC кол-во | J20: Кол-во | K20: % кол-во | L20: Доля | M20: ABC кол-во
D21: =C21/C$73 -> #DIV/0! | E21: =D21 -> #DIV/0! | F21: =IF(AND(E21<=0),"C",IF(E21<=0.8,"A",IF(E21<=0.95,"B","C"))) -> #DIV/0! | G21: =VLOOKUP(B21:B72,I$21:M$72,5,0) -> #N/A | K21: =J21/J$73 -> #DIV/0! | L21: =K21 -> #DIV/0! | M21: =_xlfn.IFS(L21<80%,"A",L21<=95%,"B",L21>95%,"C") -> #DIV/0!
D22: =C22/C$73 -> #DIV/0! | E22: =D22+E21 -> #DIV/0! | F22: =IF(AND(E22<=0),"C",IF(E22<=0.8,"A",IF(E22<=0.95,"B","C"))) -> #DIV/0! | G22: =VLOOKUP(B22:B73,I$21:M$72,5,0) -> #N/A | K22: =J22/J$73 -> #DIV/0! | L22: =K22+L21 -> #DIV/0! | M22: =_xlfn.IFS(L22<80%,"A",L22<=95%,"B",L22>95%,"C") -> #DIV/0!
D23: =C23/C$73 -> #DIV/0! | E23: =D23+E22 -> #DIV/0! | F23: =IF(AND(E23<=0),"C",IF(E23<=0.8,"A",IF(E23<=0.95,"B","C"))) -> #DIV/0! | G23: =VLOOKUP(B23:B74,I$21:M$72,5,0) -> #N/A | K23: =J23/J$73 -> #DIV/0! | L23: =K23+L22 -> #DIV/0! | M23: =_xlfn.IFS(L23<80%,"A",L23<=95%,"B",L23>95%,"C") -> #DIV/0!
D24: =C24/C$73 -> #DIV/0! | E24: =D24+E23 -> #DIV/0! | F24: =IF(AND(E24<=0),"C",IF(E24<=0.8,"A",IF(E24<=0.95,"B","C"))) -> #DIV/0! | G24: =VLOOKUP(B24:B75,I$21:M$72,5,0) -> #N/A | K24: =J24/J$73 -> #DIV/0! | L24: =K24+L23 -> #DIV/0! | M24: =_xlfn.IFS(L24<80%,"A",L24<=95%,"B",L24>95%,"C") -> #DIV/0!
D25: =C25/C$73 -> #DIV/0! | E25: =D25+E24 -> #DIV/0! | F25: =IF(AND(E25<=0),"C",IF(E25<=0.8,"A",IF(E25<=0.95,"B","C"))) -> #DIV/0! | G25: =VLOOKUP(B25:B76,I$21:M$72,5,0) -> #N/A | K25: =J25/J$73 -> #DIV/0! | L25: =K25+L24 -> #DIV/0! | M25: =_xlfn.IFS(L25<80%,"A",L25<=95%,"B",L25>95%,"C") -> #DIV/0!
D26: =C26/C$73 -> #DIV/0! | E26: =D26+E25 -> #DIV/0! | F26: =IF(AND(E26<=0),"C",IF(E26<=0.8,"A",IF(E26<=0.95,"B","C"))) -> #DIV/0! | G26: =VLOOKUP(B26:B77,I$21:M$72,5,0) -> #N/A | K26: =J26/J$73 -> #DIV/0! | L26: =K26+L25 -> #DIV/0! | M26: =_xlfn.IFS(L26<80%,"A",L26<=95%,"B",L26>95%,"C") -> #DIV/0!
D27: =C27/C$73 -> #DIV/0! | E27: =D27+E26 -> #DIV/0! | F27: =IF(AND(E27<=0),"C",IF(E27<=0.8,"A",IF(E27<=0.95,"B","C"))) -> #DIV/0! | G27: =VLOOKUP(B27:B78,I$21:M$72,5,0) -> #N/A | K27: =J27/J$73 -> #DIV/0! | L27: =K27+L26 -> #DIV/0! | M27: =_xlfn.IFS(L27<80%,"A",L27<=95%,"B",L27>95%,"C") -> #DIV/0!
D28: =C28/C$73 -> #DIV/0! | E28: =D28+E27 -> #DIV/0! | F28: =IF(AND(E28<=0),"C",IF(E28<=0.8,"A",IF(E28<=0.95,"B","C"))) -> #DIV/0! | G28: =VLOOKUP(B28:B79,I$21:M$72,5,0) -> #N/A | K28: =J28/J$73 -> #DIV/0! | L28: =K28+L27 -> #DIV/0! | M28: =_xlfn.IFS(L28<80%,"A",L28<=95%,"B",L28>95%,"C") -> #DIV/0!
D29: =C29/C$73 -> #DIV/0! | E29: =D29+E28 -> #DIV/0! | F29: =IF(AND(E29<=0),"C",IF(E29<=0.8,"A",IF(E29<=0.95,"B","C"))) -> #DIV/0! | G29: =VLOOKUP(B29:B80,I$21:M$72,5,0) -> #N/A | K29: =J29/J$73 -> #DIV/0! | L29: =K29+L28 -> #DIV/0! | M29: =_xlfn.IFS(L29<80%,"A",L29<=95%,"B",L29>95%,"C") -> #DIV/0!
D30: =C30/C$73 -> #DIV/0! | E30: =D30+E29 -> #DIV/0! | F30: =IF(AND(E30<=0),"C",IF(E30<=0.8,"A",IF(E30<=0.95,"B","C"))) -> #DIV/0! | G30: =VLOOKUP(B30:B81,I$21:M$72,5,0) -> #N/A | K30: =J30/J$73 -> #DIV/0! | L30: =K30+L29 -> #DIV/0! | M30: =_xlfn.IFS(L30<80%,"A",L30<=95%,"B",L30>95%,"C") -> #DIV/0!
D31: =C31/C$73 -> #DIV/0! | E31: =D31+E30 -> #DIV/0! | F31: =IF(AND(E31<=0),"C",IF(E31<=0.8,"A",IF(E31<=0.95,"B","C"))) -> #DIV/0! | G31: =VLOOKUP(B31:B82,I$21:M$72,5,0) -> #N/A | K31: =J31/J$73 -> #DIV/0! | L31: =K31+L30 -> #DIV/0! | M31: =_xlfn.IFS(L31<80%,"A",L31<=95%,"B",L31>95%,"C") -> #DIV/0!
D32: =C32/C$73 -> #DIV/0! | E32: =D32+E31 -> #DIV/0! | F32: =IF(AND(E32<=0),"C",IF(E32<=0.8,"A",IF(E32<=0.95,"B","C"))) -> #DIV/0! | G32: =VLOOKUP(B32:B83,I$21:M$72,5,0) -> #N/A | K32: =J32/J$73 -> #DIV/0! | L32: =K32+L31 -> #DIV/0! | M32: =_xlfn.IFS(L32<80%,"A",L32<=95%,"B",L32>95%,"C") -> #DIV/0!
D33: =C33/C$73 -> #DIV/0! | E33: =D33+E32 -> #DIV/0! | F33: =IF(AND(E33<=0),"C",IF(E33<=0.8,"A",IF(E33<=0.95,"B","C"))) -> #DIV/0! | G33: =VLOOKUP(B33:B84,I$21:M$72,5,0) -> #N/A | K33: =J33/J$73 -> #DIV/0! | L33: =K33+L32 -> #DIV/0! | M33: =_xlfn.IFS(L33<80%,"A",L33<=95%,"B",L33>95%,"C") -> #DIV/0!
... D72: =C72/C$73 -> #DIV/0! | E72: =D72+E71 -> #DIV/0! | F72: =IF(AND(E72<=0),"C",IF(E72<=0.8,"A",IF(E72<=0.95,"B","C"))) -> #DIV/0! | G72: =VLOOKUP(B72:B123,I$21:M$72,5,0) -> #N/A | K72: =J72/J$73 -> #DIV/0! | L72: =K72+L71 -> #DIV/0! | M72: =_xlfn.IFS(L72<80%,"A",L72<=95%,"B",L72>95%,"C") -> #DIV/0!
C73: =SUM(C21:C72) -> 0 | D73: =SUM(D21:D72) -> #DIV/0! | J73: =SUM(J21:J72) -> 0 | K73: =SUM(K21:K72) -> #DIV/0!

Sheet АВС 4
B2: ОЧКИ
C3: Прибыль | D3: % прибыль | E3: Доля | F3: ABC прибыль | G3: ABC кол-во | J3: Кол-во | K3: % кол-во | L3: Доля | M3: ABC кол-во
B4: Черные с железкой Сул | C4: ='Юнит 4'!AL3 -> 5677.8442 | D4: =C4/C$17 -> 0.415248 | E4: =D4 -> 0.415248 | F4: =IF(AND(E4<=0),"C",IF(E4<=0.8,"A",IF(E4<=0.95,"B","C"))) -> A | G4: =VLOOKUP(B$4:B$16,I$4:M$16,5,0) -> A | I4: Черные с железкой Сул | J4: ='Юнит 4'!S3 -> 21 | K4: =J4/J$17 -> 0.44680851 | L4: =K4 -> 0.44680851 | M4: =_xlfn.IFS(L4<80%,"A",L4<=95%,"B",L4>95%,"C") -> A | P4: A | Q4: 0.8
B5: flip желтые Сул | C5: ='Юнит 4'!AL8 -> 5497.2061 | D5: =C5/C$17 -> 0.40203707 | E5: =E4+D5 -> 0.81728507 | F5: =IF(AND(E5<=0),"C",IF(E5<=0.8,"A",IF(E5<=0.95,"B","C"))) -> B | G5: =VLOOKUP(B$4:B$16,I$4:M$16,5,0) -> A | I5: flip желтые Сул | J5: ='Юнит 4'!S8 -> 10 | K5: =J5/J$17 -> 0.21276596 | L5: =L4+K5 -> 0.65957447 | M5: =_xlfn.IFS(L5<80%,"A",L5<=95%,"B",L5>95%,"C") -> A | P5: B | Q5: 0.15
B6: Qs желт Сул | C6: ='Юнит 4'!AL6 -> 1821.9753 | D6: =C6/C$17 -> 0.1332498 | E6: =E5+D6 -> 0.95053487 | F6: =IF(AND(E6<=0),"C",IF(E6<=0.8,"A",IF(E6<=0.95,"B","C"))) -> C | G6: =VLOOKUP(B$4:B$16,I$4:M$16,5,0) -> B | I6: MR8854 C2 Сул | J6: ='Юнит 4'!S9 -> 9 | K6: =J6/J$17 -> 0.19148936 | L6: =L5+K6 -> 0.85106383 | M6: =_xlfn.IFS(L6<80%,"A",L6<=95%,"B",L6>95%,"C") -> B | P6: C | Q6: 0.05
B7: MR8854 C2 Сул | C7: ='Юнит 4'!AL9 -> 814.75132 | D7: =C7/C$17 -> 0.059586675 | E7: =E6+D7 -> 1.0101215 | F7: =IF(AND(E7<=0),"C",IF(E7<=0.8,"A",IF(E7<=0.95,"B","C"))) -> C | G7: =VLOOKUP(B$4:B$16,I$4:M$16,5,0) -> B | I7: Qs желт Сул | J7: ='Юнит 4'!S6 -> 4 | K7: =J7/J$17 -> 0.085106383 | L7: =L6+K7 -> 0.93617021 | M7: =_xlfn.IFS(L7<80%,"A",L7<=95%,"B",L7>95%,"C") -> B
B8: MR Р1886 корич | C8: ='Юнит 4'!AL15 -> 550.12526 | D8: =C8/C$17 -> 0.040233301 | E8: =E7+D8 -> 1.0503548 | F8: =IF(AND(E8<=0),"C",IF(E8<=0.8,"A",IF(E8<=0.95,"B","C"))) -> C | G8: =VLOOKUP(B$4:B$16,I$4:M$16,5,0) -> C | I8: MR Р1874 черн | J8: ='Юнит 4'!S12 -> 1 | K8: =J8/J$17 -> 0.021276596 | L8: =L7+K8 -> 0.95744681 | M8: =_xlfn.IFS(L8<80%,"A",L8<=95%,"B",L8>95%,"C") -> C
B9: MR Р1874 черн | C9: ='Юнит 4'!AL12 -> 373.65885 | D9: =C9/C$17 -> 0.027327466 | E9: =E8+D9 -> 1.0776823 | F9: =IF(AND(E9<=0),"C",IF(E9<=0.8,"A",IF(E9<=0.95,"B","C"))) -> C | G9: =VLOOKUP(B$4:B$16,I$4:M$16,5,0) -> C | I9: MR Р1874 корич | J9: ='Юнит 4'!S13 -> 1 | K9: =J9/J$17 -> 0.021276596 | L9: =L8+K9 -> 0.9787234 | M9: =_xlfn.IFS(L9<80%,"A",L9<=95%,"B",L9>95%,"C") -> C
B10: MR Р1874 корич | C10: ='Юнит 4'!AL13 -> 292.29359 | D10: =C10/C$17 -> 0.021376833 | E10: =E9+D10 -> 1.0990591 | F10: =IF(AND(E10<=0),"C",IF(E10<=0.8,"A",IF(E10<=0.95,"B","C"))) -> C | G10: =VLOOKUP(B$4:B$16,I$4:M$16,5,0) -> C | I10: MR Р1886 корич | J10: ='Юнит 4'!S15 -> 1 | K10: =J10/J$17 -> 0.021276596 | L10: =L9+K10 -> 1 | M10: =_xlfn.IFS(L10<80%,"A",L10<=95%,"B",L10>95%,"C") -> C
B11: MR 1819 корич | C11: ='Юнит 4'!AL11 -> -24.942493 | D11: =C11/C$17 -> -0.0018241643 | E11: =E10+D11 -> 1.097235 | F11: =IF(AND(E11<=0),"C",IF(E11<=0.8,"A",IF(E11<=0.95,"B","C"))) -> C | G11: =VLOOKUP(B$4:B$16,I$4:M$16,5,0) -> C | I11: Qs черн Сул | J11: ='Юнит 4'!S4 -> 0 | K11: =J11/J$17 -> 0 | L11: =L10+K11 -> 1 | M11: =_xlfn.IFS(L11<80%,"A",L11<=95%,"B",L11>95%,"C") -> C
B12: MR Р1886 черн | C12: ='Юнит 4'!AL14 -> -37.733516 | D12: =C12/C$17 -> -0.0027596331 | E12: =E11+D12 -> 1.0944753 | F12: =IF(AND(E12<=0),"C",IF(E12<=0.8,"A",IF(E12<=0.95,"B","C"))) -> C | G12: =VLOOKUP(B$4:B$16,I$4:M$16,5,0) -> C | I12: Qs син Сул | J12: ='Юнит 4'!S5 -> 0 | K12: =J12/J$17 -> 0 | L12: =L11+K12 -> 1 | M12: =_xlfn.IFS(L12<80%,"A",L12<=95%,"B",L12>95%,"C") -> C
B13: MR 1819 черн | C13: ='Юнит 4'!AL10 -> -121.34249 | D13: =C13/C$17 -> -0.008874359 | E13: =E12+D13 -> 1.085601 | F13: =IF(AND(E13<=0),"C",IF(E13<=0.8,"A",IF(E13<=0.95,"B","C"))) -> C | G13: =VLOOKUP(B$4:B$16,I$4:M$16,5,0) -> C | I13: flip черные Сул | J13: ='Юнит 4'!S7 -> 0 | K13: =J13/J$17 -> 0 | L13: =L12+K13 -> 1 | M13: =_xlfn.IFS(L13<80%,"A",L13<=95%,"B",L13>95%,"C") -> C
B14: Qs черн Сул | C14: ='Юнит 4'!AL4 -> -294.91162 | D14: =C14/C$17 -> -0.021568302 | E14: =E13+D14 -> 1.0640327 | F14: =IF(AND(E14<=0),"C",IF(E14<=0.8,"A",IF(E14<=0.95,"B","C"))) -> C | G14: =VLOOKUP(B$4:B$16,I$4:M$16,5,0) -> C | I14: MR 1819 черн | J14: ='Юнит 4'!S10 -> 0 | K14: =J14/J$17 -> 0 | L14: =L13+K14 -> 1 | M14: =_xlfn.IFS(L14<80%,"A",L14<=95%,"B",L14>95%,"C") -> C
B15: Qs син Сул | C15: ='Юнит 4'!AL5 -> -383.11077 | D15: =C15/C$17 -> -0.028018729 | E15: =E14+D15 -> 1.036014 | F15: =IF(AND(E15<=0),"C",IF(E15<=0.8,"A",IF(E15<=0.95,"B","C"))) -> C | G15: =VLOOKUP(B$4:B$16,I$4:M$16,5,0) -> C | I15: MR 1819 корич | J15: ='Юнит 4'!S11 -> 0 | K15: =J15/J$17 -> 0 | L15: =L14+K15 -> 1 | M15: =_xlfn.IFS(L15<80%,"A",L15<=95%,"B",L15>95%,"C") -> C
B16: flip черные Сул | C16: ='Юнит 4'!AL7 -> -492.43252 | D16: =C16/C$17 -> -0.036013954 | E16: =E15+D16 -> 1 | F16: =IF(AND(E16<=0),"C",IF(E16<=0.8,"A",IF(E16<=0.95,"B","C"))) -> C | G16: =VLOOKUP(B$4:B$16,I$4:M$16,5,0) -> C | I16: MR Р1886 черн | J16: ='Юнит 4'!S14 -> 0 | K16: =J16/J$17 -> 0 | L16: =L15+K16 -> 1 | M16: =_xlfn.IFS(L16<80%,"A",L16<=95%,"B",L16>95%,"C") -> C
C17: =SUM(C4:C16) -> 13673.381 | D17: =SUM(D4:D16) -> 1 | J17: =SUM(J4:J16) -> 47 | K17: =SUM(K4:K16) -> 1
C20: Прибыль | D20: % прибыль | E20: Доля | F20: ABC прибыль | G20: ABC кол-во | J20: Кол-во | K20: % кол-во | L20: Доля | M20: ABC кол-во
D21: =C21/C$73 -> #DIV/0! | E21: =D21 -> #DIV/0! | F21: =IF(AND(E21<=0),"C",IF(E21<=0.8,"A",IF(E21<=0.95,"B","C"))) -> #DIV/0! | G21: =VLOOKUP(B21:B72,I$21:M$72,5,0) -> #N/A | K21: =J21/J$73 -> #DIV/0! | L21: =K21 -> #DIV/0! | M21: =_xlfn.IFS(L21<80%,"A",L21<=95%,"B",L21>95%,"C") -> #DIV/0!
D22: =C22/C$73 -> #DIV/0! | E22: =D22+E21 -> #DIV/0! | F22: =IF(AND(E22<=0),"C",IF(E22<=0.8,"A",IF(E22<=0.95,"B","C"))) -> #DIV/0! | G22: =VLOOKUP(B22:B73,I$21:M$72,5,0) -> #N/A | K22: =J22/J$73 -> #DIV/0! | L22: =K22+L21 -> #DIV/0! | M22: =_xlfn.IFS(L22<80%,"A",L22<=95%,"B",L22>95%,"C") -> #DIV/0!
D23: =C23/C$73 -> #DIV/0! | E23: =D23+E22 -> #DIV/0! | F23: =IF(AND(E23<=0),"C",IF(E23<=0.8,"A",IF(E23<=0.95,"B","C"))) -> #DIV/0! | G23: =VLOOKUP(B23:B74,I$21:M$72,5,0) -> #N/A | K23: =J23/J$73 -> #DIV/0! | L23: =K23+L22 -> #DIV/0! | M23: =_xlfn.IFS(L23<80%,"A",L23<=95%,"B",L23>95%,"C") -> #DIV/0!
D24: =C24/C$73 -> #DIV/0! | E24: =D24+E23 -> #DIV/0! | F24: =IF(AND(E24<=0),"C",IF(E24<=0.8,"A",IF(E24<=0.95,"B","C"))) -> #DIV/0! | G24: =VLOOKUP(B24:B75,I$21:M$72,5,0) -> #N/A | K24: =J24/J$73 -> #DIV/0! | L24: =K24+L23 -> #DIV/0! | M24: =_xlfn.IFS(L24<80%,"A",L24<=95%,"B",L24>95%,"C") -> #DIV/0!
D25: =C25/C$73 -> #DIV/0! | E25: =D25+E24 -> #DIV/0! | F25: =IF(AND(E25<=0),"C",IF(E25<=0.8,"A",IF(E25<=0.95,"B","C"))) -> #DIV/0! | G25: =VLOOKUP(B25:B76,I$21:M$72,5,0) -> #N/A | K25: =J25/J$73 -> #DIV/0! | L25: =K25+L24 -> #DIV/0! | M25: =_xlfn.IFS(L25<80%,"A",L25<=95%,"B",L25>95%,"C") -> #DIV/0!
D26: =C26/C$73 -> #DIV/0! | E26: =D26+E25 -> #DIV/0! | F26: =IF(AND(E26<=0),"C",IF(E26<=0.8,"A",IF(E26<=0.95,"B","C"))) -> #DIV/0! | G26: =VLOOKUP(B26:B77,I$21:M$72,5,0) -> #N/A | K26: =J26/J$73 -> #DIV/0! | L26: =K26+L25 -> #DIV/0! | M26: =_xlfn.IFS(L26<80%,"A",L26<=95%,"B",L26>95%,"C") -> #DIV/0!
D27: =C27/C$73 -> #DIV/0! | E27: =D27+E26 -> #DIV/0! | F27: =IF(AND(E27<=0),"C",IF(E27<=0.8,"A",IF(E27<=0.95,"B","C"))) -> #DIV/0! | G27: =VLOOKUP(B27:B78,I$21:M$72,5,0) -> #N/A | K27: =J27/J$73 -> #DIV/0! | L27: =K27+L26 -> #DIV/0! | M27: =_xlfn.IFS(L27<80%,"A",L27<=95%,"B",L27>95%,"C") -> #DIV/0!
D28: =C28/C$73 -> #DIV/0! | E28: =D28+E27 -> #DIV/0! | F28: =IF(AND(E28<=0),"C",IF(E28<=0.8,"A",IF(E28<=0.95,"B","C"))) -> #DIV/0! | G28: =VLOOKUP(B28:B79,I$21:M$72,5,0) -> #N/A | K28: =J28/J$73 -> #DIV/0! | L28: =K28+L27 -> #DIV/0! | M28: =_xlfn.IFS(L28<80%,"A",L28<=95%,"B",L28>95%,"C") -> #DIV/0!
D29: =C29/C$73 -> #DIV/0! | E29: =D29+E28 -> #DIV/0! | F29: =IF(AND(E29<=0),"C",IF(E29<=0.8,"A",IF(E29<=0.95,"B","C"))) -> #DIV/0! | G29: =VLOOKUP(B29:B80,I$21:M$72,5,0) -> #N/A | K29: =J29/J$73 -> #DIV/0! | L29: =K29+L28 -> #DIV/0! | M29: =_xlfn.IFS(L29<80%,"A",L29<=95%,"B",L29>95%,"C") -> #DIV/0!
D30: =C30/C$73 -> #DIV/0! | E30: =D30+E29 -> #DIV/0! | F30: =IF(AND(E30<=0),"C",IF(E30<=0.8,"A",IF(E30<=0.95,"B","C"))) -> #DIV/0! | G30: =VLOOKUP(B30:B81,I$21:M$72,5,0) -> #N/A | K30: =J30/J$73 -> #DIV/0! | L30: =K30+L29 -> #DIV/0! | M30: =_xlfn.IFS(L30<80%,"A",L30<=95%,"B",L30>95%,"C") -> #DIV/0!
D31: =C31/C$73 -> #DIV/0! | E31: =D31+E30 -> #DIV/0! | F31: =IF(AND(E31<=0),"C",IF(E31<=0.8,"A",IF(E31<=0.95,"B","C"))) -> #DIV/0! | G31: =VLOOKUP(B31:B82,I$21:M$72,5,0) -> #N/A | K31: =J31/J$73 -> #DIV/0! | L31: =K31+L30 -> #DIV/0! | M31: =_xlfn.IFS(L31<80%,"A",L31<=95%,"B",L31>95%,"C") -> #DIV/0!
D32: =C32/C$73 -> #DIV/0! | E32: =D32+E31 -> #DIV/0! | F32: =IF(AND(E32<=0),"C",IF(E32<=0.8,"A",IF(E32<=0.95,"B","C"))) -> #DIV/0! | G32: =VLOOKUP(B32:B83,I$21:M$72,5,0) -> #N/A | K32: =J32/J$73 -> #DIV/0! | L32: =K32+L31 -> #DIV/0! | M32: =_xlfn.IFS(L32<80%,"A",L32<=95%,"B",L32>95%,"C") -> #DIV/0!
D33: =C33/C$73 -> #DIV/0! | E33: =D33+E32 -> #DIV/0! | F33: =IF(AND(E33<=0),"C",IF(E33<=0.8,"A",IF(E33<=0.95,"B","C"))) -> #DIV/0! | G33: =VLOOKUP(B33:B84,I$21:M$72,5,0) -> #N/A | K33: =J33/J$73 -> #DIV/0! | L33: =K33+L32 -> #DIV/0! | M33: =_xlfn.IFS(L33<80%,"A",L33<=95%,"B",L33>95%,"C") -> #DIV/0!
... D72: =C72/C$73 -> #DIV/0! | E72: =D72+E71 -> #DIV/0! | F72: =IF(AND(E72<=0),"C",IF(E72<=0.8,"A",IF(E72<=0.95,"B","C"))) -> #DIV/0! | G72: =VLOOKUP(B72:B123,I$21:M$72,5,0) -> #N/A | K72: =J72/J$73 -> #DIV/0! | L72: =K72+L71 -> #DIV/0! | M72: =_xlfn.IFS(L72<80%,"A",L72<=95%,"B",L72>95%,"C") -> #DIV/0!
C73: =SUM(C21:C72) -> 0 | D73: =SUM(D21:D72) -> #DIV/0! | J73: =SUM(J21:J72) -> 0 | K73: =SUM(K21:K72) -> #DIV/0!

Sheet АВС 3
B2: ОЧКИ
C3: Прибыль | D3: % прибыль | E3: Доля | F3: ABC прибыль | G3: ABC кол-во | J3: Кол-во | K3: % кол-во | L3: Доля | M3: ABC кол-во
B4: flip желтые Сул | C4: ='Юнит 3'!AL8 -> 9416.7452 | D4: =C4/C$17 -> 0.60135716 | E4: =D4 -> 0.60135716 | F4: =IF(AND(E4<=0),"C",IF(E4<=0.8,"A",IF(E4<=0.95,"B","C"))) -> A | G4: =VLOOKUP(B$4:B$16,I$4:M$16,5,0) -> A | I4: flip желтые Сул | J4: ='Юнит 3'!S8 -> 22 | K4: =J4/J$17 -> 0.45833333 | L4: =K4 -> 0.45833333 | M4: =_xlfn.IFS(L4<80%,"A",L4<=95%,"B",L4>95%,"C") -> A | P4: A | Q4: 0.8
B5: Черные с железкой Сул | C5: ='Юнит 3'!AL3 -> 2756.9039 | D5: =C5/C$17 -> 0.176057 | E5: =E4+D5 -> 0.77741417 | F5: =IF(AND(E5<=0),"C",IF(E5<=0.8,"A",IF(E5<=0.95,"B","C"))) -> A | G5: =VLOOKUP(B$4:B$16,I$4:M$16,5,0) -> A | I5: Черные с железкой Сул | J5: ='Юнит 3'!S3 -> 10 | K5: =J5/J$17 -> 0.20833333 | L5: =L4+K5 -> 0.66666667 | M5: =_xlfn.IFS(L5<80%,"A",L5<=95%,"B",L5>95%,"C") -> A | P5: B | Q5: 0.15
B6: Qs желт Сул | C6: ='Юнит 3'!AL6 -> 1819.1694 | D6: =C6/C$17 -> 0.1161729 | E6: =E5+D6 -> 0.89358706 | F6: =IF(AND(E6<=0),"C",IF(E6<=0.8,"A",IF(E6<=0.95,"B","C"))) -> B | G6: =VLOOKUP(B$4:B$16,I$4:M$16,5,0) -> A | I6: Qs желт Сул | J6: ='Юнит 3'!S6 -> 6 | K6: =J6/J$17 -> 0.125 | L6: =L5+K6 -> 0.79166667 | M6: =_xlfn.IFS(L6<80%,"A",L6<=95%,"B",L6>95%,"C") -> A | P6: C | Q6: 0.05
B7: MR Р1886 черн | C7: ='Юнит 3'!AL14 -> 1226.3922 | D7: =C7/C$17 -> 0.078317901 | E7: =E6+D7 -> 0.97190497 | F7: =IF(AND(E7<=0),"C",IF(E7<=0.8,"A",IF(E7<=0.95,"B","C"))) -> C | G7: =VLOOKUP(B$4:B$16,I$4:M$16,5,0) -> B | I7: MR8854 C2 Сул | J7: ='Юнит 3'!S9 -> 3 | K7: =J7/J$17 -> 0.0625 | L7: =L6+K7 -> 0.85416667 | M7: =_xlfn.IFS(L7<80%,"A",L7<=95%,"B",L7>95%,"C") -> B
B8: MR Р1886 корич | C8: ='Юнит 3'!AL15 -> 494.45817 | D8: =C8/C$17 -> 0.031576299 | E8: =E7+D8 -> 1.0034813 | F8: =IF(AND(E8<=0),"C",IF(E8<=0.8,"A",IF(E8<=0.95,"B","C"))) -> C | G8: =VLOOKUP(B$4:B$16,I$4:M$16,5,0) -> C | I8: MR Р1886 черн | J8: ='Юнит 3'!S14 -> 3 | K8: =J8/J$17 -> 0.0625 | L8: =L7+K8 -> 0.91666667 | M8: =_xlfn.IFS(L8<80%,"A",L8<=95%,"B",L8>95%,"C") -> B
B9: MR Р1874 корич | C9: ='Юнит 3'!AL13 -> 500.15133 | D9: =C9/C$17 -> 0.031939867 | E9: =E8+D9 -> 1.0354211 | F9: =IF(AND(E9<=0),"C",IF(E9<=0.8,"A",IF(E9<=0.95,"B","C"))) -> C | G9: =VLOOKUP(B$4:B$16,I$4:M$16,5,0) -> C | I9: Qs син Сул | J9: ='Юнит 3'!S5 -> 1 | K9: =J9/J$17 -> 0.020833333 | L9: =L8+K9 -> 0.9375 | M9: =_xlfn.IFS(L9<80%,"A",L9<=95%,"B",L9>95%,"C") -> B
B10: Qs син Сул | C10: ='Юнит 3'!AL5 -> 470.44553 | D10: =C10/C$17 -> 0.030042842 | E10: =E9+D10 -> 1.065464 | F10: =IF(AND(E10<=0),"C",IF(E10<=0.8,"A",IF(E10<=0.95,"B","C"))) -> C | G10: =VLOOKUP(B$4:B$16,I$4:M$16,5,0) -> B | I10: MR 1819 черн | J10: ='Юнит 3'!S10 -> 1 | K10: =J10/J$17 -> 0.020833333 | L10: =L9+K10 -> 0.95833333 | M10: =_xlfn.IFS(L10<80%,"A",L10<=95%,"B",L10>95%,"C") -> C
B11: MR 1819 черн | C11: ='Юнит 3'!AL10 -> 371.88742 | D11: =C11/C$17 -> 0.023748881 | E11: =E10+D11 -> 1.0892129 | F11: =IF(AND(E11<=0),"C",IF(E11<=0.8,"A",IF(E11<=0.95,"B","C"))) -> C | G11: =VLOOKUP(B$4:B$16,I$4:M$16,5,0) -> C | I11: MR Р1874 корич | J11: ='Юнит 3'!S13 -> 1 | K11: =J11/J$17 -> 0.020833333 | L11: =L10+K11 -> 0.97916667 | M11: =_xlfn.IFS(L11<80%,"A",L11<=95%,"B",L11>95%,"C") -> C
B12: MR 1819 корич | C12: ='Юнит 3'!AL11 -> -130.29333 | D12: =C12/C$17 -> -0.0083205849 | E12: =E11+D12 -> 1.0808923 | F12: =IF(AND(E12<=0),"C",IF(E12<=0.8,"A",IF(E12<=0.95,"B","C"))) -> C | G12: =VLOOKUP(B$4:B$16,I$4:M$16,5,0) -> C | I12: Qs черн Сул | J12: ='Юнит 3'!S4 -> 0 | K12: =J12/J$17 -> 0 | L12: =L11+K12 -> 0.97916667 | M12: =_xlfn.IFS(L12<80%,"A",L12<=95%,"B",L12>95%,"C") -> C
B13: Qs черн Сул | C13: ='Юнит 3'!AL4 -> -170.3584 | D13: =C13/C$17 -> -0.010879156 | E13: =E12+D13 -> 1.0700131 | F13: =IF(AND(E13<=0),"C",IF(E13<=0.8,"A",IF(E13<=0.95,"B","C"))) -> C | G13: =VLOOKUP(B$4:B$16,I$4:M$16,5,0) -> C | I13: flip черные Сул | J13: ='Юнит 3'!S7 -> 0 | K13: =J13/J$17 -> 0 | L13: =L12+K13 -> 0.97916667 | M13: =_xlfn.IFS(L13<80%,"A",L13<=95%,"B",L13>95%,"C") -> C
B14: MR Р1874 черн | C14: ='Юнит 3'!AL12 -> -236.5805 | D14: =C14/C$17 -> -0.015108126 | E14: =E13+D14 -> 1.054905 | F14: =IF(AND(E14<=0),"C",IF(E14<=0.8,"A",IF(E14<=0.95,"B","C"))) -> C | G14: =VLOOKUP(B$4:B$16,I$4:M$16,5,0) -> C | I14: MR 1819 корич | J14: ='Юнит 3'!S11 -> 0 | K14: =J14/J$17 -> 0 | L14: =L13+K14 -> 0.97916667 | M14: =_xlfn.IFS(L14<80%,"A",L14<=95%,"B",L14>95%,"C") -> C
B15: flip черные Сул | C15: ='Юнит 3'!AL7 -> -293.38406 | D15: =C15/C$17 -> -0.018735625 | E15: =E14+D15 -> 1.0361694 | F15: =IF(AND(E15<=0),"C",IF(E15<=0.8,"A",IF(E15<=0.95,"B","C"))) -> C | G15: =VLOOKUP(B$4:B$16,I$4:M$16,5,0) -> C | I15: MR Р1874 черн | J15: ='Юнит 3'!S12 -> 0 | K15: =J15/J$17 -> 0 | L15: =L14+K15 -> 0.97916667 | M15: =_xlfn.IFS(L15<80%,"A",L15<=95%,"B",L15>95%,"C") -> C
B16: MR8854 C2 Сул | C16: ='Юнит 3'!AL9 -> -566.38165 | D16: =C16/C$17 -> -0.036169361 | E16: =E15+D16 -> 1 | F16: =IF(AND(E16<=0),"C",IF(E16<=0.8,"A",IF(E16<=0.95,"B","C"))) -> C | G16: =VLOOKUP(B$4:B$16,I$4:M$16,5,0) -> B | I16: MR Р1886 корич | J16: ='Юнит 3'!S15 -> 1 | K16: =J16/J$17 -> 0.020833333 | L16: =L15+K16 -> 1 | M16: =_xlfn.IFS(L16<80%,"A",L16<=95%,"B",L16>95%,"C") -> C
C17: =SUM(C4:C16) -> 15659.155 | D17: =SUM(D4:D16) -> 1 | J17: =SUM(J4:J16) -> 48 | K17: =SUM(K4:K16) -> 1
C20: Прибыль | D20: % прибыль | E20: Доля | F20: ABC прибыль | G20: ABC кол-во | J20: Кол-во | K20: % кол-во | L20: Доля | M20: ABC кол-во
D21: =C21/C$73 -> #DIV/0! | E21: =D21 -> #DIV/0! | F21: =IF(AND(E21<=0),"C",IF(E21<=0.8,"A",IF(E21<=0.95,"B","C"))) -> #DIV/0! | G21: =VLOOKUP(B21:B72,I$21:M$72,5,0) -> #N/A | K21: =J21/J$73 -> #DIV/0! | L21: =K21 -> #DIV/0! | M21: =_xlfn.IFS(L21<80%,"A",L21<=95%,"B",L21>95%,"C") -> #DIV/0!
D22: =C22/C$73 -> #DIV/0! | E22: =D22+E21 -> #DIV/0! | F22: =IF(AND(E22<=0),"C",IF(E22<=0.8,"A",IF(E22<=0.95,"B","C"))) -> #DIV/0! | G22: =VLOOKUP(B22:B73,I$21:M$72,5,0) -> #N/A | K22: =J22/J$73 -> #DIV/0! | L22: =K22+L21 -> #DIV/0! | M22: =_xlfn.IFS(L22<80%,"A",L22<=95%,"B",L22>95%,"C") -> #DIV/0!
D23: =C23/C$73 -> #DIV/0! | E23: =D23+E22 -> #DIV/0! | F23: =IF(AND(E23<=0),"C",IF(E23<=0.8,"A",IF(E23<=0.95,"B","C"))) -> #DIV/0! | G23: =VLOOKUP(B23:B74,I$21:M$72,5,0) -> #N/A | K23: =J23/J$73 -> #DIV/0! | L23: =K23+L22 -> #DIV/0! | M23: =_xlfn.IFS(L23<80%,"A",L23<=95%,"B",L23>95%,"C") -> #DIV/0!
D24: =C24/C$73 -> #DIV/0! | E24: =D24+E23 -> #DIV/0! | F24: =IF(AND(E24<=0),"C",IF(E24<=0.8,"A",IF(E24<=0.95,"B","C"))) -> #DIV/0! | G24: =VLOOKUP(B24:B75,I$21:M$72,5,0) -> #N/A | K24: =J24/J$73 -> #DIV/0! | L24: =K24+L23 -> #DIV/0! | M24: =_xlfn.IFS(L24<80%,"A",L24<=95%,"B",L24>95%,"C") -> #DIV/0!
D25: =C25/C$73 -> #DIV/0! | E25: =D25+E24 -> #DIV/0! | F25: =IF(AND(E25<=0),"C",IF(E25<=0.8,"A",IF(E25<=0.95,"B","C"))) -> #DIV/0! | G25: =VLOOKUP(B25:B76,I$21:M$72,5,0) -> #N/A | K25: =J25/J$73 -> #DIV/0! | L25: =K25+L24 -> #DIV/0! | M25: =_xlfn.IFS(L25<80%,"A",L25<=95%,"B",L25>95%,"C") -> #DIV/0!
D26: =C26/C$73 -> #DIV/0! | E26: =D26+E25 -> #DIV/0! | F26: =IF(AND(E26<=0),"C",IF(E26<=0.8,"A",IF(E26<=0.95,"B","C"))) -> #DIV/0! | G26: =VLOOKUP(B26:B77,I$21:M$72,5,0) -> #N/A | K26: =J26/J$73 -> #DIV/0! | L26: =K26+L25 -> #DIV/0! | M26: =_xlfn.IFS(L26<80%,"A",L26<=95%,"B",L26>95%,"C") -> #DIV/0!
D27: =C27/C$73 -> #DIV/0! | E27: =D27+E26 -> #DIV/0! | F27: =IF(AND(E27<=0),"C",IF(E27<=0.8,"A",IF(E27<=0.95,"B","C"))) -> #DIV/0! | G27: =VLOOKUP(B27:B78,I$21:M$72,5,0) -> #N/A | K27: =J27/J$73 -> #DIV/0! | L27: =K27+L26 -> #DIV/0! | M27: =_xlfn.IFS(L27<80%,"A",L27<=95%,"B",L27>95%,"C") -> #DIV/0!
D28: =C28/C$73 -> #DIV/0! | E28: =D28+E27 -> #DIV/0! | F28: =IF(AND(E28<=0),"C",IF(E28<=0.8,"A",IF(E28<=0.95,"B","C"))) -> #DIV/0! | G28: =VLOOKUP(B28:B79,I$21:M$72,5,0) -> #N/A | K28: =J28/J$73 -> #DIV/0! | L28: =K28+L27 -> #DIV/0! | M28: =_xlfn.IFS(L28<80%,"A",L28<=95%,"B",L28>95%,"C") -> #DIV/0!
D29: =C29/C$73 -> #DIV/0! | E29: =D29+E28 -> #DIV/0! | F29: =IF(AND(E29<=0),"C",IF(E29<=0.8,"A",IF(E29<=0.95,"B","C"))) -> #DIV/0! | G29: =VLOOKUP(B29:B80,I$21:M$72,5,0) -> #N/A | K29: =J29/J$73 -> #DIV/0! | L29: =K29+L28 -> #DIV/0! | M29: =_xlfn.IFS(L29<80%,"A",L29<=95%,"B",L29>95%,"C") -> #DIV/0!
D30: =C30/C$73 -> #DIV/0! | E30: =D30+E29 -> #DIV/0! | F30: =IF(AND(E30<=0),"C",IF(E30<=0.8,"A",IF(E30<=0.95,"B","C"))) -> #DIV/0! | G30: =VLOOKUP(B30:B81,I$21:M$72,5,0) -> #N/A | K30: =J30/J$73 -> #DIV/0! | L30: =K30+L29 -> #DIV/0! | M30: =_xlfn.IFS(L30<80%,"A",L30<=95%,"B",L30>95%,"C") -> #DIV/0!
D31: =C31/C$73 -> #DIV/0! | E31: =D31+E30 -> #DIV/0! | F31: =IF(AND(E31<=0),"C",IF(E31<=0.8,"A",IF(E31<=0.95,"B","C"))) -> #DIV/0! | G31: =VLOOKUP(B31:B82,I$21:M$72,5,0) -> #N/A | K31: =J31/J$73 -> #DIV/0! | L31: =K31+L30 -> #DIV/0! | M31: =_xlfn.IFS(L31<80%,"A",L31<=95%,"B",L31>95%,"C") -> #DIV/0!
D32: =C32/C$73 -> #DIV/0! | E32: =D32+E31 -> #DIV/0! | F32: =IF(AND(E32<=0),"C",IF(E32<=0.8,"A",IF(E32<=0.95,"B","C"))) -> #DIV/0! | G32: =VLOOKUP(B32:B83,I$21:M$72,5,0) -> #N/A | K32: =J32/J$73 -> #DIV/0! | L32: =K32+L31 -> #DIV/0! | M32: =_xlfn.IFS(L32<80%,"A",L32<=95%,"B",L32>95%,"C") -> #DIV/0!
D33: =C33/C$73 -> #DIV/0! | E33: =D33+E32 -> #DIV/0! | F33: =IF(AND(E33<=0),"C",IF(E33<=0.8,"A",IF(E33<=0.95,"B","C"))) -> #DIV/0! | G33: =VLOOKUP(B33:B84,I$21:M$72,5,0) -> #N/A | K33: =J33/J$73 -> #DIV/0! | L33: =K33+L32 -> #DIV/0! | M33: =_xlfn.IFS(L33<80%,"A",L33<=95%,"B",L33>95%,"C") -> #DIV/0!
... D72: =C72/C$73 -> #DIV/0! | E72: =D72+E71 -> #DIV/0! | F72: =IF(AND(E72<=0),"C",IF(E72<=0.8,"A",IF(E72<=0.95,"B","C"))) -> #DIV/0! | G72: =VLOOKUP(B72:B123,I$21:M$72,5,0) -> #N/A | K72: =J72/J$73 -> #DIV/0! | L72: =K72+L71 -> #DIV/0! | M72: =_xlfn.IFS(L72<80%,"A",L72<=95%,"B",L72>95%,"C") -> #DIV/0!
C73: =SUM(C21:C72) -> 0 | D73: =SUM(D21:D72) -> #DIV/0! | J73: =SUM(J21:J72) -> 0 | K73: =SUM(K21:K72) -> #DIV/0!

Sheet АВС 2
B2: ОЧКИ
C3: Прибыль | D3: % прибыль | E3: Доля | F3: ABC прибыль | G3: ABC кол-во | J3: Кол-во | K3: % кол-во | L3: Доля | M3: ABC кол-во
B4: flip желтые Сул | C4: ='Юнит 2'!AL8 -> 10465.83 | D4: =C4/C$17 -> 0.79413735 | E4: =D4 -> 0.79413735 | F4: =IF(AND(E4<=0),"C",IF(E4<=0.8,"A",IF(E4<=0.95,"B","C"))) -> A | G4: =VLOOKUP(B$4:B$16,I$4:M$16,5,0) -> A | I4: flip желтые Сул | J4: ='Юнит 2'!S8 -> 26 | K4: =J4/J$17 -> 0.61904762 | L4: =K4 -> 0.61904762 | M4: =_xlfn.IFS(L4<80%,"A",L4<=95%,"B",L4>95%,"C") -> A | P4: A | Q4: 0.8
B5: Черные с железкой Сул | C5: ='Юнит 2'!AL3 -> 2587.3534 | D5: =C5/C$17 -> 0.19632594 | E5: =E4+D5 -> 0.9904633 | F5: =IF(AND(E5<=0),"C",IF(E5<=0.8,"A",IF(E5<=0.95,"B","C"))) -> C | G5: =VLOOKUP(B$4:B$16,I$4:M$16,5,0) -> B | I5: Черные с железкой Сул | J5: ='Юнит 2'!S3 -> 8 | K5: =J5/J$17 -> 0.19047619 | L5: =L4+K5 -> 0.80952381 | M5: =_xlfn.IFS(L5<80%,"A",L5<=95%,"B",L5>95%,"C") -> B | P5: B | Q5: 0.15
B6: MR Р1886 корич | C6: ='Юнит 2'!AL15 -> 522.96997 | D6: =C6/C$17 -> 0.039682469 | E6: =E5+D6 -> 1.0301458 | F6: =IF(AND(E6<=0),"C",IF(E6<=0.8,"A",IF(E6<=0.95,"B","C"))) -> C | G6: =VLOOKUP(B$4:B$16,I$4:M$16,5,0) -> C | I6: Qs желт Сул | J6: ='Юнит 2'!S6 -> 3 | K6: =J6/J$17 -> 0.071428571 | L6: =L5+K6 -> 0.88095238 | M6: =_xlfn.IFS(L6<80%,"A",L6<=95%,"B",L6>95%,"C") -> B | P6: C | Q6: 0.05
B7: MR Р1874 корич | C7: ='Юнит 2'!AL13 -> 499.52107 | D7: =C7/C$17 -> 0.037903188 | E7: =E6+D7 -> 1.068049 | F7: =IF(AND(E7<=0),"C",IF(E7<=0.8,"A",IF(E7<=0.95,"B","C"))) -> C | G7: =VLOOKUP(B$4:B$16,I$4:M$16,5,0) -> C | I7: MR8854 C2 Сул | J7: ='Юнит 2'!S9 -> 2 | K7: =J7/J$17 -> 0.047619048 | L7: =L6+K7 -> 0.92857143 | M7: =_xlfn.IFS(L7<80%,"A",L7<=95%,"B",L7>95%,"C") -> B
B8: MR Р1886 черн | C8: ='Юнит 2'!AL14 -> 480.04914 | D8: =C8/C$17 -> 0.036425677 | E8: =E7+D8 -> 1.1044746 | F8: =IF(AND(E8<=0),"C",IF(E8<=0.8,"A",IF(E8<=0.95,"B","C"))) -> C | G8: =VLOOKUP(B$4:B$16,I$4:M$16,5,0) -> C | I8: MR Р1874 корич | J8: ='Юнит 2'!S13 -> 1 | K8: =J8/J$17 -> 0.023809524 | L8: =L7+K8 -> 0.95238095 | M8: =_xlfn.IFS(L8<80%,"A",L8<=95%,"B",L8>95%,"C") -> C
B9: Qs желт Сул | C9: ='Юнит 2'!AL6 -> 251.54918 | D9: =C9/C$17 -> 0.019087315 | E9: =E8+D9 -> 1.1235619 | F9: =IF(AND(E9<=0),"C",IF(E9<=0.8,"A",IF(E9<=0.95,"B","C"))) -> C | G9: =VLOOKUP(B$4:B$16,I$4:M$16,5,0) -> B | I9: MR Р1886 черн | J9: ='Юнит 2'!S14 -> 1 | K9: =J9/J$17 -> 0.023809524 | L9: =L8+K9 -> 0.97619048 | M9: =_xlfn.IFS(L9<80%,"A",L9<=95%,"B",L9>95%,"C") -> C
B10: MR 1819 корич | C10: ='Юнит 2'!AL11 -> -17.763004 | D10: =C10/C$17 -> -0.00134784 | E10: =E9+D10 -> 1.1222141 | F10: =IF(AND(E10<=0),"C",IF(E10<=0.8,"A",IF(E10<=0.95,"B","C"))) -> C | G10: =VLOOKUP(B$4:B$16,I$4:M$16,5,0) -> C | I10: MR Р1886 корич | J10: ='Юнит 2'!S15 -> 1 | K10: =J10/J$17 -> 0.023809524 | L10: =L9+K10 -> 1 | M10: =_xlfn.IFS(L10<80%,"A",L10<=95%,"B",L10>95%,"C") -> C
B11: MR 1819 черн | C11: ='Юнит 2'!AL10 -> -114.59625 | D11: =C11/C$17 -> -0.0086954554 | E11: =E10+D11 -> 1.1135187 | F11: =IF(AND(E11<=0),"C",IF(E11<=0.8,"A",IF(E11<=0.95,"B","C"))) -> C | G11: =VLOOKUP(B$4:B$16,I$4:M$16,5,0) -> C | I11: Qs черн Сул | J11: ='Юнит 2'!S4 -> 0 | K11: =J11/J$17 -> 0 | L11: =L10+K11 -> 1 | M11: =_xlfn.IFS(L11<80%,"A",L11<=95%,"B",L11>95%,"C") -> C
B12: MR Р1874 черн | C12: ='Юнит 2'!AL12 -> -126.47922 | D12: =C12/C$17 -> -0.0095971244 | E12: =E11+D12 -> 1.1039215 | F12: =IF(AND(E12<=0),"C",IF(E12<=0.8,"A",IF(E12<=0.95,"B","C"))) -> C | G12: =VLOOKUP(B$4:B$16,I$4:M$16,5,0) -> C | I12: Qs син Сул | J12: ='Юнит 2'!S5 -> 0 | K12: =J12/J$17 -> 0 | L12: =L11+K12 -> 1 | M12: =_xlfn.IFS(L12<80%,"A",L12<=95%,"B",L12>95%,"C") -> C
B13: Qs син Сул | C13: ='Юнит 2'!AL5 -> -164.19948 | D13: =C13/C$17 -> -0.012459302 | E13: =E12+D13 -> 1.0914622 | F13: =IF(AND(E13<=0),"C",IF(E13<=0.8,"A",IF(E13<=0.95,"B","C"))) -> C | G13: =VLOOKUP(B$4:B$16,I$4:M$16,5,0) -> C | I13: flip черные Сул | J13: ='Юнит 2'!S7 -> 0 | K13: =J13/J$17 -> 0 | L13: =L12+K13 -> 1 | M13: =_xlfn.IFS(L13<80%,"A",L13<=95%,"B",L13>95%,"C") -> C
B14: flip черные Сул | C14: ='Юнит 2'!AL7 -> -229.5913 | D14: =C14/C$17 -> -0.017421171 | E14: =E13+D14 -> 1.0740411 | F14: =IF(AND(E14<=0),"C",IF(E14<=0.8,"A",IF(E14<=0.95,"B","C"))) -> C | G14: =VLOOKUP(B$4:B$16,I$4:M$16,5,0) -> C | I14: MR 1819 черн | J14: ='Юнит 2'!S10 -> 0 | K14: =J14/J$17 -> 0 | L14: =L13+K14 -> 1 | M14: =_xlfn.IFS(L14<80%,"A",L14<=95%,"B",L14>95%,"C") -> C
B15: Qs черн Сул | C15: ='Юнит 2'!AL4 -> -238.2913 | D15: =C15/C$17 -> -0.018081319 | E15: =E14+D15 -> 1.0559597 | F15: =IF(AND(E15<=0),"C",IF(E15<=0.8,"A",IF(E15<=0.95,"B","C"))) -> C | G15: =VLOOKUP(B$4:B$16,I$4:M$16,5,0) -> C | I15: MR 1819 корич | J15: ='Юнит 2'!S11 -> 0 | K15: =J15/J$17 -> 0 | L15: =L14+K15 -> 1 | M15: =_xlfn.IFS(L15<80%,"A",L15<=95%,"B",L15>95%,"C") -> C
B16: MR8854 C2 Сул | C16: ='Юнит 2'!AL9 -> -737.48588 | D16: =C16/C$17 -> -0.055959734 | E16: =E15+D16 -> 1 | F16: =IF(AND(E16<=0),"C",IF(E16<=0.8,"A",IF(E16<=0.95,"B","C"))) -> C | G16: =VLOOKUP(B$4:B$16,I$4:M$16,5,0) -> B | I16: MR Р1874 черн | J16: ='Юнит 2'!S12 -> 0 | K16: =J16/J$17 -> 0 | L16: =L15+K16 -> 1 | M16: =_xlfn.IFS(L16<80%,"A",L16<=95%,"B",L16>95%,"C") -> C
C17: =SUM(C4:C16) -> 13178.867 | D17: =SUM(D4:D16) -> 1 | J17: =SUM(J4:J16) -> 42 | K17: =SUM(K4:K16) -> 1
