Workbook

Sheet Реклама
B2: ПЕРИОД | C2: БАЛАНС | F2: СЧЕТ | I2: Неделя
C3: Номер документа | D3: Сумма | E3: Даты | F3: Номер документа | G3: Сумма | H3: Даты
B4: 01-04.01 | F4: 277607349 | G4: 4738 | H4: 01-04.01 | I4: 1
B5: 04-11.01 | F5: 279228154 | G5: 6535 | H5: 04-11.01 | I5: 2
B6: 11-18.01 | C6: 280305485 | D6: 2922 | E6: 14-18.01 | F6: 280297200 | G6: 3464 | H6: 11-17.01 | I6: 3
B7: 18-25.01 | C7: 281290485 | D7: 5916 | E7: 18-23.01 | F7: 281290488 | G7: 2033 | H7: 18-25.01 | I7: 4
B8: 25.01-01.02 | C8: 282283796 | D8: 12613 | E8: 27-31.01 | F8: 282343451 | G8: 9553 | H8: 25-31.01 | I8: 5
C9: 282375547 | D9: 1000 | E9: 01.02 | F9: 282385566 | G9: 79 | H9: 01.02
B10: 01-08.02 | C10: 283356234 | D10: 9526 | E10: 01-04.02 | F10: 283392061 | G10: 17308 | H10: 01-08.02 | I10: 6
B11: 08-15.02 | C11: 284419876 | D11: 16968 | E11: 09-12.02 | F11: 284354982 | G11: 25029 | H11: 08-15.02 | I11: 7
B12: 15-22.02 | C12: 285375130 | D12: 19000 | E12: 16-21.02 | F12: 285375131 | G12: 43359 | H12: 16-22.02 | I12: 8
B13: 22.02-01.03 | C13: 286365345 | D13: 20188 | E13: 23-28.02 | F13: 286438626 | G13: 41519 | H13: 22-28.02 | I13: 9
F14: 286502032 | G14: 8252 | H14: 01.03
B15: 01-08.03 | C15: 287719816 | D15: 55356 | E15: 01.03-08.03 | F15: 287759820 | G15: 14284 | H15: 01.03-05.03 | I15: 10
B16: 08-15.03 | C16: 288712526 | D16: 117662 | E16: 08-15.03 | I16: 11
B17: 15-22.03 | C17: 289759802 | D17: 121051 | E17: 15-22.03 | I17: 12
B18: 22-29.03 | C18: 290725778 | D18: 128912 | E18: 22-29.03 | I18: 13
B19: 29.03-05.04 | C19: 291768435 | D19: 65325 | E19: 29-31.03 | I19: 14
C20: 291883504 | D20: 80610 | E20: 01-05.04 | F20: 291847775 | G20: 788 | H20: 04.02
B21: 05-12.04 | C21: 292907640 | D21: 104265 | E21: 06-12.04 | I21: 15
B22: 12-19.04 | C22: 293900151 | D22: 127217 | E22: 12-19.04 | I22: 16
B23: 19-26.04 | C23: 294920472 | D23: =112470+12849 -> 125319 | E23: 19-26.04 | I23: 17
B24: 26.04-03.05 | C24: 295903378 | D24: 38906 | E24: 26-30.04 | I24: 18
C25: 296043480 | D25: 53077 | E25: 01.05-03.05
B26: 03-10.05 | C26: 296996503 | D26: 150375 | E26: 03.05-10.05 | F26: 297017628 | G26: 8172 | H26: 09.05-10.05 | I26: 19
H33: .

Sheet Сводная_план
B2: Период | E2: Дата поступления дс | F2: Итого к перечислению на счет, руб | G2: шт. | J2: ВБ реализовал товар (выручка с СПП) | M2: Выручка до вычета комиссии ВБ | P2: Себестоимость продаж | Q2: Логистика WB | R2: Комиссия WB | S2: Хранение WB | T2: Платная приемка WB | U2: Штрафы WB | V2: Прочие удержания WB | W2: Реклама БАЛАНС | X2: Реклама СЧЕТ | Y2: Блогеры | Z2: Налог | AA2: Прочие поступления WB | AB2: Прибыль до вычета налогов | AC2: Прибыль после вычета налогов | AD2: Итог месяц | AE2: % Cебестоимости | AF2: Маржинальность, % | AG2: Рентабельность, % | AH2: Доля рекламы, %
B3: Месяц | C3: Даты | D3: Нед | G3: Заказы | H3: Продажи | I3: Возвраты | J3: Продажи | K3: Возвраты | L3: Общая | M3: Продажи | N3: Возвраты | O3: Общая
B4: Январь 1 | C4: 29-31.12 | D4: 1 | AD4: =SUM(AC4:AC9) -> 0 | AE4: =P4/O4 -> #DIV/0! | AF4: =AC4/P4 -> #DIV/0! | AG4: =AC4/O4 -> #DIV/0! | AH4: =(W4+X4+Y4)/O4 -> #DIV/0!
C5: 01-04.01 | D5: 1
B6: Январь 2 | C6: 05-11.01 | D6: 2 | AE6: =P6/O6 -> #DIV/0! | AF6: =AC6/P6 -> #DIV/0! | AG6: =AC6/O6 -> #DIV/0! | AH6: =(W6+X6+Y6)/O6 -> #DIV/0!
B7: Январь 3 | C7: 12-18.01 | D7: 3 | AE7: =P7/O7 -> #DIV/0! | AF7: =AC7/P7 -> #DIV/0! | AG7: =AC7/O7 -> #DIV/0! | AH7: =(W7+X7+Y7)/O7 -> #DIV/0!
B8: Январь 4 | C8: 19-25.01 | D8: 4 | AE8: =P8/O8 -> #DIV/0! | AF8: =AC8/P8 -> #DIV/0! | AG8: =AC8/O8 -> #DIV/0! | AH8: =(W8+X8+Y8)/O8 -> #DIV/0!
B9: Январь 5 | C9: 26.01-01.02 | D9: 5 | AE9: =P9/O9 -> #DIV/0! | AF9: =AC9/P9 -> #DIV/0! | AG9: =AC9/O9 -> #DIV/0! | AH9: =(W9+X9+Y9)/O9 -> #DIV/0!
B10: Февраль 1 | C10: 02-08.02 | D10: 6 | AD10: =SUM(AC10:AC13) -> 0 | AE10: =P10/O10 -> #DIV/0! | AF10: =AC10/P10 -> #DIV/0! | AG10: =AC10/O10 -> #DIV/0! | AH10: =(W10+X10+Y10)/O10 -> #DIV/0!
B11: Февраль 2 | C11: 09-15.02 | D11: 7 | AE11: =P11/O11 -> #DIV/0! | AF11: =AC11/P11 -> #DIV/0! | AG11: =AC11/O11 -> #DIV/0! | AH11: =(W11+X11+Y11)/O11 -> #DIV/0!
B12: Февраль 3 | C12: 16-22.02 | D12: 8 | AE12: =P12/O12 -> #DIV/0! | AF12: =AC12/P12 -> #DIV/0! | AG12: =AC12/O12 -> #DIV/0! | AH12: =(W12+X12+Y12)/O12 -> #DIV/0!
B13: Февраль 4 | C13: 23.02-01.03 | D13: 9 | AE13: =P13/O13 -> #DIV/0! | AF13: =AC13/P13 -> #DIV/0! | AG13: =AC13/O13 -> #DIV/0! | AH13: =(W13+X13+Y13)/O13 -> #DIV/0!
B14: Март 1 очки | C14: 02-08.03 | D14: 10 | AD14: =SUM(AC14:AC21) -> 0 | AE14: =P14/O14 -> #DIV/0! | AF14: =AC14/P14 -> #DIV/0! | AG14: =AC14/O14 -> #DIV/0! | AH14: =(W14+X14+Y14)/O14 -> #DIV/0!
B15: Март 1 шапки | C15: 02-08.03 | D15: 10 | AE15: =P15/O15 -> #DIV/0! | AF15: =AC15/P15 -> #DIV/0! | AG15: =AC15/O15 -> #DIV/0! | AH15: =(W15+X15+Y15)/O15 -> #DIV/0!
B16: Март 2 очки | C16: 09-15.03 | D16: 11 | AE16: =P16/O16 -> #DIV/0! | AF16: =AC16/P16 -> #DIV/0! | AG16: =AC16/O16 -> #DIV/0! | AH16: =(W16+X16+Y16)/O16 -> #DIV/0!
B17: Март 2 шапки | C17: 09-15.03 | D17: 11 | AE17: =P17/O17 -> #DIV/0! | AF17: =AC17/P17 -> #DIV/0! | AG17: =AC17/O17 -> #DIV/0! | AH17: =(W17+X17+Y17)/O17 -> #DIV/0!
B18: Март 3 очки | C18: 16-22.03 | D18: 12 | AE18: =P18/O18 -> #DIV/0! | AF18: =AC18/P18 -> #DIV/0! | AG18: =AC18/O18 -> #DIV/0! | AH18: =(W18+X18+Y18)/O18 -> #DIV/0!
B19: Март 3 шапки | C19: 16-22.03 | D19: 12 | AE19: =P19/O19 -> #DIV/0! | AF19: =AC19/P19 -> #DIV/0! | AG19: =AC19/O19 -> #DIV/0! | AH19: =(W19+X19+Y19)/O19 -> #DIV/0!
B20: Март 4 очки | C20: 23-29.03 | D20: 13 | AE20: =P20/O20 -> #DIV/0! | AF20: =AC20/P20 -> #DIV/0! | AG20: =AC20/O20 -> #DIV/0! | AH20: =(W20+X20+Y20)/O20 -> #DIV/0!
B21: Март 4 шапки | C21: 23-29.03 | D21: 13 | AE21: =P21/O21 -> #DIV/0! | AF21: =AC21/P21 -> #DIV/0! | AG21: =AC21/O21 -> #DIV/0! | AH21: =(W21+X21+Y21)/O21 -> #DIV/0!
B22: Апрель 1 очки | C22: 30.03-05.04 | D22: 14 | F22: =IFERROR(O22-SUM(Q22:W22)+AA22,0) -> 367394.67 | G22: ='Юнит 14'!L$59 -> 1070 | H22: ='Юнит 14'!Q$59 -> 738 | I22: ='Юнит 14'!R$59 -> -18 | J22: ='Юнит 14'!T$59 -> 627842.82 | K22: ='Юнит 14'!U$59 -> -15191 | L22: =IFERROR(J22+K22,0) -> 612651.82 | M22: ='Юнит 14'!W$59 -> 950855.45 | N22: ='Юнит 14'!X$59 -> -23538 | O22: =IFERROR(M22+N22,0) -> 927317.45 | P22: ='Юнит 14'!AB$59 -> 91170.72 | Q22: ='Юнит 14'!AE$59 -> 96960.75 | R22: ='Юнит 14'!AC$59 -> 349571.93 | S22: ='Юнит 14'!AI$59 -> 6078.0973 | U22: ='Юнит 14'!AJ$59 -> 100 | W22: ='Юнит 14'!AF$59 -> 107212 | X22: ='Юнит 14'!AG$59 -> 788 | Y22: ='Юнит 14'!AH142 -> 0 | Z22: =IFERROR((L22)*0.01,0) -> 6126.5182 | AB22: =O22-SUM(P22:Y22)+AA22 -> 275435.95 | AC22: =O22-SUM(P22:Z22)+AA22 -> 269309.43 | AD22: =SUM(AC22:AC31) -> 778623.14 | AE22: =P22/O22 -> 0.098316623 | AF22: =AC22/P22 -> 2.9539027 | AG22: =AC22/O22 -> 0.29041774 | AH22: =(W22+X22+Y22)/O22 -> 0.11646497
B23: Апрель 1 шапки | C23: 30.03-05.04 | D23: 14 | AE23: =P23/O23 -> #DIV/0! | AF23: =AC23/P23 -> #DIV/0! | AG23: =AC23/O23 -> #DIV/0! | AH23: =(W23+X23+Y23)/O23 -> #DIV/0!
B24: Апрель 2 очки | C24: 06-12.04 | D24: 15 | F24: =IFERROR(O24-SUM(Q24:W24)+AA24,0) -> 239463.88 | G24: ='Юнит 15'!L$59 -> 712 | H24: ='Юнит 15'!Q$59 -> 475 | I24: ='Юнит 15'!R$59 -> -10 | J24: ='Юнит 15'!T$59 -> 410987.97 | K24: ='Юнит 15'!U$59 -> -8507 | L24: =IFERROR(J24+K24,0) -> 402480.97 | M24: ='Юнит 15'!W$59 -> 615994.65 | N24: ='Юнит 15'!X$59 -> -12994 | O24: =IFERROR(M24+N24,0) -> 603000.65 | P24: ='Юнит 15'!AB$59 -> 58987.17 | Q24: ='Юнит 15'!AE$59 -> 63078.87 | R24: ='Юнит 15'!AC$59 -> 228321.03 | S24: ='Юнит 15'!AI$59 -> 5840.8701 | U24: ='Юнит 15'!AJ$59 -> 30 | W24: ='Юнит 15'!AF$59 -> 66266 | X24: ='Юнит 15'!AG$59 -> 0 | Y24: ='Юнит 15'!AH144 -> 0 | Z24: =IFERROR((L24)*0.01,0) -> 4024.8097 | AB24: =O24-SUM(P24:Y24)+AA24 -> 180476.71 | AC24: =O24-SUM(P24:Z24)+AA24 -> 176451.9 | AE24: =P24/O24 -> 0.09782273 | AF24: =AC24/P24 -> 2.9913607 | AG24: =AC24/O24 -> 0.29262307 | AH24: =(W24+X24+Y24)/O24 -> 0.10989375
B25: Апрель 2 шапки | C25: 06-12.04 | D25: 15 | AE25: =P25/O25 -> #DIV/0! | AF25: =AC25/P25 -> #DIV/0! | AG25: =AC25/O25 -> #DIV/0! | AH25: =(W25+X25+Y25)/O25 -> #DIV/0!
B26: Апрель 3 очки | C26: 13-19.04 | D26: 16 | F26: =IFERROR(O26-SUM(Q26:W26)+AA26,0) -> 205868.01 | G26: ='Юнит 16'!L$59 -> 843 | H26: ='Юнит 16'!Q$59 -> 491 | I26: ='Юнит 16'!R$59 -> -6 | J26: ='Юнит 16'!T$59 -> 422194.48 | K26: ='Юнит 16'!U$59 -> -5004.64 | L26: =IFERROR(J26+K26,0) -> 417189.84 | M26: ='Юнит 16'!W$59 -> 631051.64 | N26: ='Юнит 16'!X$59 -> -7401.77 | O26: =IFERROR(M26+N26,0) -> 623649.87 | P26: ='Юнит 16'!AB$59 -> 62105.34 | Q26: ='Юнит 16'!AE$59 -> 69407.72 | R26: ='Юнит 16'!AC$59 -> 235781.61 | S26: ='Юнит 16'!AI$59 -> 5403.531 | U26: ='Юнит 16'!AJ$59 -> 200 | W26: ='Юнит 16'!AF$59 -> 106989 | X26: ='Юнит 16'!AG$59 -> 0 | Y26: ='Юнит 16'!AH146 -> 0 | Z26: =IFERROR((L26)*0.01,0) -> 4171.8984 | AB26: =O26-SUM(P26:Y26)+AA26 -> 143762.67 | AC26: =O26-SUM(P26:Z26)+AA26 -> 139590.77 | AE26: =P26/O26 -> 0.099583665 | AF26: =AC26/P26 -> 2.2476452 | AG26: =AC26/O26 -> 0.22382875 | AH26: =(W26+X26+Y26)/O26 -> 0.17155299
B27: Апрель 3 шапки | C27: 13-19.04 | D27: 16 | AE27: =P27/O27 -> #DIV/0! | AF27: =AC27/P27 -> #DIV/0! | AG27: =AC27/O27 -> #DIV/0! | AH27: =(W27+X27+Y27)/O27 -> #DIV/0!
B28: Апрель 4 очки | C28: 20-26.04 | D28: 17 | F28: =IFERROR(O28-SUM(Q28:W28)+AA28,0) -> 159366.79 | G28: ='Юнит 17'!L$59 -> 614 | H28: ='Юнит 17'!Q$59 -> 419 | I28: ='Юнит 17'!R$59 -> -3 | J28: ='Юнит 17'!T$59 -> 367593.75 | K28: ='Юнит 17'!U$59 -> -2608 | L28: =IFERROR(J28+K28,0) -> 364985.75 | M28: ='Юнит 17'!W$59 -> 538871.83 | N28: ='Юнит 17'!X$59 -> -3900 | O28: =IFERROR(M28+N28,0) -> 534971.83 | P28: ='Юнит 17'!AB$59 -> 53094.99 | Q28: ='Юнит 17'!AE$59 -> 54950.82 | R28: ='Юнит 17'!AC$59 -> 202367.99 | S28: ='Юнит 17'!AI$59 -> 5036.2292 | U28: ='Юнит 17'!AJ$59 -> 150 | W28: ='Юнит 17'!AF$59 -> 113100 | X28: ='Юнит 17'!AG$59 -> 0 | Y28: ='Юнит 17'!AH148 -> 0 | Z28: =IFERROR((L28)*0.01,0) -> 3649.8575 | AB28: =O28-SUM(P28:Y28)+AA28 -> 106271.8 | AC28: =O28-SUM(P28:Z28)+AA28 -> 102621.94 | AE28: =P28/O28 -> 0.099248198 | AF28: =AC28/P28 -> 1.932799 | AG28: =AC28/O28 -> 0.19182682 | AH28: =(W28+X28+Y28)/O28 -> 0.211413
B29: Апрель 4 шапки | C29: 20-26.04 | D29: 17 | AE29: =P29/O29 -> #DIV/0! | AF29: =AC29/P29 -> #DIV/0! | AG29: =AC29/O29 -> #DIV/0! | AH29: =(W29+X29+Y29)/O29 -> #DIV/0!
B30: Апрель 5 очки | C30: 27.04-03.05 | D30: 18 | F30: =IFERROR(O30-SUM(Q30:W30)+AA30,0) -> 142132.84 | G30: ='Юнит 18'!L$59 -> 675 | H30: ='Юнит 18'!Q$59 -> 385 | I30: ='Юнит 18'!R$59 -> -8 | J30: ='Юнит 18'!T$59 -> 337964.2 | K30: ='Юнит 18'!U$59 -> -7103.85 | L30: =IFERROR(J30+K30,0) -> 330860.35 | M30: ='Юнит 18'!W$59 -> 474292.2 | N30: ='Юнит 18'!X$59 -> -10016.93 | O30: =IFERROR(M30+N30,0) -> 464275.27 | P30: ='Юнит 18'!AB$59 -> 48175.14 | Q30: ='Юнит 18'!AE$59 -> 49084.94 | R30: ='Юнит 18'!AC$59 -> 175905.37 | S30: ='Юнит 18'!AI$59 -> 4681.1243 | U30: ='Юнит 18'!AJ$59 -> 827 | W30: ='Юнит 18'!AF$59 -> 91644 | X30: ='Юнит 18'!AG$59 -> 0 | Y30: ='Юнит 18'!AH150 -> 0 | Z30: =IFERROR((L30)*0.01,0) -> 3308.6035 | AB30: =O30-SUM(P30:Y30)+AA30 -> 93957.696 | AC30: =O30-SUM(P30:Z30)+AA30 -> 90649.092 | AE30: =P30/O30 -> 0.10376417 | AF30: =AC30/P30 -> 1.8816571 | AG30: =AC30/O30 -> 0.19524859 | AH30: =(W30+X30+Y30)/O30 -> 0.19739152
B31: Апрель 5 шапки | C31: 27.04-03.05 | D31: 18 | AE31: =P31/O31 -> #DIV/0! | AF31: =AC31/P31 -> #DIV/0! | AG31: =AC31/O31 -> #DIV/0! | AH31: =(W31+X31+Y31)/O31 -> #DIV/0!
AB33: =O33-SUM(P33:Y33)+AA33 -> 0 | AC33: =O33-SUM(P33:Z33)+AA33 -> 0 | AE33: =P33/O33 -> #DIV/0! | AF33: =AC33/P33 -> #DIV/0! | AG33: =AC33/O33 -> #DIV/0! | AH33: =(W33+X33+Y33)/O33 -> #DIV/0!
B34: Итого | F34: =SUM(F4:F33) -> 1114226.2 | G34: =SUM(G4:G33) -> 3914 | H34: =SUM(H4:H33) -> 2508 | I34: =SUM(I4:I33) -> -45 | J34: =SUM(J4:J33) -> 2166583.2 | K34: =SUM(K4:K33) -> -38414.49 | L34: =SUM(L4:L33) -> 2128168.7 | M34: =SUM(M4:M33) -> 3211065.8 | ... AD34: =SUM(AD4:AD33) -> 778623.14 | AE34: =P34/O34 -> 0.099432913 | AF34: =AC34/P34 -> 2.4833821 | AG34: =AC34/O34 -> 0.24692992 | AH34: =(W34+X34+Y34)/O34 -> 0.15412808
M35: % от выручки за весь период
N36: =-N34/M34 -> 0.018016043 | P36: =P34/$O$34 -> 0.099432913 | Q36: =Q34/$O$34 -> 0.10575971 | R36: =R34/$O$34 -> 0.37801035 | S36: =S34/$O$34 -> 0.0085753275 | T36: =T34/$O$34 -> 0 | U36: =U34/$O$34 -> 0.00041449758 | V36: =V34/$O$34 -> 0 | W36: =W34/$O$34 -> 0.15387818 | ... Z36: =Z34/$O$34 -> 0.0067492026 | AD36: =AC34/P34 -> 2.4833821 | AE36: Маржинальность, %
W37: =(W34+X34)/O34 -> 0.15412808 | AD37: =AC34/O34 -> 0.24692992 | AE37: Рентабельность, %
B39: 14 нед | W39: =W22/O22 -> 0.11561521 | X39: =X22/O22 -> 0.00084976294
B40: 15 нед | W40: =W24/O24 -> 0.10989375 | X40: =X24/O24 -> 0
B41: 16 нед | W41: =W26/O26 -> 0.17155299 | X41: =X26/O26 -> 0
B42: 17 нед | W42: =W28/O28 -> 0.211413 | X42: =X28/O28 -> 0
B43: 18 нед | W43: =W30/O30 -> 0.19739152 | X43: =X30/O30 -> 0
...

Sheet Сводная
B2: Период | E2: Дата поступления дс | F2: Итого к перечислению на счет, руб | G2: шт. | J2: ВБ реализовал товар (выручка с СПП) | M2: Выручка до вычета комиссии ВБ | P2: Себестоимость продаж | Q2: Логистика WB | R2: Комиссия WB | S2: Хранение WB | T2: Платная приемка WB | U2: Штрафы WB | V2: Прочие удержания WB | W2: Реклама БАЛАНС | X2: Реклама СЧЕТ | Y2: Блогеры | Z2: Налог | AA2: Прочие поступления WB | AB2: Прибыль до вычета налогов | AC2: Прибыль после вычета налогов | AD2: Итог месяц | AE2: % Cебестоимости | AF2: Маржинальность, % | AG2: Рентабельность, % | AH2: Доля рекламы, %
B3: Месяц | C3: Даты | D3: Нед | G3: Заказы | H3: Продажи | I3: Возвраты | J3: Продажи | K3: Возвраты | L3: Общая | M3: Продажи | N3: Возвраты | O3: Общая
B4: Январь 1 | C4: 29-31.12 | D4: 1 | F4: =IFERROR(O4-SUM(Q4:W4)+AA4,0) -> 21116.17 | G4: ='Юнит 1 29-31.12'!L$17 -> 29 | H4: ='Юнит 1 29-31.12'!Q$17 -> 31 | I4: ='Юнит 1 29-31.12'!R$17 -> 0 | J4: ='Юнит 1 29-31.12'!T$74 -> 31859.55 | K4: ='Юнит 1 29-31.12'!U$74 -> 0 | L4: =IFERROR(J4+K4,0) -> 31859.55 | M4: ='Юнит 1 29-31.12'!W$74 -> 37862.85 | N4: ='Юнит 1 29-31.12'!X$74 -> 0 | O4: =IFERROR(M4+N4,0) -> 37862.85 | P4: ='Юнит 1 29-31.12'!AB$74 -> 3949.17 | Q4: ='Юнит 1 29-31.12'!AE$74 -> 2587.3 | R4: ='Юнит 1 29-31.12'!AC$74 -> 13659.08 | S4: ='Юнит 1 29-31.12'!AI$74 -> 413.9 | U4: ='Юнит 1 29-31.12'!AJ$74 -> 0 | V4: 86.4 | W4: ='Юнит 1 29-31.12'!AF$74 -> 0 | X4: ='Юнит 1 29-31.12'!AG$74 -> 0 | Y4: ='Юнит 1 29-31.12'!AH84 -> 0 | Z4: 313.33 | AB4: =O4-SUM(P4:Y4)+AA4 -> 17167 | AC4: =O4-SUM(P4:Z4)+AA4 -> 16853.67 | AD4: =SUM(AC4:AC9) -> 67154.08 | AE4: =P4/O4 -> 0.10430197 | AF4: =AC4/P4 -> 4.2676486 | AG4: =AC4/O4 -> 0.44512418 | AH4: =(W4+X4+Y4)/O4 -> 0
C5: 01-04.01 | D5: 1 | F5: =IFERROR(O5-SUM(Q5:W5)+AA5,0) -> 8163.47 | G5: ='Юнит 1 01-04.01'!L$17 -> 37 | H5: ='Юнит 1 01-04.01'!Q$17 -> 14 | I5: ='Юнит 1 01-04.01'!R$17 -> 0 | J5: ='Юнит 1 01-04.01'!T$74 -> 14286.08 | K5: ='Юнит 1 01-04.01'!U$74 -> 0 | L5: =IFERROR(J5+K5,0) -> 14286.08 | M5: ='Юнит 1 01-04.01'!W$74 -> 17125.77 | N5: ='Юнит 1 01-04.01'!X$74 -> 0 | O5: =IFERROR(M5+N5,0) -> 17125.77 | P5: ='Юнит 1 01-04.01'!AB$74 -> 1763.04 | Q5: ='Юнит 1 01-04.01'!AE$74 -> 1955.75 | R5: ='Юнит 1 01-04.01'!AC$74 -> 6195.14 | S5: ='Юнит 1 01-04.01'!AI$74 -> 635.73 | U5: ='Юнит 1 01-04.01'!AJ$74 -> 0 | V5: 175.68 | W5: ='Юнит 1 01-04.01'!AF$74 -> 0 | X5: ='Юнит 1 01-04.01'!AG$74 -> 4738 | Y5: ='Юнит 1 01-04.01'!AH85 -> 0 | Z5: 144.56 | AB5: =O5-SUM(P5:Y5)+AA5 -> 1662.43 | AC5: =O5-SUM(P5:Z5)+AA5 -> 1517.87
B6: Январь 2 | C6: 05-11.01 | D6: 2 | F6: =IFERROR(O6-SUM(Q6:W6)+AA6,0) -> 25524.23 | G6: ='Юнит 2'!L$17 -> 86 | H6: ='Юнит 2'!Q$17 -> 43 | I6: ='Юнит 2'!R$17 -> -1 | J6: ='Юнит 2'!T$74 -> 43245.32 | K6: ='Юнит 2'!U$74 -> -931 | L6: =IFERROR(J6+K6,0) -> 42314.32 | M6: ='Юнит 2'!W$74 -> 52197.86 | N6: ='Юнит 2'!X$74 -> -1199 | O6: =IFERROR(M6+N6,0) -> 50998.86 | P6: ='Юнит 2'!AB$74 -> 5562.9 | Q6: ='Юнит 2'!AE$74 -> 5752.8 | R6: ='Юнит 2'!AC$74 -> 18463.04 | S6: ='Юнит 2'!AI$74 -> 1083.11 | U6: ='Юнит 2'!AJ$74 -> 0 | V6: 175.68 | W6: ='Юнит 2'!AF$74 -> 0 | X6: ='Юнит 2'!AG$74 -> 6535 | Y6: ='Юнит 2'!AH85 -> 0 | Z6: 416.28 | AB6: =O6-SUM(P6:Y6)+AA6 -> 13426.33 | AC6: =O6-SUM(P6:Z6)+AA6 -> 13010.05 | AE6: =P6/O6 -> 0.10907891 | AF6: =AC6/P6 -> 2.3387172 | AG6: =AC6/O6 -> 0.25510472 | AH6: =(W6+X6+Y6)/O6 -> 0.12814012
B7: Январь 3 | C7: 12-18.01 | D7: 3 | F7: =IFERROR(O7-SUM(Q7:W7)+AA7,0) -> 25982.83 | G7: ='Юнит 3'!L$17 -> 62 | H7: ='Юнит 3'!Q$17 -> 49 | I7: ='Юнит 3'!R$17 -> -1 | J7: ='Юнит 3'!T$74 -> 45785.47 | K7: ='Юнит 3'!U$74 -> -948 | L7: =IFERROR(J7+K7,0) -> 44837.47 | M7: ='Юнит 3'!W$74 -> 56919.74 | N7: ='Юнит 3'!X$74 -> -1174 | O7: =IFERROR(M7+N7,0) -> 55745.74 | P7: ='Юнит 3'!AB$74 -> 6528.42 | Q7: ='Юнит 3'!AE$74 -> 6055.25 | R7: ='Юнит 3'!AC$74 -> 19306.86 | S7: ='Юнит 3'!AI$74 -> 1361.68 | U7: ='Юнит 3'!AJ$74 -> 0 | V7: 117.12 | W7: ='Юнит 3'!AF$74 -> 2922 | X7: ='Юнит 3'!AG$74 -> 3464 | Y7: ='Юнит 3'!AH86 -> 0 | Z7: 467.24 | AB7: =O7-SUM(P7:Y7)+AA7 -> 15990.41 | AC7: =O7-SUM(P7:Z7)+AA7 -> 15523.17 | AE7: =P7/O7 -> 0.11711065 | AF7: =AC7/P7 -> 2.3777836 | AG7: =AC7/O7 -> 0.27846379 | AH7: =(W7+X7+Y7)/O7 -> 0.11455584
B8: Январь 4 | C8: 19-25.01 | D8: 4 | F8: =IFERROR(O8-SUM(Q8:W8)+AA8,0) -> 22836.85 | G8: ='Юнит 4'!L$17 -> 86 | H8: ='Юнит 4'!Q$17 -> 49 | I8: ='Юнит 4'!R$17 -> -2 | J8: ='Юнит 4'!T$74 -> 44338.88 | K8: ='Юнит 4'!U$74 -> -1888 | L8: =IFERROR(J8+K8,0) -> 42450.88 | M8: ='Юнит 4'!W$74 -> 59321.67 | N8: ='Юнит 4'!X$74 -> -2412 | O8: =IFERROR(M8+N8,0) -> 56909.67 | P8: ='Юнит 4'!AB$74 -> 6764.52 | Q8: ='Юнит 4'!AE$74 -> 6115.35 | R8: ='Юнит 4'!AC$74 -> 20543.92 | S8: ='Юнит 4'!AI$74 -> 1438.99 | U8: ='Юнит 4'!AJ$74 -> 0 | V8: 58.56 | W8: ='Юнит 4'!AF$74 -> 5916 | X8: ='Юнит 4'!AG$74 -> 2033 | Y8: ='Юнит 4'!AH87 -> 0 | Z8: 456.13 | AB8: =O8-SUM(P8:Y8)+AA8 -> 14039.33 | AC8: =O8-SUM(P8:Z8)+AA8 -> 13583.2 | AE8: =P8/O8 -> 0.11886416 | AF8: =AC8/P8 -> 2.0080065 | AG8: =AC8/O8 -> 0.23868 | AH8: =(W8+X8+Y8)/O8 -> 0.13967749
B9: Январь 5 | C9: 26.01-01.02 | D9: 5 | F9: =IFERROR(O9-SUM(Q9:W9)+AA9,0) -> 26541.81 | G9: ='Юнит 5'!L$17 -> 157 | H9: ='Юнит 5'!Q$17 -> 70 | I9: ='Юнит 5'!R$17 -> -1 | J9: ='Юнит 5'!T$74 -> 53707.42 | K9: ='Юнит 5'!U$74 -> -813 | L9: =IFERROR(J9+K9,0) -> 52894.42 | M9: ='Юнит 5'!W$74 -> 80352 | N9: ='Юнит 5'!X$74 -> -1238 | O9: =IFERROR(M9+N9,0) -> 79114 | P9: ='Юнит 5'!AB$74 -> 9760.32 | Q9: ='Юнит 5'!AE$74 -> 8509.6 | R9: ='Юнит 5'!AC$74 -> 28720.66 | S9: ='Юнит 5'!AI$74 -> 1377.57 | U9: ='Юнит 5'!AJ$74 -> 0 | V9: 351.36 | W9: ='Юнит 5'!AF$74 -> 13613 | X9: ='Юнит 5'!AG$74 -> 9632 | Y9: ='Юнит 5'!AH88 -> 0 | Z9: 483.37 | AB9: =O9-SUM(P9:Y9)+AA9 -> 7149.49 | AC9: =O9-SUM(P9:Z9)+AA9 -> 6666.12 | AE9: =P9/O9 -> 0.12337033 | AF9: =AC9/P9 -> 0.68298171 | AG9: =AC9/O9 -> 0.084259676 | AH9: =(W9+X9+Y9)/O9 -> 0.29381652
B10: Февраль 1 | C10: 02-08.02 | D10: 6 | F10: =IFERROR(O10-SUM(Q10:W10)+AA10,0) -> 59865 | G10: ='Юнит 6'!L$45 -> 286 | H10: ='Юнит 6'!Q$45 -> 118 | I10: ='Юнит 6'!R$45 -> -1 | J10: ='Юнит 6'!T$102 -> 85982.96 | K10: ='Юнит 6'!U$102 -> -777 | L10: =IFERROR(J10+K10,0) -> 85205.96 | M10: ='Юнит 6'!W$102 -> 132376.93 | N10: ='Юнит 6'!X$102 -> -1238 | O10: =IFERROR(M10+N10,0) -> 131138.93 | P10: ='Юнит 6'!AB$102 -> 15974.01 | Q10: ='Юнит 6'!AE$102 -> 12544.65 | R10: ='Юнит 6'!AC$102 -> 47795.47 | S10: ='Юнит 6'!AI$102 -> 1261.41 | U10: ='Юнит 6'!AJ$102 -> 0 | V10: 146.4 | W10: ='Юнит 6'!AF$102 -> 9526 | X10: ='Юнит 6'!AG$102 -> 17308 | Y10: ='Юнит 6'!AH117 -> 0 | Z10: 922.79 | AB10: =O10-SUM(P10:Y10)+AA10 -> 26582.99 | AC10: =O10-SUM(P10:Z10)+AA10 -> 25660.2 | AD10: =SUM(AC10:AC13) -> 265557.06 | AE10: =P10/O10 -> 0.12180982 | AF10: =AC10/P10 -> 1.6063719 | AG10: =AC10/O10 -> 0.19567187 | AH10: =(W10+X10+Y10)/O10 -> 0.20462269
B11: Февраль 2 | C11: 09-15.02 | D11: 7 | F11: =IFERROR(O11-SUM(Q11:W11)+AA11,0) -> 105982.04 | G11: ='Юнит 7'!L$45 -> 388 | H11: ='Юнит 7'!Q$45 -> 212 | I11: ='Юнит 7'!R$45 -> -2 | J11: ='Юнит 7'!T$102 -> 149383.2 | K11: ='Юнит 7'!U$102 -> -1458 | L11: =IFERROR(J11+K11,0) -> 147925.2 | M11: ='Юнит 7'!W$102 -> 234275.74 | N11: ='Юнит 7'!X$102 -> -2388 | O11: =IFERROR(M11+N11,0) -> 231887.74 | P11: ='Юнит 7'!AB$102 -> 27919.8 | Q11: ='Юнит 7'!AE$102 -> 22767.8 | R11: ='Юнит 7'!AC$102 -> 84374.68 | S11: ='Юнит 7'!AI$102 -> 1132.46 | T11: 165 | U11: ='Юнит 7'!AJ$102 -> 0 | V11: 497.76 | W11: ='Юнит 7'!AF$102 -> 16968 | X11: ='Юнит 7'!AG$102 -> 25029 | Y11: ='Юнит 7'!AH118 -> 0 | Z11: 1478.16 | AB11: =O11-SUM(P11:Y11)+AA11 -> 53033.24 | AC11: =O11-SUM(P11:Z11)+AA11 -> 51555.08 | AE11: =P11/O11 -> 0.12040223 | AF11: =AC11/P11 -> 1.8465419 | AG11: =AC11/O11 -> 0.22232775 | AH11: =(W11+X11+Y11)/O11 -> 0.18110919
B12: Февраль 3 | C12: 16-22.02 | D12: 8 | F12: =IFERROR(O12-SUM(Q12:W12)+AA12,0) -> 168699.24 | G12: ='Юнит 8'!L$45 -> 640 | H12: ='Юнит 8'!Q$45 -> 332 | I12: ='Юнит 8'!R$45 -> -3 | J12: ='Юнит 8'!T$102 -> 231517.83 | K12: ='Юнит 8'!U$102 -> -2178 | L12: =IFERROR(J12+K12,0) -> 229339.83 | M12: ='Юнит 8'!W$102 -> 360665.46 | N12: ='Юнит 8'!X$102 -> -3466 | O12: =IFERROR(M12+N12,0) -> 357199.46 | P12: ='Юнит 8'!AB$102 -> 44360.03 | Q12: ='Юнит 8'!AE$102 -> 32716.08 | R12: ='Юнит 8'!AC$102 -> 132861.28 | S12: ='Юнит 8'!AI$102 -> 1284.66 | T12: 1905 | U12: ='Юнит 8'!AJ$102 -> 294 | V12: 439.2 | W12: ='Юнит 8'!AF$102 -> 19000 | X12: ='Юнит 8'!AG$102 -> 43359 | Y12: ='Юнит 8'!AH119 -> 0 | Z12: 2261.26 | AB12: =O12-SUM(P12:Y12)+AA12 -> 80980.21 | AC12: =O12-SUM(P12:Z12)+AA12 -> 78718.95 | AE12: =P12/O12 -> 0.1241884 | AF12: =AC12/P12 -> 1.7745468 | AG12: =AC12/O12 -> 0.22037813 | AH12: =(W12+X12+Y12)/O12 -> 0.17457753
B13: Февраль 4 | C13: 23.02-01.03 | D13: 9 | F13: =IFERROR(O13-SUM(Q13:W13)+AA13,0) -> 214108.03 | G13: ='Юнит 9'!L$45 -> 632 | H13: ='Юнит 9'!Q$45 -> 399 | I13: ='Юнит 9'!R$45 -> -9 | J13: ='Юнит 9'!T$102 -> 296481.4 | K13: ='Юнит 9'!U$102 -> -6522 | L13: =IFERROR(J13+K13,0) -> 289959.4 | M13: ='Юнит 9'!W$102 -> 464446.44 | N13: ='Юнит 9'!X$102 -> -10316 | O13: =IFERROR(M13+N13,0) -> 454130.44 | P13: ='Юнит 9'!AB$102 -> 51789.51 | Q13: ='Юнит 9'!AE$102 -> 45998.58 | R13: ='Юнит 9'!AC$102 -> 171766.49 | S13: ='Юнит 9'!AI$102 -> 1545.78 | T13: 465 | U13: ='Юнит 9'!AJ$102 -> 0 | V13: 58.56 | W13: ='Юнит 9'!AF$102 -> 20188 | X13: ='Юнит 9'!AG$102 -> 49771 | Y13: ='Юнит 9'!AH120 -> 0 | Z13: 2924.69 | AB13: =O13-SUM(P13:Y13)+AA13 -> 112547.52 | AC13: =O13-SUM(P13:Z13)+AA13 -> 109622.83 | AE13: =P13/O13 -> 0.11404105 | AF13: =AC13/P13 -> 2.1166995 | AG13: =AC13/O13 -> 0.24139062 | AH13: =(W13+X13+Y13)/O13 -> 0.15405045
B14: Март 1 очки | C14: 02-08.03 | D14: 10 | F14: =IFERROR(O14-SUM(Q14:W14)+AA14,0) -> 183388.28 | G14: ='Юнит 10'!L$58 -> 833 | H14: ='Юнит 10'!Q$58 -> 382 | I14: ='Юнит 10'!R$58 -> -8 | J14: ='Юнит 10'!T$58 -> 300005.62 | K14: ='Юнит 10'!U$58 -> -6272.41 | L14: =IFERROR(J14+K14,0) -> 293733.21 | M14: ='Юнит 10'!W$58 -> 466843.39 | N14: ='Юнит 10'!X$58 -> -9947.95 | O14: =IFERROR(M14+N14,0) -> 456895.44 | P14: ='Юнит 10'!AB$58 -> 49184.92 | Q14: ='Юнит 10'!AE$58 -> 46676.69 | R14: ='Юнит 10'!AC$58 -> 172521.44 | S14: ='Юнит 10'!AI$58 -> 2108.03 | T14: 735 | U14: ='Юнит 10'!AJ$58 -> 30 | W14: ='Юнит 10'!AF$58 -> 51436 | X14: ='Юнит 10'!AG$58 -> 14284 | Y14: ='Юнит 10'!AH134 -> 0 | Z14: 3000.76 | AB14: =O14-SUM(P14:Y14)+AA14 -> 119919.36 | AC14: =O14-SUM(P14:Z14)+AA14 -> 116918.6 | AD14: =SUM(AC14:AC21) -> 1089861.5 | AE14: =P14/O14 -> 0.10765028 | AF14: =AC14/P14 -> 2.3771229 | AG14: =AC14/O14 -> 0.25589794 | AH14: =(W14+X14+Y14)/O14 -> 0.14384035
B15: Март 1 шапки | C15: 02-08.03 | D15: 10 | F15: =IFERROR(O15-SUM(Q15:W15)+AA15,0) -> -3920 | G15: ='Юнит 10'!L$68 -> 2 | H15: ='Юнит 10'!Q$68 -> 0 | I15: ='Юнит 10'!R$68 -> 0 | J15: ='Юнит 10'!T$68 -> 0 | K15: ='Юнит 10'!U$68 -> 0 | L15: =IFERROR(J15+K15,0) -> 0 | M15: ='Юнит 10'!W$68 -> 0 | N15: ='Юнит 10'!X$68 -> 0 | O15: =IFERROR(M15+N15,0) -> 0 | P15: ='Юнит 10'!AB$68 -> 0 | Q15: ='Юнит 10'!AE$68 -> 0 | R15: ='Юнит 10'!AC$68 -> 0 | S15: ='Юнит 10'!AI$68 -> 0 | U15: ='Юнит 10'!AJ$68 -> 0 | W15: ='Юнит 10'!AF$68 -> 3920 | X15: ='Юнит 10'!AG$68 -> 0 | Y15: ='Юнит 10'!AH135 -> 0 | Z15: =IFERROR((L15)*0.01,0) -> 0 | AB15: =O15-SUM(P15:Y15)+AA15 -> -3920 | AC15: =O15-SUM(P15:Z15)+AA15 -> -3920 | AE15: =P15/O15 -> #DIV/0! | AF15: =AC15/P15 -> #DIV/0! | AG15: =AC15/O15 -> #DIV/0! | AH15: =(W15+X15+Y15)/O15 -> #DIV/0!
B16: Март 2 очки | C16: 09-15.03 | D16: 11 | F16: =IFERROR(O16-SUM(Q16:W16)+AA16,0) -> 370668.61 | G16: ='Юнит 11'!L$58 -> 1503 | H16: ='Юнит 11'!Q$58 -> 797 | I16: ='Юнит 11'!R$58 -> -13 | J16: ='Юнит 11'!T$58 -> 612594.65 | K16: ='Юнит 11'!U$58 -> -10314 | L16: =IFERROR(J16+K16,0) -> 602280.65 | M16: ='Юнит 11'!W$58 -> 943118.99 | N16: ='Юнит 11'!X$58 -> -15997 | O16: =IFERROR(M16+N16,0) -> 927121.99 | P16: ='Юнит 11'!AB$58 -> 103751.9 | Q16: ='Юнит 11'!AE$58 -> 97317.48 | R16: ='Юнит 11'!AC$58 -> 349180.58 | S16: ='Юнит 11'!AI$58 -> 1851.28 | T16: 165 | U16: ='Юнит 11'!AJ$58 -> 0 | V16: 2357.04 | W16: ='Юнит 11'!AF$58 -> 105582 | X16: ='Юнит 11'!AG$58 -> 0 | Y16: ='Юнит 11'!AH136 -> 0 | Z16: 5817.33 | AB16: =O16-SUM(P16:Y16)+AA16 -> 266916.71 | AC16: =O16-SUM(P16:Z16)+AA16 -> 261099.38 | AE16: =P16/O16 -> 0.1119075 | AF16: =AC16/P16 -> 2.5165744 | AG16: =AC16/O16 -> 0.28162354 | AH16: =(W16+X16+Y16)/O16 -> 0.11388145
B17: Март 2 шапки | C17: 09-15.03 | D17: 11 | F17: =IFERROR(O17-SUM(Q17:W17)+AA17,0) -> -12473.82 | G17: ='Юнит 11'!L$68 -> 16 | H17: ='Юнит 11'!Q$68 -> 0 | I17: ='Юнит 11'!R$68 -> 0 | J17: ='Юнит 11'!T$68 -> 0 | K17: ='Юнит 11'!U$68 -> 0 | L17: =IFERROR(J17+K17,0) -> 0 | M17: ='Юнит 11'!W$68 -> 0 | N17: ='Юнит 11'!X$68 -> 0 | O17: =IFERROR(M17+N17,0) -> 0 | P17: ='Юнит 11'!AB$68 -> 0 | Q17: ='Юнит 11'!AE$68 -> 198.82 | R17: ='Юнит 11'!AC$68 -> 0 | S17: ='Юнит 11'!AI$68 -> 0 | T17: 195 | U17: ='Юнит 11'!AJ$68 -> 0 | W17: ='Юнит 11'!AF$68 -> 12080 | X17: ='Юнит 11'!AG$68 -> 0 | Y17: ='Юнит 11'!AH137 -> 0 | Z17: =IFERROR((L17)*0.01,0) -> 0 | AB17: =O17-SUM(P17:Y17)+AA17 -> -12473.82 | AC17: =O17-SUM(P17:Z17)+AA17 -> -12473.82 | AE17: =P17/O17 -> #DIV/0! | AF17: =AC17/P17 -> #DIV/0! | AG17: =AC17/O17 -> #DIV/0! | AH17: =(W17+X17+Y17)/O17 -> #DIV/0!
B18: Март 3 очки | C18: 16-22.03 | D18: 12 | F18: =IFERROR(O18-SUM(Q18:W18)+AA18,0) -> 460743.49 | G18: ='Юнит 12'!L$58 -> 1912 | H18: ='Юнит 12'!Q$58 -> 947 | I18: ='Юнит 12'!R$58 -> -22 | J18: ='Юнит 12'!T$58 -> 770335.74 | K18: ='Юнит 12'!U$58 -> -17585.11 | L18: =IFERROR(J18+K18,0) -> 752750.63 | M18: ='Юнит 12'!W$58 -> 1160661.8 | N18: ='Юнит 12'!X$58 -> -26564.08 | O18: =IFERROR(M18+N18,0) -> 1134097.7 | P18: ='Юнит 12'!AB$58 -> 122764.06 | Q18: ='Юнит 12'!AE$58 -> 116519.87 | R18: ='Юнит 12'!AC$58 -> 428981.74 | S18: ='Юнит 12'!AI$58 -> 2973.3315 | T18: 300 | U18: ='Юнит 12'!AJ$58 -> 0 | V18: 3528.24 | W18: ='Юнит 12'!AF$58 -> 121051 | X18: ='Юнит 12'!AG$58 -> 0 | Y18: ='Юнит 12'!AH138 -> 0 | Z18: =7525.32*O18/(O18+O19) -> 7481.2543 | AB18: =O18-SUM(P18:Y18)+AA18 -> 337979.43 | AC18: =O18-SUM(P18:Z18)+AA18 -> 330498.17 | AE18: =P18/O18 -> 0.10824823 | AF18: =AC18/P18 -> 2.6921411 | AG18: =AC18/O18 -> 0.2914195 | AH18: =(W18+X18+Y18)/O18 -> 0.10673772
B19: Март 3 шапки | C19: 16-22.03 | D19: 12 | F19: =IFERROR(O19-SUM(Q19:W19)+AA19,0) -> -2556.9685 | G19: ='Юнит 12'!L$68 -> 4 | H19: ='Юнит 12'!Q$68 -> 3 | I19: ='Юнит 12'!R$68 -> 0 | J19: ='Юнит 12'!T$68 -> 4468 | K19: ='Юнит 12'!U$68 -> 0 | L19: =IFERROR(J19+K19,0) -> 4468 | M19: ='Юнит 12'!W$68 -> 6680 | N19: ='Юнит 12'!X$68 -> 0 | O19: =IFERROR(M19+N19,0) -> 6680 | P19: ='Юнит 12'!AB$68 -> 1187.34 | Q19: ='Юнит 12'!AE$68 -> 2459.75 | R19: ='Юнит 12'!AC$68 -> 2953.15 | S19: ='Юнит 12'!AI$68 -> 3.7884878 | T19: 75 | U19: ='Юнит 12'!AJ$68 -> 3745.28 | W19: ='Юнит 12'!AF$68 -> 0 | X19: ='Юнит 12'!AG$68 -> 0 | Y19: ='Юнит 12'!AH139 -> 0 | Z19: =7525.32*O19/(O18+O19) -> 44.065675 | AB19: =O19-SUM(P19:Y19)+AA19 -> -3744.3085 | AC19: =O19-SUM(P19:Z19)+AA19 -> -3788.3742 | AE19: =P19/O19 -> 0.17774551 | AF19: =AC19/P19 -> -3.1906397 | AG19: =AC19/O19 -> -0.56712188 | AH19: =(W19+X19+Y19)/O19 -> 0
B20: Март 4 очки | C20: 23-29.03 | D20: 13 | F20: =IFERROR(O20-SUM(Q20:W20)+AA20,0) -> 545173.78 | G20: ='Юнит 13'!L$58 -> 1741 | H20: ='Юнит 13'!Q$58 -> 1033 | I20: ='Юнит 13'!R$58 -> -22 | J20: ='Юнит 13'!T$58 -> 894331.41 | K20: ='Юнит 13'!U$58 -> -18419.39 | L20: =IFERROR(J20+K20,0) -> 875912.02 | M20: ='Юнит 13'!W$58 -> 1343124.6 | N20: ='Юнит 13'!X$58 -> -28012.89 | O20: =IFERROR(M20+N20,0) -> 1315111.7 | P20: ='Юнит 13'!AB$58 -> 133965.07 | Q20: ='Юнит 13'!AE$58 -> 138495.53 | R20: ='Юнит 13'!AC$58 -> 495515.23 | S20: ='Юнит 13'!AI$58 -> 5304.7482 | T20: 30 | U20: ='Юнит 13'!AJ$58 -> 70 | V20: 1610.4 | W20: ='Юнит 13'!AF$58 -> 128912 | X20: ='Юнит 13'!AG$58 -> 0 | Y20: ='Юнит 13'!AH140 -> 0 | Z20: 8476.9 | AB20: =O20-SUM(P20:Y20)+AA20 -> 411208.71 | AC20: =O20-SUM(P20:Z20)+AA20 -> 402731.81 | AE20: =P20/O20 -> 0.10186593 | AF20: =AC20/P20 -> 3.0062449 | AG20: =AC20/O20 -> 0.30623392 | AH20: =(W20+X20+Y20)/O20 -> 0.098023613
B21: Март 4 шапки | C21: 23-29.03 | D21: 13 | F21: =IFERROR(O21-SUM(Q21:W21)+AA21,0) -> -1204.2518 | G21: ='Юнит 13'!L$68 -> 0 | H21: ='Юнит 13'!Q$68 -> 0 | I21: ='Юнит 13'!R$68 -> 0 | J21: ='Юнит 13'!T$68 -> 0 | K21: ='Юнит 13'!U$68 -> 0 | L21: =IFERROR(J21+K21,0) -> 0 | M21: ='Юнит 13'!W$68 -> 0 | N21: ='Юнит 13'!X$68 -> 0 | O21: =IFERROR(M21+N21,0) -> 0 | P21: ='Юнит 13'!AB$68 -> 0 | Q21: ='Юнит 13'!AE$68 -> 1195.55 | R21: ='Юнит 13'!AC$68 -> 0 | S21: ='Юнит 13'!AI$68 -> 8.7017952 | U21: ='Юнит 13'!AJ$68 -> 0 | W21: ='Юнит 13'!AF$68 -> 0 | X21: ='Юнит 13'!AG$68 -> 0 | Y21: ='Юнит 13'!AH141 -> 0 | Z21: =IFERROR((L21)*0.01,0) -> 0 | AB21: =O21-SUM(P21:Y21)+AA21 -> -1204.2518 | AC21: =O21-SUM(P21:Z21)+AA21 -> -1204.2518 | AE21: =P21/O21 -> #DIV/0! | AF21: =AC21/P21 -> #DIV/0! | AG21: =AC21/O21 -> #DIV/0! | AH21: =(W21+X21+Y21)/O21 -> #DIV/0!
B22: Апрель 1 очки | C22: 30.03-05.04 | D22: 14 | F22: =IFERROR(O22-SUM(Q22:W22)+AA22,0) -> 458789.03 | G22: ='Юнит 14'!L$58 -> 1458 | H22: ='Юнит 14'!Q$58 -> 957 | I22: ='Юнит 14'!R$58 -> -29 | J22: ='Юнит 14'!T$58 -> 818298.19 | K22: ='Юнит 14'!U$58 -> -24782 | L22: =IFERROR(J22+K22,0) -> 793516.19 | M22: ='Юнит 14'!W$58 -> 1234216.1 | N22: ='Юнит 14'!X$58 -> -37862 | O22: =IFERROR(M22+N22,0) -> 1196354.1 | P22: ='Юнит 14'!AB$58 -> 123010.15 | Q22: ='Юнит 14'!AE$58 -> 131915.07 | R22: ='Юнит 14'!AC$58 -> 450831.19 | S22: ='Юнит 14'!AI$58 -> 7319.828 | U22: ='Юнит 14'!AJ$58 -> 100 | V22: 1464 | W22: ='Юнит 14'!AF$58 -> 145935 | X22: ='Юнит 14'!AG$58 -> 788 | Y22: ='Юнит 14'!AH142 -> 0 | Z22: =IFERROR((L22)*0.01,0) -> 7935.1619 | AB22: =O22-SUM(P22:Y22)+AA22 -> 334990.88 | AC22: =O22-SUM(P22:Z22)+AA22 -> 327055.72 | AD22: =SUM(AC22:AC31) -> 992641.16 | AE22: =P22/O22 -> 0.10282085 | AF22: =AC22/P22 -> 2.6587702 | AG22: =AC22/O22 -> 0.27337702 | AH22: =(W22+X22+Y22)/O22 -> 0.12264178
B23: Апрель 1 шапки | C23: 30.03-05.04 | D23: 14 | F23: =IFERROR(O23-SUM(Q23:W23)+AA23,0) -> -211.39204 | G23: ='Юнит 14'!L$68 -> 1 | H23: ='Юнит 14'!Q$68 -> 0 | I23: ='Юнит 14'!R$68 -> 0 | J23: ='Юнит 14'!T$68 -> 0 | K23: ='Юнит 14'!U$68 -> 0 | L23: =IFERROR(J23+K23,0) -> 0 | M23: ='Юнит 14'!W$68 -> 0 | N23: ='Юнит 14'!X$68 -> 0 | O23: =IFERROR(M23+N23,0) -> 0 | P23: ='Юнит 14'!AB$68 -> 0 | Q23: ='Юнит 14'!AE$68 -> 198.82 | R23: ='Юнит 14'!AC$68 -> 0 | S23: ='Юнит 14'!AI$68 -> 12.572039 | U23: ='Юнит 14'!AJ$68 -> 0 | W23: ='Юнит 14'!AF$68 -> 0 | X23: ='Юнит 14'!AG$68 -> 0 | Y23: ='Юнит 14'!AH143 -> 0 | Z23: =IFERROR((L23)*0.01,0) -> 0 | AB23: =O23-SUM(P23:Y23)+AA23 -> -211.39204 | AC23: =O23-SUM(P23:Z23)+AA23 -> -211.39204 | AE23: =P23/O23 -> #DIV/0! | AF23: =AC23/P23 -> #DIV/0! | AG23: =AC23/O23 -> #DIV/0! | AH23: =(W23+X23+Y23)/O23 -> #DIV/0!
B24: Апрель 2 очки | C24: 06-12.04 | D24: 15 | F24: =IFERROR(O24-SUM(Q24:W24)+AA24,0) -> 308596.97 | G24: ='Юнит 15'!L$58 -> 1031 | H24: ='Юнит 15'!Q$58 -> 649 | I24: ='Юнит 15'!R$58 -> -15 | J24: ='Юнит 15'!T$58 -> 565037.61 | K24: ='Юнит 15'!U$58 -> -13075 | L24: =IFERROR(J24+K24,0) -> 551962.61 | M24: ='Юнит 15'!W$58 -> 842036.95 | N24: ='Юнит 15'!X$58 -> -19867 | O24: =IFERROR(M24+N24,0) -> 822169.95 | P24: ='Юнит 15'!AB$58 -> 84927.51 | Q24: ='Юнит 15'!AE$58 -> 91879.1 | R24: ='Юнит 15'!AC$58 -> 310403.9 | S24: ='Юнит 15'!AI$58 -> 6994.9839 | U24: ='Юнит 15'!AJ$58 -> 30 | W24: ='Юнит 15'!AF$58 -> 104265 | X24: ='Юнит 15'!AG$58 -> 0 | Y24: ='Юнит 15'!AH144 -> 0 | Z24: =IFERROR((L24)*0.01,0) -> 5519.6261 | AB24: =O24-SUM(P24:Y24)+AA24 -> 223669.46 | AC24: =O24-SUM(P24:Z24)+AA24 -> 218149.83 | AE24: =P24/O24 -> 0.10329678 | AF24: =AC24/P24 -> 2.5686592 | AG24: =AC24/O24 -> 0.26533423 | AH24: =(W24+X24+Y24)/O24 -> 0.12681685
B25: Апрель 2 шапки | C25: 06-12.04 | D25: 15 | F25: =IFERROR(O25-SUM(Q25:W25)+AA25,0) -> -163.32611 | G25: ='Юнит 15'!L$68 -> 0 | H25: ='Юнит 15'!Q$68 -> 0 | I25: ='Юнит 15'!R$68 -> 0 | J25: ='Юнит 15'!T$68 -> 0 | K25: ='Юнит 15'!U$68 -> 0 | L25: =IFERROR(J25+K25,0) -> 0 | M25: ='Юнит 15'!W$68 -> 0 | N25: ='Юнит 15'!X$68 -> 0 | O25: =IFERROR(M25+N25,0) -> 0 | P25: ='Юнит 15'!AB$68 -> 0 | Q25: ='Юнит 15'!AE$68 -> 148.68 | R25: ='Юнит 15'!AC$68 -> 0 | S25: ='Юнит 15'!AI$68 -> 14.646114 | U25: ='Юнит 15'!AJ$68 -> 0 | W25: ='Юнит 15'!AF$68 -> 0 | X25: ='Юнит 15'!AG$68 -> 0 | Y25: ='Юнит 15'!AH145 -> 0 | Z25: =IFERROR((L25)*0.01,0) -> 0 | AB25: =O25-SUM(P25:Y25)+AA25 -> -163.32611 | AC25: =O25-SUM(P25:Z25)+AA25 -> -163.32611 | AE25: =P25/O25 -> #DIV/0! | AF25: =AC25/P25 -> #DIV/0! | AG25: =AC25/O25 -> #DIV/0! | AH25: =(W25+X25+Y25)/O25 -> #DIV/0!
B26: Апрель 3 очки | C26: 13-19.04 | D26: 16 | F26: =IFERROR(O26-SUM(Q26:W26)+AA26,0) -> 274995.95 | G26: ='Юнит 16'!L$58 -> 1081 | H26: ='Юнит 16'!Q$58 -> 638 | I26: ='Юнит 16'!R$58 -> -9 | J26: ='Юнит 16'!T$58 -> 548435.46 | K26: ='Юнит 16'!U$58 -> -7418.64 | L26: =IFERROR(J26+K26,0) -> 541016.82 | M26: ='Юнит 16'!W$58 -> 817854.85 | N26: ='Юнит 16'!X$58 -> -11109.77 | O26: =IFERROR(M26+N26,0) -> 806745.08 | P26: ='Юнит 16'!AB$58 -> 85073.03 | Q26: ='Юнит 16'!AE$58 -> 97296.2 | R26: ='Юнит 16'!AC$58 -> 303420.29 | S26: ='Юнит 16'!AI$58 -> 6515.645 | U26: ='Юнит 16'!AJ$58 -> 300 | W26: ='Юнит 16'!AF$58 -> 124217 | X26: ='Юнит 16'!AG$58 -> 0 | Y26: ='Юнит 16'!AH146 -> 0 | Z26: =IFERROR((L26)*0.01,0) -> 5410.1682 | AB26: =O26-SUM(P26:Y26)+AA26 -> 189922.92 | AC26: =O26-SUM(P26:Z26)+AA26 -> 184512.75 | AE26: =P26/O26 -> 0.10545218 | AF26: =AC26/P26 -> 2.1688748 | AG26: =AC26/O26 -> 0.22871258 | AH26: =(W26+X26+Y26)/O26 -> 0.15397305
B27: Апрель 3 шапки | C27: 13-19.04 | D27: 16 | F27: =IFERROR(O27-SUM(Q27:W27)+AA27,0) -> -14.815018 | G27: ='Юнит 16'!L$68 -> 0 | H27: ='Юнит 16'!Q$68 -> 0 | I27: ='Юнит 16'!R$68 -> 0 | J27: ='Юнит 16'!T$68 -> 0 | K27: ='Юнит 16'!U$68 -> 0 | L27: =IFERROR(J27+K27,0) -> 0 | M27: ='Юнит 16'!W$68 -> 0 | N27: ='Юнит 16'!X$68 -> 0 | O27: =IFERROR(M27+N27,0) -> 0 | P27: ='Юнит 16'!AB$68 -> 0 | Q27: ='Юнит 16'!AE$68 -> 0 | R27: ='Юнит 16'!AC$68 -> 0 | S27: ='Юнит 16'!AI$68 -> 14.815018 | U27: ='Юнит 16'!AJ$68 -> 0 | W27: ='Юнит 16'!AF$68 -> 0 | X27: ='Юнит 16'!AG$68 -> 0 | Y27: ='Юнит 16'!AH147 -> 0 | Z27: =IFERROR((L27)*0.01,0) -> 0 | AB27: =O27-SUM(P27:Y27)+AA27 -> -14.815018 | AC27: =O27-SUM(P27:Z27)+AA27 -> -14.815018 | AE27: =P27/O27 -> #DIV/0! | AF27: =AC27/P27 -> #DIV/0! | AG27: =AC27/O27 -> #DIV/0! | AH27: =(W27+X27+Y27)/O27 -> #DIV/0!
B28: Апрель 4 очки | C28: 20-26.04 | D28: 17 | F28: =IFERROR(O28-SUM(Q28:W28)+AA28,0) -> 208993.55 | G28: ='Юнит 17'!L$58 -> 765 | H28: ='Юнит 17'!Q$58 -> 508 | I28: ='Юнит 17'!R$58 -> -5 | J28: ='Юнит 17'!T$58 -> 446671.25 | K28: ='Юнит 17'!U$58 -> -4383 | L28: =IFERROR(J28+K28,0) -> 442288.25 | M28: ='Юнит 17'!W$58 -> 653283.95 | N28: ='Юнит 17'!X$58 -> -6573 | O28: =IFERROR(M28+N28,0) -> 646710.95 | P28: ='Юнит 17'!AB$58 -> 66479.62 | Q28: ='Юнит 17'!AE$58 -> 71227.13 | R28: ='Юнит 17'!AC$58 -> 244596.21 | S28: ='Юнит 17'!AI$58 -> 6101.0598 | U28: ='Юнит 17'!AJ$58 -> 260 | W28: ='Юнит 17'!AF$58 -> 115533 | X28: ='Юнит 17'!AG$58 -> 0 | Y28: ='Юнит 17'!AH148 -> 0 | Z28: =IFERROR((L28)*0.01,0) -> 4422.8825 | AB28: =O28-SUM(P28:Y28)+AA28 -> 142513.93 | AC28: =O28-SUM(P28:Z28)+AA28 -> 138091.05 | AE28: =P28/O28 -> 0.1027965 | AF28: =AC28/P28 -> 2.0771937 | AG28: =AC28/O28 -> 0.21352823 | AH28: =(W28+X28+Y28)/O28 -> 0.17864704
B29: Апрель 4 шапки | C29: 20-26.04 | D29: 17 | F29: =IFERROR(O29-SUM(Q29:W29)+AA29,0) -> -14.640201 | G29: ='Юнит 17'!L$68 -> 0 | H29: ='Юнит 17'!Q$68 -> 0 | I29: ='Юнит 17'!R$68 -> 0 | J29: ='Юнит 17'!T$68 -> 0 | K29: ='Юнит 17'!U$68 -> 0 | L29: =IFERROR(J29+K29,0) -> 0 | M29: ='Юнит 17'!W$68 -> 0 | N29: ='Юнит 17'!X$68 -> 0 | O29: =IFERROR(M29+N29,0) -> 0 | P29: ='Юнит 17'!AB$68 -> 0 | Q29: ='Юнит 17'!AE$68 -> 0 | R29: ='Юнит 17'!AC$68 -> 0 | S29: ='Юнит 17'!AI$68 -> 14.640201 | U29: ='Юнит 17'!AJ$68 -> 0 | W29: ='Юнит 17'!AF$68 -> 0 | X29: ='Юнит 17'!AG$68 -> 0 | Y29: ='Юнит 17'!AH149 -> 0 | Z29: =IFERROR((L29)*0.01,0) -> 0 | AB29: =O29-SUM(P29:Y29)+AA29 -> -14.640201 | AC29: =O29-SUM(P29:Z29)+AA29 -> -14.640201 | AE29: =P29/O29 -> #DIV/0! | AF29: =AC29/P29 -> #DIV/0! | AG29: =AC29/O29 -> #DIV/0! | AH29: =(W29+X29+Y29)/O29 -> #DIV/0!
B30: Апрель 5 очки | C30: 27.04-03.05 | D30: 18 | F30: =IFERROR(O30-SUM(Q30:W30)+AA30,0) -> 189562.38 | G30: ='Юнит 18'!L$58 -> 792 | H30: ='Юнит 18'!Q$58 -> 468 | I30: ='Юнит 18'!R$58 -> -10 | J30: ='Юнит 18'!T$58 -> 410333.48 | K30: ='Юнит 18'!U$58 -> -8792.85 | L30: =IFERROR(J30+K30,0) -> 401540.63 | M30: ='Юнит 18'!W$58 -> 576307.26 | N30: ='Юнит 18'!X$58 -> -12539.93 | O30: =IFERROR(M30+N30,0) -> 563767.33 | P30: ='Юнит 18'!AB$58 -> 60278.12 | Q30: ='Юнит 18'!AE$58 -> 62131.89 | R30: ='Юнит 18'!AC$58 -> 213539.48 | S30: ='Юнит 18'!AI$58 -> 5723.5761 | U30: ='Юнит 18'!AJ$58 -> 827 | W30: ='Юнит 18'!AF$58 -> 91983 | X30: ='Юнит 18'!AG$58 -> 0 | Y30: ='Юнит 18'!AH150 -> 0 | Z30: =IFERROR((L30)*0.01,0) -> 4015.4063 | AB30: =O30-SUM(P30:Y30)+AA30 -> 129284.26 | AC30: =O30-SUM(P30:Z30)+AA30 -> 125268.86 | AE30: =P30/O30 -> 0.10692021 | AF30: =AC30/P30 -> 2.0781812 | AG30: =AC30/O30 -> 0.22219957 | AH30: =(W30+X30+Y30)/O30 -> 0.16315773
B31: Апрель 5 шапки | C31: 27.04-03.05 | D31: 18 | F31: =IFERROR(O31-SUM(Q31:W31)+AA31,0) -> -32.863858 | G31: ='Юнит 18'!L$68 -> 0 | H31: ='Юнит 18'!Q$68 -> 0 | I31: ='Юнит 18'!R$68 -> 0 | J31: ='Юнит 18'!T$68 -> 0 | K31: ='Юнит 18'!U$68 -> 0 | L31: =IFERROR(J31+K31,0) -> 0 | M31: ='Юнит 18'!W$68 -> 0 | N31: ='Юнит 18'!X$68 -> 0 | O31: =IFERROR(M31+N31,0) -> 0 | P31: ='Юнит 18'!AB$68 -> 0 | Q31: ='Юнит 18'!AE$68 -> 18 | R31: ='Юнит 18'!AC$68 -> 0 | S31: ='Юнит 18'!AI$68 -> 14.863858 | U31: ='Юнит 18'!AJ$68 -> 0 | W31: ='Юнит 18'!AF$68 -> 0 | X31: ='Юнит 18'!AG$68 -> 0 | Y31: ='Юнит 18'!AH151 -> 0 | Z31: =IFERROR((L31)*0.01,0) -> 0 | AB31: =O31-SUM(P31:Y31)+AA31 -> -32.863858 | AC31: =O31-SUM(P31:Z31)+AA31 -> -32.863858 | AE31: =P31/O31 -> #DIV/0! | AF31: =AC31/P31 -> #DIV/0! | AG31: =AC31/O31 -> #DIV/0! | AH31: =(W31+X31+Y31)/O31 -> #DIV/0!
B32: Май 1 очки | C32: 04-10.05 | D32: 19 | F32: =IFERROR(O32-SUM(Q32:W32)+AA32,0) -> 294239.53 | G32: ='Юнит 19'!L$64 -> 1366 | H32: ='Юнит 19'!Q$64 -> 712 | I32: ='Юнит 19'!R$64 -> -12 | J32: ='Юнит 19'!T$64 -> 623893.13 | K32: ='Юнит 19'!U$64 -> -10793 | L32: =IFERROR(J32+K32,0) -> 613100.13 | M32: ='Юнит 19'!W$64 -> 864482.03 | N32: ='Юнит 19'!X$64 -> -14966 | O32: =IFERROR(M32+N32,0) -> 849516.03 | P32: ='Юнит 19'!AB$64 -> 90756.23 | Q32: ='Юнит 19'!AE$64 -> 77440.42 | R32: ='Юнит 19'!AC$64 -> 321797.17 | S32: ='Юнит 19'!AI$64 -> 5038.9143 | T32: 435 | U32: ='Юнит 19'!AJ$64 -> 190 | W32: ='Юнит 19'!AF$64 -> 150375 | X32: ='Юнит 19'!AG$64 -> 8172 | Y32: ='Юнит 19'!AH152 -> 0 | Z32: =IFERROR((L32)*0.01,0) -> 6131.0013 | AB32: =O32-SUM(P32:Y32)+AA32 -> 195311.3 | AC32: =O32-SUM(P32:Z32)+AA32 -> 189180.29 | AE32: =P32/O32 -> 0.10683286 | AF32: =AC32/P32 -> 2.0844882 | AG32: =AC32/O32 -> 0.22269185 | AH32: =(W32+X32+Y32)/O32 -> 0.18663215
B33: Май 1 шапки | C33: 04-10.05 | D33: 19 | F33: =IFERROR(O33-SUM(Q33:W33)+AA33,0) -> -15.835683 | G33: ='Юнит 19'!L$74 -> 0 | H33: ='Юнит 19'!Q$74 -> 0 | I33: ='Юнит 19'!R$74 -> 0 | J33: ='Юнит 19'!T$74 -> 0 | K33: ='Юнит 19'!U$74 -> 0 | L33: =IFERROR(J33+K33,0) -> 0 | M33: ='Юнит 19'!W$74 -> 0 | N33: ='Юнит 19'!X$74 -> 0 | O33: =IFERROR(M33+N33,0) -> 0 | P33: ='Юнит 19'!AB$74 -> 0 | Q33: ='Юнит 19'!AE$74 -> 0 | R33: ='Юнит 19'!AC$74 -> 0 | S33: ='Юнит 19'!AI$74 -> 15.835683 | U33: ='Юнит 19'!AJ$74 -> 0 | W33: ='Юнит 19'!AF$74 -> 0 | X33: ='Юнит 19'!AG$74 -> 0 | Y33: ='Юнит 19'!AH153 -> 0 | Z33: =IFERROR((L33)*0.01,0) -> 0 | AB33: =O33-SUM(P33:Y33)+AA33 -> -15.835683 | AC33: =O33-SUM(P33:Z33)+AA33 -> -15.835683 | AE33: =P33/O33 -> #DIV/0! | AF33: =AC33/P33 -> #DIV/0! | AG33: =AC33/O33 -> #DIV/0! | AH33: =(W33+X33+Y33)/O33 -> #DIV/0!
AB39: =O39-SUM(P39:Y39)+AA39 -> 0 | AC39: =O39-SUM(P39:Z39)+AA39 -> 0 | AE39: =P39/O39 -> #DIV/0! | AF39: =AC39/P39 -> #DIV/0! | AG39: =AC39/O39 -> #DIV/0! | AH39: =(W39+X39+Y39)/O39 -> #DIV/0!
B40: Итого | F40: =SUM(F4:F39) -> 3953363.3 | G40: =SUM(G4:G39) -> 14908 | H40: =SUM(H4:H39) -> 8411 | I40: =SUM(I4:I39) -> -165 | J40: =SUM(J4:J39) -> 6990992.7 | K40: =SUM(K4:K39) -> -137350.4 | L40: =SUM(L4:L39) -> 6853642.3 | M40: =SUM(M4:M39) -> 10404154 | ... AD40: =SUM(AD4:AD39) -> 2415213.8 | AE40: =P40/O40 -> 0.10745505 | AF40: =AC40/P40 -> 2.3768004 | AG40: =AC40/O40 -> 0.25539922 | AH40: =(W40+X40+Y40)/O40 -> 0.14008976
M41: % от выручки за весь период
N42: =-N40/M40 -> 0.019883463 | P42: =P40/$O$40 -> 0.10745505 | Q42: =Q40/$O$40 -> 0.10592254 | R42: =R40/$O$40 -> 0.37631855 | S42: =S40/$O$40 -> 0.0060375441 | T42: =T40/$O$40 -> 0.00043835203 | U42: =U40/$O$40 -> 0.00057331738 | V42: =V40/$O$40 -> 0.0010852302 | W42: =W40/$O$40 -> 0.12193659 | ... Z42: =Z40/$O$40 -> 0.0066804424 | AD42: =AC40/P40 -> 2.3768004 | AE42: Маржинальность, %
W43: =(W40+X40)/O40 -> 0.14008976 | AD43: =AC40/O40 -> 0.25539922 | AE43: Рентабельность, %
B45: ЯНВАРЬ | G45: =SUM(G4:G9) -> 457 | H45: =SUM(H4:H9) -> 256 | I45: =SUM(I4:I9) -> -5 | J45: =SUM(J4:J9) -> 233222.72 | K45: =SUM(K4:K9) -> -4580 | L45: =SUM(L4:L9) -> 228642.72 | M45: =SUM(M4:M9) -> 303779.89 | N45: =SUM(N4:N9) -> -6023 | ... AA45: =SUM(AA4:AA9) -> 0 | AC45: =SUM(AC4:AC9) -> 67154.08 | AD45: =AC45/P45 -> 1.9562269
N46: =-N45/M45 -> 0.019826856 | P46: =P45/$O$45 -> 0.11528993 | Q46: =Q45/$O$45 -> 0.10403135 | R46: =R45/$O$45 -> 0.35897977 | S46: =S45/$O$45 -> 0.021195076 | T46: =T45/$O$45 -> 0 | U46: =U45/$O$45 -> 0 | V46: =V45/$O$45 -> 0.0032402273 | W46: =W45/$O$45 -> 0.075400438 | ... AA46: =AA45/$O$45 -> 0 | AC46: =AC45/O45 -> 0.22553325 | AD46: =AC45/O45 -> 0.22553325
B48: ФЕВРАЛЬ | G48: =SUM(G10:G13) -> 1946 | H48: =SUM(H10:H13) -> 1061 | I48: =SUM(I10:I13) -> -15 | J48: =SUM(J10:J13) -> 763365.39 | K48: =SUM(K10:K13) -> -10935 | L48: =SUM(L10:L13) -> 752430.39 | M48: =SUM(M10:M13) -> 1191764.6 | N48: =SUM(N10:N13) -> -17408 | ... AC48: =SUM(AC10:AC13) -> 265557.06 | AD48: =AC48/P48 -> 1.896249
...

Sheet АВС 20
B2: ОЧКИ
C3: Прибыль | D3: % прибыль | E3: Доля | F3: ABC прибыль | G3: ABC кол-во | J3: Кол-во | K3: % кол-во | L3: Доля | M3: ABC кол-во
B4: Черные с железкой Сул | D4: =C4/C$64 -> #DIV/0! | E4: =D4 -> #DIV/0! | F4: =IF(AND(E4<=0),"C",IF(E4<=0.8,"A",IF(E4<=0.95,"B","C"))) -> #DIV/0! | G4: =VLOOKUP(B$4:B$57,I$4:M$57,5,0) -> #DIV/0! | I4: Черные с железкой Сул | K4: =J4/J$64 -> #DIV/0! | L4: =K4 -> #DIV/0! | M4: =_xlfn.IFS(L4<80%,"A",L4<=95%,"B",L4>95%,"C") -> #DIV/0! | P4: A | Q4: 0.8
B5: Qs черн Сул | D5: =C5/C$64 -> #DIV/0! | E5: =E4+D5 -> #DIV/0! | F5: =IF(AND(E5<=0),"C",IF(E5<=0.8,"A",IF(E5<=0.95,"B","C"))) -> #DIV/0! | G5: =VLOOKUP(B$4:B$57,I$4:M$57,5,0) -> #DIV/0! | I5: Qs черн Сул | K5: =J5/J$64 -> #DIV/0! | L5: =L4+K5 -> #DIV/0! | M5: =_xlfn.IFS(L5<80%,"A",L5<=95%,"B",L5>95%,"C") -> #DIV/0! | P5: B | Q5: 0.15
B6: Qs син Сул | D6: =C6/C$64 -> #DIV/0! | E6: =E5+D6 -> #DIV/0! | F6: =IF(AND(E6<=0),"C",IF(E6<=0.8,"A",IF(E6<=0.95,"B","C"))) -> #DIV/0! | G6: =VLOOKUP(B$4:B$57,I$4:M$57,5,0) -> #DIV/0! | I6: Qs син Сул | K6: =J6/J$64 -> #DIV/0! | L6: =L5+K6 -> #DIV/0! | M6: =_xlfn.IFS(L6<80%,"A",L6<=95%,"B",L6>95%,"C") -> #DIV/0! | P6: C | Q6: 0.05
B7: Qs желт Сул | D7: =C7/C$64 -> #DIV/0! | E7: =E6+D7 -> #DIV/0! | F7: =IF(AND(E7<=0),"C",IF(E7<=0.8,"A",IF(E7<=0.95,"B","C"))) -> #DIV/0! | G7: =VLOOKUP(B$4:B$57,I$4:M$57,5,0) -> #DIV/0! | I7: Qs желт Сул | K7: =J7/J$64 -> #DIV/0! | L7: =L6+K7 -> #DIV/0! | M7: =_xlfn.IFS(L7<80%,"A",L7<=95%,"B",L7>95%,"C") -> #DIV/0!
B8: flip черные Сул | D8: =C8/C$64 -> #DIV/0! | E8: =E7+D8 -> #DIV/0! | F8: =IF(AND(E8<=0),"C",IF(E8<=0.8,"A",IF(E8<=0.95,"B","C"))) -> #DIV/0! | G8: =VLOOKUP(B$4:B$57,I$4:M$57,5,0) -> #DIV/0! | I8: flip черные Сул | K8: =J8/J$64 -> #DIV/0! | L8: =L7+K8 -> #DIV/0! | M8: =_xlfn.IFS(L8<80%,"A",L8<=95%,"B",L8>95%,"C") -> #DIV/0!
B9: flip желтые Сул | D9: =C9/C$64 -> #DIV/0! | E9: =E8+D9 -> #DIV/0! | F9: =IF(AND(E9<=0),"C",IF(E9<=0.8,"A",IF(E9<=0.95,"B","C"))) -> #DIV/0! | G9: =VLOOKUP(B$4:B$57,I$4:M$57,5,0) -> #DIV/0! | I9: flip желтые Сул | K9: =J9/J$64 -> #DIV/0! | L9: =L8+K9 -> #DIV/0! | M9: =_xlfn.IFS(L9<80%,"A",L9<=95%,"B",L9>95%,"C") -> #DIV/0!
B10: MR8854 C2 Сул | D10: =C10/C$64 -> #DIV/0! | E10: =E9+D10 -> #DIV/0! | F10: =IF(AND(E10<=0),"C",IF(E10<=0.8,"A",IF(E10<=0.95,"B","C"))) -> #DIV/0! | G10: =VLOOKUP(B$4:B$57,I$4:M$57,5,0) -> #DIV/0! | I10: MR8854 C2 Сул | K10: =J10/J$64 -> #DIV/0! | L10: =L9+K10 -> #DIV/0! | M10: =_xlfn.IFS(L10<80%,"A",L10<=95%,"B",L10>95%,"C") -> #DIV/0!
B11: MR 1819 черн | D11: =C11/C$64 -> #DIV/0! | E11: =E10+D11 -> #DIV/0! | F11: =IF(AND(E11<=0),"C",IF(E11<=0.8,"A",IF(E11<=0.95,"B","C"))) -> #DIV/0! | G11: =VLOOKUP(B$4:B$57,I$4:M$57,5,0) -> #DIV/0! | I11: MR 1819 черн | K11: =J11/J$64 -> #DIV/0! | L11: =L10+K11 -> #DIV/0! | M11: =_xlfn.IFS(L11<80%,"A",L11<=95%,"B",L11>95%,"C") -> #DIV/0!
B12: MR 1819 корич | D12: =C12/C$64 -> #DIV/0! | E12: =E11+D12 -> #DIV/0! | F12: =IF(AND(E12<=0),"C",IF(E12<=0.8,"A",IF(E12<=0.95,"B","C"))) -> #DIV/0! | G12: =VLOOKUP(B$4:B$57,I$4:M$57,5,0) -> #DIV/0! | I12: MR 1819 корич | K12: =J12/J$64 -> #DIV/0! | L12: =L11+K12 -> #DIV/0! | M12: =_xlfn.IFS(L12<80%,"A",L12<=95%,"B",L12>95%,"C") -> #DIV/0!
B13: MR Р1874 черн | D13: =C13/C$64 -> #DIV/0! | E13: =E12+D13 -> #DIV/0! | F13: =IF(AND(E13<=0),"C",IF(E13<=0.8,"A",IF(E13<=0.95,"B","C"))) -> #DIV/0! | G13: =VLOOKUP(B$4:B$57,I$4:M$57,5,0) -> #DIV/0! | I13: MR Р1874 черн | K13: =J13/J$64 -> #DIV/0! | L13: =L12+K13 -> #DIV/0! | M13: =_xlfn.IFS(L13<80%,"A",L13<=95%,"B",L13>95%,"C") -> #DIV/0!
B14: MR Р1874 корич | D14: =C14/C$64 -> #DIV/0! | E14: =E13+D14 -> #DIV/0! | F14: =IF(AND(E14<=0),"C",IF(E14<=0.8,"A",IF(E14<=0.95,"B","C"))) -> #DIV/0! | G14: =VLOOKUP(B$4:B$57,I$4:M$57,5,0) -> #DIV/0! | I14: MR Р1874 корич | K14: =J14/J$64 -> #DIV/0! | L14: =L13+K14 -> #DIV/0! | M14: =_xlfn.IFS(L14<80%,"A",L14<=95%,"B",L14>95%,"C") -> #DIV/0!
B15: MR Р1886 черн | D15: =C15/C$64 -> #DIV/0! | E15: =E14+D15 -> #DIV/0! | F15: =IF(AND(E15<=0),"C",IF(E15<=0.8,"A",IF(E15<=0.95,"B","C"))) -> #DIV/0! | G15: =VLOOKUP(B$4:B$57,I$4:M$57,5,0) -> #DIV/0! | I15: MR Р1886 черн | K15: =J15/J$64 -> #DIV/0! | L15: =L14+K15 -> #DIV/0! | M15: =_xlfn.IFS(L15<80%,"A",L15<=95%,"B",L15>95%,"C") -> #DIV/0!
B16: MR Р1886 корич | D16: =C16/C$64 -> #DIV/0! | E16: =E15+D16 -> #DIV/0! | F16: =IF(AND(E16<=0),"C",IF(E16<=0.8,"A",IF(E16<=0.95,"B","C"))) -> #DIV/0! | G16: =VLOOKUP(B$4:B$57,I$4:M$57,5,0) -> #DIV/0! | I16: MR Р1886 корич | K16: =J16/J$64 -> #DIV/0! | L16: =L15+K16 -> #DIV/0! | M16: =_xlfn.IFS(L16<80%,"A",L16<=95%,"B",L16>95%,"C") -> #DIV/0!
B17: MR 1890 черн | D17: =C17/C$64 -> #DIV/0! | E17: =E16+D17 -> #DIV/0! | F17: =IF(AND(E17<=0),"C",IF(E17<=0.8,"A",IF(E17<=0.95,"B","C"))) -> #DIV/0! | G17: =VLOOKUP(B$4:B$57,I$4:M$57,5,0) -> #DIV/0! | I17: MR 1890 черн | K17: =J17/J$64 -> #DIV/0! | L17: =L16+K17 -> #DIV/0! | M17: =_xlfn.IFS(L17<80%,"A",L17<=95%,"B",L17>95%,"C") -> #DIV/0!
B18: MR 1890 желт | D18: =C18/C$64 -> #DIV/0! | E18: =E17+D18 -> #DIV/0! | F18: =IF(AND(E18<=0),"C",IF(E18<=0.8,"A",IF(E18<=0.95,"B","C"))) -> #DIV/0! | G18: =VLOOKUP(B$4:B$57,I$4:M$57,5,0) -> #DIV/0! | I18: MR 1890 желт | K18: =J18/J$64 -> #DIV/0! | L18: =L17+K18 -> #DIV/0! | M18: =_xlfn.IFS(L18<80%,"A",L18<=95%,"B",L18>95%,"C") -> #DIV/0!
... B27: qs009 | D27: =C27/C$64 -> #DIV/0! | E27: =E26+D27 -> #DIV/0! | F27: =IF(AND(E27<=0),"C",IF(E27<=0.8,"A",IF(E27<=0.95,"B","C"))) -> #DIV/0! | G27: =VLOOKUP(B$4:B$57,I$4:M$57,5,0) -> #DIV/0! | I27: qs009 | K27: =J27/J$64 -> #DIV/0! | L27: =L26+K27 -> #DIV/0! | M27: =_xlfn.IFS(L27<80%,"A",L27<=95%,"B",L27>95%,"C") -> #DIV/0!
B28: qs010 | D28: =C28/C$64 -> #DIV/0! | E28: =E24+D28 -> #DIV/0! | F28: =IF(AND(E28<=0),"C",IF(E28<=0.8,"A",IF(E28<=0.95,"B","C"))) -> #DIV/0! | G28: =VLOOKUP(B$4:B$57,I$4:M$57,5,0) -> #DIV/0! | I28: qs010 | K28: =J28/J$64 -> #DIV/0! | L28: =L24+K28 -> #DIV/0! | M28: =_xlfn.IFS(L28<80%,"A",L28<=95%,"B",L28>95%,"C") -> #DIV/0!
B29: qs011 | D29: =C29/C$64 -> #DIV/0! | E29: =E28+D29 -> #DIV/0! | F29: =IF(AND(E29<=0),"C",IF(E29<=0.8,"A",IF(E29<=0.95,"B","C"))) -> #DIV/0! | G29: =VLOOKUP(B$4:B$57,I$4:M$57,5,0) -> #DIV/0! | I29: qs011 | K29: =J29/J$64 -> #DIV/0! | L29: =L28+K29 -> #DIV/0! | M29: =_xlfn.IFS(L29<80%,"A",L29<=95%,"B",L29>95%,"C") -> #DIV/0!
B30: qs012 | D30: =C30/C$64 -> #DIV/0! | E30: =E29+D30 -> #DIV/0! | F30: =IF(AND(E30<=0),"C",IF(E30<=0.8,"A",IF(E30<=0.95,"B","C"))) -> #DIV/0! | G30: =VLOOKUP(B$4:B$57,I$4:M$57,5,0) -> #DIV/0! | I30: qs012 | K30: =J30/J$64 -> #DIV/0! | L30: =L29+K30 -> #DIV/0! | M30: =_xlfn.IFS(L30<80%,"A",L30<=95%,"B",L30>95%,"C") -> #DIV/0!
B31: qs013 | D31: =C31/C$64 -> #DIV/0! | E31: =E30+D31 -> #DIV/0! | F31: =IF(AND(E31<=0),"C",IF(E31<=0.8,"A",IF(E31<=0.95,"B","C"))) -> #DIV/0! | G31: =VLOOKUP(B$4:B$57,I$4:M$57,5,0) -> #DIV/0! | I31: qs013 | K31: =J31/J$64 -> #DIV/0! | L31: =L30+K31 -> #DIV/0! | M31: =_xlfn.IFS(L31<80%,"A",L31<=95%,"B",L31>95%,"C") -> #DIV/0!
B32: qs014 | D32: =C32/C$64 -> #DIV/0! | E32: =E31+D32 -> #DIV/0! | F32: =IF(AND(E32<=0),"C",IF(E32<=0.8,"A",IF(E32<=0.95,"B","C"))) -> #DIV/0! | G32: =VLOOKUP(B$4:B$57,I$4:M$57,5,0) -> #DIV/0! | I32: qs014 | K32: =J32/J$64 -> #DIV/0! | L32: =L31+K32 -> #DIV/0! | M32: =_xlfn.IFS(L32<80%,"A",L32<=95%,"B",L32>95%,"C") -> #DIV/0!
B33: qs015 | D33: =C33/C$64 -> #DIV/0! | E33: =E32+D33 -> #DIV/0! | F33: =IF(AND(E33<=0),"C",IF(E33<=0.8,"A",IF(E33<=0.95,"B","C"))) -> #DIV/0! | G33: =VLOOKUP(B$4:B$57,I$4:M$57,5,0) -> #DIV/0! | I33: qs015 | K33: =J33/J$64 -> #DIV/0! | L33: =L32+K33 -> #DIV/0! | M33: =_xlfn.IFS(L33<80%,"A",L33<=95%,"B",L33>95%,"C") -> #DIV/0!
B34: qs001 Ж | D34: =C34/C$64 -> #DIV/0! | E34: =E33+D34 -> #DIV/0! | F34: =IF(AND(E34<=0),"C",IF(E34<=0.8,"A",IF(E34<=0.95,"B","C"))) -> #DIV/0! | G34: =VLOOKUP(B$4:B$57,I$4:M$57,5,0) -> #DIV/0! | I34: qs001 Ж | K34: =J34/J$64 -> #DIV/0! | L34: =L33+K34 -> #DIV/0! | M34: =_xlfn.IFS(L34<80%,"A",L34<=95%,"B",L34>95%,"C") -> #DIV/0!
B35: qs010ж | D35: =C35/C$64 -> #DIV/0! | E35: =E34+D35 -> #DIV/0! | F35: =IF(AND(E35<=0),"C",IF(E35<=0.8,"A",IF(E35<=0.95,"B","C"))) -> #DIV/0! | G35: =VLOOKUP(B$4:B$57,I$4:M$57,5,0) -> #DIV/0! | I35: qs010ж | K35: =J35/J$64 -> #DIV/0! | L35: =L34+K35 -> #DIV/0! | M35: =_xlfn.IFS(L35<80%,"A",L35<=95%,"B",L35>95%,"C") -> #DIV/0!
B36: qs011ж | D36: =C36/C$64 -> #DIV/0! | E36: =E35+D36 -> #DIV/0! | F36: =IF(AND(E36<=0),"C",IF(E36<=0.8,"A",IF(E36<=0.95,"B","C"))) -> #DIV/0! | G36: =VLOOKUP(B$4:B$57,I$4:M$57,5,0) -> #DIV/0! | I36: qs011ж | K36: =J36/J$64 -> #DIV/0! | L36: =L35+K36 -> #DIV/0! | M36: =_xlfn.IFS(L36<80%,"A",L36<=95%,"B",L36>95%,"C") -> #DIV/0!
B37: qs012ж | D37: =C37/C$64 -> #DIV/0! | E37: =E36+D37 -> #DIV/0! | F37: =IF(AND(E37<=0),"C",IF(E37<=0.8,"A",IF(E37<=0.95,"B","C"))) -> #DIV/0! | G37: =VLOOKUP(B$4:B$57,I$4:M$57,5,0) -> #DIV/0! | I37: qs012ж | K37: =J37/J$64 -> #DIV/0! | L37: =L36+K37 -> #DIV/0! | M37: =_xlfn.IFS(L37<80%,"A",L37<=95%,"B",L37>95%,"C") -> #DIV/0!
B38: 2038ч/б | D38: =C38/C$64 -> #DIV/0! | E38: =E37+D38 -> #DIV/0! | F38: =IF(AND(E38<=0),"C",IF(E38<=0.8,"A",IF(E38<=0.95,"B","C"))) -> #DIV/0! | G38: =VLOOKUP(B$4:B$57,I$4:M$57,5,0) -> #DIV/0! | I38: 2038ч/б | K38: =J38/J$64 -> #DIV/0! | L38: =L37+K38 -> #DIV/0! | M38: =_xlfn.IFS(L38<80%,"A",L38<=95%,"B",L38>95%,"C") -> #DIV/0!
B39: 2038красный | D39: =C39/C$64 -> #DIV/0! | E39: =E38+D39 -> #DIV/0! | F39: =IF(AND(E39<=0),"C",IF(E39<=0.8,"A",IF(E39<=0.95,"B","C"))) -> #DIV/0! | G39: =VLOOKUP(B$4:B$57,I$4:M$57,5,0) -> #DIV/0! | I39: 2038красный | K39: =J39/J$64 -> #DIV/0! | L39: =L38+K39 -> #DIV/0! | M39: =_xlfn.IFS(L39<80%,"A",L39<=95%,"B",L39>95%,"C") -> #DIV/0!
B40: 2100черный | D40: =C40/C$64 -> #DIV/0! | E40: =E39+D40 -> #DIV/0! | F40: =IF(AND(E40<=0),"C",IF(E40<=0.8,"A",IF(E40<=0.95,"B","C"))) -> #DIV/0! | G40: =VLOOKUP(B$4:B$57,I$4:M$57,5,0) -> #DIV/0! | I40: 2100черный | K40: =J40/J$64 -> #DIV/0! | L40: =L39+K40 -> #DIV/0! | M40: =_xlfn.IFS(L40<80%,"A",L40<=95%,"B",L40>95%,"C") -> #DIV/0!
... B57: 8852 | D57: =C57/C$64 -> #DIV/0! | E57: =E56+D57 -> #DIV/0! | F57: =IF(AND(E57<=0),"C",IF(E57<=0.8,"A",IF(E57<=0.95,"B","C"))) -> #DIV/0! | G57: =VLOOKUP(B$4:B$57,I$4:M$57,5,0) -> #DIV/0! | I57: 8852 | K57: =J57/J$64 -> #DIV/0! | L57: =L56+K57 -> #DIV/0! | M57: =_xlfn.IFS(L57<80%,"A",L57<=95%,"B",L57>95%,"C") -> #DIV/0!
B58: 2801 | D58: =C58/C$64 -> #DIV/0! | E58: =E57+D58 -> #DIV/0! | F58: =IF(AND(E58<=0),"C",IF(E58<=0.8,"A",IF(E58<=0.95,"B","C"))) -> #DIV/0! | G58: =VLOOKUP(B$4:B$57,I$4:M$57,5,0) -> #VALUE! | I58: 2801 | K58: =J58/J$64 -> #DIV/0! | L58: =L57+K58 -> #DIV/0! | M58: =_xlfn.IFS(L58<80%,"A",L58<=95%,"B",L58>95%,"C") -> #DIV/0!
B59: 2811 С3 | D59: =C59/C$64 -> #DIV/0! | E59: =E58+D59 -> #DIV/0! | F59: =IF(AND(E59<=0),"C",IF(E59<=0.8,"A",IF(E59<=0.95,"B","C"))) -> #DIV/0! | G59: =VLOOKUP(B$4:B$57,I$4:M$57,5,0) -> #VALUE! | I59: 2811 С3 | K59: =J59/J$64 -> #DIV/0! | L59: =L58+K59 -> #DIV/0! | M59: =_xlfn.IFS(L59<80%,"A",L59<=95%,"B",L59>95%,"C") -> #DIV/0!
B60: 03004 С8-02 | D60: =C60/C$64 -> #DIV/0! | E60: =E59+D60 -> #DIV/0! | F60: =IF(AND(E60<=0),"C",IF(E60<=0.8,"A",IF(E60<=0.95,"B","C"))) -> #DIV/0! | G60: =VLOOKUP(B$4:B$57,I$4:M$57,5,0) -> #VALUE! | I60: 03004 С8-02 | K60: =J60/J$64 -> #DIV/0! | L60: =L59+K60 -> #DIV/0! | M60: =_xlfn.IFS(L60<80%,"A",L60<=95%,"B",L60>95%,"C") -> #DIV/0!
B61: 03004 С9-08 | D61: =C61/C$64 -> #DIV/0! | E61: =E60+D61 -> #DIV/0! | F61: =IF(AND(E61<=0),"C",IF(E61<=0.8,"A",IF(E61<=0.95,"B","C"))) -> #DIV/0! | G61: =VLOOKUP(B$4:B$57,I$4:M$57,5,0) -> #VALUE! | I61: 03004 С9-08 | K61: =J61/J$64 -> #DIV/0! | L61: =L60+K61 -> #DIV/0! | M61: =_xlfn.IFS(L61<80%,"A",L61<=95%,"B",L61>95%,"C") -> #DIV/0!
B62: 03977 С9-08 | D62: =C62/C$64 -> #DIV/0! | E62: =E61+D62 -> #DIV/0! | F62: =IF(AND(E62<=0),"C",IF(E62<=0.8,"A",IF(E62<=0.95,"B","C"))) -> #DIV/0! | G62: =VLOOKUP(B$4:B$57,I$4:M$57,5,0) -> #VALUE! | I62: 03977 С9-08 | K62: =J62/J$64 -> #DIV/0! | L62: =L61+K62 -> #DIV/0! | M62: =_xlfn.IFS(L62<80%,"A",L62<=95%,"B",L62>95%,"C") -> #DIV/0!
B63: 03985 С9-124 | D63: =C63/C$64 -> #DIV/0! | E63: =E62+D63 -> #DIV/0! | F63: =IF(AND(E63<=0),"C",IF(E63<=0.8,"A",IF(E63<=0.95,"B","C"))) -> #DIV/0! | G63: =VLOOKUP(B$4:B$57,I$4:M$57,5,0) -> #VALUE! | I63: 03985 С9-124 | K63: =J63/J$64 -> #DIV/0! | L63: =L62+K63 -> #DIV/0! | M63: =_xlfn.IFS(L63<80%,"A",L63<=95%,"B",L63>95%,"C") -> #DIV/0!
C64: =SUM(C4:C63) -> 0 | D64: =SUM(D4:D44) -> #DIV/0! | J64: =SUM(J4:J63) -> 0 | K64: =SUM(K4:K44) -> #DIV/0!
C67: Прибыль | D67: % прибыль | E67: Доля | F67: ABC прибыль | G67: ABC кол-во | J67: Кол-во | K67: % кол-во | L67: Доля | M67: ABC кол-во
...

Sheet АВС 19
B2: ОЧКИ
C3: Прибыль | D3: % прибыль | E3: Доля | F3: ABC прибыль | G3: ABC кол-во | J3: Кол-во | K3: % кол-во | L3: Доля | M3: ABC кол-во
B4: Qs черн Сул | C4: ='Юнит 19'!AL4 -> 111708.02 | D4: =C4/C$64 -> 0.58807534 | E4: =D4 -> 0.58807534 | F4: =IF(AND(E4<=0),"C",IF(E4<=0.8,"A",IF(E4<=0.95,"B","C"))) -> A | G4: =VLOOKUP(B$4:B$63,I$4:M$63,5,0) -> A | I4: Qs черн Сул | J4: ='Юнит 19'!S4 -> 322 | K4: =J4/J$64 -> 0.46 | L4: =K4 -> 0.46 | M4: =_xlfn.IFS(L4<80%,"A",L4<=95%,"B",L4>95%,"C") -> A | P4: A | Q4: 0.8
B5: Черные с железкой Сул | C5: ='Юнит 19'!AL3 -> 43040.11 | D5: =C5/C$64 -> 0.22658021 | E5: =E4+D5 -> 0.81465554 | F5: =IF(AND(E5<=0),"C",IF(E5<=0.8,"A",IF(E5<=0.95,"B","C"))) -> B | G5: =VLOOKUP(B$4:B$63,I$4:M$63,5,0) -> A | I5: Черные с железкой Сул | J5: ='Юнит 19'!S3 -> 118 | K5: =J5/J$64 -> 0.16857143 | L5: =L4+K5 -> 0.62857143 | M5: =_xlfn.IFS(L5<80%,"A",L5<=95%,"B",L5>95%,"C") -> A | P5: B | Q5: 0.15
B6: flip желтые Сул | C6: ='Юнит 19'!AL8 -> 20857.187 | D6: =C6/C$64 -> 0.1098005 | E6: =E5+D6 -> 0.92445605 | F6: =IF(AND(E6<=0),"C",IF(E6<=0.8,"A",IF(E6<=0.95,"B","C"))) -> B | G6: =VLOOKUP(B$4:B$63,I$4:M$63,5,0) -> A | I6: flip желтые Сул | J6: ='Юнит 19'!S8 -> 62 | K6: =J6/J$64 -> 0.088571429 | L6: =L5+K6 -> 0.71714286 | M6: =_xlfn.IFS(L6<80%,"A",L6<=95%,"B",L6>95%,"C") -> A | P6: C | Q6: 0.05
B7: Qs желт Сул | C7: ='Юнит 19'!AL6 -> 9730.1643 | D7: =C7/C$64 -> 0.051223444 | E7: =E6+D7 -> 0.97567949 | F7: =IF(AND(E7<=0),"C",IF(E7<=0.8,"A",IF(E7<=0.95,"B","C"))) -> C | G7: =VLOOKUP(B$4:B$63,I$4:M$63,5,0) -> B | I7: Qs син Сул | J7: ='Юнит 19'!S5 -> 51 | K7: =J7/J$64 -> 0.072857143 | L7: =L6+K7 -> 0.79 | M7: =_xlfn.IFS(L7<80%,"A",L7<=95%,"B",L7>95%,"C") -> A
B8: flip черные Сул | C8: ='Юнит 19'!AL7 -> 5426.7534 | D8: =C8/C$64 -> 0.028568582 | E8: =E7+D8 -> 1.0042481 | F8: =IF(AND(E8<=0),"C",IF(E8<=0.8,"A",IF(E8<=0.95,"B","C"))) -> C | G8: =VLOOKUP(B$4:B$63,I$4:M$63,5,0) -> B | I8: flip черные Сул | J8: ='Юнит 19'!S7 -> 29 | K8: =J8/J$64 -> 0.041428571 | L8: =L7+K8 -> 0.83142857 | M8: =_xlfn.IFS(L8<80%,"A",L8<=95%,"B",L8>95%,"C") -> B
B9: Qs син Сул | C9: ='Юнит 19'!AL5 -> 3708.9954 | D9: =C9/C$64 -> 0.019525623 | E9: =E8+D9 -> 1.0237737 | F9: =IF(AND(E9<=0),"C",IF(E9<=0.8,"A",IF(E9<=0.95,"B","C"))) -> C | G9: =VLOOKUP(B$4:B$63,I$4:M$63,5,0) -> A | I9: Qs желт Сул | J9: ='Юнит 19'!S6 -> 28 | K9: =J9/J$64 -> 0.04 | L9: =L8+K9 -> 0.87142857 | M9: =_xlfn.IFS(L9<80%,"A",L9<=95%,"B",L9>95%,"C") -> B
B10: qs015 | C10: ='Юнит 19'!AL32 -> 3671.9772 | D10: =C10/C$64 -> 0.019330744 | E10: =E9+D10 -> 1.0431044 | F10: =IF(AND(E10<=0),"C",IF(E10<=0.8,"A",IF(E10<=0.95,"B","C"))) -> C | G10: =VLOOKUP(B$4:B$63,I$4:M$63,5,0) -> B | I10: MR 1890 корич | J10: ='Юнит 19'!S18 -> 10 | K10: =J10/J$64 -> 0.014285714 | L10: =L9+K10 -> 0.88571429 | M10: =_xlfn.IFS(L10<80%,"A",L10<=95%,"B",L10>95%,"C") -> B
B11: qs007 | C11: ='Юнит 19'!AL24 -> 2760.2195 | D11: =C11/C$64 -> 0.01453089 | E11: =E10+D11 -> 1.0576353 | F11: =IF(AND(E11<=0),"C",IF(E11<=0.8,"A",IF(E11<=0.95,"B","C"))) -> C | G11: =VLOOKUP(B$4:B$63,I$4:M$63,5,0) -> B | I11: MR 1890 черн | J11: ='Юнит 19'!S16 -> 9 | K11: =J11/J$64 -> 0.012857143 | L11: =L10+K11 -> 0.89857143 | M11: =_xlfn.IFS(L11<80%,"A",L11<=95%,"B",L11>95%,"C") -> B
B12: qs006 | C12: ='Юнит 19'!AL23 -> 2450.28 | D12: =C12/C$64 -> 0.012899246 | E12: =E11+D12 -> 1.0705346 | F12: =IF(AND(E12<=0),"C",IF(E12<=0.8,"A",IF(E12<=0.95,"B","C"))) -> C | G12: =VLOOKUP(B$4:B$63,I$4:M$63,5,0) -> C | I12: MR 1890 желт | J12: ='Юнит 19'!S17 -> 8 | K12: =J12/J$64 -> 0.011428571 | L12: =L11+K12 -> 0.91 | M12: =_xlfn.IFS(L12<80%,"A",L12<=95%,"B",L12>95%,"C") -> B
B13: qs005 | C13: ='Юнит 19'!AL22 -> 2261.443 | D13: =C13/C$64 -> 0.011905133 | E13: =E12+D13 -> 1.0824397 | F13: =IF(AND(E13<=0),"C",IF(E13<=0.8,"A",IF(E13<=0.95,"B","C"))) -> C | G13: =VLOOKUP(B$4:B$63,I$4:M$63,5,0) -> B | I13: qs015 | J13: ='Юнит 19'!S32 -> 8 | K13: =J13/J$64 -> 0.011428571 | L13: =L12+K13 -> 0.92142857 | M13: =_xlfn.IFS(L13<80%,"A",L13<=95%,"B",L13>95%,"C") -> B
B14: qs014 | C14: ='Юнит 19'!AL31 -> 2072.55 | D14: =C14/C$64 -> 0.010910725 | E14: =E13+D14 -> 1.0933504 | F14: =IF(AND(E14<=0),"C",IF(E14<=0.8,"A",IF(E14<=0.95,"B","C"))) -> C | G14: =VLOOKUP(B$4:B$63,I$4:M$63,5,0) -> C | I14: qs005 | J14: ='Юнит 19'!S22 -> 7 | K14: =J14/J$64 -> 0.01 | L14: =L13+K14 -> 0.93142857 | M14: =_xlfn.IFS(L14<80%,"A",L14<=95%,"B",L14>95%,"C") -> B
B15: MR 1890 черн | C15: ='Юнит 19'!AL16 -> 1970.1401 | D15: =C15/C$64 -> 0.010371599 | E15: =E14+D15 -> 1.103722 | F15: =IF(AND(E15<=0),"C",IF(E15<=0.8,"A",IF(E15<=0.95,"B","C"))) -> C | G15: =VLOOKUP(B$4:B$63,I$4:M$63,5,0) -> B | I15: qs007 | J15: ='Юнит 19'!S24 -> 6 | K15: =J15/J$64 -> 0.0085714286 | L15: =L14+K15 -> 0.94 | M15: =_xlfn.IFS(L15<80%,"A",L15<=95%,"B",L15>95%,"C") -> B
